10:28:33.097: 658347 - 118 - 1128=935=X34=65834752=20140610-13:28:33.10875=20140610268=2279=2269=022=8207=BVMF48=380963983=255737273=83:31:07272=2014061037=80531942220288=45290=65279=0269=022=8207=BVMF48=380963983=255738270=26.39273=83:31:07271=3000272=2014061037016=2014061037017=83:31:0737=80531942347288=45290=5
10:28:33.097: 658348 - 72 - 1128=935=X34=65834852=20140610-13:28:33.10875=20140610268=1279=2269=122=8207=BVMF48=380968883=253396273=83:31:07272=2014061037=80531941733289=45290=30
10:28:33.107: 658349 - 83 - 1128=935=X34=65834952=20140610-13:28:33.11775=20140610268=1279=0269=122=8207=BVMF48=380963983=255739270=26.4273=83:31:16271=900272=2014061037016=2014061037017=83:31:1637=80531942403289=45290=2
10:28:33.112: 658350 - 81 - 1128=935=X34=65835052=20140610-13:28:33.12275=20140610268=1279=0269=022=8207=BVMF48=380963983=255740270=26.37273=83:31:21271=300272=2014061037016=2014061037017=83:31:2137=80531942412288=45290=16
10:28:33.116: 658351 - 80 - 1128=935=X34=65835152=20140610-13:28:33.12675=20140610268=1279=0269=022=8207=BVMF48=380963983=255741270=26.39273=83:31:26271=300272=2014061037016=2014061037017=83:31:2637=80531942415288=3290=6
10:28:33.134: 658352 - 199 - 1128=935=X34=65835252=20140610-13:28:33.14575=20140610268=4279=0269=222=8207=BVMF48=380963983=255742270=26.4273=83:31:44271=600272=2014061037016=2014061037017=83:31:441500=E451=-0.211020=1403600274=1277=L1003=18890288=3289=85279=0269=922=8207=BVMF48=380963983=255743270=26.47273=83:31:44272=201406101500=E279=1269=122=8207=BVMF48=380963983=255744270=26.4273=83:31:44271=300272=2014061037016=2014061037017=83:31:0537=80531942343289=85290=1279=2269=022=8207=BVMF48=380963983=255745273=83:31:44272=2014061037=80531942088288=3290=3
10:28:33.143: 658353 - 80 - 1128=935=X34=65835352=20140610-13:28:33.15375=20140610268=1279=0269=022=8207=BVMF48=380963983=255746270=26.39273=83:31:53271=600272=2014061037016=2014061037017=83:31:5337=80531942451288=3290=6
10:28:33.146: 658354 - 80 - 1128=935=X34=65835452=20140610-13:28:33.15675=20140610268=1279=0269=022=8207=BVMF48=380963983=255747270=26.37273=83:31:56271=100272=2014061037016=2014061037017=83:31:5637=80531942453288=8290=18
10:28:33.149: 658355 - 82 - 1128=935=X34=65835552=20140610-13:28:33.15975=20140610268=1279=1269=122=8207=BVMF48=380963983=255748270=26.4273=83:31:58271=300272=2014061037016=2014061037017=83:31:1637=80531942456289=45290=2
10:28:33.153: 658356 - 296 - 1128=935=X34=65835652=20140610-13:28:33.16375=20140610268=7279=0269=222=8207=BVMF48=380963983=255749270=26.4273=83:31:63271=300272=2014061037016=2014061037017=83:31:621500=E451=-0.211020=1403900274=1277=L1003=18900288=3289=85279=0269=922=8207=BVMF48=380963983=255750270=26.47273=83:31:63272=201406101500=E279=0269=222=8207=BVMF48=380963983=255751270=26.4273=83:31:63271=300272=2014061037016=2014061037017=83:31:621500=E451=-0.211020=1404200274=1277=L1003=18910288=3289=45279=0269=922=8207=BVMF48=380963983=255752270=26.47273=83:31:63272=201406101500=E279=4269=122=8207=BVMF48=380963983=255753273=83:31:63272=20140610290=2279=0269=122=8207=BVMF48=380963983=255754270=26.4273=83:31:63271=5000272=2014061037016=2014061037017=83:31:6237=80531942464289=85290=1279=2269=022=8207=BVMF48=380963983=255755273=83:31:63272=2014061037=80531942451288=3290=6
10:28:33.154: 658357 - 70 - 1128=935=X34=65835752=20140610-13:28:33.16575=20140610268=1279=2269=022=8207=BVMF48=380963983=255756273=83:31:64272=2014061037=80531942453288=8290=17
10:28:33.154: 658358 - 71 - 1128=935=X34=65835852=20140610-13:28:33.16575=20140610268=1279=2269=022=8207=BVMF48=380963983=255757273=83:31:64272=2014061037=80531942347288=45290=4
10:28:33.158: 658359 - 72 - 1128=935=X34=65835952=20140610-13:28:33.16875=20140610268=1279=2269=122=8207=BVMF48=380963983=255758273=83:31:68272=2014061037=80531942130289=45290=9
10:28:33.164: 658360 - 83 - 1128=935=X34=65836052=20140610-13:28:33.17575=20140610268=1279=0269=122=8207=BVMF48=380963983=255759270=26.4273=83:31:74271=300272=2014061037016=2014061037017=83:31:7437=80531942496289=45290=2
10:28:33.166: 658361 - 80 - 1128=935=X34=65836152=20140610-13:28:33.17775=20140610268=1279=0269=022=8207=BVMF48=380963983=255760270=26.39273=83:31:76271=600272=2014061037016=2014061037017=83:31:7637=80531942503288=3290=5
10:28:33.182: 658362 - 199 - 1128=935=X34=65836252=20140610-13:28:33.19275=20140610268=4279=0269=222=8207=BVMF48=380963983=255761270=26.4273=83:31:91271=600272=2014061037016=2014061037017=83:31:911500=E451=-0.211020=1404800274=1277=L1003=18920288=3289=85279=0269=922=8207=BVMF48=380963983=255762270=26.47273=83:31:91272=201406101500=E279=1269=122=8207=BVMF48=380963983=255763270=26.4273=83:31:91271=4400272=2014061037016=2014061037017=83:31:6237=80531942464289=85290=1279=2269=022=8207=BVMF48=380963983=255764273=83:31:91272=2014061037=80531942503288=3290=5
10:28:33.210: 658363 - 83 - 1128=935=X34=65836352=20140610-13:28:33.22175=20140610268=1279=0269=122=8207=BVMF48=380249383=103473270=9.4273=83:32:20271=4700272=2014061037016=2014061037017=83:32:2037=80531942540289=40290=31
10:28:33.213: 658364 - 82 - 1128=935=X34=65836452=20140610-13:28:33.22375=20140610268=1279=0269=122=8207=BVMF48=380249383=103474270=9.42273=83:32:22271=4500272=2014061037016=2014061037017=83:32:2237=80531942542289=40290=40
10:28:33.232: 658365 - 81 - 1128=935=X34=65836552=20140610-13:28:33.24375=20140610268=1279=0269=122=8207=BVMF48=380968883=253397270=29.39273=83:32:42271=100272=2014061037016=2014061037017=83:32:4237=80531942547289=3290=5
10:28:33.240: 658366 - 83 - 1128=935=X34=65836652=20140610-13:28:33.25075=20140610268=1279=0269=122=8207=BVMF48=380963983=255765270=26.4273=83:32:49271=900272=2014061037016=2014061037017=83:32:4937=80531942549289=40290=3
10:28:33.297: 658367 - 82 - 1128=935=X34=65836752=20140610-13:28:33.30875=20140610268=1279=0269=122=8207=BVMF48=380963983=255766270=26.42273=83:33:07271=3000272=2014061037016=2014061037017=83:33:0737=80531942568289=45290=11
10:28:33.298: 658368 - 82 - 1128=935=X34=65836852=20140610-13:28:33.30975=20140610268=1279=0269=122=8207=BVMF48=380968883=253398270=29.47273=83:33:08271=2000272=2014061037016=2014061037017=83:33:0837=80531942569289=45290=31
10:28:33.355: 658369 - 81 - 1128=935=X34=65836952=20140610-13:28:33.36675=20140610268=1279=0269=022=8207=BVMF48=380963983=255767270=26.29273=83:33:65271=3000272=2014061037016=2014061037017=83:33:6537=80531942575288=45290=66
10:28:33.359: 658370 - 83 - 1128=935=X34=65837052=20140610-13:28:33.37075=20140610268=1279=0269=122=8207=BVMF48=380963983=255768270=26.5273=83:33:69271=5000272=2014061037016=2014061037017=83:33:6937=80531942576289=45290=58
10:28:33.401: 658371 - 71 - 1128=935=X34=65837152=20140610-13:28:33.41175=20140610268=1279=2269=122=8207=BVMF48=380249383=103475273=83:34:11272=2014061037=80531924789289=8290=11
10:28:33.401: 658372 - 81 - 1128=935=X34=65837252=20140610-13:28:33.41175=20140610268=1279=0269=122=8207=BVMF48=380249383=103476270=9.42273=83:34:11271=800272=2014061037016=2014061037017=83:34:1137=80531942580289=8290=40
10:28:33.574: 658373 - 118 - 1128=935=X34=65837352=20140610-13:28:33.58475=20140610268=2279=2269=122=8207=BVMF48=386391783=2484273=83:35:83272=2014061037=80531931369289=63290=2279=0269=122=8207=BVMF48=386391783=2485270=9.47273=83:35:83271=97272=2014061037016=2014061037017=83:35:8337=80531942586289=63290=1
10:28:33.587: 658374 - 119 - 1128=935=X34=65837452=20140610-13:28:33.59775=20140610268=2279=2269=122=8207=BVMF48=386391783=2486273=83:35:97272=2014061037=80531942289289=110290=2279=0269=122=8207=BVMF48=386391783=2487270=9.46273=83:35:97271=4272=2014061037016=2014061037017=83:35:9637=80531942587289=110290=1
10:28:33.596: 658375 - 70 - 1128=935=X34=65837552=20140610-13:28:33.60775=20140610268=1279=2269=022=8207=BVMF48=380963983=255769273=83:36:06272=2014061037=80531934374288=8290=13
10:28:33.597: 658376 - 80 - 1128=935=X34=65837652=20140610-13:28:33.60775=20140610268=1279=0269=022=8207=BVMF48=380963983=255770270=26.34273=83:36:06271=300272=2014061037016=2014061037017=83:36:0637=80531942588288=8290=40
10:28:33.606: 658377 - 118 - 1128=935=X34=65837752=20140610-13:28:33.61775=20140610268=2279=2269=022=8207=BVMF48=380963983=255771273=83:36:16272=2014061037=80531942412288=45290=14279=0269=022=8207=BVMF48=380963983=255772270=26.36273=83:36:16271=2600272=2014061037016=2014061037017=83:36:1637=80531942589288=45290=24
10:28:34.096: 658378 - 70 - 1128=935=X34=65837852=20140610-13:28:34.10675=20140610268=1279=2269=022=8207=BVMF48=380963983=255773273=83:41:06272=2014061037=80531933877288=8290=21
10:28:34.096: 658379 - 80 - 1128=935=X34=65837952=20140610-13:28:34.10775=20140610268=1279=0269=022=8207=BVMF48=380963983=255774270=26.33273=83:41:06271=300272=2014061037016=2014061037017=83:41:0637=80531942593288=8290=45
10:28:34.102: 658380 - 80 - 1128=935=X34=65838052=20140610-13:28:34.11275=20140610268=1279=1269=022=8207=BVMF48=380963983=255775270=26.36273=83:41:12271=2300272=2014061037016=2014061037017=83:36:1637=80531942594288=45290=23
10:28:34.190: 658381 - 118 - 1128=935=X34=65838152=20140610-13:28:34.20175=20140610268=2279=2269=122=8207=BVMF48=386391783=2488273=83:42:00272=2014061037=80531942586289=63290=2279=0269=122=8207=BVMF48=386391783=2489270=9.45273=83:42:00271=97272=2014061037016=2014061037017=83:42:0037=80531942595289=63290=1
10:28:34.196: 658382 - 119 - 1128=935=X34=65838252=20140610-13:28:34.20675=20140610268=2279=2269=122=8207=BVMF48=386391783=2490273=83:42:06272=2014061037=80531942587289=110290=2279=0269=122=8207=BVMF48=386391783=2491270=9.44273=83:42:06271=4272=2014061037016=2014061037017=83:42:0637=80531942596289=110290=1
10:28:34.349: 658383 - 71 - 1128=935=X34=65838352=20140610-13:28:34.36075=20140610268=1279=2269=122=8207=BVMF48=380968883=253399273=83:43:59272=2014061037=80531942547289=3290=5
10:28:34.981: 658384 - 84 - 1128=935=X34=65838452=20140610-13:28:34.99275=20140610268=1279=0269=122=8207=BVMF48=380963983=255776270=26.4273=83:49:91271=200272=2014061037016=2014061037017=83:49:9137=80531942607289=238290=4
10:28:35.010: 658385 - 81 - 1128=935=X34=65838552=20140610-13:28:35.02175=20140610268=1279=0269=122=8207=BVMF48=380965483=79517270=8.22273=83:50:20271=1000272=2014061037016=2014061037017=83:50:2037=80531942608289=3290=7
10:28:35.149: 658386 - 71 - 1128=935=X34=65838652=20140610-13:28:35.15975=20140610268=1279=2269=122=8207=BVMF48=380965483=79518273=83:51:58272=2014061037=80531939460289=8290=20
10:28:35.251: 658387 - 119 - 1128=935=X34=65838752=20140610-13:28:35.26175=20140610268=2279=2269=122=8207=BVMF48=380394783=65748273=83:52:61272=2014061037=80531941205289=23290=5279=0269=122=8207=BVMF48=380394783=65749270=17.06273=83:52:61271=100272=2014061037016=2014061037017=83:52:6137=80531942609289=23290=6
10:28:35.272: 658388 - 82 - 1128=935=X34=65838852=20140610-13:28:35.28275=20140610268=1279=0269=122=8207=BVMF48=380249383=103477270=9.35273=83:52:82271=400272=2014061037016=2014061037017=83:52:8237=80531942610289=70290=9
10:28:35.386: 658389 - 118 - 1128=935=X34=65838952=20140610-13:28:35.39775=20140610268=2279=2269=122=8207=BVMF48=386391783=2492273=83:53:96272=2014061037=80531942595289=63290=2279=0269=122=8207=BVMF48=386391783=2493270=9.43273=83:53:96271=97272=2014061037016=2014061037017=83:53:9637=80531942611289=63290=1
10:28:35.393: 658390 - 119 - 1128=935=X34=65839052=20140610-13:28:35.40375=20140610268=2279=2269=122=8207=BVMF48=386391783=2494273=83:54:03272=2014061037=80531942596289=110290=2279=0269=122=8207=BVMF48=386391783=2495270=9.42273=83:54:03271=4272=2014061037016=2014061037017=83:54:0337=80531942612289=110290=1
10:28:35.462: 658391 - 80 - 1128=935=X34=65839152=20140610-13:28:35.47275=20140610268=1279=0269=022=8207=BVMF48=380391383=106155270=13.84273=83:54:72271=100272=2014061037016=2014061037017=83:54:7237=80531942613288=8290=1
10:28:35.469: 658392 - 116 - 1128=935=X34=65839252=20140610-13:28:35.47975=20140610268=2279=2269=022=8207=BVMF48=380394783=65750273=83:54:79272=2014061037=80531941577288=3290=6279=0269=022=8207=BVMF48=380394783=65751270=17.02273=83:54:79271=600272=2014061037016=2014061037017=83:54:7937=80531942614288=3290=4
10:28:35.482: 658393 - 72 - 1128=935=X34=65839352=20140610-13:28:35.49275=20140610268=1279=2269=022=8207=BVMF48=380394783=65752273=83:54:92272=2014061037=80531941595288=110290=10
10:28:35.485: 658394 - 70 - 1128=935=X34=65839452=20140610-13:28:35.49575=20140610268=1279=2269=022=8207=BVMF48=380391383=106156273=83:54:95272=2014061037=80531941601288=8290=34
10:28:35.496: 658395 - 80 - 1128=935=X34=65839552=20140610-13:28:35.50675=20140610268=1279=0269=022=8207=BVMF48=380391383=106157270=13.78273=83:55:06271=1000272=2014061037016=2014061037017=83:55:0637=80531942622288=8290=34
10:28:35.605: 658396 - 70 - 1128=935=X34=65839652=20140610-13:28:35.61675=20140610268=1279=2269=022=8207=BVMF48=380394783=65753273=83:56:15272=2014061037=80531941596288=8290=2
10:28:35.743: 658397 - 80 - 1128=935=X34=65839752=20140610-13:28:35.75475=20140610268=1279=0269=022=8207=BVMF48=380394783=65754270=17.03273=83:57:53271=400272=2014061037016=2014061037017=83:57:5337=80531942629288=8290=1
10:28:35.757: 658398 - 70 - 1128=935=X34=65839852=20140610-13:28:35.76875=20140610268=1279=2269=022=8207=BVMF48=380391383=106158273=83:57:67272=2014061037=80531942622288=8290=34
10:28:35.767: 658399 - 80 - 1128=935=X34=65839952=20140610-13:28:35.77875=20140610268=1279=0269=022=8207=BVMF48=380391383=106159270=13.78273=83:57:77271=400272=2014061037016=2014061037017=83:57:7737=80531942630288=8290=34
10:28:35.953: 658400 - 115 - 1128=935=X34=65840052=20140610-13:28:35.96475=20140610268=2279=2269=022=8207=BVMF48=390102283=4015273=83:59:63272=2014061037=80531941602288=3290=2279=0269=022=8207=BVMF48=390102283=4016270=17.02273=83:59:63271=96272=2014061037016=2014061037017=83:59:6337=80531942636288=3290=1
10:28:36.045: 658401 - 82 - 1128=935=X34=65840152=20140610-13:28:36.05575=20140610268=1279=0269=122=8207=BVMF48=380394783=65755270=17.04273=83:60:55271=400272=2014061037016=2014061037017=83:60:5537=80531942637289=40290=3
10:28:36.053: 658402 - 118 - 1128=935=X34=65840252=20140610-13:28:36.06475=20140610268=2279=2269=122=8207=BVMF48=386391783=2496273=83:60:63272=2014061037=80531942611289=63290=2279=0269=122=8207=BVMF48=386391783=2497270=9.41273=83:60:63271=97272=2014061037016=2014061037017=83:60:6337=80531942638289=63290=1
10:28:36.059: 658403 - 120 - 1128=935=X34=65840352=20140610-13:28:36.06975=20140610268=2279=2269=122=8207=BVMF48=386391783=2498273=83:60:69272=2014061037=80531942612289=110290=2279=0269=122=8207=BVMF48=386391783=2499270=9.4273=83:60:69271=4272=2014061037016=2014061037017=83:60:6937=80531942639289=110290=1
10:28:36.145: 658404 - 71 - 1128=935=X34=65840452=20140610-13:28:36.15575=20140610268=1279=2269=122=8207=BVMF48=380394783=65756273=83:61:55272=2014061037=80531941578289=8290=6
10:28:36.146: 658405 - 81 - 1128=935=X34=65840552=20140610-13:28:36.15775=20140610268=1279=0269=122=8207=BVMF48=380394783=65757270=17.06273=83:61:56271=100272=2014061037016=2014061037017=83:61:5637=80531942640289=8290=7
10:28:36.184: 658406 - 81 - 1128=935=X34=65840652=20140610-13:28:36.19575=20140610268=1279=0269=022=8207=BVMF48=380391383=106160270=13.84273=83:61:94271=200272=2014061037016=2014061037017=83:61:9437=80531942641288=40290=2
10:28:36.186: 658407 - 80 - 1128=935=X34=65840752=20140610-13:28:36.19675=20140610268=1279=0269=022=8207=BVMF48=380566083=11399270=2.47273=83:61:96271=100272=2014061037016=2014061037017=83:61:9537=80531942642288=40290=3
10:28:36.188: 658408 - 81 - 1128=935=X34=65840852=20140610-13:28:36.19875=20140610268=1279=0269=022=8207=BVMF48=380963983=255777270=26.39273=83:61:98271=600272=2014061037016=2014061037017=83:61:9837=80531942643288=40290=5
10:28:36.188: 658409 - 81 - 1128=935=X34=65840952=20140610-13:28:36.19975=20140610268=1279=0269=022=8207=BVMF48=380968883=253400270=29.38273=83:61:98271=300272=2014061037016=2014061037017=83:61:9837=80531942644288=40290=1
10:28:36.189: 658410 - 71 - 1128=935=X34=65841052=20140610-13:28:36.20075=20140610268=1279=2269=122=8207=BVMF48=380968883=253401273=83:61:99272=2014061037=80531941666289=8290=3
10:28:36.190: 658411 - 81 - 1128=935=X34=65841152=20140610-13:28:36.20075=20140610268=1279=0269=022=8207=BVMF48=380394783=65758270=17.03273=83:62:00271=100272=2014061037016=2014061037017=83:62:0037=80531942645288=40290=2
10:28:36.195: 658412 - 81 - 1128=935=X34=65841252=20140610-13:28:36.20575=20140610268=1279=0269=022=8207=BVMF48=380249383=103478270=9.34273=83:62:05271=200272=2014061037016=2014061037017=83:62:0537=80531942648288=40290=1
10:28:36.195: 658413 - 81 - 1128=935=X34=65841352=20140610-13:28:36.20675=20140610268=1279=0269=022=8207=BVMF48=380965483=79519270=8.21273=83:62:05271=100272=2014061037016=2014061037017=83:62:0537=80531942649288=40290=3
10:28:36.202: 658414 - 118 - 1128=935=X34=65841452=20140610-13:28:36.21275=20140610268=2279=2269=022=8207=BVMF48=380963983=255778273=83:62:12272=2014061037=80531942594288=45290=24279=0269=022=8207=BVMF48=380963983=255779270=26.39273=83:62:12271=600272=2014061037016=2014061037017=83:62:1137=80531942654288=45290=6
10:28:36.225: 658415 - 70 - 1128=935=X34=65841552=20140610-13:28:36.23575=20140610268=1279=2269=022=8207=BVMF48=380249383=103479273=83:62:34272=2014061037=80531930910288=8290=50
10:28:36.225: 658416 - 80 - 1128=935=X34=65841652=20140610-13:28:36.23575=20140610268=1279=0269=022=8207=BVMF48=380249383=103480270=9.31273=83:62:35271=700272=2014061037016=2014061037017=83:62:3537=80531942680288=8290=23
10:28:36.250: 658417 - 71 - 1128=935=X34=65841752=20140610-13:28:36.26175=20140610268=1279=2269=122=8207=BVMF48=380249383=103481273=83:62:61272=2014061037=80531942284289=8290=6
10:28:36.262: 658418 - 70 - 1128=935=X34=65841852=20140610-13:28:36.27375=20140610268=1279=2269=022=8207=BVMF48=380391383=106161273=83:62:72272=2014061037=80531942630288=8290=35
10:28:36.300: 658419 - 81 - 1128=935=X34=65841952=20140610-13:28:36.31175=20140610268=1279=0269=022=8207=BVMF48=380391383=106162270=13.84273=83:63:10271=300272=2014061037016=2014061037017=83:63:1037=80531942697288=40290=3
10:28:36.306: 658420 - 81 - 1128=935=X34=65842052=20140610-13:28:36.31675=20140610268=1279=0269=022=8207=BVMF48=380394783=65759270=17.03273=83:63:16271=100272=2014061037016=2014061037017=83:63:1637=80531942699288=40290=3
10:28:36.307: 658421 - 81 - 1128=935=X34=65842152=20140610-13:28:36.31775=20140610268=1279=0269=022=8207=BVMF48=380963983=255780270=26.39273=83:63:17271=500272=2014061037016=2014061037017=83:63:1737=80531942700288=40290=7
10:28:36.308: 658422 - 81 - 1128=935=X34=65842252=20140610-13:28:36.31875=20140610268=1279=0269=022=8207=BVMF48=380968883=253402270=29.38273=83:63:18271=400272=2014061037016=2014061037017=83:63:1737=80531942701288=40290=2
10:28:36.309: 658423 - 81 - 1128=935=X34=65842352=20140610-13:28:36.32075=20140610268=1279=0269=022=8207=BVMF48=380249383=103482270=9.34273=83:63:20271=200272=2014061037016=2014061037017=83:63:1937=80531942702288=40290=2
10:28:36.310: 658424 - 81 - 1128=935=X34=65842452=20140610-13:28:36.32175=20140610268=1279=0269=022=8207=BVMF48=380965483=79520270=8.21273=83:63:20271=200272=2014061037016=2014061037017=83:63:2037=80531942703288=40290=4
10:28:36.323: 658425 - 80 - 1128=935=X34=65842552=20140610-13:28:36.33475=20140610268=1279=0269=022=8207=BVMF48=380391383=106163270=13.78273=83:63:34271=600272=2014061037016=2014061037017=83:63:3337=80531942707288=8290=36
10:28:36.334: 658426 - 71 - 1128=935=X34=65842652=20140610-13:28:36.34575=20140610268=1279=2269=022=8207=BVMF48=380394783=65760273=83:63:44272=2014061037=80531942699288=40290=3
10:28:36.334: 658427 - 71 - 1128=935=X34=65842752=20140610-13:28:36.34575=20140610268=1279=2269=022=8207=BVMF48=380394783=65761273=83:63:45272=2014061037=80531942645288=40290=2
10:28:36.344: 658428 - 70 - 1128=935=X34=65842852=20140610-13:28:36.35575=20140610268=1279=2269=022=8207=BVMF48=380566083=11400273=83:63:54272=2014061037=80531926480288=85290=5
10:28:36.488: 658429 - 81 - 1128=935=X34=65842952=20140610-13:28:36.49975=20140610268=1279=1269=122=8207=BVMF48=380394783=65762270=17.04273=83:64:98271=300272=2014061037016=2014061037017=83:60:5537=80531942709289=40290=3
10:28:36.497: 658430 - 118 - 1128=935=X34=65843052=20140610-13:28:36.50775=20140610268=2279=2269=022=8207=BVMF48=380249383=103483273=83:65:07272=2014061037=80531941398288=40290=6279=0269=022=8207=BVMF48=380249383=103484270=9.34273=83:65:07271=100272=2014061037016=2014061037017=83:65:0737=80531942710288=40290=3
10:28:36.508: 658431 - 80 - 1128=935=X34=65843152=20140610-13:28:36.51975=20140610268=1279=0269=022=8207=BVMF48=380566083=11401270=2.46273=83:65:18271=5000272=2014061037016=2014061037017=83:65:1837=80531942711288=85290=5
10:28:36.565: 658432 - 70 - 1128=935=X34=65843252=20140610-13:28:36.57675=20140610268=1279=2269=022=8207=BVMF48=380391383=106164273=83:65:75272=2014061037=80531942707288=8290=36
10:28:36.584: 658433 - 118 - 1128=935=X34=65843352=20140610-13:28:36.59575=20140610268=2279=2269=022=8207=BVMF48=380249383=103485273=83:65:94272=2014061037=80531940591288=40290=6279=0269=022=8207=BVMF48=380249383=103486270=9.34273=83:65:94271=100272=2014061037016=2014061037017=83:65:9437=80531942713288=40290=4
10:28:36.630: 658434 - 80 - 1128=935=X34=65843452=20140610-13:28:36.64175=20140610268=1279=0269=022=8207=BVMF48=380391383=106165270=13.78273=83:66:40271=700272=2014061037016=2014061037017=83:66:4037=80531942715288=8290=36
10:28:36.646: 658435 - 70 - 1128=935=X34=65843552=20140610-13:28:36.65775=20140610268=1279=2269=022=8207=BVMF48=380391383=106166273=83:66:56272=2014061037=80531942715288=8290=36
10:28:36.657: 658436 - 80 - 1128=935=X34=65843652=20140610-13:28:36.66875=20140610268=1279=0269=022=8207=BVMF48=380391383=106167270=13.78273=83:66:67271=400272=2014061037016=2014061037017=83:66:6737=80531942716288=8290=36
10:28:36.729: 658437 - 118 - 1128=935=X34=65843752=20140610-13:28:36.73975=20140610268=2279=2269=122=8207=BVMF48=386391783=2500273=83:67:38272=2014061037=80531942638289=63290=2279=0269=122=8207=BVMF48=386391783=2501270=9.39273=83:67:38271=97272=2014061037016=2014061037017=83:67:3837=80531942717289=63290=1
10:28:36.734: 658438 - 119 - 1128=935=X34=65843852=20140610-13:28:36.74575=20140610268=2279=2269=122=8207=BVMF48=386391783=2502273=83:67:44272=2014061037=80531942639289=110290=2279=0269=122=8207=BVMF48=386391783=2503270=9.38273=83:67:44271=4272=2014061037016=2014061037017=83:67:4437=80531942718289=110290=1
10:28:36.845: 658439 - 80 - 1128=935=X34=65843952=20140610-13:28:36.85575=20140610268=1279=0269=022=8207=BVMF48=380968883=253403270=29.37273=83:68:55271=300272=2014061037016=2014061037017=83:68:5537=80531942723288=8290=4
10:28:36.971: 658440 - 118 - 1128=935=X34=65844052=20140610-13:28:36.98175=20140610268=2279=2269=022=8207=BVMF48=380968883=253404273=83:69:80272=2014061037=80531942122288=45290=7279=0269=022=8207=BVMF48=380968883=253405270=29.37273=83:69:80271=1000272=2014061037016=2014061037017=83:69:8037=80531942726288=45290=5
10:28:37.036: 658441 - 81 - 1128=935=X34=65844152=20140610-13:28:37.04675=20140610268=1279=0269=122=8207=BVMF48=380963983=255781270=26.41273=83:70:46271=100272=2014061037016=2014061037017=83:70:4537=80531942727289=3290=5
10:28:37.045: 658442 - 162 - 1128=935=X34=65844252=20140610-13:28:37.05475=20140610268=3279=0269=222=8207=BVMF48=380963983=255782270=26.4273=83:70:53271=100272=2014061037016=2014061037017=83:70:531500=E451=-0.211020=1404900274=1277=L1003=18930288=735289=85279=0269=922=8207=BVMF48=380963983=255783270=26.47273=83:70:53272=201406101500=E279=1269=122=8207=BVMF48=380963983=255784270=26.4273=83:70:53271=4300272=2014061037016=2014061037017=83:31:6237=80531942464289=85290=1
10:28:37.048: 658443 - 70 - 1128=935=X34=65844352=20140610-13:28:37.05875=20140610268=1279=2269=022=8207=BVMF48=380963983=255785273=83:70:58272=2014061037=80531942097288=3290=3
10:28:37.059: 658444 - 71 - 1128=935=X34=65844452=20140610-13:28:37.07075=20140610268=1279=2269=122=8207=BVMF48=380963983=255786273=83:70:69272=2014061037=80531942058289=8290=11
10:28:37.068: 658445 - 70 - 1128=935=X34=65844552=20140610-13:28:37.07975=20140610268=1279=2269=022=8207=BVMF48=380963983=255787273=83:70:78272=2014061037=80531942053288=3290=2
10:28:37.145: 658446 - 71 - 1128=935=X34=65844652=20140610-13:28:37.15575=20140610268=1279=2269=122=8207=BVMF48=380249383=103487273=83:71:55272=2014061037=80531942331289=8290=12
10:28:37.145: 658447 - 71 - 1128=935=X34=65844752=20140610-13:28:37.15675=20140610268=1279=2269=122=8207=BVMF48=380968883=253406273=83:71:55272=2014061037=80531942121289=8290=15
10:28:37.603: 658448 - 118 - 1128=935=X34=65844852=20140610-13:28:37.61475=20140610268=2279=2269=122=8207=BVMF48=386391783=2504273=83:76:13272=2014061037=80531942717289=63290=2279=0269=122=8207=BVMF48=386391783=2505270=9.37273=83:76:13271=97272=2014061037016=2014061037017=83:76:1337=80531942745289=63290=1
10:28:37.610: 658449 - 119 - 1128=935=X34=65844952=20140610-13:28:37.62075=20140610268=2279=2269=122=8207=BVMF48=386391783=2506273=83:76:20272=2014061037=80531942718289=110290=2279=0269=122=8207=BVMF48=386391783=2507270=9.36273=83:76:20271=4272=2014061037016=2014061037017=83:76:2037=80531942746289=110290=1
10:28:37.612: 658450 - 81 - 1128=935=X34=65845052=20140610-13:28:37.62375=20140610268=1279=0269=022=8207=BVMF48=380963983=255788270=26.34273=83:76:22271=100272=2014061037016=2014061037017=83:76:2237=80531942747288=40290=40
10:28:37.756: 658451 - 193 - 1128=935=X34=65845152=20140610-13:28:37.76675=20140610268=4279=0269=222=8207=BVMF48=380391383=106168270=13.85273=83:77:66271=100272=2014061037016=2014061037017=83:77:651500=E451=-0.041020=108200274=01003=3340288=8289=8279=0269=922=8207=BVMF48=380391383=106169270=13.878273=83:77:66272=201406101500=E279=1269=122=8207=BVMF48=380391383=106170270=13.85273=83:77:66271=600272=2014061037016=2014061037017=50:95:0937=80531929098289=8290=1279=2269=022=8207=BVMF48=380391383=106171273=83:77:66272=2014061037=80531942613288=8290=1
10:28:37.757: 658452 - 80 - 1128=935=X34=65845252=20140610-13:28:37.76875=20140610268=1279=0269=022=8207=BVMF48=380391383=106172270=13.84273=83:77:67271=300272=2014061037016=2014061037017=83:77:6737=80531942749288=8290=3
10:28:38.038: 658453 - 118 - 1128=935=X34=65845352=20140610-13:28:38.04975=20140610268=2279=2269=122=8207=BVMF48=386391783=2508273=83:80:48272=2014061037=80531942745289=63290=2279=0269=122=8207=BVMF48=386391783=2509270=9.49273=83:80:48271=97272=2014061037016=2014061037017=83:80:4837=80531942754289=63290=2
10:28:38.316: 658454 - 121 - 1128=935=X34=65845452=20140610-13:28:38.32775=20140610268=2279=2269=022=8207=BVMF48=380963983=255789273=83:83:26272=2014061037=80531927440288=106290=29279=0269=022=8207=BVMF48=380963983=255790270=26.33273=83:83:26271=10000272=2014061037016=2014061037017=83:83:2637=80531942755288=106290=46
10:28:38.517: 658455 - 83 - 1128=935=X34=65845552=20140610-13:28:38.52875=20140610268=1279=0269=022=8207=BVMF48=380965483=79521270=8.2273=83:85:28271=1000272=2014061037016=2014061037017=83:85:2737=80531942756288=114290=6
10:28:38.544: 658456 - 81 - 1128=935=X34=65845652=20140610-13:28:38.55575=20140610268=1279=0269=122=8207=BVMF48=380965483=79522270=8.24273=83:85:54271=100272=2014061037016=2014061037017=83:85:5437=80531942757289=8290=16
10:28:38.594: 658457 - 80 - 1128=935=X34=65845752=20140610-13:28:38.60575=20140610268=1279=0269=022=8207=BVMF48=380566083=11402270=2.38273=83:86:04271=100272=2014061037016=2014061037017=83:86:0437=80531942758288=72290=46
10:28:38.596: 658458 - 79 - 1128=935=X34=65845852=20140610-13:28:38.60775=20140610268=1279=0269=022=8207=BVMF48=394036883=1648270=2.38273=83:86:07271=40272=2014061037016=2014061037017=83:86:0637=80531942759288=72290=5
10:28:38.596: 658459 - 80 - 1128=935=X34=65845952=20140610-13:28:38.60775=20140610268=1279=0269=122=8207=BVMF48=400218483=3611270=29.71273=83:86:07271=23272=2014061037016=2014061037017=83:86:0737=80531942760289=72290=1
10:28:38.825: 658460 - 117 - 1128=935=X34=65846052=20140610-13:28:38.83675=20140610268=2279=2269=122=8207=BVMF48=400218483=3612273=83:88:35272=2014061037=80531919372289=3290=2279=0269=122=8207=BVMF48=400218483=3613270=29.7273=83:88:35271=95272=2014061037016=2014061037017=83:88:3537=80531942761289=3290=1
10:28:39.118: 658461 - 72 - 1128=935=X34=65846152=20140610-13:28:39.12975=20140610268=1279=2269=122=8207=BVMF48=380249383=103488273=83:91:28272=2014061037=80531942281289=16290=55
10:28:39.145: 658462 - 81 - 1128=935=X34=65846252=20140610-13:28:39.15675=20140610268=1279=0269=122=8207=BVMF48=380249383=103489270=9.36273=83:91:55271=100272=2014061037016=2014061037017=83:91:5537=80531942763289=8290=12
10:28:39.654: 658463 - 120 - 1128=935=X34=65846352=20140610-13:28:39.66575=20140610268=2279=2269=122=8207=BVMF48=380963983=255791273=83:96:64272=2014061037=80531941190289=27290=8279=0269=122=8207=BVMF48=380963983=255792270=26.4273=83:96:64271=300272=2014061037016=2014061037017=83:96:6437=80531942767289=27290=5
10:28:39.661: 658464 - 118 - 1128=935=X34=65846452=20140610-13:28:39.67275=20140610268=2279=2269=022=8207=BVMF48=380249383=103490273=83:96:71272=2014061037=80531941400288=40290=7279=0269=022=8207=BVMF48=380249383=103491270=9.34273=83:96:71271=100272=2014061037016=2014061037017=83:96:7137=80531942768288=40290=5
10:28:39.939: 658465 - 83 - 1128=935=X34=65846552=20140610-13:28:39.95075=20140610268=1279=0269=122=8207=BVMF48=380249383=103492270=9.45273=83:99:49271=11600272=2014061037016=2014061037017=83:99:4937=80531942772289=16290=53
10:28:40.256: 658466 - 71 - 1128=935=X34=65846652=20140610-13:28:40.26775=20140610268=1279=2269=022=8207=BVMF48=380249383=103493273=84:02:66272=2014061037=80531938521288=16290=38
10:28:40.865: 658467 - 80 - 1128=935=X34=65846752=20140610-13:28:40.87675=20140610268=1279=0269=022=8207=BVMF48=380963983=255793270=26.39273=84:08:75271=600272=2014061037016=2014061037017=84:08:7537=80531942803288=3290=6
10:28:40.880: 658468 - 72 - 1128=935=X34=65846852=20140610-13:28:40.89175=20140610268=1279=2269=122=8207=BVMF48=380963983=255794273=84:08:90272=2014061037=80531942131289=45290=15
10:28:40.893: 658469 - 80 - 1128=935=X34=65846952=20140610-13:28:40.90475=20140610268=1279=0269=022=8207=BVMF48=380963983=255795270=26.39273=84:09:04271=600272=2014061037016=2014061037017=84:09:0437=80531942828288=3290=7
10:28:40.944: 658470 - 70 - 1128=935=X34=65847052=20140610-13:28:40.95575=20140610268=1279=2269=022=8207=BVMF48=380963983=255796273=84:09:54272=2014061037=80531942828288=3290=7
10:28:40.959: 658471 - 70 - 1128=935=X34=65847152=20140610-13:28:40.97075=20140610268=1279=2269=022=8207=BVMF48=380963983=255797273=84:09:69272=2014061037=80531942803288=3290=6
10:28:41.070: 658472 - 83 - 1128=935=X34=65847252=20140610-13:28:41.08175=20140610268=1279=0269=022=8207=BVMF48=380249383=103494270=9.3273=84:10:81271=18800272=2014061037016=2014061037017=84:10:8037=80531942850288=16290=31
10:28:41.081: 658473 - 82 - 1128=935=X34=65847352=20140610-13:28:41.09275=20140610268=1279=0269=122=8207=BVMF48=380963983=255798270=26.43273=84:10:91271=5000272=2014061037016=2014061037017=84:10:9137=80531942851289=45290=17
10:28:41.184: 658474 - 437 - 1128=935=X34=65847452=20140610-13:28:41.19475=20140610268=11279=0269=222=8207=BVMF48=380968883=253407270=29.39273=84:11:94271=4000272=2014061037016=2014061037017=84:11:931500=E451=-0.241020=443500274=01003=6390288=72289=45279=0269=922=8207=BVMF48=380968883=253408270=29.479273=84:11:94272=201406101500=E279=0269=222=8207=BVMF48=380968883=253409270=29.39273=84:11:94271=300272=2014061037016=2014061037017=84:11:931500=E451=-0.241020=443800274=1277=L1003=6400288=72289=8279=0269=922=8207=BVMF48=380968883=253410270=29.479273=84:11:94272=201406101500=E279=0269=222=8207=BVMF48=380968883=253411270=29.39273=84:11:94271=300272=2014061037016=2014061037017=84:11:931500=E451=-0.241020=444100274=1277=L1003=6410288=72289=45279=0269=922=8207=BVMF48=380968883=253412270=29.479273=84:11:94272=201406101500=E279=4269=122=8207=BVMF48=380968883=253413273=84:11:94272=20140610290=3279=0269=122=8207=BVMF48=380968883=253414270=29.39273=84:11:94271=5000272=2014061037016=2014061037017=84:11:9337=80531942856289=45290=1279=0269=222=8207=BVMF48=380968883=253415270=29.39273=84:11:94271=400272=2014061037016=2014061037017=84:11:931500=E451=-0.241020=444500274=1277=L1003=6420288=72289=45279=0269=922=8207=BVMF48=380968883=253416270=29.479273=84:11:94272=201406101500=E279=1269=122=8207=BVMF48=380968883=253417270=29.39273=84:11:94271=4600272=2014061037016=2014061037017=84:11:9337=80531942856289=45290=1
10:28:41.185: 658475 - 80 - 1128=935=X34=65847552=20140610-13:28:41.19675=20140610268=1279=0269=022=8207=BVMF48=380968883=253418270=29.34273=84:11:95271=100272=2014061037016=2014061037017=84:11:9537=80531942857288=8290=16
10:28:41.197: 658476 - 118 - 1128=935=X34=65847652=20140610-13:28:41.20875=20140610268=2279=2269=022=8207=BVMF48=380968883=253419273=84:12:07272=2014061037=80531942726288=45290=5279=0269=022=8207=BVMF48=380968883=253420270=29.38273=84:12:07271=700272=2014061037016=2014061037017=84:12:0737=80531942858288=45290=3
10:28:41.204: 658477 - 83 - 1128=935=X34=65847752=20140610-13:28:41.21475=20140610268=1279=0269=122=8207=BVMF48=380968883=253421270=29.4273=84:12:14271=5000272=2014061037016=2014061037017=84:12:1437=80531942859289=45290=5
10:28:41.309: 658478 - 118 - 1128=935=X34=65847852=20140610-13:28:41.31975=20140610268=2279=2269=022=8207=BVMF48=380394783=65763273=84:13:19272=2014061037=80531931826288=45290=6279=0269=022=8207=BVMF48=380394783=65764270=17.02273=84:13:19271=1000272=2014061037016=2014061037017=84:13:1937=80531942861288=45290=5
10:28:41.344: 658479 - 80 - 1128=935=X34=65847952=20140610-13:28:41.35575=20140610268=1279=0269=022=8207=BVMF48=380394783=65765270=17273=84:13:54271=100272=2014061037016=2014061037017=84:13:5437=80531942862288=8290=7
10:28:41.440: 658480 - 82 - 1128=935=X34=65848052=20140610-13:28:41.45175=20140610268=1279=0269=122=8207=BVMF48=380968883=253422270=29.39273=84:14:50271=200272=2014061037016=2014061037017=84:14:5037=80531942863289=77290=2
10:28:41.718: 658481 - 158 - 1128=935=X34=65848152=20140610-13:28:41.72975=20140610268=3279=0269=222=8207=BVMF48=380968883=253423270=29.39273=84:17:28271=1600272=2014061037016=2014061037017=84:17:281500=E451=-0.241020=446100274=1277=L1003=6430288=227289=45279=0269=922=8207=BVMF48=380968883=253424270=29.479273=84:17:28272=201406101500=E279=1269=122=8207=BVMF48=380968883=253425270=29.39273=84:17:28271=3000272=2014061037016=2014061037017=84:11:9337=80531942856289=45290=1
10:28:41.805: 658482 - 71 - 1128=935=X34=65848252=20140610-13:28:41.81675=20140610268=1279=2269=122=8207=BVMF48=380968883=253426273=84:18:15272=2014061037=80531933493289=8290=32
10:28:41.811: 658483 - 70 - 1128=935=X34=65848352=20140610-13:28:41.82275=20140610268=1279=2269=022=8207=BVMF48=380391383=106173273=84:18:21272=2014061037=80531942749288=8290=3
10:28:41.812: 658484 - 81 - 1128=935=X34=65848452=20140610-13:28:41.82375=20140610268=1279=0269=122=8207=BVMF48=380968883=253427270=29.39273=84:18:22271=300272=2014061037016=2014061037017=84:18:2237=80531942865289=8290=3
10:28:41.824: 658485 - 119 - 1128=935=X34=65848552=20140610-13:28:41.83575=20140610268=2279=2269=122=8207=BVMF48=380968883=253428273=84:18:34272=2014061037=80531942859289=45290=7279=0269=122=8207=BVMF48=380968883=253429270=29.39273=84:18:34271=300272=2014061037016=2014061037017=84:18:3437=80531942866289=45290=4
10:28:41.826: 658486 - 65 - 1128=935=X34=65848652=20140610-13:28:41.83775=20140610268=1279=0269=B22=8207=BVMF48=380968883=253430270=13103349273=84:18:38271=642272=201406101500=E15=BRL
10:28:41.828: 658487 - 65 - 1128=935=X34=65848752=20140610-13:28:41.83975=20140610268=1279=0269=B22=8207=BVMF48=380963983=255799270=37187501273=84:18:38271=1893272=201406101500=E15=BRL
10:28:41.832: 658488 - 61 - 1128=935=X34=65848852=20140610-13:28:41.84375=20140610268=1279=0269=B22=8207=BVMF48=386389183=34270=38041.02273=84:18:38271=6272=201406101500=E15=BRL
10:28:41.835: 658489 - 62 - 1128=935=X34=65848952=20140610-13:28:41.84675=20140610268=1279=0269=B22=8207=BVMF48=400223483=5871270=17389.96273=84:18:38271=37272=201406101500=E15=BRL
10:28:41.841: 658490 - 65 - 1128=935=X34=65849052=20140610-13:28:41.85275=20140610268=1279=0269=B22=8207=BVMF48=380391383=106174270=1501557273=84:18:38271=334272=201406101500=E15=BRL
10:28:41.846: 658491 - 71 - 1128=935=X34=65849152=20140610-13:28:41.85775=20140610268=1279=2269=122=8207=BVMF48=380391383=106175273=84:18:56272=2014061037=80531931613289=3290=3
10:28:41.857: 658492 - 65 - 1128=935=X34=65849252=20140610-13:28:41.86875=20140610268=1279=0269=B22=8207=BVMF48=380249383=103495270=2445711273=84:18:38271=368272=201406101500=E15=BRL
10:28:41.889: 658493 - 65 - 1128=935=X34=65849352=20140610-13:28:41.90075=20140610268=1279=0269=B22=8207=BVMF48=380965483=79523270=1926941273=84:18:38271=296272=201406101500=E15=BRL
10:28:42.145: 658494 - 71 - 1128=935=X34=65849452=20140610-13:28:42.15575=20140610268=1279=2269=122=8207=BVMF48=380249383=103496273=84:21:55272=2014061037=80531942763289=8290=12
10:28:42.145: 658495 - 70 - 1128=935=X34=65849552=20140610-13:28:42.15575=20140610268=1279=2269=022=8207=BVMF48=380394783=65766273=84:21:55272=2014061037=80531942862288=8290=7
10:28:43.424: 658496 - 81 - 1128=935=X34=65849652=20140610-13:28:43.43575=20140610268=1279=0269=122=8207=BVMF48=400223483=5872270=27273=84:34:35271=84272=2014061037016=2014061037017=84:34:3537=80531942871289=98290=21
10:28:43.548: 658497 - 70 - 1128=935=X34=65849752=20140610-13:28:43.55975=20140610268=1279=2269=122=8207=BVMF48=380653683=6225273=84:35:58272=2014061037=80531926237289=8290=9
10:28:43.684: 658498 - 72 - 1128=935=X34=65849852=20140610-13:28:43.69575=20140610268=1279=2269=022=8207=BVMF48=380968883=253431273=84:36:95272=2014061037=80531939698288=227290=7
10:28:43.684: 658499 - 82 - 1128=935=X34=65849952=20140610-13:28:43.69575=20140610268=1279=0269=022=8207=BVMF48=380968883=253432270=29.32273=84:36:95271=1000272=2014061037016=2014061037017=84:36:9537=80531942872288=227290=23
10:28:43.950: 658500 - 71 - 1128=935=X34=65850052=20140610-13:28:43.96175=20140610268=1279=2269=122=8207=BVMF48=380391383=106176273=84:39:60272=2014061037=80531939863289=8290=4
10:28:44.555: 658501 - 119 - 1128=935=X34=65850152=20140610-13:28:44.56675=20140610268=2279=2269=122=8207=BVMF48=380394783=65767273=84:45:65272=2014061037=80531942226289=40290=10279=0269=122=8207=BVMF48=380394783=65768270=17.05273=84:45:65271=100272=2014061037016=2014061037017=84:45:6537=80531942874289=40290=6
10:28:45.635: 658502 - 83 - 1128=935=X34=65850252=20140610-13:28:45.64675=20140610268=1279=0269=022=8207=BVMF48=380963983=255800270=25.9273=84:56:46271=100272=2014061037016=2014061037017=84:56:4637=80531942875288=21290=166
10:28:45.640: 658503 - 70 - 1128=935=X34=65850352=20140610-13:28:45.65175=20140610268=1279=2269=022=8207=BVMF48=380963983=255801273=84:56:50272=2014061037=80531942415288=3290=2
10:28:46.660: 658504 - 82 - 1128=935=X34=65850452=20140610-13:28:46.67175=20140610268=1279=0269=122=8207=BVMF48=380968883=253433270=29.39273=84:66:70271=300272=2014061037016=2014061037017=84:66:7037=80531942879289=77290=5
10:28:47.086: 658505 - 162 - 1128=935=X34=65850552=20140610-13:28:47.09875=20140610268=3279=0269=222=8207=BVMF48=380963983=255802270=26.4273=84:70:97271=100272=2014061037016=2014061037017=84:70:971500=E451=-0.211020=1405000274=1277=L1003=18940288=735289=85279=0269=922=8207=BVMF48=380963983=255803270=26.47273=84:70:97272=201406101500=E279=1269=122=8207=BVMF48=380963983=255804270=26.4273=84:70:97271=4200272=2014061037016=2014061037017=83:31:6237=80531942464289=85290=1
10:28:47.230: 658506 - 119 - 1128=935=X34=65850652=20140610-13:28:47.24175=20140610268=2279=2269=122=8207=BVMF48=380394783=65769273=84:72:41272=2014061037=80531942609289=23290=7279=0269=122=8207=BVMF48=380394783=65770270=17.05273=84:72:41271=100272=2014061037016=2014061037017=84:72:4037=80531942881289=23290=7
10:28:50.784: 658507 - 81 - 1128=935=X34=65850752=20140610-13:28:50.79675=20140610268=1279=0269=022=8207=BVMF48=380965483=79524270=8.18273=85:07:95271=1000272=2014061037016=2014061037017=85:07:9537=80531942926288=72290=24
10:28:51.096: 658508 - 72 - 1128=935=X34=65850852=20140610-13:28:51.10775=20140610268=1279=2269=122=8207=BVMF48=380968883=253434273=85:11:06272=2014061037=80531893444289=72290=54
10:28:51.417: 658509 - 148 - 1128=935=X34=65850952=20140610-13:28:51.42975=20140610268=3279=0269=222=8207=BVMF48=380965483=79525270=8.21273=85:14:28271=3500272=2014061037016=2014061037017=85:14:281500=E451=-0.071020=237100274=21003=2970288=227289=735279=0269=922=8207=BVMF48=380965483=79526270=8.248273=85:14:28272=201406101500=E279=2269=022=8207=BVMF48=380965483=79527273=85:14:28272=2014061037=80531941210288=227290=1
10:28:51.508: 658510 - 81 - 1128=935=X34=65851052=20140610-13:28:51.51975=20140610268=1279=0269=022=8207=BVMF48=380249383=103497270=9.34273=85:15:19271=100272=2014061037016=2014061037017=85:15:1937=80531942936288=40290=6
10:28:52.145: 658511 - 71 - 1128=935=X34=65851152=20140610-13:28:52.15675=20140610268=1279=2269=122=8207=BVMF48=380963983=255805273=85:21:55272=2014061037=80531941611289=8290=42
10:28:52.592: 658512 - 71 - 1128=935=X34=65851252=20140610-13:28:52.60475=20140610268=1279=2269=122=8207=BVMF48=380249383=103498273=85:26:03272=2014061037=80531942330289=8290=7
10:28:53.369: 658513 - 119 - 1128=935=X34=65851352=20140610-13:28:53.38075=20140610268=2279=2269=022=8207=BVMF48=380653683=6226273=85:33:80272=2014061037=80531878526288=114290=6279=0269=022=8207=BVMF48=380653683=6227270=3.11273=85:33:80271=600272=2014061037016=2014061037017=85:33:7937=80531942995288=114290=5
10:28:53.401: 658514 - 84 - 1128=935=X34=65851452=20140610-13:28:53.41375=20140610268=1279=0269=122=8207=BVMF48=380963983=255806270=26.4273=85:34:12271=200272=2014061037016=2014061037017=85:34:1237=80531942998289=238290=6
10:28:53.414: 658515 - 80 - 1128=935=X34=65851552=20140610-13:28:53.42675=20140610268=1279=0269=022=8207=BVMF48=380963983=255807270=26.39273=85:34:25271=300272=2014061037016=2014061037017=85:34:2537=80531943003288=3290=5
10:28:53.958: 658516 - 119 - 1128=935=X34=65851652=20140610-13:28:53.96975=20140610268=2279=2269=122=8207=BVMF48=380968883=253435273=85:39:69272=2014061037=80531938531289=13290=8279=0269=122=8207=BVMF48=380968883=253436270=29.39273=85:39:69271=1300272=2014061037016=2014061037017=85:39:6937=80531943007289=13290=6
10:28:54.144: 658517 - 70 - 1128=935=X34=65851752=20140610-13:28:54.15675=20140610268=1279=2269=022=8207=BVMF48=380968883=253437273=85:41:55272=2014061037=80531942857288=8290=15
10:28:54.324: 658518 - 83 - 1128=935=X34=65851852=20140610-13:28:54.33575=20140610268=1279=0269=022=8207=BVMF48=380963983=255808270=25.9273=85:43:35271=100272=2014061037016=2014061037017=85:43:3537=80531943012288=21290=167
10:28:54.374: 658519 - 81 - 1128=935=X34=65851952=20140610-13:28:54.38575=20140610268=1279=0269=022=8207=BVMF48=380965483=79528270=8.21273=85:43:84271=1200272=2014061037016=2014061037017=85:43:8437=80531943013288=90290=4
10:28:54.950: 658520 - 71 - 1128=935=X34=65852052=20140610-13:28:54.96175=20140610268=1279=2269=122=8207=BVMF48=380963983=255809273=85:49:60272=2014061037=80531940501289=8290=15
10:28:55.090: 658521 - 80 - 1128=935=X34=65852152=20140610-13:28:55.10175=20140610268=1279=0269=022=8207=BVMF48=380963983=255810270=26.39273=85:51:00271=100272=2014061037016=2014061037017=85:51:0037=80531943020288=8290=6
10:28:55.678: 658522 - 972 - 1128=935=X34=65852252=20140610-13:28:55.68975=20140610268=27279=0269=222=8207=BVMF48=380965483=79529270=8.21273=85:56:87271=1000272=2014061037016=2014061037017=85:56:861500=E451=-0.071020=238100274=3277=L1003=2980288=114289=8279=0269=922=8207=BVMF48=380965483=79530270=8.248273=85:56:87272=201406101500=E279=0269=222=8207=BVMF48=380965483=79531270=8.21273=85:56:87271=100272=2014061037016=2014061037017=85:56:861500=E451=-0.071020=238200274=3277=L1003=2990288=40289=8279=0269=922=8207=BVMF48=380965483=79532270=8.248273=85:56:87272=201406101500=E279=0269=222=8207=BVMF48=380965483=79533270=8.21273=85:56:87271=200272=2014061037016=2014061037017=85:56:861500=E451=-0.071020=238400274=3277=L1003=3000288=40289=8279=0269=922=8207=BVMF48=380965483=79534270=8.248273=85:56:87272=201406101500=E279=0269=222=8207=BVMF48=380965483=79535270=8.21273=85:56:87271=1200272=2014061037016=2014061037017=85:56:861500=E451=-0.071020=239600274=3277=L1003=3010288=90289=8279=0269=922=8207=BVMF48=380965483=79536270=8.248273=85:56:87272=201406101500=E279=0269=222=8207=BVMF48=380965483=79537270=8.2273=85:56:87271=800272=2014061037016=2014061037017=85:56:861500=E451=-0.081020=240400274=21003=3020288=27289=8279=0269=922=8207=BVMF48=380965483=79538270=8.248273=85:56:87272=201406101500=E279=0269=222=8207=BVMF48=380965483=79539270=8.2273=85:56:87271=1000272=2014061037016=2014061037017=85:56:861500=E451=-0.081020=241400274=3277=L1003=3030288=114289=8279=0269=922=8207=BVMF48=380965483=79540270=8.248273=85:56:87272=201406101500=E279=0269=222=8207=BVMF48=380965483=79541270=8.19273=85:56:87271=1200272=2014061037016=2014061037017=85:56:861500=E451=-0.091020=242600274=21003=3040288=262289=8279=0269=822=8207=BVMF48=380965483=79542270=8.19273=85:56:87272=201406101500=E279=0269=922=8207=BVMF48=380965483=79543270=8.247273=85:56:87272=201406101500=E279=0269=222=8207=BVMF48=380965483=79544270=8.19273=85:56:87271=100272=2014061037016=2014061037017=85:56:861500=E451=-0.091020=242700274=3277=L1003=3050288=72289=8279=0269=922=8207=BVMF48=380965483=79545270=8.247273=85:56:87272=201406101500=E279=0269=222=8207=BVMF48=380965483=79546270=8.19273=85:56:87271=900272=2014061037016=2014061037017=85:56:861500=E451=-0.091020=243600274=3277=L1003=3060288=3289=8279=0269=922=8207=BVMF48=380965483=79547270=8.247273=85:56:87272=201406101500=E279=0269=222=8207=BVMF48=380965483=79548270=8.19273=85:56:87271=500272=2014061037016=2014061037017=85:56:861500=E451=-0.091020=244100274=3277=L1003=3070288=8289=8279=0269=922=8207=BVMF48=380965483=79549270=8.247273=85:56:87272=201406101500=E279=0269=222=8207=BVMF48=380965483=79550270=8.19273=85:56:87271=2500272=2014061037016=2014061037017=85:56:861500=E451=-0.091020=246600274=3277=L1003=3080288=386289=8279=0269=922=8207=BVMF48=380965483=79551270=8.246273=85:56:87272=201406101500=E279=0269=222=8207=BVMF48=380965483=79552270=8.19273=85:56:87271=500272=2014061037016=2014061037017=85:56:861500=E451=-0.091020=247100274=3277=L1003=3090288=8289=8279=0269=922=8207=BVMF48=380965483=79553270=8.246273=85:56:87272=201406101500=E279=4269=022=8207=BVMF48=380965483=79554273=85:56:87272=20140610290=11279=1269=022=8207=BVMF48=380965483=79555270=8.19273=85:56:87271=300272=2014061037016=2014061037017=71:86:1037=80531939039288=8290=1
10:28:55.679: 658523 - 70 - 1128=935=X34=65852352=20140610-13:28:55.69175=20140610268=1279=2269=022=8207=BVMF48=380965483=79556273=85:56:90272=2014061037=80531940148288=8290=12
10:28:55.679: 658524 - 81 - 1128=935=X34=65852452=20140610-13:28:55.69175=20140610268=1279=0269=122=8207=BVMF48=380965483=79557270=8.22273=85:56:90271=100272=2014061037016=2014061037017=85:56:9037=80531943024289=8290=8
10:28:55.680: 658525 - 80 - 1128=935=X34=65852552=20140610-13:28:55.69175=20140610268=1279=0269=022=8207=BVMF48=380965483=79558270=8.19273=85:56:90271=100272=2014061037016=2014061037017=85:56:9037=80531943025288=8290=2
10:28:55.680: 658526 - 71 - 1128=935=X34=65852652=20140610-13:28:55.69175=20140610268=1279=2269=122=8207=BVMF48=380965483=79559273=85:56:91272=2014061037=80531943024289=8290=8
10:28:55.680: 658527 - 70 - 1128=935=X34=65852752=20140610-13:28:55.69275=20140610268=1279=2269=022=8207=BVMF48=380965483=79560273=85:56:91272=2014061037=80531943025288=8290=2
10:28:55.680: 658528 - 80 - 1128=935=X34=65852852=20140610-13:28:55.69275=20140610268=1279=0269=022=8207=BVMF48=380965483=79561270=8.19273=85:56:91271=600272=2014061037016=2014061037017=85:56:9137=80531943026288=3290=2
10:28:55.681: 658529 - 81 - 1128=935=X34=65852952=20140610-13:28:55.69275=20140610268=1279=0269=122=8207=BVMF48=380965483=79562270=8.22273=85:56:92271=100272=2014061037016=2014061037017=85:56:9237=80531943027289=8290=8
10:28:55.681: 658530 - 71 - 1128=935=X34=65853052=20140610-13:28:55.69375=20140610268=1279=2269=122=8207=BVMF48=380965483=79563273=85:56:92272=2014061037=80531943027289=8290=8
10:28:55.729: 658531 - 82 - 1128=935=X34=65853152=20140610-13:28:55.74075=20140610268=1279=0269=022=8207=BVMF48=380965483=79564270=8.18273=85:57:40271=100272=2014061037016=2014061037017=85:57:4037=80531943105288=735290=14
10:28:55.743: 658532 - 80 - 1128=935=X34=65853252=20140610-13:28:55.75575=20140610268=1279=0269=022=8207=BVMF48=380965483=79565270=8.18273=85:57:55271=100272=2014061037016=2014061037017=85:57:5437=80531943112288=8290=15
10:28:55.834: 658533 - 483 - 1128=935=X34=65853352=20140610-13:28:55.84675=20140610268=13279=0269=222=8207=BVMF48=380965483=79566270=8.19273=85:58:45271=300272=2014061037016=2014061037017=85:58:441500=E451=-0.091020=247400274=3277=L1003=3100288=8289=86279=0269=922=8207=BVMF48=380965483=79567270=8.246273=85:58:45272=201406101500=E279=0269=222=8207=BVMF48=380965483=79568270=8.19273=85:58:45271=600272=2014061037016=2014061037017=85:58:441500=E451=-0.091020=248000274=3277=L1003=3110288=3289=86279=0269=922=8207=BVMF48=380965483=79569270=8.246273=85:58:45272=201406101500=E279=0269=222=8207=BVMF48=380965483=79570270=8.18273=85:58:45271=500272=2014061037016=2014061037017=85:58:441500=E451=-0.11020=248500274=21003=3120288=3289=86279=0269=822=8207=BVMF48=380965483=79571270=8.18273=85:58:45272=201406101500=E279=0269=922=8207=BVMF48=380965483=79572270=8.246273=85:58:45272=201406101500=E279=0269=222=8207=BVMF48=380965483=79573270=8.18273=85:58:45271=400272=2014061037016=2014061037017=85:58:441500=E451=-0.11020=248900274=3277=L1003=3130288=58289=86279=0269=922=8207=BVMF48=380965483=79574270=8.246273=85:58:45272=201406101500=E279=0269=222=8207=BVMF48=380965483=79575270=8.18273=85:58:45271=700272=2014061037016=2014061037017=85:58:441500=E451=-0.11020=249600274=3277=L1003=3140288=77289=86279=0269=922=8207=BVMF48=380965483=79576270=8.246273=85:58:45272=201406101500=E279=4269=022=8207=BVMF48=380965483=79577273=85:58:45272=20140610290=4279=1269=022=8207=BVMF48=380965483=79578270=8.18273=85:58:45271=9300272=2014061037016=2014061037017=50:71:7737=80531856537288=77290=1
10:28:55.836: 658534 - 221 - 1128=935=X34=65853452=20140610-13:28:55.84775=20140610268=6279=0269=222=8207=BVMF48=380977983=20198270=7.37273=85:58:47271=300272=2014061037016=2014061037017=85:58:461500=E451=-0.081020=43500274=21003=880288=262289=3279=0269=822=8207=BVMF48=380977983=20199270=7.37273=85:58:47272=201406101500=E279=0269=922=8207=BVMF48=380977983=20200270=7.426273=85:58:47272=201406101500=E279=0269=222=8207=BVMF48=380977983=20201270=7.37273=85:58:47271=300272=2014061037016=2014061037017=85:58:461500=E451=-0.081020=43800274=3277=L1003=890288=58289=3279=0269=922=8207=BVMF48=380977983=20202270=7.426273=85:58:47272=201406101500=E279=4269=022=8207=BVMF48=380977983=20203273=85:58:47272=20140610290=2
10:28:55.836: 658535 - 80 - 1128=935=X34=65853552=20140610-13:28:55.84875=20140610268=1279=0269=022=8207=BVMF48=380965483=79579270=8.18273=85:58:47271=100272=2014061037016=2014061037017=85:58:4737=80531943128288=8290=12
10:28:55.836: 658536 - 80 - 1128=935=X34=65853652=20140610-13:28:55.84875=20140610268=1279=0269=022=8207=BVMF48=380965483=79580270=8.19273=85:58:47271=700272=2014061037016=2014061037017=85:58:4737=80531943129288=8290=1
10:28:55.837: 658537 - 80 - 1128=935=X34=65853752=20140610-13:28:55.84875=20140610268=1279=0269=022=8207=BVMF48=380965483=79581270=8.18273=85:58:48271=600272=2014061037016=2014061037017=85:58:4837=80531943135288=3290=14
10:28:55.838: 658538 - 70 - 1128=935=X34=65853852=20140610-13:28:55.84975=20140610268=1279=2269=022=8207=BVMF48=380977983=20204273=85:58:49272=2014061037=80531932408288=8290=1
10:28:55.838: 658539 - 81 - 1128=935=X34=65853952=20140610-13:28:55.84975=20140610268=1279=0269=122=8207=BVMF48=380977983=20205270=7.38273=85:58:49271=800272=2014061037016=2014061037017=85:58:4937=80531943144289=8290=1
10:28:55.838: 658540 - 70 - 1128=935=X34=65854052=20140610-13:28:55.85075=20140610268=1279=2269=022=8207=BVMF48=380965483=79582273=85:58:49272=2014061037=80531943135288=3290=14
10:28:55.839: 658541 - 80 - 1128=935=X34=65854152=20140610-13:28:55.85075=20140610268=1279=0269=022=8207=BVMF48=380977983=20206270=7.36273=85:58:50271=100272=2014061037016=2014061037017=85:58:5037=80531943153288=8290=2
10:28:55.839: 658542 - 80 - 1128=935=X34=65854252=20140610-13:28:55.85175=20140610268=1279=0269=022=8207=BVMF48=380977983=20207270=7.36273=85:58:50271=100272=2014061037016=2014061037017=85:58:5037=80531943155288=8290=3
10:28:55.840: 658543 - 117 - 1128=935=X34=65854352=20140610-13:28:55.85175=20140610268=2279=2269=122=8207=BVMF48=380977983=20208273=85:58:51272=2014061037=80531935246289=8290=3279=0269=122=8207=BVMF48=380977983=20209270=7.38273=85:58:51271=200272=2014061037016=2014061037017=85:58:5037=80531943158289=8290=2
10:28:55.840: 658544 - 71 - 1128=935=X34=65854452=20140610-13:28:55.85175=20140610268=1279=2269=122=8207=BVMF48=380977983=20210273=85:58:51272=2014061037=80531940008289=3290=4
10:28:55.848: 658545 - 118 - 1128=935=X34=65854552=20140610-13:28:55.86075=20140610268=2279=2269=022=8207=BVMF48=399692383=862273=85:58:59272=2014061037=80531925526288=110290=1279=0269=022=8207=BVMF48=399692383=863270=7.31273=85:58:59271=5272=2014061037016=2014061037017=85:58:5937=80531943187288=110290=1
10:28:55.849: 658546 - 81 - 1128=935=X34=65854652=20140610-13:28:55.86175=20140610268=1279=0269=122=8207=BVMF48=380977983=20211270=7.39273=85:58:60271=100272=2014061037016=2014061037017=85:58:6037=80531943188289=8290=4
10:28:55.850: 658547 - 80 - 1128=935=X34=65854752=20140610-13:28:55.86175=20140610268=1279=0269=022=8207=BVMF48=380977983=20212270=7.37273=85:58:61271=100272=2014061037016=2014061037017=85:58:6037=80531943189288=8290=1
10:28:55.850: 658548 - 71 - 1128=935=X34=65854852=20140610-13:28:55.86175=20140610268=1279=2269=122=8207=BVMF48=380977983=20213273=85:58:61272=2014061037=80531943188289=8290=4
10:28:55.850: 658549 - 70 - 1128=935=X34=65854952=20140610-13:28:55.86175=20140610268=1279=2269=022=8207=BVMF48=380977983=20214273=85:58:61272=2014061037=80531943189288=8290=1
10:28:55.851: 658550 - 115 - 1128=935=X34=65855052=20140610-13:28:55.86275=20140610268=2279=2269=022=8207=BVMF48=399729383=2274273=85:58:62272=2014061037=80531941322288=3290=1279=0269=022=8207=BVMF48=399729383=2275270=8.15273=85:58:62271=96272=2014061037016=2014061037017=85:58:6137=80531943190288=3290=2
10:28:55.861: 658551 - 71 - 1128=935=X34=65855152=20140610-13:28:55.87275=20140610268=1279=2269=122=8207=BVMF48=380977983=20215273=85:58:72272=2014061037=80531866841289=8290=27
10:28:55.861: 658552 - 81 - 1128=935=X34=65855252=20140610-13:28:55.87275=20140610268=1279=0269=122=8207=BVMF48=380977983=20216270=7.41273=85:58:72271=500272=2014061037016=2014061037017=85:58:7237=80531943192289=8290=8
10:28:55.866: 658553 - 72 - 1128=935=X34=65855352=20140610-13:28:55.87875=20140610268=1279=2269=122=8207=BVMF48=380965483=79583273=85:58:77272=2014061037=80531924753289=40290=57
10:28:55.867: 658554 - 71 - 1128=935=X34=65855452=20140610-13:28:55.87975=20140610268=1279=2269=022=8207=BVMF48=380965483=79584273=85:58:78272=2014061037=80531924754288=40290=27
10:28:55.870: 658555 - 72 - 1128=935=X34=65855552=20140610-13:28:55.88175=20140610268=1279=2269=022=8207=BVMF48=380965483=79585273=85:58:81272=2014061037=80531943105288=735290=11
10:28:55.889: 658556 - 71 - 1128=935=X34=65855652=20140610-13:28:55.90175=20140610268=1279=2269=122=8207=BVMF48=380977983=20217273=85:59:00272=2014061037=80531925539289=8290=18
10:28:55.890: 658557 - 71 - 1128=935=X34=65855752=20140610-13:28:55.90175=20140610268=1279=2269=122=8207=BVMF48=380977983=20218273=85:59:01272=2014061037=80531925538289=8290=23
10:28:55.890: 658558 - 70 - 1128=935=X34=65855852=20140610-13:28:55.90175=20140610268=1279=2269=022=8207=BVMF48=380977983=20219273=85:59:01272=2014061037=80531925541288=8290=14
10:28:55.890: 658559 - 70 - 1128=935=X34=65855952=20140610-13:28:55.90175=20140610268=1279=2269=022=8207=BVMF48=380977983=20220273=85:59:01272=2014061037=80531925540288=8290=7
10:28:55.891: 658560 - 81 - 1128=935=X34=65856052=20140610-13:28:55.90375=20140610268=1279=0269=122=8207=BVMF48=380977983=20221270=7.46273=85:59:02271=500272=2014061037016=2014061037017=85:59:0237=80531943193289=8290=19
10:28:55.891: 658561 - 81 - 1128=935=X34=65856152=20140610-13:28:55.90375=20140610268=1279=0269=122=8207=BVMF48=380977983=20222270=7.44273=85:59:03271=600272=2014061037016=2014061037017=85:59:0237=80531943194289=8290=14
10:28:55.892: 658562 - 80 - 1128=935=X34=65856252=20140610-13:28:55.90475=20140610268=1279=0269=022=8207=BVMF48=380977983=20223270=7.33273=85:59:03271=600272=2014061037016=2014061037017=85:59:0337=80531943195288=8290=13
10:28:55.892: 658563 - 81 - 1128=935=X34=65856352=20140610-13:28:55.90475=20140610268=1279=0269=022=8207=BVMF48=380977983=20224270=7.3273=85:59:03271=500272=2014061037016=2014061037017=85:59:0337=80531943196288=8290=20
10:28:55.919: 658564 - 81 - 1128=935=X34=65856452=20140610-13:28:55.93175=20140610268=1279=0269=122=8207=BVMF48=380965483=79586270=8.21273=85:59:30271=100272=2014061037016=2014061037017=85:59:3037=80531943197289=8290=1
10:28:55.920: 658565 - 71 - 1128=935=X34=65856552=20140610-13:28:55.93175=20140610268=1279=2269=122=8207=BVMF48=380965483=79587273=85:59:31272=2014061037=80531943197289=8290=1
10:28:55.920: 658566 - 81 - 1128=935=X34=65856652=20140610-13:28:55.93175=20140610268=1279=0269=122=8207=BVMF48=380977983=20225270=7.38273=85:59:31271=100272=2014061037016=2014061037017=85:59:3037=80531943198289=8290=3
10:28:55.920: 658567 - 71 - 1128=935=X34=65856752=20140610-13:28:55.93175=20140610268=1279=2269=122=8207=BVMF48=380977983=20226273=85:59:31272=2014061037=80531943198289=8290=3
10:28:55.921: 658568 - 81 - 1128=935=X34=65856852=20140610-13:28:55.93275=20140610268=1279=0269=122=8207=BVMF48=380965483=79588270=8.21273=85:59:32271=500272=2014061037016=2014061037017=85:59:3237=80531943199289=8290=1
10:28:55.921: 658569 - 80 - 1128=935=X34=65856952=20140610-13:28:55.93375=20140610268=1279=0269=022=8207=BVMF48=380977983=20227270=7.36273=85:59:32271=100272=2014061037016=2014061037017=85:59:3237=80531943201288=8290=4
10:28:55.921: 658570 - 70 - 1128=935=X34=65857052=20140610-13:28:55.93375=20140610268=1279=2269=022=8207=BVMF48=380977983=20228273=85:59:33272=2014061037=80531943201288=8290=4
10:28:55.923: 658571 - 81 - 1128=935=X34=65857152=20140610-13:28:55.93475=20140610268=1279=0269=122=8207=BVMF48=380965483=79589270=8.21273=85:59:34271=300272=2014061037016=2014061037017=85:59:3437=80531943214289=8290=2
10:28:55.950: 658572 - 81 - 1128=935=X34=65857252=20140610-13:28:55.96175=20140610268=1279=0269=122=8207=BVMF48=380965483=79590270=8.22273=85:59:60271=100272=2014061037016=2014061037017=85:59:6037=80531943221289=8290=10
10:28:55.958: 658573 - 82 - 1128=935=X34=65857352=20140610-13:28:55.97075=20140610268=1279=0269=122=8207=BVMF48=380965483=79591270=8.22273=85:59:69271=2600272=2014061037016=2014061037017=85:59:6937=80531943227289=40290=11
10:28:55.999: 658574 - 115 - 1128=935=X34=65857452=20140610-13:28:56.01075=20140610268=2279=2269=022=8207=BVMF48=399692383=864273=85:60:10272=2014061037=80531931548288=3290=2279=0269=022=8207=BVMF48=399692383=865270=7.32273=85:60:10271=88272=2014061037016=2014061037017=85:60:1037=80531943235288=3290=1
10:28:56.005: 658575 - 118 - 1128=935=X34=65857552=20140610-13:28:56.01775=20140610268=2279=2269=022=8207=BVMF48=399692383=866273=85:60:16272=2014061037=80531943187288=110290=2279=0269=022=8207=BVMF48=399692383=867270=7.33273=85:60:16271=5272=2014061037016=2014061037017=85:60:1637=80531943236288=110290=1
10:28:56.010: 658576 - 82 - 1128=935=X34=65857652=20140610-13:28:56.02275=20140610268=1279=0269=022=8207=BVMF48=380965483=79592270=8.14273=85:60:21271=13700272=2014061037016=2014061037017=85:60:2137=80531943237288=40290=52
10:28:56.012: 658577 - 83 - 1128=935=X34=65857752=20140610-13:28:56.02475=20140610268=1279=0269=122=8207=BVMF48=380965483=79593270=8.29273=85:60:23271=11200272=2014061037016=2014061037017=85:60:2337=80531943238289=40290=53
10:28:56.062: 658578 - 71 - 1128=935=X34=65857852=20140610-13:28:56.07375=20140610268=1279=2269=022=8207=BVMF48=380977983=20229273=85:60:73272=2014061037=80531925554288=40290=16
10:28:56.063: 658579 - 72 - 1128=935=X34=65857952=20140610-13:28:56.07575=20140610268=1279=2269=122=8207=BVMF48=380977983=20230273=85:60:74272=2014061037=80531925585289=40290=19
10:28:56.064: 658580 - 71 - 1128=935=X34=65858052=20140610-13:28:56.07675=20140610268=1279=2269=022=8207=BVMF48=380977983=20231273=85:60:75272=2014061037=80531925580288=40290=12
10:28:56.065: 658581 - 72 - 1128=935=X34=65858152=20140610-13:28:56.07775=20140610268=1279=2269=122=8207=BVMF48=380977983=20232273=85:60:76272=2014061037=80531925584289=40290=16
10:28:56.067: 658582 - 71 - 1128=935=X34=65858252=20140610-13:28:56.07875=20140610268=1279=2269=022=8207=BVMF48=380977983=20233273=85:60:78272=2014061037=80531925555288=40290=11
10:28:56.068: 658583 - 71 - 1128=935=X34=65858352=20140610-13:28:56.07975=20140610268=1279=2269=022=8207=BVMF48=380977983=20234273=85:60:79272=2014061037=80531925581288=40290=14
10:28:56.069: 658584 - 71 - 1128=935=X34=65858452=20140610-13:28:56.08075=20140610268=1279=2269=022=8207=BVMF48=380977983=20235273=85:60:80272=2014061037=80531925582288=40290=7
10:28:56.124: 658585 - 72 - 1128=935=X34=65858552=20140610-13:28:56.13675=20140610268=1279=2269=122=8207=BVMF48=380977983=20236273=85:61:36272=2014061037=80531925583289=40290=23
10:28:56.145: 658586 - 70 - 1128=935=X34=65858652=20140610-13:28:56.15675=20140610268=1279=2269=022=8207=BVMF48=380965483=79594273=85:61:55272=2014061037=80531943112288=8290=11
10:28:56.145: 658587 - 70 - 1128=935=X34=65858752=20140610-13:28:56.15775=20140610268=1279=2269=122=8207=BVMF48=380653683=6228273=85:61:56272=2014061037=80531940733289=8290=10
10:28:56.147: 658588 - 80 - 1128=935=X34=65858852=20140610-13:28:56.15875=20140610268=1279=0269=122=8207=BVMF48=380653683=6229270=3.15273=85:61:58271=100272=2014061037016=2014061037017=85:61:5737=80531943241289=8290=10
10:28:56.202: 658589 - 81 - 1128=935=X34=65858952=20140610-13:28:56.21375=20140610268=1279=0269=022=8207=BVMF48=380963983=255811270=26.39273=85:62:12271=100272=2014061037016=2014061037017=85:62:1237=80531943247288=74290=7
10:28:56.209: 658590 - 82 - 1128=935=X34=65859052=20140610-13:28:56.22175=20140610268=1279=0269=122=8207=BVMF48=380977983=20237270=7.44273=85:62:20271=800272=2014061037016=2014061037017=85:62:2037=80531943256289=40290=15
10:28:56.211: 658591 - 81 - 1128=935=X34=65859152=20140610-13:28:56.22375=20140610268=1279=0269=022=8207=BVMF48=380977983=20238270=7.31273=85:62:22271=700272=2014061037016=2014061037017=85:62:2237=80531943257288=40290=13
10:28:56.250: 658592 - 115 - 1128=935=X34=65859252=20140610-13:28:56.26275=20140610268=2279=2269=022=8207=BVMF48=399692383=868273=85:62:61272=2014061037=80531943235288=3290=2279=0269=022=8207=BVMF48=399692383=869270=7.34273=85:62:61271=88272=2014061037016=2014061037017=85:62:6137=80531943282288=3290=1
10:28:56.256: 658593 - 118 - 1128=935=X34=65859352=20140610-13:28:56.26775=20140610268=2279=2269=022=8207=BVMF48=399692383=870273=85:62:67272=2014061037=80531943236288=110290=2279=0269=022=8207=BVMF48=399692383=871270=7.35273=85:62:67271=5272=2014061037016=2014061037017=85:62:6737=80531943283288=110290=1
10:28:56.288: 658594 - 80 - 1128=935=X34=65859452=20140610-13:28:56.29975=20140610268=1279=0269=022=8207=BVMF48=380965483=79595270=8.19273=85:62:98271=200272=2014061037016=2014061037017=85:62:9837=80531943292288=9290=2
10:28:56.310: 658595 - 81 - 1128=935=X34=65859552=20140610-13:28:56.32275=20140610268=1279=0269=022=8207=BVMF48=380977983=20239270=7.31273=85:63:21271=500272=2014061037016=2014061037017=85:63:2137=80531943296288=40290=14
10:28:56.312: 658596 - 81 - 1128=935=X34=65859652=20140610-13:28:56.32375=20140610268=1279=0269=022=8207=BVMF48=380977983=20240270=7.29273=85:63:23271=200272=2014061037016=2014061037017=85:63:2237=80531943297288=40290=19
10:28:56.353: 658597 - 82 - 1128=935=X34=65859752=20140610-13:28:56.36475=20140610268=1279=0269=122=8207=BVMF48=380394783=65771270=17.04273=85:63:63271=100272=2014061037016=2014061037017=85:63:6337=80531943300289=70290=4
10:28:56.359: 658598 - 117 - 1128=935=X34=65859852=20140610-13:28:56.37175=20140610268=2279=2269=122=8207=BVMF48=380391383=106177273=85:63:70272=2014061037=80531939561289=3290=7279=0269=122=8207=BVMF48=380391383=106178270=13.85273=85:63:70271=1100272=2014061037016=2014061037017=85:63:7037=80531943301289=3290=5
10:28:56.687: 658599 - 70 - 1128=935=X34=65859952=20140610-13:28:56.69875=20140610268=1279=2269=022=8207=BVMF48=380965483=79596273=85:66:97272=2014061037=80531938989288=8290=10
10:28:56.687: 658600 - 71 - 1128=935=X34=65860052=20140610-13:28:56.69875=20140610268=1279=2269=122=8207=BVMF48=380965483=79597273=85:66:97272=2014061037=80531893372289=8290=49
10:28:56.687: 658601 - 80 - 1128=935=X34=65860152=20140610-13:28:56.69875=20140610268=1279=0269=022=8207=BVMF48=380965483=79598270=8.12273=85:66:98271=800272=2014061037016=2014061037017=85:66:9737=80531943326288=8290=61
10:28:56.687: 658602 - 81 - 1128=935=X34=65860252=20140610-13:28:56.69975=20140610268=1279=0269=122=8207=BVMF48=380965483=79599270=8.24273=85:66:98271=1000272=2014061037016=2014061037017=85:66:9837=80531943328289=8290=21
10:28:57.226: 658603 - 162 - 1128=935=X34=65860352=20140610-13:28:57.23875=20140610268=3279=0269=222=8207=BVMF48=380963983=255812270=26.4273=85:72:37271=100272=2014061037016=2014061037017=85:72:371500=E451=-0.211020=1405100274=1277=L1003=18950288=735289=85279=0269=922=8207=BVMF48=380963983=255813270=26.47273=85:72:37272=201406101500=E279=1269=122=8207=BVMF48=380963983=255814270=26.4273=85:72:37271=4100272=2014061037016=2014061037017=83:31:6237=80531942464289=85290=1
10:28:57.485: 658604 - 154 - 1128=935=X34=65860452=20140610-13:28:57.49775=20140610268=3279=0269=222=8207=BVMF48=380965483=79600270=8.19273=85:74:96271=100272=2014061037016=2014061037017=85:74:961500=E451=-0.091020=249700274=01003=3150288=8289=114279=0269=922=8207=BVMF48=380965483=79601270=8.246273=85:74:96272=201406101500=E279=1269=022=8207=BVMF48=380965483=79602270=8.19273=85:74:96271=600272=2014061037016=2014061037017=85:58:4737=80531943129288=8290=1
10:28:57.487: 658605 - 80 - 1128=935=X34=65860552=20140610-13:28:57.49875=20140610268=1279=0269=022=8207=BVMF48=380965483=79603270=8.19273=85:74:98271=100272=2014061037016=2014061037017=85:74:9837=80531943460288=8290=3
10:28:57.487: 658606 - 81 - 1128=935=X34=65860652=20140610-13:28:57.49975=20140610268=1279=0269=122=8207=BVMF48=380977983=20241270=7.38273=85:74:98271=800272=2014061037016=2014061037017=85:74:9837=80531943461289=3290=3
10:28:57.489: 658607 - 80 - 1128=935=X34=65860752=20140610-13:28:57.50075=20140610268=1279=0269=022=8207=BVMF48=380977983=20242270=7.36273=85:75:00271=100272=2014061037016=2014061037017=85:75:0037=80531943462288=8290=4
10:28:57.545: 658608 - 393 - 1128=935=X34=65860852=20140610-13:28:57.55775=20140610268=10279=0269=222=8207=BVMF48=380965483=79604270=8.19273=85:75:56271=600272=2014061037016=2014061037017=85:75:561500=E451=-0.091020=250300274=1277=L1003=3160288=8289=114279=0269=922=8207=BVMF48=380965483=79605270=8.245273=85:75:56272=201406101500=E279=0269=222=8207=BVMF48=380965483=79606270=8.19273=85:75:56271=200272=2014061037016=2014061037017=85:75:561500=E451=-0.091020=250500274=1277=L1003=3170288=9289=114279=0269=922=8207=BVMF48=380965483=79607270=8.245273=85:75:56272=201406101500=E279=0269=222=8207=BVMF48=380965483=79608270=8.19273=85:75:56271=100272=2014061037016=2014061037017=85:75:561500=E451=-0.091020=250600274=1277=L1003=3180288=8289=114279=0269=922=8207=BVMF48=380965483=79609270=8.245273=85:75:56272=201406101500=E279=0269=222=8207=BVMF48=380965483=79610270=8.18273=85:75:56271=1100272=2014061037016=2014061037017=85:75:561500=E451=-0.11020=251700274=21003=3190288=77289=114279=0269=922=8207=BVMF48=380965483=79611270=8.245273=85:75:56272=201406101500=E279=4269=022=8207=BVMF48=380965483=79612273=85:75:56272=20140610290=3279=1269=022=8207=BVMF48=380965483=79613270=8.18273=85:75:56271=8200272=2014061037016=2014061037017=50:71:7737=80531856537288=77290=1
10:28:57.547: 658609 - 80 - 1128=935=X34=65860952=20140610-13:28:57.55975=20140610268=1279=0269=022=8207=BVMF48=380965483=79614270=8.19273=85:75:58271=700272=2014061037016=2014061037017=85:75:5837=80531943464288=8290=1
10:28:57.547: 658610 - 80 - 1128=935=X34=65861052=20140610-13:28:57.55975=20140610268=1279=0269=022=8207=BVMF48=380965483=79615270=8.17273=85:75:58271=100272=2014061037016=2014061037017=85:75:5837=80531943465288=8290=22
10:28:57.548: 658611 - 80 - 1128=935=X34=65861152=20140610-13:28:57.56075=20140610268=1279=0269=022=8207=BVMF48=380965483=79616270=8.18273=85:75:59271=600272=2014061037016=2014061037017=85:75:5937=80531943470288=3290=11
10:28:57.549: 658612 - 81 - 1128=935=X34=65861252=20140610-13:28:57.56175=20140610268=1279=0269=122=8207=BVMF48=380965483=79617270=8.21273=85:75:60271=400272=2014061037016=2014061037017=85:75:6037=80531943477289=8290=3
10:28:57.549: 658613 - 70 - 1128=935=X34=65861352=20140610-13:28:57.56175=20140610268=1279=2269=022=8207=BVMF48=380965483=79618273=85:75:61272=2014061037=80531943128288=8290=10
10:28:57.550: 658614 - 70 - 1128=935=X34=65861452=20140610-13:28:57.56175=20140610268=1279=2269=022=8207=BVMF48=380965483=79619273=85:75:61272=2014061037=80531943470288=3290=10
10:28:57.550: 658615 - 117 - 1128=935=X34=65861552=20140610-13:28:57.56275=20140610268=2279=2269=122=8207=BVMF48=380965483=79620273=85:75:62272=2014061037=80531940330289=8290=7279=0269=122=8207=BVMF48=380965483=79621270=8.21273=85:75:62271=200272=2014061037016=2014061037017=85:75:6237=80531943491289=8290=4
10:28:57.763: 658616 - 71 - 1128=935=X34=65861652=20140610-13:28:57.77575=20140610268=1279=2269=022=8207=BVMF48=380965483=79622273=85:77:74272=2014061037=80531932748288=40290=24
10:28:57.765: 658617 - 72 - 1128=935=X34=65861752=20140610-13:28:57.77675=20140610268=1279=2269=122=8207=BVMF48=380965483=79623273=85:77:76272=2014061037=80531932640289=40290=52
10:28:57.765: 658618 - 72 - 1128=935=X34=65861852=20140610-13:28:57.77675=20140610268=1279=2269=122=8207=BVMF48=380965483=79624273=85:77:76272=2014061037=80531932639289=40290=65
10:28:57.766: 658619 - 71 - 1128=935=X34=65861952=20140610-13:28:57.77775=20140610268=1279=2269=022=8207=BVMF48=380965483=79625273=85:77:77272=2014061037=80531932753288=40290=52
10:28:57.985: 658620 - 199 - 1128=935=X34=65862052=20140610-13:28:57.99675=20140610268=4279=0269=222=8207=BVMF48=380963983=255815270=26.4273=85:79:95271=100272=2014061037016=2014061037017=85:79:951500=E451=-0.211020=1405200274=1277=L1003=18960288=8289=85279=0269=922=8207=BVMF48=380963983=255816270=26.47273=85:79:95272=201406101500=E279=1269=122=8207=BVMF48=380963983=255817270=26.4273=85:79:95271=4000272=2014061037016=2014061037017=83:31:6237=80531942464289=85290=1279=2269=022=8207=BVMF48=380963983=255818273=85:79:95272=2014061037=80531943020288=8290=6
10:28:58.074: 658621 - 72 - 1128=935=X34=65862152=20140610-13:28:58.08675=20140610268=1279=2269=122=8207=BVMF48=380965483=79626273=85:80:85272=2014061037=80531940355289=16290=8
10:28:58.196: 658622 - 82 - 1128=935=X34=65862252=20140610-13:28:58.20875=20140610268=1279=0269=122=8207=BVMF48=380965483=79627270=8.21273=85:82:07271=100272=2014061037016=2014061037017=85:82:0737=80531943566289=16290=5
10:29:00.004: 658623 - 367 - 1128=935=X34=65862352=20140610-13:29:00.01675=20140610268=9279=0269=222=8207=BVMF48=380968883=253438270=29.38273=90:00:15271=300272=2014061037016=2014061037017=90:00:151500=E451=-0.251020=446400274=21003=6440288=40289=13279=0269=922=8207=BVMF48=380968883=253439270=29.478273=90:00:15272=201406101500=E279=0269=222=8207=BVMF48=380968883=253440270=29.38273=90:00:15271=400272=2014061037016=2014061037017=90:00:151500=E451=-0.251020=446800274=3277=L1003=6450288=40289=13279=0269=922=8207=BVMF48=380968883=253441270=29.478273=90:00:15272=201406101500=E279=0269=222=8207=BVMF48=380968883=253442270=29.38273=90:00:15271=600272=2014061037016=2014061037017=90:00:151500=E451=-0.251020=447400274=3277=L1003=6460288=45289=13279=0269=922=8207=BVMF48=380968883=253443270=29.478273=90:00:15272=201406101500=E279=4269=022=8207=BVMF48=380968883=253444273=90:00:15272=20140610290=2279=1269=022=8207=BVMF48=380968883=253445270=29.38273=90:00:15271=100272=2014061037016=2014061037017=84:12:0737=80531942858288=45290=1279=2269=122=8207=BVMF48=380968883=253446273=90:00:15272=2014061037=80531943007289=13290=6
10:29:00.006: 658624 - 81 - 1128=935=X34=65862452=20140610-13:29:00.01775=20140610268=1279=0269=122=8207=BVMF48=380968883=253447270=29.43273=90:00:17271=100272=2014061037016=2014061037017=90:00:1737=80531943631289=8290=16
10:29:00.029: 658625 - 71 - 1128=935=X34=65862552=20140610-13:29:00.04175=20140610268=1279=2269=022=8207=BVMF48=380968883=253448273=90:00:40272=2014061037=80531942858288=45290=1
10:29:00.034: 658626 - 81 - 1128=935=X34=65862652=20140610-13:29:00.04675=20140610268=1279=0269=022=8207=BVMF48=380968883=253449270=29.37273=90:00:46271=300272=2014061037016=2014061037017=90:00:4537=80531943632288=45290=3
10:29:00.039: 658627 - 80 - 1128=935=X34=65862752=20140610-13:29:00.05175=20140610268=1279=0269=022=8207=BVMF48=380968883=253450270=29.37273=90:00:50271=700272=2014061037016=2014061037017=90:00:5037=80531943633288=3290=4
10:29:00.139: 658628 - 81 - 1128=935=X34=65862852=20140610-13:29:00.15075=20140610268=1279=0269=022=8207=BVMF48=380968883=253451270=29.38273=90:01:50271=300272=2014061037016=2014061037017=90:01:5037=80531943634288=70290=1
10:29:00.144: 658629 - 71 - 1128=935=X34=65862952=20140610-13:29:00.15675=20140610268=1279=2269=122=8207=BVMF48=380968883=253452273=90:01:55272=2014061037=80531943631289=8290=16
10:29:00.148: 658630 - 118 - 1128=935=X34=65863052=20140610-13:29:00.16075=20140610268=2279=2269=022=8207=BVMF48=380968883=253453273=90:01:59272=2014061037=80531943632288=45290=4279=0269=022=8207=BVMF48=380968883=253454270=29.38273=90:01:59271=300272=2014061037016=2014061037017=90:01:5937=80531943635288=45290=2
10:29:01.246: 658631 - 162 - 1128=935=X34=65863152=20140610-13:29:01.25775=20140610268=3279=0269=222=8207=BVMF48=380963983=255819270=26.4273=90:12:57271=500272=2014061037016=2014061037017=90:12:561500=E451=-0.211020=1405700274=1277=L1003=18970288=227289=85279=0269=922=8207=BVMF48=380963983=255820270=26.47273=90:12:57272=201406101500=E279=1269=122=8207=BVMF48=380963983=255821270=26.4273=90:12:57271=3500272=2014061037016=2014061037017=83:31:6237=80531942464289=85290=1
10:29:01.247: 658632 - 158 - 1128=935=X34=65863252=20140610-13:29:01.25875=20140610268=3279=0269=222=8207=BVMF48=380968883=253455270=29.39273=90:12:57271=400272=2014061037016=2014061037017=90:12:571500=E451=-0.241020=447800274=01003=6470288=227289=45279=0269=922=8207=BVMF48=380968883=253456270=29.478273=90:12:57272=201406101500=E279=1269=122=8207=BVMF48=380968883=253457270=29.39273=90:12:57271=2600272=2014061037016=2014061037017=84:11:9337=80531942856289=45290=1
10:29:01.259: 658633 - 155 - 1128=935=X34=65863352=20140610-13:29:01.27075=20140610268=3279=0269=222=8207=BVMF48=380391383=106179270=13.85273=90:12:70271=300272=2014061037016=2014061037017=90:12:691500=E451=-0.041020=108500274=1277=L1003=3350288=227289=8279=0269=922=8207=BVMF48=380391383=106180270=13.878273=90:12:70272=201406101500=E279=1269=122=8207=BVMF48=380391383=106181270=13.85273=90:12:70271=300272=2014061037016=2014061037017=50:95:0937=80531929098289=8290=1
10:29:01.260: 658634 - 71 - 1128=935=X34=65863452=20140610-13:29:01.27275=20140610268=1279=2269=122=8207=BVMF48=380391383=106182273=90:12:71272=2014061037=80531930313289=8290=2
10:29:01.260: 658635 - 80 - 1128=935=X34=65863552=20140610-13:29:01.27275=20140610268=1279=0269=022=8207=BVMF48=380391383=106183270=13.84273=90:12:71271=300272=2014061037016=2014061037017=90:12:7137=80531943642288=8290=3
10:29:01.267: 658636 - 156 - 1128=935=X34=65863652=20140610-13:29:01.27975=20140610268=3279=0269=222=8207=BVMF48=380249383=103499270=9.35273=90:12:78271=200272=2014061037016=2014061037017=90:12:781500=E451=-0.11020=260900274=01003=3690288=227289=8279=0269=922=8207=BVMF48=380249383=103500270=9.381273=90:12:78272=201406101500=E279=1269=122=8207=BVMF48=380249383=103501270=9.35273=90:12:78271=100272=2014061037016=2014061037017=15:70:1437=80531921001289=8290=1
10:29:01.279: 658637 - 156 - 1128=935=X34=65863752=20140610-13:29:01.29175=20140610268=3279=0269=222=8207=BVMF48=380394783=65772270=17.04273=90:12:90271=100272=2014061037016=2014061037017=90:12:901500=E451=-0.121020=18900274=01003=1130288=227289=8279=0269=922=8207=BVMF48=380394783=65773270=17.1273=90:12:90272=201406101500=E279=1269=122=8207=BVMF48=380394783=65774270=17.04273=90:12:90271=200272=2014061037016=2014061037017=53:81:3137=80531931296289=8290=1
10:29:01.281: 658638 - 154 - 1128=935=X34=65863852=20140610-13:29:01.29275=20140610268=3279=0269=222=8207=BVMF48=380965483=79628270=8.21273=90:12:92271=100272=2014061037016=2014061037017=90:12:921500=E451=-0.071020=251800274=01003=3200288=227289=8279=0269=922=8207=BVMF48=380965483=79629270=8.245273=90:12:92272=201406101500=E279=1269=122=8207=BVMF48=380965483=79630270=8.21273=90:12:92271=400272=2014061037016=2014061037017=85:59:3237=80531943199289=8290=1
10:29:01.283: 658639 - 152 - 1128=935=X34=65863952=20140610-13:29:01.29575=20140610268=3279=0269=222=8207=BVMF48=380965483=79631270=8.19273=90:12:94271=100272=2014061037016=2014061037017=90:12:941500=E451=-0.091020=251900274=21003=3210288=8289=3279=0269=922=8207=BVMF48=380965483=79632270=8.245273=90:12:94272=201406101500=E279=1269=022=8207=BVMF48=380965483=79633270=8.19273=90:12:94271=600272=2014061037016=2014061037017=85:75:5837=80531943464288=8290=1
10:29:01.299: 658640 - 80 - 1128=935=X34=65864052=20140610-13:29:01.31075=20140610268=1279=0269=022=8207=BVMF48=380391383=106184270=13.84273=90:13:09271=100272=2014061037016=2014061037017=90:13:0937=80531943647288=8290=4
10:29:01.300: 658641 - 71 - 1128=935=X34=65864152=20140610-13:29:01.31175=20140610268=1279=2269=122=8207=BVMF48=380391383=106185273=90:13:11272=2014061037=80531929098289=8290=1
10:29:01.344: 658642 - 80 - 1128=935=X34=65864252=20140610-13:29:01.35575=20140610268=1279=0269=022=8207=BVMF48=380968883=253458270=29.34273=90:13:55271=100272=2014061037016=2014061037017=90:13:5437=80531943648288=8290=15
10:29:01.382: 658643 - 117 - 1128=935=X34=65864352=20140610-13:29:01.39475=20140610268=2279=2269=122=8207=BVMF48=380391383=106186273=90:13:93272=2014061037=80531943301289=3290=3279=0269=122=8207=BVMF48=380391383=106187270=13.86273=90:13:93271=1100272=2014061037016=2014061037017=90:13:9337=80531943649289=3290=5
10:29:01.428: 658644 - 157 - 1128=935=X34=65864452=20140610-13:29:01.43975=20140610268=3279=0269=222=8207=BVMF48=380391383=106188270=13.84273=90:14:39271=100272=2014061037016=2014061037017=90:14:381500=E451=-0.051020=108600274=21003=3360288=40289=227279=0269=922=8207=BVMF48=380391383=106189270=13.877273=90:14:39272=201406101500=E279=1269=022=8207=BVMF48=380391383=106190270=13.84273=90:14:39271=100272=2014061037016=2014061037017=83:61:9437=80531942641288=40290=1
10:29:01.469: 658645 - 73 - 1128=935=X34=65864552=20140610-13:29:01.48175=20140610268=1279=2269=122=8207=BVMF48=380394783=65775273=90:14:81272=2014061037=80531935166289=227290=15
10:29:01.592: 658646 - 83 - 1128=935=X34=65864652=20140610-13:29:01.60475=20140610268=1279=0269=122=8207=BVMF48=380394783=65776270=17.11273=90:16:03271=100272=2014061037016=2014061037017=90:16:0337=80531943654289=227290=15
10:29:01.597: 658647 - 190 - 1128=935=X34=65864752=20140610-13:29:01.60975=20140610268=4279=0269=222=8207=BVMF48=380965483=79634270=8.19273=90:16:08271=600272=2014061037016=2014061037017=90:16:081500=E451=-0.091020=252500274=3277=L1003=3220288=8289=8279=0269=922=8207=BVMF48=380965483=79635270=8.245273=90:16:08272=201406101500=E279=2269=022=8207=BVMF48=380965483=79636273=90:16:08272=2014061037=80531943464288=8290=1279=0269=122=8207=BVMF48=380965483=79637270=8.19273=90:16:08271=9400272=2014061037016=2014061037017=90:16:0837=80531943655289=8290=1
10:29:01.598: 658648 - 71 - 1128=935=X34=65864852=20140610-13:29:01.61075=20140610268=1279=2269=122=8207=BVMF48=380965483=79638273=90:16:09272=2014061037=80531939948289=8290=87
10:29:01.599: 658649 - 80 - 1128=935=X34=65864952=20140610-13:29:01.61075=20140610268=1279=0269=022=8207=BVMF48=380965483=79639270=8.18273=90:16:10271=100272=2014061037016=2014061037017=90:16:0937=80531943656288=8290=9
10:29:01.599: 658650 - 152 - 1128=935=X34=65865052=20140610-13:29:01.61175=20140610268=3279=0269=222=8207=BVMF48=380965483=79640270=8.19273=90:16:10271=1000272=2014061037016=2014061037017=90:16:101500=E451=-0.091020=253500274=3277=L1003=3230288=8289=8279=0269=922=8207=BVMF48=380965483=79641270=8.245273=90:16:10272=201406101500=E279=1269=122=8207=BVMF48=380965483=79642270=8.19273=90:16:10271=8400272=2014061037016=2014061037017=90:16:0837=80531943655289=8290=1
10:29:01.599: 658651 - 152 - 1128=935=X34=65865152=20140610-13:29:01.61175=20140610268=3279=0269=222=8207=BVMF48=380965483=79643270=8.19273=90:16:10271=1500272=2014061037016=2014061037017=90:16:101500=E451=-0.091020=255000274=3277=L1003=3240288=8289=8279=0269=922=8207=BVMF48=380965483=79644270=8.244273=90:16:10272=201406101500=E279=1269=122=8207=BVMF48=380965483=79645270=8.19273=90:16:10271=6900272=2014061037016=2014061037017=90:16:0837=80531943655289=8290=1
10:29:01.599: 658652 - 82 - 1128=935=X34=65865252=20140610-13:29:01.61175=20140610268=1279=0269=122=8207=BVMF48=380965483=79646270=8.2273=90:16:11271=500272=2014061037016=2014061037017=90:16:1037=80531943659289=8290=2
10:29:01.600: 658653 - 81 - 1128=935=X34=65865352=20140610-13:29:01.61175=20140610268=1279=0269=122=8207=BVMF48=380977983=20243270=7.38273=90:16:11271=1600272=2014061037016=2014061037017=90:16:1137=80531943661289=3290=4
10:29:01.600: 658654 - 117 - 1128=935=X34=65865452=20140610-13:29:01.61275=20140610268=2279=2269=122=8207=BVMF48=380977983=20244273=90:16:11272=2014061037=80531943461289=3290=3279=0269=122=8207=BVMF48=380977983=20245270=7.37273=90:16:11271=3200272=2014061037016=2014061037017=90:16:1137=80531943665289=3290=1
10:29:01.600: 658655 - 80 - 1128=935=X34=65865552=20140610-13:29:01.61275=20140610268=1279=0269=022=8207=BVMF48=380965483=79647270=8.18273=90:16:12271=600272=2014061037016=2014061037017=90:16:1137=80531943668288=3290=10
10:29:01.601: 658656 - 71 - 1128=935=X34=65865652=20140610-13:29:01.61275=20140610268=1279=2269=122=8207=BVMF48=380965483=79648273=90:16:12272=2014061037=80531940155289=8290=10
10:29:01.602: 658657 - 142 - 1128=935=X34=65865752=20140610-13:29:01.61475=20140610268=3279=0269=222=8207=BVMF48=380965483=79649270=8.19273=90:16:13271=6900272=2014061037016=2014061037017=90:16:121500=E451=-0.091020=261900274=3277=L1003=3250288=8289=8279=0269=922=8207=BVMF48=380965483=79650270=8.243273=90:16:13272=201406101500=E279=2269=122=8207=BVMF48=380965483=79651273=90:16:13272=2014061037=80531943655289=8290=1
10:29:01.602: 658658 - 70 - 1128=935=X34=65865852=20140610-13:29:01.61475=20140610268=1279=2269=022=8207=BVMF48=380977983=20246273=90:16:14272=2014061037=80531943155288=8290=3
10:29:01.603: 658659 - 71 - 1128=935=X34=65865952=20140610-13:29:01.61575=20140610268=1279=2269=122=8207=BVMF48=380977983=20247273=90:16:14272=2014061037=80531943661289=3290=4
10:29:01.604: 658660 - 80 - 1128=935=X34=65866052=20140610-13:29:01.61675=20140610268=1279=0269=022=8207=BVMF48=380965483=79652270=8.19273=90:16:15271=700272=2014061037016=2014061037017=90:16:1537=80531943704288=8290=1
10:29:01.605: 658661 - 71 - 1128=935=X34=65866152=20140610-13:29:01.61675=20140610268=1279=2269=122=8207=BVMF48=380977983=20248273=90:16:16272=2014061037=80531943665289=3290=1
10:29:01.605: 658662 - 70 - 1128=935=X34=65866252=20140610-13:29:01.61775=20140610268=1279=2269=022=8207=BVMF48=380965483=79653273=90:16:16272=2014061037=80531893939288=8290=25
10:29:01.605: 658663 - 79 - 1128=935=X34=65866352=20140610-13:29:01.61775=20140610268=1279=1269=022=8207=BVMF48=380965483=79654270=8.18273=90:16:16271=500272=2014061037016=2014061037017=90:16:1137=80531943709288=3290=11
10:29:01.605: 658664 - 81 - 1128=935=X34=65866452=20140610-13:29:01.61775=20140610268=1279=0269=022=8207=BVMF48=380965483=79655270=8.1273=90:16:17271=800272=2014061037016=2014061037017=90:16:1637=80531943710288=8290=71
10:29:01.607: 658665 - 81 - 1128=935=X34=65866552=20140610-13:29:01.61875=20140610268=1279=0269=122=8207=BVMF48=380977983=20249270=7.38273=90:16:18271=100272=2014061037016=2014061037017=90:16:1837=80531943717289=8290=3
10:29:01.608: 658666 - 81 - 1128=935=X34=65866652=20140610-13:29:01.62075=20140610268=1279=0269=122=8207=BVMF48=380977983=20250270=7.38273=90:16:19271=500272=2014061037016=2014061037017=90:16:1937=80531943725289=3290=4
10:29:01.608: 658667 - 70 - 1128=935=X34=65866752=20140610-13:29:01.62075=20140610268=1279=2269=022=8207=BVMF48=380965483=79656273=90:16:19272=2014061037=80531943709288=3290=11
10:29:01.615: 658668 - 72 - 1128=935=X34=65866852=20140610-13:29:01.62775=20140610268=1279=2269=122=8207=BVMF48=380965483=79657273=90:16:26272=2014061037=80531924086289=16290=39
10:29:01.620: 658669 - 71 - 1128=935=X34=65866952=20140610-13:29:01.63275=20140610268=1279=2269=122=8207=BVMF48=380977983=20251273=90:16:31272=2014061037=80531875461289=8290=25
10:29:01.620: 658670 - 82 - 1128=935=X34=65867052=20140610-13:29:01.63275=20140610268=1279=0269=122=8207=BVMF48=380977983=20252270=7.4273=90:16:32271=500272=2014061037016=2014061037017=90:16:3137=80531943798289=8290=10
10:29:01.649: 658671 - 70 - 1128=935=X34=65867152=20140610-13:29:01.66175=20140610268=1279=2269=022=8207=BVMF48=380977983=20253273=90:16:61272=2014061037=80531943462288=8290=3
10:29:01.650: 658672 - 81 - 1128=935=X34=65867252=20140610-13:29:01.66275=20140610268=1279=0269=122=8207=BVMF48=380977983=20254270=7.38273=90:16:61271=100272=2014061037016=2014061037017=90:16:6137=80531943819289=8290=5
10:29:01.650: 658673 - 71 - 1128=935=X34=65867352=20140610-13:29:01.66275=20140610268=1279=2269=122=8207=BVMF48=380977983=20255273=90:16:61272=2014061037=80531943819289=8290=5
10:29:01.651: 658674 - 80 - 1128=935=X34=65867452=20140610-13:29:01.66375=20140610268=1279=0269=022=8207=BVMF48=380977983=20256270=7.36273=90:16:62271=100272=2014061037016=2014061037017=90:16:6237=80531943821288=8290=3
10:29:01.651: 658675 - 70 - 1128=935=X34=65867552=20140610-13:29:01.66375=20140610268=1279=2269=022=8207=BVMF48=380977983=20257273=90:16:62272=2014061037=80531943821288=8290=3
10:29:01.651: 658676 - 81 - 1128=935=X34=65867652=20140610-13:29:01.66375=20140610268=1279=0269=122=8207=BVMF48=380977983=20258270=7.38273=90:16:62271=100272=2014061037016=2014061037017=90:16:6237=80531943822289=8290=5
10:29:01.651: 658677 - 71 - 1128=935=X34=65867752=20140610-13:29:01.66375=20140610268=1279=2269=122=8207=BVMF48=380977983=20259273=90:16:63272=2014061037=80531943822289=8290=5
10:29:01.690: 658678 - 71 - 1128=935=X34=65867852=20140610-13:29:01.70275=20140610268=1279=2269=122=8207=BVMF48=380965483=79658273=90:17:01272=2014061037=80531940147289=8290=33
10:29:01.690: 658679 - 71 - 1128=935=X34=65867952=20140610-13:29:01.70275=20140610268=1279=2269=122=8207=BVMF48=380965483=79659273=90:17:01272=2014061037=80531940146289=8290=46
10:29:01.690: 658680 - 70 - 1128=935=X34=65868052=20140610-13:29:01.70275=20140610268=1279=2269=022=8207=BVMF48=380965483=79660273=90:17:01272=2014061037=80531940150288=8290=41
10:29:01.690: 658681 - 70 - 1128=935=X34=65868152=20140610-13:29:01.70275=20140610268=1279=2269=022=8207=BVMF48=380965483=79661273=90:17:02272=2014061037=80531940149288=8290=21
10:29:01.692: 658682 - 81 - 1128=935=X34=65868252=20140610-13:29:01.70375=20140610268=1279=0269=122=8207=BVMF48=380965483=79662270=8.29273=90:17:03271=7700272=2014061037016=2014061037017=90:17:0337=80531943829289=8290=51
10:29:01.692: 658683 - 82 - 1128=935=X34=65868352=20140610-13:29:01.70475=20140610268=1279=0269=122=8207=BVMF48=380965483=79663270=8.27273=90:17:03271=8500272=2014061037016=2014061037017=90:17:0337=80531943830289=8290=40
10:29:01.693: 658684 - 81 - 1128=935=X34=65868452=20140610-13:29:01.70475=20140610268=1279=0269=022=8207=BVMF48=380965483=79664270=8.15273=90:17:04271=8500272=2014061037016=2014061037017=90:17:0437=80531943831288=8290=42
10:29:01.693: 658685 - 81 - 1128=935=X34=65868552=20140610-13:29:01.70575=20140610268=1279=0269=022=8207=BVMF48=380965483=79665270=8.13273=90:17:04271=9200272=2014061037016=2014061037017=90:17:0437=80531943832288=8290=52
10:29:01.725: 658686 - 143 - 1128=935=X34=65868652=20140610-13:29:01.73675=20140610268=3279=0269=222=8207=BVMF48=380965483=79666270=8.2273=90:17:36271=500272=2014061037016=2014061037017=90:17:351500=E451=-0.081020=262400274=01003=3260288=8289=8279=0269=922=8207=BVMF48=380965483=79667270=8.243273=90:17:36272=201406101500=E279=2269=122=8207=BVMF48=380965483=79668273=90:17:36272=2014061037=80531943659289=8290=1
10:29:01.726: 658687 - 80 - 1128=935=X34=65868752=20140610-13:29:01.73775=20140610268=1279=0269=022=8207=BVMF48=380965483=79669270=8.17273=90:17:37271=500272=2014061037016=2014061037017=90:17:3737=80531943836288=8290=22
10:29:01.726: 658688 - 158 - 1128=935=X34=65868852=20140610-13:29:01.73875=20140610268=3279=0269=222=8207=BVMF48=380968883=253459270=29.39273=90:17:37271=600272=2014061037016=2014061037017=90:17:371500=E451=-0.241020=448400274=1277=L1003=6480288=227289=45279=0269=922=8207=BVMF48=380968883=253460270=29.478273=90:17:37272=201406101500=E279=1269=122=8207=BVMF48=380968883=253461270=29.39273=90:17:37271=2000272=2014061037016=2014061037017=84:11:9337=80531942856289=45290=1
10:29:01.727: 658689 - 71 - 1128=935=X34=65868952=20140610-13:29:01.73875=20140610268=1279=2269=122=8207=BVMF48=380977983=20260273=90:17:38272=2014061037=80531943725289=3290=4
10:29:01.763: 658690 - 72 - 1128=935=X34=65869052=20140610-13:29:01.77475=20140610268=1279=2269=122=8207=BVMF48=380965483=79670273=90:17:74272=2014061037=80531940206289=40290=38
10:29:01.768: 658691 - 72 - 1128=935=X34=65869152=20140610-13:29:01.78075=20140610268=1279=2269=122=8207=BVMF48=380965483=79671273=90:17:79272=2014061037=80531940207289=40290=48
10:29:01.914: 658692 - 82 - 1128=935=X34=65869252=20140610-13:29:01.92675=20140610268=1279=0269=122=8207=BVMF48=380965483=79672270=8.28273=90:19:25271=4300272=2014061037016=2014061037017=90:19:2537=80531943880289=40290=45
10:29:01.915: 658693 - 82 - 1128=935=X34=65869352=20140610-13:29:01.92775=20140610268=1279=0269=122=8207=BVMF48=380965483=79673270=8.26273=90:19:26271=7700272=2014061037016=2014061037017=90:19:2637=80531943881289=40290=32
10:29:01.998: 658694 - 80 - 1128=935=X34=65869452=20140610-13:29:02.01075=20140610268=1279=0269=022=8207=BVMF48=380977983=20261270=7.36273=90:20:09271=100272=2014061037016=2014061037017=90:20:0937=80531943882288=8290=3
10:29:02.144: 658695 - 71 - 1128=935=X34=65869552=20140610-13:29:02.15575=20140610268=1279=2269=122=8207=BVMF48=380394783=65777273=90:21:55272=2014061037=80531942640289=8290=9
10:29:02.403: 658696 - 160 - 1128=935=X34=65869652=20140610-13:29:02.41475=20140610268=3279=0269=222=8207=BVMF48=380963983=255822270=26.4273=90:24:14271=100272=2014061037016=2014061037017=90:24:131500=E451=-0.211020=1405800274=1277=L1003=18980288=3289=85279=0269=922=8207=BVMF48=380963983=255823270=26.47273=90:24:14272=201406101500=E279=1269=122=8207=BVMF48=380963983=255824270=26.4273=90:24:14271=3400272=2014061037016=2014061037017=83:31:6237=80531942464289=85290=1
10:29:02.405: 658697 - 265 - 1128=935=X34=65869752=20140610-13:29:02.41775=20140610268=6279=0269=222=8207=BVMF48=380391383=106191270=13.84273=90:24:16271=100272=2014061037016=2014061037017=90:24:161500=E451=-0.051020=108700274=3277=L1003=3370288=40289=8279=0269=922=8207=BVMF48=380391383=106192270=13.877273=90:24:16272=201406101500=E279=0269=222=8207=BVMF48=380391383=106193270=13.84273=90:24:16271=200272=2014061037016=2014061037017=90:24:161500=E451=-0.051020=108900274=3277=L1003=3380288=40289=8279=0269=922=8207=BVMF48=380391383=106194270=13.877273=90:24:16272=201406101500=E279=2269=022=8207=BVMF48=380391383=106195273=90:24:16272=2014061037=80531942641288=40290=1279=1269=022=8207=BVMF48=380391383=106196270=13.84273=90:24:16271=100272=2014061037016=2014061037017=83:63:1037=80531942697288=40290=1
10:29:02.407: 658698 - 203 - 1128=935=X34=65869852=20140610-13:29:02.41875=20140610268=5279=0269=222=8207=BVMF48=380249383=103502270=9.34273=90:24:18271=200272=2014061037016=2014061037017=90:24:171500=E451=-0.111020=261100274=21003=3700288=40289=8279=0269=922=8207=BVMF48=380249383=103503270=9.381273=90:24:18272=201406101500=E279=0269=222=8207=BVMF48=380249383=103504270=9.34273=90:24:18271=200272=2014061037016=2014061037017=90:24:171500=E451=-0.111020=261300274=3277=L1003=3710288=40289=8279=0269=922=8207=BVMF48=380249383=103505270=9.381273=90:24:18272=201406101500=E279=4269=022=8207=BVMF48=380249383=103506273=90:24:18272=20140610290=2
10:29:02.409: 658699 - 154 - 1128=935=X34=65869952=20140610-13:29:02.42075=20140610268=3279=0269=222=8207=BVMF48=380394783=65778270=17.03273=90:24:20271=100272=2014061037016=2014061037017=90:24:191500=E451=-0.131020=19000274=21003=1140288=8289=8279=0269=922=8207=BVMF48=380394783=65779270=17.099273=90:24:20272=201406101500=E279=1269=022=8207=BVMF48=380394783=65780270=17.03273=90:24:20271=300272=2014061037016=2014061037017=83:57:5337=80531942629288=8290=1
10:29:02.409: 658700 - 152 - 1128=935=X34=65870052=20140610-13:29:02.42175=20140610268=3279=0269=222=8207=BVMF48=380965483=79674270=8.19273=90:24:21271=100272=2014061037016=2014061037017=90:24:201500=E451=-0.091020=262500274=21003=3270288=8289=8279=0269=922=8207=BVMF48=380965483=79675270=8.243273=90:24:21272=201406101500=E279=1269=022=8207=BVMF48=380965483=79676270=8.19273=90:24:21271=600272=2014061037016=2014061037017=90:16:1537=80531943704288=8290=1
10:29:02.411: 658701 - 145 - 1128=935=X34=65870152=20140610-13:29:02.42275=20140610268=3279=0269=222=8207=BVMF48=380968883=253462270=29.38273=90:24:22271=300272=2014061037016=2014061037017=90:24:221500=E451=-0.251020=448700274=21003=6490288=70289=8279=0269=922=8207=BVMF48=380968883=253463270=29.478273=90:24:22272=201406101500=E279=2269=022=8207=BVMF48=380968883=253464273=90:24:22272=2014061037=80531943634288=70290=1
10:29:02.411: 658702 - 158 - 1128=935=X34=65870252=20140610-13:29:02.42375=20140610268=3279=0269=222=8207=BVMF48=380963983=255825270=26.39273=90:24:22271=500272=2014061037016=2014061037017=90:24:221500=E451=-0.221020=1406300274=21003=18990288=45289=8279=0269=922=8207=BVMF48=380963983=255826270=26.47273=90:24:22272=201406101500=E279=1269=022=8207=BVMF48=380963983=255827270=26.39273=90:24:22271=4400272=2014061037016=2014061037017=61:20:8437=80531933834288=45290=1
10:29:02.432: 658703 - 118 - 1128=935=X34=65870352=20140610-13:29:02.44475=20140610268=2279=2269=022=8207=BVMF48=380968883=253465273=90:24:44272=2014061037=80531943635288=45290=1279=0269=022=8207=BVMF48=380968883=253466270=29.37273=90:24:44271=300272=2014061037016=2014061037017=90:24:4337=80531943895288=45290=4
10:29:02.434: 658704 - 80 - 1128=935=X34=65870452=20140610-13:29:02.44675=20140610268=1279=0269=022=8207=BVMF48=380968883=253467270=29.37273=90:24:45271=100272=2014061037016=2014061037017=90:24:4537=80531943896288=8290=5
10:29:02.436: 658705 - 83 - 1128=935=X34=65870552=20140610-13:29:02.44875=20140610268=1279=0269=122=8207=BVMF48=380965483=79677270=8.24273=90:24:47271=21400272=2014061037016=2014061037017=90:24:4737=80531943897289=16290=22
10:29:02.444: 658706 - 81 - 1128=935=X34=65870652=20140610-13:29:02.45575=20140610268=1279=0269=122=8207=BVMF48=380965483=79678270=8.21273=90:24:55271=900272=2014061037016=2014061037017=90:24:5537=80531943898289=3290=6
10:29:02.445: 658707 - 82 - 1128=935=X34=65870752=20140610-13:29:02.45775=20140610268=1279=0269=122=8207=BVMF48=380965483=79679270=8.2273=90:24:56271=700272=2014061037016=2014061037017=90:24:5637=80531943899289=8290=1
10:29:02.446: 658708 - 82 - 1128=935=X34=65870852=20140610-13:29:02.45875=20140610268=1279=0269=122=8207=BVMF48=380965483=79680270=8.2273=90:24:57271=500272=2014061037016=2014061037017=90:24:5737=80531943900289=8290=2
10:29:02.447: 658709 - 81 - 1128=935=X34=65870952=20140610-13:29:02.45975=20140610268=1279=0269=122=8207=BVMF48=380977983=20262270=7.38273=90:24:58271=700272=2014061037016=2014061037017=90:24:5837=80531943902289=3290=4
10:29:02.467: 658710 - 246 - 1128=935=X34=65871052=20140610-13:29:02.47875=20140610268=6279=0269=222=8207=BVMF48=380249383=103507270=9.34273=90:24:78271=100272=2014061037016=2014061037017=90:24:771500=E451=-0.111020=261400274=3277=L1003=3720288=40289=735279=0269=922=8207=BVMF48=380249383=103508270=9.381273=90:24:78272=201406101500=E279=0269=222=8207=BVMF48=380249383=103509270=9.34273=90:24:78271=100272=2014061037016=2014061037017=90:24:771500=E451=-0.111020=261500274=3277=L1003=3730288=40289=735279=0269=922=8207=BVMF48=380249383=103510270=9.381273=90:24:78272=201406101500=E279=4269=022=8207=BVMF48=380249383=103511273=90:24:78272=20140610290=2279=2269=122=8207=BVMF48=380249383=103512273=90:24:78272=2014061037=80531942293289=735290=6
10:29:02.485: 658711 - 70 - 1128=935=X34=65871152=20140610-13:29:02.49775=20140610268=1279=2269=022=8207=BVMF48=380391383=106197273=90:24:97272=2014061037=80531942716288=8290=36
10:29:02.528: 658712 - 80 - 1128=935=X34=65871252=20140610-13:29:02.53975=20140610268=1279=0269=022=8207=BVMF48=380391383=106198270=13.78273=90:25:39271=300272=2014061037016=2014061037017=90:25:3937=80531943927288=8290=36
10:29:02.543: 658713 - 70 - 1128=935=X34=65871352=20140610-13:29:02.55575=20140610268=1279=2269=022=8207=BVMF48=380249383=103513273=90:25:55272=2014061037=80531942239288=8290=20
10:29:02.555: 658714 - 83 - 1128=935=X34=65871452=20140610-13:29:02.56775=20140610268=1279=0269=122=8207=BVMF48=380249383=103514270=9.35273=90:25:66271=300272=2014061037016=2014061037017=90:25:6637=80531943928289=735290=7
10:29:02.592: 658715 - 70 - 1128=935=X34=65871552=20140610-13:29:02.60475=20140610268=1279=2269=022=8207=BVMF48=380977983=20263273=90:26:03272=2014061037=80531943153288=8290=2
10:29:03.208: 658716 - 183 - 1128=935=X34=65871652=20140610-13:29:03.22075=20140610268=4279=0269=222=8207=BVMF48=380391383=106199270=13.85273=90:32:19271=100272=2014061037016=2014061037017=90:32:191500=E451=-0.041020=109000274=01003=3390288=8289=238279=0269=922=8207=BVMF48=380391383=106200270=13.877273=90:32:19272=201406101500=E279=2269=022=8207=BVMF48=380391383=106201273=90:32:19272=2014061037=80531943647288=8290=3279=2269=122=8207=BVMF48=380391383=106202273=90:32:19272=2014061037=80531935233289=238290=1
10:29:03.400: 658717 - 160 - 1128=935=X34=65871752=20140610-13:29:03.41275=20140610268=3279=0269=222=8207=BVMF48=380963983=255828270=26.4273=90:34:11271=100272=2014061037016=2014061037017=90:34:111500=E451=-0.211020=1406400274=01003=19000288=3289=85279=0269=922=8207=BVMF48=380963983=255829270=26.47273=90:34:11272=201406101500=E279=1269=122=8207=BVMF48=380963983=255830270=26.4273=90:34:11271=3300272=2014061037016=2014061037017=83:31:6237=80531942464289=85290=1
10:29:03.402: 658718 - 81 - 1128=935=X34=65871852=20140610-13:29:03.41375=20140610268=1279=0269=122=8207=BVMF48=380963983=255831270=26.45273=90:34:13271=100272=2014061037016=2014061037017=90:34:1337=80531943956289=8290=36
10:29:03.408: 658719 - 81 - 1128=935=X34=65871952=20140610-13:29:03.42075=20140610268=1279=0269=122=8207=BVMF48=380965483=79681270=8.22273=90:34:19271=2500272=2014061037016=2014061037017=90:34:1937=80531943961289=3290=15
10:29:04.076: 658720 - 72 - 1128=935=X34=65872052=20140610-13:29:04.08875=20140610268=1279=2269=122=8207=BVMF48=380965483=79682273=90:40:88272=2014061037=80531943566289=16290=7
10:29:04.080: 658721 - 153 - 1128=935=X34=65872152=20140610-13:29:04.09175=20140610268=3279=0269=222=8207=BVMF48=380965483=79683270=8.19273=90:40:91271=100272=2014061037016=2014061037017=90:40:901500=E451=-0.091020=262600274=3277=L1003=3280288=8289=16279=0269=922=8207=BVMF48=380965483=79684270=8.243273=90:40:91272=201406101500=E279=1269=022=8207=BVMF48=380965483=79685270=8.19273=90:40:91271=500272=2014061037016=2014061037017=90:16:1537=80531943704288=8290=1
10:29:04.425: 658722 - 81 - 1128=935=X34=65872252=20140610-13:29:04.43775=20140610268=1279=0269=022=8207=BVMF48=380963983=255832270=26.39273=90:44:36271=100272=2014061037016=2014061037017=90:44:3537=80531944039288=74290=7
10:29:04.566: 658723 - 147 - 1128=935=X34=65872352=20140610-13:29:04.57875=20140610268=3279=0269=222=8207=BVMF48=380391383=106203270=13.84273=90:45:77271=100272=2014061037016=2014061037017=90:45:771500=E451=-0.051020=109100274=21003=3400288=40289=227279=0269=922=8207=BVMF48=380391383=106204270=13.877273=90:45:77272=201406101500=E279=2269=022=8207=BVMF48=380391383=106205273=90:45:77272=2014061037=80531942697288=40290=1
10:29:05.048: 658724 - 72 - 1128=935=X34=65872452=20140610-13:29:05.06075=20140610268=1279=2269=122=8207=BVMF48=380249383=103515273=90:50:60272=2014061037=80531942772289=16290=51
10:29:05.143: 658725 - 677 - 1128=935=X34=65872552=20140610-13:29:05.15475=20140610268=17279=0269=222=8207=BVMF48=380963983=255833270=26.4273=90:51:53271=3300272=2014061037016=2014061037017=90:51:521500=E451=-0.211020=1409700274=1277=L1003=19010288=37289=85279=0269=922=8207=BVMF48=380963983=255834270=26.47273=90:51:53272=201406101500=E279=0269=222=8207=BVMF48=380963983=255835270=26.4273=90:51:53271=300272=2014061037016=2014061037017=90:51:521500=E451=-0.211020=1410000274=1277=L1003=19020288=37289=45279=0269=922=8207=BVMF48=380963983=255836270=26.47273=90:51:53272=201406101500=E279=0269=222=8207=BVMF48=380963983=255837270=26.4273=90:51:53271=900272=2014061037016=2014061037017=90:51:521500=E451=-0.211020=1410900274=1277=L1003=19030288=37289=40279=0269=922=8207=BVMF48=380963983=255838270=26.47273=90:51:53272=201406101500=E279=0269=222=8207=BVMF48=380963983=255839270=26.4273=90:51:53271=200272=2014061037016=2014061037017=90:51:521500=E451=-0.211020=1411100274=1277=L1003=19040288=37289=238279=0269=922=8207=BVMF48=380963983=255840270=26.47273=90:51:53272=201406101500=E279=0269=222=8207=BVMF48=380963983=255841270=26.4273=90:51:53271=300272=2014061037016=2014061037017=90:51:521500=E451=-0.211020=1411400274=1277=L1003=19050288=37289=27279=0269=922=8207=BVMF48=380963983=255842270=26.47273=90:51:53272=201406101500=E279=0269=222=8207=BVMF48=380963983=255843270=26.4273=90:51:53271=200272=2014061037016=2014061037017=90:51:521500=E451=-0.211020=1411600274=1277=L1003=19060288=37289=238279=0269=922=8207=BVMF48=380963983=255844270=26.47273=90:51:53272=201406101500=E279=4269=122=8207=BVMF48=380963983=255845273=90:51:53272=20140610290=6279=0269=122=8207=BVMF48=380963983=255846270=26.4273=90:51:53271=5000272=2014061037016=2014061037017=90:51:5237=80531944069289=85290=1279=0269=222=8207=BVMF48=380963983=255847270=26.4273=90:51:53271=100272=2014061037016=2014061037017=90:51:521500=E451=-0.211020=1411700274=1277=L1003=19070288=37289=85279=0269=922=8207=BVMF48=380963983=255848270=26.47273=90:51:53272=201406101500=E279=1269=122=8207=BVMF48=380963983=255849270=26.4273=90:51:53271=4900272=2014061037016=2014061037017=90:51:5237=80531944069289=85290=1
10:29:05.144: 658726 - 81 - 1128=935=X34=65872652=20140610-13:29:05.15675=20140610268=1279=0269=122=8207=BVMF48=380249383=103516270=9.36273=90:51:55271=100272=2014061037016=2014061037017=90:51:5537=80531944070289=8290=11
10:29:05.144: 658727 - 80 - 1128=935=X34=65872752=20140610-13:29:05.15675=20140610268=1279=0269=022=8207=BVMF48=380963983=255850270=26.36273=90:51:56271=100272=2014061037016=2014061037017=90:51:5537=80531944071288=8290=26
10:29:05.149: 658728 - 81 - 1128=935=X34=65872852=20140610-13:29:05.16175=20140610268=1279=0269=122=8207=BVMF48=380963983=255851270=26.41273=90:51:61271=100272=2014061037016=2014061037017=90:51:6137=80531944082289=8290=3
10:29:05.155: 658729 - 83 - 1128=935=X34=65872952=20140610-13:29:05.16675=20140610268=1279=0269=122=8207=BVMF48=380963983=255852270=26.4273=90:51:66271=4600272=2014061037016=2014061037017=90:51:6637=80531944083289=45290=2
10:29:05.156: 658730 - 71 - 1128=935=X34=65873052=20140610-13:29:05.16775=20140610268=1279=2269=122=8207=BVMF48=380963983=255853273=90:51:67272=2014061037=80531942087289=8290=9
10:29:05.158: 658731 - 81 - 1128=935=X34=65873152=20140610-13:29:05.16975=20140610268=1279=0269=122=8207=BVMF48=380963983=255854270=26.41273=90:51:69271=700272=2014061037016=2014061037017=90:51:6937=80531944090289=3290=5
10:29:05.171: 658732 - 72 - 1128=935=X34=65873252=20140610-13:29:05.18375=20140610268=1279=2269=122=8207=BVMF48=380963983=255855273=90:51:82272=2014061037=80531940995289=40290=6
10:29:05.173: 658733 - 72 - 1128=935=X34=65873352=20140610-13:29:05.18575=20140610268=1279=2269=122=8207=BVMF48=380963983=255856273=90:51:84272=2014061037=80531941545289=40290=7
10:29:05.176: 658734 - 82 - 1128=935=X34=65873452=20140610-13:29:05.18875=20140610268=1279=0269=122=8207=BVMF48=380963983=255857270=26.41273=90:51:88271=900272=2014061037016=2014061037017=90:51:8837=80531944177289=40290=6
10:29:05.177: 658735 - 70 - 1128=935=X34=65873552=20140610-13:29:05.18975=20140610268=1279=2269=022=8207=BVMF48=380963983=255858273=90:51:88272=2014061037=80531943003288=3290=5
10:29:05.202: 658736 - 120 - 1128=935=X34=65873652=20140610-13:29:05.21475=20140610268=2279=2269=122=8207=BVMF48=380963983=255859273=90:52:14272=2014061037=80531944177289=40290=6279=0269=122=8207=BVMF48=380963983=255860270=26.4273=90:52:14271=900272=2014061037016=2014061037017=90:52:1337=80531944188289=40290=3
10:29:05.293: 658737 - 83 - 1128=935=X34=65873752=20140610-13:29:05.30575=20140610268=1279=0269=122=8207=BVMF48=380963983=255861270=26.4273=90:53:05271=1000272=2014061037016=2014061037017=90:53:0537=80531944211289=40290=4
10:29:05.402: 658738 - 82 - 1128=935=X34=65873852=20140610-13:29:05.41475=20140610268=1279=0269=122=8207=BVMF48=380968883=253468270=29.41273=90:54:13271=1300272=2014061037016=2014061037017=90:54:1337=80531944214289=13290=10
10:29:05.868: 658739 - 83 - 1128=935=X34=65873952=20140610-13:29:05.88075=20140610268=1279=0269=122=8207=BVMF48=380249383=103517270=9.39273=90:58:79271=11600272=2014061037016=2014061037017=90:58:7937=80531944230289=16290=21
10:29:06.144: 658740 - 70 - 1128=935=X34=65874052=20140610-13:29:06.15675=20140610268=1279=2269=022=8207=BVMF48=380963983=255862273=90:61:55272=2014061037=80531944071288=8290=25
10:29:06.358: 658741 - 190 - 1128=935=X34=65874152=20140610-13:29:06.37175=20140610268=4279=0269=222=8207=BVMF48=380965483=79686270=8.19273=90:63:70271=500272=2014061037016=2014061037017=90:63:701500=E451=-0.091020=263100274=3277=L1003=3290288=8289=8279=0269=922=8207=BVMF48=380965483=79687270=8.243273=90:63:70272=201406101500=E279=2269=022=8207=BVMF48=380965483=79688273=90:63:70272=2014061037=80531943704288=8290=1279=0269=122=8207=BVMF48=380965483=79689270=8.19273=90:63:70271=19500272=2014061037016=2014061037017=90:63:7037=80531944232289=8290=1
10:29:06.360: 658742 - 81 - 1128=935=X34=65874252=20140610-13:29:06.37275=20140610268=1279=0269=122=8207=BVMF48=380965483=79690270=8.19273=90:63:72271=500272=2014061037016=2014061037017=90:63:7137=80531944233289=8290=2
10:29:06.360: 658743 - 80 - 1128=935=X34=65874352=20140610-13:29:06.37275=20140610268=1279=0269=022=8207=BVMF48=380965483=79691270=8.16273=90:63:72271=500272=2014061037016=2014061037017=90:63:7237=80531944234288=8290=23
10:29:06.361: 658744 - 153 - 1128=935=X34=65874452=20140610-13:29:06.37275=20140610268=3279=0269=222=8207=BVMF48=380965483=79692270=8.19273=90:63:72271=300272=2014061037016=2014061037017=90:63:721500=E451=-0.091020=263400274=3277=L1003=3300288=8289=8279=0269=922=8207=BVMF48=380965483=79693270=8.243273=90:63:72272=201406101500=E279=1269=122=8207=BVMF48=380965483=79694270=8.19273=90:63:72271=19200272=2014061037016=2014061037017=90:63:7037=80531944232289=8290=1
10:29:06.361: 658745 - 71 - 1128=935=X34=65874552=20140610-13:29:06.37375=20140610268=1279=2269=122=8207=BVMF48=380965483=79695273=90:63:72272=2014061037=80531935468289=8290=86
10:29:06.361: 658746 - 81 - 1128=935=X34=65874652=20140610-13:29:06.37375=20140610268=1279=0269=122=8207=BVMF48=380977983=20264270=7.38273=90:63:73271=1600272=2014061037016=2014061037017=90:63:7237=80531944237289=3290=5
10:29:06.362: 658747 - 117 - 1128=935=X34=65874752=20140610-13:29:06.37475=20140610268=2279=2269=122=8207=BVMF48=380977983=20265273=90:63:73272=2014061037=80531943902289=3290=4279=0269=122=8207=BVMF48=380977983=20266270=7.37273=90:63:73271=3200272=2014061037016=2014061037017=90:63:7337=80531944241289=3290=1
10:29:06.363: 658748 - 80 - 1128=935=X34=65874852=20140610-13:29:06.37475=20140610268=1279=0269=022=8207=BVMF48=380965483=79696270=8.18273=90:63:74271=400272=2014061037016=2014061037017=90:63:7437=80531944245288=3290=10
10:29:06.363: 658749 - 70 - 1128=935=X34=65874952=20140610-13:29:06.37575=20140610268=1279=2269=022=8207=BVMF48=380977983=20267273=90:63:75272=2014061037=80531943882288=8290=2
10:29:06.366: 658750 - 71 - 1128=935=X34=65875052=20140610-13:29:06.37875=20140610268=1279=2269=122=8207=BVMF48=380977983=20268273=90:63:78272=2014061037=80531944237289=3290=5
10:29:06.369: 658751 - 79 - 1128=935=X34=65875152=20140610-13:29:06.38175=20140610268=1279=1269=022=8207=BVMF48=380965483=79697270=8.18273=90:63:81271=300272=2014061037016=2014061037017=90:63:7437=80531944306288=3290=10
10:29:06.449: 658752 - 81 - 1128=935=X34=65875252=20140610-13:29:06.46175=20140610268=1279=0269=122=8207=BVMF48=380977983=20269270=7.38273=90:64:60271=100272=2014061037016=2014061037017=90:64:6037=80531944348289=8290=5
10:29:06.449: 658753 - 80 - 1128=935=X34=65875352=20140610-13:29:06.46175=20140610268=1279=0269=022=8207=BVMF48=380977983=20270270=7.36273=90:64:61271=100272=2014061037016=2014061037017=90:64:6037=80531944349288=8290=2
10:29:06.450: 658754 - 71 - 1128=935=X34=65875452=20140610-13:29:06.46175=20140610268=1279=2269=122=8207=BVMF48=380977983=20271273=90:64:61272=2014061037=80531944348289=8290=5
10:29:06.450: 658755 - 70 - 1128=935=X34=65875552=20140610-13:29:06.46275=20140610268=1279=2269=022=8207=BVMF48=380977983=20272273=90:64:61272=2014061037=80531944349288=8290=2
10:29:06.561: 658756 - 72 - 1128=935=X34=65875652=20140610-13:29:06.57375=20140610268=1279=2269=122=8207=BVMF48=380977983=20273273=90:65:73272=2014061037=80531917998289=40290=24
10:29:06.564: 658757 - 72 - 1128=935=X34=65875752=20140610-13:29:06.57675=20140610268=1279=2269=122=8207=BVMF48=380977983=20274273=90:65:76272=2014061037=80531918003289=40290=26
10:29:06.565: 658758 - 72 - 1128=935=X34=65875852=20140610-13:29:06.57775=20140610268=1279=2269=122=8207=BVMF48=380965483=79698273=90:65:76272=2014061037=80531943881289=40290=38
10:29:06.566: 658759 - 72 - 1128=935=X34=65875952=20140610-13:29:06.57875=20140610268=1279=2269=122=8207=BVMF48=380965483=79699273=90:65:78272=2014061037=80531943880289=40290=51
10:29:06.567: 658760 - 71 - 1128=935=X34=65876052=20140610-13:29:06.57975=20140610268=1279=2269=022=8207=BVMF48=380965483=79700273=90:65:78272=2014061037=80531940284288=40290=42
10:29:06.567: 658761 - 71 - 1128=935=X34=65876152=20140610-13:29:06.57975=20140610268=1279=2269=022=8207=BVMF48=380965483=79701273=90:65:79272=2014061037=80531940285288=40290=52
10:29:06.713: 658762 - 82 - 1128=935=X34=65876252=20140610-13:29:06.72575=20140610268=1279=0269=122=8207=BVMF48=380977983=20275270=7.46273=90:67:24271=200272=2014061037016=2014061037017=90:67:2437=80531944414289=40290=23
10:29:06.713: 658763 - 82 - 1128=935=X34=65876352=20140610-13:29:06.72575=20140610268=1279=0269=122=8207=BVMF48=380965483=79702270=8.29273=90:67:24271=4400272=2014061037016=2014061037017=90:67:2437=80531944415289=40290=56
10:29:06.714: 658764 - 83 - 1128=935=X34=65876452=20140610-13:29:06.72675=20140610268=1279=0269=122=8207=BVMF48=380965483=79703270=8.27273=90:67:26271=8600272=2014061037016=2014061037017=90:67:2637=80531944416289=40290=45
10:29:06.714: 658765 - 82 - 1128=935=X34=65876552=20140610-13:29:06.72675=20140610268=1279=0269=122=8207=BVMF48=380977983=20276270=7.44273=90:67:26271=500272=2014061037016=2014061037017=90:67:2637=80531944417289=40290=19
10:29:06.715: 658766 - 81 - 1128=935=X34=65876652=20140610-13:29:06.72775=20140610268=1279=0269=022=8207=BVMF48=380965483=79704270=8.13273=90:67:27271=4500272=2014061037016=2014061037017=90:67:2737=80531944418288=40290=53
10:29:06.717: 658767 - 81 - 1128=935=X34=65876752=20140610-13:29:06.72975=20140610268=1279=0269=022=8207=BVMF48=380965483=79705270=8.11273=90:67:29271=2800272=2014061037016=2014061037017=90:67:2937=80531944419288=40290=63
10:29:06.844: 658768 - 71 - 1128=935=X34=65876852=20140610-13:29:06.85675=20140610268=1279=2269=122=8207=BVMF48=380965483=79706273=90:68:55272=2014061037=80531927330289=8290=21
10:29:06.844: 658769 - 71 - 1128=935=X34=65876952=20140610-13:29:06.85675=20140610268=1279=2269=122=8207=BVMF48=380965483=79707273=90:68:55272=2014061037=80531941374289=8290=12
10:29:06.946: 658770 - 119 - 1128=935=X34=65877052=20140610-13:29:06.95875=20140610268=2279=2269=122=8207=BVMF48=380977983=20277273=90:69:57272=2014061037=80531932633289=40290=5279=0269=122=8207=BVMF48=380977983=20278270=7.37273=90:69:57271=300272=2014061037016=2014061037017=90:69:5737=80531944420289=40290=2
10:29:07.305: 658771 - 71 - 1128=935=X34=65877152=20140610-13:29:07.31775=20140610268=1279=2269=122=8207=BVMF48=380653683=6230273=90:73:16272=2014061037=80531928949289=72290=3
10:29:07.306: 658772 - 80 - 1128=935=X34=65877252=20140610-13:29:07.31875=20140610268=1279=0269=122=8207=BVMF48=380653683=6231270=3.14273=90:73:18271=100272=2014061037016=2014061037017=90:73:1737=80531944427289=8290=4
10:29:07.592: 658773 - 71 - 1128=935=X34=65877352=20140610-13:29:07.60475=20140610268=1279=2269=122=8207=BVMF48=380977983=20279273=90:76:03272=2014061037=80531943717289=8290=5
10:29:07.910: 658774 - 80 - 1128=935=X34=65877452=20140610-13:29:07.92275=20140610268=1279=0269=022=8207=BVMF48=380965483=79708270=8.18273=90:79:21271=3500272=2014061037016=2014061037017=90:79:2137=80531944447288=9290=11
10:29:07.911: 658775 - 153 - 1128=935=X34=65877552=20140610-13:29:07.92375=20140610268=3279=0269=222=8207=BVMF48=380965483=79709270=8.19273=90:79:23271=300272=2014061037016=2014061037017=90:79:221500=E451=-0.091020=263700274=3277=L1003=3310288=8289=8279=0269=922=8207=BVMF48=380965483=79710270=8.243273=90:79:23272=201406101500=E279=1269=122=8207=BVMF48=380965483=79711270=8.19273=90:79:23271=18900272=2014061037016=2014061037017=90:63:7037=80531944232289=8290=1
10:29:07.912: 658776 - 153 - 1128=935=X34=65877652=20140610-13:29:07.92475=20140610268=3279=0269=222=8207=BVMF48=380965483=79712270=8.19273=90:79:23271=500272=2014061037016=2014061037017=90:79:231500=E451=-0.091020=264200274=3277=L1003=3320288=8289=8279=0269=922=8207=BVMF48=380965483=79713270=8.243273=90:79:23272=201406101500=E279=1269=122=8207=BVMF48=380965483=79714270=8.19273=90:79:23271=18400272=2014061037016=2014061037017=90:63:7037=80531944232289=8290=1
10:29:07.912: 658777 - 153 - 1128=935=X34=65877752=20140610-13:29:07.92475=20140610268=3279=0269=222=8207=BVMF48=380965483=79715270=8.19273=90:79:23271=2600272=2014061037016=2014061037017=90:79:231500=E451=-0.091020=266800274=3277=L1003=3330288=8289=8279=0269=922=8207=BVMF48=380965483=79716270=8.242273=90:79:23272=201406101500=E279=1269=122=8207=BVMF48=380965483=79717270=8.19273=90:79:23271=15800272=2014061037016=2014061037017=90:63:7037=80531944232289=8290=1
10:29:07.913: 658778 - 80 - 1128=935=X34=65877852=20140610-13:29:07.92575=20140610268=1279=0269=022=8207=BVMF48=380965483=79718270=8.18273=90:79:24271=400272=2014061037016=2014061037017=90:79:2437=80531944451288=8290=12
10:29:07.914: 658779 - 201 - 1128=935=X34=65877952=20140610-13:29:07.92575=20140610268=5279=0269=222=8207=BVMF48=380965483=79719270=8.19273=90:79:25271=15800272=2014061037016=2014061037017=90:79:251500=E451=-0.091020=282600274=3277=L1003=3340288=8289=8279=0269=922=8207=BVMF48=380965483=79720270=8.239273=90:79:25272=201406101500=E279=0269=222=8207=BVMF48=380965483=79721270=8.19273=90:79:25271=500272=2014061037016=2014061037017=90:79:251500=E451=-0.091020=283100274=3277=L1003=3350288=8289=8279=0269=922=8207=BVMF48=380965483=79722270=8.239273=90:79:25272=201406101500=E279=4269=122=8207=BVMF48=380965483=79723273=90:79:25272=20140610290=2
10:29:07.917: 658780 - 71 - 1128=935=X34=65878052=20140610-13:29:07.92975=20140610268=1279=2269=122=8207=BVMF48=380965483=79724273=90:79:26272=2014061037=80531934264289=8290=80
10:29:07.917: 658781 - 80 - 1128=935=X34=65878152=20140610-13:29:07.92975=20140610268=1279=0269=022=8207=BVMF48=380965483=79725270=8.19273=90:79:26271=700272=2014061037016=2014061037017=90:79:2637=80531944453288=8290=1
10:29:07.917: 658782 - 71 - 1128=935=X34=65878252=20140610-13:29:07.92975=20140610268=1279=2269=122=8207=BVMF48=380977983=20280273=90:79:27272=2014061037=80531944241289=3290=1
10:29:07.919: 658783 - 80 - 1128=935=X34=65878352=20140610-13:29:07.93175=20140610268=1279=0269=022=8207=BVMF48=380965483=79726270=8.18273=90:79:31271=500272=2014061037016=2014061037017=90:79:3137=80531944479288=8290=14
10:29:07.919: 658784 - 70 - 1128=935=X34=65878452=20140610-13:29:07.93275=20140610268=1279=2269=022=8207=BVMF48=380965483=79727273=90:79:31272=2014061037=80531944306288=3290=11
10:29:07.949: 658785 - 71 - 1128=935=X34=65878552=20140610-13:29:07.96175=20140610268=1279=2269=122=8207=BVMF48=380965483=79728273=90:79:60272=2014061037=80531943221289=8290=11
10:29:08.074: 658786 - 153 - 1128=935=X34=65878652=20140610-13:29:08.08675=20140610268=3279=0269=222=8207=BVMF48=380965483=79729270=8.19273=90:80:85271=100272=2014061037016=2014061037017=90:80:851500=E451=-0.091020=283200274=3277=L1003=3360288=8289=16279=0269=922=8207=BVMF48=380965483=79730270=8.239273=90:80:85272=201406101500=E279=1269=022=8207=BVMF48=380965483=79731270=8.19273=90:80:85271=600272=2014061037016=2014061037017=90:79:2637=80531944453288=8290=1
10:29:08.131: 658787 - 70 - 1128=935=X34=65878752=20140610-13:29:08.14375=20140610268=1279=2269=122=8207=BVMF48=380653683=6232273=90:81:42272=2014061037=80531944427289=8290=4
10:29:09.991: 658788 - 69 - 1128=935=X34=65878852=20140610-13:29:10.00375=20140610268=1279=2269=022=8207=BVMF48=380653683=6233273=91:00:03272=2014061037=80531941414288=8290=4
10:29:09.992: 658789 - 79 - 1128=935=X34=65878952=20140610-13:29:10.00575=20140610268=1279=0269=022=8207=BVMF48=380653683=6234270=3.12273=91:00:04271=100272=2014061037016=2014061037017=91:00:0437=80531944631288=8290=4
10:29:10.385: 658790 - 152 - 1128=935=X34=65879052=20140610-13:29:10.39775=20140610268=3279=0269=222=8207=BVMF48=380965483=79732270=8.19273=91:03:96271=100272=2014061037016=2014061037017=91:03:961500=E451=-0.091020=283300274=3277=L1003=3370288=8289=8279=0269=922=8207=BVMF48=380965483=79733270=8.239273=91:03:96272=201406101500=E279=1269=022=8207=BVMF48=380965483=79734270=8.19273=91:03:96271=500272=2014061037016=2014061037017=90:79:2637=80531944453288=8290=1
10:29:10.386: 658791 - 158 - 1128=935=X34=65879152=20140610-13:29:10.39775=20140610268=3279=0269=222=8207=BVMF48=380963983=255863270=26.39273=91:03:97271=100272=2014061037016=2014061037017=91:03:961500=E451=-0.221020=1411800274=21003=19080288=45289=8279=0269=922=8207=BVMF48=380963983=255864270=26.47273=91:03:97272=201406101500=E279=1269=022=8207=BVMF48=380963983=255865270=26.39273=91:03:97271=4300272=2014061037016=2014061037017=61:20:8437=80531933834288=45290=1
10:29:10.386: 658792 - 156 - 1128=935=X34=65879252=20140610-13:29:10.39875=20140610268=3279=0269=222=8207=BVMF48=380968883=253469270=29.37273=91:03:98271=100272=2014061037016=2014061037017=91:03:971500=E451=-0.261020=448800274=21003=6500288=27289=8279=0269=922=8207=BVMF48=380968883=253470270=29.478273=91:03:98272=201406101500=E279=1269=022=8207=BVMF48=380968883=253471270=29.37273=91:03:98271=4600272=2014061037016=2014061037017=55:33:0337=80531931833288=27290=1
10:29:10.387: 658793 - 80 - 1128=935=X34=65879352=20140610-13:29:10.39975=20140610268=1279=0269=022=8207=BVMF48=380963983=255866270=26.36273=91:03:99271=100272=2014061037016=2014061037017=91:03:9837=80531944636288=8290=25
10:29:10.933: 658794 - 410 - 1128=935=X34=65879452=20140610-13:29:10.94575=20140610268=10279=0269=222=8207=BVMF48=380963983=255867270=26.4273=91:09:44271=4900272=2014061037016=2014061037017=91:09:431500=E451=-0.211020=1416700274=01003=19090288=37289=85279=0269=922=8207=BVMF48=380963983=255868270=26.469273=91:09:44272=201406101500=E279=0269=222=8207=BVMF48=380963983=255869270=26.4273=91:09:44271=4600272=2014061037016=2014061037017=91:09:431500=E451=-0.211020=1421300274=1277=L1003=19100288=37289=45279=0269=922=8207=BVMF48=380963983=255870270=26.469273=91:09:44272=201406101500=E279=0269=222=8207=BVMF48=380963983=255871270=26.4273=91:09:44271=900272=2014061037016=2014061037017=91:09:431500=E451=-0.211020=1422200274=1277=L1003=19110288=37289=40279=0269=922=8207=BVMF48=380963983=255872270=26.469273=91:09:44272=201406101500=E279=0269=222=8207=BVMF48=380963983=255873270=26.4273=91:09:44271=1000272=2014061037016=2014061037017=91:09:431500=E451=-0.211020=1423200274=1277=L1003=19120288=37289=40279=0269=922=8207=BVMF48=380963983=255874270=26.469273=91:09:44272=201406101500=E279=4269=122=8207=BVMF48=380963983=255875273=91:09:44272=20140610290=4279=0269=122=8207=BVMF48=380963983=255876270=26.4273=91:09:44271=5000272=2014061037016=2014061037017=91:09:4337=80531944644289=85290=1
10:29:10.938: 658795 - 71 - 1128=935=X34=65879552=20140610-13:29:10.95075=20140610268=1279=2269=122=8207=BVMF48=380963983=255877273=91:09:49272=2014061037=80531942144289=8290=10
10:29:10.943: 658796 - 71 - 1128=935=X34=65879652=20140610-13:29:10.95575=20140610268=1279=2269=122=8207=BVMF48=380963983=255878273=91:09:54272=2014061037=80531943956289=8290=29
10:29:10.944: 658797 - 83 - 1128=935=X34=65879752=20140610-13:29:10.95675=20140610268=1279=0269=122=8207=BVMF48=380963983=255879270=26.4273=91:09:55271=5000272=2014061037016=2014061037017=91:09:5537=80531944678289=45290=2
10:29:10.960: 658798 - 119 - 1128=935=X34=65879852=20140610-13:29:10.97275=20140610268=2279=2269=122=8207=BVMF48=380963983=255880273=91:09:71272=2014061037=80531941786289=40290=7279=0269=122=8207=BVMF48=380963983=255881270=26.41273=91:09:71271=200272=2014061037016=2014061037017=91:09:7137=80531944695289=40290=6
10:29:10.967: 658799 - 83 - 1128=935=X34=65879952=20140610-13:29:10.97975=20140610268=1279=0269=122=8207=BVMF48=380963983=255882270=26.4273=91:09:78271=900272=2014061037016=2014061037017=91:09:7837=80531944699289=40290=3
10:29:11.010: 658800 - 82 - 1128=935=X34=65880052=20140610-13:29:11.02275=20140610268=1279=0269=122=8207=BVMF48=380391383=106206270=13.86273=91:10:21271=2000272=2014061037016=2014061037017=91:10:2137=80531944707289=39290=5
10:29:11.090: 658801 - 83 - 1128=935=X34=65880152=20140610-13:29:11.10075=20140610268=1279=0269=122=8207=BVMF48=380963983=255883270=26.4273=91:11:00271=200272=2014061037016=2014061037017=91:11:0037=80531944713289=40290=4
10:29:11.662: 658802 - 80 - 1128=935=X34=65880252=20140610-13:29:11.67475=20140610268=1279=0269=022=8207=BVMF48=380965483=79735270=8.19273=91:16:73271=3000272=2014061037016=2014061037017=91:16:7337=80531944773288=3290=2
10:29:11.819: 658803 - 84 - 1128=935=X34=65880352=20140610-13:29:11.83175=20140610268=1279=0269=122=8207=BVMF48=380963983=255884270=26.4273=91:18:30271=200272=2014061037016=2014061037017=91:18:3037=80531944786289=238290=5
10:29:11.839: 658804 - 82 - 1128=935=X34=65880452=20140610-13:29:11.85175=20140610268=1279=0269=122=8207=BVMF48=380963983=255885270=26.4273=91:18:51271=200272=2014061037016=2014061037017=91:18:5037=80531944788289=3290=6
10:29:11.991: 658805 - 64 - 1128=935=X34=65880552=20140610-13:29:12.00375=20140610268=1279=0269=B22=8207=BVMF48=380977983=20281270=325249273=91:19:92271=89272=201406101500=E15=BRL
10:29:12.001: 658806 - 65 - 1128=935=X34=65880652=20140610-13:29:12.01375=20140610268=1279=0269=B22=8207=BVMF48=380965483=79736270=2334102273=91:19:92271=337272=201406101500=E15=BRL
10:29:12.012: 658807 - 64 - 1128=935=X34=65880752=20140610-13:29:12.02475=20140610268=1279=0269=B22=8207=BVMF48=380394783=65781270=324889273=91:19:92271=114272=201406101500=E15=BRL
10:29:12.027: 658808 - 65 - 1128=935=X34=65880852=20140610-13:29:12.04075=20140610268=1279=0269=B22=8207=BVMF48=380968883=253472270=13229708273=91:20:08271=650272=201406101500=E15=BRL
10:29:12.043: 658809 - 65 - 1128=935=X34=65880952=20140610-13:29:12.05575=20140610268=1279=0269=B22=8207=BVMF48=380963983=255886270=37670615273=91:20:08271=1912272=201406101500=E15=BRL
10:29:12.043: 658810 - 65 - 1128=935=X34=65881052=20140610-13:29:12.05575=20140610268=1279=0269=B22=8207=BVMF48=380391383=106207270=1514017273=91:19:92271=340272=201406101500=E15=BRL
10:29:12.061: 658811 - 65 - 1128=935=X34=65881152=20140610-13:29:12.07375=20140610268=1279=0269=B22=8207=BVMF48=380249383=103518270=2453185273=91:20:08271=373272=201406101500=E15=BRL
10:29:12.101: 658812 - 71 - 1128=935=X34=65881252=20140610-13:29:12.11475=20140610268=1279=2269=122=8207=BVMF48=380965483=79737273=91:21:13272=2014061037=80531943900289=8290=2
10:29:12.171: 658813 - 81 - 1128=935=X34=65881352=20140610-13:29:12.18475=20140610268=1279=0269=022=8207=BVMF48=380963983=255887270=26.38273=91:21:83271=800272=2014061037016=2014061037017=91:21:8337=80531944791288=59290=11
10:29:12.180: 658814 - 162 - 1128=935=X34=65881452=20140610-13:29:12.19275=20140610268=3279=0269=222=8207=BVMF48=380963983=255888270=26.4273=91:21:92271=100272=2014061037016=2014061037017=91:21:911500=E451=-0.211020=1423300274=1277=L1003=19130288=735289=85279=0269=922=8207=BVMF48=380963983=255889270=26.469273=91:21:92272=201406101500=E279=1269=122=8207=BVMF48=380963983=255890270=26.4273=91:21:92271=4900272=2014061037016=2014061037017=91:09:4337=80531944644289=85290=1
10:29:12.187: 658815 - 162 - 1128=935=X34=65881552=20140610-13:29:12.19975=20140610268=3279=0269=222=8207=BVMF48=380963983=255891270=26.4273=91:21:98271=200272=2014061037016=2014061037017=91:21:981500=E451=-0.211020=1423500274=1277=L1003=19140288=735289=85279=0269=922=8207=BVMF48=380963983=255892270=26.469273=91:21:98272=201406101500=E279=1269=122=8207=BVMF48=380963983=255893270=26.4273=91:21:98271=4700272=2014061037016=2014061037017=91:09:4337=80531944644289=85290=1
10:29:14.172: 658816 - 81 - 1128=935=X34=65881652=20140610-13:29:14.18475=20140610268=1279=0269=022=8207=BVMF48=380249383=103519270=9.34273=91:41:84271=100272=2014061037016=2014061037017=91:41:8337=80531944798288=40290=3
10:29:14.573: 658817 - 81 - 1128=935=X34=65881752=20140610-13:29:14.58575=20140610268=1279=0269=022=8207=BVMF48=380963983=255894270=26.39273=91:45:84271=100272=2014061037016=2014061037017=91:45:8437=80531944799288=74290=7
10:29:14.592: 658818 - 81 - 1128=935=X34=65881852=20140610-13:29:14.60475=20140610268=1279=0269=022=8207=BVMF48=380963983=255895270=26.39273=91:46:03271=100272=2014061037016=2014061037017=91:46:0337=80531944800288=70290=8
10:29:14.824: 658819 - 81 - 1128=935=X34=65881952=20140610-13:29:14.83675=20140610268=1279=0269=122=8207=BVMF48=380968883=253473270=29.39273=91:48:36271=100272=2014061037016=2014061037017=91:48:3637=80531944802289=3290=6
10:29:15.199: 658820 - 71 - 1128=935=X34=65882052=20140610-13:29:15.21175=20140610268=1279=2269=122=8207=BVMF48=380977983=20282273=91:52:10272=2014061037=80531941470289=8290=6
10:29:15.200: 658821 - 81 - 1128=935=X34=65882152=20140610-13:29:15.21275=20140610268=1279=0269=122=8207=BVMF48=380977983=20283270=7.39273=91:52:12271=100272=2014061037016=2014061037017=91:52:1237=80531944803289=8290=4
10:29:17.284: 658822 - 81 - 1128=935=X34=65882252=20140610-13:29:17.29775=20140610268=1279=0269=022=8207=BVMF48=380249383=103520270=9.34273=91:72:96271=100272=2014061037016=2014061037017=91:72:9637=80531944811288=40290=4
10:29:18.074: 658823 - 316 - 1128=935=X34=65882352=20140610-13:29:18.08675=20140610268=7279=0269=222=8207=BVMF48=380963983=255896270=26.4273=91:80:85271=4700272=2014061037016=2014061037017=91:80:851500=E451=-0.211020=1428200274=1277=L1003=19150288=37289=85279=0269=922=8207=BVMF48=380963983=255897270=26.469273=91:80:85272=201406101500=E279=0269=222=8207=BVMF48=380963983=255898270=26.4273=91:80:85271=1800272=2014061037016=2014061037017=91:80:851500=E451=-0.211020=1430000274=1277=L1003=19160288=37289=45279=0269=922=8207=BVMF48=380963983=255899270=26.469273=91:80:85272=201406101500=E279=2269=122=8207=BVMF48=380963983=255900273=91:80:85272=2014061037=80531944644289=85290=1279=1269=122=8207=BVMF48=380963983=255901270=26.4273=91:80:85271=3200272=2014061037016=2014061037017=91:09:5537=80531944678289=45290=1279=0269=122=8207=BVMF48=380963983=255902270=26.4273=91:80:85271=5000272=2014061037016=2014061037017=91:80:8537=80531944813289=85290=6
10:29:18.086: 658824 - 82 - 1128=935=X34=65882452=20140610-13:29:18.09875=20140610268=1279=1269=122=8207=BVMF48=380963983=255903270=26.4273=91:80:98271=1400272=2014061037016=2014061037017=91:09:5537=80531944815289=45290=1
10:29:18.095: 658825 - 72 - 1128=935=X34=65882552=20140610-13:29:18.10775=20140610268=1279=2269=122=8207=BVMF48=380963983=255904273=91:81:06272=2014061037=80531944815289=45290=1
10:29:18.104: 658826 - 83 - 1128=935=X34=65882652=20140610-13:29:18.11675=20140610268=1279=0269=122=8207=BVMF48=380963983=255905270=26.4273=91:81:16271=6300272=2014061037016=2014061037017=91:81:1637=80531944819289=45290=6
10:29:18.130: 658827 - 120 - 1128=935=X34=65882752=20140610-13:29:18.14375=20140610268=2279=2269=122=8207=BVMF48=380963983=255906273=91:81:42272=2014061037=80531944695289=40290=10279=0269=122=8207=BVMF48=380963983=255907270=26.4273=91:81:42271=200272=2014061037016=2014061037017=91:81:4237=80531944820289=40290=7
10:29:18.178: 658828 - 82 - 1128=935=X34=65882852=20140610-13:29:18.19075=20140610268=1279=0269=122=8207=BVMF48=380965483=79738270=8.2273=91:81:89271=200272=2014061037016=2014061037017=91:81:8937=80531944821289=3290=2
10:29:18.298: 658829 - 83 - 1128=935=X34=65882952=20140610-13:29:18.31175=20140610268=1279=0269=122=8207=BVMF48=380963983=255908270=26.4273=91:83:10271=500272=2014061037016=2014061037017=91:83:1037=80531944823289=77290=8
10:29:18.921: 658830 - 81 - 1128=935=X34=65883052=20140610-13:29:18.93475=20140610268=1279=0269=122=8207=BVMF48=380391383=106208270=13.85273=91:89:33271=100272=2014061037016=2014061037017=91:89:3337=80531944825289=3290=2
10:29:19.010: 658831 - 158 - 1128=935=X34=65883152=20140610-13:29:19.02375=20140610268=3279=0269=222=8207=BVMF48=380963983=255909270=26.39273=91:90:22271=1000272=2014061037016=2014061037017=91:90:221500=E451=-0.221020=1431000274=21003=19170288=45289=3279=0269=922=8207=BVMF48=380963983=255910270=26.469273=91:90:22272=201406101500=E279=1269=022=8207=BVMF48=380963983=255911270=26.39273=91:90:22271=3300272=2014061037016=2014061037017=61:20:8437=80531933834288=45290=1
10:29:19.012: 658832 - 72 - 1128=935=X34=65883252=20140610-13:29:19.02475=20140610268=1279=2269=122=8207=BVMF48=380963983=255912273=91:90:24272=2014061037=80531942576289=45290=57
10:29:19.144: 658833 - 70 - 1128=935=X34=65883352=20140610-13:29:19.15675=20140610268=1279=2269=022=8207=BVMF48=380963983=255913273=91:91:55272=2014061037=80531944636288=8290=28
10:29:19.290: 658834 - 255 - 1128=935=X34=65883452=20140610-13:29:19.30275=20140610268=6279=0269=222=8207=BVMF48=380965483=79739270=8.2273=91:93:02271=700272=2014061037016=2014061037017=91:93:011500=E451=-0.081020=284000274=01003=3380288=129289=8279=0269=922=8207=BVMF48=380965483=79740270=8.239273=91:93:02272=201406101500=E279=0269=222=8207=BVMF48=380965483=79741270=8.2273=91:93:02271=200272=2014061037016=2014061037017=91:93:011500=E451=-0.081020=284200274=1277=L1003=3390288=129289=3279=0269=922=8207=BVMF48=380965483=79742270=8.239273=91:93:02272=201406101500=E279=4269=122=8207=BVMF48=380965483=79743273=91:93:02272=20140610290=2279=0269=022=8207=BVMF48=380965483=79744270=8.2273=91:93:02271=4100272=2014061037016=2014061037017=91:93:0137=80531944851288=129290=1
10:29:19.291: 658835 - 80 - 1128=935=X34=65883552=20140610-13:29:19.30475=20140610268=1279=0269=022=8207=BVMF48=380965483=79745270=8.19273=91:93:03271=500272=2014061037016=2014061037017=91:93:0337=80531944853288=8290=4
10:29:19.440: 658836 - 71 - 1128=935=X34=65883652=20140610-13:29:19.45375=20140610268=1279=2269=122=8207=BVMF48=380391383=106209273=91:94:53272=2014061037=80531941501289=8290=11
10:29:19.442: 658837 - 81 - 1128=935=X34=65883752=20140610-13:29:19.45475=20140610268=1279=0269=122=8207=BVMF48=380391383=106210270=13.87273=91:94:54271=100272=2014061037016=2014061037017=91:94:5437=80531945019289=8290=11
10:29:19.462: 658838 - 71 - 1128=935=X34=65883852=20140610-13:29:19.47475=20140610268=1279=2269=022=8207=BVMF48=380965483=79746273=91:94:74272=2014061037=80531944418288=40290=59
10:29:19.463: 658839 - 72 - 1128=935=X34=65883952=20140610-13:29:19.47675=20140610268=1279=2269=122=8207=BVMF48=380965483=79747273=91:94:75272=2014061037=80531944416289=40290=38
10:29:19.465: 658840 - 72 - 1128=935=X34=65884052=20140610-13:29:19.47875=20140610268=1279=2269=122=8207=BVMF48=380965483=79748273=91:94:77272=2014061037=80531944415289=40290=49
10:29:19.472: 658841 - 71 - 1128=935=X34=65884152=20140610-13:29:19.48575=20140610268=1279=2269=022=8207=BVMF48=380965483=79749273=91:94:84272=2014061037=80531944419288=40290=68
10:29:19.616: 658842 - 82 - 1128=935=X34=65884252=20140610-13:29:19.62875=20140610268=1279=0269=122=8207=BVMF48=380965483=79750270=8.26273=91:96:28271=4900272=2014061037016=2014061037017=91:96:2837=80531945020289=40290=31
10:29:19.617: 658843 - 82 - 1128=935=X34=65884352=20140610-13:29:19.63075=20140610268=1279=0269=122=8207=BVMF48=380965483=79751270=8.28273=91:96:29271=3400272=2014061037016=2014061037017=91:96:2937=80531945021289=40290=45
10:29:19.618: 658844 - 70 - 1128=935=X34=65884452=20140610-13:29:19.63175=20140610268=1279=2269=022=8207=BVMF48=380965483=79752273=91:96:30272=2014061037=80531944234288=8290=30
10:29:19.619: 658845 - 81 - 1128=935=X34=65884552=20140610-13:29:19.63175=20140610268=1279=0269=022=8207=BVMF48=380965483=79753270=8.13273=91:96:31271=3300272=2014061037016=2014061037017=91:96:3137=80531945022288=40290=58
10:29:19.620: 658846 - 81 - 1128=935=X34=65884652=20140610-13:29:19.63375=20140610268=1279=0269=022=8207=BVMF48=380965483=79754270=8.15273=91:96:33271=7100272=2014061037016=2014061037017=91:96:3237=80531945023288=40290=49
10:29:19.918: 658847 - 71 - 1128=935=X34=65884752=20140610-13:29:19.93075=20140610268=1279=2269=122=8207=BVMF48=380965483=79755273=91:99:30272=2014061037=80531943477289=8290=3
10:29:20.046: 658848 - 72 - 1128=935=X34=65884852=20140610-13:29:20.05975=20140610268=1279=2269=022=8207=BVMF48=380968883=253474273=92:00:58272=2014061037=80531942872288=227290=23
10:29:20.046: 658849 - 82 - 1128=935=X34=65884952=20140610-13:29:20.05975=20140610268=1279=0269=022=8207=BVMF48=380968883=253475270=29.36273=92:00:58271=1000272=2014061037016=2014061037017=92:00:5837=80531945029288=227290=7
10:29:21.719: 658850 - 158 - 1128=935=X34=65885052=20140610-13:29:21.73175=20140610268=3279=0269=222=8207=BVMF48=380968883=253476270=29.39273=92:17:31271=200272=2014061037016=2014061037017=92:17:301500=E451=-0.241020=449000274=01003=6510288=227289=45279=0269=922=8207=BVMF48=380968883=253477270=29.478273=92:17:31272=201406101500=E279=1269=122=8207=BVMF48=380968883=253478270=29.39273=92:17:31271=1800272=2014061037016=2014061037017=84:11:9337=80531942856289=45290=1
10:29:22.027: 658851 - 483 - 1128=935=X34=65885152=20140610-13:29:22.03975=20140610268=12279=0269=222=8207=BVMF48=380963983=255914270=26.4273=92:20:38271=900272=2014061037016=2014061037017=92:20:381500=E451=-0.211020=1431900274=01003=19180288=37289=40279=0269=922=8207=BVMF48=380963983=255915270=26.469273=92:20:38272=201406101500=E279=0269=222=8207=BVMF48=380963983=255916270=26.4273=92:20:38271=200272=2014061037016=2014061037017=92:20:381500=E451=-0.211020=1432100274=1277=L1003=19190288=37289=40279=0269=922=8207=BVMF48=380963983=255917270=26.469273=92:20:38272=201406101500=E279=0269=222=8207=BVMF48=380963983=255918270=26.4273=92:20:38271=200272=2014061037016=2014061037017=92:20:381500=E451=-0.211020=1432300274=1277=L1003=19200288=37289=238279=0269=922=8207=BVMF48=380963983=255919270=26.469273=92:20:38272=201406101500=E279=0269=222=8207=BVMF48=380963983=255920270=26.4273=92:20:38271=200272=2014061037016=2014061037017=92:20:381500=E451=-0.211020=1432500274=1277=L1003=19210288=37289=3279=0269=922=8207=BVMF48=380963983=255921270=26.468273=92:20:38272=201406101500=E279=0269=222=8207=BVMF48=380963983=255922270=26.4273=92:20:38271=3500272=2014061037016=2014061037017=92:20:381500=E451=-0.211020=1436000274=1277=L1003=19220288=37289=85279=0269=922=8207=BVMF48=380963983=255923270=26.468273=92:20:38272=201406101500=E279=4269=122=8207=BVMF48=380963983=255924273=92:20:38272=20140610290=4279=1269=122=8207=BVMF48=380963983=255925270=26.4273=92:20:38271=1500272=2014061037016=2014061037017=91:80:8537=80531944813289=85290=1
10:29:22.028: 658852 - 80 - 1128=935=X34=65885252=20140610-13:29:22.04175=20140610268=1279=0269=022=8207=BVMF48=380963983=255926270=26.35273=92:20:40271=100272=2014061037016=2014061037017=92:20:4037=80531945042288=8290=34
10:29:22.037: 658853 - 82 - 1128=935=X34=65885352=20140610-13:29:22.04975=20140610268=1279=1269=122=8207=BVMF48=380963983=255927270=26.4273=92:20:49271=1700272=2014061037016=2014061037017=91:81:1637=80531945049289=45290=2
10:29:22.038: 658854 - 71 - 1128=935=X34=65885452=20140610-13:29:22.05175=20140610268=1279=2269=122=8207=BVMF48=380968883=253479273=92:20:50272=2014061037=80531942865289=8290=3
10:29:22.038: 658855 - 72 - 1128=935=X34=65885552=20140610-13:29:22.05175=20140610268=1279=2269=122=8207=BVMF48=380963983=255928273=92:20:50272=2014061037=80531942568289=45290=9
10:29:22.039: 658856 - 118 - 1128=935=X34=65885652=20140610-13:29:22.05175=20140610268=2279=2269=022=8207=BVMF48=380963983=255929273=92:20:51272=2014061037=80531942575288=45290=72279=0269=022=8207=BVMF48=380963983=255930270=26.39273=92:20:51271=3000272=2014061037016=2014061037017=92:20:5037=80531945052288=45290=9
10:29:22.050: 658857 - 80 - 1128=935=X34=65885752=20140610-13:29:22.06275=20140610268=1279=0269=022=8207=BVMF48=380963983=255931270=26.39273=92:20:62271=300272=2014061037016=2014061037017=92:20:6237=80531945080288=3290=10
10:29:22.051: 658858 - 120 - 1128=935=X34=65885852=20140610-13:29:22.06375=20140610268=2279=2269=122=8207=BVMF48=380968883=253480273=92:20:63272=2014061037=80531942866289=45290=3279=0269=122=8207=BVMF48=380968883=253481270=29.4273=92:20:63271=4300272=2014061037016=2014061037017=92:20:6337=80531945085289=45290=7
10:29:22.054: 658859 - 72 - 1128=935=X34=65885952=20140610-13:29:22.06775=20140610268=1279=2269=122=8207=BVMF48=380963983=255932273=92:20:66272=2014061037=80531944820289=40290=3
10:29:22.065: 658860 - 83 - 1128=935=X34=65886052=20140610-13:29:22.07875=20140610268=1279=0269=122=8207=BVMF48=380963983=255933270=26.4273=92:20:77271=900272=2014061037016=2014061037017=92:20:7737=80531945124289=40290=4
10:29:22.085: 658861 - 72 - 1128=935=X34=65886152=20140610-13:29:22.09875=20140610268=1279=2269=122=8207=BVMF48=380963983=255934273=92:20:97272=2014061037=80531945124289=40290=4
10:29:22.177: 658862 - 83 - 1128=935=X34=65886252=20140610-13:29:22.19075=20140610268=1279=0269=122=8207=BVMF48=380963983=255935270=26.4273=92:21:89271=300272=2014061037016=2014061037017=92:21:8937=80531945181289=40290=4
10:29:22.239: 658863 - 82 - 1128=935=X34=65886352=20140610-13:29:22.25175=20140610268=1279=0269=122=8207=BVMF48=380963983=255936270=26.52273=92:22:51271=3000272=2014061037016=2014061037017=92:22:5137=80531945199289=45290=58
10:29:22.268: 658864 - 83 - 1128=935=X34=65886452=20140610-13:29:22.28175=20140610268=1279=0269=122=8207=BVMF48=380963983=255937270=26.4273=92:22:80271=400272=2014061037016=2014061037017=92:22:8037=80531945202289=77290=5
10:29:22.272: 658865 - 70 - 1128=935=X34=65886552=20140610-13:29:22.28575=20140610268=1279=2269=022=8207=BVMF48=380963983=255938273=92:22:84272=2014061037=80531945080288=3290=10
10:29:22.459: 658866 - 72 - 1128=935=X34=65886652=20140610-13:29:22.47175=20140610268=1279=2269=122=8207=BVMF48=380963983=255939273=92:24:71272=2014061037=80531945181289=40290=4
10:29:22.469: 658867 - 81 - 1128=935=X34=65886752=20140610-13:29:22.48275=20140610268=1279=0269=022=8207=BVMF48=380963983=255940270=26.39273=92:24:82271=400272=2014061037016=2014061037017=92:24:8237=80531945206288=40290=10
10:29:22.473: 658868 - 82 - 1128=935=X34=65886852=20140610-13:29:22.48575=20140610268=1279=1269=122=8207=BVMF48=380963983=255941270=26.4273=92:24:85271=1500272=2014061037016=2014061037017=91:81:1637=80531945207289=45290=2
10:29:22.475: 658869 - 80 - 1128=935=X34=65886952=20140610-13:29:22.48775=20140610268=1279=0269=022=8207=BVMF48=380963983=255942270=26.39273=92:24:87271=300272=2014061037016=2014061037017=92:24:8737=80531945208288=3290=11
10:29:22.530: 658870 - 81 - 1128=935=X34=65887052=20140610-13:29:22.54275=20140610268=1279=0269=022=8207=BVMF48=380963983=255943270=26.33273=92:25:42271=5000272=2014061037016=2014061037017=92:25:4237=80531945209288=45290=55
10:29:22.532: 658871 - 83 - 1128=935=X34=65887152=20140610-13:29:22.54575=20140610268=1279=0269=122=8207=BVMF48=380963983=255944270=26.5273=92:25:44271=5000272=2014061037016=2014061037017=92:25:4437=80531945210289=45290=52
10:29:22.591: 658872 - 71 - 1128=935=X34=65887252=20140610-13:29:22.60475=20140610268=1279=2269=122=8207=BVMF48=380963983=255945273=92:26:03272=2014061037=80531944082289=8290=6
10:29:22.730: 658873 - 81 - 1128=935=X34=65887352=20140610-13:29:22.74375=20140610268=1279=0269=022=8207=BVMF48=380963983=255946270=26.32273=92:27:42271=5000272=2014061037016=2014061037017=92:27:4237=80531945212288=45290=61
10:29:22.733: 658874 - 82 - 1128=935=X34=65887452=20140610-13:29:22.74675=20140610268=1279=0269=122=8207=BVMF48=380963983=255947270=26.51273=92:27:45271=5000272=2014061037016=2014061037017=92:27:4537=80531945213289=45290=55
10:29:22.931: 658875 - 81 - 1128=935=X34=65887552=20140610-13:29:22.94475=20140610268=1279=0269=022=8207=BVMF48=380963983=255948270=26.31273=92:29:43271=5000272=2014061037016=2014061037017=92:29:4337=80531945215288=45290=68
10:29:22.934: 658876 - 82 - 1128=935=X34=65887652=20140610-13:29:22.94775=20140610268=1279=0269=122=8207=BVMF48=380963983=255949270=26.52273=92:29:46271=5000272=2014061037016=2014061037017=92:29:4637=80531945216289=45290=60
10:29:23.132: 658877 - 82 - 1128=935=X34=65887752=20140610-13:29:23.14475=20140610268=1279=0269=022=8207=BVMF48=380963983=255950270=26.3273=92:31:44271=5000272=2014061037016=2014061037017=92:31:4437=80531945223288=45290=77
10:29:23.364: 658878 - 81 - 1128=935=X34=65887852=20140610-13:29:23.37775=20140610268=1279=0269=122=8207=BVMF48=380394783=65782270=17.04273=92:33:76271=100272=2014061037016=2014061037017=92:33:7637=80531945227289=3290=5
10:29:23.366: 658879 - 81 - 1128=935=X34=65887952=20140610-13:29:23.37875=20140610268=1279=0269=122=8207=BVMF48=380394783=65783270=17.07273=92:33:78271=100272=2014061037016=2014061037017=92:33:7837=80531945228289=8290=12
10:29:23.449: 658880 - 82 - 1128=935=X34=65888052=20140610-13:29:23.46175=20140610268=1279=0269=122=8207=BVMF48=380249383=103521270=9.35273=92:34:60271=500272=2014061037016=2014061037017=92:34:6037=80531945230289=40290=8
10:29:23.462: 658881 - 81 - 1128=935=X34=65888152=20140610-13:29:23.47475=20140610268=1279=0269=022=8207=BVMF48=380968883=253482270=29.38273=92:34:74271=1000272=2014061037016=2014061037017=92:34:7437=80531945231288=21290=1
10:29:23.475: 658882 - 118 - 1128=935=X34=65888252=20140610-13:29:23.48875=20140610268=2279=2269=022=8207=BVMF48=380968883=253483273=92:34:87272=2014061037=80531943895288=45290=5279=0269=022=8207=BVMF48=380968883=253484270=29.38273=92:34:87271=1000272=2014061037016=2014061037017=92:34:8737=80531945232288=45290=2
10:29:23.542: 658883 - 80 - 1128=935=X34=65888352=20140610-13:29:23.55575=20140610268=1279=0269=022=8207=BVMF48=380249383=103522270=9.32273=92:35:54271=100272=2014061037016=2014061037017=92:35:5437=80531945233288=8290=18
10:29:23.629: 658884 - 72 - 1128=935=X34=65888452=20140610-13:29:23.64175=20140610268=1279=2269=122=8207=BVMF48=380394783=65784273=92:36:41272=2014061037=80531942709289=40290=3
10:29:24.009: 658885 - 81 - 1128=935=X34=65888552=20140610-13:29:24.02275=20140610268=1279=0269=022=8207=BVMF48=380965483=79756270=8.16273=92:40:21271=2000272=2014061037016=2014061037017=92:40:2137=80531945236288=90290=30
10:29:24.104: 658886 - 71 - 1128=935=X34=65888652=20140610-13:29:24.11775=20140610268=1279=2269=122=8207=BVMF48=380968883=253485273=92:41:17272=2014061037=80531944802289=3290=4
10:29:24.142: 658887 - 70 - 1128=935=X34=65888752=20140610-13:29:24.15575=20140610268=1279=2269=022=8207=BVMF48=380249383=103523273=92:41:55272=2014061037=80531945233288=8290=18
10:29:24.143: 658888 - 71 - 1128=935=X34=65888852=20140610-13:29:24.15575=20140610268=1279=2269=122=8207=BVMF48=380394783=65785273=92:41:55272=2014061037=80531945228289=8290=11
10:29:24.482: 658889 - 71 - 1128=935=X34=65888952=20140610-13:29:24.49575=20140610268=1279=2269=122=8207=BVMF48=380391383=106211273=92:44:95272=2014061037=80531944825289=3290=2
10:29:24.493: 658890 - 71 - 1128=935=X34=65889052=20140610-13:29:24.50675=20140610268=1279=2269=122=8207=BVMF48=380394783=65786273=92:45:05272=2014061037=80531945227289=3290=4
10:29:24.542: 658891 - 80 - 1128=935=X34=65889152=20140610-13:29:24.55575=20140610268=1279=0269=022=8207=BVMF48=380394783=65787270=17273=92:45:54271=100272=2014061037016=2014061037017=92:45:5437=80531945238288=8290=7
10:29:24.675: 658892 - 80 - 1128=935=X34=65889252=20140610-13:29:24.68775=20140610268=1279=0269=022=8207=BVMF48=380977983=20284270=7.36273=92:46:87271=100272=2014061037016=2014061037017=92:46:8737=80531945239288=8290=2
10:29:24.730: 658893 - 83 - 1128=935=X34=65889352=20140610-13:29:24.74375=20140610268=1279=0269=122=8207=BVMF48=380963983=255951270=26.55273=92:47:42271=500272=2014061037016=2014061037017=92:47:4237=80531945240289=114290=66
10:29:25.106: 658894 - 82 - 1128=935=X34=65889452=20140610-13:29:25.11975=20140610268=1279=0269=122=8207=BVMF48=380963983=255952270=26.4273=92:51:18271=100272=2014061037016=2014061037017=92:51:1837=80531945242289=3290=5
10:29:25.152: 658895 - 71 - 1128=935=X34=65889552=20140610-13:29:25.16575=20140610268=1279=2269=022=8207=BVMF48=380963983=255953273=92:51:64272=2014061037=80531945206288=40290=10
10:29:25.191: 658896 - 83 - 1128=935=X34=65889652=20140610-13:29:25.20475=20140610268=1279=0269=122=8207=BVMF48=380963983=255954270=26.4273=92:52:04271=100272=2014061037016=2014061037017=92:52:0437=80531945243289=40290=6
10:29:25.437: 658897 - 81 - 1128=935=X34=65889752=20140610-13:29:25.44975=20140610268=1279=0269=122=8207=BVMF48=380965483=79757270=8.21273=92:54:49271=100272=2014061037016=2014061037017=92:54:4937=80531945247289=3290=5
10:29:25.640: 658898 - 82 - 1128=935=X34=65889852=20140610-13:29:25.65275=20140610268=1279=0269=122=8207=BVMF48=380653683=6235270=3.14273=92:56:52271=30000272=2014061037016=2014061037017=92:56:5237=80531945250289=21290=4
10:29:25.648: 658899 - 80 - 1128=935=X34=65889952=20140610-13:29:25.66175=20140610268=1279=0269=122=8207=BVMF48=380653683=6236270=3.14273=92:56:60271=100272=2014061037016=2014061037017=92:56:6037=80531945251289=8290=5
10:29:26.333: 658900 - 81 - 1128=935=X34=65890052=20140610-13:29:26.34675=20140610268=1279=0269=122=8207=BVMF48=380968883=253486270=29.39273=92:63:45271=100272=2014061037016=2014061037017=92:63:4537=80531945255289=9290=4
10:29:26.347: 658901 - 119 - 1128=935=X34=65890152=20140610-13:29:26.36075=20140610268=2279=2269=122=8207=BVMF48=380968883=253487273=92:63:59272=2014061037=80531945085289=45290=7279=0269=122=8207=BVMF48=380968883=253488270=29.39273=92:63:59271=100272=2014061037016=2014061037017=92:63:5937=80531945256289=45290=5
10:29:26.597: 658902 - 80 - 1128=935=X34=65890252=20140610-13:29:26.61075=20140610268=1279=0269=022=8207=BVMF48=380963983=255955270=26.39273=92:66:09271=100272=2014061037016=2014061037017=92:66:0937=80531945258288=8290=11
10:29:26.600: 658903 - 81 - 1128=935=X34=65890352=20140610-13:29:26.61375=20140610268=1279=0269=022=8207=BVMF48=380968883=253489270=29.38273=92:66:12271=300272=2014061037016=2014061037017=92:66:1237=80531945259288=70290=3
10:29:26.877: 658904 - 160 - 1128=935=X34=65890452=20140610-13:29:26.89075=20140610268=3279=0269=222=8207=BVMF48=380963983=255956270=26.39273=92:68:90271=200272=2014061037016=2014061037017=92:68:891500=E451=-0.221020=1436200274=21003=19230288=45289=147279=0269=922=8207=BVMF48=380963983=255957270=26.468273=92:68:90272=201406101500=E279=1269=022=8207=BVMF48=380963983=255958270=26.39273=92:68:90271=3100272=2014061037016=2014061037017=61:20:8437=80531933834288=45290=1
10:29:26.879: 658905 - 71 - 1128=935=X34=65890552=20140610-13:29:26.89275=20140610268=1279=2269=022=8207=BVMF48=380963983=255959273=92:68:92272=2014061037=80531945223288=45290=77
10:29:26.879: 658906 - 72 - 1128=935=X34=65890652=20140610-13:29:26.89275=20140610268=1279=2269=122=8207=BVMF48=380963983=255960273=92:68:92272=2014061037=80531945216289=45290=62
10:29:27.186: 658907 - 81 - 1128=935=X34=65890752=20140610-13:29:27.19975=20140610268=1279=0269=022=8207=BVMF48=380391383=106212270=13.84273=92:71:99271=100272=2014061037016=2014061037017=92:71:9837=80531945264288=40290=2
10:29:27.189: 658908 - 81 - 1128=935=X34=65890852=20140610-13:29:27.20175=20140610268=1279=0269=022=8207=BVMF48=380963983=255961270=26.39273=92:72:01271=500272=2014061037016=2014061037017=92:72:0137=80531945265288=40290=12
10:29:27.189: 658909 - 81 - 1128=935=X34=65890952=20140610-13:29:27.20275=20140610268=1279=0269=022=8207=BVMF48=380968883=253490270=29.38273=92:72:01271=400272=2014061037016=2014061037017=92:72:0137=80531945266288=40290=4
10:29:27.192: 658910 - 81 - 1128=935=X34=65891052=20140610-13:29:27.20575=20140610268=1279=0269=022=8207=BVMF48=380394783=65788270=17.03273=92:72:04271=100272=2014061037016=2014061037017=92:72:0437=80531945267288=40290=2
10:29:27.215: 658911 - 81 - 1128=935=X34=65891152=20140610-13:29:27.22875=20140610268=1279=0269=022=8207=BVMF48=380249383=103524270=9.34273=92:72:27271=200272=2014061037016=2014061037017=92:72:2737=80531945268288=40290=5
10:29:27.234: 658912 - 70 - 1128=935=X34=65891252=20140610-13:29:27.24775=20140610268=1279=2269=022=8207=BVMF48=380391383=106213273=92:72:47272=2014061037=80531943927288=8290=35
10:29:27.257: 658913 - 80 - 1128=935=X34=65891352=20140610-13:29:27.27075=20140610268=1279=0269=022=8207=BVMF48=380391383=106214270=13.78273=92:72:69271=400272=2014061037016=2014061037017=92:72:6937=80531945270288=8290=35
10:29:28.348: 658914 - 70 - 1128=935=X34=65891452=20140610-13:29:28.36175=20140610268=1279=2269=022=8207=BVMF48=380394783=65789273=92:83:60272=2014061037=80531941597288=8290=4
10:29:28.489: 658915 - 80 - 1128=935=X34=65891552=20140610-13:29:28.50275=20140610268=1279=0269=022=8207=BVMF48=380391383=106215270=13.84273=92:85:01271=100272=2014061037016=2014061037017=92:85:0137=80531945271288=8290=3
10:29:29.469: 658916 - 199 - 1128=935=X34=65891652=20140610-13:29:29.48275=20140610268=4279=0269=222=8207=BVMF48=380963983=255962270=26.4273=92:94:81271=100272=2014061037016=2014061037017=92:94:811500=E451=-0.211020=1436300274=01003=19240288=8289=85279=0269=922=8207=BVMF48=380963983=255963270=26.468273=92:94:81272=201406101500=E279=1269=122=8207=BVMF48=380963983=255964270=26.4273=92:94:81271=1400272=2014061037016=2014061037017=91:80:8537=80531944813289=85290=1279=2269=022=8207=BVMF48=380963983=255965273=92:94:81272=2014061037=80531945258288=8290=11
10:29:29.694: 658917 - 183 - 1128=935=X34=65891752=20140610-13:29:29.70675=20140610268=4279=0269=222=8207=BVMF48=380391383=106216270=13.85273=92:97:06271=100272=2014061037016=2014061037017=92:97:051500=E451=-0.041020=109200274=01003=3410288=8289=238279=0269=922=8207=BVMF48=380391383=106217270=13.877273=92:97:06272=201406101500=E279=2269=022=8207=BVMF48=380391383=106218273=92:97:06272=2014061037=80531945271288=8290=3279=2269=122=8207=BVMF48=380391383=106219273=92:97:06272=2014061037=80531941441289=238290=1
10:29:29.695: 658918 - 81 - 1128=935=X34=65891852=20140610-13:29:29.70875=20140610268=1279=0269=122=8207=BVMF48=380391383=106220270=13.86273=92:97:07271=200272=2014061037016=2014061037017=92:97:0737=80531945306289=8290=5
10:29:29.699: 658919 - 83 - 1128=935=X34=65891952=20140610-13:29:29.71275=20140610268=1279=0269=122=8207=BVMF48=380391383=106221270=13.88273=92:97:11271=500272=2014061037016=2014061037017=92:97:1137=80531945307289=110290=16
10:29:29.700: 658920 - 119 - 1128=935=X34=65892052=20140610-13:29:29.71275=20140610268=2279=2269=122=8207=BVMF48=389774183=6739273=92:97:12272=2014061037=80531931032289=110290=1279=0269=122=8207=BVMF48=389774183=6740270=13.89273=92:97:12271=45272=2014061037016=2014061037017=92:97:1237=80531945311289=110290=1
10:29:29.704: 658921 - 388 - 1128=935=X34=65892152=20140610-13:29:29.71675=20140610268=10279=0269=222=8207=BVMF48=380965483=79758270=8.2273=92:97:16271=4100272=2014061037016=2014061037017=92:97:151500=E451=-0.081020=288300274=1277=L1003=3400288=129289=8279=0269=922=8207=BVMF48=380965483=79759270=8.238273=92:97:16272=201406101500=E279=0269=222=8207=BVMF48=380965483=79760270=8.19273=92:97:16271=500272=2014061037016=2014061037017=92:97:151500=E451=-0.091020=288800274=21003=3410288=8289=8279=0269=922=8207=BVMF48=380965483=79761270=8.238273=92:97:16272=201406101500=E279=0269=222=8207=BVMF48=380965483=79762270=8.19273=92:97:16271=3000272=2014061037016=2014061037017=92:97:151500=E451=-0.091020=291800274=3277=L1003=3420288=3289=8279=0269=922=8207=BVMF48=380965483=79763270=8.238273=92:97:16272=201406101500=E279=0269=222=8207=BVMF48=380965483=79764270=8.19273=92:97:16271=500272=2014061037016=2014061037017=92:97:151500=E451=-0.091020=292300274=3277=L1003=3430288=8289=8279=0269=922=8207=BVMF48=380965483=79765270=8.238273=92:97:16272=201406101500=E279=4269=022=8207=BVMF48=380965483=79766273=92:97:16272=20140610290=4279=0269=122=8207=BVMF48=380965483=79767270=8.19273=92:97:16271=11900272=2014061037016=2014061037017=92:97:1537=80531945314289=8290=1
10:29:29.704: 658922 - 81 - 1128=935=X34=65892252=20140610-13:29:29.71775=20140610268=1279=0269=022=8207=BVMF48=380391383=106222270=13.8273=92:97:16271=700272=2014061037016=2014061037017=92:97:1637=80531945315288=8290=23
10:29:29.704: 658923 - 80 - 1128=935=X34=65892352=20140610-13:29:29.71775=20140610268=1279=0269=022=8207=BVMF48=380391383=106223270=13.81273=92:97:16271=700272=2014061037016=2014061037017=92:97:1637=80531945316288=8290=18
10:29:29.704: 658924 - 81 - 1128=935=X34=65892452=20140610-13:29:29.71775=20140610268=1279=0269=122=8207=BVMF48=380391383=106224270=13.88273=92:97:16271=700272=2014061037016=2014061037017=92:97:1637=80531945317289=8290=17
10:29:29.705: 658925 - 81 - 1128=935=X34=65892552=20140610-13:29:29.71875=20140610268=1279=0269=122=8207=BVMF48=380965483=79768270=8.36273=92:97:17271=500272=2014061037016=2014061037017=92:97:1737=80531945318289=8290=78
10:29:29.705: 658926 - 70 - 1128=935=X34=65892652=20140610-13:29:29.71875=20140610268=1279=2269=022=8207=BVMF48=380977983=20285273=92:97:18272=2014061037=80531945239288=8290=2
10:29:29.705: 658927 - 70 - 1128=935=X34=65892752=20140610-13:29:29.71875=20140610268=1279=2269=022=8207=BVMF48=380965483=79769273=92:97:18272=2014061037=80531944479288=8290=12
10:29:29.705: 658928 - 82 - 1128=935=X34=65892852=20140610-13:29:29.71875=20140610268=1279=0269=122=8207=BVMF48=380965483=79770270=8.2273=92:97:18271=500272=2014061037016=2014061037017=92:97:1837=80531945319289=8290=2
10:29:29.706: 658929 - 80 - 1128=935=X34=65892952=20140610-13:29:29.71875=20140610268=1279=0269=022=8207=BVMF48=380965483=79771270=8.16273=92:97:18271=500272=2014061037016=2014061037017=92:97:1837=80531945320288=8290=26
10:29:29.706: 658930 - 81 - 1128=935=X34=65893052=20140610-13:29:29.71975=20140610268=1279=0269=122=8207=BVMF48=380977983=20286270=7.37273=92:97:19271=3200272=2014061037016=2014061037017=92:97:1837=80531945321289=3290=2
10:29:29.707: 658931 - 80 - 1128=935=X34=65893152=20140610-13:29:29.72075=20140610268=1279=0269=022=8207=BVMF48=380965483=79772270=8.18273=92:97:19271=400272=2014061037016=2014061037017=92:97:1937=80531945325288=3290=12
10:29:29.710: 658932 - 79 - 1128=935=X34=65893252=20140610-13:29:29.72375=20140610268=1279=1269=022=8207=BVMF48=380965483=79773270=8.18273=92:97:22271=300272=2014061037016=2014061037017=92:97:1937=80531945346288=3290=12
10:29:29.715: 658933 - 73 - 1128=935=X34=65893352=20140610-13:29:29.72875=20140610268=1279=2269=122=8207=BVMF48=380394783=65790273=92:97:28272=2014061037=80531943654289=227290=13
10:29:29.717: 658934 - 193 - 1128=935=X34=65893452=20140610-13:29:29.73075=20140610268=4279=0269=222=8207=BVMF48=380965483=79774270=8.18273=92:97:29271=700272=2014061037016=2014061037017=92:97:291500=E451=-0.11020=293000274=21003=3440288=77289=3279=0269=922=8207=BVMF48=380965483=79775270=8.238273=92:97:29272=201406101500=E279=1269=022=8207=BVMF48=380965483=79776270=8.18273=92:97:29271=7500272=2014061037016=2014061037017=50:71:7737=80531856537288=77290=1279=2269=122=8207=BVMF48=380965483=79777273=92:97:29272=2014061037=80531945247289=3290=7
10:29:29.723: 658935 - 119 - 1128=935=X34=65893552=20140610-13:29:29.73675=20140610268=2279=2269=122=8207=BVMF48=380391383=106225273=92:97:36272=2014061037=80531925752289=40290=9279=0269=122=8207=BVMF48=380391383=106226270=13.86273=92:97:36271=100272=2014061037016=2014061037017=92:97:3537=80531945420289=40290=6
10:29:29.725: 658936 - 83 - 1128=935=X34=65893652=20140610-13:29:29.73875=20140610268=1279=0269=122=8207=BVMF48=380394783=65791270=17.12273=92:97:38271=800272=2014061037016=2014061037017=92:97:3737=80531945424289=227290=14
10:29:29.749: 658937 - 81 - 1128=935=X34=65893752=20140610-13:29:29.76175=20140610268=1279=0269=122=8207=BVMF48=380391383=106227270=13.86273=92:97:60271=100272=2014061037016=2014061037017=92:97:6037=80531945431289=8290=7
10:29:29.749: 658938 - 70 - 1128=935=X34=65893852=20140610-13:29:29.76175=20140610268=1279=2269=022=8207=BVMF48=380965483=79778273=92:97:61272=2014061037=80531943656288=8290=9
10:29:29.828: 658939 - 116 - 1128=935=X34=65893952=20140610-13:29:29.84175=20140610268=2279=2269=122=8207=BVMF48=389774183=6741273=92:98:40272=2014061037=80531931067289=3290=2279=0269=122=8207=BVMF48=389774183=6742270=13.88273=92:98:40271=99272=2014061037016=2014061037017=92:98:4037=80531945464289=3290=1
10:29:29.837: 658940 - 119 - 1128=935=X34=65894052=20140610-13:29:29.85075=20140610268=2279=2269=122=8207=BVMF48=389774183=6743273=92:98:49272=2014061037=80531945311289=110290=2279=0269=122=8207=BVMF48=389774183=6744270=13.87273=92:98:49271=45272=2014061037016=2014061037017=92:98:4937=80531945471289=110290=1
10:29:29.861: 658941 - 71 - 1128=935=X34=65894152=20140610-13:29:29.87475=20140610268=1279=2269=022=8207=BVMF48=380965483=79779273=92:98:73272=2014061037=80531945022288=40290=56
10:29:29.862: 658942 - 72 - 1128=935=X34=65894252=20140610-13:29:29.87575=20140610268=1279=2269=122=8207=BVMF48=380965483=79780273=92:98:74272=2014061037=80531945020289=40290=32
10:29:29.863: 658943 - 72 - 1128=935=X34=65894352=20140610-13:29:29.87675=20140610268=1279=2269=122=8207=BVMF48=380965483=79781273=92:98:75272=2014061037=80531945021289=40290=45
10:29:29.864: 658944 - 71 - 1128=935=X34=65894452=20140610-13:29:29.87775=20140610268=1279=2269=022=8207=BVMF48=380965483=79782273=92:98:76272=2014061037=80531945023288=40290=46
10:29:29.985: 658945 - 80 - 1128=935=X34=65894552=20140610-13:29:29.99875=20140610268=1279=0269=022=8207=BVMF48=380968883=253491270=29.38273=92:99:97271=300272=2014061037016=2014061037017=92:99:9737=80531945485288=8290=5
10:29:29.987: 658946 - 117 - 1128=935=X34=65894652=20140610-13:29:30.00075=20140610268=2279=2269=122=8207=BVMF48=380977983=20287273=93:00:00272=2014061037=80531943158289=8290=4279=0269=122=8207=BVMF48=380977983=20288270=7.37273=93:00:00271=200272=2014061037016=2014061037017=93:00:0037=80531945486289=8290=3
10:29:30.001: 658947 - 117 - 1128=935=X34=65894752=20140610-13:29:30.01475=20140610268=2279=2269=122=8207=BVMF48=389774183=6745273=93:00:13272=2014061037=80531945464289=3290=2279=0269=122=8207=BVMF48=389774183=6746270=13.9273=93:00:13271=99272=2014061037016=2014061037017=93:00:1337=80531945487289=3290=2
10:29:30.009: 658948 - 82 - 1128=935=X34=65894852=20140610-13:29:30.02275=20140610268=1279=0269=122=8207=BVMF48=380965483=79783270=8.27273=93:00:21271=4700272=2014061037016=2014061037017=93:00:2137=80531945488289=40290=39
10:29:30.011: 658949 - 82 - 1128=935=X34=65894952=20140610-13:29:30.02475=20140610268=1279=0269=122=8207=BVMF48=380965483=79784270=8.29273=93:00:24271=4100272=2014061037016=2014061037017=93:00:2337=80531945489289=40290=51
10:29:30.013: 658950 - 81 - 1128=935=X34=65895052=20140610-13:29:30.02675=20140610268=1279=0269=022=8207=BVMF48=380965483=79785270=8.11273=93:00:26271=4100272=2014061037016=2014061037017=93:00:2637=80531945490288=40290=64
10:29:30.015: 658951 - 81 - 1128=935=X34=65895152=20140610-13:29:30.02975=20140610268=1279=0269=022=8207=BVMF48=380965483=79786270=8.13273=93:00:28271=4300272=2014061037016=2014061037017=93:00:2837=80531945492288=40290=55
10:29:30.131: 658952 - 82 - 1128=935=X34=65895252=20140610-13:29:30.14475=20140610268=1279=0269=122=8207=BVMF48=380249383=103525270=9.35273=93:01:43271=700272=2014061037016=2014061037017=93:01:4337=80531945500289=70290=9
10:29:30.142: 658953 - 70 - 1128=935=X34=65895352=20140610-13:29:30.15575=20140610268=1279=2269=022=8207=BVMF48=380394783=65792273=93:01:55272=2014061037=80531945238288=8290=7
10:29:30.236: 658954 - 84 - 1128=935=X34=65895452=20140610-13:29:30.24975=20140610268=1279=0269=122=8207=BVMF48=380963983=255966270=26.4273=93:02:48271=200272=2014061037016=2014061037017=93:02:4837=80531945504289=238290=7
10:29:30.240: 658955 - 70 - 1128=935=X34=65895552=20140610-13:29:30.25375=20140610268=1279=2269=022=8207=BVMF48=380963983=255967273=93:02:53272=2014061037=80531945208288=3290=10
10:29:30.703: 658956 - 71 - 1128=935=X34=65895652=20140610-13:29:30.71675=20140610268=1279=2269=122=8207=BVMF48=380391383=106228273=93:07:16272=2014061037=80531927830289=8290=15
10:29:31.143: 658957 - 70 - 1128=935=X34=65895752=20140610-13:29:31.15675=20140610268=1279=2269=022=8207=BVMF48=380963983=255968273=93:11:55272=2014061037=80531945042288=8290=36
10:29:31.539: 658958 - 81 - 1128=935=X34=65895852=20140610-13:29:31.55175=20140610268=1279=0269=122=8207=BVMF48=380965483=79787270=8.19273=93:15:51271=500272=2014061037016=2014061037017=93:15:5137=80531945629289=8290=2
10:29:31.933: 658959 - 81 - 1128=935=X34=65895952=20140610-13:29:31.94675=20140610268=1279=0269=022=8207=BVMF48=380963983=255969270=26.31273=93:19:46271=6700272=2014061037016=2014061037017=93:19:4537=80531945637288=16290=67
10:29:33.521: 658960 - 155 - 1128=935=X34=65896052=20140610-13:29:33.53575=20140610268=3279=0269=222=8207=BVMF48=380965483=79788270=8.19273=93:35:34271=1000272=2014061037016=2014061037017=93:35:341500=E451=-0.091020=294000274=01003=3450288=114289=8279=0269=922=8207=BVMF48=380965483=79789270=8.237273=93:35:34272=201406101500=E279=1269=122=8207=BVMF48=380965483=79790270=8.19273=93:35:34271=10900272=2014061037016=2014061037017=92:97:1537=80531945314289=8290=1
10:29:33.673: 658961 - 71 - 1128=935=X34=65896152=20140610-13:29:33.68675=20140610268=1279=2269=022=8207=BVMF48=380963983=255970273=93:36:85272=2014061037=80531945637288=16290=67
10:29:34.178: 658962 - 72 - 1128=935=X34=65896252=20140610-13:29:34.19275=20140610268=1279=2269=122=8207=BVMF48=380963983=255971273=93:41:91272=2014061037=80531901083289=39290=82
10:29:36.083: 658963 - 82 - 1128=935=X34=65896352=20140610-13:29:36.09675=20140610268=1279=0269=022=8207=BVMF48=380965483=79791270=8.07273=93:60:96271=3000272=2014061037016=2014061037017=93:60:9637=80531945679288=147290=85
10:29:37.417: 658964 - 84 - 1128=935=X34=65896452=20140610-13:29:37.43075=20140610268=1279=0269=122=8207=BVMF48=380391383=106229270=17.61273=93:74:29271=200272=2014061037016=2014061037017=93:74:2937=80531945696289=114290=266
10:29:37.544: 658965 - 158 - 1128=935=X34=65896552=20140610-13:29:37.55775=20140610268=3279=0269=222=8207=BVMF48=380968883=253492270=29.39273=93:75:56271=100272=2014061037016=2014061037017=93:75:561500=E451=-0.241020=449100274=1277=L1003=6520288=262289=45279=0269=922=8207=BVMF48=380968883=253493270=29.478273=93:75:56272=201406101500=E279=1269=122=8207=BVMF48=380968883=253494270=29.39273=93:75:56271=1700272=2014061037016=2014061037017=84:11:9337=80531942856289=45290=1
10:29:37.555: 658966 - 73 - 1128=935=X34=65896652=20140610-13:29:37.56875=20140610268=1279=2269=122=8207=BVMF48=380965483=79792273=93:75:67272=2014061037=80531926304289=735290=46
10:29:37.841: 658967 - 161 - 1128=935=X34=65896752=20140610-13:29:37.85475=20140610268=3279=0269=222=8207=BVMF48=380963983=255972270=26.4273=93:78:53271=1000272=2014061037016=2014061037017=93:78:531500=E451=-0.211020=1437300274=1277=L1003=19250288=82289=85279=0269=922=8207=BVMF48=380963983=255973270=26.468273=93:78:53272=201406101500=E279=1269=122=8207=BVMF48=380963983=255974270=26.4273=93:78:53271=400272=2014061037016=2014061037017=91:80:8537=80531944813289=85290=1
10:29:37.864: 658968 - 82 - 1128=935=X34=65896852=20140610-13:29:37.87775=20140610268=1279=1269=122=8207=BVMF48=380963983=255975270=26.4273=93:78:76271=700272=2014061037016=2014061037017=91:81:1637=80531945700289=45290=2
10:29:37.866: 658969 - 585 - 1128=935=X34=65896952=20140610-13:29:37.88075=20140610268=15279=0269=222=8207=BVMF48=380963983=255976270=26.4273=93:78:79271=400272=2014061037016=2014061037017=93:78:781500=E451=-0.211020=1437700274=1277=L1003=19260288=45289=85279=0269=922=8207=BVMF48=380963983=255977270=26.468273=93:78:79272=201406101500=E279=0269=222=8207=BVMF48=380963983=255978270=26.4273=93:78:79271=700272=2014061037016=2014061037017=93:78:781500=E451=-0.211020=1438400274=1277=L1003=19270288=45289=45279=0269=922=8207=BVMF48=380963983=255979270=26.468273=93:78:79272=201406101500=E279=0269=222=8207=BVMF48=380963983=255980270=26.4273=93:78:79271=500272=2014061037016=2014061037017=93:78:781500=E451=-0.211020=1438900274=1277=L1003=19280288=45289=77279=0269=922=8207=BVMF48=380963983=255981270=26.468273=93:78:79272=201406101500=E279=0269=222=8207=BVMF48=380963983=255982270=26.4273=93:78:79271=400272=2014061037016=2014061037017=93:78:781500=E451=-0.211020=1439300274=1277=L1003=19290288=45289=77279=0269=922=8207=BVMF48=380963983=255983270=26.468273=93:78:79272=201406101500=E279=0269=222=8207=BVMF48=380963983=255984270=26.4273=93:78:79271=100272=2014061037016=2014061037017=93:78:781500=E451=-0.211020=1439400274=1277=L1003=19300288=45289=3279=0269=922=8207=BVMF48=380963983=255985270=26.468273=93:78:79272=201406101500=E279=0269=222=8207=BVMF48=380963983=255986270=26.4273=93:78:79271=100272=2014061037016=2014061037017=93:78:781500=E451=-0.211020=1439500274=1277=L1003=19310288=45289=40279=0269=922=8207=BVMF48=380963983=255987270=26.468273=93:78:79272=201406101500=E279=0269=222=8207=BVMF48=380963983=255988270=26.4273=93:78:79271=200272=2014061037016=2014061037017=93:78:781500=E451=-0.211020=1439700274=1277=L1003=19320288=45289=238279=0269=922=8207=BVMF48=380963983=255989270=26.468273=93:78:79272=201406101500=E279=4269=122=8207=BVMF48=380963983=255990273=93:78:79272=20140610290=7
10:29:37.868: 658970 - 71 - 1128=935=X34=65897052=20140610-13:29:37.88175=20140610268=1279=2269=122=8207=BVMF48=380968883=253495273=93:78:81272=2014061037=80531938138289=8290=7
10:29:37.868: 658971 - 71 - 1128=935=X34=65897152=20140610-13:29:37.88275=20140610268=1279=2269=022=8207=BVMF48=380968883=253496273=93:78:81272=2014061037=80531941988288=45290=19
10:29:37.868: 658972 - 72 - 1128=935=X34=65897252=20140610-13:29:37.88275=20140610268=1279=2269=122=8207=BVMF48=380968883=253497273=93:78:81272=2014061037=80531942569289=45290=29
10:29:37.869: 658973 - 72 - 1128=935=X34=65897352=20140610-13:29:37.88275=20140610268=1279=2269=122=8207=BVMF48=380968883=253498273=93:78:81272=2014061037=80531941618289=45290=32
10:29:37.874: 658974 - 119 - 1128=935=X34=65897452=20140610-13:29:37.88775=20140610268=2279=2269=022=8207=BVMF48=380963983=255991273=93:78:87272=2014061037=80531945215288=45290=66279=0269=022=8207=BVMF48=380963983=255992270=26.4273=93:78:87271=5000272=2014061037016=2014061037017=93:78:8137=80531945715288=45290=1
10:29:37.874: 658975 - 80 - 1128=935=X34=65897552=20140610-13:29:37.88875=20140610268=1279=0269=022=8207=BVMF48=380963983=255993270=26.39273=93:78:87271=300272=2014061037016=2014061037017=93:78:8737=80531945719288=3290=12
10:29:37.875: 658976 - 160 - 1128=935=X34=65897652=20140610-13:29:37.88875=20140610268=3279=0269=222=8207=BVMF48=380963983=255994270=26.4273=93:78:88271=300272=2014061037016=2014061037017=93:78:871500=E451=-0.211020=1440000274=1277=L1003=19330288=45289=3279=0269=922=8207=BVMF48=380963983=255995270=26.468273=93:78:88272=201406101500=E279=1269=022=8207=BVMF48=380963983=255996270=26.4273=93:78:88271=4700272=2014061037016=2014061037017=93:78:8137=80531945715288=45290=1
10:29:37.876: 658977 - 72 - 1128=935=X34=65897752=20140610-13:29:37.88975=20140610268=1279=2269=122=8207=BVMF48=380963983=255997273=93:78:89272=2014061037=80531942133289=45290=5
10:29:37.876: 658978 - 81 - 1128=935=X34=65897852=20140610-13:29:37.88975=20140610268=1279=0269=122=8207=BVMF48=380968883=253499270=29.48273=93:78:89271=300272=2014061037016=2014061037017=93:78:8937=80531945734289=8290=32
10:29:37.876: 658979 - 119 - 1128=935=X34=65897952=20140610-13:29:37.89075=20140610268=2279=2269=022=8207=BVMF48=380963983=255998273=93:78:89272=2014061037=80531942217288=45290=74279=0269=022=8207=BVMF48=380963983=255999270=26.4273=93:78:89271=3000272=2014061037016=2014061037017=93:78:8937=80531945738288=45290=2
10:29:37.879: 658980 - 161 - 1128=935=X34=65898052=20140610-13:29:37.89375=20140610268=3279=0269=222=8207=BVMF48=380963983=256000270=26.4273=93:78:92271=700272=2014061037016=2014061037017=93:78:921500=E451=-0.211020=1440700274=1277=L1003=19340288=45289=45279=0269=922=8207=BVMF48=380963983=256001270=26.468273=93:78:92272=201406101500=E279=1269=022=8207=BVMF48=380963983=256002270=26.4273=93:78:92271=4000272=2014061037016=2014061037017=93:78:8137=80531945715288=45290=1
10:29:37.880: 658981 - 71 - 1128=935=X34=65898152=20140610-13:29:37.89375=20140610268=1279=2269=022=8207=BVMF48=380963983=256003273=93:78:92272=2014061037=80531942700288=40290=6
10:29:37.881: 658982 - 119 - 1128=935=X34=65898252=20140610-13:29:37.89475=20140610268=2279=2269=022=8207=BVMF48=380963983=256004273=93:78:94272=2014061037=80531945265288=40290=11279=0269=022=8207=BVMF48=380963983=256005270=26.4273=93:78:94271=300272=2014061037016=2014061037017=93:78:9437=80531945753288=40290=3
10:29:37.882: 658983 - 119 - 1128=935=X34=65898352=20140610-13:29:37.89575=20140610268=2279=2269=022=8207=BVMF48=380963983=256006273=93:78:95272=2014061037=80531942643288=40290=5279=0269=022=8207=BVMF48=380963983=256007270=26.4273=93:78:95271=1100272=2014061037016=2014061037017=93:78:9437=80531945758288=40290=4
10:29:37.882: 658984 - 71 - 1128=935=X34=65898452=20140610-13:29:37.89575=20140610268=1279=2269=022=8207=BVMF48=380963983=256008273=93:78:95272=2014061037=80531945715288=45290=1
10:29:37.889: 658985 - 119 - 1128=935=X34=65898552=20140610-13:29:37.90375=20140610268=2279=2269=022=8207=BVMF48=380963983=256009273=93:79:02272=2014061037=80531942654288=45290=5279=0269=022=8207=BVMF48=380963983=256010270=26.4273=93:79:02271=1400272=2014061037016=2014061037017=93:79:0237=80531945787288=45290=4
10:29:37.893: 658986 - 82 - 1128=935=X34=65898652=20140610-13:29:37.90775=20140610268=1279=0269=122=8207=BVMF48=380963983=256011270=26.41273=93:79:06271=900272=2014061037016=2014061037017=93:79:0637=80531945809289=40290=3
10:29:37.894: 658987 - 82 - 1128=935=X34=65898752=20140610-13:29:37.90775=20140610268=1279=0269=122=8207=BVMF48=380963983=256012270=26.44273=93:79:07271=1300272=2014061037016=2014061037017=93:79:0737=80531945813289=45290=14
10:29:37.896: 658988 - 116 - 1128=935=X34=65898852=20140610-13:29:37.90975=20140610268=2279=2269=022=8207=BVMF48=380968883=253500273=93:79:08272=2014061037=80531943633288=3290=8279=0269=022=8207=BVMF48=380968883=253501270=29.38273=93:79:08271=700272=2014061037016=2014061037017=93:79:0837=80531945823288=3290=6
10:29:37.896: 658989 - 82 - 1128=935=X34=65898952=20140610-13:29:37.90975=20140610268=1279=0269=022=8207=BVMF48=380963983=256013270=26.4273=93:79:09271=200272=2014061037016=2014061037017=93:79:0837=80531945825288=77290=5
10:29:37.902: 658990 - 82 - 1128=935=X34=65899052=20140610-13:29:37.91375=20140610268=1279=0269=022=8207=BVMF48=380963983=256014270=26.4273=93:79:13271=100272=2014061037016=2014061037017=93:79:1337=80531945844288=77290=6
10:29:37.902: 658991 - 82 - 1128=935=X34=65899152=20140610-13:29:37.91675=20140610268=1279=0269=022=8207=BVMF48=380963983=256015270=26.4273=93:79:15271=900272=2014061037016=2014061037017=93:79:1537=80531945852288=77290=7
10:29:37.905: 658992 - 82 - 1128=935=X34=65899252=20140610-13:29:37.91975=20140610268=1279=0269=022=8207=BVMF48=380963983=256016270=26.4273=93:79:18271=1700272=2014061037016=2014061037017=93:79:1837=80531945858288=77290=8
10:29:37.907: 658993 - 72 - 1128=935=X34=65899352=20140610-13:29:37.92175=20140610268=1279=2269=022=8207=BVMF48=380968883=253502273=93:79:20272=2014061037=80531941826288=227290=18
10:29:37.909: 658994 - 119 - 1128=935=X34=65899452=20140610-13:29:37.92275=20140610268=2279=2269=122=8207=BVMF48=380963983=256017273=93:79:22272=2014061037=80531945813289=45290=14279=0269=122=8207=BVMF48=380963983=256018270=26.41273=93:79:22271=900272=2014061037016=2014061037017=93:79:2137=80531945865289=45290=4
10:29:37.912: 658995 - 82 - 1128=935=X34=65899552=20140610-13:29:37.92575=20140610268=1279=0269=022=8207=BVMF48=380963983=256019270=26.4273=93:79:25271=300272=2014061037016=2014061037017=93:79:2537=80531945869288=77290=9
10:29:37.912: 658996 - 118 - 1128=935=X34=65899652=20140610-13:29:37.92675=20140610268=2279=2269=022=8207=BVMF48=380963983=256020273=93:79:25272=2014061037=80531944791288=59290=21279=0269=022=8207=BVMF48=380963983=256021270=26.39273=93:79:25271=800272=2014061037016=2014061037017=93:79:2537=80531945870288=59290=17
10:29:37.913: 658997 - 82 - 1128=935=X34=65899752=20140610-13:29:37.92775=20140610268=1279=0269=022=8207=BVMF48=380963983=256022270=26.4273=93:79:27271=300272=2014061037016=2014061037017=93:79:2637=80531945871288=77290=10
10:29:37.916: 658998 - 82 - 1128=935=X34=65899852=20140610-13:29:37.93075=20140610268=1279=0269=022=8207=BVMF48=380963983=256023270=26.4273=93:79:29271=400272=2014061037016=2014061037017=93:79:2937=80531945878288=77290=11
10:29:37.918: 658999 - 82 - 1128=935=X34=65899952=20140610-13:29:37.93275=20140610268=1279=0269=022=8207=BVMF48=380968883=253503270=29.35273=93:79:31271=800272=2014061037016=2014061037017=93:79:3137=80531945884288=227290=15
10:29:37.919: 659000 - 82 - 1128=935=X34=65900052=20140610-13:29:37.93275=20140610268=1279=0269=022=8207=BVMF48=380963983=256024270=26.4273=93:79:32271=100272=2014061037016=2014061037017=93:79:3237=80531945885288=77290=12
10:29:37.921: 659001 - 82 - 1128=935=X34=65900152=20140610-13:29:37.93475=20140610268=1279=0269=022=8207=BVMF48=380963983=256025270=26.4273=93:79:34271=200272=2014061037016=2014061037017=93:79:3337=80531945887288=77290=13
10:29:37.942: 659002 - 80 - 1128=935=X34=65900252=20140610-13:29:37.95575=20140610268=1279=0269=022=8207=BVMF48=380963983=256026270=26.35273=93:79:54271=100272=2014061037016=2014061037017=93:79:5437=80531945888288=8290=46
10:29:37.943: 659003 - 81 - 1128=935=X34=65900352=20140610-13:29:37.95675=20140610268=1279=0269=122=8207=BVMF48=380963983=256027270=26.42273=93:79:56271=2500272=2014061037016=2014061037017=93:79:5637=80531945889289=8290=6
10:29:38.020: 659004 - 81 - 1128=935=X34=65900452=20140610-13:29:38.03375=20140610268=1279=1269=022=8207=BVMF48=380963983=256028270=26.4273=93:80:33271=700272=2014061037016=2014061037017=93:78:9437=80531945909288=40290=3
10:29:38.026: 659005 - 115 - 1128=935=X34=65900552=20140610-13:29:38.04075=20140610268=2279=2269=022=8207=BVMF48=400223483=5873273=93:80:39272=2014061037=80531941973288=3290=4279=0269=022=8207=BVMF48=400223483=5874270=26.38273=93:80:39271=85272=2014061037016=2014061037017=93:80:3937=80531945911288=3290=3
10:29:38.049: 659006 - 81 - 1128=935=X34=65900652=20140610-13:29:38.06375=20140610268=1279=1269=022=8207=BVMF48=380963983=256029270=26.4273=93:80:62271=1000272=2014061037016=2014061037017=93:79:0237=80531945915288=45290=4
10:29:38.058: 659007 - 161 - 1128=935=X34=65900752=20140610-13:29:38.07175=20140610268=3279=0269=222=8207=BVMF48=380963983=256030270=26.4273=93:80:71271=400272=2014061037016=2014061037017=93:80:701500=E451=-0.211020=1441100274=1277=L1003=19350288=45289=77279=0269=922=8207=BVMF48=380963983=256031270=26.468273=93:80:71272=201406101500=E279=1269=022=8207=BVMF48=380963983=256032270=26.4273=93:80:71271=2600272=2014061037016=2014061037017=93:78:8937=80531945738288=45290=1
10:29:38.059: 659008 - 71 - 1128=935=X34=65900852=20140610-13:29:38.07375=20140610268=1279=2269=022=8207=BVMF48=380963983=256033273=93:80:72272=2014061037=80531942132288=45290=76
10:29:38.059: 659009 - 71 - 1128=935=X34=65900952=20140610-13:29:38.07375=20140610268=1279=2269=022=8207=BVMF48=380963983=256034273=93:80:72272=2014061037=80531945738288=45290=1
10:29:38.069: 659010 - 81 - 1128=935=X34=65901052=20140610-13:29:38.08275=20140610268=1279=0269=022=8207=BVMF48=380968883=253504270=29.35273=93:80:82271=2000272=2014061037016=2014061037017=93:80:8137=80531945920288=45290=16
10:29:38.069: 659011 - 82 - 1128=935=X34=65901152=20140610-13:29:38.08275=20140610268=1279=0269=122=8207=BVMF48=380968883=253505270=29.48273=93:80:82271=2000272=2014061037016=2014061037017=93:80:8237=80531945921289=45290=33
10:29:38.142: 659012 - 81 - 1128=935=X34=65901252=20140610-13:29:38.15575=20140610268=1279=0269=022=8207=BVMF48=380963983=256035270=26.39273=93:81:54271=600272=2014061037016=2014061037017=93:81:5437=80531945923288=40290=21
10:29:38.270: 659013 - 83 - 1128=935=X34=65901352=20140610-13:29:38.28375=20140610268=1279=0269=122=8207=BVMF48=380968883=253506270=29.5273=93:82:82271=2000272=2014061037016=2014061037017=93:82:8237=80531945926289=45290=38
10:29:38.314: 659014 - 82 - 1128=935=X34=65901452=20140610-13:29:38.32775=20140610268=1279=0269=022=8207=BVMF48=380963983=256036270=26.4273=93:83:27271=1800272=2014061037016=2014061037017=93:83:2637=80531945927288=37290=13
10:29:38.498: 659015 - 81 - 1128=935=X34=65901552=20140610-13:29:38.51275=20140610268=1279=1269=122=8207=BVMF48=380963983=256037270=26.41273=93:85:11271=800272=2014061037016=2014061037017=93:79:0637=80531945930289=40290=3
10:29:38.518: 659016 - 81 - 1128=935=X34=65901652=20140610-13:29:38.53275=20140610268=1279=1269=122=8207=BVMF48=380963983=256038270=26.41273=93:85:31271=800272=2014061037016=2014061037017=93:79:2137=80531945931289=45290=4
10:29:38.541: 659017 - 71 - 1128=935=X34=65901752=20140610-13:29:38.55575=20140610268=1279=2269=122=8207=BVMF48=380965483=79793273=93:85:54272=2014061037=80531942757289=8290=20
10:29:38.543: 659018 - 81 - 1128=935=X34=65901852=20140610-13:29:38.55675=20140610268=1279=0269=122=8207=BVMF48=380965483=79794270=8.22273=93:85:56271=100272=2014061037016=2014061037017=93:85:5537=80531945932289=8290=13
10:29:38.656: 659019 - 71 - 1128=935=X34=65901952=20140610-13:29:38.67075=20140610268=1279=2269=022=8207=BVMF48=380963983=256039273=93:86:69272=2014061037=80531945923288=40290=22
10:29:38.659: 659020 - 81 - 1128=935=X34=65902052=20140610-13:29:38.67275=20140610268=1279=1269=122=8207=BVMF48=380963983=256040270=26.41273=93:86:72271=500272=2014061037016=2014061037017=93:79:0637=80531945933289=40290=3
10:29:38.675: 659021 - 81 - 1128=935=X34=65902152=20140610-13:29:38.68875=20140610268=1279=1269=122=8207=BVMF48=380963983=256041270=26.41273=93:86:88271=500272=2014061037016=2014061037017=93:79:2137=80531945934289=45290=4
10:29:38.884: 659022 - 81 - 1128=935=X34=65902252=20140610-13:29:38.89775=20140610268=1279=0269=022=8207=BVMF48=380963983=256042270=26.31273=93:88:97271=5000272=2014061037016=2014061037017=93:88:9737=80531945936288=45290=76
10:29:38.957: 659023 - 83 - 1128=935=X34=65902352=20140610-13:29:38.97075=20140610268=1279=0269=122=8207=BVMF48=380249383=103526270=9.42273=93:89:69271=500272=2014061037016=2014061037017=93:89:6937=80531945939289=308290=43
10:29:39.061: 659024 - 81 - 1128=935=X34=65902452=20140610-13:29:39.07575=20140610268=1279=0269=022=8207=BVMF48=380963983=256043270=26.31273=93:90:75271=3000272=2014061037016=2014061037017=93:90:7437=80531945940288=45290=77
10:29:39.062: 659025 - 82 - 1128=935=X34=65902552=20140610-13:29:39.07575=20140610268=1279=0269=122=8207=BVMF48=380963983=256044270=26.43273=93:90:75271=3000272=2014061037016=2014061037017=93:90:7537=80531945941289=45290=9
10:29:39.184: 659026 - 81 - 1128=935=X34=65902652=20140610-13:29:39.19775=20140610268=1279=0269=022=8207=BVMF48=380963983=256045270=26.32273=93:91:97271=6700272=2014061037016=2014061037017=93:91:9737=80531945942288=16290=71
10:29:39.259: 659027 - 183 - 1128=935=X34=65902752=20140610-13:29:39.27375=20140610268=4279=0269=222=8207=BVMF48=380963983=256046270=26.41273=93:92:72271=100272=2014061037016=2014061037017=93:92:721500=E451=-0.21020=1441200274=01003=19360288=70289=3279=0269=922=8207=BVMF48=380963983=256047270=26.468273=93:92:72272=201406101500=E279=2269=022=8207=BVMF48=380963983=256048273=93:92:72272=2014061037=80531944800288=70290=18279=2269=122=8207=BVMF48=380963983=256049273=93:92:72272=2014061037=80531942727289=3290=1
