10:26:41.653: 656972 - 161 - 1128=935=X34=65697252=20140610-13:26:41.65975=20140610268=3279=0269=222=8207=BVMF48=380963983=254753270=26.41273=64:16:58271=3800272=2014061037016=2014061037017=64:16:581500=E451=-0.21020=1325900274=01003=17680288=77289=114279=0269=922=8207=BVMF48=380963983=254754270=26.474273=64:16:58272=201406101500=E279=1269=122=8207=BVMF48=380963983=254755270=26.41273=64:16:58271=1200272=2014061037016=2014061037017=64:16:4537=80531936939289=114290=1
10:26:41.653: 656973 - 71 - 1128=935=X34=65697352=20140610-13:26:41.65975=20140610268=1279=2269=022=8207=BVMF48=380963983=254756273=64:16:58272=2014061037=80531935606288=45290=1
10:26:41.657: 656974 - 73 - 1128=935=X34=65697452=20140610-13:26:41.66375=20140610268=1279=2269=122=8207=BVMF48=380963983=254757273=64:16:62272=2014061037=80531936939289=114290=1
10:26:41.659: 656975 - 199 - 1128=935=X34=65697552=20140610-13:26:41.66475=20140610268=4279=0269=222=8207=BVMF48=380968883=253031270=29.39273=64:16:63271=3400272=2014061037016=2014061037017=64:16:631500=E451=-0.241020=408800274=1277=L1003=5990288=114289=45279=0269=922=8207=BVMF48=380968883=253032270=29.487273=64:16:63272=201406101500=E279=1269=122=8207=BVMF48=380968883=253033270=29.39273=64:16:63271=700272=2014061037016=2014061037017=64:16:1937=80531936842289=45290=1279=2269=022=8207=BVMF48=380968883=253034273=64:16:63272=2014061037=80531936894288=114290=5
10:26:41.661: 656976 - 158 - 1128=935=X34=65697652=20140610-13:26:41.66675=20140610268=3279=0269=222=8207=BVMF48=380963983=254758270=26.42273=64:16:66271=200272=2014061037016=2014061037017=64:16:661500=E451=-0.191020=1326100274=01003=17690288=3289=40279=0269=922=8207=BVMF48=380963983=254759270=26.474273=64:16:66272=201406101500=E279=1269=122=8207=BVMF48=380963983=254760270=26.42273=64:16:66271=700272=2014061037016=2014061037017=63:97:8637=80531936360289=40290=1
10:26:41.661: 656977 - 119 - 1128=935=X34=65697752=20140610-13:26:41.66775=20140610268=2279=2269=122=8207=BVMF48=380963983=254761273=64:16:66272=2014061037=80531936360289=40290=1279=0269=122=8207=BVMF48=380963983=254762270=26.41273=64:16:66271=700272=2014061037016=2014061037017=64:16:6637=80531937010289=40290=1
10:26:41.662: 656978 - 82 - 1128=935=X34=65697852=20140610-13:26:41.66875=20140610268=1279=0269=022=8207=BVMF48=380968883=253035270=29.36273=64:16:67271=800272=2014061037016=2014061037017=64:16:6737=80531937013288=227290=10
10:26:41.663: 656979 - 83 - 1128=935=X34=65697952=20140610-13:26:41.66875=20140610268=1279=0269=122=8207=BVMF48=380963983=254763270=26.41273=64:16:68271=5000272=2014061037016=2014061037017=64:16:6837=80531937020289=114290=2
10:26:41.663: 656980 - 82 - 1128=935=X34=65698052=20140610-13:26:41.66975=20140610268=1279=0269=022=8207=BVMF48=380968883=253036270=29.38273=64:16:68271=6300272=2014061037016=2014061037017=64:16:6837=80531937025288=114290=5
10:26:41.665: 656981 - 70 - 1128=935=X34=65698152=20140610-13:26:41.67175=20140610268=1279=2269=022=8207=BVMF48=380963983=254764273=64:16:70272=2014061037=80531936789288=3290=5
10:26:41.667: 656982 - 82 - 1128=935=X34=65698252=20140610-13:26:41.67275=20140610268=1279=1269=122=8207=BVMF48=380963983=254765270=26.41273=64:16:72271=4600272=2014061037016=2014061037017=64:16:6837=80531937033289=114290=2
10:26:41.668: 656983 - 349 - 1128=935=X34=65698352=20140610-13:26:41.67375=20140610268=8279=0269=222=8207=BVMF48=380968883=253037270=29.39273=64:16:73271=700272=2014061037016=2014061037017=64:16:721500=E451=-0.241020=409500274=1277=L1003=6000288=114289=45279=0269=922=8207=BVMF48=380968883=253038270=29.487273=64:16:73272=201406101500=E279=2269=122=8207=BVMF48=380968883=253039273=64:16:73272=2014061037=80531936842289=45290=1279=0269=122=8207=BVMF48=380968883=253040270=29.39273=64:16:73271=5000272=2014061037016=2014061037017=64:16:7237=80531937036289=45290=1279=0269=222=8207=BVMF48=380968883=253041270=29.39273=64:16:73271=3800272=2014061037016=2014061037017=64:16:721500=E451=-0.241020=413300274=1277=L1003=6010288=114289=45279=0269=922=8207=BVMF48=380968883=253042270=29.486273=64:16:73272=201406101500=E279=1269=122=8207=BVMF48=380968883=253043270=29.39273=64:16:73271=1200272=2014061037016=2014061037017=64:16:7237=80531937036289=45290=1279=2269=022=8207=BVMF48=380968883=253044273=64:16:73272=2014061037=80531937025288=114290=5
10:26:41.673: 656984 - 72 - 1128=935=X34=65698452=20140610-13:26:41.67775=20140610268=1279=2269=022=8207=BVMF48=380968883=253045273=64:16:77272=2014061037=80531937013288=227290=10
10:26:41.673: 656985 - 203 - 1128=935=X34=65698552=20140610-13:26:41.67875=20140610268=4279=0269=222=8207=BVMF48=380963983=254766270=26.4273=64:16:78271=700272=2014061037016=2014061037017=64:16:771500=E451=-0.211020=1326800274=21003=17700288=59289=114279=0269=922=8207=BVMF48=380963983=254767270=26.474273=64:16:78272=201406101500=E279=1269=022=8207=BVMF48=380963983=254768270=26.4273=64:16:78271=100272=2014061037016=2014061037017=63:95:1837=80531936063288=59290=1279=2269=122=8207=BVMF48=380963983=254769273=64:16:78272=2014061037=80531937033289=114290=2
10:26:41.680: 656986 - 413 - 1128=935=X34=65698652=20140610-13:26:41.68575=20140610268=10279=0269=222=8207=BVMF48=380963983=254770270=26.4273=64:16:84271=100272=2014061037016=2014061037017=64:16:841500=E451=-0.211020=1326900274=3277=L1003=17710288=59289=114279=0269=922=8207=BVMF48=380963983=254771270=26.474273=64:16:84272=201406101500=E279=0269=222=8207=BVMF48=380963983=254772270=26.4273=64:16:84271=800272=2014061037016=2014061037017=64:16:841500=E451=-0.211020=1327700274=3277=L1003=17720288=45289=114279=0269=922=8207=BVMF48=380963983=254773270=26.473273=64:16:84272=201406101500=E279=0269=222=8207=BVMF48=380963983=254774270=26.4273=64:16:84271=600272=2014061037016=2014061037017=64:16:841500=E451=-0.211020=1328300274=3277=L1003=17730288=3289=114279=0269=922=8207=BVMF48=380963983=254775270=26.473273=64:16:84272=201406101500=E279=0269=222=8207=BVMF48=380963983=254776270=26.4273=64:16:84271=2800272=2014061037016=2014061037017=64:16:841500=E451=-0.211020=1331100274=3277=L1003=17740288=45289=114279=0269=922=8207=BVMF48=380963983=254777270=26.473273=64:16:84272=201406101500=E279=4269=022=8207=BVMF48=380963983=254778273=64:16:84272=20140610290=3279=1269=022=8207=BVMF48=380963983=254779270=26.4273=64:16:84271=200272=2014061037016=2014061037017=63:96:5137=80531936229288=45290=1
10:26:41.681: 656987 - 71 - 1128=935=X34=65698752=20140610-13:26:41.68675=20140610268=1279=2269=022=8207=BVMF48=380963983=254780273=64:16:86272=2014061037=80531936229288=45290=1
10:26:41.681: 656988 - 71 - 1128=935=X34=65698852=20140610-13:26:41.68775=20140610268=1279=2269=022=8207=BVMF48=380968883=253046273=64:16:86272=2014061037=80531933850288=45290=12
10:26:41.681: 656989 - 72 - 1128=935=X34=65698952=20140610-13:26:41.68775=20140610268=1279=2269=122=8207=BVMF48=380968883=253047273=64:16:86272=2014061037=80531935121289=45290=28
10:26:41.685: 656990 - 82 - 1128=935=X34=65699052=20140610-13:26:41.69075=20140610268=1279=0269=022=8207=BVMF48=380968883=253048270=29.35273=64:16:90271=800272=2014061037016=2014061037017=64:16:8937=80531937077288=227290=12
10:26:41.686: 656991 - 83 - 1128=935=X34=65699152=20140610-13:26:41.69275=20140610268=1279=0269=122=8207=BVMF48=380963983=254781270=26.41273=64:16:91271=800272=2014061037016=2014061037017=64:16:9137=80531937082289=114290=2
10:26:41.687: 656992 - 82 - 1128=935=X34=65699252=20140610-13:26:41.69275=20140610268=1279=0269=022=8207=BVMF48=380968883=253049270=29.38273=64:16:92271=1800272=2014061037016=2014061037017=64:16:9237=80531937084288=114290=5
10:26:41.690: 656993 - 82 - 1128=935=X34=65699352=20140610-13:26:41.69575=20140610268=1279=0269=022=8207=BVMF48=380963983=254782270=26.4273=64:16:95271=800272=2014061037016=2014061037017=64:16:9537=80531937091288=88290=3
10:26:41.690: 656994 - 73 - 1128=935=X34=65699452=20140610-13:26:41.69575=20140610268=1279=2269=122=8207=BVMF48=380963983=254783273=64:16:95272=2014061037=80531937082289=114290=2
10:26:41.690: 656995 - 82 - 1128=935=X34=65699552=20140610-13:26:41.69675=20140610268=1279=0269=022=8207=BVMF48=380963983=254784270=26.4273=64:16:95271=100272=2014061037016=2014061037017=64:16:9537=80531937092288=45290=4
10:26:41.693: 656996 - 73 - 1128=935=X34=65699652=20140610-13:26:41.69975=20140610268=1279=2269=122=8207=BVMF48=380963983=254785273=64:16:98272=2014061037=80531936346289=227290=11
10:26:41.694: 656997 - 83 - 1128=935=X34=65699752=20140610-13:26:41.69975=20140610268=1279=0269=122=8207=BVMF48=380963983=254786270=26.41273=64:16:99271=1300272=2014061037016=2014061037017=64:16:9937=80531937105289=114290=2
10:26:41.696: 656998 - 118 - 1128=935=X34=65699852=20140610-13:26:41.70275=20140610268=2279=2269=022=8207=BVMF48=380963983=254787273=64:17:02272=2014061037=80531937092288=45290=4279=0269=022=8207=BVMF48=380963983=254788270=26.37273=64:17:02271=300272=2014061037016=2014061037017=64:17:0137=80531937115288=45290=17
10:26:41.697: 656999 - 119 - 1128=935=X34=65699952=20140610-13:26:41.70375=20140610268=2279=2269=122=8207=BVMF48=380963983=254789273=64:17:02272=2014061037=80531937010289=40290=1279=0269=122=8207=BVMF48=380963983=254790270=26.42273=64:17:02271=700272=2014061037016=2014061037017=64:17:0237=80531937118289=40290=2
10:26:41.699: 657000 - 81 - 1128=935=X34=65700052=20140610-13:26:41.70575=20140610268=1279=0269=022=8207=BVMF48=380963983=254791270=26.4273=64:17:04271=600272=2014061037016=2014061037017=64:17:0437=80531937122288=3290=4
10:26:41.711: 657001 - 81 - 1128=935=X34=65700152=20140610-13:26:41.71775=20140610268=1279=1269=022=8207=BVMF48=380968883=253050270=29.38273=64:17:16271=1100272=2014061037016=2014061037017=64:16:9237=80531937150288=114290=5
10:26:41.713: 657002 - 83 - 1128=935=X34=65700252=20140610-13:26:41.71875=20140610268=1279=0269=122=8207=BVMF48=380963983=254792270=26.44273=64:17:18271=700272=2014061037016=2014061037017=64:17:1837=80531937152289=227290=14
10:26:41.721: 657003 - 73 - 1128=935=X34=65700352=20140610-13:26:41.72675=20140610268=1279=2269=122=8207=BVMF48=380963983=254793273=64:17:25272=2014061037=80531937152289=227290=14
10:26:41.721: 657004 - 120 - 1128=935=X34=65700452=20140610-13:26:41.72775=20140610268=2279=2269=022=8207=BVMF48=380968883=253051273=64:17:26272=2014061037=80531937150288=114290=5279=0269=022=8207=BVMF48=380968883=253052270=29.38273=64:17:26271=1800272=2014061037016=2014061037017=64:17:2637=80531937169288=114290=5
10:26:41.724: 657005 - 308 - 1128=935=X34=65700552=20140610-13:26:41.72975=20140610268=7279=0269=222=8207=BVMF48=380968883=253053270=29.39273=64:17:28271=1200272=2014061037016=2014061037017=64:17:281500=E451=-0.241020=414500274=1277=L1003=6020288=227289=45279=0269=922=8207=BVMF48=380968883=253054270=29.485273=64:17:28272=201406101500=E279=2269=122=8207=BVMF48=380968883=253055273=64:17:28272=2014061037=80531937036289=45290=1279=0269=122=8207=BVMF48=380968883=253056270=29.39273=64:17:28271=5000272=2014061037016=2014061037017=64:17:2837=80531937178289=45290=1279=0269=222=8207=BVMF48=380968883=253057270=29.39273=64:17:28271=3500272=2014061037016=2014061037017=64:17:281500=E451=-0.241020=418000274=1277=L1003=6030288=227289=45279=0269=922=8207=BVMF48=380968883=253058270=29.485273=64:17:28272=201406101500=E279=1269=122=8207=BVMF48=380968883=253059270=29.39273=64:17:28271=1500272=2014061037016=2014061037017=64:17:2837=80531937178289=45290=1
10:26:41.726: 657006 - 83 - 1128=935=X34=65700652=20140610-13:26:41.73175=20140610268=1279=0269=122=8207=BVMF48=380249383=103326270=9.36273=64:17:31271=300272=2014061037016=2014061037017=64:17:3137=80531937186289=238290=15
10:26:41.733: 657007 - 83 - 1128=935=X34=65700752=20140610-13:26:41.73875=20140610268=1279=0269=122=8207=BVMF48=380963983=254794270=26.44273=64:17:37271=1000272=2014061037016=2014061037017=64:17:3737=80531937189289=227290=14
10:26:41.733: 657008 - 119 - 1128=935=X34=65700852=20140610-13:26:41.73875=20140610268=2279=2269=022=8207=BVMF48=380963983=254795273=64:17:37272=2014061037=80531937115288=45290=18279=0269=022=8207=BVMF48=380963983=254796270=26.4273=64:17:37271=800272=2014061037016=2014061037017=64:17:3737=80531937190288=45290=5
10:26:41.741: 657009 - 121 - 1128=935=X34=65700952=20140610-13:26:41.74675=20140610268=2279=2269=122=8207=BVMF48=380963983=254797273=64:17:46272=2014061037=80531937105289=114290=1279=0269=122=8207=BVMF48=380963983=254798270=26.41273=64:17:46271=1700272=2014061037016=2014061037017=64:17:4537=80531937200289=114290=1
10:26:41.756: 657010 - 82 - 1128=935=X34=65701052=20140610-13:26:41.76175=20140610268=1279=0269=122=8207=BVMF48=380968883=253060270=29.4273=64:17:61271=100272=2014061037016=2014061037017=64:17:6037=80531937218289=8290=4
10:26:41.756: 657011 - 71 - 1128=935=X34=65701152=20140610-13:26:41.76175=20140610268=1279=2269=122=8207=BVMF48=380968883=253061273=64:17:61272=2014061037=80531937218289=8290=4
10:26:41.785: 657012 - 70 - 1128=935=X34=65701252=20140610-13:26:41.79075=20140610268=1279=2269=022=8207=BVMF48=380963983=254799273=64:17:90272=2014061037=80531936914288=3290=2
10:26:41.792: 657013 - 70 - 1128=935=X34=65701352=20140610-13:26:41.79775=20140610268=1279=2269=022=8207=BVMF48=380963983=254800273=64:17:96272=2014061037=80531936910288=3290=1
10:26:41.858: 657014 - 118 - 1128=935=X34=65701452=20140610-13:26:41.86475=20140610268=2279=2269=022=8207=BVMF48=380963983=254801273=64:18:63272=2014061037=80531937091288=88290=1279=0269=022=8207=BVMF48=380963983=254802270=26.38273=64:18:63271=800272=2014061037016=2014061037017=64:18:6337=80531937259288=88290=10
10:26:41.866: 657015 - 81 - 1128=935=X34=65701552=20140610-13:26:41.87275=20140610268=1279=1269=022=8207=BVMF48=380968883=253062270=29.38273=64:18:71271=1300272=2014061037016=2014061037017=64:17:2637=80531937267288=114290=5
10:26:41.876: 657016 - 118 - 1128=935=X34=65701652=20140610-13:26:41.88175=20140610268=2279=2269=022=8207=BVMF48=380963983=254803273=64:18:81272=2014061037=80531937190288=45290=2279=0269=022=8207=BVMF48=380963983=254804270=26.38273=64:18:81271=800272=2014061037016=2014061037017=64:18:8137=80531937273288=45290=10
10:26:41.882: 657017 - 81 - 1128=935=X34=65701752=20140610-13:26:41.88775=20140610268=1279=0269=022=8207=BVMF48=380968883=253063270=29.33273=64:18:87271=2000272=2014061037016=2014061037017=64:18:8737=80531937274288=45290=21
10:26:41.882: 657018 - 83 - 1128=935=X34=65701852=20140610-13:26:41.88775=20140610268=1279=0269=122=8207=BVMF48=380968883=253064270=29.5273=64:18:87271=2000272=2014061037016=2014061037017=64:18:8737=80531937275289=45290=32
10:26:41.887: 657019 - 81 - 1128=935=X34=65701952=20140610-13:26:41.89375=20140610268=1279=1269=022=8207=BVMF48=380968883=253065270=29.38273=64:18:92271=500272=2014061037016=2014061037017=64:17:2637=80531937285288=114290=5
10:26:41.887: 657020 - 71 - 1128=935=X34=65702052=20140610-13:26:41.89375=20140610268=1279=2269=022=8207=BVMF48=380963983=254805273=64:18:93272=2014061037=80531937259288=88290=9
10:26:41.890: 657021 - 71 - 1128=935=X34=65702152=20140610-13:26:41.89675=20140610268=1279=2269=122=8207=BVMF48=380963983=254806273=64:18:95272=2014061037=80531936331289=3290=5
10:26:41.891: 657022 - 71 - 1128=935=X34=65702252=20140610-13:26:41.89675=20140610268=1279=2269=122=8207=BVMF48=380963983=254807273=64:18:96272=2014061037=80531936344289=3290=5
10:26:41.892: 657023 - 118 - 1128=935=X34=65702352=20140610-13:26:41.89875=20140610268=2279=2269=022=8207=BVMF48=380963983=254808273=64:18:97272=2014061037=80531937273288=45290=9279=0269=022=8207=BVMF48=380963983=254809270=26.37273=64:18:97271=300272=2014061037016=2014061037017=64:18:9737=80531937287288=45290=15
10:26:41.896: 657024 - 72 - 1128=935=X34=65702452=20140610-13:26:41.90275=20140610268=1279=2269=022=8207=BVMF48=380968883=253066273=64:19:01272=2014061037=80531937077288=227290=13
10:26:41.907: 657025 - 82 - 1128=935=X34=65702552=20140610-13:26:41.91275=20140610268=1279=0269=022=8207=BVMF48=380968883=253067270=29.35273=64:19:12271=500272=2014061037016=2014061037017=64:19:1137=80531937291288=227290=13
10:26:41.926: 657026 - 79 - 1128=935=X34=65702652=20140610-13:26:41.93175=20140610268=1279=1269=022=8207=BVMF48=380968883=253068270=29.37273=64:19:31271=500272=2014061037016=2014061037017=63:97:2137=80531937297288=8290=8
10:26:41.945: 657027 - 82 - 1128=935=X34=65702752=20140610-13:26:41.95175=20140610268=1279=0269=022=8207=BVMF48=380963983=254810270=26.4273=64:19:50271=800272=2014061037016=2014061037017=64:19:5037=80531937302288=88290=2
10:26:41.947: 657028 - 81 - 1128=935=X34=65702852=20140610-13:26:41.95275=20140610268=1279=0269=022=8207=BVMF48=380968883=253069270=29.35273=64:19:52271=2000272=2014061037016=2014061037017=64:19:5237=80531937303288=45290=14
10:26:41.947: 657029 - 82 - 1128=935=X34=65702952=20140610-13:26:41.95275=20140610268=1279=0269=122=8207=BVMF48=380968883=253070270=29.48273=64:19:52271=2000272=2014061037016=2014061037017=64:19:5237=80531937304289=45290=25
10:26:41.951: 657030 - 81 - 1128=935=X34=65703052=20140610-13:26:41.95775=20140610268=1279=0269=122=8207=BVMF48=380963983=254811270=26.43273=64:19:56271=100272=2014061037016=2014061037017=64:19:5637=80531937307289=8290=7
10:26:41.952: 657031 - 81 - 1128=935=X34=65703152=20140610-13:26:41.95775=20140610268=1279=0269=022=8207=BVMF48=380963983=254812270=26.4273=64:19:57271=600272=2014061037016=2014061037017=64:19:5637=80531937311288=3290=3
10:26:41.953: 657032 - 120 - 1128=935=X34=65703252=20140610-13:26:41.95975=20140610268=2279=2269=022=8207=BVMF48=380968883=253071273=64:19:58272=2014061037=80531937285288=114290=5279=0269=022=8207=BVMF48=380968883=253072270=29.38273=64:19:58271=1300272=2014061037016=2014061037017=64:19:5837=80531937315288=114290=5
10:26:41.954: 657033 - 119 - 1128=935=X34=65703352=20140610-13:26:41.95975=20140610268=2279=2269=022=8207=BVMF48=380963983=254813273=64:19:59272=2014061037=80531937287288=45290=17279=0269=022=8207=BVMF48=380963983=254814270=26.4273=64:19:59271=800272=2014061037016=2014061037017=64:19:5837=80531937317288=45290=4
10:26:41.957: 657034 - 81 - 1128=935=X34=65703452=20140610-13:26:41.96375=20140610268=1279=0269=122=8207=BVMF48=380963983=254815270=26.43273=64:19:62271=1000272=2014061037016=2014061037017=64:19:6237=80531937324289=8290=8
10:26:41.961: 657035 - 72 - 1128=935=X34=65703552=20140610-13:26:41.96675=20140610268=1279=2269=022=8207=BVMF48=380968883=253073273=64:19:66272=2014061037=80531937291288=227290=13
10:26:41.962: 657036 - 81 - 1128=935=X34=65703652=20140610-13:26:41.96875=20140610268=1279=0269=022=8207=BVMF48=380963983=254816270=26.4273=64:19:67271=600272=2014061037016=2014061037017=64:19:6737=80531937328288=3290=5
10:26:41.971: 657037 - 120 - 1128=935=X34=65703752=20140610-13:26:41.97675=20140610268=2279=2269=022=8207=BVMF48=380968883=253074273=64:19:76272=2014061037=80531937315288=114290=5279=0269=022=8207=BVMF48=380968883=253075270=29.38273=64:19:76271=1800272=2014061037016=2014061037017=64:19:7637=80531937337288=114290=5
10:26:41.971: 657038 - 82 - 1128=935=X34=65703852=20140610-13:26:41.97775=20140610268=1279=0269=022=8207=BVMF48=380968883=253076270=29.35273=64:19:76271=800272=2014061037016=2014061037017=64:19:7637=80531937338288=227290=14
10:26:41.989: 657039 - 70 - 1128=935=X34=65703952=20140610-13:26:41.99575=20140610268=1279=2269=022=8207=BVMF48=380963983=254817273=64:19:94272=2014061037=80531937311288=3290=3
10:26:41.999: 657040 - 71 - 1128=935=X34=65704052=20140610-13:26:42.00475=20140610268=1279=2269=122=8207=BVMF48=380963983=254818273=64:20:04272=2014061037=80531937307289=8290=7
10:26:42.005: 657041 - 118 - 1128=935=X34=65704152=20140610-13:26:42.01075=20140610268=2279=2269=022=8207=BVMF48=380963983=254819273=64:20:09272=2014061037=80531937302288=88290=2279=0269=022=8207=BVMF48=380963983=254820270=26.38273=64:20:09271=800272=2014061037016=2014061037017=64:20:0937=80531937351288=88290=11
10:26:42.006: 657042 - 71 - 1128=935=X34=65704252=20140610-13:26:42.01175=20140610268=1279=2269=122=8207=BVMF48=380963983=254821273=64:20:11272=2014061037=80531937324289=8290=7
10:26:42.017: 657043 - 118 - 1128=935=X34=65704352=20140610-13:26:42.02275=20140610268=2279=2269=022=8207=BVMF48=380963983=254822273=64:20:22272=2014061037=80531937317288=45290=2279=0269=022=8207=BVMF48=380963983=254823270=26.38273=64:20:22271=800272=2014061037016=2014061037017=64:20:2237=80531937355288=45290=11
10:26:42.026: 657044 - 81 - 1128=935=X34=65704452=20140610-13:26:42.03175=20140610268=1279=1269=022=8207=BVMF48=380968883=253077270=29.38273=64:20:31271=1100272=2014061037016=2014061037017=64:19:7637=80531937361288=114290=5
10:26:42.036: 657045 - 71 - 1128=935=X34=65704552=20140610-13:26:42.04175=20140610268=1279=2269=022=8207=BVMF48=380963983=254824273=64:20:41272=2014061037=80531937351288=88290=10
10:26:42.045: 657046 - 80 - 1128=935=X34=65704652=20140610-13:26:42.05075=20140610268=1279=0269=022=8207=BVMF48=380968883=253078270=29.37273=64:20:50271=1200272=2014061037016=2014061037017=64:20:4937=80531937364288=8290=9
10:26:42.047: 657047 - 118 - 1128=935=X34=65704752=20140610-13:26:42.05375=20140610268=2279=2269=022=8207=BVMF48=380963983=254825273=64:20:52272=2014061037=80531937355288=45290=10279=0269=022=8207=BVMF48=380963983=254826270=26.37273=64:20:52271=300272=2014061037016=2014061037017=64:20:5237=80531937365288=45290=16
10:26:42.073: 657048 - 82 - 1128=935=X34=65704852=20140610-13:26:42.07875=20140610268=1279=0269=022=8207=BVMF48=380963983=254827270=26.4273=64:20:78271=500272=2014061037016=2014061037017=64:20:7737=80531937371288=40290=3
10:26:42.079: 657049 - 119 - 1128=935=X34=65704952=20140610-13:26:42.08575=20140610268=2279=2269=022=8207=BVMF48=380963983=254828273=64:20:84272=2014061037=80531937365288=45290=17279=0269=022=8207=BVMF48=380963983=254829270=26.4273=64:20:84271=500272=2014061037016=2014061037017=64:20:8437=80531937372288=45290=4
10:26:42.082: 657050 - 120 - 1128=935=X34=65705052=20140610-13:26:42.08775=20140610268=2279=2269=022=8207=BVMF48=380968883=253079273=64:20:87272=2014061037=80531937361288=114290=5279=0269=022=8207=BVMF48=380968883=253080270=29.38273=64:20:87271=1500272=2014061037016=2014061037017=64:20:8737=80531937377288=114290=5
10:26:42.092: 657051 - 120 - 1128=935=X34=65705152=20140610-13:26:42.09875=20140610268=2279=2269=022=8207=BVMF48=380968883=253081273=64:20:97272=2014061037=80531937377288=114290=5279=0269=022=8207=BVMF48=380968883=253082270=29.38273=64:20:97271=1800272=2014061037016=2014061037017=64:20:9737=80531937382288=114290=5
10:26:42.108: 657052 - 80 - 1128=935=X34=65705252=20140610-13:26:42.11375=20140610268=1279=0269=022=8207=BVMF48=380968883=253083270=29.37273=64:21:13271=200272=2014061037016=2014061037017=64:21:1337=80531937384288=8290=10
10:26:42.135: 657053 - 70 - 1128=935=X34=65705352=20140610-13:26:42.14175=20140610268=1279=2269=022=8207=BVMF48=380963983=254830273=64:21:40272=2014061037=80531937328288=3290=2
10:26:42.142: 657054 - 81 - 1128=935=X34=65705452=20140610-13:26:42.14775=20140610268=1279=1269=022=8207=BVMF48=380968883=253084270=29.38273=64:21:47271=1400272=2014061037016=2014061037017=64:20:9737=80531937389288=114290=5
10:26:42.169: 657055 - 79 - 1128=935=X34=65705552=20140610-13:26:42.17575=20140610268=1279=1269=022=8207=BVMF48=380968883=253085270=29.37273=64:21:74271=700272=2014061037016=2014061037017=64:20:4937=80531937406288=8290=9
10:26:42.191: 657056 - 81 - 1128=935=X34=65705652=20140610-13:26:42.19675=20140610268=1279=0269=122=8207=BVMF48=380963983=254831270=26.41273=64:21:96271=300272=2014061037016=2014061037017=64:21:9637=80531937409289=9290=2
10:26:42.471: 657057 - 71 - 1128=935=X34=65705752=20140610-13:26:42.47775=20140610268=1279=2269=022=8207=BVMF48=380963983=254832273=64:24:76272=2014061037=80531937371288=40290=2
10:26:42.480: 657058 - 81 - 1128=935=X34=65705852=20140610-13:26:42.48675=20140610268=1279=1269=022=8207=BVMF48=380968883=253086270=29.38273=64:24:85271=1000272=2014061037016=2014061037017=64:20:9737=80531937426288=114290=5
10:26:42.485: 657059 - 118 - 1128=935=X34=65705952=20140610-13:26:42.49175=20140610268=2279=2269=022=8207=BVMF48=380963983=254833273=64:24:90272=2014061037=80531937372288=45290=2279=0269=022=8207=BVMF48=380963983=254834270=26.37273=64:24:90271=300272=2014061037016=2014061037017=64:24:9037=80531937427288=45290=15
10:26:42.492: 657060 - 81 - 1128=935=X34=65706052=20140610-13:26:42.49875=20140610268=1279=1269=022=8207=BVMF48=380968883=253087270=29.38273=64:24:97271=500272=2014061037016=2014061037017=64:20:9737=80531937433288=114290=5
10:26:42.495: 657061 - 79 - 1128=935=X34=65706152=20140610-13:26:42.50075=20140610268=1279=1269=022=8207=BVMF48=380968883=253088270=29.37273=64:25:00271=200272=2014061037016=2014061037017=64:20:4937=80531937435288=8290=9
10:26:42.501: 657062 - 72 - 1128=935=X34=65706252=20140610-13:26:42.50675=20140610268=1279=2269=022=8207=BVMF48=380968883=253089273=64:25:06272=2014061037=80531937338288=227290=16
10:26:42.511: 657063 - 82 - 1128=935=X34=65706352=20140610-13:26:42.51675=20140610268=1279=0269=022=8207=BVMF48=380968883=253090270=29.35273=64:25:16271=500272=2014061037016=2014061037017=64:25:1537=80531937444288=227290=16
10:26:42.542: 657064 - 79 - 1128=935=X34=65706452=20140610-13:26:42.54875=20140610268=1279=1269=022=8207=BVMF48=380968883=253091270=29.37273=64:25:47271=300272=2014061037016=2014061037017=63:97:2137=80531937455288=8290=8
10:26:42.548: 657065 - 70 - 1128=935=X34=65706552=20140610-13:26:42.55375=20140610268=1279=2269=022=8207=BVMF48=380968883=253092273=64:25:53272=2014061037=80531937435288=8290=9
10:26:42.600: 657066 - 80 - 1128=935=X34=65706652=20140610-13:26:42.60575=20140610268=1279=0269=022=8207=BVMF48=380963983=254835270=26.37273=64:26:04271=300272=2014061037016=2014061037017=64:26:0437=80531937456288=8290=16
10:26:42.632: 657067 - 81 - 1128=935=X34=65706752=20140610-13:26:42.63875=20140610268=1279=0269=022=8207=BVMF48=380963983=254836270=26.32273=64:26:37271=5000272=2014061037016=2014061037017=64:26:3737=80531937457288=45290=54
10:26:42.633: 657068 - 119 - 1128=935=X34=65706852=20140610-13:26:42.63875=20140610268=2279=2269=122=8207=BVMF48=380963983=254837273=64:26:38272=2014061037=80531934663289=45290=57279=0269=122=8207=BVMF48=380963983=254838270=26.43273=64:26:38271=5000272=2014061037016=2014061037017=64:26:3737=80531937458289=45290=8
10:26:42.645: 657069 - 72 - 1128=935=X34=65706952=20140610-13:26:42.65175=20140610268=1279=2269=122=8207=BVMF48=380963983=254839273=64:26:50272=2014061037=80531937458289=45290=8
10:26:42.646: 657070 - 119 - 1128=935=X34=65707052=20140610-13:26:42.65175=20140610268=2279=2269=022=8207=BVMF48=380963983=254840273=64:26:51272=2014061037=80531937457288=45290=54279=0269=022=8207=BVMF48=380963983=254841270=26.4273=64:26:51271=5000272=2014061037016=2014061037017=64:26:5137=80531937460288=45290=2
10:26:42.655: 657071 - 81 - 1128=935=X34=65707152=20140610-13:26:42.66175=20140610268=1279=0269=022=8207=BVMF48=380963983=254842270=26.4273=64:26:60271=300272=2014061037016=2014061037017=64:26:6037=80531937466288=3290=3
10:26:42.659: 657072 - 120 - 1128=935=X34=65707252=20140610-13:26:42.66475=20140610268=2279=2269=022=8207=BVMF48=380968883=253093273=64:26:63272=2014061037=80531937433288=114290=5279=0269=022=8207=BVMF48=380968883=253094270=29.38273=64:26:63271=1800272=2014061037016=2014061037017=64:26:6337=80531937474288=114290=5
10:26:42.666: 657073 - 81 - 1128=935=X34=65707352=20140610-13:26:42.67275=20140610268=1279=0269=022=8207=BVMF48=380963983=254843270=26.4273=64:26:71271=600272=2014061037016=2014061037017=64:26:7137=80531937491288=3290=4
10:26:42.666: 657074 - 72 - 1128=935=X34=65707452=20140610-13:26:42.67275=20140610268=1279=2269=022=8207=BVMF48=380968883=253095273=64:26:71272=2014061037=80531937444288=227290=15
10:26:42.676: 657075 - 82 - 1128=935=X34=65707552=20140610-13:26:42.68275=20140610268=1279=0269=022=8207=BVMF48=380968883=253096270=29.35273=64:26:81271=800272=2014061037016=2014061037017=64:26:8137=80531937503288=227290=15
10:26:42.682: 657076 - 82 - 1128=935=X34=65707652=20140610-13:26:42.68775=20140610268=1279=0269=022=8207=BVMF48=380963983=254844270=26.4273=64:26:87271=800272=2014061037016=2014061037017=64:26:8637=80531937506288=88290=5
10:26:42.683: 657077 - 82 - 1128=935=X34=65707752=20140610-13:26:42.68875=20140610268=1279=0269=022=8207=BVMF48=380963983=254845270=26.4273=64:26:88271=3000272=2014061037016=2014061037017=64:26:8737=80531937511288=45290=6
10:26:42.683: 657078 - 82 - 1128=935=X34=65707852=20140610-13:26:42.68875=20140610268=1279=0269=122=8207=BVMF48=380963983=254846270=26.44273=64:26:88271=3000272=2014061037016=2014061037017=64:26:8837=80531937512289=45290=14
10:26:42.684: 657079 - 80 - 1128=935=X34=65707952=20140610-13:26:42.69075=20140610268=1279=0269=022=8207=BVMF48=380968883=253097270=29.37273=64:26:89271=2000272=2014061037016=2014061037017=64:26:8937=80531937513288=8290=10
10:26:42.689: 657080 - 119 - 1128=935=X34=65708052=20140610-13:26:42.69575=20140610268=2279=2269=022=8207=BVMF48=380963983=254847273=64:26:94272=2014061037=80531937427288=45290=20279=0269=022=8207=BVMF48=380963983=254848270=26.4273=64:26:94271=800272=2014061037016=2014061037017=64:26:9437=80531937514288=45290=7
10:26:42.701: 657081 - 70 - 1128=935=X34=65708152=20140610-13:26:42.70775=20140610268=1279=2269=022=8207=BVMF48=380963983=254849273=64:27:06272=2014061037=80531937491288=3290=4
10:26:42.707: 657082 - 118 - 1128=935=X34=65708252=20140610-13:26:42.71275=20140610268=2279=2269=022=8207=BVMF48=380963983=254850273=64:27:12272=2014061037=80531937506288=88290=4279=0269=022=8207=BVMF48=380963983=254851270=26.38273=64:27:12271=800272=2014061037016=2014061037017=64:27:1237=80531937517288=88290=13
10:26:42.717: 657083 - 71 - 1128=935=X34=65708352=20140610-13:26:42.72375=20140610268=1279=2269=022=8207=BVMF48=380963983=254852273=64:27:22272=2014061037=80531937517288=88290=13
10:26:42.719: 657084 - 118 - 1128=935=X34=65708452=20140610-13:26:42.72575=20140610268=2279=2269=022=8207=BVMF48=380963983=254853273=64:27:24272=2014061037=80531937514288=45290=5279=0269=022=8207=BVMF48=380963983=254854270=26.38273=64:27:24271=800272=2014061037016=2014061037017=64:27:2437=80531937518288=45290=12
10:26:42.734: 657085 - 118 - 1128=935=X34=65708552=20140610-13:26:42.74075=20140610268=2279=2269=022=8207=BVMF48=380963983=254855273=64:27:39272=2014061037=80531937518288=45290=12279=0269=022=8207=BVMF48=380963983=254856270=26.37273=64:27:39271=600272=2014061037016=2014061037017=64:27:3937=80531937519288=45290=19
10:26:42.770: 657086 - 70 - 1128=935=X34=65708652=20140610-13:26:42.77675=20140610268=1279=2269=022=8207=BVMF48=400223483=5856273=64:27:75272=2014061037=80531935465288=29290=84
10:26:42.847: 657087 - 82 - 1128=935=X34=65708752=20140610-13:26:42.85275=20140610268=1279=0269=122=8207=BVMF48=380963983=254857270=26.51273=64:28:52271=5000272=2014061037016=2014061037017=64:28:5237=80531937523289=45290=58
10:26:42.883: 657088 - 81 - 1128=935=X34=65708852=20140610-13:26:42.88875=20140610268=1279=0269=022=8207=BVMF48=380963983=254858270=26.31273=64:28:88271=3000272=2014061037016=2014061037017=64:28:8737=80531937524288=45290=62
10:26:43.226: 657089 - 118 - 1128=935=X34=65708952=20140610-13:26:43.23175=20140610268=2279=2269=022=8207=BVMF48=380965483=79262273=64:32:30272=2014061037=80531846134288=82290=83279=0269=022=8207=BVMF48=380965483=79263270=8.17273=64:32:30271=1200272=2014061037016=2014061037017=64:32:3037=80531937525288=82290=30
10:26:43.318: 657090 - 80 - 1128=935=X34=65709052=20140610-13:26:43.32475=20140610268=1279=0269=122=8207=BVMF48=394036883=1647270=2.52273=64:33:23271=25272=2014061037016=2014061037017=64:33:2337=80531937528289=72290=3
10:26:43.643: 657091 - 71 - 1128=935=X34=65709152=20140610-13:26:43.64975=20140610268=1279=2269=122=8207=BVMF48=380391383=106039273=64:36:48272=2014061037=80531935249289=3290=5
10:26:44.150: 657092 - 70 - 1128=935=X34=65709252=20140610-13:26:44.15575=20140610268=1279=2269=022=8207=BVMF48=380249383=103327273=64:41:55272=2014061037=80531931620288=8290=15
10:26:44.474: 657093 - 83 - 1128=935=X34=65709352=20140610-13:26:44.48075=20140610268=1279=0269=122=8207=BVMF48=380963983=254859270=26.41273=64:44:79271=200272=2014061037016=2014061037017=64:44:7937=80531937529289=238290=3
10:26:44.480: 657094 - 70 - 1128=935=X34=65709452=20140610-13:26:44.48575=20140610268=1279=2269=022=8207=BVMF48=380963983=254860273=64:44:85272=2014061037=80531937466288=3290=3
10:26:46.419: 657095 - 82 - 1128=935=X34=65709552=20140610-13:26:46.42575=20140610268=1279=0269=122=8207=BVMF48=380963983=254861270=26.41273=64:64:24271=200272=2014061037016=2014061037017=64:64:2437=80531937536289=40290=4
10:26:46.463: 657096 - 82 - 1128=935=X34=65709652=20140610-13:26:46.46875=20140610268=1279=0269=022=8207=BVMF48=380977983=20186270=7.35273=64:64:68271=500272=2014061037016=2014061037017=64:64:6837=80531937537288=564290=5
10:26:46.499: 657097 - 81 - 1128=935=X34=65709752=20140610-13:26:46.50475=20140610268=1279=0269=022=8207=BVMF48=380391383=106040270=13.84273=64:65:04271=300272=2014061037016=2014061037017=64:65:0337=80531937538288=40290=1
10:26:46.504: 657098 - 81 - 1128=935=X34=65709852=20140610-13:26:46.50975=20140610268=1279=0269=022=8207=BVMF48=380968883=253098270=29.38273=64:65:09271=400272=2014061037016=2014061037017=64:65:0937=80531937540288=40290=6
10:26:46.504: 657099 - 82 - 1128=935=X34=65709952=20140610-13:26:46.51075=20140610268=1279=0269=022=8207=BVMF48=380963983=254862270=26.4273=64:65:09271=500272=2014061037016=2014061037017=64:65:0937=80531937543288=40290=4
10:26:46.508: 657100 - 81 - 1128=935=X34=65710052=20140610-13:26:46.51475=20140610268=1279=0269=022=8207=BVMF48=380965483=79264270=8.21273=64:65:14271=200272=2014061037016=2014061037017=64:65:1437=80531937550288=40290=4
10:26:46.512: 657101 - 81 - 1128=935=X34=65710152=20140610-13:26:46.51775=20140610268=1279=0269=022=8207=BVMF48=380249383=103328270=9.33273=64:65:17271=200272=2014061037016=2014061037017=64:65:1737=80531937551288=40290=1
10:26:46.528: 657102 - 119 - 1128=935=X34=65710252=20140610-13:26:46.53475=20140610268=2279=2269=022=8207=BVMF48=380963983=254863273=64:65:34272=2014061037=80531937519288=45290=19279=0269=022=8207=BVMF48=380963983=254864270=26.4273=64:65:34271=500272=2014061037016=2014061037017=64:65:3337=80531937566288=45290=5
10:26:46.585: 657103 - 70 - 1128=935=X34=65710352=20140610-13:26:46.59075=20140610268=1279=2269=022=8207=BVMF48=380249383=103329273=64:65:90272=2014061037=80531936604288=3290=44
10:26:46.706: 657104 - 71 - 1128=935=X34=65710452=20140610-13:26:46.71175=20140610268=1279=2269=122=8207=BVMF48=380965483=79265273=64:67:11272=2014061037=80531919357289=8290=15
10:26:46.993: 657105 - 70 - 1128=935=X34=65710552=20140610-13:26:46.99975=20140610268=1279=2269=022=8207=BVMF48=380394783=65653273=64:69:98272=2014061037=80531935713288=8290=5
10:26:47.028: 657106 - 80 - 1128=935=X34=65710652=20140610-13:26:47.03475=20140610268=1279=0269=022=8207=BVMF48=380394783=65654270=17.03273=64:70:34271=400272=2014061037016=2014061037017=64:70:3437=80531937569288=8290=2
10:26:47.047: 657107 - 70 - 1128=935=X34=65710752=20140610-13:26:47.05275=20140610268=1279=2269=022=8207=BVMF48=380391383=106041273=64:70:52272=2014061037=80531935712288=8290=33
10:26:47.059: 657108 - 145 - 1128=935=X34=65710852=20140610-13:26:47.06475=20140610268=3279=0269=222=8207=BVMF48=380394783=65655270=17.03273=64:70:64271=100272=2014061037016=2014061037017=64:70:631500=E451=-0.131020=18500274=1277=L1003=1090288=40289=8279=0269=922=8207=BVMF48=380394783=65656270=17.101273=64:70:64272=201406101500=E279=2269=022=8207=BVMF48=380394783=65657273=64:70:64272=2014061037=80531935257288=40290=1
10:26:47.075: 657109 - 80 - 1128=935=X34=65710952=20140610-13:26:47.08075=20140610268=1279=0269=022=8207=BVMF48=380391383=106042270=13.78273=64:70:80271=600272=2014061037016=2014061037017=64:70:8037=80531937572288=8290=34
10:26:47.091: 657110 - 70 - 1128=935=X34=65711052=20140610-13:26:47.09775=20140610268=1279=2269=022=8207=BVMF48=380391383=106043273=64:70:97272=2014061037=80531937572288=8290=34
10:26:47.101: 657111 - 80 - 1128=935=X34=65711152=20140610-13:26:47.10675=20140610268=1279=0269=022=8207=BVMF48=380391383=106044270=13.78273=64:71:06271=400272=2014061037016=2014061037017=64:71:0637=80531937573288=8290=34
10:26:47.150: 657112 - 71 - 1128=935=X34=65711252=20140610-13:26:47.15575=20140610268=1279=2269=122=8207=BVMF48=380394783=65658273=64:71:55272=2014061037=80531934875289=8290=7
10:26:47.151: 657113 - 81 - 1128=935=X34=65711352=20140610-13:26:47.15775=20140610268=1279=0269=122=8207=BVMF48=380394783=65659270=17.06273=64:71:56271=100272=2014061037016=2014061037017=64:71:5637=80531937574289=8290=8
10:26:47.244: 657114 - 81 - 1128=935=X34=65711452=20140610-13:26:47.25075=20140610268=1279=0269=022=8207=BVMF48=380963983=254865270=26.4273=64:72:49271=600272=2014061037016=2014061037017=64:72:4937=80531937586288=3290=6
10:26:47.252: 657115 - 81 - 1128=935=X34=65711552=20140610-13:26:47.25875=20140610268=1279=0269=022=8207=BVMF48=380963983=254866270=26.4273=64:72:57271=300272=2014061037016=2014061037017=64:72:5737=80531937591288=3290=7
10:26:47.273: 657116 - 81 - 1128=935=X34=65711652=20140610-13:26:47.27975=20140610268=1279=0269=022=8207=BVMF48=380963983=254867270=26.4273=64:72:78271=600272=2014061037016=2014061037017=64:72:7837=80531937601288=3290=8
10:26:47.277: 657117 - 81 - 1128=935=X34=65711752=20140610-13:26:47.28375=20140610268=1279=0269=022=8207=BVMF48=380963983=254868270=26.4273=64:72:82271=600272=2014061037016=2014061037017=64:72:8237=80531937605288=3290=9
10:26:47.288: 657118 - 82 - 1128=935=X34=65711852=20140610-13:26:47.29475=20140610268=1279=0269=022=8207=BVMF48=380963983=254869270=26.4273=64:72:93271=800272=2014061037016=2014061037017=64:72:9337=80531937612288=88290=10
10:26:47.292: 657119 - 70 - 1128=935=X34=65711952=20140610-13:26:47.29775=20140610268=1279=2269=022=8207=BVMF48=380963983=254870273=64:72:96272=2014061037=80531937601288=3290=8
10:26:47.298: 657120 - 81 - 1128=935=X34=65712052=20140610-13:26:47.30475=20140610268=1279=0269=022=8207=BVMF48=380963983=254871270=26.4273=64:73:03271=600272=2014061037016=2014061037017=64:73:0337=80531937614288=3290=10
10:26:47.307: 657121 - 199 - 1128=935=X34=65712152=20140610-13:26:47.31375=20140610268=4279=0269=222=8207=BVMF48=380963983=254872270=26.41273=64:73:12271=300272=2014061037016=2014061037017=64:73:121500=E451=-0.21020=1331400274=01003=17750288=3289=114279=0269=922=8207=BVMF48=380963983=254873270=26.473273=64:73:12272=201406101500=E279=1269=122=8207=BVMF48=380963983=254874270=26.41273=64:73:12271=1400272=2014061037016=2014061037017=64:17:4537=80531937200289=114290=1279=2269=022=8207=BVMF48=380963983=254875273=64:73:12272=2014061037=80531937614288=3290=10
10:26:47.312: 657122 - 73 - 1128=935=X34=65712252=20140610-13:26:47.31875=20140610268=1279=2269=122=8207=BVMF48=380963983=254876273=64:73:17272=2014061037=80531937200289=114290=1
10:26:47.313: 657123 - 199 - 1128=935=X34=65712352=20140610-13:26:47.31975=20140610268=4279=0269=222=8207=BVMF48=380968883=253099270=29.39273=64:73:18271=200272=2014061037016=2014061037017=64:73:181500=E451=-0.241020=418200274=1277=L1003=6040288=114289=45279=0269=922=8207=BVMF48=380968883=253100270=29.485273=64:73:18272=201406101500=E279=1269=122=8207=BVMF48=380968883=253101270=29.39273=64:73:18271=1300272=2014061037016=2014061037017=64:17:2837=80531937178289=45290=1279=2269=022=8207=BVMF48=380968883=253102273=64:73:18272=2014061037=80531937474288=114290=5
10:26:47.313: 657124 - 72 - 1128=935=X34=65712452=20140610-13:26:47.31975=20140610268=1279=2269=122=8207=BVMF48=380968883=253103273=64:73:19272=2014061037=80531937304289=45290=25
10:26:47.314: 657125 - 282 - 1128=935=X34=65712552=20140610-13:26:47.32075=20140610268=7279=0269=222=8207=BVMF48=380963983=254877270=26.41273=64:73:19271=300272=2014061037016=2014061037017=64:73:191500=E451=-0.21020=1331700274=1277=L1003=17760288=45289=9279=0269=922=8207=BVMF48=380963983=254878270=26.473273=64:73:19272=201406101500=E279=0269=222=8207=BVMF48=380963983=254879270=26.41273=64:73:19271=200272=2014061037016=2014061037017=64:73:191500=E451=-0.21020=1331900274=1277=L1003=17770288=45289=238279=0269=922=8207=BVMF48=380963983=254880270=26.473273=64:73:19272=201406101500=E279=0269=222=8207=BVMF48=380963983=254881270=26.41273=64:73:19271=200272=2014061037016=2014061037017=64:73:191500=E451=-0.21020=1332100274=1277=L1003=17780288=45289=40279=0269=922=8207=BVMF48=380963983=254882270=26.473273=64:73:19272=201406101500=E279=4269=122=8207=BVMF48=380963983=254883273=64:73:19272=20140610290=3
10:26:47.316: 657126 - 118 - 1128=935=X34=65712652=20140610-13:26:47.32275=20140610268=2279=2269=022=8207=BVMF48=380963983=254884273=64:73:21272=2014061037=80531924222288=45290=52279=0269=022=8207=BVMF48=380963983=254885270=26.41273=64:73:21271=5000272=2014061037016=2014061037017=64:73:2137=80531937634288=45290=1
10:26:47.317: 657127 - 81 - 1128=935=X34=65712752=20140610-13:26:47.32375=20140610268=1279=0269=022=8207=BVMF48=380963983=254886270=26.4273=64:73:23271=600272=2014061037016=2014061037017=64:73:2237=80531937635288=3290=11
10:26:47.317: 657128 - 72 - 1128=935=X34=65712852=20140610-13:26:47.32375=20140610268=1279=2269=122=8207=BVMF48=380963983=254887273=64:73:23272=2014061037=80531937512289=45290=12
10:26:47.318: 657129 - 118 - 1128=935=X34=65712952=20140610-13:26:47.32375=20140610268=2279=2269=022=8207=BVMF48=380963983=254888273=64:73:23272=2014061037=80531937524288=45290=67279=0269=022=8207=BVMF48=380963983=254889270=26.41273=64:73:23271=3000272=2014061037016=2014061037017=64:73:2337=80531937637288=45290=2
10:26:47.318: 657130 - 160 - 1128=935=X34=65713052=20140610-13:26:47.32475=20140610268=3279=0269=222=8207=BVMF48=380963983=254890270=26.41273=64:73:23271=1600272=2014061037016=2014061037017=64:73:231500=E451=-0.21020=1333700274=1277=L1003=17790288=45289=114279=0269=922=8207=BVMF48=380963983=254891270=26.473273=64:73:23272=201406101500=E279=1269=022=8207=BVMF48=380963983=254892270=26.41273=64:73:23271=3400272=2014061037016=2014061037017=64:73:2137=80531937634288=45290=1
10:26:47.318: 657131 - 118 - 1128=935=X34=65713152=20140610-13:26:47.32475=20140610268=2279=2269=022=8207=BVMF48=380968883=253104273=64:73:24272=2014061037=80531937274288=45290=24279=0269=022=8207=BVMF48=380968883=253105270=29.36273=64:73:24271=2000272=2014061037016=2014061037017=64:73:2337=80531937642288=45290=13
10:26:47.318: 657132 - 82 - 1128=935=X34=65713252=20140610-13:26:47.32475=20140610268=1279=0269=022=8207=BVMF48=380968883=253106270=29.38273=64:73:24271=1600272=2014061037016=2014061037017=64:73:2437=80531937644288=114290=6
10:26:47.319: 657133 - 71 - 1128=935=X34=65713352=20140610-13:26:47.32575=20140610268=1279=2269=022=8207=BVMF48=380963983=254893273=64:73:25272=2014061037=80531937634288=45290=1
10:26:47.319: 657134 - 72 - 1128=935=X34=65713452=20140610-13:26:47.32575=20140610268=1279=2269=122=8207=BVMF48=380963983=254894273=64:73:25272=2014061037=80531937523289=45290=55
10:26:47.322: 657135 - 116 - 1128=935=X34=65713552=20140610-13:26:47.32775=20140610268=2279=2269=022=8207=BVMF48=380963983=254895273=64:73:27272=2014061037=80531937586288=3290=7279=0269=022=8207=BVMF48=380963983=254896270=26.41273=64:73:27271=600272=2014061037016=2014061037017=64:73:2737=80531937650288=3290=2
10:26:47.323: 657136 - 80 - 1128=935=X34=65713652=20140610-13:26:47.32975=20140610268=1279=0269=022=8207=BVMF48=380963983=254897270=26.41273=64:73:28271=600272=2014061037016=2014061037017=64:73:2837=80531937653288=3290=3
10:26:47.323: 657137 - 349 - 1128=935=X34=65713752=20140610-13:26:47.32975=20140610268=8279=0269=222=8207=BVMF48=380968883=253107270=29.39273=64:73:29271=1300272=2014061037016=2014061037017=64:73:281500=E451=-0.241020=419500274=1277=L1003=6050288=114289=45279=0269=922=8207=BVMF48=380968883=253108270=29.484273=64:73:29272=201406101500=E279=2269=122=8207=BVMF48=380968883=253109273=64:73:29272=2014061037=80531937178289=45290=1279=0269=122=8207=BVMF48=380968883=253110270=29.39273=64:73:29271=5000272=2014061037016=2014061037017=64:73:2837=80531937655289=45290=1279=0269=222=8207=BVMF48=380968883=253111270=29.39273=64:73:29271=200272=2014061037016=2014061037017=64:73:281500=E451=-0.241020=419700274=1277=L1003=6060288=114289=45279=0269=922=8207=BVMF48=380968883=253112270=29.484273=64:73:29272=201406101500=E279=1269=122=8207=BVMF48=380968883=253113270=29.39273=64:73:29271=4800272=2014061037016=2014061037017=64:73:2837=80531937655289=45290=1279=2269=022=8207=BVMF48=380968883=253114273=64:73:29272=2014061037=80531937644288=114290=6
10:26:47.326: 657138 - 116 - 1128=935=X34=65713852=20140610-13:26:47.33275=20140610268=2279=2269=022=8207=BVMF48=380963983=254898273=64:73:32272=2014061037=80531937635288=3290=12279=0269=022=8207=BVMF48=380963983=254899270=26.41273=64:73:32271=600272=2014061037016=2014061037017=64:73:3137=80531937658288=3290=4
10:26:47.327: 657139 - 118 - 1128=935=X34=65713952=20140610-13:26:47.33375=20140610268=2279=2269=022=8207=BVMF48=380963983=254900273=64:73:33272=2014061037=80531937543288=40290=8279=0269=022=8207=BVMF48=380963983=254901270=26.41273=64:73:33271=500272=2014061037016=2014061037017=64:73:3337=80531937660288=40290=5
10:26:47.328: 657140 - 197 - 1128=935=X34=65714052=20140610-13:26:47.33475=20140610268=4279=0269=222=8207=BVMF48=380963983=254902270=26.42273=64:73:33271=600272=2014061037016=2014061037017=64:73:331500=E451=-0.191020=1334300274=01003=17800288=3289=40279=0269=922=8207=BVMF48=380963983=254903270=26.473273=64:73:33272=201406101500=E279=1269=122=8207=BVMF48=380963983=254904270=26.42273=64:73:33271=100272=2014061037016=2014061037017=64:17:0237=80531937118289=40290=1279=2269=022=8207=BVMF48=380963983=254905273=64:73:33272=2014061037=80531937650288=3290=2
10:26:47.330: 657141 - 310 - 1128=935=X34=65714152=20140610-13:26:47.33575=20140610268=7279=0269=222=8207=BVMF48=380963983=254906270=26.42273=64:73:35271=100272=2014061037016=2014061037017=64:73:341500=E451=-0.191020=1334400274=1277=L1003=17810288=3289=40279=0269=922=8207=BVMF48=380963983=254907270=26.473273=64:73:35272=201406101500=E279=0269=222=8207=BVMF48=380963983=254908270=26.43273=64:73:35271=500272=2014061037016=2014061037017=64:73:341500=E451=-0.181020=1334900274=01003=17820288=3289=106279=0269=922=8207=BVMF48=380963983=254909270=26.473273=64:73:35272=201406101500=E279=2269=122=8207=BVMF48=380963983=254910273=64:73:35272=2014061037=80531937118289=40290=1279=1269=122=8207=BVMF48=380963983=254911270=26.43273=64:73:35271=8700272=2014061037016=2014061037017=33:65:1137=80531926113289=106290=1279=2269=022=8207=BVMF48=380963983=254912273=64:73:35272=2014061037=80531937653288=3290=2
10:26:47.330: 657142 - 160 - 1128=935=X34=65714252=20140610-13:26:47.33575=20140610268=3279=0269=222=8207=BVMF48=380963983=254913270=26.41273=64:73:35271=100272=2014061037016=2014061037017=64:73:351500=E451=-0.21020=1335000274=21003=17830288=45289=114279=0269=922=8207=BVMF48=380963983=254914270=26.473273=64:73:35272=201406101500=E279=1269=022=8207=BVMF48=380963983=254915270=26.41273=64:73:35271=2900272=2014061037016=2014061037017=64:73:2337=80531937637288=45290=1
10:26:47.330: 657143 - 82 - 1128=935=X34=65714352=20140610-13:26:47.33675=20140610268=1279=0269=022=8207=BVMF48=380968883=253115270=29.38273=64:73:35271=100272=2014061037016=2014061037017=64:73:3537=80531937664288=114290=6
10:26:47.331: 657144 - 71 - 1128=935=X34=65714452=20140610-13:26:47.33775=20140610268=1279=2269=022=8207=BVMF48=380963983=254916273=64:73:36272=2014061037=80531918208288=45290=58
10:26:47.332: 657145 - 199 - 1128=935=X34=65714552=20140610-13:26:47.33775=20140610268=4279=0269=222=8207=BVMF48=380963983=254917270=26.43273=64:73:37271=600272=2014061037016=2014061037017=64:73:371500=E451=-0.181020=1335600274=01003=17840288=3289=106279=0269=922=8207=BVMF48=380963983=254918270=26.473273=64:73:37272=201406101500=E279=1269=122=8207=BVMF48=380963983=254919270=26.43273=64:73:37271=8100272=2014061037016=2014061037017=33:65:1137=80531926113289=106290=1279=2269=022=8207=BVMF48=380963983=254920273=64:73:37272=2014061037=80531937658288=3290=2
10:26:47.335: 657146 - 81 - 1128=935=X34=65714652=20140610-13:26:47.34175=20140610268=1279=0269=022=8207=BVMF48=380963983=254921270=26.4273=64:73:40271=600272=2014061037016=2014061037017=64:73:4037=80531937669288=3290=10
10:26:47.336: 657147 - 71 - 1128=935=X34=65714752=20140610-13:26:47.34275=20140610268=1279=2269=122=8207=BVMF48=380963983=254922273=64:73:41272=2014061037=80531936509289=8290=4
10:26:47.336: 657148 - 70 - 1128=935=X34=65714852=20140610-13:26:47.34275=20140610268=1279=2269=022=8207=BVMF48=380963983=254923273=64:73:42272=2014061037=80531937591288=3290=7
10:26:47.340: 657149 - 80 - 1128=935=X34=65714952=20140610-13:26:47.34675=20140610268=1279=0269=022=8207=BVMF48=380963983=254924270=26.38273=64:73:45271=300272=2014061037016=2014061037017=64:73:4537=80531937682288=8290=17
10:26:47.342: 657150 - 118 - 1128=935=X34=65715052=20140610-13:26:47.34875=20140610268=2279=2269=022=8207=BVMF48=380963983=254925273=64:73:47272=2014061037=80531937660288=40290=2279=0269=022=8207=BVMF48=380963983=254926270=26.42273=64:73:47271=500272=2014061037016=2014061037017=64:73:4737=80531937693288=40290=1
10:26:47.345: 657151 - 81 - 1128=935=X34=65715152=20140610-13:26:47.35075=20140610268=1279=0269=022=8207=BVMF48=380963983=254927270=26.4273=64:73:50271=600272=2014061037016=2014061037017=64:73:5037=80531937695288=3290=10
10:26:47.349: 657152 - 116 - 1128=935=X34=65715252=20140610-13:26:47.35575=20140610268=2279=2269=022=8207=BVMF48=380963983=254928273=64:73:54272=2014061037=80531937669288=3290=9279=0269=022=8207=BVMF48=380963983=254929270=26.41273=64:73:54271=600272=2014061037016=2014061037017=64:73:5437=80531937710288=3290=3
10:26:47.350: 657153 - 71 - 1128=935=X34=65715352=20140610-13:26:47.35675=20140610268=1279=2269=122=8207=BVMF48=380965483=79266273=64:73:55272=2014061037=80531935714289=3290=4
10:26:47.355: 657154 - 71 - 1128=935=X34=65715452=20140610-13:26:47.36175=20140610268=1279=2269=122=8207=BVMF48=380963983=254930273=64:73:60272=2014061037=80531936349289=8290=3
10:26:47.356: 657155 - 82 - 1128=935=X34=65715552=20140610-13:26:47.36175=20140610268=1279=0269=122=8207=BVMF48=380968883=253116270=29.4273=64:73:61271=100272=2014061037016=2014061037017=64:73:6137=80531937721289=8290=4
10:26:47.356: 657156 - 72 - 1128=935=X34=65715652=20140610-13:26:47.36275=20140610268=1279=2269=022=8207=BVMF48=380968883=253117273=64:73:61272=2014061037=80531937503288=227290=18
10:26:47.356: 657157 - 71 - 1128=935=X34=65715752=20140610-13:26:47.36275=20140610268=1279=2269=122=8207=BVMF48=380968883=253118273=64:73:61272=2014061037=80531937721289=8290=4
10:26:47.362: 657158 - 197 - 1128=935=X34=65715852=20140610-13:26:47.36775=20140610268=4279=0269=222=8207=BVMF48=380963983=254931270=26.42273=64:73:66271=500272=2014061037016=2014061037017=64:73:661500=E451=-0.191020=1336100274=21003=17850288=40289=40279=0269=922=8207=BVMF48=380963983=254932270=26.473273=64:73:66272=201406101500=E279=2269=022=8207=BVMF48=380963983=254933273=64:73:66272=2014061037=80531937693288=40290=1279=0269=122=8207=BVMF48=380963983=254934270=26.42273=64:73:66271=200272=2014061037016=2014061037017=64:73:6637=80531937733289=40290=1
10:26:47.366: 657159 - 82 - 1128=935=X34=65715952=20140610-13:26:47.37275=20140610268=1279=0269=022=8207=BVMF48=380968883=253119270=29.36273=64:73:71271=800272=2014061037016=2014061037017=64:73:7137=80531937740288=227290=15
10:26:47.370: 657160 - 70 - 1128=935=X34=65716052=20140610-13:26:47.37575=20140610268=1279=2269=022=8207=BVMF48=380963983=254935273=64:73:75272=2014061037=80531937695288=3290=9
10:26:47.382: 657161 - 71 - 1128=935=X34=65716152=20140610-13:26:47.38875=20140610268=1279=2269=122=8207=BVMF48=380963983=254936273=64:73:87272=2014061037=80531928642289=8290=6
10:26:47.382: 657162 - 71 - 1128=935=X34=65716252=20140610-13:26:47.38875=20140610268=1279=2269=122=8207=BVMF48=380963983=254937273=64:73:87272=2014061037=80531936734289=8290=6
10:26:47.382: 657163 - 81 - 1128=935=X34=65716352=20140610-13:26:47.38875=20140610268=1279=0269=122=8207=BVMF48=380963983=254938270=26.48273=64:73:87271=300272=2014061037016=2014061037017=64:73:8737=80531937746289=8290=36
10:26:47.384: 657164 - 81 - 1128=935=X34=65716452=20140610-13:26:47.39075=20140610268=1279=0269=122=8207=BVMF48=380963983=254939270=26.43273=64:73:89271=1000272=2014061037016=2014061037017=64:73:8937=80531937750289=3290=4
10:26:47.387: 657165 - 81 - 1128=935=X34=65716552=20140610-13:26:47.39375=20140610268=1279=0269=122=8207=BVMF48=380963983=254940270=26.43273=64:73:93271=1000272=2014061037016=2014061037017=64:73:9237=80531937751289=3290=5
10:26:47.389: 657166 - 71 - 1128=935=X34=65716652=20140610-13:26:47.39475=20140610268=1279=2269=022=8207=BVMF48=380963983=254941273=64:73:94272=2014061037=80531937612288=88290=8
10:26:47.393: 657167 - 82 - 1128=935=X34=65716752=20140610-13:26:47.39875=20140610268=1279=0269=122=8207=BVMF48=380963983=254942270=26.42273=64:73:98271=800272=2014061037016=2014061037017=64:73:9837=80531937752289=40290=2
10:26:47.408: 657168 - 70 - 1128=935=X34=65716852=20140610-13:26:47.41475=20140610268=1279=2269=022=8207=BVMF48=380968883=253120273=64:74:13272=2014061037=80531937384288=8290=10
10:26:47.414: 657169 - 70 - 1128=935=X34=65716952=20140610-13:26:47.42075=20140610268=1279=2269=022=8207=BVMF48=380968883=253121273=64:74:19272=2014061037=80531937455288=8290=9
10:26:47.414: 657170 - 72 - 1128=935=X34=65717052=20140610-13:26:47.42075=20140610268=1279=2269=122=8207=BVMF48=380963983=254943273=64:74:19272=2014061037=80531937733289=40290=1
10:26:47.415: 657171 - 70 - 1128=935=X34=65717152=20140610-13:26:47.42175=20140610268=1279=2269=022=8207=BVMF48=380968883=253122273=64:74:20272=2014061037=80531937513288=8290=9
10:26:47.415: 657172 - 72 - 1128=935=X34=65717252=20140610-13:26:47.42175=20140610268=1279=2269=122=8207=BVMF48=380963983=254944273=64:74:21272=2014061037=80531937752289=40290=1
10:26:47.416: 657173 - 81 - 1128=935=X34=65717352=20140610-13:26:47.42275=20140610268=1279=0269=122=8207=BVMF48=380963983=254945270=26.43273=64:74:22271=100272=2014061037016=2014061037017=64:74:2237=80531937754289=8290=5
10:26:47.419: 657174 - 82 - 1128=935=X34=65717452=20140610-13:26:47.42575=20140610268=1279=0269=122=8207=BVMF48=380963983=254946270=26.43273=64:74:24271=900272=2014061037016=2014061037017=64:74:2437=80531937755289=40290=6
10:26:47.434: 657175 - 81 - 1128=935=X34=65717552=20140610-13:26:47.44075=20140610268=1279=0269=122=8207=BVMF48=380963983=254947270=26.42273=64:74:39271=2500272=2014061037016=2014061037017=64:74:3937=80531937761289=8290=1
10:26:47.435: 657176 - 71 - 1128=935=X34=65717652=20140610-13:26:47.44175=20140610268=1279=2269=022=8207=BVMF48=380963983=254948273=64:74:40272=2014061037=80531937637288=45290=1
10:26:47.440: 657177 - 81 - 1128=935=X34=65717752=20140610-13:26:47.44675=20140610268=1279=0269=122=8207=BVMF48=380963983=254949270=26.44273=64:74:46271=300272=2014061037016=2014061037017=64:74:4537=80531937766289=8290=12
10:26:47.446: 657178 - 119 - 1128=935=X34=65717852=20140610-13:26:47.45175=20140610268=2279=2269=122=8207=BVMF48=380963983=254950273=64:74:51272=2014061037=80531937755289=40290=7279=0269=122=8207=BVMF48=380963983=254951270=26.42273=64:74:51271=900272=2014061037016=2014061037017=64:74:5137=80531937773289=40290=2
10:26:47.447: 657179 - 71 - 1128=935=X34=65717952=20140610-13:26:47.45275=20140610268=1279=2269=022=8207=BVMF48=380968883=253123273=64:74:52272=2014061037=80531937642288=45290=11
10:26:47.457: 657180 - 72 - 1128=935=X34=65718052=20140610-13:26:47.46375=20140610268=1279=2269=022=8207=BVMF48=380968883=253124273=64:74:62272=2014061037=80531937740288=227290=11
10:26:47.468: 657181 - 82 - 1128=935=X34=65718152=20140610-13:26:47.47375=20140610268=1279=0269=022=8207=BVMF48=380968883=253125270=29.36273=64:74:73271=500272=2014061037016=2014061037017=64:74:7337=80531937797288=227290=11
10:26:47.469: 657182 - 334 - 1128=935=X34=65718252=20140610-13:26:47.47575=20140610268=8279=0269=222=8207=BVMF48=380963983=254952270=26.41273=64:74:74271=600272=2014061037016=2014061037017=64:74:741500=E451=-0.21020=1336700274=21003=17860288=3289=308279=0269=922=8207=BVMF48=380963983=254953270=26.473273=64:74:74272=201406101500=E279=0269=222=8207=BVMF48=380963983=254954270=26.4273=64:74:74271=600272=2014061037016=2014061037017=64:74:741500=E451=-0.211020=1337300274=21003=17870288=3289=308279=0269=922=8207=BVMF48=380963983=254955270=26.473273=64:74:74272=201406101500=E279=0269=222=8207=BVMF48=380963983=254956270=26.4273=64:74:74271=1300272=2014061037016=2014061037017=64:74:741500=E451=-0.211020=1338600274=3277=L1003=17880288=45289=308279=0269=922=8207=BVMF48=380963983=254957270=26.473273=64:74:74272=201406101500=E279=4269=022=8207=BVMF48=380963983=254958273=64:74:74272=20140610290=2279=1269=022=8207=BVMF48=380963983=254959270=26.4273=64:74:74271=3700272=2014061037016=2014061037017=64:26:5137=80531937460288=45290=1
10:26:47.472: 657183 - 157 - 1128=935=X34=65718352=20140610-13:26:47.47775=20140610268=3279=0269=222=8207=BVMF48=380963983=254960270=26.42273=64:74:77271=200272=2014061037016=2014061037017=64:74:771500=E451=-0.191020=1338800274=01003=17890288=88289=8279=0269=922=8207=BVMF48=380963983=254961270=26.473273=64:74:77272=201406101500=E279=1269=122=8207=BVMF48=380963983=254962270=26.42273=64:74:77271=2300272=2014061037016=2014061037017=64:74:3937=80531937761289=8290=1
10:26:47.477: 657184 - 81 - 1128=935=X34=65718452=20140610-13:26:47.48375=20140610268=1279=0269=122=8207=BVMF48=380963983=254963270=26.43273=64:74:83271=100272=2014061037016=2014061037017=64:74:8237=80531937808289=8290=8
10:26:47.479: 657185 - 81 - 1128=935=X34=65718552=20140610-13:26:47.48475=20140610268=1279=0269=122=8207=BVMF48=380963983=254964270=26.43273=64:74:84271=1000272=2014061037016=2014061037017=64:74:8437=80531937814289=8290=9
10:26:47.482: 657186 - 80 - 1128=935=X34=65718652=20140610-13:26:47.48875=20140610268=1279=0269=022=8207=BVMF48=380963983=254965270=26.41273=64:74:87271=600272=2014061037016=2014061037017=64:74:8737=80531937820288=3290=1
10:26:47.487: 657187 - 156 - 1128=935=X34=65718752=20140610-13:26:47.49375=20140610268=3279=0269=222=8207=BVMF48=380968883=253126270=29.39273=64:74:93271=200272=2014061037016=2014061037017=64:74:921500=E451=-0.241020=419900274=1277=L1003=6070288=8289=45279=0269=922=8207=BVMF48=380968883=253127270=29.484273=64:74:93272=201406101500=E279=1269=122=8207=BVMF48=380968883=253128270=29.39273=64:74:93271=4600272=2014061037016=2014061037017=64:73:2837=80531937655289=45290=1
10:26:47.490: 657188 - 81 - 1128=935=X34=65718852=20140610-13:26:47.49575=20140610268=1279=0269=122=8207=BVMF48=380963983=254966270=26.44273=64:74:95271=300272=2014061037016=2014061037017=64:74:9537=80531937832289=8290=15
10:26:47.490: 657189 - 70 - 1128=935=X34=65718952=20140610-13:26:47.49675=20140610268=1279=2269=022=8207=BVMF48=380963983=254967273=64:74:95272=2014061037=80531937456288=8290=20
10:26:47.492: 657190 - 81 - 1128=935=X34=65719052=20140610-13:26:47.49875=20140610268=1279=0269=022=8207=BVMF48=380963983=254968270=26.4273=64:74:97271=600272=2014061037016=2014061037017=64:74:9737=80531937835288=3290=6
10:26:47.493: 657191 - 71 - 1128=935=X34=65719152=20140610-13:26:47.49975=20140610268=1279=2269=122=8207=BVMF48=380963983=254969273=64:74:98272=2014061037=80531937761289=8290=1
10:26:47.496: 657192 - 81 - 1128=935=X34=65719252=20140610-13:26:47.50275=20140610268=1279=0269=022=8207=BVMF48=380963983=254970270=26.4273=64:75:01271=600272=2014061037016=2014061037017=64:75:0137=80531937836288=3290=7
10:26:47.503: 657193 - 72 - 1128=935=X34=65719352=20140610-13:26:47.50875=20140610268=1279=2269=022=8207=BVMF48=380968883=253129273=64:75:08272=2014061037=80531937797288=227290=11
10:26:47.508: 657194 - 231 - 1128=935=X34=65719452=20140610-13:26:47.51475=20140610268=5279=0269=222=8207=BVMF48=380963983=254971270=26.41273=64:75:14271=600272=2014061037016=2014061037017=64:75:131500=E451=-0.21020=1339400274=21003=17900288=3289=40279=0269=922=8207=BVMF48=380963983=254972270=26.473273=64:75:14272=201406101500=E279=2269=022=8207=BVMF48=380963983=254973273=64:75:14272=2014061037=80531937820288=3290=1279=2269=122=8207=BVMF48=380963983=254974273=64:75:14272=2014061037=80531937773289=40290=1279=0269=122=8207=BVMF48=380963983=254975270=26.41273=64:75:14271=300272=2014061037016=2014061037017=64:75:1337=80531937848289=40290=1
10:26:47.515: 657195 - 82 - 1128=935=X34=65719552=20140610-13:26:47.52075=20140610268=1279=0269=122=8207=BVMF48=380968883=253130270=29.49273=64:75:20271=2000272=2014061037016=2014061037017=64:75:2037=80531937859289=45290=28
10:26:47.521: 657196 - 194 - 1128=935=X34=65719652=20140610-13:26:47.52675=20140610268=4279=0269=222=8207=BVMF48=380963983=254976270=26.41273=64:75:26271=300272=2014061037016=2014061037017=64:75:251500=E451=-0.21020=1339700274=3277=L1003=17910288=3289=40279=0269=922=8207=BVMF48=380963983=254977270=26.473273=64:75:26272=201406101500=E279=2269=122=8207=BVMF48=380963983=254978273=64:75:26272=2014061037=80531937848289=40290=1279=0269=022=8207=BVMF48=380963983=254979270=26.41273=64:75:26271=300272=2014061037016=2014061037017=64:75:2537=80531937863288=3290=1
10:26:47.522: 657197 - 81 - 1128=935=X34=65719752=20140610-13:26:47.52875=20140610268=1279=0269=122=8207=BVMF48=380963983=254980270=26.42273=64:75:27271=3000272=2014061037016=2014061037017=64:75:2737=80531937864289=8290=1
10:26:47.525: 657198 - 70 - 1128=935=X34=65719852=20140610-13:26:47.53175=20140610268=1279=2269=022=8207=BVMF48=380963983=254981273=64:75:30272=2014061037=80531937863288=3290=1
10:26:47.532: 657199 - 82 - 1128=935=X34=65719952=20140610-13:26:47.53875=20140610268=1279=0269=022=8207=BVMF48=380968883=253131270=29.35273=64:75:37271=800272=2014061037016=2014061037017=64:75:3737=80531937875288=227290=14
10:26:47.542: 657200 - 80 - 1128=935=X34=65720052=20140610-13:26:47.54875=20140610268=1279=0269=022=8207=BVMF48=380963983=254982270=26.41273=64:75:48271=600272=2014061037016=2014061037017=64:75:4837=80531937896288=3290=1
10:26:47.554: 657201 - 82 - 1128=935=X34=65720152=20140610-13:26:47.56075=20140610268=1279=0269=122=8207=BVMF48=380963983=254983270=26.42273=64:75:60271=900272=2014061037016=2014061037017=64:75:6037=80531937905289=40290=2
10:26:47.560: 657202 - 72 - 1128=935=X34=65720252=20140610-13:26:47.56575=20140610268=1279=2269=022=8207=BVMF48=380968883=253132273=64:75:65272=2014061037=80531937875288=227290=14
10:26:47.570: 657203 - 82 - 1128=935=X34=65720352=20140610-13:26:47.57675=20140610268=1279=0269=022=8207=BVMF48=380968883=253133270=29.36273=64:75:75271=500272=2014061037016=2014061037017=64:75:7537=80531937915288=227290=11
10:26:47.608: 657204 - 197 - 1128=935=X34=65720452=20140610-13:26:47.61475=20140610268=4279=0269=222=8207=BVMF48=380963983=254984270=26.42273=64:76:13271=500272=2014061037016=2014061037017=64:76:131500=E451=-0.191020=1340200274=01003=17920288=45289=8279=0269=922=8207=BVMF48=380963983=254985270=26.473273=64:76:13272=201406101500=E279=1269=122=8207=BVMF48=380963983=254986270=26.42273=64:76:13271=2500272=2014061037016=2014061037017=64:75:2737=80531937864289=8290=1279=2269=022=8207=BVMF48=380963983=254987273=64:76:13272=2014061037=80531937566288=45290=4
10:26:47.610: 657205 - 80 - 1128=935=X34=65720552=20140610-13:26:47.61675=20140610268=1279=0269=022=8207=BVMF48=380968883=253134270=29.37273=64:76:15271=2500272=2014061037016=2014061037017=64:76:1537=80531937923288=8290=9
10:26:47.629: 657206 - 81 - 1128=935=X34=65720652=20140610-13:26:47.63475=20140610268=1279=0269=022=8207=BVMF48=380963983=254988270=26.38273=64:76:34271=300272=2014061037016=2014061037017=64:76:3437=80531937928288=45290=15
10:26:47.648: 657207 - 81 - 1128=935=X34=65720752=20140610-13:26:47.65475=20140610268=1279=0269=022=8207=BVMF48=380968883=253135270=29.33273=64:76:54271=2000272=2014061037016=2014061037017=64:76:5337=80531937931288=45290=23
10:26:47.723: 657208 - 71 - 1128=935=X34=65720852=20140610-13:26:47.72975=20140610268=1279=2269=122=8207=BVMF48=380394783=65660273=64:77:28272=2014061037=80531936188289=3290=2
10:26:47.725: 657209 - 70 - 1128=935=X34=65720952=20140610-13:26:47.73075=20140610268=1279=2269=022=8207=BVMF48=380968883=253136273=64:77:30272=2014061037=80531937923288=8290=9
10:26:47.734: 657210 - 81 - 1128=935=X34=65721052=20140610-13:26:47.74075=20140610268=1279=0269=122=8207=BVMF48=380963983=254989270=26.42273=64:77:40271=2500272=2014061037016=2014061037017=64:77:4037=80531937946289=8290=3
10:26:47.750: 657211 - 70 - 1128=935=X34=65721152=20140610-13:26:47.75575=20140610268=1279=2269=022=8207=BVMF48=380963983=254990273=64:77:55272=2014061037=80531937836288=3290=6
10:26:47.753: 657212 - 117 - 1128=935=X34=65721252=20140610-13:26:47.75975=20140610268=2279=2269=022=8207=BVMF48=380963983=254991273=64:77:59272=2014061037=80531937896288=3290=1279=0269=022=8207=BVMF48=380963983=254992270=26.4273=64:77:59271=600272=2014061037016=2014061037017=64:77:5937=80531937969288=3290=5
10:26:47.773: 657213 - 81 - 1128=935=X34=65721352=20140610-13:26:47.77875=20140610268=1279=0269=022=8207=BVMF48=380963983=254993270=26.4273=64:77:78271=600272=2014061037016=2014061037017=64:77:7837=80531937983288=3290=6
10:26:47.777: 657214 - 72 - 1128=935=X34=65721452=20140610-13:26:47.78275=20140610268=1279=2269=022=8207=BVMF48=380968883=253137273=64:77:82272=2014061037=80531937915288=227290=11
10:26:47.784: 657215 - 119 - 1128=935=X34=65721552=20140610-13:26:47.78975=20140610268=2279=2269=122=8207=BVMF48=380963983=254994273=64:77:88272=2014061037=80531937905289=40290=2279=0269=122=8207=BVMF48=380963983=254995270=26.41273=64:77:88271=900272=2014061037016=2014061037017=64:77:8837=80531937988289=40290=1
10:26:47.785: 657216 - 82 - 1128=935=X34=65721652=20140610-13:26:47.79075=20140610268=1279=0269=022=8207=BVMF48=380963983=254996270=26.4273=64:77:90271=800272=2014061037016=2014061037017=64:77:8937=80531937989288=88290=7
10:26:47.785: 657217 - 119 - 1128=935=X34=65721752=20140610-13:26:47.79075=20140610268=2279=2269=122=8207=BVMF48=380968883=253138273=64:77:90272=2014061037=80531937859289=45290=28279=0269=122=8207=BVMF48=380968883=253139270=29.48273=64:77:90271=2000272=2014061037016=2014061037017=64:77:9037=80531937990289=45290=25
10:26:47.786: 657218 - 82 - 1128=935=X34=65721852=20140610-13:26:47.79275=20140610268=1279=0269=022=8207=BVMF48=380968883=253140270=29.35273=64:77:91271=800272=2014061037016=2014061037017=64:77:9137=80531937992288=227290=14
10:26:47.827: 657219 - 119 - 1128=935=X34=65721952=20140610-13:26:47.83275=20140610268=2279=2269=022=8207=BVMF48=380963983=254997273=64:78:31272=2014061037=80531937928288=45290=16279=0269=022=8207=BVMF48=380963983=254998270=26.4273=64:78:31271=800272=2014061037016=2014061037017=64:78:3137=80531938006288=45290=8
10:26:47.834: 657220 - 70 - 1128=935=X34=65722052=20140610-13:26:47.84075=20140610268=1279=2269=022=8207=BVMF48=380963983=254999273=64:78:39272=2014061037=80531937983288=3290=6
10:26:47.842: 657221 - 81 - 1128=935=X34=65722152=20140610-13:26:47.84775=20140610268=1279=0269=022=8207=BVMF48=380963983=255000270=26.4273=64:78:47271=600272=2014061037016=2014061037017=64:78:4737=80531938010288=3290=8
10:26:47.859: 657222 - 197 - 1128=935=X34=65722252=20140610-13:26:47.86575=20140610268=4279=0269=222=8207=BVMF48=380963983=255001270=26.41273=64:78:64271=600272=2014061037016=2014061037017=64:78:641500=E451=-0.21020=1340800274=21003=17930288=3289=40279=0269=922=8207=BVMF48=380963983=255002270=26.473273=64:78:64272=201406101500=E279=1269=122=8207=BVMF48=380963983=255003270=26.41273=64:78:64271=300272=2014061037016=2014061037017=64:77:8837=80531937988289=40290=1279=2269=022=8207=BVMF48=380963983=255004273=64:78:64272=2014061037=80531937969288=3290=5
10:26:47.864: 657223 - 70 - 1128=935=X34=65722352=20140610-13:26:47.86975=20140610268=1279=2269=022=8207=BVMF48=380963983=255005273=64:78:69272=2014061037=80531938010288=3290=7
10:26:47.869: 657224 - 194 - 1128=935=X34=65722452=20140610-13:26:47.87575=20140610268=4279=0269=222=8207=BVMF48=380963983=255006270=26.41273=64:78:74271=300272=2014061037016=2014061037017=64:78:741500=E451=-0.21020=1341100274=3277=L1003=17940288=3289=40279=0269=922=8207=BVMF48=380963983=255007270=26.473273=64:78:74272=201406101500=E279=2269=122=8207=BVMF48=380963983=255008273=64:78:74272=2014061037=80531937988289=40290=1279=0269=022=8207=BVMF48=380963983=255009270=26.41273=64:78:74271=300272=2014061037016=2014061037017=64:78:7437=80531938022288=3290=1
10:26:47.873: 657225 - 81 - 1128=935=X34=65722552=20140610-13:26:47.87875=20140610268=1279=0269=022=8207=BVMF48=380963983=255010270=26.4273=64:78:77271=600272=2014061037016=2014061037017=64:78:7737=80531938025288=3290=8
10:26:47.874: 657226 - 70 - 1128=935=X34=65722652=20140610-13:26:47.87975=20140610268=1279=2269=022=8207=BVMF48=380963983=255011273=64:78:79272=2014061037=80531938022288=3290=1
10:26:47.882: 657227 - 80 - 1128=935=X34=65722752=20140610-13:26:47.88775=20140610268=1279=0269=022=8207=BVMF48=380963983=255012270=26.41273=64:78:86271=600272=2014061037016=2014061037017=64:78:8637=80531938032288=3290=1
10:26:47.890: 657228 - 195 - 1128=935=X34=65722852=20140610-13:26:47.89575=20140610268=4279=0269=222=8207=BVMF48=380963983=255013270=26.41273=64:78:95271=600272=2014061037016=2014061037017=64:78:941500=E451=-0.21020=1341700274=3277=L1003=17950288=3289=40279=0269=922=8207=BVMF48=380963983=255014270=26.473273=64:78:95272=201406101500=E279=2269=022=8207=BVMF48=380963983=255015273=64:78:95272=2014061037=80531938032288=3290=1279=0269=122=8207=BVMF48=380963983=255016270=26.41273=64:78:95271=100272=2014061037016=2014061037017=64:78:9437=80531938036289=40290=1
10:26:47.904: 657229 - 195 - 1128=935=X34=65722952=20140610-13:26:47.90975=20140610268=4279=0269=222=8207=BVMF48=380963983=255017270=26.41273=64:79:09271=100272=2014061037016=2014061037017=64:79:081500=E451=-0.21020=1341800274=3277=L1003=17960288=3289=40279=0269=922=8207=BVMF48=380963983=255018270=26.473273=64:79:09272=201406101500=E279=2269=122=8207=BVMF48=380963983=255019273=64:79:09272=2014061037=80531938036289=40290=1279=0269=022=8207=BVMF48=380963983=255020270=26.41273=64:79:09271=500272=2014061037016=2014061037017=64:79:0837=80531938049288=3290=1
10:26:47.906: 657230 - 117 - 1128=935=X34=65723052=20140610-13:26:47.91275=20140610268=2279=2269=022=8207=BVMF48=380566083=11394273=64:79:11272=2014061037=80531846491288=27290=49279=0269=022=8207=BVMF48=380566083=11395270=2.37273=64:79:11271=8000272=2014061037016=2014061037017=64:79:1137=80531938051288=27290=49
10:26:47.908: 657231 - 70 - 1128=935=X34=65723152=20140610-13:26:47.91475=20140610268=1279=2269=022=8207=BVMF48=380963983=255021273=64:79:13272=2014061037=80531938049288=3290=1
10:26:47.918: 657232 - 82 - 1128=935=X34=65723252=20140610-13:26:47.92475=20140610268=1279=0269=122=8207=BVMF48=380963983=255022270=26.41273=64:79:24271=900272=2014061037016=2014061037017=64:79:2337=80531938059289=40290=1
10:26:47.920: 657233 - 158 - 1128=935=X34=65723352=20140610-13:26:47.92675=20140610268=3279=0269=222=8207=BVMF48=380963983=255023270=26.41273=64:79:25271=600272=2014061037016=2014061037017=64:79:251500=E451=-0.21020=1342400274=3277=L1003=17970288=3289=40279=0269=922=8207=BVMF48=380963983=255024270=26.473273=64:79:25272=201406101500=E279=1269=122=8207=BVMF48=380963983=255025270=26.41273=64:79:25271=300272=2014061037016=2014061037017=64:79:2337=80531938059289=40290=1
10:26:47.924: 657234 - 72 - 1128=935=X34=65723452=20140610-13:26:47.92975=20140610268=1279=2269=022=8207=BVMF48=380968883=253141273=64:79:29272=2014061037=80531937992288=227290=14
10:26:47.930: 657235 - 70 - 1128=935=X34=65723552=20140610-13:26:47.93675=20140610268=1279=2269=022=8207=BVMF48=380963983=255026273=64:79:36272=2014061037=80531938025288=3290=7
10:26:47.934: 657236 - 194 - 1128=935=X34=65723652=20140610-13:26:47.94075=20140610268=4279=0269=222=8207=BVMF48=380963983=255027270=26.41273=64:79:39271=300272=2014061037016=2014061037017=64:79:391500=E451=-0.21020=1342700274=3277=L1003=17980288=3289=40279=0269=922=8207=BVMF48=380963983=255028270=26.473273=64:79:39272=201406101500=E279=2269=122=8207=BVMF48=380963983=255029273=64:79:39272=2014061037=80531938059289=40290=1279=0269=022=8207=BVMF48=380963983=255030270=26.41273=64:79:39271=300272=2014061037016=2014061037017=64:79:3937=80531938073288=3290=1
10:26:47.936: 657237 - 82 - 1128=935=X34=65723752=20140610-13:26:47.94275=20140610268=1279=0269=022=8207=BVMF48=380968883=253142270=29.36273=64:79:41271=500272=2014061037016=2014061037017=64:79:4137=80531938077288=227290=11
10:26:47.939: 657238 - 71 - 1128=935=X34=65723852=20140610-13:26:47.94475=20140610268=1279=2269=122=8207=BVMF48=380963983=255031273=64:79:44272=2014061037=80531937808289=8290=8
10:26:47.941: 657239 - 70 - 1128=935=X34=65723952=20140610-13:26:47.94675=20140610268=1279=2269=022=8207=BVMF48=380963983=255032273=64:79:46272=2014061037=80531938073288=3290=1
10:26:47.945: 657240 - 80 - 1128=935=X34=65724052=20140610-13:26:47.95075=20140610268=1279=0269=022=8207=BVMF48=380963983=255033270=26.41273=64:79:50271=300272=2014061037016=2014061037017=64:79:5037=80531938080288=3290=1
10:26:47.945: 657241 - 71 - 1128=935=X34=65724152=20140610-13:26:47.95075=20140610268=1279=2269=122=8207=BVMF48=380963983=255034273=64:79:50272=2014061037=80531937814289=8290=8
10:26:47.945: 657242 - 72 - 1128=935=X34=65724252=20140610-13:26:47.95175=20140610268=1279=2269=022=8207=BVMF48=380968883=253143273=64:79:50272=2014061037=80531938077288=227290=11
10:26:47.947: 657243 - 81 - 1128=935=X34=65724352=20140610-13:26:47.95275=20140610268=1279=0269=022=8207=BVMF48=380963983=255035270=26.4273=64:79:52271=600272=2014061037016=2014061037017=64:79:5237=80531938081288=3290=8
10:26:47.950: 657244 - 195 - 1128=935=X34=65724452=20140610-13:26:47.95675=20140610268=4279=0269=222=8207=BVMF48=380963983=255036270=26.41273=64:79:55271=300272=2014061037016=2014061037017=64:79:551500=E451=-0.21020=1343000274=3277=L1003=17990288=3289=40279=0269=922=8207=BVMF48=380963983=255037270=26.473273=64:79:55272=201406101500=E279=2269=022=8207=BVMF48=380963983=255038273=64:79:55272=2014061037=80531938080288=3290=1279=0269=122=8207=BVMF48=380963983=255039270=26.41273=64:79:55271=400272=2014061037016=2014061037017=64:79:5537=80531938085289=40290=1
10:26:47.953: 657245 - 82 - 1128=935=X34=65724552=20140610-13:26:47.95775=20140610268=1279=0269=022=8207=BVMF48=380968883=253144270=29.36273=64:79:57271=400272=2014061037016=2014061037017=64:79:5737=80531938088288=227290=11
10:26:47.953: 657246 - 71 - 1128=935=X34=65724652=20140610-13:26:47.95775=20140610268=1279=2269=022=8207=BVMF48=380963983=255040273=64:79:57272=2014061037=80531937989288=88290=5
10:26:47.954: 657247 - 195 - 1128=935=X34=65724752=20140610-13:26:47.96075=20140610268=4279=0269=222=8207=BVMF48=380963983=255041270=26.41273=64:79:59271=400272=2014061037016=2014061037017=64:79:591500=E451=-0.21020=1343400274=3277=L1003=18000288=3289=40279=0269=922=8207=BVMF48=380963983=255042270=26.473273=64:79:59272=201406101500=E279=2269=122=8207=BVMF48=380963983=255043273=64:79:59272=2014061037=80531938085289=40290=1279=0269=022=8207=BVMF48=380963983=255044270=26.41273=64:79:59271=200272=2014061037016=2014061037017=64:79:5937=80531938089288=3290=1
10:26:47.962: 657248 - 70 - 1128=935=X34=65724852=20140610-13:26:47.96875=20140610268=1279=2269=022=8207=BVMF48=380963983=255045273=64:79:67272=2014061037=80531938089288=3290=1
10:26:47.965: 657249 - 72 - 1128=935=X34=65724952=20140610-13:26:47.97075=20140610268=1279=2269=022=8207=BVMF48=380968883=253145273=64:79:70272=2014061037=80531938088288=227290=11
10:26:47.970: 657250 - 81 - 1128=935=X34=65725052=20140610-13:26:47.97575=20140610268=1279=1269=022=8207=BVMF48=380963983=255046270=26.4273=64:79:75271=100272=2014061037016=2014061037017=64:78:3137=80531938106288=45290=5
10:26:47.970: 657251 - 80 - 1128=935=X34=65725152=20140610-13:26:47.97675=20140610268=1279=0269=022=8207=BVMF48=380963983=255047270=26.41273=64:79:75271=600272=2014061037016=2014061037017=64:79:7537=80531938108288=3290=1
10:26:47.974: 657252 - 82 - 1128=935=X34=65725252=20140610-13:26:47.98075=20140610268=1279=0269=022=8207=BVMF48=380968883=253146270=29.36273=64:79:80271=200272=2014061037016=2014061037017=64:79:7937=80531938116288=227290=11
10:26:47.975: 657253 - 118 - 1128=935=X34=65725352=20140610-13:26:47.98175=20140610268=2279=2269=022=8207=BVMF48=380963983=255048273=64:79:80272=2014061037=80531938106288=45290=6279=0269=022=8207=BVMF48=380963983=255049270=26.38273=64:79:80271=300272=2014061037016=2014061037017=64:79:8037=80531938117288=45290=15
10:26:47.983: 657254 - 82 - 1128=935=X34=65725452=20140610-13:26:47.98875=20140610268=1279=0269=122=8207=BVMF48=380963983=255050270=26.42273=64:79:88271=600272=2014061037016=2014061037017=64:79:8837=80531938121289=40290=3
10:26:47.988: 657255 - 72 - 1128=935=X34=65725552=20140610-13:26:47.99475=20140610268=1279=2269=022=8207=BVMF48=380968883=253147273=64:79:94272=2014061037=80531938116288=227290=11
10:26:47.994: 657256 - 82 - 1128=935=X34=65725652=20140610-13:26:48.00075=20140610268=1279=0269=022=8207=BVMF48=380968883=253148270=29.36273=64:79:99271=100272=2014061037016=2014061037017=64:79:9937=80531938127288=227290=11
10:26:48.006: 657257 - 70 - 1128=935=X34=65725752=20140610-13:26:48.01275=20140610268=1279=2269=022=8207=BVMF48=380963983=255051273=64:80:11272=2014061037=80531938081288=3290=6
10:26:48.008: 657258 - 72 - 1128=935=X34=65725852=20140610-13:26:48.01375=20140610268=1279=2269=022=8207=BVMF48=380968883=253149273=64:80:13272=2014061037=80531938127288=227290=11
10:26:48.018: 657259 - 82 - 1128=935=X34=65725952=20140610-13:26:48.02475=20140610268=1279=0269=022=8207=BVMF48=380968883=253150270=29.36273=64:80:23271=500272=2014061037016=2014061037017=64:80:2337=80531938133288=227290=11
10:26:48.108: 657260 - 82 - 1128=935=X34=65726052=20140610-13:26:48.11375=20140610268=1279=0269=122=8207=BVMF48=380968883=253151270=29.4273=64:81:12271=300272=2014061037016=2014061037017=64:81:1237=80531938138289=8290=4
10:26:48.116: 657261 - 81 - 1128=935=X34=65726152=20140610-13:26:48.12275=20140610268=1279=0269=122=8207=BVMF48=380963983=255052270=26.43273=64:81:21271=100272=2014061037016=2014061037017=64:81:2137=80531938140289=8290=9
10:26:48.122: 657262 - 81 - 1128=935=X34=65726252=20140610-13:26:48.12875=20140610268=1279=0269=122=8207=BVMF48=380963983=255053270=26.43273=64:81:28271=1000272=2014061037016=2014061037017=64:81:2737=80531938141289=8290=10
10:26:48.153: 657263 - 82 - 1128=935=X34=65726352=20140610-13:26:48.15975=20140610268=1279=0269=022=8207=BVMF48=380963983=255054270=26.4273=64:81:59271=600272=2014061037016=2014061037017=64:81:5837=80531938144288=40290=6
10:26:48.172: 657264 - 119 - 1128=935=X34=65726452=20140610-13:26:48.17875=20140610268=2279=2269=022=8207=BVMF48=380963983=255055273=64:81:78272=2014061037=80531938117288=45290=15279=0269=022=8207=BVMF48=380963983=255056270=26.4273=64:81:78271=600272=2014061037016=2014061037017=64:81:7737=80531938151288=45290=7
10:26:48.244: 657265 - 72 - 1128=935=X34=65726552=20140610-13:26:48.25075=20140610268=1279=2269=122=8207=BVMF48=380963983=255057273=64:82:49272=2014061037=80531936735289=45290=13
10:26:48.287: 657266 - 70 - 1128=935=X34=65726652=20140610-13:26:48.29375=20140610268=1279=2269=022=8207=BVMF48=380963983=255058273=64:82:92272=2014061037=80531937605288=3290=4
10:26:48.333: 657267 - 81 - 1128=935=X34=65726752=20140610-13:26:48.33975=20140610268=1279=0269=022=8207=BVMF48=380963983=255059270=26.32273=64:83:39271=3000272=2014061037016=2014061037017=64:83:3837=80531938254288=45290=56
10:26:48.333: 657268 - 82 - 1128=935=X34=65726852=20140610-13:26:48.33975=20140610268=1279=0269=122=8207=BVMF48=380963983=255060270=26.44273=64:83:39271=3000272=2014061037016=2014061037017=64:83:3937=80531938255289=45290=16
10:26:48.343: 657269 - 117 - 1128=935=X34=65726952=20140610-13:26:48.34975=20140610268=2279=2269=022=8207=BVMF48=380963983=255061273=64:83:48272=2014061037=80531938108288=3290=1279=0269=022=8207=BVMF48=380963983=255062270=26.4273=64:83:48271=600272=2014061037016=2014061037017=64:83:4837=80531938260288=3290=6
10:26:48.349: 657270 - 70 - 1128=935=X34=65727052=20140610-13:26:48.35575=20140610268=1279=2269=022=8207=BVMF48=380963983=255063273=64:83:54272=2014061037=80531937682288=8290=14
10:26:48.363: 657271 - 72 - 1128=935=X34=65727152=20140610-13:26:48.36875=20140610268=1279=2269=022=8207=BVMF48=380968883=253152273=64:83:68272=2014061037=80531938133288=227290=11
10:26:48.363: 657272 - 72 - 1128=935=X34=65727252=20140610-13:26:48.36975=20140610268=1279=2269=122=8207=BVMF48=380963983=255064273=64:83:69272=2014061037=80531938121289=40290=3
10:26:48.369: 657273 - 82 - 1128=935=X34=65727352=20140610-13:26:48.37475=20140610268=1279=0269=122=8207=BVMF48=380963983=255065270=26.41273=64:83:74271=900272=2014061037016=2014061037017=64:83:7437=80531938272289=40290=1
10:26:48.373: 657274 - 82 - 1128=935=X34=65727452=20140610-13:26:48.37975=20140610268=1279=0269=022=8207=BVMF48=380968883=253153270=29.35273=64:83:79271=800272=2014061037016=2014061037017=64:83:7937=80531938274288=227290=14
10:26:48.377: 657275 - 71 - 1128=935=X34=65727552=20140610-13:26:48.38375=20140610268=1279=2269=122=8207=BVMF48=380963983=255066273=64:83:82272=2014061037=80531937746289=8290=45
10:26:48.377: 657276 - 81 - 1128=935=X34=65727652=20140610-13:26:48.38375=20140610268=1279=0269=122=8207=BVMF48=380963983=255067270=26.43273=64:83:82271=300272=2014061037016=2014061037017=64:83:8237=80531938276289=8290=11
10:26:48.472: 657277 - 82 - 1128=935=X34=65727752=20140610-13:26:48.47875=20140610268=1279=0269=122=8207=BVMF48=380963983=255068270=26.44273=64:84:77271=5000272=2014061037016=2014061037017=64:84:7737=80531938289289=45290=18
10:26:48.521: 657278 - 80 - 1128=935=X34=65727852=20140610-13:26:48.52675=20140610268=1279=0269=022=8207=BVMF48=380963983=255069270=26.37273=64:85:26271=300272=2014061037016=2014061037017=64:85:2637=80531938291288=8290=20
10:26:48.534: 657279 - 81 - 1128=935=X34=65727952=20140610-13:26:48.53975=20140610268=1279=0269=022=8207=BVMF48=380963983=255070270=26.31273=64:85:39271=3000272=2014061037016=2014061037017=64:85:3937=80531938292288=45290=62
10:26:48.748: 657280 - 71 - 1128=935=X34=65728052=20140610-13:26:48.75475=20140610268=1279=2269=022=8207=BVMF48=380963983=255071273=64:87:53272=2014061037=80531938144288=40290=4
10:26:48.766: 657281 - 118 - 1128=935=X34=65728152=20140610-13:26:48.77275=20140610268=2279=2269=022=8207=BVMF48=380963983=255072273=64:87:71272=2014061037=80531938151288=45290=4279=0269=022=8207=BVMF48=380963983=255073270=26.37273=64:87:71271=600272=2014061037016=2014061037017=64:87:7137=80531938294288=45290=19
10:26:48.900: 657282 - 81 - 1128=935=X34=65728252=20140610-13:26:48.90575=20140610268=1279=1269=122=8207=BVMF48=380963983=255074270=26.41273=64:89:05271=400272=2014061037016=2014061037017=64:83:7437=80531938295289=40290=1
10:26:48.931: 657283 - 82 - 1128=935=X34=65728352=20140610-13:26:48.93775=20140610268=1279=0269=122=8207=BVMF48=380963983=255075270=26.41273=64:89:36271=600272=2014061037016=2014061037017=64:89:3637=80531938297289=40290=2
10:26:49.005: 657284 - 71 - 1128=935=X34=65728452=20140610-13:26:49.01175=20140610268=1279=2269=122=8207=BVMF48=380963983=255076273=64:90:10272=2014061037=80531938140289=8290=10
10:26:49.012: 657285 - 71 - 1128=935=X34=65728552=20140610-13:26:49.01875=20140610268=1279=2269=122=8207=BVMF48=380963983=255077273=64:90:17272=2014061037=80531938141289=8290=10
10:26:49.073: 657286 - 81 - 1128=935=X34=65728652=20140610-13:26:49.07975=20140610268=1279=0269=122=8207=BVMF48=380963983=255078270=26.43273=64:90:78271=100272=2014061037016=2014061037017=64:90:7837=80531938299289=8290=11
10:26:49.232: 657287 - 71 - 1128=935=X34=65728752=20140610-13:26:49.23875=20140610268=1279=2269=122=8207=BVMF48=380963983=255079273=64:92:38272=2014061037=80531938299289=8290=11
10:26:49.240: 657288 - 72 - 1128=935=X34=65728852=20140610-13:26:49.24675=20140610268=1279=2269=122=8207=BVMF48=380963983=255080273=64:92:45272=2014061037=80531938289289=45290=17
10:26:49.440: 657289 - 82 - 1128=935=X34=65728952=20140610-13:26:49.44675=20140610268=1279=0269=122=8207=BVMF48=380963983=255081270=26.44273=64:94:45271=5000272=2014061037016=2014061037017=64:94:4537=80531938306289=45290=17
10:26:49.754: 657290 - 197 - 1128=935=X34=65729052=20140610-13:26:49.76075=20140610268=4279=0269=222=8207=BVMF48=380394783=65661270=17.04273=64:97:59271=100272=2014061037016=2014061037017=64:97:591500=E451=-0.121020=18600274=01003=1100288=735289=8279=0269=922=8207=BVMF48=380394783=65662270=17.101273=64:97:59272=201406101500=E279=1269=122=8207=BVMF48=380394783=65663270=17.04273=64:97:59271=300272=2014061037016=2014061037017=53:81:3137=80531931296289=8290=1279=2269=022=8207=BVMF48=380394783=65664273=64:97:59272=2014061037=80531931383288=735290=3
10:26:50.433: 657291 - 82 - 1128=935=X34=65729152=20140610-13:26:50.44075=20140610268=1279=0269=122=8207=BVMF48=380963983=255082270=26.41273=65:04:39271=100272=2014061037016=2014061037017=65:04:3937=80531938315289=40290=3
10:26:50.449: 657292 - 307 - 1128=935=X34=65729252=20140610-13:26:50.45575=20140610268=7279=0269=222=8207=BVMF48=380963983=255083270=26.41273=65:04:54271=400272=2014061037016=2014061037017=65:04:541500=E451=-0.21020=1343800274=3277=L1003=18010288=3289=40279=0269=922=8207=BVMF48=380963983=255084270=26.473273=65:04:54272=201406101500=E279=0269=222=8207=BVMF48=380963983=255085270=26.41273=65:04:54271=100272=2014061037016=2014061037017=65:04:541500=E451=-0.21020=1343900274=3277=L1003=18020288=3289=40279=0269=922=8207=BVMF48=380963983=255086270=26.473273=65:04:54272=201406101500=E279=2269=122=8207=BVMF48=380963983=255087273=65:04:54272=2014061037=80531938295289=40290=1279=1269=122=8207=BVMF48=380963983=255088270=26.41273=65:04:54271=500272=2014061037016=2014061037017=64:89:3637=80531938297289=40290=1279=2269=022=8207=BVMF48=380963983=255089273=65:04:54272=2014061037=80531938260288=3290=4
10:26:50.501: 657293 - 81 - 1128=935=X34=65729352=20140610-13:26:50.50775=20140610268=1279=0269=022=8207=BVMF48=380963983=255090270=26.4273=65:05:07271=600272=2014061037016=2014061037017=65:05:0637=80531938351288=3290=4
10:26:51.150: 657294 - 70 - 1128=935=X34=65729452=20140610-13:26:51.15675=20140610268=1279=2269=022=8207=BVMF48=380968883=253154273=65:11:55272=2014061037=80531931758288=8290=21
10:26:51.151: 657295 - 80 - 1128=935=X34=65729552=20140610-13:26:51.15775=20140610268=1279=0269=022=8207=BVMF48=380968883=253155270=29.33273=65:11:57271=100272=2014061037016=2014061037017=65:11:5737=80531938360288=8290=22
10:26:51.211: 657296 - 70 - 1128=935=X34=65729652=20140610-13:26:51.21775=20140610268=1279=2269=022=8207=BVMF48=380968883=253156273=65:12:17272=2014061037=80531934030288=8290=1
10:26:51.212: 657297 - 71 - 1128=935=X34=65729752=20140610-13:26:51.21775=20140610268=1279=2269=122=8207=BVMF48=380968883=253157273=65:12:17272=2014061037=80531935906289=8290=33
10:26:51.213: 657298 - 81 - 1128=935=X34=65729852=20140610-13:26:51.21975=20140610268=1279=0269=122=8207=BVMF48=380968883=253158270=29.39273=65:12:18271=300272=2014061037016=2014061037017=65:12:1837=80531938361289=8290=2
10:26:51.218: 657299 - 81 - 1128=935=X34=65729952=20140610-13:26:51.22475=20140610268=1279=0269=122=8207=BVMF48=380968883=253159270=29.43273=65:12:23271=100272=2014061037016=2014061037017=65:12:2337=80531938362289=3290=10
10:26:51.220: 657300 - 119 - 1128=935=X34=65730052=20140610-13:26:51.22675=20140610268=2279=2269=122=8207=BVMF48=380968883=253160273=65:12:25272=2014061037=80531935986289=45290=4279=0269=122=8207=BVMF48=380968883=253161270=29.39273=65:12:25271=300272=2014061037016=2014061037017=65:12:2537=80531938363289=45290=3
10:26:51.799: 657301 - 82 - 1128=935=X34=65730152=20140610-13:26:51.80575=20140610268=1279=0269=022=8207=BVMF48=380394783=65665270=17.03273=65:18:04271=100272=2014061037016=2014061037017=65:18:0437=80531938366288=735290=2
10:26:51.813: 657302 - 70 - 1128=935=X34=65730252=20140610-13:26:51.81975=20140610268=1279=2269=022=8207=BVMF48=380391383=106045273=65:18:19272=2014061037=80531937573288=8290=34
10:26:51.823: 657303 - 80 - 1128=935=X34=65730352=20140610-13:26:51.82975=20140610268=1279=0269=022=8207=BVMF48=380391383=106046270=13.78273=65:18:28271=600272=2014061037016=2014061037017=65:18:2837=80531938367288=8290=34
10:26:51.838: 657304 - 80 - 1128=935=X34=65730452=20140610-13:26:51.84475=20140610268=1279=0269=022=8207=BVMF48=380391383=106047270=13.84273=65:18:44271=100272=2014061037016=2014061037017=65:18:4437=80531938368288=8290=2
10:26:51.839: 657305 - 81 - 1128=935=X34=65730552=20140610-13:26:51.84575=20140610268=1279=0269=022=8207=BVMF48=380391383=106048270=13.84273=65:18:44271=300272=2014061037016=2014061037017=65:18:4437=80531938369288=40290=3
10:26:51.847: 657306 - 82 - 1128=935=X34=65730652=20140610-13:26:51.85175=20140610268=1279=0269=022=8207=BVMF48=380963983=255091270=26.4273=65:18:50271=500272=2014061037016=2014061037017=65:18:5037=80531938372288=40290=5
10:26:51.849: 657307 - 81 - 1128=935=X34=65730752=20140610-13:26:51.85575=20140610268=1279=0269=022=8207=BVMF48=380968883=253162270=29.38273=65:18:55271=400272=2014061037016=2014061037017=65:18:5537=80531938373288=40290=6
10:26:51.853: 657308 - 81 - 1128=935=X34=65730852=20140610-13:26:51.85975=20140610268=1279=0269=022=8207=BVMF48=380394783=65666270=17.03273=65:18:58271=100272=2014061037016=2014061037017=65:18:5837=80531938374288=40290=3
10:26:51.858: 657309 - 81 - 1128=935=X34=65730952=20140610-13:26:51.86475=20140610268=1279=0269=022=8207=BVMF48=380965483=79267270=8.21273=65:18:63271=100272=2014061037016=2014061037017=65:18:6337=80531938375288=40290=5
10:26:51.859: 657310 - 81 - 1128=935=X34=65731052=20140610-13:26:51.86575=20140610268=1279=0269=022=8207=BVMF48=380249383=103330270=9.33273=65:18:64271=200272=2014061037016=2014061037017=65:18:6437=80531938376288=40290=2
10:26:51.875: 657311 - 119 - 1128=935=X34=65731152=20140610-13:26:51.88175=20140610268=2279=2269=022=8207=BVMF48=380963983=255092273=65:18:80272=2014061037=80531938294288=45290=20279=0269=022=8207=BVMF48=380963983=255093270=26.4273=65:18:80271=500272=2014061037016=2014061037017=65:18:8037=80531938379288=45290=6
10:26:51.881: 657312 - 81 - 1128=935=X34=65731252=20140610-13:26:51.88775=20140610268=1279=0269=022=8207=BVMF48=380963983=255094270=26.4273=65:18:87271=100272=2014061037016=2014061037017=65:18:8737=80531938380288=8290=7
10:26:51.893: 657313 - 70 - 1128=935=X34=65731352=20140610-13:26:51.89975=20140610268=1279=2269=022=8207=BVMF48=380391383=106049273=65:18:98272=2014061037=80531938367288=8290=36
10:26:51.941: 657314 - 80 - 1128=935=X34=65731452=20140610-13:26:51.94675=20140610268=1279=0269=022=8207=BVMF48=380391383=106050270=13.78273=65:19:46271=700272=2014061037016=2014061037017=65:19:4537=80531938381288=8290=36
10:26:52.086: 657315 - 71 - 1128=935=X34=65731552=20140610-13:26:52.09275=20140610268=1279=2269=022=8207=BVMF48=380391383=106051273=65:20:91272=2014061037=80531938369288=40290=3
10:26:52.088: 657316 - 71 - 1128=935=X34=65731652=20140610-13:26:52.09475=20140610268=1279=2269=022=8207=BVMF48=380963983=255095273=65:20:94272=2014061037=80531938372288=40290=5
10:26:52.090: 657317 - 71 - 1128=935=X34=65731752=20140610-13:26:52.09575=20140610268=1279=2269=022=8207=BVMF48=380968883=253163273=65:20:95272=2014061037=80531938373288=40290=6
10:26:52.090: 657318 - 71 - 1128=935=X34=65731852=20140610-13:26:52.09675=20140610268=1279=2269=022=8207=BVMF48=380394783=65667273=65:20:96272=2014061037=80531938374288=40290=3
10:26:52.094: 657319 - 81 - 1128=935=X34=65731952=20140610-13:26:52.10075=20140610268=1279=1269=022=8207=BVMF48=380963983=255096270=26.4273=65:21:00271=100272=2014061037016=2014061037017=65:18:8037=80531938382288=45290=5
10:26:52.097: 657320 - 71 - 1128=935=X34=65732052=20140610-13:26:52.10375=20140610268=1279=2269=022=8207=BVMF48=380249383=103331273=65:21:02272=2014061037=80531938376288=40290=2
10:26:52.097: 657321 - 71 - 1128=935=X34=65732152=20140610-13:26:52.10375=20140610268=1279=2269=022=8207=BVMF48=380965483=79268273=65:21:02272=2014061037=80531938375288=40290=5
10:26:52.130: 657322 - 160 - 1128=935=X34=65732252=20140610-13:26:52.13675=20140610268=3279=0269=222=8207=BVMF48=380963983=255097270=26.4273=65:21:36271=100272=2014061037016=2014061037017=65:21:351500=E451=-0.211020=1344000274=21003=18030288=45289=3279=0269=922=8207=BVMF48=380963983=255098270=26.473273=65:21:36272=201406101500=E279=1269=022=8207=BVMF48=380963983=255099270=26.4273=65:21:36271=3600272=2014061037016=2014061037017=64:26:5137=80531937460288=45290=1
10:26:52.141: 657323 - 70 - 1128=935=X34=65732352=20140610-13:26:52.14775=20140610268=1279=2269=022=8207=BVMF48=380391383=106052273=65:21:46272=2014061037=80531938381288=8290=35
10:26:52.158: 657324 - 80 - 1128=935=X34=65732452=20140610-13:26:52.16475=20140610268=1279=0269=022=8207=BVMF48=380391383=106053270=13.78273=65:21:63271=600272=2014061037016=2014061037017=65:21:6337=80531938384288=8290=35
10:26:52.616: 657325 - 70 - 1128=935=X34=65732552=20140610-13:26:52.62275=20140610268=1279=2269=022=8207=BVMF48=380963983=255100273=65:26:21272=2014061037=80531930358288=3290=28
10:26:52.616: 657326 - 80 - 1128=935=X34=65732652=20140610-13:26:52.62275=20140610268=1279=0269=022=8207=BVMF48=380963983=255101270=26.32273=65:26:21271=3000272=2014061037016=2014061037017=65:26:2137=80531938389288=3290=56
10:26:52.621: 657327 - 70 - 1128=935=X34=65732752=20140610-13:26:52.62775=20140610268=1279=2269=022=8207=BVMF48=380963983=255102273=65:26:26272=2014061037=80531936867288=3290=9
10:26:52.661: 657328 - 145 - 1128=935=X34=65732852=20140610-13:26:52.66775=20140610268=3279=0269=222=8207=BVMF48=380249383=103332270=9.33273=65:26:66271=200272=2014061037016=2014061037017=65:26:651500=E451=-0.121020=256200274=01003=3530288=40289=8279=0269=922=8207=BVMF48=380249383=103333270=9.382273=65:26:66272=201406101500=E279=2269=022=8207=BVMF48=380249383=103334273=65:26:66272=2014061037=80531937551288=40290=1
10:26:52.662: 657329 - 81 - 1128=935=X34=65732952=20140610-13:26:52.66875=20140610268=1279=0269=122=8207=BVMF48=380249383=103335270=9.34273=65:26:68271=100272=2014061037016=2014061037017=65:26:6737=80531938391289=8290=7
10:26:52.682: 657330 - 199 - 1128=935=X34=65733052=20140610-13:26:52.68875=20140610268=4279=0269=222=8207=BVMF48=380249383=103336270=9.32273=65:26:87271=100272=2014061037016=2014061037017=65:26:871500=E451=-0.131020=256300274=21003=3540288=21289=735279=0269=922=8207=BVMF48=380249383=103337270=9.382273=65:26:87272=201406101500=E279=1269=022=8207=BVMF48=380249383=103338270=9.32273=65:26:87271=500272=2014061037016=2014061037017=54:88:9437=80531931617288=21290=1279=2269=122=8207=BVMF48=380249383=103339273=65:26:87272=2014061037=80531936605289=735290=6
10:26:52.685: 657331 - 80 - 1128=935=X34=65733152=20140610-13:26:52.69175=20140610268=1279=0269=022=8207=BVMF48=380249383=103340270=9.22273=65:26:90271=1600272=2014061037016=2014061037017=65:26:9037=80531938398288=3290=43
10:26:52.697: 657332 - 83 - 1128=935=X34=65733252=20140610-13:26:52.70275=20140610268=1279=0269=122=8207=BVMF48=380249383=103341270=9.34273=65:27:02271=300272=2014061037016=2014061037017=65:27:0237=80531938401289=735290=7
10:26:52.826: 657333 - 83 - 1128=935=X34=65733352=20140610-13:26:52.83275=20140610268=1279=0269=022=8207=BVMF48=380963983=255103270=25.8273=65:28:31271=2000272=2014061037016=2014061037017=65:28:3137=80531938404288=39290=172
10:26:52.829: 657334 - 82 - 1128=935=X34=65733452=20140610-13:26:52.83575=20140610268=1279=0269=022=8207=BVMF48=380963983=255104270=26.4273=65:28:35271=800272=2014061037016=2014061037017=65:28:3537=80531938407288=88290=7
10:26:52.836: 657335 - 81 - 1128=935=X34=65733552=20140610-13:26:52.84275=20140610268=1279=0269=022=8207=BVMF48=380963983=255105270=26.4273=65:28:41271=600272=2014061037016=2014061037017=65:28:4137=80531938408288=3290=8
10:26:52.854: 657336 - 82 - 1128=935=X34=65733652=20140610-13:26:52.86075=20140610268=1279=0269=022=8207=BVMF48=380963983=255106270=26.4273=65:28:59271=100272=2014061037016=2014061037017=65:28:5937=80531938415288=70290=9
10:26:52.859: 657337 - 70 - 1128=935=X34=65733752=20140610-13:26:52.86675=20140610268=1279=2269=022=8207=BVMF48=380963983=255107273=65:28:65272=2014061037=80531938408288=3290=8
10:26:52.892: 657338 - 118 - 1128=935=X34=65733852=20140610-13:26:52.89875=20140610268=2279=2269=022=8207=BVMF48=380963983=255108273=65:28:98272=2014061037=80531938407288=88290=7279=0269=022=8207=BVMF48=380963983=255109270=26.38273=65:28:98271=800272=2014061037016=2014061037017=65:28:9737=80531938419288=88290=14
10:26:52.902: 657339 - 71 - 1128=935=X34=65733952=20140610-13:26:52.90775=20140610268=1279=2269=022=8207=BVMF48=380963983=255110273=65:29:07272=2014061037=80531938419288=88290=14
10:26:53.189: 657340 - 82 - 1128=935=X34=65734052=20140610-13:26:53.19575=20140610268=1279=0269=122=8207=BVMF48=380249383=103342270=9.33273=65:31:95271=800272=2014061037016=2014061037017=65:31:9537=80531938421289=40290=1
10:26:53.198: 657341 - 121 - 1128=935=X34=65734152=20140610-13:26:53.20475=20140610268=2279=2269=122=8207=BVMF48=380249383=103343273=65:32:04272=2014061037=80531938401289=735290=8279=0269=122=8207=BVMF48=380249383=103344270=9.33273=65:32:04271=300272=2014061037016=2014061037017=65:32:0337=80531938436289=735290=2
10:26:53.221: 657342 - 71 - 1128=935=X34=65734252=20140610-13:26:53.22775=20140610268=1279=2269=022=8207=BVMF48=380249383=103345273=65:32:27272=2014061037=80531934874288=40290=6
10:26:53.255: 657343 - 71 - 1128=935=X34=65734352=20140610-13:26:53.26175=20140610268=1279=2269=122=8207=BVMF48=380249383=103346273=65:32:60272=2014061037=80531938391289=8290=8
10:26:53.452: 657344 - 81 - 1128=935=X34=65734452=20140610-13:26:53.45875=20140610268=1279=0269=022=8207=BVMF48=380391383=106054270=13.83273=65:34:58271=100272=2014061037016=2014061037017=65:34:5737=80531938442288=40290=8
10:26:53.597: 657345 - 70 - 1128=935=X34=65734552=20140610-13:26:53.60475=20140610268=1279=2269=022=8207=BVMF48=380249383=103347273=65:36:03272=2014061037=80531936583288=8290=6
10:26:53.692: 657346 - 269 - 1128=935=X34=65734652=20140610-13:26:53.69875=20140610268=6279=0269=222=8207=BVMF48=380249383=103348270=9.33273=65:36:98271=800272=2014061037016=2014061037017=65:36:971500=E451=-0.121020=257100274=01003=3550288=45289=40279=0269=922=8207=BVMF48=380249383=103349270=9.382273=65:36:98272=201406101500=E279=0269=222=8207=BVMF48=380249383=103350270=9.33273=65:36:98271=200272=2014061037016=2014061037017=65:36:971500=E451=-0.121020=257300274=1277=L1003=3560288=45289=735279=0269=922=8207=BVMF48=380249383=103351270=9.382273=65:36:98272=201406101500=E279=2269=122=8207=BVMF48=380249383=103352273=65:36:98272=2014061037=80531938421289=40290=1279=1269=122=8207=BVMF48=380249383=103353270=9.33273=65:36:98271=100272=2014061037016=2014061037017=65:32:0337=80531938436289=735290=1
10:26:53.708: 657347 - 199 - 1128=935=X34=65734752=20140610-13:26:53.71475=20140610268=4279=0269=222=8207=BVMF48=380249383=103354270=9.32273=65:37:13271=100272=2014061037016=2014061037017=65:37:131500=E451=-0.131020=257400274=21003=3570288=21289=735279=0269=922=8207=BVMF48=380249383=103355270=9.382273=65:37:13272=201406101500=E279=1269=022=8207=BVMF48=380249383=103356270=9.32273=65:37:13271=400272=2014061037016=2014061037017=54:88:9437=80531931617288=21290=1279=2269=122=8207=BVMF48=380249383=103357273=65:37:13272=2014061037=80531938436289=735290=1
10:26:53.715: 657348 - 83 - 1128=935=X34=65734852=20140610-13:26:53.72175=20140610268=1279=0269=122=8207=BVMF48=380249383=103358270=9.34273=65:37:20271=200272=2014061037016=2014061037017=65:37:2037=80531938455289=735290=6
10:26:53.717: 657349 - 81 - 1128=935=X34=65734952=20140610-13:26:53.72275=20140610268=1279=0269=122=8207=BVMF48=380249383=103359270=9.34273=65:37:22271=100272=2014061037016=2014061037017=65:37:2237=80531938456289=8290=7
10:26:53.717: 657350 - 81 - 1128=935=X34=65735052=20140610-13:26:53.72375=20140610268=1279=0269=022=8207=BVMF48=380249383=103360270=9.32273=65:37:23271=500272=2014061037016=2014061037017=65:37:2337=80531938457288=40290=6
10:26:53.865: 657351 - 197 - 1128=935=X34=65735152=20140610-13:26:53.87175=20140610268=4279=0269=222=8207=BVMF48=380963983=255111270=26.41273=65:38:70271=100272=2014061037016=2014061037017=65:38:701500=E451=-0.21020=1344100274=01003=18040288=8289=40279=0269=922=8207=BVMF48=380963983=255112270=26.473273=65:38:70272=201406101500=E279=1269=122=8207=BVMF48=380963983=255113270=26.41273=65:38:70271=400272=2014061037016=2014061037017=64:89:3637=80531938297289=40290=1279=2269=022=8207=BVMF48=380963983=255114273=65:38:70272=2014061037=80531938380288=8290=6
10:26:53.898: 657352 - 82 - 1128=935=X34=65735252=20140610-13:26:53.90475=20140610268=1279=0269=122=8207=BVMF48=380963983=255115270=26.41273=65:39:03271=600272=2014061037016=2014061037017=65:39:0337=80531938459289=40290=3
10:26:54.128: 657353 - 193 - 1128=935=X34=65735352=20140610-13:26:54.13475=20140610268=4279=0269=222=8207=BVMF48=380391383=106055270=13.85273=65:41:33271=100272=2014061037016=2014061037017=65:41:331500=E451=-0.041020=106900274=01003=3240288=8289=8279=0269=922=8207=BVMF48=380391383=106056270=13.878273=65:41:33272=201406101500=E279=1269=122=8207=BVMF48=380391383=106057270=13.85273=65:41:33271=900272=2014061037016=2014061037017=50:95:0937=80531929098289=8290=1279=2269=022=8207=BVMF48=380391383=106058273=65:41:33272=2014061037=80531938368288=8290=2
10:26:54.634: 657354 - 71 - 1128=935=X34=65735452=20140610-13:26:54.64075=20140610268=1279=2269=122=8207=BVMF48=380249383=103361273=65:46:39272=2014061037=80531931882289=8290=4
10:26:55.583: 657355 - 82 - 1128=935=X34=65735552=20140610-13:26:55.58975=20140610268=1279=0269=022=8207=BVMF48=380965483=79269270=8.11273=65:55:88271=2000272=2014061037016=2014061037017=65:55:8837=80531938485288=564290=74
10:26:56.113: 657356 - 70 - 1128=935=X34=65735652=20140610-13:26:56.11975=20140610268=1279=2269=022=8207=BVMF48=380653683=6206273=65:61:18272=2014061037=80531919404288=86290=11
10:26:56.150: 657357 - 80 - 1128=935=X34=65735752=20140610-13:26:56.15675=20140610268=1279=0269=122=8207=BVMF48=380653683=6207270=3.15273=65:61:55271=100272=2014061037016=2014061037017=65:61:5537=80531938488289=8290=10
10:26:56.192: 657358 - 160 - 1128=935=X34=65735852=20140610-13:26:56.19875=20140610268=3279=0269=222=8207=BVMF48=380963983=255116270=26.4273=65:61:97271=100272=2014061037016=2014061037017=65:61:971500=E451=-0.211020=1344200274=21003=18050288=45289=3279=0269=922=8207=BVMF48=380963983=255117270=26.473273=65:61:97272=201406101500=E279=1269=022=8207=BVMF48=380963983=255118270=26.4273=65:61:97271=3500272=2014061037016=2014061037017=64:26:5137=80531937460288=45290=1
10:26:56.196: 657359 - 70 - 1128=935=X34=65735952=20140610-13:26:56.20275=20140610268=1279=2269=022=8207=BVMF48=380963983=255119273=65:62:02272=2014061037=80531933757288=3290=12
10:26:56.529: 657360 - 82 - 1128=935=X34=65736052=20140610-13:26:56.53575=20140610268=1279=0269=022=8207=BVMF48=380249383=103362270=9.3273=65:65:35271=100272=2014061037016=2014061037017=65:65:3537=80531938493288=40290=16
10:26:57.194: 657361 - 147 - 1128=935=X34=65736152=20140610-13:26:57.20075=20140610268=3279=0269=222=8207=BVMF48=380391383=106059270=13.84273=65:72:00271=300272=2014061037016=2014061037017=65:71:991500=E451=-0.051020=107200274=21003=3250288=40289=227279=0269=922=8207=BVMF48=380391383=106060270=13.878273=65:72:00272=201406101500=E279=2269=022=8207=BVMF48=380391383=106061273=65:72:00272=2014061037=80531937538288=40290=1
10:26:57.249: 657362 - 81 - 1128=935=X34=65736252=20140610-13:26:57.25575=20140610268=1279=0269=122=8207=BVMF48=380391383=106062270=13.84273=65:72:54271=100272=2014061037016=2014061037017=65:72:5437=80531938507289=8290=1
10:26:57.249: 657363 - 71 - 1128=935=X34=65736352=20140610-13:26:57.25575=20140610268=1279=2269=122=8207=BVMF48=380391383=106063273=65:72:54272=2014061037=80531938507289=8290=1
10:26:57.290: 657364 - 70 - 1128=935=X34=65736452=20140610-13:26:57.29675=20140610268=1279=2269=022=8207=BVMF48=380394783=65668273=65:72:95272=2014061037=80531937569288=8290=1
10:26:57.291: 657365 - 147 - 1128=935=X34=65736552=20140610-13:26:57.29775=20140610268=3279=0269=222=8207=BVMF48=380394783=65669270=17.03273=65:72:97271=100272=2014061037016=2014061037017=65:72:961500=E451=-0.131020=18700274=21003=1110288=735289=8279=0269=922=8207=BVMF48=380394783=65670270=17.101273=65:72:97272=201406101500=E279=2269=022=8207=BVMF48=380394783=65671273=65:72:97272=2014061037=80531938366288=735290=1
10:26:57.293: 657366 - 81 - 1128=935=X34=65736652=20140610-13:26:57.29975=20140610268=1279=0269=122=8207=BVMF48=380394783=65672270=17.03273=65:72:98271=100272=2014061037016=2014061037017=65:72:9837=80531938509289=8290=1
10:26:57.304: 657367 - 70 - 1128=935=X34=65736752=20140610-13:26:57.31075=20140610268=1279=2269=022=8207=BVMF48=380391383=106064273=65:73:09272=2014061037=80531938384288=8290=34
10:26:57.304: 657368 - 80 - 1128=935=X34=65736852=20140610-13:26:57.31075=20140610268=1279=0269=022=8207=BVMF48=380394783=65673270=17.02273=65:73:10271=400272=2014061037016=2014061037017=65:73:0937=80531938510288=8290=3
10:26:57.312: 657369 - 82 - 1128=935=X34=65736952=20140610-13:26:57.31975=20140610268=1279=0269=022=8207=BVMF48=380394783=65674270=16.98273=65:73:18271=400272=2014061037016=2014061037017=65:73:1837=80531938511288=110290=10
10:26:57.314: 657370 - 83 - 1128=935=X34=65737052=20140610-13:26:57.32075=20140610268=1279=0269=122=8207=BVMF48=380391383=106065270=13.87273=65:73:20271=100272=2014061037016=2014061037017=65:73:1937=80531938512289=110290=14
10:26:57.315: 657371 - 80 - 1128=935=X34=65737152=20140610-13:26:57.32275=20140610268=1279=0269=022=8207=BVMF48=380391383=106066270=13.78273=65:73:21271=100272=2014061037016=2014061037017=65:73:2137=80531938513288=8290=34
10:26:57.367: 657372 - 70 - 1128=935=X34=65737252=20140610-13:26:57.37375=20140610268=1279=2269=022=8207=BVMF48=380391383=106067273=65:73:73272=2014061037=80531938513288=8290=34
10:26:57.380: 657373 - 80 - 1128=935=X34=65737352=20140610-13:26:57.38675=20140610268=1279=0269=022=8207=BVMF48=380391383=106068270=13.78273=65:73:85271=1000272=2014061037016=2014061037017=65:73:8537=80531938514288=8290=34
10:26:57.453: 657374 - 115 - 1128=935=X34=65737452=20140610-13:26:57.45975=20140610268=2279=2269=022=8207=BVMF48=390102283=4001273=65:74:58272=2014061037=80531935369288=3290=1279=0269=022=8207=BVMF48=390102283=4002270=17.01273=65:74:58271=96272=2014061037016=2014061037017=65:74:5837=80531938515288=3290=2
10:26:57.597: 657375 - 70 - 1128=935=X34=65737552=20140610-13:26:57.60475=20140610268=1279=2269=022=8207=BVMF48=380391383=106069273=65:76:03272=2014061037=80531934897288=8290=5
10:26:57.753: 657376 - 81 - 1128=935=X34=65737652=20140610-13:26:57.76075=20140610268=1279=0269=022=8207=BVMF48=380965483=79270270=8.15273=65:77:59271=400272=2014061037016=2014061037017=65:77:5937=80531938520288=72290=56
10:26:57.998: 657377 - 82 - 1128=935=X34=65737752=20140610-13:26:58.00575=20140610268=1279=0269=022=8207=BVMF48=380249383=103363270=9.28273=65:80:04271=18800272=2014061037016=2014061037017=65:80:0437=80531938521288=16290=24
10:26:58.000: 657378 - 80 - 1128=935=X34=65737852=20140610-13:26:58.00675=20140610268=1279=0269=122=8207=BVMF48=380388983=12943270=11.38273=65:80:06271=200272=2014061037016=2014061037017=65:80:0537=80531938522289=8290=1
10:26:58.142: 657379 - 71 - 1128=935=X34=65737952=20140610-13:26:58.14875=20140610268=1279=2269=122=8207=BVMF48=380394783=65675273=65:81:47272=2014061037=80531938509289=8290=1
10:26:58.146: 657380 - 121 - 1128=935=X34=65738052=20140610-13:26:58.15275=20140610268=2279=2269=122=8207=BVMF48=380391383=106070273=65:81:52272=2014061037=80531938512289=110290=14279=0269=122=8207=BVMF48=380391383=106071270=13.88273=65:81:52271=300272=2014061037016=2014061037017=65:81:5237=80531938523289=110290=19
10:26:58.150: 657381 - 70 - 1128=935=X34=65738152=20140610-13:26:58.15675=20140610268=1279=2269=022=8207=BVMF48=380965483=79271273=65:81:55272=2014061037=80531934775288=8290=12
10:26:58.150: 657382 - 73 - 1128=935=X34=65738252=20140610-13:26:58.15675=20140610268=1279=2269=122=8207=BVMF48=380391383=106072273=65:81:55272=2014061037=80531938523289=110290=19
10:26:58.155: 657383 - 81 - 1128=935=X34=65738352=20140610-13:26:58.16175=20140610268=1279=0269=122=8207=BVMF48=380394783=65676270=17.04273=65:81:60271=100272=2014061037016=2014061037017=65:81:6037=80531938524289=8290=2
10:26:58.170: 657384 - 71 - 1128=935=X34=65738452=20140610-13:26:58.17775=20140610268=1279=2269=122=8207=BVMF48=380388983=12944273=65:81:76272=2014061037=80531890376289=40290=7
10:26:58.171: 657385 - 70 - 1128=935=X34=65738552=20140610-13:26:58.17775=20140610268=1279=2269=022=8207=BVMF48=380388983=12945273=65:81:77272=2014061037=80531890377288=40290=5
10:26:58.322: 657386 - 81 - 1128=935=X34=65738652=20140610-13:26:58.32875=20140610268=1279=0269=122=8207=BVMF48=380388983=12946270=11.46273=65:83:28271=300272=2014061037016=2014061037017=65:83:2837=80531938525289=40290=5
10:26:58.324: 657387 - 80 - 1128=935=X34=65738752=20140610-13:26:58.33075=20140610268=1279=0269=022=8207=BVMF48=380388983=12947270=11.28273=65:83:29271=300272=2014061037016=2014061037017=65:83:2937=80531938526288=40290=7
10:26:58.900: 657388 - 82 - 1128=935=X34=65738852=20140610-13:26:58.90775=20140610268=1279=0269=022=8207=BVMF48=380963983=255120270=26.07273=65:89:06271=400272=2014061037016=2014061037017=65:89:0637=80531938527288=114290=109
10:26:59.905: 657389 - 70 - 1128=935=X34=65738952=20140610-13:26:59.91275=20140610268=1279=2269=022=8207=BVMF48=380963983=255121273=65:99:11272=2014061037=80531938291288=8290=18
10:27:00.006: 657390 - 83 - 1128=935=X34=65739052=20140610-13:27:00.01275=20140610268=1279=0269=122=8207=BVMF48=380968883=253164270=29.4273=70:00:11271=1300272=2014061037016=2014061037017=70:00:1137=80531938531289=13290=6
10:27:00.010: 657391 - 81 - 1128=935=X34=65739152=20140610-13:27:00.01675=20140610268=1279=0269=122=8207=BVMF48=380968883=253165270=29.39273=70:00:16271=100272=2014061037016=2014061037017=70:00:1537=80531938532289=3290=4
10:27:00.015: 657392 - 82 - 1128=935=X34=65739252=20140610-13:27:00.02175=20140610268=1279=0269=122=8207=BVMF48=380968883=253166270=29.4273=70:00:21271=100272=2014061037016=2014061037017=70:00:2137=80531938533289=3290=8
10:27:00.019: 657393 - 81 - 1128=935=X34=65739352=20140610-13:27:00.02675=20140610268=1279=0269=122=8207=BVMF48=380968883=253167270=29.41273=70:00:25271=100272=2014061037016=2014061037017=70:00:2537=80531938534289=3290=10
10:27:00.024: 657394 - 81 - 1128=935=X34=65739452=20140610-13:27:00.03175=20140610268=1279=0269=122=8207=BVMF48=380968883=253168270=29.42273=70:00:30271=100272=2014061037016=2014061037017=70:00:3037=80531938535289=3290=12
10:27:00.137: 657395 - 81 - 1128=935=X34=65739552=20140610-13:27:00.14375=20140610268=1279=0269=022=8207=BVMF48=380968883=253169270=29.38273=70:01:43271=300272=2014061037016=2014061037017=70:01:4237=80531938536288=70290=6
10:27:00.530: 657396 - 82 - 1128=935=X34=65739652=20140610-13:27:00.53775=20140610268=1279=0269=022=8207=BVMF48=380965483=79272270=8.19273=70:05:36271=2500272=2014061037016=2014061037017=70:05:3637=80531938537288=386290=12
10:27:00.964: 657397 - 83 - 1128=935=X34=65739752=20140610-13:27:00.97175=20140610268=1279=0269=022=8207=BVMF48=380963983=255122270=25.1273=70:09:70271=800272=2014061037016=2014061037017=70:09:7037=80531938538288=39290=349
10:27:01.227: 657398 - 197 - 1128=935=X34=65739852=20140610-13:27:01.23475=20140610268=4279=0269=222=8207=BVMF48=380963983=255123270=26.41273=70:12:33271=300272=2014061037016=2014061037017=70:12:331500=E451=-0.21020=1344500274=01003=18060288=3289=40279=0269=922=8207=BVMF48=380963983=255124270=26.473273=70:12:33272=201406101500=E279=1269=122=8207=BVMF48=380963983=255125270=26.41273=70:12:33271=100272=2014061037016=2014061037017=64:89:3637=80531938297289=40290=1279=2269=022=8207=BVMF48=380963983=255126273=70:12:33272=2014061037=80531938351288=3290=4
10:27:01.242: 657399 - 81 - 1128=935=X34=65739952=20140610-13:27:01.24875=20140610268=1279=0269=022=8207=BVMF48=380963983=255127270=26.4273=70:12:48271=600272=2014061037016=2014061037017=70:12:4837=80531938554288=3290=6
10:27:01.243: 657400 - 82 - 1128=935=X34=65740052=20140610-13:27:01.24975=20140610268=1279=0269=122=8207=BVMF48=380653683=6208270=3.14273=70:12:48271=1000272=2014061037016=2014061037017=70:12:4837=80531938555289=262290=4
10:27:01.468: 657401 - 71 - 1128=935=X34=65740152=20140610-13:27:01.47575=20140610268=1279=2269=122=8207=BVMF48=380653683=6209273=70:14:74272=2014061037=80531925588289=40290=23
10:27:01.469: 657402 - 70 - 1128=935=X34=65740252=20140610-13:27:01.47675=20140610268=1279=2269=022=8207=BVMF48=380653683=6210273=70:14:75272=2014061037=80531925592288=40290=16
10:27:01.470: 657403 - 70 - 1128=935=X34=65740352=20140610-13:27:01.47775=20140610268=1279=2269=022=8207=BVMF48=380653683=6211273=70:14:76272=2014061037=80531925591288=40290=8
10:27:01.471: 657404 - 71 - 1128=935=X34=65740452=20140610-13:27:01.47875=20140610268=1279=2269=122=8207=BVMF48=380653683=6212273=70:14:77272=2014061037=80531925589289=40290=30
10:27:01.617: 657405 - 80 - 1128=935=X34=65740552=20140610-13:27:01.62475=20140610268=1279=0269=022=8207=BVMF48=380653683=6213270=3.09273=70:16:23271=500272=2014061037016=2014061037017=70:16:2337=80531938561288=40290=12
10:27:01.618: 657406 - 80 - 1128=935=X34=65740652=20140610-13:27:01.62575=20140610268=1279=0269=022=8207=BVMF48=380653683=6214270=3.06273=70:16:24271=100272=2014061037016=2014061037017=70:16:2437=80531938562288=40290=19
10:27:01.620: 657407 - 81 - 1128=935=X34=65740752=20140610-13:27:01.62775=20140610268=1279=0269=122=8207=BVMF48=380653683=6215270=3.17273=70:16:26271=500272=2014061037016=2014061037017=70:16:2637=80531938563289=40290=21
10:27:01.622: 657408 - 81 - 1128=935=X34=65740852=20140610-13:27:01.62875=20140610268=1279=0269=122=8207=BVMF48=380653683=6216270=3.2273=70:16:28271=100272=2014061037016=2014061037017=70:16:2737=80531938564289=40290=30
10:27:01.738: 657409 - 401 - 1128=935=X34=65740952=20140610-13:27:01.74475=20140610268=10279=0269=222=8207=BVMF48=380968883=253170270=29.39273=70:17:43271=4600272=2014061037016=2014061037017=70:17:431500=E451=-0.241020=424500274=1277=L1003=6080288=227289=45279=0269=922=8207=BVMF48=380968883=253171270=29.483273=70:17:43272=201406101500=E279=0269=222=8207=BVMF48=380968883=253172270=29.39273=70:17:43271=300272=2014061037016=2014061037017=70:17:431500=E451=-0.241020=424800274=1277=L1003=6090288=227289=8279=0269=922=8207=BVMF48=380968883=253173270=29.483273=70:17:43272=201406101500=E279=0269=222=8207=BVMF48=380968883=253174270=29.39273=70:17:43271=300272=2014061037016=2014061037017=70:17:431500=E451=-0.241020=425100274=1277=L1003=6100288=227289=45279=0269=922=8207=BVMF48=380968883=253175270=29.483273=70:17:43272=201406101500=E279=0269=222=8207=BVMF48=380968883=253176270=29.39273=70:17:43271=100272=2014061037016=2014061037017=70:17:431500=E451=-0.241020=425200274=1277=L1003=6110288=227289=3279=0269=922=8207=BVMF48=380968883=253177270=29.483273=70:17:43272=201406101500=E279=4269=122=8207=BVMF48=380968883=253178273=70:17:43272=20140610290=4279=0269=122=8207=BVMF48=380968883=253179270=29.39273=70:17:43271=5000272=2014061037016=2014061037017=70:17:4337=80531938566289=45290=1
10:27:01.739: 657410 - 71 - 1128=935=X34=65741052=20140610-13:27:01.74575=20140610268=1279=2269=122=8207=BVMF48=380968883=253180273=70:17:45272=2014061037=80531933852289=8290=33
10:27:01.746: 657411 - 80 - 1128=935=X34=65741152=20140610-13:27:01.75375=20140610268=1279=0269=022=8207=BVMF48=380968883=253181270=29.29273=70:17:52271=100272=2014061037016=2014061037017=70:17:5237=80531938567288=3290=36
10:27:01.748: 657412 - 71 - 1128=935=X34=65741252=20140610-13:27:01.75475=20140610268=1279=2269=122=8207=BVMF48=380963983=255128273=70:17:54272=2014061037=80531937750289=3290=8
10:27:01.750: 657413 - 83 - 1128=935=X34=65741352=20140610-13:27:01.75675=20140610268=1279=0269=122=8207=BVMF48=380968883=253182270=29.4273=70:17:56271=5000272=2014061037016=2014061037017=70:17:5637=80531938568289=45290=6
10:27:01.751: 657414 - 71 - 1128=935=X34=65741452=20140610-13:27:01.75875=20140610268=1279=2269=122=8207=BVMF48=380963983=255129273=70:17:57272=2014061037=80531937751289=3290=8
10:27:02.467: 657415 - 118 - 1128=935=X34=65741552=20140610-13:27:02.47375=20140610268=2279=2269=022=8207=BVMF48=380391383=106073273=70:24:73272=2014061037=80531938442288=40290=5279=0269=022=8207=BVMF48=380391383=106074270=13.81273=70:24:73271=100272=2014061037016=2014061037017=70:24:7337=80531938570288=40290=15
10:27:02.567: 657416 - 82 - 1128=935=X34=65741652=20140610-13:27:02.57375=20140610268=1279=0269=022=8207=BVMF48=380963983=255130270=25.91273=70:25:72271=300272=2014061037016=2014061037017=70:25:7237=80531938571288=72290=158
10:27:02.779: 657417 - 70 - 1128=935=X34=65741752=20140610-13:27:02.78675=20140610268=1279=2269=022=8207=BVMF48=380963983=255131273=70:27:85272=2014061037=80531937835288=3290=3
10:27:02.892: 657418 - 83 - 1128=935=X34=65741852=20140610-13:27:02.89975=20140610268=1279=0269=122=8207=BVMF48=380963983=255132270=26.41273=70:28:98271=200272=2014061037016=2014061037017=70:28:9837=80531938575289=238290=4
10:27:03.694: 657419 - 81 - 1128=935=X34=65741952=20140610-13:27:03.69975=20140610268=1279=0269=122=8207=BVMF48=380968883=253183270=29.39273=70:36:99271=300272=2014061037016=2014061037017=70:36:9937=80531938579289=8290=2
10:27:03.700: 657420 - 80 - 1128=935=X34=65742052=20140610-13:27:03.70775=20140610268=1279=0269=022=8207=BVMF48=380968883=253184270=29.33273=70:37:06271=100272=2014061037016=2014061037017=70:37:0637=80531938580288=3290=23
10:27:03.703: 657421 - 119 - 1128=935=X34=65742152=20140610-13:27:03.70975=20140610268=2279=2269=122=8207=BVMF48=380968883=253185273=70:37:09272=2014061037=80531938568289=45290=7279=0269=122=8207=BVMF48=380968883=253186270=29.39273=70:37:09271=300272=2014061037016=2014061037017=70:37:0837=80531938581289=45290=3
10:27:04.268: 657422 - 80 - 1128=935=X34=65742252=20140610-13:27:04.27575=20140610268=1279=0269=022=8207=BVMF48=380388983=12948270=11.35273=70:42:74271=200272=2014061037016=2014061037017=70:42:7437=80531938586288=72290=1
10:27:04.270: 657423 - 115 - 1128=935=X34=65742352=20140610-13:27:04.27675=20140610268=2279=2269=022=8207=BVMF48=380388983=12949273=70:42:76272=2014061037=80531932789288=8290=2279=0269=022=8207=BVMF48=380388983=12950270=11.35273=70:42:76271=200272=2014061037016=2014061037017=70:42:7537=80531938587288=8290=2
10:27:04.294: 657424 - 72 - 1128=935=X34=65742452=20140610-13:27:04.30175=20140610268=1279=2269=022=8207=BVMF48=380963983=255133273=70:43:00272=2014061037=80531938571288=72290=157
10:27:04.302: 657425 - 82 - 1128=935=X34=65742552=20140610-13:27:04.30875=20140610268=1279=0269=022=8207=BVMF48=380963983=255134270=25.91273=70:43:08271=200272=2014061037016=2014061037017=70:43:0837=80531938588288=72290=157
10:27:04.363: 657426 - 120 - 1128=935=X34=65742652=20140610-13:27:04.37075=20140610268=2279=2269=022=8207=BVMF48=380963983=255135273=70:43:69272=2014061037=80531938588288=72290=157279=0269=022=8207=BVMF48=380963983=255136270=25.91273=70:43:69271=300272=2014061037016=2014061037017=70:43:6937=80531938589288=72290=157
10:27:04.467: 657427 - 71 - 1128=935=X34=65742752=20140610-13:27:04.47475=20140610268=1279=2269=122=8207=BVMF48=380388983=12951273=70:44:73272=2014061037=80531872138289=40290=11
10:27:04.469: 657428 - 70 - 1128=935=X34=65742852=20140610-13:27:04.47575=20140610268=1279=2269=022=8207=BVMF48=380388983=12952273=70:44:75272=2014061037=80531872137288=40290=5
10:27:04.613: 657429 - 80 - 1128=935=X34=65742952=20140610-13:27:04.62075=20140610268=1279=0269=022=8207=BVMF48=380388983=12953270=11.27273=70:46:19271=300272=2014061037016=2014061037017=70:46:1937=80531938591288=40290=8
10:27:04.617: 657430 - 81 - 1128=935=X34=65743052=20140610-13:27:04.62375=20140610268=1279=0269=122=8207=BVMF48=380388983=12954270=11.48273=70:46:22271=300272=2014061037016=2014061037017=70:46:2237=80531938592289=40290=7
10:27:05.486: 657431 - 82 - 1128=935=X34=65743152=20140610-13:27:05.49375=20140610268=1279=0269=022=8207=BVMF48=380963983=255137270=26.33273=70:54:93271=1000272=2014061037016=2014061037017=70:54:9237=80531938596288=114290=47
10:27:06.116: 657432 - 119 - 1128=935=X34=65743252=20140610-13:27:06.12275=20140610268=2279=2269=122=8207=BVMF48=380394783=65677273=70:61:22272=2014061037=80531935678289=23290=6279=0269=122=8207=BVMF48=380394783=65678270=17.07273=70:61:22271=100272=2014061037016=2014061037017=70:61:2137=80531938598289=23290=9
10:27:06.151: 657433 - 80 - 1128=935=X34=65743352=20140610-13:27:06.15675=20140610268=1279=0269=022=8207=BVMF48=380394783=65679270=17273=70:61:55271=100272=2014061037016=2014061037017=70:61:5537=80531938599288=8290=6
10:27:06.162: 657434 - 72 - 1128=935=X34=65743452=20140610-13:27:06.16975=20140610268=1279=2269=022=8207=BVMF48=380394783=65680273=70:61:68272=2014061037=80531938511288=110290=11
10:27:06.554: 657435 - 71 - 1128=935=X34=65743552=20140610-13:27:06.56175=20140610268=1279=2269=122=8207=BVMF48=380977983=20187273=70:65:60272=2014061037=80531932539289=8290=5
10:27:06.555: 657436 - 80 - 1128=935=X34=65743652=20140610-13:27:06.56275=20140610268=1279=0269=022=8207=BVMF48=380977983=20188270=7.36273=70:65:62271=100272=2014061037016=2014061037017=70:65:6137=80531938600288=8290=5
10:27:06.748: 657437 - 70 - 1128=935=X34=65743752=20140610-13:27:06.75575=20140610268=1279=2269=022=8207=BVMF48=380963983=255138273=70:67:54272=2014061037=80531932588288=8290=39
10:27:06.750: 657438 - 80 - 1128=935=X34=65743852=20140610-13:27:06.75675=20140610268=1279=0269=022=8207=BVMF48=380963983=255139270=26.36273=70:67:56271=100272=2014061037016=2014061037017=70:67:5637=80531938601288=8290=26
10:27:07.429: 657439 - 69 - 1128=935=X34=65743952=20140610-13:27:07.43575=20140610268=1279=2269=022=8207=BVMF48=380388983=12955273=70:74:35272=2014061037=80531932790288=8290=3
10:27:07.487: 657440 - 82 - 1128=935=X34=65744052=20140610-13:27:07.49475=20140610268=1279=0269=022=8207=BVMF48=380977983=20189270=7.35273=70:74:93271=9500272=2014061037016=2014061037017=70:74:9337=80531938603288=39290=7
10:27:08.091: 657441 - 71 - 1128=935=X34=65744152=20140610-13:27:08.09775=20140610268=1279=2269=122=8207=BVMF48=380968883=253187273=70:80:97272=2014061037=80531938579289=8290=2
10:27:08.108: 657442 - 120 - 1128=935=X34=65744252=20140610-13:27:08.11575=20140610268=2279=2269=122=8207=BVMF48=380968883=253188273=70:81:14272=2014061037=80531938581289=45290=2279=0269=122=8207=BVMF48=380968883=253189270=29.4273=70:81:14271=5000272=2014061037016=2014061037017=70:81:1437=80531938607289=45290=6
10:27:08.312: 657443 - 81 - 1128=935=X34=65744352=20140610-13:27:08.31975=20140610268=1279=0269=022=8207=BVMF48=380566083=11396270=2.45273=70:83:18271=12200272=2014061037016=2014061037017=70:83:1837=80531938609288=86290=11
10:27:08.419: 657444 - 119 - 1128=935=X34=65744452=20140610-13:27:08.42675=20140610268=2279=2269=122=8207=BVMF48=380394783=65681273=70:84:25272=2014061037=80531931803289=40290=5279=0269=122=8207=BVMF48=380394783=65682270=17.07273=70:84:25271=100272=2014061037016=2014061037017=70:84:2537=80531938610289=40290=9
10:27:09.149: 657445 - 69 - 1128=935=X34=65744552=20140610-13:27:09.15675=20140610268=1279=2269=022=8207=BVMF48=380388983=12956273=70:91:55272=2014061037=80531933196288=8290=3
10:27:09.956: 657446 - 69 - 1128=935=X34=65744652=20140610-13:27:09.96275=20140610268=1279=2269=022=8207=BVMF48=380653683=6217273=70:99:62272=2014061037=80531933274288=8290=3
10:27:09.957: 657447 - 79 - 1128=935=X34=65744752=20140610-13:27:09.96475=20140610268=1279=0269=022=8207=BVMF48=380653683=6218270=3.11273=70:99:63271=100272=2014061037016=2014061037017=70:99:6337=80531938636288=8290=3
10:27:10.149: 657448 - 70 - 1128=935=X34=65744852=20140610-13:27:10.15575=20140610268=1279=2269=022=8207=BVMF48=380394783=65683273=71:01:55272=2014061037=80531938599288=8290=6
10:27:10.153: 657449 - 82 - 1128=935=X34=65744952=20140610-13:27:10.16075=20140610268=1279=0269=022=8207=BVMF48=380394783=65684270=16.98273=71:01:60271=400272=2014061037016=2014061037017=71:01:5937=80531938637288=110290=10
10:27:10.676: 657450 - 81 - 1128=935=X34=65745052=20140610-13:27:10.68375=20140610268=1279=0269=022=8207=BVMF48=380963983=255140270=26.39273=71:06:82271=800272=2014061037016=2014061037017=71:06:8237=80531938640288=59290=8
10:27:11.347: 657451 - 65 - 1128=935=X34=65745152=20140610-13:27:11.35475=20140610268=1279=0269=B22=8207=BVMF48=380963983=255141270=35592516273=71:13:52271=1806272=201406101500=E15=BRL
10:27:11.349: 657452 - 65 - 1128=935=X34=65745252=20140610-13:27:11.35675=20140610268=1279=0269=B22=8207=BVMF48=380249383=103364270=2414852273=71:13:52271=356272=201406101500=E15=BRL
10:27:11.361: 657453 - 65 - 1128=935=X34=65745352=20140610-13:27:11.36875=20140610268=1279=0269=B22=8207=BVMF48=380391383=106075270=1487717273=71:13:52271=325272=201406101500=E15=BRL
10:27:11.409: 657454 - 65 - 1128=935=X34=65745452=20140610-13:27:11.41675=20140610268=1279=0269=B22=8207=BVMF48=380968883=253190270=12536156273=71:13:52271=611272=201406101500=E15=BRL
10:27:11.410: 657455 - 64 - 1128=935=X34=65745552=20140610-13:27:11.41775=20140610268=1279=0269=B22=8207=BVMF48=380394783=65685270=319780273=71:13:52271=111272=201406101500=E15=BRL
10:27:11.648: 657456 - 82 - 1128=935=X34=65745652=20140610-13:27:11.65475=20140610268=1279=0269=122=8207=BVMF48=380963983=255142270=26.41273=71:16:54271=200272=2014061037016=2014061037017=71:16:5437=80531938643289=27290=5
10:27:11.908: 657457 - 81 - 1128=935=X34=65745752=20140610-13:27:11.91575=20140610268=1279=1269=122=8207=BVMF48=380963983=255143270=26.41273=71:19:14271=200272=2014061037016=2014061037017=65:39:0337=80531938663289=40290=3
10:27:11.942: 657458 - 82 - 1128=935=X34=65745852=20140610-13:27:11.94975=20140610268=1279=0269=122=8207=BVMF48=380963983=255144270=26.41273=71:19:48271=700272=2014061037016=2014061037017=71:19:4837=80531938675289=40290=6
10:27:11.977: 657459 - 82 - 1128=935=X34=65745952=20140610-13:27:11.98475=20140610268=1279=0269=022=8207=BVMF48=380249383=103365270=9.32273=71:19:84271=1000272=2014061037016=2014061037017=71:19:8337=80531938692288=102290=7
10:27:11.978: 657460 - 80 - 1128=935=X34=65746052=20140610-13:27:11.98575=20140610268=1279=0269=022=8207=BVMF48=380249383=103366270=9.31273=71:19:85271=100272=2014061037016=2014061037017=71:19:8537=80531938693288=8290=11
10:27:13.151: 657461 - 71 - 1128=935=X34=65746152=20140610-13:27:13.15775=20140610268=1279=2269=122=8207=BVMF48=380965483=79273273=71:31:57272=2014061037=80531934649289=8290=18
10:27:13.152: 657462 - 81 - 1128=935=X34=65746252=20140610-13:27:13.15975=20140610268=1279=0269=022=8207=BVMF48=380965483=79274270=8.2273=71:31:58271=100272=2014061037016=2014061037017=71:31:5837=80531938697288=8290=7
10:27:13.800: 657463 - 149 - 1128=935=X34=65746352=20140610-13:27:13.80775=20140610268=3279=0269=222=8207=BVMF48=380963983=255145270=26.41273=71:38:06271=100272=2014061037016=2014061037017=71:38:061500=E451=-0.21020=1344600274=1277=L1003=18070288=735289=40279=0269=922=8207=BVMF48=380963983=255146270=26.473273=71:38:06272=201406101500=E279=2269=122=8207=BVMF48=380963983=255147273=71:38:06272=2014061037=80531938297289=40290=1
10:27:13.806: 657464 - 71 - 1128=935=X34=65746452=20140610-13:27:13.81275=20140610268=1279=2269=122=8207=BVMF48=380963983=255148273=71:38:12272=2014061037=80531935940289=8290=42
10:27:13.806: 657465 - 81 - 1128=935=X34=65746552=20140610-13:27:13.81375=20140610268=1279=0269=122=8207=BVMF48=380963983=255149270=26.43273=71:38:12271=300272=2014061037016=2014061037017=71:38:1237=80531938704289=8290=12
10:27:14.435: 657466 - 82 - 1128=935=X34=65746652=20140610-13:27:14.44275=20140610268=1279=0269=022=8207=BVMF48=380965483=79275270=8.2273=71:44:42271=1000272=2014061037016=2014061037017=71:44:4137=80531938707288=27290=8
10:27:14.437: 657467 - 81 - 1128=935=X34=65746752=20140610-13:27:14.44475=20140610268=1279=0269=122=8207=BVMF48=380965483=79276270=8.23273=71:44:43271=100272=2014061037016=2014061037017=71:44:4337=80531938708289=8290=7
10:27:14.703: 657468 - 81 - 1128=935=X34=65746852=20140610-13:27:14.71075=20140610268=1279=0269=022=8207=BVMF48=380963983=255150270=26.4273=71:47:09271=600272=2014061037016=2014061037017=71:47:0937=80531938711288=3290=6
10:27:15.007: 657469 - 72 - 1128=935=X34=65746952=20140610-13:27:15.01475=20140610268=1279=2269=022=8207=BVMF48=380963983=255151273=71:50:13272=2014061037=80531938589288=72290=160
10:27:15.011: 657470 - 82 - 1128=935=X34=65747052=20140610-13:27:15.01875=20140610268=1279=0269=022=8207=BVMF48=380963983=255152270=25.89273=71:50:17271=300272=2014061037016=2014061037017=71:50:1737=80531938713288=72290=165
10:27:15.034: 657471 - 81 - 1128=935=X34=65747152=20140610-13:27:15.04075=20140610268=1279=0269=122=8207=BVMF48=380968883=253191270=29.41273=71:50:40271=300272=2014061037016=2014061037017=71:50:4037=80531938714289=3290=9
10:27:15.034: 657472 - 81 - 1128=935=X34=65747252=20140610-13:27:15.04175=20140610268=1279=0269=122=8207=BVMF48=380963983=255153270=26.43273=71:50:41271=800272=2014061037016=2014061037017=71:50:4037=80531938715289=3290=13
10:27:15.079: 657473 - 439 - 1128=935=X34=65747352=20140610-13:27:15.08675=20140610268=11279=0269=222=8207=BVMF48=380963983=255154270=26.41273=71:50:85271=100272=2014061037016=2014061037017=71:50:841500=E451=-0.21020=1344700274=1277=L1003=18080288=3289=40279=0269=922=8207=BVMF48=380963983=255155270=26.473273=71:50:85272=201406101500=E279=0269=222=8207=BVMF48=380963983=255156270=26.41273=71:50:85271=200272=2014061037016=2014061037017=71:50:841500=E451=-0.21020=1344900274=1277=L1003=18090288=3289=40279=0269=922=8207=BVMF48=380963983=255157270=26.473273=71:50:85272=201406101500=E279=0269=222=8207=BVMF48=380963983=255158270=26.41273=71:50:85271=200272=2014061037016=2014061037017=71:50:841500=E451=-0.21020=1345100274=1277=L1003=18100288=3289=238279=0269=922=8207=BVMF48=380963983=255159270=26.473273=71:50:85272=201406101500=E279=0269=222=8207=BVMF48=380963983=255160270=26.41273=71:50:85271=100272=2014061037016=2014061037017=71:50:841500=E451=-0.21020=1345200274=1277=L1003=18110288=3289=27279=0269=922=8207=BVMF48=380963983=255161270=26.473273=71:50:85272=201406101500=E279=4269=122=8207=BVMF48=380963983=255162273=71:50:85272=20140610290=3279=1269=122=8207=BVMF48=380963983=255163270=26.41273=71:50:85271=100272=2014061037016=2014061037017=71:16:5437=80531938643289=27290=1279=2269=022=8207=BVMF48=380963983=255164273=71:50:85272=2014061037=80531938554288=3290=5
10:27:15.096: 657474 - 268 - 1128=935=X34=65747452=20140610-13:27:15.10375=20140610268=6279=0269=222=8207=BVMF48=380963983=255165270=26.41273=71:51:02271=100272=2014061037016=2014061037017=71:51:021500=E451=-0.21020=1345300274=1277=L1003=18120288=3289=27279=0269=922=8207=BVMF48=380963983=255166270=26.473273=71:51:02272=201406101500=E279=0269=222=8207=BVMF48=380963983=255167270=26.41273=71:51:02271=500272=2014061037016=2014061037017=71:51:021500=E451=-0.21020=1345800274=1277=L1003=18130288=3289=40279=0269=922=8207=BVMF48=380963983=255168270=26.473273=71:51:02272=201406101500=E279=2269=122=8207=BVMF48=380963983=255169273=71:51:02272=2014061037=80531938643289=27290=1279=1269=122=8207=BVMF48=380963983=255170270=26.41273=71:51:02271=200272=2014061037016=2014061037017=71:19:4837=80531938675289=40290=1
10:27:15.122: 657475 - 82 - 1128=935=X34=65747552=20140610-13:27:15.12975=20140610268=1279=0269=122=8207=BVMF48=380963983=255171270=26.42273=71:51:29271=200272=2014061037016=2014061037017=71:51:2937=80531938732289=40290=4
10:27:15.126: 657476 - 82 - 1128=935=X34=65747652=20140610-13:27:15.13375=20140610268=1279=0269=122=8207=BVMF48=380963983=255172270=26.41273=71:51:32271=800272=2014061037016=2014061037017=71:51:3237=80531938733289=40290=2
10:27:15.149: 657477 - 70 - 1128=935=X34=65747752=20140610-13:27:15.15675=20140610268=1279=2269=022=8207=BVMF48=380977983=20190273=71:51:55272=2014061037=80531938600288=8290=5
10:27:15.149: 657478 - 70 - 1128=935=X34=65747852=20140610-13:27:15.15675=20140610268=1279=2269=022=8207=BVMF48=380965483=79277273=71:51:55272=2014061037=80531938697288=8290=7
10:27:15.150: 657479 - 71 - 1128=935=X34=65747952=20140610-13:27:15.15775=20140610268=1279=2269=122=8207=BVMF48=380977983=20191273=71:51:56272=2014061037=80531934678289=8290=5
10:27:15.151: 657480 - 82 - 1128=935=X34=65748052=20140610-13:27:15.15875=20140610268=1279=0269=122=8207=BVMF48=380977983=20192270=7.4273=71:51:58271=100272=2014061037016=2014061037017=71:51:5737=80531938735289=8290=5
10:27:15.225: 657481 - 267 - 1128=935=X34=65748152=20140610-13:27:15.23275=20140610268=6279=0269=222=8207=BVMF48=380963983=255173270=26.41273=71:52:31271=200272=2014061037016=2014061037017=71:52:311500=E451=-0.21020=1346000274=1277=L1003=18140288=3289=40279=0269=922=8207=BVMF48=380963983=255174270=26.473273=71:52:31272=201406101500=E279=0269=222=8207=BVMF48=380963983=255175270=26.41273=71:52:31271=400272=2014061037016=2014061037017=71:52:311500=E451=-0.21020=1346400274=1277=L1003=18150288=3289=40279=0269=922=8207=BVMF48=380963983=255176270=26.473273=71:52:31272=201406101500=E279=2269=122=8207=BVMF48=380963983=255177273=71:52:31272=2014061037=80531938675289=40290=1279=1269=122=8207=BVMF48=380963983=255178270=26.41273=71:52:31271=400272=2014061037016=2014061037017=71:51:3237=80531938733289=40290=1
10:27:15.235: 657482 - 195 - 1128=935=X34=65748252=20140610-13:27:15.24275=20140610268=4279=0269=222=8207=BVMF48=380963983=255179270=26.41273=71:52:41271=400272=2014061037016=2014061037017=71:52:411500=E451=-0.21020=1346800274=1277=L1003=18160288=3289=40279=0269=922=8207=BVMF48=380963983=255180270=26.473273=71:52:41272=201406101500=E279=2269=122=8207=BVMF48=380963983=255181273=71:52:41272=2014061037=80531938733289=40290=1279=0269=022=8207=BVMF48=380963983=255182270=26.41273=71:52:41271=200272=2014061037016=2014061037017=71:52:4137=80531938743288=3290=1
10:27:15.236: 657483 - 195 - 1128=935=X34=65748352=20140610-13:27:15.24375=20140610268=4279=0269=222=8207=BVMF48=380963983=255183270=26.41273=71:52:42271=200272=2014061037016=2014061037017=71:52:421500=E451=-0.21020=1347000274=1277=L1003=18170288=3289=40279=0269=922=8207=BVMF48=380963983=255184270=26.473273=71:52:42272=201406101500=E279=2269=022=8207=BVMF48=380963983=255185273=71:52:42272=2014061037=80531938743288=3290=1279=0269=122=8207=BVMF48=380963983=255186270=26.41273=71:52:42271=700272=2014061037016=2014061037017=71:52:4237=80531938745289=40290=1
10:27:15.236: 657484 - 71 - 1128=935=X34=65748452=20140610-13:27:15.24375=20140610268=1279=2269=122=8207=BVMF48=380963983=255187273=71:52:42272=2014061037=80531937754289=8290=7
10:27:15.237: 657485 - 234 - 1128=935=X34=65748552=20140610-13:27:15.24475=20140610268=5279=0269=222=8207=BVMF48=380963983=255188270=26.41273=71:52:43271=700272=2014061037016=2014061037017=71:52:431500=E451=-0.21020=1347700274=1277=L1003=18180288=45289=40279=0269=922=8207=BVMF48=380963983=255189270=26.473273=71:52:43272=201406101500=E279=2269=022=8207=BVMF48=380963983=255190273=71:52:43272=2014061037=80531923336288=45290=39279=2269=122=8207=BVMF48=380963983=255191273=71:52:43272=2014061037=80531938745289=40290=1279=0269=022=8207=BVMF48=380963983=255192270=26.41273=71:52:43271=4300272=2014061037016=2014061037017=71:52:4337=80531938747288=45290=1
10:27:15.238: 657486 - 72 - 1128=935=X34=65748652=20140610-13:27:15.24575=20140610268=1279=2269=122=8207=BVMF48=380968883=253192273=71:52:44272=2014061037=80531937990289=45290=32
10:27:15.238: 657487 - 81 - 1128=935=X34=65748752=20140610-13:27:15.24575=20140610268=1279=0269=122=8207=BVMF48=380963983=255193270=26.42273=71:52:45271=100272=2014061037016=2014061037017=71:52:4437=80531938749289=8290=4
10:27:15.238: 657488 - 118 - 1128=935=X34=65748852=20140610-13:27:15.24575=20140610268=2279=2269=022=8207=BVMF48=380968883=253193273=71:52:45272=2014061037=80531937931288=45290=21279=0269=022=8207=BVMF48=380968883=253194270=29.36273=71:52:45271=2000272=2014061037016=2014061037017=71:52:4537=80531938752288=45290=11
10:27:15.244: 657489 - 80 - 1128=935=X34=65748952=20140610-13:27:15.25175=20140610268=1279=0269=022=8207=BVMF48=380963983=255194270=26.41273=71:52:50271=600272=2014061037016=2014061037017=71:52:5037=80531938764288=3290=2
10:27:15.259: 657490 - 159 - 1128=935=X34=65749052=20140610-13:27:15.26675=20140610268=3279=0269=222=8207=BVMF48=380963983=255195270=26.41273=71:52:65271=600272=2014061037016=2014061037017=71:52:651500=E451=-0.21020=1348300274=1277=L1003=18190288=45289=40279=0269=922=8207=BVMF48=380963983=255196270=26.473273=71:52:65272=201406101500=E279=1269=022=8207=BVMF48=380963983=255197270=26.41273=71:52:65271=3700272=2014061037016=2014061037017=71:52:4337=80531938747288=45290=1
10:27:15.259: 657491 - 195 - 1128=935=X34=65749152=20140610-13:27:15.26675=20140610268=4279=0269=222=8207=BVMF48=380963983=255198270=26.42273=71:52:66271=600272=2014061037016=2014061037017=71:52:651500=E451=-0.191020=1348900274=01003=18200288=3289=8279=0269=922=8207=BVMF48=380963983=255199270=26.472273=71:52:66272=201406101500=E279=1269=122=8207=BVMF48=380963983=255200270=26.42273=71:52:66271=1900272=2014061037016=2014061037017=64:75:2737=80531937864289=8290=1279=2269=022=8207=BVMF48=380963983=255201273=71:52:66272=2014061037=80531938764288=3290=2
10:27:15.264: 657492 - 80 - 1128=935=X34=65749252=20140610-13:27:15.27175=20140610268=1279=0269=022=8207=BVMF48=380963983=255202270=26.41273=71:52:70271=600272=2014061037016=2014061037017=71:52:7037=80531938805288=3290=2
10:27:15.267: 657493 - 72 - 1128=935=X34=65749352=20140610-13:27:15.27475=20140610268=1279=2269=022=8207=BVMF48=380968883=253195273=71:52:74272=2014061037=80531938274288=227290=15
10:27:15.279: 657494 - 82 - 1128=935=X34=65749452=20140610-13:27:15.28675=20140610268=1279=0269=022=8207=BVMF48=380968883=253196270=29.36273=71:52:85271=800272=2014061037016=2014061037017=71:52:8537=80531938821288=227290=12
10:27:15.284: 657495 - 119 - 1128=935=X34=65749552=20140610-13:27:15.29175=20140610268=2279=2269=022=8207=BVMF48=380963983=255203273=71:52:90272=2014061037=80531938640288=59290=10279=0269=022=8207=BVMF48=380963983=255204270=26.4273=71:52:90271=800272=2014061037016=2014061037017=71:52:9037=80531938822288=59290=8
10:27:15.292: 657496 - 82 - 1128=935=X34=65749652=20140610-13:27:15.29975=20140610268=1279=0269=122=8207=BVMF48=380963983=255205270=26.42273=71:52:98271=900272=2014061037016=2014061037017=71:52:9837=80531938824289=40290=5
10:27:15.354: 657497 - 71 - 1128=935=X34=65749752=20140610-13:27:15.36175=20140610268=1279=2269=122=8207=BVMF48=380963983=255206273=71:53:60272=2014061037=80531938749289=8290=4
10:27:15.431: 657498 - 81 - 1128=935=X34=65749852=20140610-13:27:15.43875=20140610268=1279=0269=122=8207=BVMF48=380963983=255207270=26.43273=71:54:38271=100272=2014061037016=2014061037017=71:54:3737=80531938835289=8290=10
10:27:15.432: 657499 - 81 - 1128=935=X34=65749952=20140610-13:27:15.43975=20140610268=1279=0269=122=8207=BVMF48=380963983=255208270=26.43273=71:54:39271=1000272=2014061037016=2014061037017=71:54:3937=80531938836289=8290=11
10:27:15.439: 657500 - 82 - 1128=935=X34=65750052=20140610-13:27:15.44675=20140610268=1279=0269=122=8207=BVMF48=380968883=253197270=29.49273=71:54:46271=2000272=2014061037016=2014061037017=71:54:4637=80531938837289=45290=34
10:27:15.471: 657501 - 117 - 1128=935=X34=65750152=20140610-13:27:15.47875=20140610268=2279=2269=122=8207=BVMF48=380963983=255209273=71:54:77272=2014061037=80531938715289=3290=9279=0269=122=8207=BVMF48=380963983=255210270=26.44273=71:54:77271=800272=2014061037016=2014061037017=71:54:7737=80531938838289=3290=18
10:27:15.483: 657502 - 81 - 1128=935=X34=65750252=20140610-13:27:15.49075=20140610268=1279=1269=022=8207=BVMF48=380963983=255211270=25.89273=71:54:89271=100272=2014061037016=2014061037017=71:50:1737=80531938839288=72290=165
10:27:15.486: 657503 - 71 - 1128=935=X34=65750352=20140610-13:27:15.49375=20140610268=1279=2269=122=8207=BVMF48=380963983=255212273=71:54:93272=2014061037=80531938838289=3290=18
10:27:15.487: 657504 - 71 - 1128=935=X34=65750452=20140610-13:27:15.49475=20140610268=1279=2269=122=8207=BVMF48=380968883=253198273=71:54:93272=2014061037=80531938714289=3290=9
10:27:15.492: 657505 - 81 - 1128=935=X34=65750552=20140610-13:27:15.49975=20140610268=1279=0269=122=8207=BVMF48=380963983=255213270=26.44273=71:54:99271=800272=2014061037016=2014061037017=71:54:9937=80531938840289=3290=18
10:27:15.494: 657506 - 81 - 1128=935=X34=65750652=20140610-13:27:15.50175=20140610268=1279=0269=122=8207=BVMF48=380968883=253199270=29.41273=71:55:00271=300272=2014061037016=2014061037017=71:55:0037=80531938841289=3290=9
10:27:15.495: 657507 - 120 - 1128=935=X34=65750752=20140610-13:27:15.50275=20140610268=2279=2269=022=8207=BVMF48=380963983=255214273=71:55:01272=2014061037=80531938839288=72290=165279=0269=022=8207=BVMF48=380963983=255215270=25.87273=71:55:01271=1000272=2014061037016=2014061037017=71:55:0137=80531938842288=72290=165
10:27:15.497: 657508 - 71 - 1128=935=X34=65750852=20140610-13:27:15.50475=20140610268=1279=2269=122=8207=BVMF48=380963983=255216273=71:55:03272=2014061037=80531938840289=3290=18
10:27:15.497: 657509 - 71 - 1128=935=X34=65750952=20140610-13:27:15.50475=20140610268=1279=2269=122=8207=BVMF48=380968883=253200273=71:55:04272=2014061037=80531938841289=3290=9
10:27:15.741: 657510 - 80 - 1128=935=X34=65751052=20140610-13:27:15.74875=20140610268=1279=0269=022=8207=BVMF48=380963983=255217270=26.38273=71:57:47271=300272=2014061037016=2014061037017=71:57:4737=80531938844288=8290=14
10:27:15.741: 657511 - 71 - 1128=935=X34=65751152=20140610-13:27:15.74875=20140610268=1279=2269=122=8207=BVMF48=380963983=255218273=71:57:47272=2014061037=80531938276289=8290=7
10:27:15.774: 657512 - 81 - 1128=935=X34=65751252=20140610-13:27:15.78175=20140610268=1279=0269=122=8207=BVMF48=380394783=65686270=17.04273=71:57:81271=100272=2014061037016=2014061037017=71:57:8037=80531938846289=3290=3
10:27:15.907: 657513 - 121 - 1128=935=X34=65751352=20140610-13:27:15.91475=20140610268=2279=2269=022=8207=BVMF48=380963983=255219273=71:59:14272=2014061037=80531938842288=72290=166279=0269=022=8207=BVMF48=380963983=255220270=25.9273=71:59:14271=100272=2014061037016=2014061037017=71:59:1437=80531938847288=72290=165
10:27:16.241: 657514 - 71 - 1128=935=X34=65751452=20140610-13:27:16.24875=20140610268=1279=2269=122=8207=BVMF48=380963983=255221273=71:62:47272=2014061037=80531938704289=8290=7
10:27:16.241: 657515 - 80 - 1128=935=X34=65751552=20140610-13:27:16.24875=20140610268=1279=0269=022=8207=BVMF48=380963983=255222270=26.37273=71:62:47271=300272=2014061037016=2014061037017=71:62:4737=80531938849288=8290=21
10:27:16.932: 657516 - 120 - 1128=935=X34=65751652=20140610-13:27:16.93975=20140610268=2279=2269=022=8207=BVMF48=380963983=255223273=71:69:38272=2014061037=80531938847288=72290=166279=0269=022=8207=BVMF48=380963983=255224270=25.87273=71:69:38271=1000272=2014061037016=2014061037017=71:69:3837=80531938851288=72290=167
10:27:16.944: 657517 - 120 - 1128=935=X34=65751752=20140610-13:27:16.95175=20140610268=2279=2269=022=8207=BVMF48=380963983=255225273=71:69:51272=2014061037=80531938851288=72290=167279=0269=022=8207=BVMF48=380963983=255226270=25.89273=71:69:51271=100272=2014061037016=2014061037017=71:69:5037=80531938852288=72290=167
10:27:17.256: 657518 - 197 - 1128=935=X34=65751852=20140610-13:27:17.26375=20140610268=4279=0269=222=8207=BVMF48=380963983=255227270=26.42273=71:72:62271=100272=2014061037016=2014061037017=71:72:621500=E451=-0.191020=1349000274=1277=L1003=18210288=70289=8279=0269=922=8207=BVMF48=380963983=255228270=26.472273=71:72:62272=201406101500=E279=1269=122=8207=BVMF48=380963983=255229270=26.42273=71:72:62271=1800272=2014061037016=2014061037017=64:75:2737=80531937864289=8290=1279=2269=022=8207=BVMF48=380963983=255230273=71:72:62272=2014061037=80531938415288=70290=6
10:27:17.283: 657519 - 72 - 1128=935=X34=65751952=20140610-13:27:17.29075=20140610268=1279=2269=122=8207=BVMF48=380963983=255231273=71:72:89272=2014061037=80531938732289=40290=3
10:27:17.342: 657520 - 80 - 1128=935=X34=65752052=20140610-13:27:17.35075=20140610268=1279=0269=022=8207=BVMF48=380391383=106076270=13.84273=71:73:49271=100272=2014061037016=2014061037017=71:73:4937=80531938855288=8290=1
10:27:17.347: 657521 - 72 - 1128=935=X34=65752152=20140610-13:27:17.35475=20140610268=1279=2269=022=8207=BVMF48=380394783=65687273=71:73:53272=2014061037=80531938637288=110290=10
10:27:17.350: 657522 - 80 - 1128=935=X34=65752252=20140610-13:27:17.35775=20140610268=1279=0269=022=8207=BVMF48=380391383=106077270=13.83273=71:73:56271=500272=2014061037016=2014061037017=71:73:5637=80531938861288=3290=6
10:27:17.530: 657523 - 70 - 1128=935=X34=65752352=20140610-13:27:17.53775=20140610268=1279=2269=022=8207=BVMF48=380394783=65688273=71:75:36272=2014061037=80531938510288=8290=3
10:27:17.534: 657524 - 81 - 1128=935=X34=65752452=20140610-13:27:17.54175=20140610268=1279=1269=022=8207=BVMF48=380963983=255232270=26.21273=71:75:40271=1000272=2014061037016=2014061037017=90:41:1337=80531938871288=308290=86
10:27:17.554: 657525 - 80 - 1128=935=X34=65752552=20140610-13:27:17.56175=20140610268=1279=0269=022=8207=BVMF48=380394783=65689270=17.03273=71:75:60271=400272=2014061037016=2014061037017=71:75:6037=80531938872288=8290=1
10:27:17.568: 657526 - 70 - 1128=935=X34=65752652=20140610-13:27:17.57575=20140610268=1279=2269=022=8207=BVMF48=380391383=106078273=71:75:74272=2014061037=80531938514288=8290=35
10:27:17.578: 657527 - 80 - 1128=935=X34=65752752=20140610-13:27:17.58575=20140610268=1279=0269=022=8207=BVMF48=380391383=106079270=13.78273=71:75:85271=400272=2014061037016=2014061037017=71:75:8537=80531938873288=8290=35
10:27:17.833: 657528 - 115 - 1128=935=X34=65752852=20140610-13:27:17.84075=20140610268=2279=2269=022=8207=BVMF48=390102283=4003273=71:78:40272=2014061037=80531938515288=3290=2279=0269=022=8207=BVMF48=390102283=4004270=17.02273=71:78:40271=96272=2014061037016=2014061037017=71:78:4037=80531938876288=3290=1
10:27:18.090: 657529 - 363 - 1128=935=X34=65752952=20140610-13:27:18.09775=20140610268=9279=0269=222=8207=BVMF48=380965483=79278270=8.22273=71:80:96271=500272=2014061037016=2014061037017=71:80:951500=E451=-0.061020=191700274=01003=2670288=564289=8279=0269=922=8207=BVMF48=380965483=79279270=8.255273=71:80:96272=201406101500=E279=0269=222=8207=BVMF48=380965483=79280270=8.22273=71:80:96271=200272=2014061037016=2014061037017=71:80:951500=E451=-0.061020=191900274=1277=L1003=2680288=564289=40279=0269=922=8207=BVMF48=380965483=79281270=8.255273=71:80:96272=201406101500=E279=0269=222=8207=BVMF48=380965483=79282270=8.22273=71:80:96271=200272=2014061037016=2014061037017=71:80:951500=E451=-0.061020=192100274=1277=L1003=2690288=564289=16279=0269=922=8207=BVMF48=380965483=79283270=8.255273=71:80:96272=201406101500=E279=2269=022=8207=BVMF48=380965483=79284273=71:80:96272=2014061037=80531872397288=564290=10279=4269=122=8207=BVMF48=380965483=79285273=71:80:96272=20140610290=3279=0269=022=8207=BVMF48=380965483=79286270=8.22273=71:80:96271=1100272=2014061037016=2014061037017=71:80:9537=80531938877288=564290=1
10:27:18.091: 657530 - 80 - 1128=935=X34=65753052=20140610-13:27:18.09875=20140610268=1279=0269=022=8207=BVMF48=380965483=79287270=8.21273=71:80:97271=500272=2014061037016=2014061037017=71:80:9737=80531938878288=8290=6
10:27:18.092: 657531 - 80 - 1128=935=X34=65753152=20140610-13:27:18.09875=20140610268=1279=0269=022=8207=BVMF48=380965483=79288270=8.21273=71:80:98271=100272=2014061037016=2014061037017=71:80:9837=80531938879288=8290=7
10:27:18.092: 657532 - 70 - 1128=935=X34=65753252=20140610-13:27:18.09975=20140610268=1279=2269=022=8207=BVMF48=380965483=79289273=71:80:98272=2014061037=80531938879288=8290=7
10:27:18.102: 657533 - 71 - 1128=935=X34=65753352=20140610-13:27:18.10975=20140610268=1279=2269=022=8207=BVMF48=380965483=79290273=71:81:08272=2014061037=80531937550288=40290=5
10:27:18.104: 657534 - 118 - 1128=935=X34=65753452=20140610-13:27:18.11175=20140610268=2279=2269=022=8207=BVMF48=380965483=79291273=71:81:10272=2014061037=80531935259288=40290=2279=0269=022=8207=BVMF48=380965483=79292270=8.22273=71:81:10271=300272=2014061037016=2014061037017=71:81:1037=80531938988288=40290=2
10:27:18.104: 657535 - 80 - 1128=935=X34=65753552=20140610-13:27:18.11175=20140610268=1279=0269=022=8207=BVMF48=380965483=79293270=8.18273=71:81:11271=800272=2014061037016=2014061037017=71:81:1037=80531938989288=8290=24
10:27:18.116: 657536 - 81 - 1128=935=X34=65753652=20140610-13:27:18.12375=20140610268=1279=0269=022=8207=BVMF48=380965483=79294270=8.22273=71:81:22271=200272=2014061037016=2014061037017=71:81:2237=80531939013288=40290=3
10:27:18.149: 657537 - 71 - 1128=935=X34=65753752=20140610-13:27:18.15675=20140610268=1279=2269=122=8207=BVMF48=380965483=79295273=71:81:55272=2014061037=80531938708289=8290=4
10:27:18.158: 657538 - 71 - 1128=935=X34=65753852=20140610-13:27:18.16575=20140610268=1279=2269=022=8207=BVMF48=380965483=79296273=71:81:64272=2014061037=80531939013288=40290=3
10:27:18.270: 657539 - 71 - 1128=935=X34=65753952=20140610-13:27:18.27775=20140610268=1279=2269=022=8207=BVMF48=380965483=79297273=71:82:76272=2014061037=80531932750288=40290=67
10:27:18.270: 657540 - 71 - 1128=935=X34=65754052=20140610-13:27:18.27875=20140610268=1279=2269=022=8207=BVMF48=380965483=79298273=71:82:77272=2014061037=80531932751288=40290=56
10:27:18.364: 657541 - 81 - 1128=935=X34=65754152=20140610-13:27:18.37175=20140610268=1279=0269=122=8207=BVMF48=380968883=253201270=29.39273=71:83:70271=100272=2014061037016=2014061037017=71:83:7037=80531939014289=3290=2
10:27:18.418: 657542 - 81 - 1128=935=X34=65754252=20140610-13:27:18.42575=20140610268=1279=0269=022=8207=BVMF48=380965483=79299270=8.17273=71:84:25271=7000272=2014061037016=2014061037017=71:84:2537=80531939015288=40290=34
10:27:18.420: 657543 - 81 - 1128=935=X34=65754352=20140610-13:27:18.42775=20140610268=1279=0269=022=8207=BVMF48=380965483=79300270=8.15273=71:84:27271=2100272=2014061037016=2014061037017=71:84:2637=80531939016288=40290=59
10:27:18.426: 657544 - 72 - 1128=935=X34=65754452=20140610-13:27:18.43275=20140610268=1279=2269=022=8207=BVMF48=380965483=79301273=71:84:32272=2014061037=80531936077288=114290=4
10:27:18.495: 657545 - 193 - 1128=935=X34=65754552=20140610-13:27:18.50275=20140610268=4279=0269=222=8207=BVMF48=380391383=106080270=13.85273=71:85:02271=100272=2014061037016=2014061037017=71:85:011500=E451=-0.041020=107300274=01003=3260288=8289=8279=0269=922=8207=BVMF48=380391383=106081270=13.878273=71:85:02272=201406101500=E279=1269=122=8207=BVMF48=380391383=106082270=13.85273=71:85:02271=800272=2014061037016=2014061037017=50:95:0937=80531929098289=8290=1279=2269=022=8207=BVMF48=380391383=106083273=71:85:02272=2014061037=80531938855288=8290=1
10:27:18.551: 657546 - 82 - 1128=935=X34=65754652=20140610-13:27:18.55875=20140610268=1279=0269=022=8207=BVMF48=380965483=79302270=8.22273=71:85:57271=1000272=2014061037016=2014061037017=71:85:5737=80531939035288=114290=3
10:27:18.554: 657547 - 80 - 1128=935=X34=65754752=20140610-13:27:18.56175=20140610268=1279=0269=022=8207=BVMF48=380391383=106084270=13.83273=71:85:60271=100272=2014061037016=2014061037017=71:85:6037=80531939036288=8290=6
10:27:18.604: 657548 - 70 - 1128=935=X34=65754852=20140610-13:27:18.61175=20140610268=1279=2269=022=8207=BVMF48=380965483=79303273=71:86:10272=2014061037=80531932767288=8290=69
10:27:18.604: 657549 - 71 - 1128=935=X34=65754952=20140610-13:27:18.61175=20140610268=1279=2269=122=8207=BVMF48=380965483=79304273=71:86:10272=2014061037=80531932768289=8290=9
10:27:18.604: 657550 - 80 - 1128=935=X34=65755052=20140610-13:27:18.61175=20140610268=1279=0269=022=8207=BVMF48=380965483=79305270=8.19273=71:86:10271=800272=2014061037016=2014061037017=71:86:1037=80531939039288=8290=14
10:27:18.871: 657551 - 70 - 1128=935=X34=65755152=20140610-13:27:18.87975=20140610268=1279=2269=022=8207=BVMF48=380394783=65690273=71:88:78272=2014061037=80531938872288=8290=1
10:27:18.878: 657552 - 82 - 1128=935=X34=65755252=20140610-13:27:18.88575=20140610268=1279=0269=022=8207=BVMF48=380394783=65691270=16.98273=71:88:85271=400272=2014061037016=2014061037017=71:88:8537=80531939040288=110290=9
10:27:18.885: 657553 - 70 - 1128=935=X34=65755352=20140610-13:27:18.89275=20140610268=1279=2269=022=8207=BVMF48=380391383=106085273=71:88:91272=2014061037=80531938873288=8290=35
10:27:18.886: 657554 - 80 - 1128=935=X34=65755452=20140610-13:27:18.89375=20140610268=1279=0269=022=8207=BVMF48=380394783=65692270=17.02273=71:88:93271=400272=2014061037016=2014061037017=71:88:9337=80531939041288=8290=3
10:27:18.895: 657555 - 80 - 1128=935=X34=65755552=20140610-13:27:18.90275=20140610268=1279=0269=022=8207=BVMF48=380391383=106086270=13.78273=71:89:01271=1000272=2014061037016=2014061037017=71:89:0137=80531939042288=8290=35
10:27:18.980: 657556 - 115 - 1128=935=X34=65755652=20140610-13:27:18.98775=20140610268=2279=2269=022=8207=BVMF48=390102283=4005273=71:89:86272=2014061037=80531938876288=3290=1279=0269=022=8207=BVMF48=390102283=4006270=17.01273=71:89:86271=96272=2014061037016=2014061037017=71:89:8637=80531939043288=3290=2
10:27:19.104: 657557 - 70 - 1128=935=X34=65755752=20140610-13:27:19.11175=20140610268=1279=2269=022=8207=BVMF48=380965483=79306273=71:91:10272=2014061037=80531933374288=8290=74
10:27:19.104: 657558 - 80 - 1128=935=X34=65755852=20140610-13:27:19.11175=20140610268=1279=0269=022=8207=BVMF48=380965483=79307270=8.19273=71:91:10271=800272=2014061037016=2014061037017=71:91:1037=80531939044288=8290=15
10:27:19.433: 657559 - 82 - 1128=935=X34=65755952=20140610-13:27:19.44175=20140610268=1279=0269=022=8207=BVMF48=380963983=255233270=26.41273=71:94:40271=4700272=2014061037016=2014061037017=71:94:4037=80531939048288=227290=3
10:27:19.435: 657560 - 71 - 1128=935=X34=65756052=20140610-13:27:19.44275=20140610268=1279=2269=122=8207=BVMF48=380391383=106087273=71:94:41272=2014061037=80531934784289=8290=13
10:27:19.436: 657561 - 81 - 1128=935=X34=65756152=20140610-13:27:19.44375=20140610268=1279=0269=122=8207=BVMF48=380391383=106088270=13.87273=71:94:43271=100272=2014061037016=2014061037017=71:94:4337=80531939049289=8290=13
10:27:20.093: 657562 - 70 - 1128=935=X34=65756252=20140610-13:27:20.10175=20140610268=1279=2269=022=8207=BVMF48=380965483=79308273=72:01:00272=2014061037=80531935415288=8290=4
10:27:20.533: 657563 - 82 - 1128=935=X34=65756352=20140610-13:27:20.54175=20140610268=1279=0269=122=8207=BVMF48=380963983=255234270=26.42273=72:05:40271=100272=2014061037016=2014061037017=72:05:4037=80531939058289=40290=4
10:27:20.806: 657564 - 80 - 1128=935=X34=65756452=20140610-13:27:20.81375=20140610268=1279=0269=022=8207=BVMF48=380963983=255235270=26.41273=72:08:13271=1000272=2014061037016=2014061037017=72:08:1237=80531939059288=3290=4
10:27:21.095: 657565 - 80 - 1128=935=X34=65756552=20140610-13:27:21.10275=20140610268=1279=0269=022=8207=BVMF48=380965483=79309270=8.22273=72:11:01271=6300272=2014061037016=2014061037017=72:11:0137=80531939061288=8290=4
10:27:21.096: 657566 - 80 - 1128=935=X34=65756652=20140610-13:27:21.10375=20140610268=1279=0269=022=8207=BVMF48=380965483=79310270=8.22273=72:11:03271=500272=2014061037016=2014061037017=72:11:0337=80531939062288=8290=5
10:27:21.311: 657567 - 83 - 1128=935=X34=65756752=20140610-13:27:21.31875=20140610268=1279=0269=122=8207=BVMF48=380963983=255236270=26.42273=72:13:17271=200272=2014061037016=2014061037017=72:13:1737=80531939068289=238290=5
10:27:21.753: 657568 - 158 - 1128=935=X34=65756852=20140610-13:27:21.76075=20140610268=3279=0269=222=8207=BVMF48=380968883=253202270=29.39273=72:17:60271=1200272=2014061037016=2014061037017=72:17:591500=E451=-0.241020=426400274=1277=L1003=6120288=227289=45279=0269=922=8207=BVMF48=380968883=253203270=29.483273=72:17:60272=201406101500=E279=1269=122=8207=BVMF48=380968883=253204270=29.39273=72:17:60271=3800272=2014061037016=2014061037017=70:17:4337=80531938566289=45290=1
10:27:21.754: 657569 - 82 - 1128=935=X34=65756952=20140610-13:27:21.76175=20140610268=1279=0269=122=8207=BVMF48=380963983=255237270=26.42273=72:17:60271=200272=2014061037016=2014061037017=72:17:6037=80531939071289=72290=6
10:27:22.540: 657570 - 80 - 1128=935=X34=65757052=20140610-13:27:22.54775=20140610268=1279=0269=022=8207=BVMF48=380963983=255238270=26.41273=72:25:46271=100272=2014061037016=2014061037017=72:25:4637=80531939115288=8290=5
10:27:22.544: 657571 - 118 - 1128=935=X34=65757152=20140610-13:27:22.55275=20140610268=2279=2269=022=8207=BVMF48=380963983=255239273=72:25:51272=2014061037=80531938382288=45290=8279=0269=022=8207=BVMF48=380963983=255240270=26.41273=72:25:51271=100272=2014061037016=2014061037017=72:25:5137=80531939116288=45290=6
10:27:22.547: 657572 - 158 - 1128=935=X34=65757252=20140610-13:27:22.55575=20140610268=3279=0269=222=8207=BVMF48=380963983=255241270=26.42273=72:25:54271=100272=2014061037016=2014061037017=72:25:541500=E451=-0.191020=1349100274=1277=L1003=18220288=735289=8279=0269=922=8207=BVMF48=380963983=255242270=26.472273=72:25:54272=201406101500=E279=1269=122=8207=BVMF48=380963983=255243270=26.42273=72:25:54271=1700272=2014061037016=2014061037017=64:75:2737=80531937864289=8290=1
10:27:22.597: 657573 - 70 - 1128=935=X34=65757352=20140610-13:27:22.60575=20140610268=1279=2269=022=8207=BVMF48=380965483=79311273=72:26:04272=2014061037=80531939061288=8290=4
10:27:22.599: 657574 - 70 - 1128=935=X34=65757452=20140610-13:27:22.60675=20140610268=1279=2269=022=8207=BVMF48=380965483=79312273=72:26:05272=2014061037=80531939062288=8290=4
10:27:22.599: 657575 - 81 - 1128=935=X34=65757552=20140610-13:27:22.60675=20140610268=1279=0269=122=8207=BVMF48=380965483=79313270=8.24273=72:26:06271=100272=2014061037016=2014061037017=72:26:0537=80531939118289=8290=9
10:27:22.706: 657576 - 373 - 1128=935=X34=65757652=20140610-13:27:22.71375=20140610268=9279=0269=222=8207=BVMF48=380963983=255244270=26.42273=72:27:12271=1700272=2014061037016=2014061037017=72:27:121500=E451=-0.191020=1350800274=1277=L1003=18230288=227289=8279=0269=922=8207=BVMF48=380963983=255245270=26.472273=72:27:12272=201406101500=E279=0269=222=8207=BVMF48=380963983=255246270=26.42273=72:27:12271=2500272=2014061037016=2014061037017=72:27:121500=E451=-0.191020=1353300274=1277=L1003=18240288=227289=8279=0269=922=8207=BVMF48=380963983=255247270=26.472273=72:27:12272=201406101500=E279=0269=222=8207=BVMF48=380963983=255248270=26.42273=72:27:12271=500272=2014061037016=2014061037017=72:27:121500=E451=-0.191020=1353800274=1277=L1003=18250288=227289=40279=0269=922=8207=BVMF48=380963983=255249270=26.472273=72:27:12272=201406101500=E279=4269=122=8207=BVMF48=380963983=255250273=72:27:12272=20140610290=2279=1269=122=8207=BVMF48=380963983=255251270=26.42273=72:27:12271=400272=2014061037016=2014061037017=71:52:9837=80531938824289=40290=1279=2269=022=8207=BVMF48=380963983=255252273=72:27:12272=2014061037=80531939048288=227290=3
10:27:22.707: 657577 - 72 - 1128=935=X34=65757752=20140610-13:27:22.71475=20140610268=1279=2269=122=8207=BVMF48=380963983=255253273=72:27:14272=2014061037=80531938255289=45290=14
10:27:22.708: 657578 - 118 - 1128=935=X34=65757852=20140610-13:27:22.71675=20140610268=2279=2269=022=8207=BVMF48=380963983=255254273=72:27:15272=2014061037=80531938292288=45290=64279=0269=022=8207=BVMF48=380963983=255255270=26.41273=72:27:15271=3000272=2014061037016=2014061037017=72:27:1537=80531939125288=45290=6
10:27:22.719: 657579 - 156 - 1128=935=X34=65757952=20140610-13:27:22.72675=20140610268=3279=0269=222=8207=BVMF48=380968883=253205270=29.39273=72:27:25271=2200272=2014061037016=2014061037017=72:27:251500=E451=-0.241020=428600274=1277=L1003=6130288=8289=45279=0269=922=8207=BVMF48=380968883=253206270=29.482273=72:27:25272=201406101500=E279=1269=122=8207=BVMF48=380968883=253207270=29.39273=72:27:25271=1600272=2014061037016=2014061037017=70:17:4337=80531938566289=45290=1
10:27:22.737: 657580 - 82 - 1128=935=X34=65758052=20140610-13:27:22.74475=20140610268=1279=0269=122=8207=BVMF48=380963983=255256270=26.42273=72:27:44271=600272=2014061037016=2014061037017=72:27:4337=80531939179289=40290=5
10:27:22.757: 657581 - 81 - 1128=935=X34=65758152=20140610-13:27:22.76475=20140610268=1279=0269=122=8207=BVMF48=380963983=255257270=26.42273=72:27:63271=1800272=2014061037016=2014061037017=72:27:6337=80531939192289=8290=6
10:27:22.908: 657582 - 82 - 1128=935=X34=65758252=20140610-13:27:22.91575=20140610268=1279=0269=122=8207=BVMF48=380963983=255258270=26.54273=72:29:15271=3000272=2014061037016=2014061037017=72:29:1537=80531939207289=45290=68
10:27:23.175: 657583 - 81 - 1128=935=X34=65758352=20140610-13:27:23.18275=20140610268=1279=0269=122=8207=BVMF48=380391383=106089270=13.85273=72:31:81271=100272=2014061037016=2014061037017=72:31:8137=80531939211289=3290=6
10:27:23.599: 657584 - 80 - 1128=935=X34=65758452=20140610-13:27:23.60675=20140610268=1279=0269=022=8207=BVMF48=380965483=79314270=8.22273=72:36:05271=5300272=2014061037016=2014061037017=72:36:0537=80531939216288=8290=4
10:27:23.600: 657585 - 80 - 1128=935=X34=65758552=20140610-13:27:23.60775=20140610268=1279=0269=022=8207=BVMF48=380965483=79315270=8.22273=72:36:07271=500272=2014061037016=2014061037017=72:36:0737=80531939217288=8290=5
10:27:23.698: 657586 - 81 - 1128=935=X34=65758652=20140610-13:27:23.70575=20140610268=1279=0269=022=8207=BVMF48=380963983=255259270=26.25273=72:37:04271=1000272=2014061037016=2014061037017=72:37:0437=80531939218288=21290=82
10:27:23.812: 657587 - 119 - 1128=935=X34=65758752=20140610-13:27:23.81975=20140610268=2279=2269=122=8207=BVMF48=380394783=65693273=72:38:18272=2014061037=80531938598289=23290=9279=0269=122=8207=BVMF48=380394783=65694270=17.06273=72:38:18271=100272=2014061037016=2014061037017=72:38:1837=80531939219289=23290=8
10:27:23.813: 657588 - 80 - 1128=935=X34=65758852=20140610-13:27:23.82075=20140610268=1279=0269=022=8207=BVMF48=380394783=65695270=17273=72:38:20271=100272=2014061037016=2014061037017=72:38:2037=80531939220288=8290=6
10:27:23.822: 657589 - 72 - 1128=935=X34=65758952=20140610-13:27:23.82975=20140610268=1279=2269=022=8207=BVMF48=380394783=65696273=72:38:28272=2014061037=80531939040288=110290=11
10:27:23.910: 657590 - 156 - 1128=935=X34=65759052=20140610-13:27:23.91875=20140610268=3279=0269=222=8207=BVMF48=380965483=79316270=8.22273=72:39:17271=100272=2014061037016=2014061037017=72:39:171500=E451=-0.061020=192200274=1277=L1003=2700288=564289=3279=0269=922=8207=BVMF48=380965483=79317270=8.255273=72:39:17272=201406101500=E279=1269=022=8207=BVMF48=380965483=79318270=8.22273=72:39:17271=1000272=2014061037016=2014061037017=71:80:9537=80531938877288=564290=1
10:27:24.297: 657591 - 197 - 1128=935=X34=65759152=20140610-13:27:24.30575=20140610268=4279=0269=222=8207=BVMF48=380963983=255260270=26.42273=72:43:04271=100272=2014061037016=2014061037017=72:43:041500=E451=-0.191020=1353900274=1277=L1003=18260288=8289=40279=0269=922=8207=BVMF48=380963983=255261270=26.472273=72:43:04272=201406101500=E279=1269=122=8207=BVMF48=380963983=255262270=26.42273=72:43:04271=300272=2014061037016=2014061037017=71:52:9837=80531938824289=40290=1279=2269=022=8207=BVMF48=380963983=255263273=72:43:04272=2014061037=80531939115288=8290=4
10:27:24.310: 657592 - 119 - 1128=935=X34=65759252=20140610-13:27:24.31875=20140610268=2279=2269=022=8207=BVMF48=380963983=255264273=72:43:17272=2014061037=80531939116288=45290=4279=0269=022=8207=BVMF48=380963983=255265270=26.4273=72:43:17271=800272=2014061037016=2014061037017=72:43:1737=80531939224288=45290=9
10:27:24.581: 657593 - 72 - 1128=935=X34=65759352=20140610-13:27:24.58875=20140610268=1279=2269=122=8207=BVMF48=380963983=255266273=72:45:88272=2014061037=80531938824289=40290=1
10:27:24.584: 657594 - 72 - 1128=935=X34=65759452=20140610-13:27:24.59175=20140610268=1279=2269=122=8207=BVMF48=380963983=255267273=72:45:91272=2014061037=80531939179289=40290=4
10:27:25.269: 657595 - 245 - 1128=935=X34=65759552=20140610-13:27:25.27775=20140610268=6279=0269=222=8207=BVMF48=380963983=255268270=26.42273=72:52:76271=100272=2014061037016=2014061037017=72:52:761500=E451=-0.191020=1354000274=1277=L1003=18270288=3289=40279=0269=922=8207=BVMF48=380963983=255269270=26.472273=72:52:76272=201406101500=E279=0269=222=8207=BVMF48=380963983=255270270=26.42273=72:52:76271=200272=2014061037016=2014061037017=72:52:761500=E451=-0.191020=1354200274=1277=L1003=18280288=3289=238279=0269=922=8207=BVMF48=380963983=255271270=26.472273=72:52:76272=201406101500=E279=2269=022=8207=BVMF48=380963983=255272273=72:52:76272=2014061037=80531938805288=3290=2279=4269=122=8207=BVMF48=380963983=255273273=72:52:76272=20140610290=2
10:27:25.279: 657596 - 80 - 1128=935=X34=65759652=20140610-13:27:25.28675=20140610268=1279=0269=022=8207=BVMF48=380963983=255274270=26.41273=72:52:85271=600272=2014061037016=2014061037017=72:52:8537=80531939235288=3290=4
10:27:25.294: 657597 - 81 - 1128=935=X34=65759752=20140610-13:27:25.30175=20140610268=1279=0269=022=8207=BVMF48=380653683=6219270=3.13273=72:53:01271=2000272=2014061037016=2014061037017=72:53:0137=80531939238288=564290=1
10:27:25.302: 657598 - 69 - 1128=935=X34=65759852=20140610-13:27:25.31075=20140610268=1279=2269=022=8207=BVMF48=380653683=6220273=72:53:09272=2014061037=80531928002288=3290=27
10:27:25.423: 657599 - 82 - 1128=935=X34=65759952=20140610-13:27:25.43175=20140610268=1279=0269=122=8207=BVMF48=380963983=255275270=26.42273=72:54:30271=200272=2014061037016=2014061037017=72:54:3037=80531939239289=40290=3
10:27:25.568: 657600 - 81 - 1128=935=X34=65760052=20140610-13:27:25.57675=20140610268=1279=0269=022=8207=BVMF48=380965483=79319270=8.22273=72:55:75271=500272=2014061037016=2014061037017=72:55:7537=80531939241288=72290=6
10:27:25.650: 657601 - 82 - 1128=935=X34=65760152=20140610-13:27:25.65775=20140610268=1279=0269=122=8207=BVMF48=380963983=255276270=26.42273=72:56:56271=500272=2014061037016=2014061037017=72:56:5637=80531939243289=27290=4
10:27:26.130: 657602 - 158 - 1128=935=X34=65760252=20140610-13:27:26.13775=20140610268=3279=0269=222=8207=BVMF48=380963983=255277270=26.41273=72:61:36271=100272=2014061037016=2014061037017=72:61:361500=E451=-0.21020=1354300274=21003=18290288=45289=3279=0269=922=8207=BVMF48=380963983=255278270=26.472273=72:61:36272=201406101500=E279=1269=022=8207=BVMF48=380963983=255279270=26.41273=72:61:36271=3600272=2014061037016=2014061037017=71:52:4337=80531938747288=45290=1
10:27:27.269: 657603 - 305 - 1128=935=X34=65760352=20140610-13:27:27.27775=20140610268=7279=0269=222=8207=BVMF48=380963983=255280270=26.42273=72:72:76271=200272=2014061037016=2014061037017=72:72:751500=E451=-0.191020=1354500274=01003=18300288=3289=72279=0269=922=8207=BVMF48=380963983=255281270=26.472273=72:72:76272=201406101500=E279=0269=222=8207=BVMF48=380963983=255282270=26.42273=72:72:76271=100272=2014061037016=2014061037017=72:72:751500=E451=-0.191020=1354600274=1277=L1003=18310288=3289=8279=0269=922=8207=BVMF48=380963983=255283270=26.472273=72:72:76272=201406101500=E279=2269=122=8207=BVMF48=380963983=255284273=72:72:76272=2014061037=80531939071289=72290=1279=1269=122=8207=BVMF48=380963983=255285270=26.42273=72:72:76271=1700272=2014061037016=2014061037017=72:27:6337=80531939192289=8290=1279=2269=022=8207=BVMF48=380963983=255286273=72:72:76272=2014061037=80531939235288=3290=4
10:27:27.281: 657604 - 156 - 1128=935=X34=65760452=20140610-13:27:27.28975=20140610268=3279=0269=222=8207=BVMF48=380968883=253208270=29.39273=72:72:88271=100272=2014061037016=2014061037017=72:72:881500=E451=-0.241020=428700274=1277=L1003=6140288=8289=45279=0269=922=8207=BVMF48=380968883=253209270=29.482273=72:72:88272=201406101500=E279=1269=122=8207=BVMF48=380968883=253210270=29.39273=72:72:88271=1500272=2014061037016=2014061037017=70:17:4337=80531938566289=45290=1
10:27:27.287: 657605 - 71 - 1128=935=X34=65760552=20140610-13:27:27.29475=20140610268=1279=2269=122=8207=BVMF48=380963983=255287273=72:72:94272=2014061037=80531939192289=8290=1
10:27:27.308: 657606 - 80 - 1128=935=X34=65760652=20140610-13:27:27.31675=20140610268=1279=0269=022=8207=BVMF48=380963983=255288270=26.41273=72:73:15271=600272=2014061037016=2014061037017=72:73:1537=80531939273288=3290=4
10:27:27.318: 657607 - 81 - 1128=935=X34=65760752=20140610-13:27:27.32675=20140610268=1279=0269=122=8207=BVMF48=380963983=255289270=26.42273=72:73:25271=1700272=2014061037016=2014061037017=72:73:2537=80531939276289=8290=3
10:27:28.079: 657608 - 82 - 1128=935=X34=65760852=20140610-13:27:28.08675=20140610268=1279=0269=122=8207=BVMF48=380965483=79320270=8.23273=72:80:86271=100272=2014061037016=2014061037017=72:80:8637=80531939298289=16290=4
10:27:29.148: 657609 - 70 - 1128=935=X34=65760952=20140610-13:27:29.15575=20140610268=1279=2269=022=8207=BVMF48=380394783=65697273=72:91:55272=2014061037=80531939220288=8290=6
10:27:29.148: 657610 - 70 - 1128=935=X34=65761052=20140610-13:27:29.15675=20140610268=1279=2269=122=8207=BVMF48=380388983=12957273=72:91:55272=2014061037=80531935245289=8290=3
10:27:29.149: 657611 - 80 - 1128=935=X34=65761152=20140610-13:27:29.15775=20140610268=1279=0269=122=8207=BVMF48=380388983=12958270=11.39273=72:91:57271=100272=2014061037016=2014061037017=72:91:5737=80531939300289=8290=3
10:27:29.153: 657612 - 82 - 1128=935=X34=65761252=20140610-13:27:29.16075=20140610268=1279=0269=022=8207=BVMF48=380394783=65698270=16.98273=72:91:60271=400272=2014061037016=2014061037017=72:91:6037=80531939301288=110290=10
10:27:29.836: 657613 - 71 - 1128=935=X34=65761352=20140610-13:27:29.84375=20140610268=1279=2269=122=8207=BVMF48=380394783=65699273=72:98:43272=2014061037=80531938846289=3290=3
10:27:29.844: 657614 - 71 - 1128=935=X34=65761452=20140610-13:27:29.85275=20140610268=1279=2269=122=8207=BVMF48=380968883=253211273=72:98:51272=2014061037=80531939014289=3290=2
10:27:29.886: 657615 - 80 - 1128=935=X34=65761552=20140610-13:27:29.89475=20140610268=1279=1269=122=8207=BVMF48=380963983=255290270=26.42273=72:98:93271=1600272=2014061037016=2014061037017=72:73:2537=80531939304289=8290=3
10:27:30.137: 657616 - 157 - 1128=935=X34=65761652=20140610-13:27:30.14575=20140610268=3279=0269=222=8207=BVMF48=380968883=253212270=29.39273=73:01:44271=300272=2014061037016=2014061037017=73:01:441500=E451=-0.241020=429000274=1277=L1003=6150288=70289=45279=0269=922=8207=BVMF48=380968883=253213270=29.482273=73:01:44272=201406101500=E279=1269=122=8207=BVMF48=380968883=253214270=29.39273=73:01:44271=1200272=2014061037016=2014061037017=70:17:4337=80531938566289=45290=1
10:27:30.147: 657617 - 71 - 1128=935=X34=65761752=20140610-13:27:30.15575=20140610268=1279=2269=122=8207=BVMF48=380394783=65700273=73:01:55272=2014061037=80531937574289=8290=6
10:27:30.149: 657618 - 80 - 1128=935=X34=65761852=20140610-13:27:30.15775=20140610268=1279=0269=022=8207=BVMF48=380394783=65701270=17273=73:01:56271=100272=2014061037016=2014061037017=73:01:5637=80531939308288=8290=6
10:27:30.192: 657619 - 72 - 1128=935=X34=65761952=20140610-13:27:30.20075=20140610268=1279=2269=022=8207=BVMF48=380394783=65702273=73:01:99272=2014061037=80531939301288=110290=11
10:27:30.254: 657620 - 159 - 1128=935=X34=65762052=20140610-13:27:30.26275=20140610268=3279=0269=222=8207=BVMF48=380963983=255291270=26.41273=73:02:61271=100272=2014061037016=2014061037017=73:02:611500=E451=-0.21020=1354700274=21003=18320288=45289=72279=0269=922=8207=BVMF48=380963983=255292270=26.472273=73:02:61272=201406101500=E279=1269=022=8207=BVMF48=380963983=255293270=26.41273=73:02:61271=3500272=2014061037016=2014061037017=71:52:4337=80531938747288=45290=1
10:27:30.306: 657621 - 80 - 1128=935=X34=65762152=20140610-13:27:30.31475=20140610268=1279=1269=122=8207=BVMF48=380963983=255294270=26.42273=73:03:13271=1300272=2014061037016=2014061037017=72:73:2537=80531939310289=8290=3
10:27:30.596: 657622 - 71 - 1128=935=X34=65762252=20140610-13:27:30.60475=20140610268=1279=2269=122=8207=BVMF48=380394783=65703273=73:06:03272=2014061037=80531938524289=8290=2
10:27:31.313: 657623 - 206 - 1128=935=X34=65762352=20140610-13:27:31.32175=20140610268=5279=0269=222=8207=BVMF48=380557983=2407270=2.93273=73:13:20271=100272=2014061037016=2014061037017=73:13:201500=E451=-0.11020=4500274=21003=60288=8289=3279=0269=822=8207=BVMF48=380557983=2408270=2.93273=73:13:20272=201406101500=E279=0269=922=8207=BVMF48=380557983=2409270=3.036273=73:13:20272=201406101500=E279=2269=022=8207=BVMF48=380557983=2410273=73:13:20272=2014061037=80531915516288=8290=1279=0269=122=8207=BVMF48=380557983=2411270=2.93273=73:13:20271=100272=2014061037016=2014061037017=73:13:2037=80531939314289=3290=1
10:27:31.315: 657624 - 138 - 1128=935=X34=65762452=20140610-13:27:31.32375=20140610268=3279=0269=222=8207=BVMF48=380557983=2412270=2.93273=73:13:22271=100272=2014061037016=2014061037017=73:13:221500=E451=-0.11020=4600274=3277=L1003=70288=8289=3279=0269=922=8207=BVMF48=380557983=2413270=3.034273=73:13:22272=201406101500=E279=2269=122=8207=BVMF48=380557983=2414273=73:13:22272=2014061037=80531939314289=3290=1
10:27:31.316: 657625 - 80 - 1128=935=X34=65762552=20140610-13:27:31.32475=20140610268=1279=0269=122=8207=BVMF48=380557983=2415270=3.02273=73:13:24271=100272=2014061037016=2014061037017=73:13:2337=80531939316289=8290=1
10:27:31.317: 657626 - 71 - 1128=935=X34=65762652=20140610-13:27:31.32575=20140610268=1279=2269=122=8207=BVMF48=380391383=106090273=73:13:25272=2014061037=80531939211289=3290=6
10:27:32.148: 657627 - 70 - 1128=935=X34=65762752=20140610-13:27:32.15675=20140610268=1279=2269=022=8207=BVMF48=380394783=65704273=73:21:55272=2014061037=80531939308288=8290=6
10:27:32.156: 657628 - 82 - 1128=935=X34=65762852=20140610-13:27:32.16475=20140610268=1279=0269=022=8207=BVMF48=380394783=65705270=16.98273=73:21:63271=400272=2014061037016=2014061037017=73:21:6337=80531939319288=110290=10
10:27:33.285: 657629 - 307 - 1128=935=X34=65762952=20140610-13:27:33.29375=20140610268=7279=0269=222=8207=BVMF48=380963983=255295270=26.42273=73:32:92271=200272=2014061037016=2014061037017=73:32:921500=E451=-0.191020=1354900274=01003=18330288=3289=40279=0269=922=8207=BVMF48=380963983=255296270=26.472273=73:32:92272=201406101500=E279=0269=222=8207=BVMF48=380963983=255297270=26.42273=73:32:92271=100272=2014061037016=2014061037017=73:32:921500=E451=-0.191020=1355000274=1277=L1003=18340288=3289=27279=0269=922=8207=BVMF48=380963983=255298270=26.472273=73:32:92272=201406101500=E279=2269=122=8207=BVMF48=380963983=255299273=73:32:92272=2014061037=80531939239289=40290=1279=1269=122=8207=BVMF48=380963983=255300270=26.42273=73:32:92271=400272=2014061037016=2014061037017=72:56:5637=80531939243289=27290=1279=2269=022=8207=BVMF48=380963983=255301273=73:32:92272=2014061037=80531939273288=3290=4
10:27:33.294: 657630 - 80 - 1128=935=X34=65763052=20140610-13:27:33.30275=20140610268=1279=0269=022=8207=BVMF48=380963983=255302270=26.41273=73:33:01271=600272=2014061037016=2014061037017=73:33:0137=80531939324288=3290=4
10:27:33.435: 657631 - 82 - 1128=935=X34=65763152=20140610-13:27:33.44375=20140610268=1279=0269=122=8207=BVMF48=380963983=255303270=26.42273=73:34:43271=200272=2014061037016=2014061037017=73:34:4237=80531939328289=40290=3
10:27:33.907: 657632 - 145 - 1128=935=X34=65763252=20140610-13:27:33.91575=20140610268=3279=0269=222=8207=BVMF48=380968883=253215270=29.38273=73:39:14271=100272=2014061037016=2014061037017=73:39:141500=E451=-0.251020=429100274=21003=6160288=45289=3279=0269=922=8207=BVMF48=380968883=253216270=29.482273=73:39:14272=201406101500=E279=2269=022=8207=BVMF48=380968883=253217273=73:39:14272=2014061037=80531934070288=45290=1
10:27:33.908: 657633 - 81 - 1128=935=X34=65763352=20140610-13:27:33.91675=20140610268=1279=0269=122=8207=BVMF48=380968883=253218270=29.39273=73:39:16271=300272=2014061037016=2014061037017=73:39:1637=80531939333289=8290=2
10:27:33.930: 657634 - 119 - 1128=935=X34=65763452=20140610-13:27:33.93875=20140610268=2279=2269=122=8207=BVMF48=380968883=253219273=73:39:37272=2014061037=80531938607289=45290=7279=0269=122=8207=BVMF48=380968883=253220270=29.39273=73:39:37271=300272=2014061037016=2014061037017=73:39:3737=80531939334289=45290=3
10:27:33.934: 657635 - 81 - 1128=935=X34=65763552=20140610-13:27:33.94275=20140610268=1279=0269=022=8207=BVMF48=380968883=253221270=29.38273=73:39:42271=1500272=2014061037016=2014061037017=73:39:4237=80531939335288=45290=6
10:27:33.958: 657636 - 81 - 1128=935=X34=65763652=20140610-13:27:33.96675=20140610268=1279=0269=122=8207=BVMF48=380963983=255304270=26.42273=73:39:65271=700272=2014061037016=2014061037017=73:39:6537=80531939336289=8290=4
10:27:34.769: 657637 - 71 - 1128=935=X34=65763752=20140610-13:27:34.77775=20140610268=1279=2269=122=8207=BVMF48=380249383=103367273=73:47:76272=2014061037=80531935619289=8290=11
10:27:34.771: 657638 - 81 - 1128=935=X34=65763852=20140610-13:27:34.77975=20140610268=1279=0269=122=8207=BVMF48=380249383=103368270=9.35273=73:47:78271=100272=2014061037016=2014061037017=73:47:7837=80531939344289=8290=11
10:27:35.080: 657639 - 396 - 1128=935=X34=65763952=20140610-13:27:35.08875=20140610268=10279=0269=222=8207=BVMF48=380965483=79321270=8.23273=73:50:87271=400272=2014061037016=2014061037017=73:50:861500=E451=-0.051020=192600274=01003=2710288=227289=8279=0269=922=8207=BVMF48=380965483=79322270=8.255273=73:50:87272=201406101500=E279=0269=222=8207=BVMF48=380965483=79323270=8.23273=73:50:87271=500272=2014061037016=2014061037017=73:50:861500=E451=-0.051020=193100274=1277=L1003=2720288=227289=8279=0269=922=8207=BVMF48=380965483=79324270=8.255273=73:50:87272=201406101500=E279=0269=222=8207=BVMF48=380965483=79325270=8.23273=73:50:87271=900272=2014061037016=2014061037017=73:50:861500=E451=-0.051020=194000274=1277=L1003=2730288=227289=3279=0269=922=8207=BVMF48=380965483=79326270=8.254273=73:50:87272=201406101500=E279=0269=222=8207=BVMF48=380965483=79327270=8.23273=73:50:87271=100272=2014061037016=2014061037017=73:50:861500=E451=-0.051020=194100274=1277=L1003=2740288=227289=16279=0269=922=8207=BVMF48=380965483=79328270=8.254273=73:50:87272=201406101500=E279=4269=122=8207=BVMF48=380965483=79329273=73:50:87272=20140610290=4279=0269=022=8207=BVMF48=380965483=79330270=8.23273=73:50:87271=13100272=2014061037016=2014061037017=73:50:8637=80531939345288=227290=1
10:27:35.082: 657640 - 80 - 1128=935=X34=65764052=20140610-13:27:35.08975=20140610268=1279=0269=022=8207=BVMF48=380965483=79331270=8.23273=73:50:89271=500272=2014061037016=2014061037017=73:50:8937=80531939346288=8290=2
10:27:35.083: 657641 - 81 - 1128=935=X34=65764152=20140610-13:27:35.09175=20140610268=1279=0269=122=8207=BVMF48=380965483=79332270=8.24273=73:50:91271=100272=2014061037016=2014061037017=73:50:9037=80531939354289=8290=7
10:27:35.088: 657642 - 71 - 1128=935=X34=65764252=20140610-13:27:35.09675=20140610268=1279=2269=122=8207=BVMF48=380965483=79333273=73:50:95272=2014061037=80531932942289=8290=12
10:27:35.089: 657643 - 81 - 1128=935=X34=65764352=20140610-13:27:35.09675=20140610268=1279=0269=022=8207=BVMF48=380965483=79334270=8.2273=73:50:96271=900272=2014061037016=2014061037017=73:50:9637=80531939385288=3290=13
10:27:35.091: 657644 - 71 - 1128=935=X34=65764452=20140610-13:27:35.09975=20140610268=1279=2269=022=8207=BVMF48=380965483=79335273=73:50:98272=2014061037=80531938988288=40290=4
10:27:35.094: 657645 - 71 - 1128=935=X34=65764552=20140610-13:27:35.10275=20140610268=1279=2269=122=8207=BVMF48=380965483=79336273=73:51:02272=2014061037=80531932527289=8290=39
10:27:35.094: 657646 - 70 - 1128=935=X34=65764652=20140610-13:27:35.10275=20140610268=1279=2269=022=8207=BVMF48=380965483=79337273=73:51:02272=2014061037=80531932766288=8290=63
10:27:35.094: 657647 - 71 - 1128=935=X34=65764752=20140610-13:27:35.10275=20140610268=1279=2269=122=8207=BVMF48=380965483=79338273=73:51:02272=2014061037=80531932526289=8290=50
10:27:35.095: 657648 - 70 - 1128=935=X34=65764852=20140610-13:27:35.10275=20140610268=1279=2269=022=8207=BVMF48=380965483=79339273=73:51:02272=2014061037=80531932529288=8290=69
10:27:35.095: 657649 - 81 - 1128=935=X34=65764952=20140610-13:27:35.10375=20140610268=1279=0269=022=8207=BVMF48=380965483=79340270=8.2273=73:51:02271=800272=2014061037016=2014061037017=73:51:0237=80531939431288=8290=13
10:27:35.095: 657650 - 70 - 1128=935=X34=65765052=20140610-13:27:35.10375=20140610268=1279=2269=022=8207=BVMF48=380965483=79341273=73:51:02272=2014061037=80531932528288=8290=46
10:27:35.095: 657651 - 80 - 1128=935=X34=65765152=20140610-13:27:35.10375=20140610268=1279=0269=022=8207=BVMF48=380965483=79342270=8.17273=73:51:02271=900272=2014061037016=2014061037017=73:51:0237=80531939432288=3290=42
10:27:35.096: 657652 - 83 - 1128=935=X34=65765252=20140610-13:27:35.10475=20140610268=1279=0269=122=8207=BVMF48=380965483=79343270=8.3273=73:51:04271=8900272=2014061037016=2014061037017=73:51:0437=80531939444289=8290=46
10:27:35.097: 657653 - 82 - 1128=935=X34=65765352=20140610-13:27:35.10575=20140610268=1279=0269=122=8207=BVMF48=380965483=79344270=8.28273=73:51:04271=10800272=2014061037016=2014061037017=73:51:0437=80531939446289=8290=35
10:27:35.097: 657654 - 80 - 1128=935=X34=65765452=20140610-13:27:35.10575=20140610268=1279=0269=022=8207=BVMF48=380965483=79345270=8.19273=73:51:05271=6100272=2014061037016=2014061037017=73:51:0537=80531939448288=8290=21
10:27:35.097: 657655 - 81 - 1128=935=X34=65765552=20140610-13:27:35.10575=20140610268=1279=0269=022=8207=BVMF48=380965483=79346270=8.17273=73:51:05271=8700272=2014061037016=2014061037017=73:51:0537=80531939451288=8290=44
10:27:35.119: 657656 - 153 - 1128=935=X34=65765652=20140610-13:27:35.12775=20140610268=3279=0269=222=8207=BVMF48=380965483=79347270=8.24273=73:51:26271=200272=2014061037016=2014061037017=73:51:261500=E451=-0.041020=194300274=01003=2750288=40289=3279=0269=922=8207=BVMF48=380965483=79348270=8.254273=73:51:26272=201406101500=E279=1269=122=8207=BVMF48=380965483=79349270=8.24273=73:51:26271=100272=2014061037016=2014061037017=34:44:0737=80531926244289=3290=1
10:27:35.146: 657657 - 80 - 1128=935=X34=65765752=20140610-13:27:35.15475=20140610268=1279=0269=022=8207=BVMF48=380965483=79350270=8.21273=73:51:53271=900272=2014061037016=2014061037017=73:51:5337=80531939459288=3290=9
