10:29:39.262: 659028 - 82 - 1128=935=X34=65902852=20140610-13:29:39.27575=20140610268=1279=0269=022=8207=BVMF48=380963983=256050270=26.3273=93:92:75271=3000272=2014061037016=2014061037017=93:92:7537=80531945945288=45290=85
10:29:39.909: 659029 - 197 - 1128=935=X34=65902952=20140610-13:29:39.92275=20140610268=4279=0269=222=8207=BVMF48=380963983=256051270=26.41273=93:99:21271=200272=2014061037016=2014061037017=93:99:211500=E451=-0.21020=1441400274=1277=L1003=19370288=77289=3279=0269=922=8207=BVMF48=380963983=256052270=26.468273=93:99:21272=201406101500=E279=1269=122=8207=BVMF48=380963983=256053270=26.41273=93:99:21271=500272=2014061037016=2014061037017=90:51:6937=80531944090289=3290=1279=2269=022=8207=BVMF48=380963983=256054273=93:99:21272=2014061037=80531945825288=77290=4
10:29:39.910: 659030 - 197 - 1128=935=X34=65903052=20140610-13:29:39.92375=20140610268=4279=0269=222=8207=BVMF48=380963983=256055270=26.41273=93:99:23271=100272=2014061037016=2014061037017=93:99:221500=E451=-0.21020=1441500274=1277=L1003=19380288=77289=3279=0269=922=8207=BVMF48=380963983=256056270=26.468273=93:99:23272=201406101500=E279=1269=122=8207=BVMF48=380963983=256057270=26.41273=93:99:23271=400272=2014061037016=2014061037017=90:51:6937=80531944090289=3290=1279=2269=022=8207=BVMF48=380963983=256058273=93:99:23272=2014061037=80531945844288=77290=4
10:29:39.911: 659031 - 246 - 1128=935=X34=65903152=20140610-13:29:39.92475=20140610268=6279=0269=222=8207=BVMF48=380963983=256059270=26.41273=93:99:24271=400272=2014061037016=2014061037017=93:99:241500=E451=-0.21020=1441900274=1277=L1003=19390288=77289=3279=0269=922=8207=BVMF48=380963983=256060270=26.468273=93:99:24272=201406101500=E279=0269=222=8207=BVMF48=380963983=256061270=26.41273=93:99:24271=500272=2014061037016=2014061037017=93:99:241500=E451=-0.21020=1442400274=1277=L1003=19400288=77289=40279=0269=922=8207=BVMF48=380963983=256062270=26.468273=93:99:24272=201406101500=E279=2269=022=8207=BVMF48=380963983=256063273=93:99:24272=2014061037=80531945852288=77290=4279=4269=122=8207=BVMF48=380963983=256064273=93:99:24272=20140610290=2
10:29:39.913: 659032 - 234 - 1128=935=X34=65903252=20140610-13:29:39.92675=20140610268=5279=0269=222=8207=BVMF48=380963983=256065270=26.41273=93:99:25271=500272=2014061037016=2014061037017=93:99:251500=E451=-0.21020=1442900274=1277=L1003=19410288=77289=45279=0269=922=8207=BVMF48=380963983=256066270=26.468273=93:99:25272=201406101500=E279=2269=022=8207=BVMF48=380963983=256067273=93:99:25272=2014061037=80531945858288=77290=4279=2269=122=8207=BVMF48=380963983=256068273=93:99:25272=2014061037=80531945934289=45290=1279=0269=022=8207=BVMF48=380963983=256069270=26.41273=93:99:25271=1200272=2014061037016=2014061037017=93:99:2537=80531945955288=77290=1
10:29:39.913: 659033 - 72 - 1128=935=X34=65903352=20140610-13:29:39.92675=20140610268=1279=2269=122=8207=BVMF48=380968883=253507273=93:99:26272=2014061037=80531945921289=45290=33
10:29:39.914: 659034 - 118 - 1128=935=X34=65903452=20140610-13:29:39.92775=20140610268=2279=2269=022=8207=BVMF48=380963983=256070273=93:99:27272=2014061037=80531945869288=77290=5279=0269=022=8207=BVMF48=380963983=256071270=26.41273=93:99:27271=300272=2014061037016=2014061037017=93:99:2737=80531945960288=77290=2
10:29:39.916: 659035 - 195 - 1128=935=X34=65903552=20140610-13:29:39.93075=20140610268=4279=0269=222=8207=BVMF48=380968883=253508270=29.39273=93:99:29271=200272=2014061037016=2014061037017=93:99:291500=E451=-0.241020=449300274=1277=L1003=6530288=3289=45279=0269=922=8207=BVMF48=380968883=253509270=29.478273=93:99:29272=201406101500=E279=1269=122=8207=BVMF48=380968883=253510270=29.39273=93:99:29271=1500272=2014061037016=2014061037017=84:11:9337=80531942856289=45290=1279=2269=022=8207=BVMF48=380968883=253511273=93:99:29272=2014061037=80531945823288=3290=6
10:29:39.917: 659036 - 118 - 1128=935=X34=65903652=20140610-13:29:39.93075=20140610268=2279=2269=022=8207=BVMF48=380963983=256072273=93:99:30272=2014061037=80531945871288=77290=6279=0269=022=8207=BVMF48=380963983=256073270=26.41273=93:99:30271=300272=2014061037016=2014061037017=93:99:2937=80531945966288=77290=3
10:29:39.921: 659037 - 119 - 1128=935=X34=65903752=20140610-13:29:39.93575=20140610268=2279=2269=022=8207=BVMF48=400223483=5875273=93:99:34272=2014061037=80531941839288=110290=2279=0269=022=8207=BVMF48=400223483=5876270=26.4273=93:99:34271=35272=2014061037016=2014061037017=93:99:3437=80531945978288=110290=1
10:29:39.921: 659038 - 156 - 1128=935=X34=65903852=20140610-13:29:39.93575=20140610268=3279=0269=222=8207=BVMF48=380968883=253512270=29.39273=93:99:34271=500272=2014061037016=2014061037017=93:99:341500=E451=-0.241020=449800274=1277=L1003=6540288=3289=45279=0269=922=8207=BVMF48=380968883=253513270=29.478273=93:99:34272=201406101500=E279=1269=122=8207=BVMF48=380968883=253514270=29.39273=93:99:34271=1000272=2014061037016=2014061037017=84:11:9337=80531942856289=45290=1
10:29:39.922: 659039 - 118 - 1128=935=X34=65903952=20140610-13:29:39.93575=20140610268=2279=2269=022=8207=BVMF48=380963983=256074273=93:99:35272=2014061037=80531945878288=77290=7279=0269=022=8207=BVMF48=380963983=256075270=26.41273=93:99:35271=400272=2014061037016=2014061037017=93:99:3537=80531945981288=77290=4
10:29:39.923: 659040 - 71 - 1128=935=X34=65904052=20140610-13:29:39.93675=20140610268=1279=2269=022=8207=BVMF48=380963983=256076273=93:99:35272=2014061037=80531945909288=40290=6
10:29:39.923: 659041 - 118 - 1128=935=X34=65904152=20140610-13:29:39.93775=20140610268=2279=2269=022=8207=BVMF48=380963983=256077273=93:99:37272=2014061037=80531945885288=77290=7279=0269=022=8207=BVMF48=380963983=256078270=26.41273=93:99:37271=100272=2014061037016=2014061037017=93:99:3737=80531945987288=77290=5
10:29:39.925: 659042 - 159 - 1128=935=X34=65904252=20140610-13:29:39.93875=20140610268=3279=0269=222=8207=BVMF48=380963983=256079270=26.41273=93:99:38271=500272=2014061037016=2014061037017=93:99:371500=E451=-0.21020=1443400274=1277=L1003=19420288=77289=45279=0269=922=8207=BVMF48=380963983=256080270=26.468273=93:99:38272=201406101500=E279=1269=022=8207=BVMF48=380963983=256081270=26.41273=93:99:38271=700272=2014061037016=2014061037017=93:99:2537=80531945955288=77290=1
10:29:39.925: 659043 - 118 - 1128=935=X34=65904352=20140610-13:29:39.93875=20140610268=2279=2269=022=8207=BVMF48=380963983=256082273=93:99:38272=2014061037=80531945753288=40290=6279=0269=022=8207=BVMF48=380963983=256083270=26.41273=93:99:38271=100272=2014061037016=2014061037017=93:99:3837=80531945989288=40290=6
10:29:39.927: 659044 - 118 - 1128=935=X34=65904452=20140610-13:29:39.94075=20140610268=2279=2269=022=8207=BVMF48=380963983=256084273=93:99:39272=2014061037=80531945887288=77290=8279=0269=022=8207=BVMF48=380963983=256085270=26.41273=93:99:39271=200272=2014061037016=2014061037017=93:99:3937=80531945990288=77290=7
10:29:39.928: 659045 - 80 - 1128=935=X34=65904552=20140610-13:29:39.94075=20140610268=1279=0269=022=8207=BVMF48=380963983=256086270=26.37273=93:99:40271=300272=2014061037016=2014061037017=93:99:3937=80531945991288=8290=26
10:29:39.928: 659046 - 80 - 1128=935=X34=65904652=20140610-13:29:39.94075=20140610268=1279=0269=022=8207=BVMF48=380963983=256087270=26.36273=93:99:40271=300272=2014061037016=2014061037017=93:99:4037=80531945993288=8290=36
10:29:39.934: 659047 - 81 - 1128=935=X34=65904752=20140610-13:29:39.94875=20140610268=1279=1269=022=8207=BVMF48=380963983=256088270=26.4273=93:99:47271=300272=2014061037016=2014061037017=93:79:0237=80531946015288=45290=8
10:29:39.937: 659048 - 81 - 1128=935=X34=65904852=20140610-13:29:39.95175=20140610268=1279=0269=022=8207=BVMF48=380963983=256089270=26.41273=93:99:50271=700272=2014061037016=2014061037017=93:99:5037=80531946020288=40290=8
10:29:39.939: 659049 - 118 - 1128=935=X34=65904952=20140610-13:29:39.95275=20140610268=2279=2269=022=8207=BVMF48=380968883=253515273=93:99:52272=2014061037=80531942060288=45290=26279=0269=022=8207=BVMF48=380968883=253516270=29.36273=93:99:52271=2000272=2014061037016=2014061037017=93:99:5137=80531946022288=45290=11
10:29:39.939: 659050 - 80 - 1128=935=X34=65905052=20140610-13:29:39.95275=20140610268=1279=0269=022=8207=BVMF48=380968883=253517270=29.38273=93:99:52271=100272=2014061037016=2014061037017=93:99:5237=80531946023288=3290=6
10:29:39.941: 659051 - 71 - 1128=935=X34=65905152=20140610-13:29:39.95475=20140610268=1279=2269=022=8207=BVMF48=380963983=256090273=93:99:54272=2014061037=80531945989288=40290=6
10:29:39.942: 659052 - 80 - 1128=935=X34=65905252=20140610-13:29:39.95575=20140610268=1279=0269=022=8207=BVMF48=380968883=253518270=29.37273=93:99:55271=100272=2014061037016=2014061037017=93:99:5537=80531946027288=3290=10
10:29:39.943: 659053 - 72 - 1128=935=X34=65905352=20140610-13:29:39.95775=20140610268=1279=2269=022=8207=BVMF48=380968883=253519273=93:99:56272=2014061037=80531945884288=227290=17
10:29:39.946: 659054 - 119 - 1128=935=X34=65905452=20140610-13:29:39.96075=20140610268=2279=2269=022=8207=BVMF48=380963983=256091273=93:99:59272=2014061037=80531945936288=45290=74279=0269=022=8207=BVMF48=380963983=256092270=26.4273=93:99:59271=5000272=2014061037016=2014061037017=93:99:5937=80531946035288=45290=10
10:29:39.946: 659055 - 72 - 1128=935=X34=65905552=20140610-13:29:39.96075=20140610268=1279=2269=122=8207=BVMF48=380963983=256093273=93:99:59272=2014061037=80531942851289=45290=4
10:29:39.947: 659056 - 119 - 1128=935=X34=65905652=20140610-13:29:39.96175=20140610268=2279=2269=022=8207=BVMF48=380963983=256094273=93:99:60272=2014061037=80531945870288=59290=17279=0269=022=8207=BVMF48=380963983=256095270=26.4273=93:99:60271=800272=2014061037016=2014061037017=93:99:6037=80531946040288=59290=11
10:29:39.947: 659057 - 72 - 1128=935=X34=65905752=20140610-13:29:39.96175=20140610268=1279=2269=122=8207=BVMF48=380963983=256096273=93:99:60272=2014061037=80531945941289=45290=4
10:29:39.948: 659058 - 81 - 1128=935=X34=65905852=20140610-13:29:39.96175=20140610268=1279=0269=122=8207=BVMF48=380963983=256097270=26.42273=93:99:61271=100272=2014061037016=2014061037017=93:99:6037=80531946043289=8290=3
10:29:39.948: 659059 - 119 - 1128=935=X34=65905952=20140610-13:29:39.96175=20140610268=2279=2269=022=8207=BVMF48=380963983=256098273=93:99:61272=2014061037=80531945945288=45290=83279=0269=022=8207=BVMF48=380963983=256099270=26.4273=93:99:61271=3000272=2014061037016=2014061037017=93:99:6137=80531946045288=45290=12
10:29:39.948: 659060 - 71 - 1128=935=X34=65906052=20140610-13:29:39.96275=20140610268=1279=2269=122=8207=BVMF48=380963983=256100273=93:99:61272=2014061037=80531946043289=8290=3
10:29:39.952: 659061 - 270 - 1128=935=X34=65906152=20140610-13:29:39.96575=20140610268=6279=0269=222=8207=BVMF48=380963983=256101270=26.41273=93:99:65271=700272=2014061037016=2014061037017=93:99:641500=E451=-0.21020=1444100274=1277=L1003=19430288=77289=40279=0269=922=8207=BVMF48=380963983=256102270=26.468273=93:99:65272=201406101500=E279=0269=222=8207=BVMF48=380963983=256103270=26.41273=93:99:65271=100272=2014061037016=2014061037017=93:99:641500=E451=-0.21020=1444200274=1277=L1003=19440288=77289=40279=0269=922=8207=BVMF48=380963983=256104270=26.468273=93:99:65272=201406101500=E279=2269=022=8207=BVMF48=380963983=256105273=93:99:65272=2014061037=80531945955288=77290=1279=1269=022=8207=BVMF48=380963983=256106270=26.41273=93:99:65271=200272=2014061037016=2014061037017=93:99:2737=80531945960288=77290=1
10:29:39.953: 659062 - 82 - 1128=935=X34=65906252=20140610-13:29:39.96675=20140610268=1279=0269=122=8207=BVMF48=380963983=256107270=26.42273=93:99:66271=200272=2014061037016=2014061037017=93:99:6637=80531946053289=40290=3
10:29:39.954: 659063 - 80 - 1128=935=X34=65906352=20140610-13:29:39.96775=20140610268=1279=0269=022=8207=BVMF48=380968883=253520270=29.36273=93:99:67271=100272=2014061037016=2014061037017=93:99:6637=80531946056288=3290=14
10:29:39.954: 659064 - 82 - 1128=935=X34=65906452=20140610-13:29:39.96775=20140610268=1279=0269=122=8207=BVMF48=380963983=256108270=26.42273=93:99:67271=2500272=2014061037016=2014061037017=93:99:6737=80531946057289=45290=4
10:29:39.959: 659065 - 80 - 1128=935=X34=65906552=20140610-13:29:39.97275=20140610268=1279=0269=022=8207=BVMF48=380968883=253521270=29.35273=93:99:72271=100272=2014061037016=2014061037017=93:99:7137=80531946065288=3290=19
10:29:39.960: 659066 - 118 - 1128=935=X34=65906652=20140610-13:29:39.97275=20140610268=2279=2269=022=8207=BVMF48=380963983=256109273=93:99:72272=2014061037=80531946015288=45290=7279=0269=022=8207=BVMF48=380963983=256110270=26.41273=93:99:72271=700272=2014061037016=2014061037017=93:99:7137=80531946066288=45290=7
10:29:39.960: 659067 - 82 - 1128=935=X34=65906752=20140610-13:29:39.97475=20140610268=1279=0269=022=8207=BVMF48=380968883=253522270=29.36273=93:99:74271=800272=2014061037016=2014061037017=93:99:7337=80531946074288=227290=15
10:29:39.966: 659068 - 81 - 1128=935=X34=65906852=20140610-13:29:39.98075=20140610268=1279=0269=022=8207=BVMF48=380963983=256111270=26.41273=93:99:79271=100272=2014061037016=2014061037017=93:99:7937=80531946084288=40290=8
10:29:39.984: 659069 - 82 - 1128=935=X34=65906952=20140610-13:29:39.99775=20140610268=1279=0269=122=8207=BVMF48=380963983=256112270=26.42273=93:99:97271=900272=2014061037016=2014061037017=93:99:9737=80531946092289=40290=5
10:29:40.048: 659070 - 193 - 1128=935=X34=65907052=20140610-13:29:40.06275=20140610268=4279=0269=222=8207=BVMF48=380965483=79795270=8.18273=94:00:61271=1000272=2014061037016=2014061037017=94:00:601500=E451=-0.11020=295000274=21003=3460288=77289=3279=0269=922=8207=BVMF48=380965483=79796270=8.237273=94:00:61272=201406101500=E279=1269=022=8207=BVMF48=380965483=79797270=8.18273=94:00:61271=6500272=2014061037016=2014061037017=50:71:7737=80531856537288=77290=1279=2269=122=8207=BVMF48=380965483=79798273=94:00:61272=2014061037=80531942608289=3290=10
10:29:40.053: 659071 - 82 - 1128=935=X34=65907152=20140610-13:29:40.06775=20140610268=1279=0269=122=8207=BVMF48=380965483=79799270=8.2273=94:00:66271=900272=2014061037016=2014061037017=94:00:6637=80531946105289=3290=4
10:29:40.061: 659072 - 80 - 1128=935=X34=65907252=20140610-13:29:40.07475=20140610268=1279=1269=122=8207=BVMF48=380963983=256113270=26.42273=94:00:74271=1800272=2014061037016=2014061037017=93:79:5637=80531946106289=8290=2
10:29:40.113: 659073 - 82 - 1128=935=X34=65907352=20140610-13:29:40.12775=20140610268=1279=0269=122=8207=BVMF48=380968883=253523270=29.49273=94:01:26271=2000272=2014061037016=2014061037017=94:01:2637=80531946107289=45290=34
10:29:40.147: 659074 - 82 - 1128=935=X34=65907452=20140610-13:29:40.16175=20140610268=1279=0269=122=8207=BVMF48=380963983=256114270=26.52273=94:01:60271=5000272=2014061037016=2014061037017=94:01:6037=80531946108289=45290=56
10:29:40.148: 659075 - 82 - 1128=935=X34=65907552=20140610-13:29:40.16275=20140610268=1279=0269=122=8207=BVMF48=380963983=256115270=26.53273=94:01:61271=3000272=2014061037016=2014061037017=94:01:6137=80531946109289=45290=58
10:29:40.164: 659076 - 81 - 1128=935=X34=65907652=20140610-13:29:40.17775=20140610268=1279=0269=122=8207=BVMF48=380963983=256116270=26.43273=94:01:77271=100272=2014061037016=2014061037017=94:01:7737=80531946110289=8290=7
10:29:40.170: 659077 - 80 - 1128=935=X34=65907752=20140610-13:29:40.18475=20140610268=1279=0269=022=8207=BVMF48=380968883=253524270=29.37273=94:01:83271=1000272=2014061037016=2014061037017=94:01:8337=80531946111288=8290=11
10:29:40.666: 659078 - 80 - 1128=935=X34=65907852=20140610-13:29:40.68075=20140610268=1279=0269=022=8207=BVMF48=380963983=256117270=26.35273=94:06:79271=1000272=2014061037016=2014061037017=94:06:7937=80531946114288=3290=46
10:29:40.671: 659079 - 70 - 1128=935=X34=65907952=20140610-13:29:40.68475=20140610268=1279=2269=022=8207=BVMF48=380963983=256118273=94:06:84272=2014061037=80531942588288=8290=55
10:29:40.671: 659080 - 80 - 1128=935=X34=65908052=20140610-13:29:40.68475=20140610268=1279=0269=022=8207=BVMF48=380963983=256119270=26.38273=94:06:84271=300272=2014061037016=2014061037017=94:06:8437=80531946115288=8290=23
10:29:40.878: 659081 - 81 - 1128=935=X34=65908152=20140610-13:29:40.89275=20140610268=1279=0269=022=8207=BVMF48=380391383=106230270=13.84273=94:08:91271=200272=2014061037016=2014061037017=94:08:9137=80531946117288=40290=3
10:29:40.884: 659082 - 81 - 1128=935=X34=65908252=20140610-13:29:40.89875=20140610268=1279=0269=022=8207=BVMF48=380963983=256120270=26.41273=94:08:97271=200272=2014061037016=2014061037017=94:08:9737=80531946118288=40290=9
10:29:40.896: 659083 - 81 - 1128=935=X34=65908352=20140610-13:29:40.90975=20140610268=1279=0269=022=8207=BVMF48=380965483=79800270=8.18273=94:09:09271=200272=2014061037016=2014061037017=94:09:0837=80531946119288=40290=12
10:29:40.898: 659084 - 81 - 1128=935=X34=65908452=20140610-13:29:40.91175=20140610268=1279=0269=022=8207=BVMF48=380249383=103527270=9.34273=94:09:11271=100272=2014061037016=2014061037017=94:09:1137=80531946120288=40290=6
10:29:41.081: 659085 - 82 - 1128=935=X34=65908552=20140610-13:29:41.09475=20140610268=1279=0269=122=8207=BVMF48=380965483=79801270=8.2273=94:10:94271=200272=2014061037016=2014061037017=94:10:9437=80531946121289=3290=5
10:29:41.316: 659086 - 84 - 1128=935=X34=65908652=20140610-13:29:41.33075=20140610268=1279=0269=122=8207=BVMF48=380249383=103528270=9.5273=94:13:29271=300272=2014061037016=2014061037017=94:13:2937=80531946124289=131290=73
10:29:41.561: 659087 - 81 - 1128=935=X34=65908752=20140610-13:29:41.57575=20140610268=1279=0269=122=8207=BVMF48=386391783=2510270=9.31273=94:15:74271=40272=2014061037016=2014061037017=94:15:7437=80531946126289=114290=1
10:29:41.563: 659088 - 166 - 1128=935=X34=65908852=20140610-13:29:41.57675=20140610268=4279=0269=222=8207=BVMF48=386391783=2511270=9.31273=94:15:76271=40272=2014061037016=2014061037017=94:15:751500=E451=-0.141020=271274=21003=70288=110289=114279=0269=822=8207=BVMF48=386391783=2512270=9.31273=94:15:76272=201406101500=E279=0269=922=8207=BVMF48=386391783=2513270=9.411273=94:15:76272=201406101500=E279=2269=122=8207=BVMF48=386391783=2514273=94:15:76272=2014061037=80531946126289=114290=1
10:29:41.567: 659089 - 80 - 1128=935=X34=65908952=20140610-13:29:41.58075=20140610268=1279=0269=022=8207=BVMF48=386391783=2515270=9.31273=94:15:80271=40272=2014061037016=2014061037017=94:15:8037=80531946128288=110290=1
10:29:41.652: 659090 - 147 - 1128=935=X34=65909052=20140610-13:29:41.66575=20140610268=3279=0269=222=8207=BVMF48=380249383=103529270=9.34273=94:16:65271=100272=2014061037016=2014061037017=94:16:641500=E451=-0.111020=261600274=3277=L1003=3740288=40289=114279=0269=922=8207=BVMF48=380249383=103530270=9.381273=94:16:65272=201406101500=E279=2269=022=8207=BVMF48=380249383=103531273=94:16:65272=2014061037=80531942768288=40290=1
10:29:41.716: 659091 - 158 - 1128=935=X34=65909152=20140610-13:29:41.72975=20140610268=3279=0269=222=8207=BVMF48=380968883=253525270=29.39273=94:17:28271=200272=2014061037016=2014061037017=94:17:281500=E451=-0.241020=450000274=1277=L1003=6550288=227289=45279=0269=922=8207=BVMF48=380968883=253526270=29.478273=94:17:28272=201406101500=E279=1269=122=8207=BVMF48=380968883=253527270=29.39273=94:17:28271=800272=2014061037016=2014061037017=84:11:9337=80531942856289=45290=1
10:29:41.733: 659092 - 80 - 1128=935=X34=65909252=20140610-13:29:41.74775=20140610268=1279=1269=122=8207=BVMF48=380963983=256121270=26.42273=94:17:46271=1600272=2014061037016=2014061037017=93:79:5637=80531946132289=8290=2
10:29:41.739: 659093 - 70 - 1128=935=X34=65909352=20140610-13:29:41.75275=20140610268=1279=2269=022=8207=BVMF48=380963983=256122273=94:17:52272=2014061037=80531942593288=8290=63
10:29:41.739: 659094 - 80 - 1128=935=X34=65909452=20140610-13:29:41.75275=20140610268=1279=0269=022=8207=BVMF48=380963983=256123270=26.37273=94:17:52271=300272=2014061037016=2014061037017=94:17:5237=80531946133288=8290=31
10:29:41.803: 659095 - 118 - 1128=935=X34=65909552=20140610-13:29:41.81675=20140610268=2279=2269=022=8207=BVMF48=380963983=256124273=94:18:15272=2014061037=80531942747288=40290=58279=0269=022=8207=BVMF48=380963983=256125270=26.36273=94:18:15271=100272=2014061037016=2014061037017=94:18:1537=80531946134288=40290=42
10:29:41.841: 659096 - 185 - 1128=935=X34=65909652=20140610-13:29:41.85575=20140610268=4279=0269=222=8207=BVMF48=380249383=103532270=9.34273=94:18:54271=100272=2014061037016=2014061037017=94:18:541500=E451=-0.111020=261700274=3277=L1003=3750288=40289=735279=0269=922=8207=BVMF48=380249383=103533270=9.381273=94:18:54272=201406101500=E279=2269=022=8207=BVMF48=380249383=103534273=94:18:54272=2014061037=80531942936288=40290=1279=2269=122=8207=BVMF48=380249383=103535273=94:18:54272=2014061037=80531943928289=735290=7
10:29:41.853: 659097 - 83 - 1128=935=X34=65909752=20140610-13:29:41.86775=20140610268=1279=0269=122=8207=BVMF48=380249383=103536270=9.35273=94:18:67271=300272=2014061037016=2014061037017=94:18:6637=80531946137289=735290=9
10:29:42.035: 659098 - 82 - 1128=935=X34=65909852=20140610-13:29:42.04975=20140610268=1279=0269=122=8207=BVMF48=380963983=256126270=26.42273=94:20:48271=100272=2014061037016=2014061037017=94:20:4837=80531946139289=40290=6
10:29:42.126: 659099 - 65 - 1128=935=X34=65909952=20140610-13:29:42.14075=20140610268=1279=0269=B22=8207=BVMF48=380391383=106231270=1515402273=94:21:33271=341272=201406101500=E15=BRL
10:29:42.127: 659100 - 65 - 1128=935=X34=65910052=20140610-13:29:42.14075=20140610268=1279=0269=B22=8207=BVMF48=380963983=256127270=38225034273=94:21:33271=1944272=201406101500=E15=BRL
10:29:42.135: 659101 - 65 - 1128=935=X34=65910152=20140610-13:29:42.14975=20140610268=1279=0269=B22=8207=BVMF48=380249383=103537270=2455053273=94:21:33271=375272=201406101500=E15=BRL
10:29:42.183: 659102 - 65 - 1128=935=X34=65910252=20140610-13:29:42.19775=20140610268=1279=0269=B22=8207=BVMF48=380968883=253528270=13264976273=94:21:33271=655272=201406101500=E15=BRL
10:29:42.184: 659103 - 61 - 1128=935=X34=65910352=20140610-13:29:42.19775=20140610268=1279=0269=B22=8207=BVMF48=386391783=2516270=2550.45273=94:21:33271=7272=201406101500=E15=BRL
10:29:42.184: 659104 - 65 - 1128=935=X34=65910452=20140610-13:29:42.19875=20140610268=1279=0269=B22=8207=BVMF48=380965483=79802270=2429958273=94:21:33271=346272=201406101500=E15=BRL
10:29:42.281: 659105 - 82 - 1128=935=X34=65910552=20140610-13:29:42.29575=20140610268=1279=0269=122=8207=BVMF48=380963983=256128270=26.42273=94:22:94271=700272=2014061037016=2014061037017=94:22:9437=80531946142289=77290=7
10:29:42.326: 659106 - 117 - 1128=935=X34=65910652=20140610-13:29:42.34075=20140610268=2279=2269=022=8207=BVMF48=386391783=2517273=94:23:39272=2014061037=80531901734288=63290=2279=0269=022=8207=BVMF48=386391783=2518270=9.32273=94:23:39271=98272=2014061037016=2014061037017=94:23:3937=80531946143288=63290=1
10:29:42.428: 659107 - 119 - 1128=935=X34=65910752=20140610-13:29:42.44175=20140610268=2279=2269=122=8207=BVMF48=386391783=2519273=94:24:40272=2014061037=80531942746289=110290=1279=0269=122=8207=BVMF48=386391783=2520270=9.36273=94:24:40271=44272=2014061037016=2014061037017=94:24:4037=80531946144289=110290=1
10:29:42.595: 659108 - 84 - 1128=935=X34=65910852=20140610-13:29:42.60875=20140610268=1279=0269=122=8207=BVMF48=380965483=79803270=8.3273=94:26:07271=5000272=2014061037016=2014061037017=94:26:0737=80531946145289=129290=58
10:29:43.329: 659109 - 122 - 1128=935=X34=65910952=20140610-13:29:43.34375=20140610268=2279=2269=122=8207=BVMF48=380249383=103538273=94:33:42272=2014061037=80531881981289=147290=71279=0269=122=8207=BVMF48=380249383=103539270=9.5273=94:33:42271=6000272=2014061037016=2014061037017=94:33:4237=80531946157289=147290=73
10:29:43.502: 659110 - 71 - 1128=935=X34=65911052=20140610-13:29:43.51675=20140610268=1279=2269=022=8207=BVMF48=386391783=2521273=94:35:16272=2014061037=80531946128288=110290=2
10:29:43.587: 659111 - 145 - 1128=935=X34=65911152=20140610-13:29:43.60175=20140610268=3279=0269=222=8207=BVMF48=380963983=256129270=26.42273=94:36:00271=100272=2014061037016=2014061037017=94:36:001500=E451=-0.191020=1444300274=01003=19450288=3289=3279=0269=922=8207=BVMF48=380963983=256130270=26.468273=94:36:00272=201406101500=E279=2269=122=8207=BVMF48=380963983=256131273=94:36:00272=2014061037=80531941011289=3290=1
10:29:43.677: 659112 - 81 - 1128=935=X34=65911252=20140610-13:29:43.69075=20140610268=1279=0269=022=8207=BVMF48=380968883=253529270=29.29273=94:36:90271=6000272=2014061037016=2014061037017=94:36:9037=80531946160288=16290=43
10:29:43.683: 659113 - 82 - 1128=935=X34=65911352=20140610-13:29:43.69775=20140610268=1279=0269=122=8207=BVMF48=380968883=253530270=29.48273=94:36:96271=3400272=2014061037016=2014061037017=94:36:9637=80531946161289=16290=33
10:29:43.687: 659114 - 71 - 1128=935=X34=65911452=20140610-13:29:43.70175=20140610268=1279=2269=122=8207=BVMF48=380968883=253531273=94:37:01272=2014061037=80531938534289=3290=8
10:29:44.336: 659115 - 156 - 1128=935=X34=65911552=20140610-13:29:44.35075=20140610268=3279=0269=222=8207=BVMF48=380963983=256132270=26.42273=94:43:49271=100272=2014061037016=2014061037017=94:43:491500=E451=-0.191020=1444400274=1277=L1003=19460288=3289=8279=0269=922=8207=BVMF48=380963983=256133270=26.468273=94:43:49272=201406101500=E279=1269=122=8207=BVMF48=380963983=256134270=26.42273=94:43:49271=1500272=2014061037016=2014061037017=93:79:5637=80531946132289=8290=1
10:29:44.356: 659116 - 156 - 1128=935=X34=65911652=20140610-13:29:44.37075=20140610268=3279=0269=222=8207=BVMF48=380968883=253532270=29.39273=94:43:69271=100272=2014061037016=2014061037017=94:43:691500=E451=-0.241020=450100274=1277=L1003=6560288=8289=45279=0269=922=8207=BVMF48=380968883=253533270=29.478273=94:43:69272=201406101500=E279=1269=122=8207=BVMF48=380968883=253534270=29.39273=94:43:69271=700272=2014061037016=2014061037017=84:11:9337=80531942856289=45290=1
10:29:44.364: 659117 - 71 - 1128=935=X34=65911752=20140610-13:29:44.37875=20140610268=1279=2269=122=8207=BVMF48=380963983=256135273=94:43:77272=2014061037=80531946132289=8290=1
10:29:44.378: 659118 - 81 - 1128=935=X34=65911852=20140610-13:29:44.39175=20140610268=1279=1269=122=8207=BVMF48=380963983=256136270=26.42273=94:43:90271=1200272=2014061037016=2014061037017=93:99:6737=80531946176289=45290=2
10:29:44.399: 659119 - 117 - 1128=935=X34=65911952=20140610-13:29:44.41275=20140610268=2279=2269=022=8207=BVMF48=386391783=2522273=94:44:12272=2014061037=80531946143288=63290=1279=0269=022=8207=BVMF48=386391783=2523270=9.28273=94:44:12271=98272=2014061037016=2014061037017=94:44:1237=80531946178288=63290=1
10:29:44.440: 659120 - 81 - 1128=935=X34=65912052=20140610-13:29:44.45375=20140610268=1279=0269=122=8207=BVMF48=380653683=6237270=3.16273=94:44:53271=500272=2014061037016=2014061037017=94:44:5237=80531946179289=82290=17
10:29:44.984: 659121 - 81 - 1128=935=X34=65912152=20140610-13:29:44.99775=20140610268=1279=0269=022=8207=BVMF48=380963983=256137270=26.31273=94:49:96271=5000272=2014061037016=2014061037017=94:49:9637=80531946180288=45290=79
10:29:44.984: 659122 - 82 - 1128=935=X34=65912252=20140610-13:29:44.99775=20140610268=1279=0269=122=8207=BVMF48=380963983=256138270=26.53273=94:49:97271=5000272=2014061037016=2014061037017=94:49:9737=80531946181289=45290=60
10:29:45.298: 659123 - 157 - 1128=935=X34=65912352=20140610-13:29:45.31175=20140610268=3279=0269=222=8207=BVMF48=380968883=253535270=29.39273=94:53:11271=300272=2014061037016=2014061037017=94:53:101500=E451=-0.241020=450400274=1277=L1003=6570288=40289=45279=0269=922=8207=BVMF48=380968883=253536270=29.478273=94:53:11272=201406101500=E279=1269=122=8207=BVMF48=380968883=253537270=29.39273=94:53:11271=400272=2014061037016=2014061037017=84:11:9337=80531942856289=45290=1
10:29:45.300: 659124 - 71 - 1128=935=X34=65912452=20140610-13:29:45.31375=20140610268=1279=2269=122=8207=BVMF48=380968883=253538273=94:53:12272=2014061037=80531926578289=8290=7
10:29:45.300: 659125 - 365 - 1128=935=X34=65912552=20140610-13:29:45.31375=20140610268=9279=0269=222=8207=BVMF48=380968883=253539270=29.39273=94:53:13271=400272=2014061037016=2014061037017=94:53:121500=E451=-0.241020=450800274=1277=L1003=6580288=8289=45279=0269=922=8207=BVMF48=380968883=253540270=29.478273=94:53:13272=201406101500=E279=0269=222=8207=BVMF48=380968883=253541270=29.39273=94:53:13271=200272=2014061037016=2014061037017=94:53:121500=E451=-0.241020=451000274=1277=L1003=6590288=8289=77279=0269=922=8207=BVMF48=380968883=253542270=29.478273=94:53:13272=201406101500=E279=0269=222=8207=BVMF48=380968883=253543270=29.39273=94:53:13271=200272=2014061037016=2014061037017=94:53:121500=E451=-0.241020=451200274=1277=L1003=6600288=8289=77279=0269=922=8207=BVMF48=380968883=253544270=29.477273=94:53:13272=201406101500=E279=4269=122=8207=BVMF48=380968883=253545273=94:53:13272=20140610290=2279=1269=122=8207=BVMF48=380968883=253546270=29.39273=94:53:13271=100272=2014061037016=2014061037017=84:66:7037=80531942879289=77290=1279=0269=122=8207=BVMF48=380968883=253547270=29.39273=94:53:13271=5000272=2014061037016=2014061037017=94:53:1237=80531946186289=45290=4
10:29:45.301: 659126 - 80 - 1128=935=X34=65912652=20140610-13:29:45.31475=20140610268=1279=1269=022=8207=BVMF48=380968883=253548270=29.38273=94:53:14271=300272=2014061037016=2014061037017=92:72:0137=80531946187288=40290=4
10:29:45.302: 659127 - 81 - 1128=935=X34=65912752=20140610-13:29:45.31675=20140610268=1279=0269=022=8207=BVMF48=380391383=106232270=13.85273=94:53:15271=200272=2014061037016=2014061037017=94:53:1537=80531946188288=40290=1
10:29:45.307: 659128 - 81 - 1128=935=X34=65912852=20140610-13:29:45.32175=20140610268=1279=0269=022=8207=BVMF48=380963983=256139270=26.41273=94:53:20271=500272=2014061037016=2014061037017=94:53:2037=80531946189288=40290=10
10:29:45.310: 659129 - 81 - 1128=935=X34=65912952=20140610-13:29:45.32375=20140610268=1279=0269=022=8207=BVMF48=380968883=253549270=29.38273=94:53:23271=400272=2014061037016=2014061037017=94:53:2337=80531946195288=40290=7
10:29:45.311: 659130 - 81 - 1128=935=X34=65913052=20140610-13:29:45.32575=20140610268=1279=0269=022=8207=BVMF48=380394783=65793270=17.03273=94:53:24271=100272=2014061037016=2014061037017=94:53:2437=80531946196288=40290=3
10:29:45.311: 659131 - 81 - 1128=935=X34=65913152=20140610-13:29:45.32575=20140610268=1279=0269=022=8207=BVMF48=380249383=103540270=9.34273=94:53:24271=200272=2014061037016=2014061037017=94:53:2437=80531946197288=40290=5
10:29:45.312: 659132 - 71 - 1128=935=X34=65913252=20140610-13:29:45.32675=20140610268=1279=2269=122=8207=BVMF48=380394783=65794273=94:53:25272=2014061037=80531931296289=8290=1
10:29:45.315: 659133 - 81 - 1128=935=X34=65913352=20140610-13:29:45.32975=20140610268=1279=0269=022=8207=BVMF48=380965483=79804270=8.18273=94:53:29271=100272=2014061037016=2014061037017=94:53:2937=80531946198288=40290=13
10:29:45.317: 659134 - 70 - 1128=935=X34=65913452=20140610-13:29:45.33175=20140610268=1279=2269=022=8207=BVMF48=380968883=253550273=94:53:31272=2014061037=80531946023288=3290=6
10:29:45.323: 659135 - 80 - 1128=935=X34=65913552=20140610-13:29:45.33775=20140610268=1279=0269=022=8207=BVMF48=380968883=253551270=29.38273=94:53:36271=100272=2014061037016=2014061037017=94:53:3637=80531946202288=3290=7
10:29:45.325: 659136 - 118 - 1128=935=X34=65913652=20140610-13:29:45.33975=20140610268=2279=2269=022=8207=BVMF48=380391383=106233273=94:53:38272=2014061037=80531945264288=40290=3279=0269=022=8207=BVMF48=380391383=106234270=13.85273=94:53:38271=200272=2014061037016=2014061037017=94:53:3837=80531946203288=40290=2
10:29:45.326: 659137 - 71 - 1128=935=X34=65913752=20140610-13:29:45.34075=20140610268=1279=2269=022=8207=BVMF48=380391383=106235273=94:53:40272=2014061037=80531946117288=40290=4
10:29:45.336: 659138 - 146 - 1128=935=X34=65913852=20140610-13:29:45.35075=20140610268=3279=0269=222=8207=BVMF48=380968883=253552270=29.39273=94:53:49271=100272=2014061037016=2014061037017=94:53:491500=E451=-0.241020=451300274=1277=L1003=6610288=40289=77279=0269=922=8207=BVMF48=380968883=253553270=29.477273=94:53:49272=201406101500=E279=2269=122=8207=BVMF48=380968883=253554273=94:53:49272=2014061037=80531942879289=77290=1
10:29:45.344: 659139 - 82 - 1128=935=X34=65913952=20140610-13:29:45.35875=20140610268=1279=1269=122=8207=BVMF48=380391383=106236270=13.88273=94:53:57271=200272=2014061037016=2014061037017=92:97:1137=80531946210289=110290=16
10:29:45.382: 659140 - 81 - 1128=935=X34=65914052=20140610-13:29:45.39575=20140610268=1279=0269=122=8207=BVMF48=380963983=256140270=26.42273=94:53:95271=1500272=2014061037016=2014061037017=94:53:9537=80531946211289=8290=6
10:29:45.390: 659141 - 117 - 1128=935=X34=65914152=20140610-13:29:45.40475=20140610268=2279=2269=122=8207=BVMF48=380391383=106237273=94:54:03272=2014061037=80531943649289=3290=3279=0269=122=8207=BVMF48=380391383=106238270=13.87273=94:54:03271=1100272=2014061037016=2014061037017=94:54:0337=80531946212289=3290=11
10:29:45.405: 659142 - 81 - 1128=935=X34=65914252=20140610-13:29:45.41975=20140610268=1279=0269=122=8207=BVMF48=380963983=256141270=26.42273=94:54:18271=1000272=2014061037016=2014061037017=94:54:1837=80531946215289=8290=7
10:29:45.413: 659143 - 70 - 1128=935=X34=65914352=20140610-13:29:45.42775=20140610268=1279=2269=022=8207=BVMF48=380391383=106239273=94:54:27272=2014061037=80531945270288=8290=38
10:29:45.457: 659144 - 80 - 1128=935=X34=65914452=20140610-13:29:45.47175=20140610268=1279=0269=022=8207=BVMF48=380391383=106240270=13.78273=94:54:70271=600272=2014061037016=2014061037017=94:54:7037=80531946216288=8290=38
10:29:45.459: 659145 - 70 - 1128=935=X34=65914552=20140610-13:29:45.47275=20140610268=1279=2269=022=8207=BVMF48=380394783=65795273=94:54:72272=2014061037=80531942629288=8290=1
10:29:45.487: 659146 - 70 - 1128=935=X34=65914652=20140610-13:29:45.50175=20140610268=1279=2269=022=8207=BVMF48=380391383=106241273=94:55:00272=2014061037=80531946216288=8290=38
10:29:45.495: 659147 - 82 - 1128=935=X34=65914752=20140610-13:29:45.50775=20140610268=1279=0269=122=8207=BVMF48=380968883=253555270=29.39273=94:55:07271=200272=2014061037016=2014061037017=94:55:0737=80531946217289=77290=4
10:29:45.496: 659148 - 80 - 1128=935=X34=65914852=20140610-13:29:45.51075=20140610268=1279=0269=022=8207=BVMF48=380391383=106242270=13.78273=94:55:09271=200272=2014061037016=2014061037017=94:55:0937=80531946218288=8290=38
10:29:45.503: 659149 - 72 - 1128=935=X34=65914952=20140610-13:29:45.51775=20140610268=1279=2269=022=8207=BVMF48=380963983=256142273=94:55:16272=2014061037=80531941402288=72290=186
10:29:45.504: 659150 - 71 - 1128=935=X34=65915052=20140610-13:29:45.51775=20140610268=1279=2269=022=8207=BVMF48=380968883=253556273=94:55:17272=2014061037=80531941401288=72290=20
10:29:45.505: 659151 - 250 - 1128=935=X34=65915152=20140610-13:29:45.51875=20140610268=6279=0269=222=8207=BVMF48=380394783=65796270=17.04273=94:55:18271=100272=2014061037016=2014061037017=94:55:171500=E451=-0.121020=19100274=01003=1150288=8289=70279=0269=922=8207=BVMF48=380394783=65797270=17.099273=94:55:18272=201406101500=E279=0269=222=8207=BVMF48=380394783=65798270=17.04273=94:55:18271=100272=2014061037016=2014061037017=94:55:171500=E451=-0.121020=19200274=1277=L1003=1160288=8289=70279=0269=922=8207=BVMF48=380394783=65799270=17.099273=94:55:18272=201406101500=E279=4269=122=8207=BVMF48=380394783=65800273=94:55:18272=20140610290=2279=0269=022=8207=BVMF48=380394783=65801270=17.04273=94:55:18271=100272=2014061037016=2014061037017=94:55:1737=80531946219288=8290=1
10:29:45.516: 659152 - 118 - 1128=935=X34=65915252=20140610-13:29:45.53075=20140610268=2279=2269=022=8207=BVMF48=380394783=65802273=94:55:29272=2014061037=80531945267288=40290=2279=0269=022=8207=BVMF48=380394783=65803270=17.04273=94:55:29271=100272=2014061037016=2014061037017=94:55:2937=80531946220288=40290=2
10:29:45.518: 659153 - 118 - 1128=935=X34=65915352=20140610-13:29:45.53275=20140610268=2279=2269=022=8207=BVMF48=380394783=65804273=94:55:32272=2014061037=80531946196288=40290=3279=0269=022=8207=BVMF48=380394783=65805270=17.04273=94:55:32271=100272=2014061037016=2014061037017=94:55:3237=80531946221288=40290=3
10:29:45.521: 659154 - 80 - 1128=935=X34=65915452=20140610-13:29:45.53575=20140610268=1279=0269=022=8207=BVMF48=380394783=65806270=16.98273=94:55:34271=400272=2014061037016=2014061037017=94:55:3437=80531946222288=8290=11
10:29:45.535: 659155 - 70 - 1128=935=X34=65915552=20140610-13:29:45.54975=20140610268=1279=2269=022=8207=BVMF48=380391383=106243273=94:55:48272=2014061037=80531946218288=8290=38
10:29:45.547: 659156 - 80 - 1128=935=X34=65915652=20140610-13:29:45.56175=20140610268=1279=0269=022=8207=BVMF48=380391383=106244270=13.79273=94:55:60271=100272=2014061037016=2014061037017=94:55:6037=80531946223288=8290=33
10:29:45.554: 659157 - 70 - 1128=935=X34=65915752=20140610-13:29:45.56875=20140610268=1279=2269=022=8207=BVMF48=380391383=106245273=94:55:68272=2014061037=80531946223288=8290=33
10:29:45.562: 659158 - 80 - 1128=935=X34=65915852=20140610-13:29:45.57675=20140610268=1279=0269=022=8207=BVMF48=380391383=106246270=13.79273=94:55:75271=300272=2014061037016=2014061037017=94:55:7537=80531946224288=8290=33
10:29:45.579: 659159 - 121 - 1128=935=X34=65915952=20140610-13:29:45.59275=20140610268=2279=2269=122=8207=BVMF48=380391383=106247273=94:55:92272=2014061037=80531946210289=110290=16279=0269=122=8207=BVMF48=380391383=106248270=13.89273=94:55:92271=500272=2014061037016=2014061037017=94:55:9237=80531946225289=110290=21
10:29:45.584: 659160 - 73 - 1128=935=X34=65916052=20140610-13:29:45.59875=20140610268=1279=2269=122=8207=BVMF48=380391383=106249273=94:55:98272=2014061037=80531946225289=110290=21
10:29:45.590: 659161 - 71 - 1128=935=X34=65916152=20140610-13:29:45.60475=20140610268=1279=2269=122=8207=BVMF48=380391383=106250273=94:56:03272=2014061037=80531945431289=8290=6
10:29:45.629: 659162 - 144 - 1128=935=X34=65916252=20140610-13:29:45.64375=20140610268=3279=0269=222=8207=BVMF48=380653683=6238270=3.13273=94:56:43271=2000272=2014061037016=2014061037017=94:56:421500=E451=0.051020=137200274=21003=600288=564289=3279=0269=922=8207=BVMF48=380653683=6239270=3.12273=94:56:43272=201406101500=E279=2269=022=8207=BVMF48=380653683=6240273=94:56:43272=2014061037=80531939238288=564290=1
10:29:45.630: 659163 - 69 - 1128=935=X34=65916352=20140610-13:29:45.64475=20140610268=1279=2269=022=8207=BVMF48=380653683=6241273=94:56:44272=2014061037=80531944631288=8290=3
10:29:45.640: 659164 - 79 - 1128=935=X34=65916452=20140610-13:29:45.65475=20140610268=1279=0269=022=8207=BVMF48=380653683=6242270=3.02273=94:56:53271=1600272=2014061037016=2014061037017=94:56:5337=80531946227288=3290=25
10:29:45.790: 659165 - 72 - 1128=935=X34=65916552=20140610-13:29:45.80475=20140610268=1279=2269=122=8207=BVMF48=380653683=6243273=94:58:04272=2014061037=80531928010289=114290=2
10:29:45.792: 659166 - 79 - 1128=935=X34=65916652=20140610-13:29:45.80675=20140610268=1279=0269=022=8207=BVMF48=380653683=6244270=3.11273=94:58:05271=100272=2014061037016=2014061037017=94:58:0537=80531946228288=8290=4
10:29:45.808: 659167 - 145 - 1128=935=X34=65916752=20140610-13:29:45.82275=20140610268=3279=0269=222=8207=BVMF48=380566083=11403270=2.47273=94:58:21271=10000272=2014061037016=2014061037017=94:58:211500=E451=01020=71000274=21003=330288=82289=114279=0269=922=8207=BVMF48=380566083=11404270=2.486273=94:58:21272=201406101500=E279=2269=022=8207=BVMF48=380566083=11405273=94:58:21272=2014061037=80531847911288=82290=1
10:29:45.810: 659168 - 198 - 1128=935=X34=65916852=20140610-13:29:45.82375=20140610268=5279=0269=222=8207=BVMF48=380566083=11406270=2.47273=94:58:23271=500272=2014061037016=2014061037017=94:58:221500=E451=01020=71500274=3277=L1003=340288=85289=8279=0269=922=8207=BVMF48=380566083=11407270=2.486273=94:58:23272=201406101500=E279=0269=222=8207=BVMF48=380566083=11408270=2.47273=94:58:23271=100272=2014061037016=2014061037017=94:58:221500=E451=01020=71600274=3277=L1003=350288=40289=8279=0269=922=8207=BVMF48=380566083=11409270=2.486273=94:58:23272=201406101500=E279=4269=022=8207=BVMF48=380566083=11410273=94:58:23272=20140610290=2
10:29:45.899: 659169 - 70 - 1128=935=X34=65916952=20140610-13:29:45.91375=20140610268=1279=2269=022=8207=BVMF48=380394783=65807273=94:59:12272=2014061037=80531946219288=8290=1
10:29:45.922: 659170 - 70 - 1128=935=X34=65917052=20140610-13:29:45.93675=20140610268=1279=2269=022=8207=BVMF48=380391383=106251273=94:59:35272=2014061037=80531946224288=8290=33
10:29:45.927: 659171 - 80 - 1128=935=X34=65917152=20140610-13:29:45.94075=20140610268=1279=0269=022=8207=BVMF48=380394783=65808270=17.04273=94:59:40271=100272=2014061037016=2014061037017=94:59:4037=80531946231288=8290=3
10:29:45.932: 659172 - 80 - 1128=935=X34=65917252=20140610-13:29:45.94675=20140610268=1279=0269=022=8207=BVMF48=380391383=106252270=13.79273=94:59:45271=200272=2014061037016=2014061037017=94:59:4537=80531946232288=8290=33
10:29:45.946: 659173 - 70 - 1128=935=X34=65917352=20140610-13:29:45.96075=20140610268=1279=2269=022=8207=BVMF48=380391383=106253273=94:59:59272=2014061037=80531946232288=8290=33
10:29:45.952: 659174 - 70 - 1128=935=X34=65917452=20140610-13:29:45.96575=20140610268=1279=2269=022=8207=BVMF48=380394783=65809273=94:59:65272=2014061037=80531946231288=8290=3
10:29:45.957: 659175 - 80 - 1128=935=X34=65917552=20140610-13:29:45.97175=20140610268=1279=0269=022=8207=BVMF48=380391383=106254270=13.79273=94:59:70271=300272=2014061037016=2014061037017=94:59:7037=80531946233288=8290=33
10:29:45.983: 659176 - 80 - 1128=935=X34=65917652=20140610-13:29:45.99675=20140610268=1279=0269=022=8207=BVMF48=380394783=65810270=17.04273=94:59:96271=400272=2014061037016=2014061037017=94:59:9537=80531946234288=8290=3
10:29:45.994: 659177 - 82 - 1128=935=X34=65917752=20140610-13:29:46.00875=20140610268=1279=0269=122=8207=BVMF48=380653683=6245270=3.13273=94:60:07271=2600272=2014061037016=2014061037017=94:60:0737=80531946235289=114290=1
10:29:46.007: 659178 - 70 - 1128=935=X34=65917852=20140610-13:29:46.02175=20140610268=1279=2269=022=8207=BVMF48=380391383=106255273=94:60:21272=2014061037=80531946233288=8290=33
10:29:46.019: 659179 - 80 - 1128=935=X34=65917952=20140610-13:29:46.03375=20140610268=1279=0269=022=8207=BVMF48=380391383=106256270=13.79273=94:60:32271=700272=2014061037016=2014061037017=94:60:3237=80531946236288=8290=33
10:29:46.032: 659180 - 72 - 1128=935=X34=65918052=20140610-13:29:46.04575=20140610268=1279=2269=122=8207=BVMF48=380394783=65811273=94:60:45272=2014061037=80531931010289=40290=1
10:29:46.037: 659181 - 72 - 1128=935=X34=65918152=20140610-13:29:46.05175=20140610268=1279=2269=122=8207=BVMF48=380394783=65812273=94:60:50272=2014061037=80531931129289=40290=1
10:29:46.111: 659182 - 71 - 1128=935=X34=65918252=20140610-13:29:46.12575=20140610268=1279=2269=122=8207=BVMF48=380391383=106257273=94:61:24272=2014061037=80531946212289=3290=10
10:29:46.160: 659183 - 71 - 1128=935=X34=65918352=20140610-13:29:46.17475=20140610268=1279=2269=122=8207=BVMF48=380653683=6246273=94:61:74272=2014061037=80531925587289=40290=30
10:29:46.162: 659184 - 71 - 1128=935=X34=65918452=20140610-13:29:46.17575=20140610268=1279=2269=122=8207=BVMF48=380653683=6247273=94:61:75272=2014061037=80531925586289=40290=34
10:29:46.228: 659185 - 81 - 1128=935=X34=65918552=20140610-13:29:46.24275=20140610268=1279=0269=022=8207=BVMF48=380391383=106258270=13.84273=94:62:41271=100272=2014061037016=2014061037017=94:62:4137=80531946237288=40290=4
10:29:46.305: 659186 - 81 - 1128=935=X34=65918652=20140610-13:29:46.31975=20140610268=1279=0269=122=8207=BVMF48=380653683=6248270=3.2273=94:63:19271=200272=2014061037016=2014061037017=94:63:1837=80531946239289=40290=31
10:29:46.309: 659187 - 81 - 1128=935=X34=65918752=20140610-13:29:46.32175=20140610268=1279=0269=122=8207=BVMF48=380653683=6249270=3.18273=94:63:20271=400272=2014061037016=2014061037017=94:63:2037=80531946240289=40290=25
10:29:47.186: 659188 - 82 - 1128=935=X34=65918852=20140610-13:29:47.20075=20140610268=1279=0269=022=8207=BVMF48=380965483=79805270=8.12273=94:71:99271=1000272=2014061037016=2014061037017=94:71:9937=80531946250288=564290=64
10:29:47.925: 659189 - 159 - 1128=935=X34=65918952=20140610-13:29:47.93975=20140610268=3279=0269=222=8207=BVMF48=380963983=256143270=26.42273=94:79:39271=100272=2014061037016=2014061037017=94:79:381500=E451=-0.191020=1444500274=1277=L1003=19470288=735289=40279=0269=922=8207=BVMF48=380963983=256144270=26.468273=94:79:39272=201406101500=E279=1269=122=8207=BVMF48=380963983=256145270=26.42273=94:79:39271=100272=2014061037016=2014061037017=93:99:6637=80531946053289=40290=1
10:29:48.073: 659190 - 82 - 1128=935=X34=65919052=20140610-13:29:48.08775=20140610268=1279=0269=122=8207=BVMF48=380965483=79806270=8.19273=94:80:86271=100272=2014061037016=2014061037017=94:80:8637=80531946254289=16290=3
10:29:48.394: 659191 - 119 - 1128=935=X34=65919152=20140610-13:29:48.40875=20140610268=2279=2269=122=8207=BVMF48=380394783=65813273=94:84:07272=2014061037=80531942874289=40290=1279=0269=122=8207=BVMF48=380394783=65814270=17.06273=94:84:07271=100272=2014061037016=2014061037017=94:84:0737=80531946255289=40290=2
10:29:48.449: 659192 - 81 - 1128=935=X34=65919252=20140610-13:29:48.46375=20140610268=1279=0269=122=8207=BVMF48=380968883=253557270=29.41273=94:84:62271=300272=2014061037016=2014061037017=94:84:6237=80531946256289=8290=7
10:29:48.654: 659193 - 83 - 1128=935=X34=65919352=20140610-13:29:48.66775=20140610268=1279=0269=122=8207=BVMF48=380963983=256146270=26.42273=94:86:67271=200272=2014061037016=2014061037017=94:86:6737=80531946260289=238290=8
10:29:49.294: 659194 - 70 - 1128=935=X34=65919452=20140610-13:29:49.30875=20140610268=1279=2269=022=8207=BVMF48=380963983=256147273=94:93:07272=2014061037=80531938389288=3290=71
10:29:49.294: 659195 - 80 - 1128=935=X34=65919552=20140610-13:29:49.30875=20140610268=1279=0269=022=8207=BVMF48=380963983=256148270=26.36273=94:93:07271=3000272=2014061037016=2014061037017=94:93:0737=80531946264288=3290=44
10:29:49.657: 659196 - 82 - 1128=935=X34=65919652=20140610-13:29:49.67175=20140610268=1279=0269=122=8207=BVMF48=380968883=253558270=29.39273=94:96:70271=300272=2014061037016=2014061037017=94:96:7037=80531946266289=77290=5
10:29:49.662: 659197 - 70 - 1128=935=X34=65919752=20140610-13:29:49.67675=20140610268=1279=2269=022=8207=BVMF48=380968883=253559273=94:96:76272=2014061037=80531946202288=3290=7
10:29:50.998: 659198 - 80 - 1128=935=X34=65919852=20140610-13:29:51.01275=20140610268=1279=0269=022=8207=BVMF48=380963983=256149270=26.39273=95:10:12271=300272=2014061037016=2014061037017=95:10:1237=80531946268288=3290=21
10:29:51.253: 659199 - 119 - 1128=935=X34=65919952=20140610-13:29:51.26775=20140610268=2279=2269=122=8207=BVMF48=380394783=65815273=95:12:66272=2014061037=80531942881289=23290=1279=0269=122=8207=BVMF48=380394783=65816270=17.06273=95:12:66271=100272=2014061037016=2014061037017=95:12:6637=80531946269289=23290=2
10:29:51.254: 659200 - 81 - 1128=935=X34=65920052=20140610-13:29:51.26875=20140610268=1279=0269=122=8207=BVMF48=380394783=65817270=17.06273=95:12:68271=200272=2014061037016=2014061037017=95:12:6737=80531946270289=8290=3
10:29:51.341: 659201 - 80 - 1128=935=X34=65920152=20140610-13:29:51.35575=20140610268=1279=0269=022=8207=BVMF48=380394783=65818270=17.01273=95:13:54271=100272=2014061037016=2014061037017=95:13:5437=80531946272288=8290=8
10:29:51.590: 659202 - 70 - 1128=935=X34=65920252=20140610-13:29:51.60475=20140610268=1279=2269=022=8207=BVMF48=380968883=253560273=95:16:03272=2014061037=80531943896288=8290=9
10:29:51.957: 659203 - 121 - 1128=935=X34=65920352=20140610-13:29:51.97175=20140610268=2279=2269=122=8207=BVMF48=380965483=79807273=95:19:71272=2014061037=80531946145289=129290=59279=0269=122=8207=BVMF48=380965483=79808270=8.25273=95:19:71271=5000272=2014061037016=2014061037017=95:19:7137=80531946290289=129290=30
10:29:52.258: 659204 - 71 - 1128=935=X34=65920452=20140610-13:29:52.27275=20140610268=1279=2269=122=8207=BVMF48=380394783=65819273=95:22:71272=2014061037=80531931579289=8290=6
10:29:52.729: 659205 - 118 - 1128=935=X34=65920552=20140610-13:29:52.74375=20140527268=2279=2269=122=8207=BVMF48=380394783=65820273=95:27:43272=2014061037=80520806352289=3290=49279=0269=122=8207=BVMF48=380394783=65821270=17.3273=95:27:43271=100272=2014061037016=2014061037017=95:27:4337=80531946295289=3290=30
10:29:53.001: 659206 - 82 - 1128=935=X34=65920652=20140610-13:29:53.01575=20140610268=1279=0269=122=8207=BVMF48=380965483=79809270=8.19273=95:30:14271=400272=2014061037016=2014061037017=95:30:1437=80531946296289=74290=4
10:29:53.204: 659207 - 80 - 1128=935=X34=65920752=20140610-13:29:53.21875=20140610268=1279=0269=022=8207=BVMF48=400223483=5877270=26.4273=95:32:18271=70272=2014061037016=2014061037017=95:32:1837=80531946297288=3290=2
10:29:53.250: 659208 - 148 - 1128=935=X34=65920852=20140610-13:29:53.26475=20140610268=3279=0269=222=8207=BVMF48=380963983=256150270=26.42273=95:32:63271=100272=2014061037016=2014061037017=95:32:631500=E451=-0.191020=1444600274=1277=L1003=19480288=39289=40279=0269=922=8207=BVMF48=380963983=256151270=26.468273=95:32:63272=201406101500=E279=2269=122=8207=BVMF48=380963983=256152273=95:32:63272=2014061037=80531946053289=40290=1
10:29:53.284: 659209 - 82 - 1128=935=X34=65920952=20140610-13:29:53.29875=20140610268=1279=0269=122=8207=BVMF48=380963983=256153270=26.42273=95:32:97271=200272=2014061037016=2014061037017=95:32:9737=80531946299289=40290=8
10:29:53.465: 659210 - 73 - 1128=935=X34=65921052=20140610-13:29:53.48075=20140610268=1279=2269=122=8207=BVMF48=380965483=79810273=95:34:79272=2014061037=80531887716289=21290=135
10:29:53.986: 659211 - 80 - 1128=935=X34=65921152=20140610-13:29:54.00075=20140610268=1279=0269=022=8207=BVMF48=380391383=106259270=13.85273=95:40:00271=100272=2014061037016=2014061037017=95:40:0037=80531946304288=8290=3
10:29:53.987: 659212 - 72 - 1128=935=X34=65921252=20140610-13:29:54.00275=20140610268=1279=2269=122=8207=BVMF48=380394783=65822273=95:40:01272=2014061037=80531930276289=45290=15
10:29:54.751: 659213 - 81 - 1128=935=X34=65921352=20140610-13:29:54.76475=20140610268=1279=0269=022=8207=BVMF48=380249383=103541270=9.33273=95:47:64271=100272=2014061037016=2014061037017=95:47:6437=80531946307288=40290=9
10:29:55.407: 659214 - 81 - 1128=935=X34=65921452=20140610-13:29:55.42175=20140610268=1279=0269=022=8207=BVMF48=380249383=103542270=9.34273=95:54:20271=100272=2014061037016=2014061037017=95:54:2037=80531946309288=40290=6
10:29:55.412: 659215 - 119 - 1128=935=X34=65921552=20140610-13:29:55.42675=20140610268=2279=2269=122=8207=BVMF48=380394783=65823273=95:54:25272=2014061037=80531946255289=40290=1279=0269=122=8207=BVMF48=380394783=65824270=17.09273=95:54:25271=100272=2014061037016=2014061037017=95:54:2537=80531946310289=40290=5
10:29:55.415: 659216 - 120 - 1128=935=X34=65921652=20140610-13:29:55.42975=20140610268=2279=2269=122=8207=BVMF48=380394783=65825273=95:54:29272=2014061037=80531938610289=40290=4279=0269=122=8207=BVMF48=380394783=65826270=17.1273=95:54:29271=100272=2014061037016=2014061037017=95:54:2937=80531946311289=40290=6
10:29:55.416: 659217 - 71 - 1128=935=X34=65921752=20140610-13:29:55.43175=20140610268=1279=2269=122=8207=BVMF48=380394783=65827273=95:54:30272=2014061037=80531946270289=8290=2
10:29:55.697: 659218 - 82 - 1128=935=X34=65921852=20140610-13:29:55.71175=20140610268=1279=0269=122=8207=BVMF48=380394783=65828270=17.06273=95:57:10271=100272=2014061037016=2014061037017=95:57:1037=80531946316289=40290=2
10:29:55.707: 659219 - 159 - 1128=935=X34=65921952=20140610-13:29:55.72175=20140610268=3279=0269=222=8207=BVMF48=380963983=256154270=26.41273=95:57:21271=100272=2014061037016=2014061037017=95:57:201500=E451=-0.21020=1444700274=21003=19490288=77289=114279=0269=922=8207=BVMF48=380963983=256155270=26.468273=95:57:21272=201406101500=E279=1269=022=8207=BVMF48=380963983=256156270=26.41273=95:57:21271=100272=2014061037016=2014061037017=93:99:2737=80531945960288=77290=1
10:29:55.956: 659220 - 82 - 1128=935=X34=65922052=20140610-13:29:55.97075=20140610268=1279=0269=122=8207=BVMF48=380394783=65829270=17.06273=95:59:70271=100272=2014061037016=2014061037017=95:59:7037=80531946318289=40290=3
10:29:56.022: 659221 - 82 - 1128=935=X34=65922152=20140610-13:29:56.03675=20140610268=1279=0269=122=8207=BVMF48=380963983=256157270=26.45273=95:60:36271=600272=2014061037016=2014061037017=95:60:3537=80531946319289=39290=29
10:29:56.104: 659222 - 192 - 1128=935=X34=65922252=20140610-13:29:56.11975=20140610268=4279=0269=222=8207=BVMF48=380391383=106260270=13.86273=95:61:18271=100272=2014061037016=2014061037017=95:61:171500=E451=-0.031020=109300274=01003=3420288=8289=8279=0269=922=8207=BVMF48=380391383=106261270=13.877273=95:61:18272=201406101500=E279=1269=122=8207=BVMF48=380391383=106262270=13.86273=95:61:18271=100272=2014061037016=2014061037017=40:20:8137=80531926402289=8290=1279=2269=022=8207=BVMF48=380391383=106263273=95:61:18272=2014061037=80531946304288=8290=3
10:29:56.143: 659223 - 70 - 1128=935=X34=65922352=20140610-13:29:56.15875=20140610268=1279=2269=122=8207=BVMF48=380653683=6250273=95:61:57272=2014061037=80531943241289=8290=11
10:29:56.145: 659224 - 80 - 1128=935=X34=65922452=20140610-13:29:56.15975=20140610268=1279=0269=122=8207=BVMF48=380653683=6251270=3.14273=95:61:59271=100272=2014061037016=2014061037017=95:61:5937=80531946321289=8290=6
10:29:56.226: 659225 - 157 - 1128=935=X34=65922552=20140610-13:29:56.24075=20140610268=3279=0269=222=8207=BVMF48=380391383=106264270=13.85273=95:62:39271=100272=2014061037016=2014061037017=95:62:391500=E451=-0.041020=109400274=21003=3430288=40289=227279=0269=922=8207=BVMF48=380391383=106265270=13.877273=95:62:39272=201406101500=E279=1269=022=8207=BVMF48=380391383=106266270=13.85273=95:62:39271=100272=2014061037016=2014061037017=94:53:1537=80531946188288=40290=1
10:29:56.364: 659226 - 82 - 1128=935=X34=65922652=20140610-13:29:56.37875=20140610268=1279=0269=122=8207=BVMF48=380394783=65830270=17.06273=95:63:77271=100272=2014061037016=2014061037017=95:63:7737=80531946323289=70290=4
10:29:56.365: 659227 - 81 - 1128=935=X34=65922752=20140610-13:29:56.37975=20140610268=1279=0269=122=8207=BVMF48=380394783=65831270=17.06273=95:63:79271=200272=2014061037016=2014061037017=95:63:7937=80531946324289=8290=5
10:29:56.468: 659228 - 82 - 1128=935=X34=65922852=20140610-13:29:56.48375=20140610268=1279=0269=122=8207=BVMF48=380968883=253561270=29.4273=95:64:82271=300272=2014061037016=2014061037017=95:64:8237=80531946325289=8290=7
10:29:56.521: 659229 - 82 - 1128=935=X34=65922952=20140610-13:29:56.53575=20140610268=1279=0269=122=8207=BVMF48=380394783=65832270=17.06273=95:65:34271=100272=2014061037016=2014061037017=95:65:3437=80531946326289=40290=6
10:29:56.530: 659230 - 81 - 1128=935=X34=65923052=20140610-13:29:56.54475=20140610268=1279=0269=122=8207=BVMF48=380391383=106267270=13.87273=95:65:44271=1100272=2014061037016=2014061037017=95:65:4337=80531946327289=3290=10
10:29:57.112: 659231 - 80 - 1128=935=X34=65923152=20140610-13:29:57.12675=20140610268=1279=0269=022=8207=BVMF48=380963983=256158270=26.41273=95:71:25271=100272=2014061037016=2014061037017=95:71:2537=80531946328288=8290=11
10:29:57.120: 659232 - 160 - 1128=935=X34=65923252=20140610-13:29:57.13475=20140610268=3279=0269=222=8207=BVMF48=380963983=256159270=26.42273=95:71:33271=100272=2014061037016=2014061037017=95:71:331500=E451=-0.191020=1444800274=01003=19500288=735289=45279=0269=922=8207=BVMF48=380963983=256160270=26.468273=95:71:33272=201406101500=E279=1269=122=8207=BVMF48=380963983=256161270=26.42273=95:71:33271=1100272=2014061037016=2014061037017=93:99:6737=80531946176289=45290=1
10:29:57.126: 659233 - 81 - 1128=935=X34=65923352=20140610-13:29:57.14075=20140610268=1279=1269=122=8207=BVMF48=380963983=256162270=26.42273=95:71:40271=1000272=2014061037016=2014061037017=93:99:6737=80531946330289=45290=1
10:29:57.133: 659234 - 81 - 1128=935=X34=65923452=20140610-13:29:57.14775=20140610268=1279=1269=122=8207=BVMF48=380963983=256163270=26.42273=95:71:46271=900272=2014061037016=2014061037017=93:99:6737=80531946331289=45290=1
10:29:57.141: 659235 - 70 - 1128=935=X34=65923552=20140610-13:29:57.15675=20140610268=1279=2269=122=8207=BVMF48=380653683=6252273=95:71:55272=2014061037=80531946321289=8290=6
10:29:57.160: 659236 - 81 - 1128=935=X34=65923652=20140610-13:29:57.17475=20140610268=1279=1269=122=8207=BVMF48=380963983=256164270=26.42273=95:71:73271=800272=2014061037016=2014061037017=93:99:6737=80531946332289=45290=1
10:29:57.167: 659237 - 81 - 1128=935=X34=65923752=20140610-13:29:57.18175=20140610268=1279=1269=122=8207=BVMF48=380963983=256165270=26.42273=95:71:81271=700272=2014061037016=2014061037017=93:99:6737=80531946333289=45290=1
10:29:57.174: 659238 - 81 - 1128=935=X34=65923852=20140610-13:29:57.18875=20140610268=1279=1269=122=8207=BVMF48=380963983=256166270=26.42273=95:71:88271=600272=2014061037016=2014061037017=93:99:6737=80531946334289=45290=1
10:29:57.179: 659239 - 81 - 1128=935=X34=65923952=20140610-13:29:57.19475=20140610268=1279=1269=122=8207=BVMF48=380963983=256167270=26.42273=95:71:93271=500272=2014061037016=2014061037017=93:99:6737=80531946335289=45290=1
10:29:57.187: 659240 - 81 - 1128=935=X34=65924052=20140610-13:29:57.20175=20140610268=1279=1269=122=8207=BVMF48=380963983=256168270=26.42273=95:72:00271=400272=2014061037016=2014061037017=93:99:6737=80531946336289=45290=1
10:29:57.194: 659241 - 81 - 1128=935=X34=65924152=20140610-13:29:57.20875=20140610268=1279=1269=122=8207=BVMF48=380963983=256169270=26.42273=95:72:08271=300272=2014061037016=2014061037017=93:99:6737=80531946337289=45290=1
10:29:57.205: 659242 - 81 - 1128=935=X34=65924252=20140610-13:29:57.22075=20140610268=1279=1269=122=8207=BVMF48=380963983=256170270=26.42273=95:72:19271=200272=2014061037016=2014061037017=93:99:6737=80531946338289=45290=1
10:29:57.213: 659243 - 81 - 1128=935=X34=65924352=20140610-13:29:57.22775=20140610268=1279=1269=122=8207=BVMF48=380963983=256171270=26.42273=95:72:26271=100272=2014061037016=2014061037017=93:99:6737=80531946339289=45290=1
10:29:57.220: 659244 - 72 - 1128=935=X34=65924452=20140610-13:29:57.23475=20140610268=1279=2269=122=8207=BVMF48=380963983=256172273=95:72:34272=2014061037=80531946339289=45290=1
10:29:57.225: 659245 - 82 - 1128=935=X34=65924552=20140610-13:29:57.24075=20140610268=1279=0269=122=8207=BVMF48=380963983=256173270=26.42273=95:72:39271=3900272=2014061037016=2014061037017=95:72:3937=80531946340289=45290=8
10:29:57.243: 659246 - 71 - 1128=935=X34=65924652=20140610-13:29:57.25775=20140610268=1279=2269=122=8207=BVMF48=380968883=253562273=95:72:56272=2014061037=80531946325289=8290=7
10:29:57.317: 659247 - 145 - 1128=935=X34=65924752=20140610-13:29:57.33275=20140610268=3279=0269=222=8207=BVMF48=380249383=103543270=9.34273=95:73:31271=100272=2014061037016=2014061037017=95:73:311500=E451=-0.111020=261800274=3277=L1003=3760288=40289=8279=0269=922=8207=BVMF48=380249383=103544270=9.381273=95:73:31272=201406101500=E279=2269=022=8207=BVMF48=380249383=103545273=95:73:31272=2014061037=80531944798288=40290=1
10:29:57.544: 659248 - 70 - 1128=935=X34=65924852=20140610-13:29:57.55975=20140610268=1279=2269=022=8207=BVMF48=380965483=79811273=95:75:58272=2014061037=80531943465288=8290=24
10:29:57.546: 659249 - 80 - 1128=935=X34=65924952=20140610-13:29:57.56075=20140610268=1279=0269=022=8207=BVMF48=380965483=79812270=8.17273=95:75:60271=100272=2014061037016=2014061037017=95:75:5937=80531946353288=8290=25
10:29:58.010: 659250 - 81 - 1128=935=X34=65925052=20140610-13:29:58.02475=20140610268=1279=0269=022=8207=BVMF48=380249383=103546270=9.34273=95:80:24271=1000272=2014061037016=2014061037017=95:80:2437=80531946354288=21290=6
10:29:58.030: 659251 - 72 - 1128=935=X34=65925152=20140610-13:29:58.04475=20140610268=1279=2269=122=8207=BVMF48=380249383=103547273=95:80:43272=2014061037=80531945230289=40290=7
10:29:58.568: 659252 - 71 - 1128=935=X34=65925252=20140610-13:29:58.58275=20140610268=1279=2269=022=8207=BVMF48=380968883=253563273=95:85:81272=2014061037=80531946187288=40290=4
10:29:58.568: 659253 - 71 - 1128=935=X34=65925352=20140610-13:29:58.58275=20140610268=1279=2269=022=8207=BVMF48=380963983=256174273=95:85:82272=2014061037=80531946118288=40290=9
10:29:58.568: 659254 - 71 - 1128=935=X34=65925452=20140610-13:29:58.58375=20140610268=1279=2269=022=8207=BVMF48=380391383=106268273=95:85:82272=2014061037=80531946203288=40290=2
10:29:58.569: 659255 - 71 - 1128=935=X34=65925552=20140610-13:29:58.58475=20140610268=1279=2269=022=8207=BVMF48=380394783=65833273=95:85:83272=2014061037=80531946220288=40290=1
10:29:58.570: 659256 - 71 - 1128=935=X34=65925652=20140610-13:29:58.58575=20140610268=1279=2269=022=8207=BVMF48=380965483=79813273=95:85:84272=2014061037=80531946119288=40290=12
10:29:58.576: 659257 - 71 - 1128=935=X34=65925752=20140610-13:29:58.59075=20140610268=1279=2269=022=8207=BVMF48=380249383=103548273=95:85:90272=2014061037=80531946120288=40290=3
10:29:58.577: 659258 - 81 - 1128=935=X34=65925852=20140610-13:29:58.59275=20140610268=1279=0269=022=8207=BVMF48=380963983=256175270=26.41273=95:85:91271=300272=2014061037016=2014061037017=95:85:9137=80531946366288=40290=11
10:29:58.579: 659259 - 81 - 1128=935=X34=65925952=20140610-13:29:58.59375=20140610268=1279=0269=022=8207=BVMF48=380391383=106269270=13.85273=95:85:93271=100272=2014061037016=2014061037017=95:85:9337=80531946367288=40290=2
10:29:58.579: 659260 - 71 - 1128=935=X34=65926052=20140610-13:29:58.59375=20140610268=1279=2269=022=8207=BVMF48=380963983=256176273=95:85:93272=2014061037=80531946084288=40290=8
10:29:58.580: 659261 - 71 - 1128=935=X34=65926152=20140610-13:29:58.59475=20140610268=1279=2269=022=8207=BVMF48=380249383=103549273=95:85:94272=2014061037=80531945268288=40290=2
10:29:58.609: 659262 - 81 - 1128=935=X34=65926252=20140610-13:29:58.62475=20140610268=1279=0269=022=8207=BVMF48=380968883=253564270=29.38273=95:86:23271=300272=2014061037016=2014061037017=95:86:2337=80531946370288=40290=6
10:29:58.612: 659263 - 81 - 1128=935=X34=65926352=20140610-13:29:58.62675=20140610268=1279=0269=022=8207=BVMF48=380963983=256177270=26.41273=95:86:26271=200272=2014061037016=2014061037017=95:86:2637=80531946371288=40290=11
10:29:58.612: 659264 - 81 - 1128=935=X34=65926452=20140610-13:29:58.62775=20140610268=1279=0269=022=8207=BVMF48=380965483=79814270=8.18273=95:86:26271=200272=2014061037016=2014061037017=95:86:2637=80531946372288=40290=13
10:29:58.619: 659265 - 81 - 1128=935=X34=65926552=20140610-13:29:58.63375=20140610268=1279=0269=022=8207=BVMF48=380391383=106270270=13.85273=95:86:32271=200272=2014061037016=2014061037017=95:86:3237=80531946373288=40290=3
10:29:58.623: 659266 - 81 - 1128=935=X34=65926652=20140610-13:29:58.63775=20140610268=1279=0269=022=8207=BVMF48=380394783=65834270=17.04273=95:86:37271=100272=2014061037016=2014061037017=95:86:3637=80531946374288=40290=3
10:29:58.625: 659267 - 81 - 1128=935=X34=65926752=20140610-13:29:58.64075=20140610268=1279=0269=022=8207=BVMF48=380249383=103550270=9.34273=95:86:40271=100272=2014061037016=2014061037017=95:86:3937=80531946375288=40290=5
10:29:58.630: 659268 - 81 - 1128=935=X34=65926852=20140610-13:29:58.64475=20140610268=1279=0269=022=8207=BVMF48=380963983=256178270=26.41273=95:86:44271=100272=2014061037016=2014061037017=95:86:4437=80531946376288=40290=12
10:29:58.631: 659269 - 81 - 1128=935=X34=65926952=20140610-13:29:58.64575=20140610268=1279=0269=022=8207=BVMF48=380249383=103551270=9.34273=95:86:44271=200272=2014061037016=2014061037017=95:86:4437=80531946377288=40290=6
10:29:58.654: 659270 - 70 - 1128=935=X34=65927052=20140610-13:29:58.66975=20140610268=1279=2269=022=8207=BVMF48=380391383=106271273=95:86:68272=2014061037=80531946236288=8290=35
10:29:58.731: 659271 - 80 - 1128=935=X34=65927152=20140610-13:29:58.74575=20140610268=1279=0269=022=8207=BVMF48=380391383=106272270=13.79273=95:87:44271=600272=2014061037016=2014061037017=95:87:4437=80531946378288=8290=35
10:29:58.995: 659272 - 82 - 1128=935=X34=65927252=20140610-13:29:59.00975=20140610268=1279=0269=122=8207=BVMF48=380394783=65835270=17.16273=95:90:09271=1000272=2014061037016=2014061037017=95:90:0937=80531946379289=45290=21
10:29:59.141: 659273 - 70 - 1128=935=X34=65927352=20140610-13:29:59.15575=20140610268=1279=2269=022=8207=BVMF48=380394783=65836273=95:91:55272=2014061037=80531946272288=8290=8
10:29:59.531: 659274 - 69 - 1128=935=X34=65927452=20140610-13:29:59.54575=20140610268=1279=2269=022=8207=BVMF48=380653683=6253273=95:95:45272=2014061037=80531928011288=8290=2
10:29:59.532: 659275 - 79 - 1128=935=X34=65927552=20140610-13:29:59.54775=20140610268=1279=0269=022=8207=BVMF48=380653683=6254270=3.12273=95:95:46271=100272=2014061037016=2014061037017=95:95:4637=80531946382288=8290=2
10:29:59.657: 659276 - 71 - 1128=935=X34=65927652=20140610-13:29:59.67275=20140610268=1279=2269=122=8207=BVMF48=380653683=6255273=95:96:71272=2014061037=80531925590289=40290=28
10:29:59.661: 659277 - 70 - 1128=935=X34=65927752=20140610-13:29:59.67575=20140610268=1279=2269=022=8207=BVMF48=380653683=6256273=95:96:75272=2014061037=80531925593288=40290=11
10:29:59.799: 659278 - 81 - 1128=935=X34=65927852=20140610-13:29:59.81375=20140610268=1279=0269=022=8207=BVMF48=380249383=103552270=9.34273=95:98:13271=100272=2014061037016=2014061037017=95:98:1337=80531946383288=40290=7
10:29:59.805: 659279 - 80 - 1128=935=X34=65927952=20140610-13:29:59.81975=20140610268=1279=0269=022=8207=BVMF48=380653683=6257270=3.08273=95:98:19271=700272=2014061037016=2014061037017=95:98:1837=80531946384288=40290=14
10:29:59.806: 659280 - 80 - 1128=935=X34=65928052=20140610-13:29:59.82175=20140610268=1279=0269=122=8207=BVMF48=380653683=6258270=3.14273=95:98:20271=100272=2014061037016=2014061037017=95:98:2037=80531946385289=8290=6
10:29:59.807: 659281 - 81 - 1128=935=X34=65928152=20140610-13:29:59.82175=20140610268=1279=0269=122=8207=BVMF48=380653683=6259270=3.18273=95:98:21271=700272=2014061037016=2014061037017=95:98:2037=80531946386289=40290=26
10:30:00.061: 659282 - 72 - 1128=935=X34=65928252=20140610-13:30:00.07575=20140610268=1279=2269=022=8207=BVMF48=380968883=253565273=00:00:75272=2014061037=80531927580288=227290=22
10:30:00.061: 659283 - 72 - 1128=935=X34=65928352=20140610-13:30:00.07575=20140610268=1279=2269=022=8207=BVMF48=380968883=253566273=00:00:75272=2014061037=80531945029288=227290=12
10:30:00.061: 659284 - 73 - 1128=935=X34=65928452=20140610-13:30:00.07675=20140610268=1279=2269=122=8207=BVMF48=380968883=253567273=00:00:75272=2014061037=80531916335289=227290=64
10:30:00.062: 659285 - 73 - 1128=935=X34=65928552=20140610-13:30:00.07675=20140610268=1279=2269=122=8207=BVMF48=380968883=253568273=00:00:75272=2014061037=80531930366289=227290=60
10:30:00.062: 659286 - 70 - 1128=935=X34=65928652=20140610-13:30:00.07675=20140610268=1279=2269=022=8207=BVMF48=380963983=256179273=00:00:75272=2014061037=80531925961288=3290=60
10:30:00.063: 659287 - 70 - 1128=935=X34=65928752=20140610-13:30:00.07675=20140610268=1279=2269=022=8207=BVMF48=380963983=256180273=00:00:76272=2014061037=80531946264288=3290=47
10:30:00.063: 659288 - 71 - 1128=935=X34=65928852=20140610-13:30:00.07675=20140610268=1279=2269=122=8207=BVMF48=380963983=256181273=00:00:76272=2014061037=80531918617289=3290=86
10:30:00.063: 659289 - 71 - 1128=935=X34=65928952=20140610-13:30:00.07675=20140610268=1279=2269=122=8207=BVMF48=380963983=256182273=00:00:76272=2014061037=80531930827289=3290=80
10:30:00.065: 659290 - 72 - 1128=935=X34=65929052=20140610-13:30:00.07975=20140610268=1279=2269=022=8207=BVMF48=380391383=106273273=00:00:78272=2014061037=80531930649288=227290=84
10:30:00.065: 659291 - 72 - 1128=935=X34=65929152=20140610-13:30:00.07975=20140610268=1279=2269=022=8207=BVMF48=380391383=106274273=00:00:79272=2014061037=80531882000288=227290=80
10:30:00.065: 659292 - 73 - 1128=935=X34=65929252=20140610-13:30:00.07975=20140610268=1279=2269=122=8207=BVMF48=380391383=106275273=00:00:79272=2014061037=80531927862289=227290=14
10:30:00.065: 659293 - 73 - 1128=935=X34=65929352=20140610-13:30:00.07975=20140610268=1279=2269=122=8207=BVMF48=380391383=106276273=00:00:79272=2014061037=80531923184289=227290=22
10:30:00.081: 659294 - 197 - 1128=935=X34=65929452=20140610-13:30:00.09575=20140610268=4279=0269=222=8207=BVMF48=380963983=256183270=26.42273=00:00:95271=100272=2014061037016=2014061037017=00:00:941500=E451=-0.191020=1444900274=1277=L1003=19510288=8289=40279=0269=922=8207=BVMF48=380963983=256184270=26.468273=00:00:95272=201406101500=E279=1269=122=8207=BVMF48=380963983=256185270=26.42273=00:00:95271=800272=2014061037016=2014061037017=93:99:9737=80531946092289=40290=1279=2269=022=8207=BVMF48=380963983=256186273=00:00:95272=2014061037=80531946328288=8290=9
10:30:00.087: 659295 - 81 - 1128=935=X34=65929552=20140610-13:30:00.10175=20140610268=1279=1269=122=8207=BVMF48=380963983=256187270=26.42273=00:01:01271=3800272=2014061037016=2014061037017=95:72:3937=80531946388289=45290=8
10:30:00.146: 659296 - 400 - 1128=935=X34=65929652=20140610-13:30:00.16175=20140610268=10279=0269=222=8207=BVMF48=380249383=103553270=9.34273=00:01:60271=100272=2014061037016=2014061037017=00:01:591500=E451=-0.111020=261900274=3277=L1003=3770288=40289=70279=0269=922=8207=BVMF48=380249383=103554270=9.381273=00:01:60272=201406101500=E279=0269=222=8207=BVMF48=380249383=103555270=9.34273=00:01:60271=200272=2014061037016=2014061037017=00:01:591500=E451=-0.111020=262100274=3277=L1003=3780288=40289=70279=0269=922=8207=BVMF48=380249383=103556270=9.381273=00:01:60272=201406101500=E279=0269=222=8207=BVMF48=380249383=103557270=9.34273=00:01:60271=100272=2014061037016=2014061037017=00:01:591500=E451=-0.111020=262200274=3277=L1003=3790288=40289=70279=0269=922=8207=BVMF48=380249383=103558270=9.381273=00:01:60272=201406101500=E279=0269=222=8207=BVMF48=380249383=103559270=9.34273=00:01:60271=800272=2014061037016=2014061037017=00:01:591500=E451=-0.111020=263000274=3277=L1003=3800288=21289=70279=0269=922=8207=BVMF48=380249383=103560270=9.381273=00:01:60272=201406101500=E279=4269=022=8207=BVMF48=380249383=103561273=00:01:60272=20140610290=3279=1269=022=8207=BVMF48=380249383=103562270=9.34273=00:01:60271=200272=2014061037016=2014061037017=95:80:2437=80531946354288=21290=1
10:30:00.149: 659297 - 155 - 1128=935=X34=65929752=20140610-13:30:00.16375=20140610268=3279=0269=222=8207=BVMF48=380249383=103563270=9.34273=00:01:62271=100272=2014061037016=2014061037017=00:01:621500=E451=-0.111020=263100274=3277=L1003=3810288=21289=8279=0269=922=8207=BVMF48=380249383=103564270=9.381273=00:01:62272=201406101500=E279=1269=022=8207=BVMF48=380249383=103565270=9.34273=00:01:62271=100272=2014061037016=2014061037017=95:80:2437=80531946354288=21290=1
10:30:00.152: 659298 - 322 - 1128=935=X34=65929852=20140610-13:30:00.16675=20140610268=8279=0269=222=8207=BVMF48=380968883=253569270=29.39273=00:01:65271=100272=2014061037016=2014061037017=00:01:651500=E451=-0.241020=451400274=1277=L1003=6620288=8289=9279=0269=922=8207=BVMF48=380968883=253570270=29.477273=00:01:65272=201406101500=E279=0269=222=8207=BVMF48=380968883=253571270=29.39273=00:01:65271=100272=2014061037016=2014061037017=00:01:651500=E451=-0.241020=451500274=1277=L1003=6630288=8289=45279=0269=922=8207=BVMF48=380968883=253572270=29.477273=00:01:65272=201406101500=E279=0269=222=8207=BVMF48=380968883=253573270=29.39273=00:01:65271=1900272=2014061037016=2014061037017=00:01:651500=E451=-0.241020=453400274=1277=L1003=6640288=8289=45279=0269=922=8207=BVMF48=380968883=253574270=29.477273=00:01:65272=201406101500=E279=4269=122=8207=BVMF48=380968883=253575273=00:01:65272=20140610290=2279=1269=122=8207=BVMF48=380968883=253576270=29.39273=00:01:65271=3100272=2014061037016=2014061037017=94:53:1237=80531946186289=45290=1
10:30:00.152: 659299 - 80 - 1128=935=X34=65929952=20140610-13:30:00.16775=20140610268=1279=0269=022=8207=BVMF48=380968883=253577270=29.38273=00:01:66271=1000272=2014061037016=2014061037017=00:01:6637=80531946396288=8290=7
10:30:00.153: 659300 - 156 - 1128=935=X34=65930052=20140610-13:30:00.16875=20140610268=3279=0269=222=8207=BVMF48=380968883=253578270=29.39273=00:01:67271=1300272=2014061037016=2014061037017=00:01:671500=E451=-0.241020=454700274=1277=L1003=6650288=8289=45279=0269=922=8207=BVMF48=380968883=253579270=29.477273=00:01:67272=201406101500=E279=1269=122=8207=BVMF48=380968883=253580270=29.39273=00:01:67271=1800272=2014061037016=2014061037017=94:53:1237=80531946186289=45290=1
10:30:00.153: 659301 - 71 - 1128=935=X34=65930152=20140610-13:30:00.16875=20140610268=1279=2269=122=8207=BVMF48=380968883=253581273=00:01:67272=2014061037=80531946256289=8290=6
10:30:00.161: 659302 - 83 - 1128=935=X34=65930252=20140610-13:30:00.17575=20140610268=1279=0269=122=8207=BVMF48=380968883=253582270=29.4273=00:01:74271=4000272=2014061037016=2014061037017=00:01:7437=80531946398289=45290=5
10:30:00.164: 659303 - 368 - 1128=935=X34=65930352=20140610-13:30:00.17975=20140610268=9279=0269=222=8207=BVMF48=380249383=103566270=9.34273=00:01:78271=100272=2014061037016=2014061037017=00:01:781500=E451=-0.111020=263200274=3277=L1003=3820288=21289=735279=0269=922=8207=BVMF48=380249383=103567270=9.381273=00:01:78272=201406101500=E279=0269=222=8207=BVMF48=380249383=103568270=9.34273=00:01:78271=100272=2014061037016=2014061037017=00:01:781500=E451=-0.111020=263300274=3277=L1003=3830288=40289=735279=0269=922=8207=BVMF48=380249383=103569270=9.381273=00:01:78272=201406101500=E279=0269=222=8207=BVMF48=380249383=103570270=9.34273=00:01:78271=100272=2014061037016=2014061037017=00:01:781500=E451=-0.111020=263400274=3277=L1003=3840288=40289=735279=0269=922=8207=BVMF48=380249383=103571270=9.381273=00:01:78272=201406101500=E279=4269=022=8207=BVMF48=380249383=103572273=00:01:78272=20140610290=2279=1269=022=8207=BVMF48=380249383=103573270=9.34273=00:01:78271=100272=2014061037016=2014061037017=95:86:4437=80531946377288=40290=1279=2269=122=8207=BVMF48=380249383=103574273=00:01:78272=2014061037=80531946137289=735290=8
10:30:00.165: 659304 - 80 - 1128=935=X34=65930452=20140610-13:30:00.17975=20140610268=1279=1269=022=8207=BVMF48=380968883=253583270=29.38273=00:01:79271=200272=2014061037016=2014061037017=95:86:2337=80531946400288=40290=6
10:30:00.166: 659305 - 80 - 1128=935=X34=65930552=20140610-13:30:00.18075=20140610268=1279=0269=022=8207=BVMF48=380968883=253584270=29.38273=00:01:79271=100272=2014061037016=2014061037017=00:01:7937=80531946401288=3290=8
10:30:00.174: 659306 - 70 - 1128=935=X34=65930652=20140610-13:30:00.18875=20140610268=1279=2269=022=8207=BVMF48=380968883=253585273=00:01:87272=2014061037=80531946401288=3290=8
10:30:00.174: 659307 - 147 - 1128=935=X34=65930752=20140610-13:30:00.18975=20140610268=3279=0269=222=8207=BVMF48=380249383=103575270=9.34273=00:01:88271=100272=2014061037016=2014061037017=00:01:881500=E451=-0.111020=263500274=3277=L1003=3850288=40289=735279=0269=922=8207=BVMF48=380249383=103576270=9.381273=00:01:88272=201406101500=E279=2269=022=8207=BVMF48=380249383=103577273=00:01:88272=2014061037=80531946377288=40290=1
10:30:00.180: 659308 - 82 - 1128=935=X34=65930852=20140610-13:30:00.19575=20140610268=1279=0269=122=8207=BVMF48=380249383=103578270=9.35273=00:01:94271=500272=2014061037016=2014061037017=00:01:9437=80531946414289=40290=8
10:30:00.182: 659309 - 157 - 1128=935=X34=65930952=20140610-13:30:00.19675=20140610268=3279=0269=222=8207=BVMF48=380968883=253586270=29.39273=00:01:96271=100272=2014061037016=2014061037017=00:01:951500=E451=-0.241020=454800274=1277=L1003=6660288=40289=45279=0269=922=8207=BVMF48=380968883=253587270=29.477273=00:01:96272=201406101500=E279=1269=122=8207=BVMF48=380968883=253588270=29.39273=00:01:96271=1700272=2014061037016=2014061037017=94:53:1237=80531946186289=45290=1
10:30:00.182: 659310 - 81 - 1128=935=X34=65931052=20140610-13:30:00.19775=20140610268=1279=0269=022=8207=BVMF48=380249383=103579270=9.34273=00:01:96271=100272=2014061037016=2014061037017=00:01:9637=80531946416288=40290=2
10:30:00.184: 659311 - 83 - 1128=935=X34=65931152=20140610-13:30:00.19875=20140610268=1279=0269=122=8207=BVMF48=380249383=103580270=9.35273=00:01:98271=300272=2014061037016=2014061037017=00:01:9837=80531946417289=735290=9
10:30:00.235: 659312 - 275 - 1128=935=X34=65931252=20140610-13:30:00.24975=20140610268=7279=0269=222=8207=BVMF48=380391383=106277270=13.85273=00:02:49271=100272=2014061037016=2014061037017=00:02:481500=E451=-0.041020=109500274=3277=L1003=3440288=40289=8279=0269=922=8207=BVMF48=380391383=106278270=13.877273=00:02:49272=201406101500=E279=0269=222=8207=BVMF48=380391383=106279270=13.85273=00:02:49271=100272=2014061037016=2014061037017=00:02:481500=E451=-0.041020=109600274=3277=L1003=3450288=40289=8279=0269=922=8207=BVMF48=380391383=106280270=13.877273=00:02:49272=201406101500=E279=0269=222=8207=BVMF48=380391383=106281270=13.85273=00:02:49271=200272=2014061037016=2014061037017=00:02:481500=E451=-0.041020=109800274=3277=L1003=3460288=40289=8279=0269=922=8207=BVMF48=380391383=106282270=13.877273=00:02:49272=201406101500=E279=4269=022=8207=BVMF48=380391383=106283273=00:02:49272=20140610290=3
10:30:00.236: 659313 - 80 - 1128=935=X34=65931352=20140610-13:30:00.25175=20140610268=1279=0269=022=8207=BVMF48=380391383=106284270=13.84273=00:02:50271=100272=2014061037016=2014061037017=00:02:5037=80531946423288=8290=3
10:30:00.237: 659314 - 116 - 1128=935=X34=65931452=20140610-13:30:00.25175=20140610268=2279=2269=022=8207=BVMF48=380391383=106285273=00:02:51272=2014061037=80531930514288=8290=6279=0269=022=8207=BVMF48=380391383=106286270=13.84273=00:02:51271=100272=2014061037016=2014061037017=00:02:5037=80531946424288=8290=4
10:30:00.238: 659315 - 262 - 1128=935=X34=65931552=20140610-13:30:00.25275=20140610268=6279=0269=222=8207=BVMF48=380394783=65837270=17.04273=00:02:52271=100272=2014061037016=2014061037017=00:02:511500=E451=-0.121020=19300274=1277=L1003=1170288=40289=8279=0269=922=8207=BVMF48=380394783=65838270=17.098273=00:02:52272=201406101500=E279=0269=222=8207=BVMF48=380394783=65839270=17.04273=00:02:52271=100272=2014061037016=2014061037017=00:02:511500=E451=-0.121020=19400274=1277=L1003=1180288=8289=8279=0269=922=8207=BVMF48=380394783=65840270=17.098273=00:02:52272=201406101500=E279=2269=022=8207=BVMF48=380394783=65841273=00:02:52272=2014061037=80531946221288=40290=1279=1269=022=8207=BVMF48=380394783=65842270=17.04273=00:02:52271=300272=2014061037016=2014061037017=94:59:9537=80531946234288=8290=1
10:30:00.238: 659316 - 324 - 1128=935=X34=65931652=20140610-13:30:00.25375=20140610268=8279=0269=222=8207=BVMF48=380249383=103581270=9.34273=00:02:52271=100272=2014061037016=2014061037017=00:02:521500=E451=-0.111020=263600274=3277=L1003=3860288=40289=8279=0269=922=8207=BVMF48=380249383=103582270=9.381273=00:02:52272=201406101500=E279=0269=222=8207=BVMF48=380249383=103583270=9.34273=00:02:52271=100272=2014061037016=2014061037017=00:02:521500=E451=-0.111020=263700274=3277=L1003=3870288=40289=8279=0269=922=8207=BVMF48=380249383=103584270=9.381273=00:02:52272=201406101500=E279=0269=222=8207=BVMF48=380249383=103585270=9.33273=00:02:52271=100272=2014061037016=2014061037017=00:02:521500=E451=-0.121020=263800274=21003=3880288=127289=8279=0269=922=8207=BVMF48=380249383=103586270=9.381273=00:02:52272=201406101500=E279=4269=022=8207=BVMF48=380249383=103587273=00:02:52272=20140610290=2279=1269=022=8207=BVMF48=380249383=103588270=9.33273=00:02:52271=2500272=2014061037016=2014061037017=75:48:4737=80531940535288=127290=1
10:30:00.239: 659317 - 81 - 1128=935=X34=65931752=20140610-13:30:00.25475=20140610268=1279=0269=122=8207=BVMF48=380394783=65843270=17.05273=00:02:53271=100272=2014061037016=2014061037017=00:02:5337=80531946427289=8290=1
10:30:00.239: 659318 - 71 - 1128=935=X34=65931852=20140610-13:30:00.25475=20140610268=1279=2269=122=8207=BVMF48=380394783=65844273=00:02:53272=2014061037=80531946427289=8290=1
10:30:00.240: 659319 - 116 - 1128=935=X34=65931952=20140610-13:30:00.25575=20140610268=2279=2269=022=8207=BVMF48=380249383=103589273=00:02:54272=2014061037=80531931836288=8290=9279=0269=022=8207=BVMF48=380249383=103590270=9.33273=00:02:54271=100272=2014061037016=2014061037017=00:02:5437=80531946428288=8290=5
10:30:00.241: 659320 - 81 - 1128=935=X34=65932052=20140610-13:30:00.25575=20140610268=1279=0269=122=8207=BVMF48=380394783=65845270=17.06273=00:02:55271=100272=2014061037016=2014061037017=00:02:5537=80531946429289=8290=7
10:30:00.243: 659321 - 327 - 1128=935=X34=65932152=20140610-13:30:00.25775=20140610268=8279=0269=222=8207=BVMF48=380963983=256188270=26.41273=00:02:56271=100272=2014061037016=2014061037017=00:02:561500=E451=-0.21020=1445000274=21003=19520288=77289=8279=0269=922=8207=BVMF48=380963983=256189270=26.468273=00:02:56272=201406101500=E279=0269=222=8207=BVMF48=380963983=256190270=26.41273=00:02:56271=300272=2014061037016=2014061037017=00:02:561500=E451=-0.21020=1445300274=3277=L1003=19530288=77289=8279=0269=922=8207=BVMF48=380963983=256191270=26.468273=00:02:56272=201406101500=E279=0269=222=8207=BVMF48=380963983=256192270=26.41273=00:02:56271=200272=2014061037016=2014061037017=00:02:561500=E451=-0.21020=1445500274=3277=L1003=19540288=77289=8279=0269=922=8207=BVMF48=380963983=256193270=26.468273=00:02:56272=201406101500=E279=4269=022=8207=BVMF48=380963983=256194273=00:02:56272=20140610290=2279=1269=022=8207=BVMF48=380963983=256195270=26.41273=00:02:56271=200272=2014061037016=2014061037017=93:99:3537=80531945981288=77290=1
10:30:00.244: 659322 - 81 - 1128=935=X34=65932252=20140610-13:30:00.25875=20140610268=1279=0269=122=8207=BVMF48=380965483=79815270=8.19273=00:02:58271=200272=2014061037016=2014061037017=00:02:5737=80531946436289=8290=5
10:30:00.248: 659323 - 81 - 1128=935=X34=65932352=20140610-13:30:00.26275=20140610268=1279=0269=122=8207=BVMF48=380249383=103591270=9.35273=00:02:62271=100272=2014061037016=2014061037017=00:02:6137=80531946441289=8290=10
10:30:00.248: 659324 - 71 - 1128=935=X34=65932452=20140610-13:30:00.26275=20140610268=1279=2269=122=8207=BVMF48=380249383=103592273=00:02:62272=2014061037=80531946441289=8290=10
10:30:00.249: 659325 - 70 - 1128=935=X34=65932552=20140610-13:30:00.26375=20140610268=1279=2269=022=8207=BVMF48=380249383=103593273=00:02:63272=2014061037=80531940538288=8290=2
10:30:00.250: 659326 - 81 - 1128=935=X34=65932652=20140610-13:30:00.26575=20140610268=1279=0269=122=8207=BVMF48=380249383=103594270=9.35273=00:02:64271=100272=2014061037016=2014061037017=00:02:6437=80531946442289=8290=10
10:30:00.254: 659327 - 80 - 1128=935=X34=65932752=20140610-13:30:00.26875=20140610268=1279=1269=122=8207=BVMF48=380963983=256196270=26.42273=00:02:68271=1400272=2014061037016=2014061037017=94:53:9537=80531946444289=8290=4
10:30:00.262: 659328 - 70 - 1128=935=X34=65932852=20140610-13:30:00.27675=20140610268=1279=2269=022=8207=BVMF48=380968883=253589273=00:02:76272=2014061037=80531946396288=8290=7
10:30:00.262: 659329 - 324 - 1128=935=X34=65932952=20140610-13:30:00.27775=20140610268=8279=0269=222=8207=BVMF48=380968883=253590270=29.39273=00:02:76271=1700272=2014061037016=2014061037017=00:02:761500=E451=-0.241020=456500274=1277=L1003=6670288=8289=45279=0269=922=8207=BVMF48=380968883=253591270=29.476273=00:02:76272=201406101500=E279=0269=222=8207=BVMF48=380968883=253592270=29.39273=00:02:76271=200272=2014061037016=2014061037017=00:02:761500=E451=-0.241020=456700274=1277=L1003=6680288=8289=77279=0269=922=8207=BVMF48=380968883=253593270=29.476273=00:02:76272=201406101500=E279=0269=222=8207=BVMF48=380968883=253594270=29.39273=00:02:76271=100272=2014061037016=2014061037017=00:02:761500=E451=-0.241020=456800274=1277=L1003=6690288=8289=77279=0269=922=8207=BVMF48=380968883=253595270=29.476273=00:02:76272=201406101500=E279=4269=122=8207=BVMF48=380968883=253596273=00:02:76272=20140610290=2279=1269=122=8207=BVMF48=380968883=253597270=29.39273=00:02:76271=200272=2014061037016=2014061037017=94:96:7037=80531946266289=77290=1
10:30:00.264: 659330 - 81 - 1128=935=X34=65933052=20140610-13:30:00.27875=20140610268=1279=0269=122=8207=BVMF48=380249383=103595270=9.35273=00:02:77271=300272=2014061037016=2014061037017=00:02:7737=80531946449289=8290=11
10:30:00.264: 659331 - 81 - 1128=935=X34=65933152=20140610-13:30:00.27875=20140610268=1279=1269=122=8207=BVMF48=380963983=256197270=26.42273=00:02:78271=3700272=2014061037016=2014061037017=95:72:3937=80531946450289=45290=8
10:30:00.274: 659332 - 265 - 1128=935=X34=65933252=20140610-13:30:00.28975=20140610268=6279=0269=222=8207=BVMF48=380968883=253598270=29.39273=00:02:88271=200272=2014061037016=2014061037017=00:02:871500=E451=-0.241020=457000274=1277=L1003=6700288=8289=77279=0269=922=8207=BVMF48=380968883=253599270=29.476273=00:02:88272=201406101500=E279=0269=222=8207=BVMF48=380968883=253600270=29.4273=00:02:88271=800272=2014061037016=2014061037017=00:02:871500=E451=-0.231020=457800274=01003=6710288=8289=8279=0269=922=8207=BVMF48=380968883=253601270=29.476273=00:02:88272=201406101500=E279=2269=122=8207=BVMF48=380968883=253602273=00:02:88272=2014061037=80531946266289=77290=1279=1269=122=8207=BVMF48=380968883=253603270=29.4273=00:02:88271=3200272=2014061037016=2014061037017=42:17:5937=80531927360289=8290=1
10:30:00.275: 659333 - 401 - 1128=935=X34=65933352=20140610-13:30:00.28975=20140610268=10279=0269=222=8207=BVMF48=380963983=256198270=26.41273=00:02:88271=200272=2014061037016=2014061037017=00:02:881500=E451=-0.21020=1445700274=3277=L1003=19550288=77289=8279=0269=922=8207=BVMF48=380963983=256199270=26.468273=00:02:88272=201406101500=E279=0269=222=8207=BVMF48=380963983=256200270=26.41273=00:02:88271=100272=2014061037016=2014061037017=00:02:881500=E451=-0.21020=1445800274=3277=L1003=19560288=77289=8279=0269=922=8207=BVMF48=380963983=256201270=26.468273=00:02:88272=201406101500=E279=0269=222=8207=BVMF48=380963983=256202270=26.41273=00:02:88271=200272=2014061037016=2014061037017=00:02:881500=E451=-0.21020=1446000274=3277=L1003=19570288=77289=8279=0269=922=8207=BVMF48=380963983=256203270=26.468273=00:02:88272=201406101500=E279=0269=222=8207=BVMF48=380963983=256204270=26.41273=00:02:88271=500272=2014061037016=2014061037017=00:02:881500=E451=-0.21020=1446500274=3277=L1003=19580288=40289=8279=0269=922=8207=BVMF48=380963983=256205270=26.468273=00:02:88272=201406101500=E279=4269=022=8207=BVMF48=380963983=256206273=00:02:88272=20140610290=3279=1269=022=8207=BVMF48=380963983=256207270=26.41273=00:02:88271=200272=2014061037016=2014061037017=93:99:5037=80531946020288=40290=1
10:30:00.276: 659334 - 71 - 1128=935=X34=65933452=20140610-13:30:00.29175=20140610268=1279=2269=022=8207=BVMF48=380963983=256208273=00:02:90272=2014061037=80531946045288=45290=10
10:30:00.277: 659335 - 119 - 1128=935=X34=65933552=20140610-13:30:00.29175=20140610268=2279=2269=122=8207=BVMF48=380963983=256209273=00:02:90272=2014061037=80531946109289=45290=63279=0269=122=8207=BVMF48=380963983=256210270=26.43273=00:02:90271=3000272=2014061037016=2014061037017=00:02:9037=80531946456289=45290=11
10:30:00.288: 659336 - 81 - 1128=935=X34=65933652=20140610-13:30:00.30275=20140610268=1279=0269=122=8207=BVMF48=380968883=253604270=29.41273=00:03:01271=300272=2014061037016=2014061037017=00:03:0137=80531946460289=8290=4
10:30:00.293: 659337 - 82 - 1128=935=X34=65933752=20140610-13:30:00.30775=20140610268=1279=1269=122=8207=BVMF48=380968883=253605270=29.4273=00:03:07271=3200272=2014061037016=2014061037017=00:01:7437=80531946462289=45290=2
10:30:00.294: 659338 - 73 - 1128=935=X34=65933852=20140610-13:30:00.30875=20140610268=1279=2269=122=8207=BVMF48=380963983=256211273=00:03:07272=2014061037=80531940290289=227290=14
10:30:00.298: 659339 - 83 - 1128=935=X34=65933952=20140610-13:30:00.31275=20140610268=1279=0269=022=8207=BVMF48=380963983=256212270=25.9273=00:03:12271=1000272=2014061037016=2014061037017=00:03:1137=80531946465288=72290=182
10:30:00.299: 659340 - 81 - 1128=935=X34=65934052=20140610-13:30:00.31375=20140610268=1279=0269=022=8207=BVMF48=380968883=253606270=29.35273=00:03:13271=1000272=2014061037016=2014061037017=00:03:1337=80531946466288=72290=19
10:30:00.306: 659341 - 83 - 1128=935=X34=65934152=20140610-13:30:00.32175=20140610268=1279=0269=122=8207=BVMF48=380963983=256213270=26.44273=00:03:20271=200272=2014061037016=2014061037017=00:03:2037=80531946468289=227290=18
10:30:00.333: 659342 - 201 - 1128=935=X34=65934252=20140610-13:30:00.34775=20140610268=4279=0269=222=8207=BVMF48=380249383=103596270=9.33273=00:03:47271=100272=2014061037016=2014061037017=00:03:461500=E451=-0.121020=263900274=3277=L1003=3890288=127289=735279=0269=922=8207=BVMF48=380249383=103597270=9.381273=00:03:47272=201406101500=E279=1269=022=8207=BVMF48=380249383=103598270=9.33273=00:03:47271=2400272=2014061037016=2014061037017=75:48:4737=80531940535288=127290=1279=2269=122=8207=BVMF48=380249383=103599273=00:03:47272=2014061037=80531946417289=735290=9
10:30:00.342: 659343 - 70 - 1128=935=X34=65934352=20140610-13:30:00.35675=20140610268=1279=2269=022=8207=BVMF48=380391383=106287273=00:03:56272=2014061037=80531946378288=8290=33
10:30:00.342: 659344 - 70 - 1128=935=X34=65934452=20140610-13:30:00.35675=20140610268=1279=2269=022=8207=BVMF48=380963983=256214273=00:03:56272=2014061037=80531945888288=8290=46
10:30:00.346: 659345 - 81 - 1128=935=X34=65934552=20140610-13:30:00.36075=20140610268=1279=0269=122=8207=BVMF48=380249383=103600270=9.34273=00:03:60271=100272=2014061037016=2014061037017=00:03:5937=80531946474289=8290=1
10:30:00.347: 659346 - 82 - 1128=935=X34=65934652=20140610-13:30:00.36175=20140610268=1279=0269=122=8207=BVMF48=380968883=253607270=29.4273=00:03:61271=100272=2014061037016=2014061037017=00:03:6137=80531946475289=8290=3
10:30:00.351: 659347 - 83 - 1128=935=X34=65934752=20140610-13:30:00.36675=20140610268=1279=0269=122=8207=BVMF48=380249383=103601270=9.35273=00:03:65271=300272=2014061037016=2014061037017=00:03:6537=80531946480289=735290=12
10:30:00.354: 659348 - 463 - 1128=935=X34=65934852=20140610-13:30:00.36875=20140610268=12279=0269=222=8207=BVMF48=380391383=106288270=13.84273=00:03:67271=300272=2014061037016=2014061037017=00:03:661500=E451=-0.051020=110100274=21003=3470288=8289=8279=0269=922=8207=BVMF48=380391383=106289270=13.877273=00:03:67272=201406101500=E279=0269=222=8207=BVMF48=380391383=106290270=13.84273=00:03:67271=100272=2014061037016=2014061037017=00:03:661500=E451=-0.051020=110200274=3277=L1003=3480288=40289=8279=0269=922=8207=BVMF48=380391383=106291270=13.877273=00:03:67272=201406101500=E279=0269=222=8207=BVMF48=380391383=106292270=13.84273=00:03:67271=100272=2014061037016=2014061037017=00:03:661500=E451=-0.051020=110300274=3277=L1003=3490288=8289=8279=0269=922=8207=BVMF48=380391383=106293270=13.877273=00:03:67272=201406101500=E279=0269=222=8207=BVMF48=380391383=106294270=13.84273=00:03:67271=100272=2014061037016=2014061037017=00:03:661500=E451=-0.051020=110400274=3277=L1003=3500288=8289=8279=0269=922=8207=BVMF48=380391383=106295270=13.877273=00:03:67272=201406101500=E279=0269=222=8207=BVMF48=380391383=106296270=13.83273=00:03:67271=1400272=2014061037016=2014061037017=00:03:661500=E451=-0.061020=111800274=21003=3510288=39289=8279=0269=922=8207=BVMF48=380391383=106297270=13.876273=00:03:67272=201406101500=E279=4269=022=8207=BVMF48=380391383=106298273=00:03:67272=20140610290=4279=1269=022=8207=BVMF48=380391383=106299270=13.83273=00:03:67271=1700272=2014061037016=2014061037017=25:97:0537=80531848615288=39290=1
10:30:00.355: 659349 - 81 - 1128=935=X34=65934952=20140610-13:30:00.36975=20140610268=1279=0269=122=8207=BVMF48=380391383=106300270=13.95273=00:03:68271=300272=2014061037016=2014061037017=00:03:6837=80531946497289=8290=48
10:30:00.355: 659350 - 80 - 1128=935=X34=65935052=20140610-13:30:00.36975=20140610268=1279=0269=022=8207=BVMF48=380391383=106301270=13.84273=00:03:69271=1200272=2014061037016=2014061037017=00:03:6937=80531946499288=8290=1
10:30:00.355: 659351 - 80 - 1128=935=X34=65935152=20140610-13:30:00.37075=20140610268=1279=0269=022=8207=BVMF48=380391383=106302270=13.83273=00:03:69271=100272=2014061037016=2014061037017=00:03:6937=80531946500288=8290=6
10:30:00.355: 659352 - 80 - 1128=935=X34=65935252=20140610-13:30:00.37075=20140610268=1279=0269=022=8207=BVMF48=380391383=106303270=13.83273=00:03:69271=200272=2014061037016=2014061037017=00:03:6937=80531946501288=8290=7
10:30:00.358: 659353 - 83 - 1128=935=X34=65935352=20140610-13:30:00.37375=20140610268=1279=0269=122=8207=BVMF48=380391383=106304270=13.85273=00:03:72271=1500272=2014061037016=2014061037017=00:03:7237=80531946502289=227290=1
10:30:00.361: 659354 - 81 - 1128=935=X34=65935452=20140610-13:30:00.37475=20140610268=1279=0269=122=8207=BVMF48=380391383=106305270=13.85273=00:03:74271=300272=2014061037016=2014061037017=00:03:7437=80531946503289=8290=2
10:30:00.361: 659355 - 80 - 1128=935=X34=65935552=20140610-13:30:00.37475=20140610268=1279=0269=022=8207=BVMF48=380391383=106306270=13.79273=00:03:74271=400272=2014061037016=2014061037017=00:03:7437=80531946504288=8290=32
10:30:00.366: 659356 - 71 - 1128=935=X34=65935652=20140610-13:30:00.38075=20140610268=1279=2269=122=8207=BVMF48=380963983=256215273=00:03:79272=2014061037=80531946215289=8290=5
10:30:00.370: 659357 - 147 - 1128=935=X34=65935752=20140610-13:30:00.38575=20140610268=3279=0269=222=8207=BVMF48=380963983=256216270=26.41273=00:03:84271=200272=2014061037016=2014061037017=00:03:841500=E451=-0.21020=1446700274=3277=L1003=19590288=40289=8279=0269=922=8207=BVMF48=380963983=256217270=26.468273=00:03:84272=201406101500=E279=2269=022=8207=BVMF48=380963983=256218273=00:03:84272=2014061037=80531946020288=40290=1
10:30:00.370: 659358 - 70 - 1128=935=X34=65935852=20140610-13:30:00.38575=20140610268=1279=2269=022=8207=BVMF48=380394783=65846273=00:03:84272=2014061037=80531946234288=8290=1
10:30:00.372: 659359 - 71 - 1128=935=X34=65935952=20140610-13:30:00.38675=20140610268=1279=2269=122=8207=BVMF48=380963983=256219273=00:03:86272=2014061037=80531946444289=8290=4
10:30:00.375: 659360 - 156 - 1128=935=X34=65936052=20140610-13:30:00.39075=20140610268=3279=0269=222=8207=BVMF48=380391383=106307270=13.84273=00:03:89271=100272=2014061037016=2014061037017=00:03:891500=E451=-0.051020=111900274=01003=3520288=8289=227279=0269=922=8207=BVMF48=380391383=106308270=13.876273=00:03:89272=201406101500=E279=1269=022=8207=BVMF48=380391383=106309270=13.84273=00:03:89271=1100272=2014061037016=2014061037017=00:03:6937=80531946499288=8290=1
10:30:00.376: 659361 - 70 - 1128=935=X34=65936152=20140610-13:30:00.39175=20140610268=1279=2269=022=8207=BVMF48=380391383=106310273=00:03:91272=2014061037=80531946500288=8290=6
10:30:00.379: 659362 - 81 - 1128=935=X34=65936252=20140610-13:30:00.39475=20140610268=1279=1269=122=8207=BVMF48=380963983=256220270=26.42273=00:03:93271=2700272=2014061037016=2014061037017=95:72:3937=80531946511289=45290=6
10:30:00.385: 659363 - 81 - 1128=935=X34=65936352=20140610-13:30:00.39975=20140610268=1279=1269=122=8207=BVMF48=380963983=256221270=26.42273=00:03:99271=1300272=2014061037016=2014061037017=95:72:3937=80531946516289=45290=6
10:30:00.387: 659364 - 82 - 1128=935=X34=65936452=20140610-13:30:00.40175=20140610268=1279=0269=122=8207=BVMF48=380391383=106311270=13.86273=00:04:01271=3900272=2014061037016=2014061037017=00:04:0137=80531946517289=40290=8
10:30:00.393: 659365 - 155 - 1128=935=X34=65936552=20140610-13:30:00.40775=20140610268=3279=0269=222=8207=BVMF48=380391383=106312270=13.84273=00:04:06271=900272=2014061037016=2014061037017=00:04:061500=E451=-0.051020=112800274=1277=L1003=3530288=8289=40279=0269=922=8207=BVMF48=380391383=106313270=13.876273=00:04:06272=201406101500=E279=1269=022=8207=BVMF48=380391383=106314270=13.84273=00:04:06271=200272=2014061037016=2014061037017=00:03:6937=80531946499288=8290=1
10:30:00.393: 659366 - 80 - 1128=935=X34=65936652=20140610-13:30:00.40775=20140610268=1279=0269=022=8207=BVMF48=380968883=253608270=29.38273=00:04:07271=2200272=2014061037016=2014061037017=00:04:0637=80531946525288=8290=7
10:30:00.394: 659367 - 70 - 1128=935=X34=65936752=20140610-13:30:00.40875=20140610268=1279=2269=022=8207=BVMF48=380391383=106315273=00:04:08272=2014061037=80531946499288=8290=1
10:30:00.394: 659368 - 71 - 1128=935=X34=65936852=20140610-13:30:00.40975=20140610268=1279=2269=022=8207=BVMF48=380394783=65847273=00:04:08272=2014061037=80531942861288=45290=4
10:30:00.396: 659369 - 145 - 1128=935=X34=65936952=20140610-13:30:00.41075=20140610268=3279=0269=222=8207=BVMF48=380394783=65848270=17.04273=00:04:09271=100272=2014061037016=2014061037017=00:04:091500=E451=-0.121020=19500274=1277=L1003=1190288=40289=8279=0269=922=8207=BVMF48=380394783=65849270=17.098273=00:04:09272=201406101500=E279=2269=022=8207=BVMF48=380394783=65850273=00:04:09272=2014061037=80531946374288=40290=1
10:30:00.396: 659370 - 81 - 1128=935=X34=65937052=20140610-13:30:00.41075=20140610268=1279=0269=022=8207=BVMF48=380391383=106316270=13.79273=00:04:09271=3900272=2014061037016=2014061037017=00:04:0937=80531946530288=40290=31
10:30:00.397: 659371 - 71 - 1128=935=X34=65937152=20140610-13:30:00.41175=20140610268=1279=2269=122=8207=BVMF48=380394783=65851273=00:04:11272=2014061037=80531927670289=8290=8
10:30:00.397: 659372 - 81 - 1128=935=X34=65937252=20140610-13:30:00.41175=20140610268=1279=0269=122=8207=BVMF48=380394783=65852270=17.05273=00:04:11271=100272=2014061037016=2014061037017=00:04:1137=80531946534289=8290=1
10:30:00.397: 659373 - 80 - 1128=935=X34=65937352=20140610-13:30:00.41275=20140610268=1279=0269=022=8207=BVMF48=380394783=65853270=17.02273=00:04:11271=100272=2014061037016=2014061037017=00:04:1137=80531946535288=8290=3
10:30:00.397: 659374 - 117 - 1128=935=X34=65937452=20140610-13:30:00.41275=20140610268=2279=2269=122=8207=BVMF48=380394783=65854273=00:04:11272=2014061037=80531946324289=8290=6279=0269=122=8207=BVMF48=380394783=65855270=17.05273=00:04:11271=200272=2014061037016=2014061037017=00:04:1137=80531946536289=8290=2
10:30:00.399: 659375 - 81 - 1128=935=X34=65937552=20140610-13:30:00.41375=20140610268=1279=0269=122=8207=BVMF48=380394783=65856270=17.05273=00:04:12271=400272=2014061037016=2014061037017=00:04:1237=80531946537289=8290=3
10:30:00.401: 659376 - 81 - 1128=935=X34=65937652=20140610-13:30:00.41675=20140610268=1279=0269=022=8207=BVMF48=380963983=256222270=26.41273=00:04:15271=600272=2014061037016=2014061037017=00:04:1537=80531946539288=40290=6
10:30:00.403: 659377 - 144 - 1128=935=X34=65937752=20140610-13:30:00.41775=20140610268=3279=0269=222=8207=BVMF48=380394783=65857270=17.05273=00:04:17271=100272=2014061037016=2014061037017=00:04:171500=E451=-0.111020=19600274=01003=1200288=40289=8279=0269=922=8207=BVMF48=380394783=65858270=17.098273=00:04:17272=201406101500=E279=2269=122=8207=BVMF48=380394783=65859273=00:04:17272=2014061037=80531946534289=8290=1
10:30:00.403: 659378 - 81 - 1128=935=X34=65937852=20140610-13:30:00.41875=20140610268=1279=0269=022=8207=BVMF48=380968883=253609270=29.38273=00:04:17271=300272=2014061037016=2014061037017=00:04:1737=80531946541288=40290=8
10:30:00.404: 659379 - 159 - 1128=935=X34=65937952=20140610-13:30:00.41875=20140610268=3279=0269=222=8207=BVMF48=380391383=106317270=13.85273=00:04:18271=300272=2014061037016=2014061037017=00:04:181500=E451=-0.041020=113100274=01003=3540288=40289=227279=0269=922=8207=BVMF48=380391383=106318270=13.876273=00:04:18272=201406101500=E279=1269=122=8207=BVMF48=380391383=106319270=13.85273=00:04:18271=1200272=2014061037016=2014061037017=00:03:7237=80531946502289=227290=1
10:30:00.405: 659380 - 81 - 1128=935=X34=65938052=20140610-13:30:00.41975=20140610268=1279=0269=022=8207=BVMF48=380965483=79816270=8.18273=00:04:19271=100272=2014061037016=2014061037017=00:04:1937=80531946543288=40290=14
10:30:00.408: 659381 - 80 - 1128=935=X34=65938152=20140610-13:30:00.42275=20140610268=1279=0269=022=8207=BVMF48=380394783=65860270=17.03273=00:04:22271=300272=2014061037016=2014061037017=00:04:2237=80531946545288=8290=1
10:30:00.409: 659382 - 192 - 1128=935=X34=65938252=20140610-13:30:00.42475=20140610268=4279=0269=222=8207=BVMF48=380249383=103602270=9.34273=00:04:23271=100272=2014061037016=2014061037017=00:04:231500=E451=-0.111020=264000274=01003=3900288=40289=8279=0269=922=8207=BVMF48=380249383=103603270=9.381273=00:04:23272=201406101500=E279=2269=122=8207=BVMF48=380249383=103604273=00:04:23272=2014061037=80531946474289=8290=1279=0269=022=8207=BVMF48=380249383=103605270=9.34273=00:04:23271=100272=2014061037016=2014061037017=00:04:2337=80531946546288=40290=1
10:30:00.410: 659383 - 81 - 1128=935=X34=65938352=20140610-13:30:00.42575=20140610268=1279=0269=122=8207=BVMF48=380249383=103606270=9.35273=00:04:24271=100272=2014061037016=2014061037017=00:04:2437=80531946547289=8290=12
10:30:00.424: 659384 - 81 - 1128=935=X34=65938452=20140610-13:30:00.43975=20140610268=1279=0269=022=8207=BVMF48=380394783=65861270=17.02273=00:04:38271=100272=2014061037016=2014061037017=00:04:3837=80531946550288=40290=5
10:30:00.426: 659385 - 71 - 1128=935=X34=65938552=20140610-13:30:00.44175=20140610268=1279=2269=122=8207=BVMF48=380968883=253610273=00:04:40272=2014061037=80531946460289=8290=5
10:30:00.441: 659386 - 81 - 1128=935=X34=65938652=20140610-13:30:00.45675=20140610268=1279=0269=122=8207=BVMF48=380391383=106320270=13.84273=00:04:55271=100272=2014061037016=2014061037017=00:04:5537=80531946554289=8290=1
10:30:00.443: 659387 - 143 - 1128=935=X34=65938752=20140610-13:30:00.45775=20140610268=3279=0269=222=8207=BVMF48=380391383=106321270=13.84273=00:04:57271=100272=2014061037016=2014061037017=00:04:561500=E451=-0.051020=113200274=21003=3550288=8289=8279=0269=922=8207=BVMF48=380391383=106322270=13.876273=00:04:57272=201406101500=E279=2269=122=8207=BVMF48=380391383=106323273=00:04:57272=2014061037=80531946554289=8290=1
10:30:00.444: 659388 - 81 - 1128=935=X34=65938852=20140610-13:30:00.45975=20140610268=1279=0269=122=8207=BVMF48=380391383=106324270=13.85273=00:04:58271=100272=2014061037016=2014061037017=00:04:5837=80531946556289=8290=3
10:30:00.446: 659389 - 71 - 1128=935=X34=65938952=20140610-13:30:00.46175=20140610268=1279=2269=122=8207=BVMF48=380249383=103607273=00:04:60272=2014061037=80531946442289=8290=9
10:30:00.447: 659390 - 81 - 1128=935=X34=65939052=20140610-13:30:00.46275=20140610268=1279=0269=122=8207=BVMF48=380394783=65862270=17.06273=00:04:61271=100272=2014061037016=2014061037017=00:04:6137=80531946558289=8290=9
10:30:00.448: 659391 - 71 - 1128=935=X34=65939152=20140610-13:30:00.46275=20140610268=1279=2269=122=8207=BVMF48=380394783=65863273=00:04:61272=2014061037=80531946558289=8290=9
10:30:00.459: 659392 - 81 - 1128=935=X34=65939252=20140610-13:30:00.47475=20140610268=1279=0269=122=8207=BVMF48=380968883=253611270=29.41273=00:04:73271=300272=2014061037016=2014061037017=00:04:7337=80531946566289=8290=5
10:30:00.475: 659393 - 82 - 1128=935=X34=65939352=20140610-13:30:00.49075=20140610268=1279=0269=122=8207=BVMF48=380968883=253612270=29.39273=00:04:89271=300272=2014061037016=2014061037017=00:04:8937=80531946570289=77290=1
10:30:00.476: 659394 - 82 - 1128=935=X34=65939452=20140610-13:30:00.49175=20140610268=1279=0269=022=8207=BVMF48=380963983=256223270=26.3273=00:04:90271=3000272=2014061037016=2014061037017=00:04:9037=80531946571288=45290=81
10:30:00.483: 659395 - 80 - 1128=935=X34=65939552=20140610-13:30:00.49775=20140610268=1279=0269=022=8207=BVMF48=380968883=253613270=29.38273=00:04:96271=100272=2014061037016=2014061037017=00:04:9637=80531946572288=3290=9
10:30:00.509: 659396 - 82 - 1128=935=X34=65939652=20140610-13:30:00.52475=20140610268=1279=0269=022=8207=BVMF48=380394783=65864270=16.98273=00:05:23271=400272=2014061037016=2014061037017=00:05:2337=80531946577288=110290=11
10:30:00.528: 659397 - 72 - 1128=935=X34=65939752=20140610-13:30:00.54375=20140610268=1279=2269=022=8207=BVMF48=380394783=65865273=00:05:42272=2014061037=80531946577288=110290=11
10:30:00.530: 659398 - 83 - 1128=935=X34=65939852=20140610-13:30:00.54575=20140610268=1279=0269=122=8207=BVMF48=380391383=106325270=13.86273=00:05:44271=100272=2014061037016=2014061037017=00:05:4437=80531946579289=238290=10
10:30:00.533: 659399 - 71 - 1128=935=X34=65939952=20140610-13:30:00.54775=20140610268=1279=2269=022=8207=BVMF48=380968883=253614273=00:05:47272=2014061037=80531946466288=72290=22
10:30:00.535: 659400 - 72 - 1128=935=X34=65940052=20140610-13:30:00.54975=20140610268=1279=2269=022=8207=BVMF48=380963983=256224273=00:05:48272=2014061037=80531946465288=72290=182
10:30:00.537: 659401 - 73 - 1128=935=X34=65940152=20140610-13:30:00.55175=20140610268=1279=2269=122=8207=BVMF48=380963983=256225273=00:05:50272=2014061037=80531946468289=227290=16
10:30:00.555: 659402 - 71 - 1128=935=X34=65940252=20140610-13:30:00.56975=20140610268=1279=2269=122=8207=BVMF48=380963983=256226273=00:05:69272=2014061037=80531946110289=8290=8
10:30:00.556: 659403 - 80 - 1128=935=X34=65940352=20140610-13:30:00.57175=20140610268=1279=0269=022=8207=BVMF48=380963983=256227270=26.36273=00:05:70271=100272=2014061037016=2014061037017=00:05:7037=80531946580288=8290=40
10:30:00.589: 659404 - 71 - 1128=935=X34=65940452=20140610-13:30:00.60475=20140610268=1279=2269=122=8207=BVMF48=380968883=253615273=00:06:03272=2014061037=80531946475289=8290=4
10:30:00.605: 659405 - 82 - 1128=935=X34=65940552=20140610-13:30:00.61975=20140610268=1279=0269=122=8207=BVMF48=380391383=106326270=13.84273=00:06:19271=300272=2014061037016=2014061037017=00:06:1937=80531946582289=40290=1
10:30:00.607: 659406 - 145 - 1128=935=X34=65940652=20140610-13:30:00.62175=20140610268=3279=0269=222=8207=BVMF48=380391383=106327270=13.84273=00:06:20271=300272=2014061037016=2014061037017=00:06:201500=E451=-0.051020=113500274=3277=L1003=3560288=8289=40279=0269=922=8207=BVMF48=380391383=106328270=13.876273=00:06:20272=201406101500=E279=2269=122=8207=BVMF48=380391383=106329273=00:06:20272=2014061037=80531946582289=40290=1
10:30:00.620: 659407 - 81 - 1128=935=X34=65940752=20140610-13:30:00.63475=20140610268=1279=0269=122=8207=BVMF48=380391383=106330270=13.89273=00:06:34271=700272=2014061037016=2014061037017=00:06:3337=80531946585289=8290=24
10:30:00.627: 659408 - 70 - 1128=935=X34=65940852=20140610-13:30:00.64175=20140610268=1279=2269=022=8207=BVMF48=380394783=65866273=00:06:41272=2014061037=80531942614288=3290=3
10:30:00.639: 659409 - 80 - 1128=935=X34=65940952=20140610-13:30:00.65375=20140610268=1279=0269=022=8207=BVMF48=380394783=65867270=17.02273=00:06:53271=600272=2014061037016=2014061037017=00:06:5337=80531946586288=3290=5
10:30:00.640: 659410 - 71 - 1128=935=X34=65941052=20140610-13:30:00.65575=20140610268=1279=2269=122=8207=BVMF48=380391383=106331273=00:06:54272=2014061037=80531946327289=3290=15
10:30:00.646: 659411 - 119 - 1128=935=X34=65941152=20140610-13:30:00.66075=20140610268=2279=2269=122=8207=BVMF48=380391383=106332273=00:06:60272=2014061037=80531945420289=40290=8279=0269=122=8207=BVMF48=380391383=106333270=13.85273=00:06:60271=100272=2014061037016=2014061037017=00:06:6037=80531946587289=40290=4
10:30:00.659: 659412 - 83 - 1128=935=X34=65941252=20140610-13:30:00.67375=20140610268=1279=0269=022=8207=BVMF48=380963983=256228270=25.9273=00:06:73271=1000272=2014061037016=2014061037017=00:06:7337=80531946588288=72290=183
10:30:00.660: 659413 - 81 - 1128=935=X34=65941352=20140610-13:30:00.67575=20140610268=1279=0269=022=8207=BVMF48=380968883=253616270=29.35273=00:06:74271=1000272=2014061037016=2014061037017=00:06:7437=80531946589288=72290=22
10:30:00.661: 659414 - 83 - 1128=935=X34=65941452=20140610-13:30:00.67575=20140610268=1279=0269=122=8207=BVMF48=380963983=256229270=26.44273=00:06:75271=300272=2014061037016=2014061037017=00:06:7537=80531946590289=227290=15
10:30:00.687: 659415 - 70 - 1128=935=X34=65941552=20140610-13:30:00.70175=20140610268=1279=2269=022=8207=BVMF48=380394783=65868273=00:07:01272=2014061037=80531946586288=3290=5
10:30:00.704: 659416 - 73 - 1128=935=X34=65941652=20140610-13:30:00.71975=20140610268=1279=2269=122=8207=BVMF48=380394783=65869273=00:07:18272=2014061037=80531945424289=227290=14
10:30:00.716: 659417 - 70 - 1128=935=X34=65941752=20140610-13:30:00.73175=20140610268=1279=2269=022=8207=BVMF48=380391383=106334273=00:07:30272=2014061037=80531946504288=8290=30
10:30:00.744: 659418 - 80 - 1128=935=X34=65941852=20140610-13:30:00.75975=20140610268=1279=0269=022=8207=BVMF48=380394783=65870270=17.01273=00:07:58271=600272=2014061037016=2014061037017=00:07:5837=80531946604288=3290=6
10:30:00.749: 659419 - 79 - 1128=935=X34=65941952=20140610-13:30:00.76475=20140610268=1279=1269=022=8207=BVMF48=380968883=253617270=29.38273=00:07:63271=2100272=2014061037016=2014061037017=00:04:0637=80531946607288=8290=7
10:30:00.763: 659420 - 81 - 1128=935=X34=65942052=20140610-13:30:00.77875=20140610268=1279=0269=122=8207=BVMF48=380391383=106335270=13.86273=00:07:77271=1100272=2014061037016=2014061037017=00:07:7737=80531946613289=3290=11
10:30:00.765: 659421 - 70 - 1128=935=X34=65942152=20140610-13:30:00.78075=20140610268=1279=2269=022=8207=BVMF48=380394783=65871273=00:07:79272=2014061037=80531946545288=8290=1
10:30:00.771: 659422 - 81 - 1128=935=X34=65942252=20140610-13:30:00.78575=20140610268=1279=0269=122=8207=BVMF48=380394783=65872270=17.07273=00:07:85271=400272=2014061037016=2014061037017=00:07:8537=80531946618289=8290=9
10:30:00.773: 659423 - 71 - 1128=935=X34=65942352=20140610-13:30:00.78875=20140610268=1279=2269=122=8207=BVMF48=380391383=106336273=00:07:87272=2014061037=80531946613289=3290=11
10:30:00.794: 659424 - 82 - 1128=935=X34=65942452=20140610-13:30:00.80975=20140610268=1279=0269=022=8207=BVMF48=380394783=65873270=16.98273=00:08:08271=400272=2014061037016=2014061037017=00:08:0837=80531946619288=110290=10
10:30:00.895: 659425 - 83 - 1128=935=X34=65942552=20140610-13:30:00.90975=20140610268=1279=0269=122=8207=BVMF48=380394783=65874270=17.11273=00:09:09271=800272=2014061037016=2014061037017=00:09:0937=80531946621289=227290=14
10:30:00.908: 659426 - 80 - 1128=935=X34=65942652=20140610-13:30:00.92375=20140610268=1279=0269=022=8207=BVMF48=380391383=106337270=13.79273=00:09:22271=100272=2014061037016=2014061037017=00:09:2237=80531946622288=8290=31
10:30:00.913: 659427 - 118 - 1128=935=X34=65942752=20140610-13:30:00.92775=20140610268=2279=2269=122=8207=BVMF48=386391783=2524273=00:09:27272=2014061037=80531942754289=63290=2279=0269=122=8207=BVMF48=386391783=2525270=9.35273=00:09:27271=97272=2014061037016=2014061037017=00:09:2637=80531946623289=63290=1
10:30:00.930: 659428 - 80 - 1128=935=X34=65942852=20140610-13:30:00.94475=20140610268=1279=0269=022=8207=BVMF48=380394783=65875270=17.02273=00:09:43271=400272=2014061037016=2014061037017=00:09:4337=80531946624288=8290=4
10:30:00.941: 659429 - 81 - 1128=935=X34=65942952=20140610-13:30:00.95575=20140610268=1279=0269=122=8207=BVMF48=380394783=65876270=17.07273=00:09:55271=100272=2014061037016=2014061037017=00:09:5437=80531946626289=8290=10
10:30:00.980: 659430 - 71 - 1128=935=X34=65943052=20140610-13:30:00.99575=20140610268=1279=2269=122=8207=BVMF48=380394783=65877273=00:09:94272=2014061037=80531946618289=8290=9
10:30:00.985: 659431 - 70 - 1128=935=X34=65943152=20140610-13:30:01.00075=20140610268=1279=2269=022=8207=BVMF48=380394783=65878273=00:09:99272=2014061037=80531946624288=8290=4
10:30:01.013: 659432 - 80 - 1128=935=X34=65943252=20140610-13:30:01.02775=20140610268=1279=0269=022=8207=BVMF48=380394783=65879270=17.01273=00:10:27271=400272=2014061037016=2014061037017=00:10:2737=80531946627288=8290=6
10:30:01.037: 659433 - 158 - 1128=935=X34=65943352=20140610-13:30:01.05175=20140610268=3279=0269=222=8207=BVMF48=380391383=106338270=13.85273=00:10:50271=100272=2014061037016=2014061037017=00:10:501500=E451=-0.041020=113600274=01003=3570288=8289=227279=0269=922=8207=BVMF48=380391383=106339270=13.876273=00:10:50272=201406101500=E279=1269=122=8207=BVMF48=380391383=106340270=13.85273=00:10:50271=1100272=2014061037016=2014061037017=00:03:7237=80531946502289=227290=1
10:30:01.047: 659434 - 156 - 1128=935=X34=65943452=20140610-13:30:01.06175=20140610268=3279=0269=222=8207=BVMF48=380968883=253618270=29.39273=00:10:60271=100272=2014061037016=2014061037017=00:10:601500=E451=-0.241020=457900274=21003=6720288=8289=77279=0269=922=8207=BVMF48=380968883=253619270=29.476273=00:10:60272=201406101500=E279=1269=122=8207=BVMF48=380968883=253620270=29.39273=00:10:60271=200272=2014061037016=2014061037017=00:04:8937=80531946570289=77290=1
10:30:01.048: 659435 - 145 - 1128=935=X34=65943552=20140610-13:30:01.06375=20140610268=3279=0269=222=8207=BVMF48=380968883=253621270=29.39273=00:10:62271=200272=2014061037016=2014061037017=00:10:621500=E451=-0.241020=458100274=3277=L1003=6730288=8289=77279=0269=922=8207=BVMF48=380968883=253622270=29.476273=00:10:62272=201406101500=E279=2269=122=8207=BVMF48=380968883=253623273=00:10:62272=2014061037=80531946570289=77290=1
10:30:01.050: 659436 - 80 - 1128=935=X34=65943652=20140610-13:30:01.06475=20140610268=1279=0269=022=8207=BVMF48=380968883=253624270=29.39273=00:10:63271=1300272=2014061037016=2014061037017=00:10:6337=80531946631288=8290=1
10:30:01.059: 659437 - 82 - 1128=935=X34=65943752=20140610-13:30:01.07375=20140610268=1279=0269=122=8207=BVMF48=380968883=253625270=29.4273=00:10:73271=300272=2014061037016=2014061037017=00:10:7237=80531946632289=8290=3
10:30:01.059: 659438 - 71 - 1128=935=X34=65943852=20140610-13:30:01.07475=20140610268=1279=2269=022=8207=BVMF48=380968883=253626273=00:10:73272=2014061037=80531946541288=40290=9
10:30:01.061: 659439 - 118 - 1128=935=X34=65943952=20140610-13:30:01.07675=20140610268=2279=2269=022=8207=BVMF48=380968883=253627273=00:10:75272=2014061037=80531946400288=40290=7279=0269=022=8207=BVMF48=380968883=253628270=29.39273=00:10:75271=100272=2014061037016=2014061037017=00:10:7537=80531946633288=40290=2
10:30:01.062: 659440 - 118 - 1128=935=X34=65944052=20140610-13:30:01.07775=20140610268=2279=2269=022=8207=BVMF48=380968883=253629273=00:10:76272=2014061037=80531946195288=40290=7279=0269=022=8207=BVMF48=380968883=253630270=29.39273=00:10:76271=700272=2014061037016=2014061037017=00:10:7637=80531946634288=40290=3
10:30:01.065: 659441 - 118 - 1128=935=X34=65944152=20140610-13:30:01.07975=20140610268=2279=2269=022=8207=BVMF48=380968883=253631273=00:10:79272=2014061037=80531945232288=45290=5279=0269=022=8207=BVMF48=380968883=253632270=29.39273=00:10:79271=1300272=2014061037016=2014061037017=00:10:7937=80531946635288=45290=4
10:30:01.066: 659442 - 81 - 1128=935=X34=65944252=20140610-13:30:01.08075=20140610268=1279=0269=122=8207=BVMF48=380963983=256230270=26.43273=00:10:80271=100272=2014061037016=2014061037017=00:10:8037=80531946636289=8290=9
10:30:01.074: 659443 - 81 - 1128=935=X34=65944352=20140610-13:30:01.08875=20140610268=1279=0269=022=8207=BVMF48=380968883=253633270=29.39273=00:10:88271=300272=2014061037016=2014061037017=00:10:8837=80531946637288=40290=5
10:30:01.088: 659444 - 71 - 1128=935=X34=65944452=20140610-13:30:01.10275=20140610268=1279=2269=022=8207=BVMF48=380968883=253634273=00:11:01272=2014061037=80531946637288=40290=5
10:30:01.097: 659445 - 70 - 1128=935=X34=65944552=20140610-13:30:01.11275=20140610268=1279=2269=022=8207=BVMF48=380968883=253635273=00:11:11272=2014061037=80531941717288=8290=49
10:30:01.099: 659446 - 116 - 1128=935=X34=65944652=20140610-13:30:01.11375=20140610268=2279=2269=122=8207=BVMF48=389774183=6747273=00:11:13272=2014061037=80531945487289=3290=2279=0269=122=8207=BVMF48=389774183=6748270=13.86273=00:11:13271=99272=2014061037016=2014061037017=00:11:1337=80531946638289=3290=1
10:30:01.106: 659447 - 115 - 1128=935=X34=65944752=20140610-13:30:01.12175=20140610268=2279=2269=022=8207=BVMF48=390102283=4017273=00:11:21272=2014061037=80531942636288=3290=1279=0269=022=8207=BVMF48=390102283=4018270=17.01273=00:11:21271=96272=2014061037016=2014061037017=00:11:2037=80531946639288=3290=2
10:30:01.118: 659448 - 71 - 1128=935=X34=65944852=20140610-13:30:01.13275=20140610268=1279=2269=122=8207=BVMF48=380968883=253636273=00:11:32272=2014061037=80531946632289=8290=3
10:30:01.120: 659449 - 70 - 1128=935=X34=65944952=20140610-13:30:01.13475=20140610268=1279=2269=022=8207=BVMF48=380391383=106341273=00:11:33272=2014061037=80531945316288=8290=16
10:30:01.218: 659450 - 80 - 1128=935=X34=65945052=20140610-13:30:01.23075=20140610268=1279=0269=022=8207=BVMF48=380968883=253637270=29.39273=00:12:30271=300272=2014061037016=2014061037017=00:12:3037=80531946650288=8290=5
10:30:01.219: 659451 - 71 - 1128=935=X34=65945152=20140610-13:30:01.23475=20140610268=1279=2269=122=8207=BVMF48=380963983=256231273=00:12:33272=2014061037=80531946636289=8290=9
10:30:01.225: 659452 - 70 - 1128=935=X34=65945252=20140610-13:30:01.23975=20140610268=1279=2269=022=8207=BVMF48=380968883=253638273=00:12:39272=2014061037=80531946111288=8290=14
10:30:01.233: 659453 - 70 - 1128=935=X34=65945352=20140610-13:30:01.24775=20140610268=1279=2269=022=8207=BVMF48=380968883=253639273=00:12:47272=2014061037=80531946607288=8290=9
10:30:01.261: 659454 - 81 - 1128=935=X34=65945452=20140610-13:30:01.27575=20140610268=1279=0269=122=8207=BVMF48=380963983=256232270=26.43273=00:12:74271=2500272=2014061037016=2014061037017=00:12:7437=80531946651289=8290=9
10:30:01.340: 659455 - 70 - 1128=935=X34=65945552=20140610-13:30:01.35575=20140610268=1279=2269=022=8207=BVMF48=380968883=253640273=00:13:54272=2014061037=80531943648288=8290=24
10:30:01.429: 659456 - 119 - 1128=935=X34=65945652=20140610-13:30:01.44475=20140610268=2279=2269=122=8207=BVMF48=380391383=106342273=00:14:43272=2014061037=80531946517289=40290=9279=0269=122=8207=BVMF48=380391383=106343270=13.88273=00:14:43271=4700272=2014061037016=2014061037017=00:14:4337=80531946699289=40290=18
10:30:01.459: 659457 - 158 - 1128=935=X34=65945752=20140610-13:30:01.47375=20140610268=3279=0269=222=8207=BVMF48=380391383=106344270=13.83273=00:14:73271=100272=2014061037016=2014061037017=00:14:721500=E451=-0.061020=113700274=21003=3580288=39289=238279=0269=922=8207=BVMF48=380391383=106345270=13.876273=00:14:73272=201406101500=E279=1269=022=8207=BVMF48=380391383=106346270=13.83273=00:14:73271=1600272=2014061037016=2014061037017=25:97:0537=80531848615288=39290=1
10:30:01.467: 659458 - 118 - 1128=935=X34=65945852=20140610-13:30:01.48175=20140610268=2279=2269=122=8207=BVMF48=386391783=2526273=00:14:81272=2014061037=80531946623289=63290=1279=0269=122=8207=BVMF48=386391783=2527270=9.36273=00:14:81271=97272=2014061037016=2014061037017=00:14:8137=80531946702289=63290=2
10:30:01.524: 659459 - 120 - 1128=935=X34=65945952=20140610-13:30:01.53875=20140610268=2279=2269=122=8207=BVMF48=380968883=253641273=00:15:38272=2014061037=80531944214289=13290=3279=0269=122=8207=BVMF48=380968883=253642270=29.4273=00:15:38271=1300272=2014061037016=2014061037017=00:15:3837=80531946703289=13290=3
10:30:01.528: 659460 - 81 - 1128=935=X34=65946052=20140610-13:30:01.54375=20140610268=1279=0269=022=8207=BVMF48=380963983=256233270=26.41273=00:15:42271=100272=2014061037016=2014061037017=00:15:4237=80531946704288=70290=7
10:30:01.541: 659461 - 80 - 1128=935=X34=65946152=20140610-13:30:01.55575=20140610268=1279=0269=022=8207=BVMF48=380968883=253643270=29.33273=00:15:55271=100272=2014061037016=2014061037017=00:15:5437=80531946705288=8290=27
10:30:01.605: 659462 - 70 - 1128=935=X34=65946252=20140610-13:30:01.61975=20140610268=1279=2269=022=8207=BVMF48=380391383=106347273=00:16:19272=2014061037=80531946622288=8290=30
10:30:01.619: 659463 - 70 - 1128=935=X34=65946352=20140610-13:30:01.63475=20140610268=1279=2269=022=8207=BVMF48=380391383=106348273=00:16:33272=2014061037=80531945315288=8290=21
10:30:01.620: 659464 - 146 - 1128=935=X34=65946452=20140610-13:30:01.63475=20140610268=3279=0269=222=8207=BVMF48=380249383=103608270=9.34273=00:16:34271=100272=2014061037016=2014061037017=00:16:331500=E451=-0.111020=264100274=1277=L1003=3910288=40289=13279=0269=922=8207=BVMF48=380249383=103609270=9.381273=00:16:34272=201406101500=E279=2269=022=8207=BVMF48=380249383=103610273=00:16:34272=2014061037=80531946546288=40290=1
10:30:01.620: 659465 - 71 - 1128=935=X34=65946552=20140610-13:30:01.63575=20140610268=1279=2269=122=8207=BVMF48=380391383=106349273=00:16:34272=2014061037=80531872522289=8290=47
10:30:01.620: 659466 - 81 - 1128=935=X34=65946652=20140610-13:30:01.63575=20140610268=1279=0269=122=8207=BVMF48=380391383=106350270=13.88273=00:16:34271=700272=2014061037016=2014061037017=00:16:3437=80531946707289=8290=19
10:30:01.628: 659467 - 70 - 1128=935=X34=65946752=20140610-13:30:01.64375=20140610268=1279=2269=022=8207=BVMF48=380249383=103611273=00:16:42272=2014061037=80531942680288=8290=18
10:30:01.636: 659468 - 159 - 1128=935=X34=65946852=20140610-13:30:01.65075=20140610268=3279=0269=222=8207=BVMF48=380249383=103612270=9.33273=00:16:50271=200272=2014061037016=2014061037017=00:16:491500=E451=-0.121020=264300274=21003=3920288=127289=13279=0269=922=8207=BVMF48=380249383=103613270=9.381273=00:16:50272=201406101500=E279=1269=022=8207=BVMF48=380249383=103614270=9.33273=00:16:50271=2200272=2014061037016=2014061037017=75:48:4737=80531940535288=127290=1
10:30:01.637: 659469 - 81 - 1128=935=X34=65946952=20140610-13:30:01.65275=20140610268=1279=0269=122=8207=BVMF48=380249383=103615270=9.34273=00:16:51271=100272=2014061037016=2014061037017=00:16:5137=80531946719289=8290=1
10:30:01.646: 659470 - 81 - 1128=935=X34=65947052=20140610-13:30:01.66175=20140610268=1279=0269=122=8207=BVMF48=380249383=103616270=9.35273=00:16:60271=100272=2014061037016=2014061037017=00:16:6037=80531946738289=8290=13
10:30:01.646: 659471 - 71 - 1128=935=X34=65947152=20140610-13:30:01.66175=20140610268=1279=2269=122=8207=BVMF48=380249383=103617273=00:16:61272=2014061037=80531946738289=8290=13
10:30:01.654: 659472 - 201 - 1128=935=X34=65947252=20140610-13:30:01.66975=20140610268=4279=0269=222=8207=BVMF48=380249383=103618270=9.33273=00:16:68271=100272=2014061037016=2014061037017=00:16:681500=E451=-0.121020=264400274=3277=L1003=3930288=127289=735279=0269=922=8207=BVMF48=380249383=103619270=9.381273=00:16:68272=201406101500=E279=1269=022=8207=BVMF48=380249383=103620270=9.33273=00:16:68271=2100272=2014061037016=2014061037017=75:48:4737=80531940535288=127290=1279=2269=122=8207=BVMF48=380249383=103621273=00:16:68272=2014061037=80531946480289=735290=11
10:30:01.668: 659473 - 83 - 1128=935=X34=65947352=20140610-13:30:01.68375=20140610268=1279=0269=122=8207=BVMF48=380249383=103622270=9.34273=00:16:83271=100272=2014061037016=2014061037017=00:16:8237=80531946751289=735290=2
10:30:01.674: 659474 - 70 - 1128=935=X34=65947452=20140610-13:30:01.68875=20140610268=1279=2269=022=8207=BVMF48=380394783=65880273=00:16:88272=2014061037=80531946222288=8290=10
10:30:01.700: 659475 - 73 - 1128=935=X34=65947552=20140610-13:30:01.71475=20140610268=1279=2269=122=8207=BVMF48=380963983=256234273=00:17:14272=2014061037=80531946590289=227290=16
10:30:01.745: 659476 - 80 - 1128=935=X34=65947652=20140610-13:30:01.76075=20140610268=1279=0269=022=8207=BVMF48=380391383=106351270=13.78273=00:17:59271=400272=2014061037016=2014061037017=00:17:5937=80531946752288=8290=34
10:30:01.865: 659477 - 83 - 1128=935=X34=65947752=20140610-13:30:01.87975=20140610268=1279=0269=122=8207=BVMF48=380963983=256235270=26.44273=00:18:79271=1000272=2014061037016=2014061037017=00:18:7937=80531946766289=227290=16
10:30:01.910: 659478 - 118 - 1128=935=X34=65947852=20140610-13:30:01.92475=20140610268=2279=2269=122=8207=BVMF48=386391783=2528273=00:19:24272=2014061037=80531946702289=63290=2279=0269=122=8207=BVMF48=386391783=2529270=9.49273=00:19:24271=97272=2014061037016=2014061037017=00:19:2337=80531946767289=63290=2
10:30:02.066: 659479 - 154 - 1128=935=X34=65947952=20140610-13:30:02.08075=20140610268=3279=0269=222=8207=BVMF48=380968883=253644270=29.39273=00:20:80271=100272=2014061037016=2014061037017=00:20:791500=E451=-0.241020=458200274=3277=L1003=6740288=8289=8279=0269=922=8207=BVMF48=380968883=253645270=29.476273=00:20:80272=201406101500=E279=1269=022=8207=BVMF48=380968883=253646270=29.39273=00:20:80271=1200272=2014061037016=2014061037017=00:10:6337=80531946631288=8290=1
10:30:02.066: 659480 - 158 - 1128=935=X34=65948052=20140610-13:30:02.08175=20140610268=3279=0269=222=8207=BVMF48=380963983=256236270=26.41273=00:20:80271=100272=2014061037016=2014061037017=00:20:801500=E451=-0.21020=1446800274=3277=L1003=19600288=45289=8279=0269=922=8207=BVMF48=380963983=256237270=26.468273=00:20:80272=201406101500=E279=1269=022=8207=BVMF48=380963983=256238270=26.41273=00:20:80271=600272=2014061037016=2014061037017=93:99:7137=80531946066288=45290=1
10:30:02.067: 659481 - 70 - 1128=935=X34=65948152=20140610-13:30:02.08175=20140610268=1279=2269=022=8207=BVMF48=380968883=253647273=00:20:81272=2014061037=80531946650288=8290=5
10:30:02.080: 659482 - 80 - 1128=935=X34=65948252=20140610-13:30:02.09475=20140610268=1279=1269=022=8207=BVMF48=380963983=256239270=26.41273=00:20:94271=500272=2014061037016=2014061037017=93:99:7137=80531946770288=45290=1
10:30:02.105: 659483 - 80 - 1128=935=X34=65948352=20140610-13:30:02.12075=20140610268=1279=1269=022=8207=BVMF48=380963983=256240270=26.41273=00:21:19271=400272=2014061037016=2014061037017=93:99:7137=80531946771288=45290=1
10:30:02.112: 659484 - 80 - 1128=935=X34=65948452=20140610-13:30:02.12775=20140610268=1279=1269=022=8207=BVMF48=380963983=256241270=26.41273=00:21:27271=300272=2014061037016=2014061037017=93:99:7137=80531946772288=45290=1
10:30:02.120: 659485 - 80 - 1128=935=X34=65948552=20140610-13:30:02.13475=20140610268=1279=1269=022=8207=BVMF48=380963983=256242270=26.41273=00:21:34271=200272=2014061037016=2014061037017=93:99:7137=80531946773288=45290=1
10:30:02.126: 659486 - 80 - 1128=935=X34=65948652=20140610-13:30:02.14075=20140610268=1279=1269=022=8207=BVMF48=380963983=256243270=26.41273=00:21:40271=100272=2014061037016=2014061037017=93:99:7137=80531946774288=45290=1
10:30:02.131: 659487 - 71 - 1128=935=X34=65948752=20140610-13:30:02.14675=20140610268=1279=2269=022=8207=BVMF48=380963983=256244273=00:21:45272=2014061037=80531946774288=45290=1
10:30:02.145: 659488 - 81 - 1128=935=X34=65948852=20140610-13:30:02.16075=20140610268=1279=0269=022=8207=BVMF48=380963983=256245270=26.41273=00:21:59271=1800272=2014061037016=2014061037017=00:21:5937=80531946788288=45290=7
10:30:02.423: 659489 - 119 - 1128=935=X34=65948952=20140610-13:30:02.43875=20140610268=2279=2269=122=8207=BVMF48=380394783=65881273=00:24:37272=2014061037=80531946269289=23290=3279=0269=122=8207=BVMF48=380394783=65882270=17.09273=00:24:37271=100272=2014061037016=2014061037017=00:24:3737=80531946804289=23290=10
10:30:02.434: 659490 - 159 - 1128=935=X34=65949052=20140610-13:30:02.44975=20140610268=3279=0269=222=8207=BVMF48=380249383=103623270=9.33273=00:24:48271=100272=2014061037016=2014061037017=00:24:481500=E451=-0.121020=264500274=3277=L1003=3940288=127289=13279=0269=922=8207=BVMF48=380249383=103624270=9.381273=00:24:48272=201406101500=E279=1269=022=8207=BVMF48=380249383=103625270=9.33273=00:24:48271=2000272=2014061037016=2014061037017=75:48:4737=80531940535288=127290=1
10:30:02.437: 659491 - 81 - 1128=935=X34=65949152=20140610-13:30:02.45275=20140610268=1279=0269=122=8207=BVMF48=380968883=253648270=29.41273=00:24:51271=100272=2014061037016=2014061037017=00:24:5137=80531946806289=3290=5
10:30:02.438: 659492 - 70 - 1128=935=X34=65949252=20140610-13:30:02.45375=20140610268=1279=2269=022=8207=BVMF48=380968883=253649273=00:24:52272=2014061037=80531946631288=8290=1
10:30:02.444: 659493 - 118 - 1128=935=X34=65949352=20140610-13:30:02.45975=20140610268=2279=2269=122=8207=BVMF48=386391783=2530273=00:24:58272=2014061037=80531946767289=63290=2279=0269=122=8207=BVMF48=386391783=2531270=9.35273=00:24:58271=97272=2014061037016=2014061037017=00:24:5837=80531946807289=63290=1
10:30:02.452: 659494 - 159 - 1128=935=X34=65949452=20140610-13:30:02.46675=20140610268=3279=0269=222=8207=BVMF48=380249383=103626270=9.33273=00:24:65271=100272=2014061037016=2014061037017=00:24:651500=E451=-0.121020=264600274=3277=L1003=3950288=127289=13279=0269=922=8207=BVMF48=380249383=103627270=9.381273=00:24:65272=201406101500=E279=1269=022=8207=BVMF48=380249383=103628270=9.33273=00:24:65271=1900272=2014061037016=2014061037017=75:48:4737=80531940535288=127290=1
10:30:02.460: 659495 - 80 - 1128=935=X34=65949552=20140610-13:30:02.47575=20140610268=1279=1269=022=8207=BVMF48=380968883=253650270=29.39273=00:24:74271=800272=2014061037016=2014061037017=00:10:7937=80531946809288=45290=3
10:30:02.485: 659496 - 201 - 1128=935=X34=65949652=20140610-13:30:02.50075=20140610268=4279=0269=222=8207=BVMF48=380249383=103629270=9.33273=00:24:99271=100272=2014061037016=2014061037017=00:24:991500=E451=-0.121020=264700274=3277=L1003=3960288=127289=735279=0269=922=8207=BVMF48=380249383=103630270=9.381273=00:24:99272=201406101500=E279=1269=022=8207=BVMF48=380249383=103631270=9.33273=00:24:99271=1800272=2014061037016=2014061037017=75:48:4737=80531940535288=127290=1279=2269=122=8207=BVMF48=380249383=103632273=00:24:99272=2014061037=80531946751289=735290=2
10:30:02.496: 659497 - 83 - 1128=935=X34=65949752=20140610-13:30:02.51175=20140610268=1279=0269=122=8207=BVMF48=380249383=103633270=9.34273=00:25:10271=100272=2014061037016=2014061037017=00:25:1037=80531946811289=735290=2
10:30:02.594: 659498 - 82 - 1128=935=X34=65949852=20140610-13:30:02.60875=20140610268=1279=0269=122=8207=BVMF48=380968883=253651270=29.4273=00:26:08271=300272=2014061037016=2014061037017=00:26:0837=80531946816289=8290=4
10:30:02.602: 659499 - 70 - 1128=935=X34=65949952=20140610-13:30:02.61775=20140610268=1279=2269=022=8207=BVMF48=380968883=253652273=00:26:16272=2014061037=80531946572288=3290=7
10:30:02.603: 659500 - 82 - 1128=935=X34=65950052=20140610-13:30:02.61775=20140610268=1279=0269=122=8207=BVMF48=380968883=253653270=29.4273=00:26:17271=100272=2014061037016=2014061037017=00:26:1637=80531946819289=3290=5
10:30:02.609: 659501 - 81 - 1128=935=X34=65950152=20140610-13:30:02.62475=20140610268=1279=0269=122=8207=BVMF48=380968883=253654270=29.41273=00:26:23271=100272=2014061037016=2014061037017=00:26:2337=80531946820289=3290=8
10:30:02.618: 659502 - 72 - 1128=935=X34=65950252=20140610-13:30:02.63275=20140610268=1279=2269=122=8207=BVMF48=380249383=103634273=00:26:31272=2014061037=80531945500289=70290=9
10:30:02.627: 659503 - 72 - 1128=935=X34=65950352=20140610-13:30:02.64175=20140610268=1279=2269=122=8207=BVMF48=380394783=65883273=00:26:41272=2014061037=80531946323289=70290=5
10:30:02.715: 659504 - 81 - 1128=935=X34=65950452=20140610-13:30:02.73075=20140610268=1279=0269=122=8207=BVMF48=380965483=79817270=8.19273=00:27:29271=500272=2014061037016=2014061037017=00:27:2937=80531946821289=3290=6
10:30:02.718: 659505 - 81 - 1128=935=X34=65950552=20140610-13:30:02.73275=20140610268=1279=0269=122=8207=BVMF48=380968883=253655270=29.41273=00:27:32271=1000272=2014061037016=2014061037017=00:27:3237=80531946822289=3290=9
10:30:02.723: 659506 - 70 - 1128=935=X34=65950652=20140610-13:30:02.73875=20140610268=1279=2269=022=8207=BVMF48=380965483=79818273=00:27:37272=2014061037=80531895961288=3290=6
10:30:02.817: 659507 - 71 - 1128=935=X34=65950752=20140610-13:30:02.83175=20140610268=1279=2269=022=8207=BVMF48=380968883=253656273=00:28:31272=2014061037=80531945259288=70290=5
10:30:02.830: 659508 - 82 - 1128=935=X34=65950852=20140610-13:30:02.84575=20140610268=1279=0269=122=8207=BVMF48=380249383=103635270=9.34273=00:28:44271=700272=2014061037016=2014061037017=00:28:4437=80531946823289=70290=3
10:30:02.840: 659509 - 82 - 1128=935=X34=65950952=20140610-13:30:02.85575=20140610268=1279=0269=122=8207=BVMF48=380394783=65884270=17.05273=00:28:54271=100272=2014061037016=2014061037017=00:28:5437=80531946827289=70290=3
10:30:02.850: 659510 - 81 - 1128=935=X34=65951052=20140610-13:30:02.86575=20140610268=1279=0269=122=8207=BVMF48=380391383=106352270=13.86273=00:28:64271=1100272=2014061037016=2014061037017=00:28:6437=80531946828289=3290=10
10:30:02.930: 659511 - 82 - 1128=935=X34=65951152=20140610-13:30:02.94475=20140610268=1279=0269=122=8207=BVMF48=380968883=253657270=29.4273=00:29:44271=100272=2014061037016=2014061037017=00:29:4437=80531946832289=9290=6
10:30:02.974: 659512 - 73 - 1128=935=X34=65951252=20140610-13:30:02.98975=20140610268=1279=2269=122=8207=BVMF48=380391383=106353273=00:29:88272=2014061037=80531946579289=238290=9
10:30:03.033: 659513 - 81 - 1128=935=X34=65951352=20140610-13:30:03.04875=20140610268=1279=0269=022=8207=BVMF48=380968883=253658270=29.39273=00:30:47271=300272=2014061037016=2014061037017=00:30:4737=80531946833288=70290=4
10:30:03.074: 659514 - 82 - 1128=935=X34=65951452=20140610-13:30:03.08875=20140610268=1279=0269=122=8207=BVMF48=380249383=103636270=9.34273=00:30:88271=600272=2014061037016=2014061037017=00:30:8837=80531946834289=40290=4
10:30:03.164: 659515 - 83 - 1128=935=X34=65951552=20140610-13:30:03.17975=20140610268=1279=0269=122=8207=BVMF48=380391383=106354270=13.85273=00:31:78271=100272=2014061037016=2014061037017=00:31:7837=80531946835289=238290=5
10:30:03.205: 659516 - 118 - 1128=935=X34=65951652=20140610-13:30:03.21975=20140610268=2279=2269=022=8207=BVMF48=380391383=106355273=00:32:18272=2014061037=80531946530288=40290=28279=0269=022=8207=BVMF48=380391383=106356270=13.81273=00:32:18271=4700272=2014061037016=2014061037017=00:32:1837=80531946836288=40290=16
10:30:03.328: 659517 - 82 - 1128=935=X34=65951752=20140610-13:30:03.34275=20140610268=1279=0269=122=8207=BVMF48=380394783=65885270=17.05273=00:33:42271=100272=2014061037016=2014061037017=00:33:4137=80531946838289=40290=4
10:30:03.359: 659518 - 73 - 1128=935=X34=65951852=20140610-13:30:03.37375=20140610268=1279=2269=122=8207=BVMF48=380391383=106357273=00:33:72272=2014061037=80531946502289=227290=1
10:30:03.373: 659519 - 73 - 1128=935=X34=65951952=20140610-13:30:03.38875=20140610268=1279=2269=122=8207=BVMF48=380394783=65886273=00:33:87272=2014061037=80531946621289=227290=15
10:30:03.401: 659520 - 83 - 1128=935=X34=65952052=20140610-13:30:03.41675=20140610268=1279=0269=122=8207=BVMF48=380394783=65887270=17.11273=00:34:15271=400272=2014061037016=2014061037017=00:34:1537=80531946839289=227290=15
10:30:03.460: 659521 - 82 - 1128=935=X34=65952152=20140610-13:30:03.47475=20140610268=1279=0269=122=8207=BVMF48=380963983=256246270=26.52273=00:34:74271=500272=2014061037016=2014061037017=00:34:7337=80531946840289=82290=61
10:30:04.103: 659522 - 71 - 1128=935=X34=65952252=20140610-13:30:04.11875=20140610268=1279=2269=122=8207=BVMF48=380968883=253659273=00:41:17272=2014061037=80531946816289=8290=4
10:30:04.274: 659523 - 119 - 1128=935=X34=65952352=20140610-13:30:04.28875=20140610268=2279=2269=122=8207=BVMF48=380391383=106358273=00:42:88272=2014061037=80531946699289=40290=18279=0269=122=8207=BVMF48=380391383=106359270=13.87273=00:42:88271=4700272=2014061037016=2014061037017=00:42:8737=80531946847289=40290=14
10:30:04.281: 659524 - 70 - 1128=935=X34=65952452=20140610-13:30:04.29675=20140610268=1279=2269=022=8207=BVMF48=380391383=106360273=00:42:95272=2014061037=80531938861288=3290=3
10:30:04.384: 659525 - 154 - 1128=935=X34=65952552=20140610-13:30:04.39975=20140610268=3279=0269=222=8207=BVMF48=380965483=79819270=8.19273=00:43:98271=500272=2014061037016=2014061037017=00:43:971500=E451=-0.091020=295500274=01003=3470288=72289=8279=0269=922=8207=BVMF48=380965483=79820270=8.237273=00:43:98272=201406101500=E279=1269=122=8207=BVMF48=380965483=79821270=8.19273=00:43:98271=10400272=2014061037016=2014061037017=92:97:1537=80531945314289=8290=1
10:30:04.420: 659526 - 72 - 1128=935=X34=65952652=20140610-13:30:04.43575=20140610268=1279=2269=122=8207=BVMF48=380394783=65888273=00:44:34272=2014061037=80531946838289=40290=4
10:30:04.431: 659527 - 71 - 1128=935=X34=65952752=20140610-13:30:04.44575=20140610268=1279=2269=122=8207=BVMF48=380391383=106361273=00:44:45272=2014061037=80531946828289=3290=9
10:30:04.474: 659528 - 83 - 1128=935=X34=65952852=20140610-13:30:04.48975=20140610268=1279=0269=122=8207=BVMF48=380965483=79822270=8.21273=00:44:88271=700272=2014061037016=2014061037017=00:44:8837=80531946850289=735290=14
10:30:04.530: 659529 - 80 - 1128=935=X34=65952952=20140610-13:30:04.54475=20140610268=1279=0269=022=8207=BVMF48=380968883=253660270=29.39273=00:45:44271=300272=2014061037016=2014061037017=00:45:4337=80531946851288=8290=5
10:30:04.656: 659530 - 83 - 1128=935=X34=65953052=20140610-13:30:04.67175=20140610268=1279=0269=122=8207=BVMF48=380968883=253661270=29.4273=00:46:70271=300272=2014061037016=2014061037017=00:46:7037=80531946852289=77290=6
10:30:04.925: 659531 - 119 - 1128=935=X34=65953152=20140610-13:30:04.94075=20140610268=2279=2269=122=8207=BVMF48=380391383=106362273=00:49:39272=2014061037=80531946847289=40290=13279=0269=122=8207=BVMF48=380391383=106363270=13.88273=00:49:39271=4700272=2014061037016=2014061037017=00:49:3937=80531946856289=40290=18
10:30:04.952: 659532 - 72 - 1128=935=X34=65953252=20140610-13:30:04.96675=20140610268=1279=2269=122=8207=BVMF48=380391383=106364273=00:49:66272=2014061037=80531946587289=40290=3
10:30:05.104: 659533 - 70 - 1128=935=X34=65953352=20140610-13:30:05.11875=20140610268=1279=2269=022=8207=BVMF48=380968883=253662273=00:51:18272=2014061037=80531946851288=8290=5
10:30:05.108: 659534 - 82 - 1128=935=X34=65953452=20140610-13:30:05.12275=20140610268=1279=0269=122=8207=BVMF48=380968883=253663270=29.4273=00:51:22271=300272=2014061037016=2014061037017=00:51:2237=80531946857289=8290=7
10:30:05.114: 659535 - 70 - 1128=935=X34=65953552=20140610-13:30:05.12875=20140610268=1279=2269=022=8207=BVMF48=380968883=253664273=00:51:28272=2014061037=80531946027288=3290=9
10:30:05.141: 659536 - 71 - 1128=935=X34=65953652=20140610-13:30:05.15675=20140610268=1279=2269=122=8207=BVMF48=380249383=103637273=00:51:55272=2014061037=80531944070289=8290=17
10:30:05.155: 659537 - 116 - 1128=935=X34=65953752=20140610-13:30:05.17075=20140610268=2279=2269=022=8207=BVMF48=380249383=103638273=00:51:69272=2014061037=80531928659288=3290=44279=0269=022=8207=BVMF48=380249383=103639270=9.24273=00:51:69271=1600272=2014061037016=2014061037017=00:51:6937=80531946858288=3290=46
10:30:05.244: 659538 - 119 - 1128=935=X34=65953852=20140610-13:30:05.25975=20140610268=2279=2269=122=8207=BVMF48=380394783=65889273=00:52:58272=2014061037=80531946379289=45290=23279=0269=122=8207=BVMF48=380394783=65890270=17.15273=00:52:58271=1000272=2014061037016=2014061037017=00:52:5837=80531946859289=45290=22
10:30:05.401: 659539 - 81 - 1128=935=X34=65953952=20140610-13:30:05.41575=20140610268=1279=0269=022=8207=BVMF48=380394783=65891270=17.01273=00:54:15271=1000272=2014061037016=2014061037017=00:54:1537=80531946864288=45290=7
10:30:05.557: 659540 - 70 - 1128=935=X34=65954052=20140610-13:30:05.57275=20140610268=1279=2269=022=8207=BVMF48=380968883=253665273=00:55:71272=2014061037=80531945485288=8290=6
10:30:05.705: 659541 - 80 - 1128=935=X34=65954152=20140610-13:30:05.72075=20140610268=1279=0269=022=8207=BVMF48=380968883=253666270=29.38273=00:57:20271=300272=2014061037016=2014061037017=00:57:1937=80531946873288=8290=6
10:30:06.042: 659542 - 80 - 1128=935=X34=65954252=20140610-13:30:06.05675=20140610268=1279=0269=022=8207=BVMF48=380963983=256247270=26.39273=00:60:56271=100272=2014061037016=2014061037017=00:60:5637=80531946877288=3290=18
10:30:06.139: 659543 - 118 - 1128=935=X34=65954352=20140610-13:30:06.15375=20140610268=2279=2269=022=8207=BVMF48=380963983=256248273=00:61:53272=2014061037=80531946180288=45290=76279=0269=022=8207=BVMF48=380963983=256249270=26.41273=00:61:53271=5000272=2014061037016=2014061037017=00:61:5337=80531946880288=45290=8
10:30:06.140: 659544 - 72 - 1128=935=X34=65954452=20140610-13:30:06.15575=20140610268=1279=2269=122=8207=BVMF48=380963983=256250273=00:61:54272=2014061037=80531946456289=45290=8
10:30:06.140: 659545 - 119 - 1128=935=X34=65954552=20140610-13:30:06.15575=20140610268=2279=2269=022=8207=BVMF48=380963983=256251273=00:61:55272=2014061037=80531946571288=45290=84279=0269=022=8207=BVMF48=380963983=256252270=26.4273=00:61:55271=3000272=2014061037016=2014061037017=00:61:5437=80531946881288=45290=12
10:30:06.163: 659546 - 72 - 1128=935=X34=65954652=20140610-13:30:06.17875=20140610268=1279=2269=122=8207=BVMF48=380963983=256253273=00:61:77272=2014061037=80531946299289=40290=5
10:30:06.341: 659547 - 82 - 1128=935=X34=65954752=20140610-13:30:06.35675=20140610268=1279=0269=122=8207=BVMF48=380963983=256254270=26.53273=00:63:55271=3000272=2014061037016=2014061037017=00:63:5537=80531946907289=45290=62
10:30:06.439: 659548 - 81 - 1128=935=X34=65954852=20140610-13:30:06.45475=20140610268=1279=1269=122=8207=BVMF48=380963983=256255270=26.42273=00:64:54271=1100272=2014061037016=2014061037017=95:72:3937=80531946909289=45290=5
10:30:07.072: 659549 - 83 - 1128=935=X34=65954952=20140610-13:30:07.08775=20140610268=1279=0269=122=8207=BVMF48=380963983=256256270=26.42273=00:70:86271=200272=2014061037016=2014061037017=00:70:8637=80531946915289=238290=6
10:30:07.117: 659550 - 81 - 1128=935=X34=65955052=20140610-13:30:07.13275=20140610268=1279=0269=122=8207=BVMF48=380963983=256257270=26.42273=00:71:31271=100272=2014061037016=2014061037017=00:71:3137=80531946917289=3290=7
10:30:07.386: 659551 - 82 - 1128=935=X34=65955152=20140610-13:30:07.40175=20140610268=1279=0269=122=8207=BVMF48=380394783=65892270=17.05273=00:74:00271=300272=2014061037016=2014061037017=00:74:0037=80531946923289=40290=4
10:30:07.400: 659552 - 81 - 1128=935=X34=65955252=20140610-13:30:07.41475=20140610268=1279=0269=122=8207=BVMF48=380391383=106365270=13.86273=00:74:14271=1100272=2014061037016=2014061037017=00:74:1337=80531946924289=3290=8
10:30:07.425: 659553 - 82 - 1128=935=X34=65955352=20140610-13:30:07.43975=20140610268=1279=0269=122=8207=BVMF48=380391383=106366270=13.85273=00:74:39271=100272=2014061037016=2014061037017=00:74:3937=80531946925289=40290=4
10:30:07.877: 659554 - 158 - 1128=935=X34=65955452=20140610-13:30:07.89275=20140610268=3279=0269=222=8207=BVMF48=380963983=256258270=26.41273=00:78:91271=400272=2014061037016=2014061037017=00:78:911500=E451=-0.21020=1447200274=3277=L1003=19610288=40289=8279=0269=922=8207=BVMF48=380963983=256259270=26.468273=00:78:91272=201406101500=E279=1269=022=8207=BVMF48=380963983=256260270=26.41273=00:78:91271=100272=2014061037016=2014061037017=94:53:2037=80531946189288=40290=1
10:30:07.878: 659555 - 693 - 1128=935=X34=65955552=20140610-13:30:07.89375=20140610268=18279=0269=222=8207=BVMF48=380963983=256261270=26.41273=00:78:92271=100272=2014061037016=2014061037017=00:78:911500=E451=-0.21020=1447300274=3277=L1003=19620288=40289=8279=0269=922=8207=BVMF48=380963983=256262270=26.468273=00:78:92272=201406101500=E279=0269=222=8207=BVMF48=380963983=256263270=26.41273=00:78:92271=300272=2014061037016=2014061037017=00:78:911500=E451=-0.21020=1447600274=3277=L1003=19630288=40289=8279=0269=922=8207=BVMF48=380963983=256264270=26.468273=00:78:92272=201406101500=E279=0269=222=8207=BVMF48=380963983=256265270=26.41273=00:78:92271=200272=2014061037016=2014061037017=00:78:911500=E451=-0.21020=1447800274=3277=L1003=19640288=40289=8279=0269=922=8207=BVMF48=380963983=256266270=26.468273=00:78:92272=201406101500=E279=0269=222=8207=BVMF48=380963983=256267270=26.41273=00:78:92271=100272=2014061037016=2014061037017=00:78:911500=E451=-0.21020=1447900274=3277=L1003=19650288=40289=8279=0269=922=8207=BVMF48=380963983=256268270=26.468273=00:78:92272=201406101500=E279=0269=222=8207=BVMF48=380963983=256269270=26.41273=00:78:92271=600272=2014061037016=2014061037017=00:78:911500=E451=-0.21020=1448500274=3277=L1003=19660288=40289=8279=0269=922=8207=BVMF48=380963983=256270270=26.468273=00:78:92272=201406101500=E279=0269=222=8207=BVMF48=380963983=256271270=26.41273=00:78:92271=100272=2014061037016=2014061037017=00:78:911500=E451=-0.21020=1448600274=3277=L1003=19670288=70289=8279=0269=922=8207=BVMF48=380963983=256272270=26.468273=00:78:92272=201406101500=E279=0269=222=8207=BVMF48=380963983=256273270=26.41273=00:78:92271=1800272=2014061037016=2014061037017=00:78:911500=E451=-0.21020=1450400274=3277=L1003=19680288=45289=8279=0269=922=8207=BVMF48=380963983=256274270=26.468273=00:78:92272=201406101500=E279=0269=222=8207=BVMF48=380963983=256275270=26.41273=00:78:92271=600272=2014061037016=2014061037017=00:78:911500=E451=-0.21020=1451000274=3277=L1003=19690288=45289=8279=0269=922=8207=BVMF48=380963983=256276270=26.468273=00:78:92272=201406101500=E279=4269=022=8207=BVMF48=380963983=256277273=00:78:92272=20140610290=7279=1269=022=8207=BVMF48=380963983=256278270=26.41273=00:78:92271=4400272=2014061037016=2014061037017=00:61:5337=80531946880288=45290=1
10:30:07.880: 659556 - 71 - 1128=935=X34=65955652=20140610-13:30:07.89475=20140610268=1279=2269=022=8207=BVMF48=380963983=256279273=00:78:94272=2014061037=80531945212288=45290=63
10:30:07.880: 659557 - 72 - 1128=935=X34=65955752=20140610-13:30:07.89575=20140610268=1279=2269=122=8207=BVMF48=380963983=256280273=00:78:94272=2014061037=80531946181289=45290=63
10:30:07.887: 659558 - 71 - 1128=935=X34=65955852=20140610-13:30:07.90275=20140610268=1279=2269=022=8207=BVMF48=380963983=256281273=00:79:01272=2014061037=80531946881288=45290=5
10:30:07.888: 659559 - 119 - 1128=935=X34=65955952=20140610-13:30:07.90375=20140610268=2279=2269=122=8207=BVMF48=380963983=256282273=00:79:02272=2014061037=80531946907289=45290=63279=0269=122=8207=BVMF48=380963983=256283270=26.43273=00:79:02271=3000272=2014061037016=2014061037017=00:79:0237=80531946943289=45290=10
10:30:07.891: 659560 - 81 - 1128=935=X34=65956052=20140610-13:30:07.90675=20140610268=1279=0269=022=8207=BVMF48=380963983=256284270=26.41273=00:79:05271=1400272=2014061037016=2014061037017=00:79:0537=80531946947288=45290=2
10:30:07.896: 659561 - 119 - 1128=935=X34=65956152=20140610-13:30:07.91175=20140610268=2279=2269=022=8207=BVMF48=380963983=256285273=00:79:10272=2014061037=80531946947288=45290=2279=0269=022=8207=BVMF48=380963983=256286270=26.4273=00:79:10271=800272=2014061037016=2014061037017=00:79:1037=80531946949288=45290=5
10:30:07.902: 659562 - 81 - 1128=935=X34=65956252=20140610-13:30:07.91775=20140610268=1279=0269=022=8207=BVMF48=380963983=256287270=26.41273=00:79:16271=400272=2014061037016=2014061037017=00:79:1637=80531946950288=40290=2
10:30:07.905: 659563 - 82 - 1128=935=X34=65956352=20140610-13:30:07.92075=20140610268=1279=0269=122=8207=BVMF48=380963983=256288270=26.42273=00:79:19271=200272=2014061037016=2014061037017=00:79:1937=80531946951289=40290=8
10:30:07.907: 659564 - 70 - 1128=935=X34=65956452=20140610-13:30:07.92175=20140610268=1279=2269=022=8207=BVMF48=380963983=256289273=00:79:20272=2014061037=80531945719288=3290=12
10:30:07.907: 659565 - 118 - 1128=935=X34=65956552=20140610-13:30:07.92275=20140610268=2279=2269=022=8207=BVMF48=380963983=256290273=00:79:21272=2014061037=80531946949288=45290=6279=0269=022=8207=BVMF48=380963983=256291270=26.41273=00:79:21271=400272=2014061037016=2014061037017=00:79:2137=80531946952288=45290=3
10:30:07.934: 659566 - 81 - 1128=935=X34=65956652=20140610-13:30:07.94975=20140610268=1279=0269=022=8207=BVMF48=380968883=253667270=29.35273=00:79:48271=3000272=2014061037016=2014061037017=00:79:4837=80531946953288=45290=18
10:30:07.934: 659567 - 82 - 1128=935=X34=65956752=20140610-13:30:07.94975=20140610268=1279=0269=122=8207=BVMF48=380968883=253668270=29.44273=00:79:49271=3000272=2014061037016=2014061037017=00:79:4937=80531946954289=45290=22
10:30:07.938: 659568 - 72 - 1128=935=X34=65956852=20140610-13:30:07.95375=20140610268=1279=2269=122=8207=BVMF48=380968883=253669273=00:79:53272=2014061037=80531946954289=45290=22
10:30:08.075: 659569 - 156 - 1128=935=X34=65956952=20140610-13:30:08.08975=20140610268=3279=0269=222=8207=BVMF48=380968883=253670270=29.4273=00:80:89271=500272=2014061037016=2014061037017=00:80:881500=E451=-0.231020=458700274=01003=6750288=8289=8279=0269=922=8207=BVMF48=380968883=253671270=29.476273=00:80:89272=201406101500=E279=1269=122=8207=BVMF48=380968883=253672270=29.4273=00:80:89271=2700272=2014061037016=2014061037017=42:17:5937=80531927360289=8290=1
10:30:08.075: 659570 - 71 - 1128=935=X34=65957052=20140610-13:30:08.08975=20140610268=1279=2269=122=8207=BVMF48=380968883=253673273=00:80:89272=2014061037=80531946857289=8290=7
10:30:08.076: 659571 - 80 - 1128=935=X34=65957152=20140610-13:30:08.09175=20140610268=1279=0269=022=8207=BVMF48=380968883=253674270=29.39273=00:80:90271=300272=2014061037016=2014061037017=00:80:9037=80531946956288=8290=5
10:30:08.076: 659572 - 81 - 1128=935=X34=65957252=20140610-13:30:08.09175=20140610268=1279=0269=022=8207=BVMF48=380968883=253675270=29.37273=00:80:90271=3000272=2014061037016=2014061037017=00:80:9037=80531946957288=45290=10
10:30:08.076: 659573 - 81 - 1128=935=X34=65957352=20140610-13:30:08.09175=20140610268=1279=0269=022=8207=BVMF48=380968883=253676270=29.36273=00:80:90271=3000272=2014061037016=2014061037017=00:80:9037=80531946958288=45290=15
10:30:08.077: 659574 - 71 - 1128=935=X34=65957452=20140610-13:30:08.09275=20140610268=1279=2269=122=8207=BVMF48=380968883=253677273=00:80:91272=2014061037=80531946566289=8290=7
10:30:08.082: 659575 - 399 - 1128=935=X34=65957552=20140610-13:30:08.09775=20140610268=10279=0269=222=8207=BVMF48=380249383=103640270=9.34273=00:80:96271=100272=2014061037016=2014061037017=00:80:961500=E451=-0.111020=264800274=01003=3970288=45289=8279=0269=922=8207=BVMF48=380249383=103641270=9.381273=00:80:96272=201406101500=E279=0269=222=8207=BVMF48=380249383=103642270=9.34273=00:80:96271=100272=2014061037016=2014061037017=00:80:961500=E451=-0.111020=264900274=1277=L1003=3980288=45289=735279=0269=922=8207=BVMF48=380249383=103643270=9.381273=00:80:96272=201406101500=E279=0269=222=8207=BVMF48=380249383=103644270=9.34273=00:80:96271=700272=2014061037016=2014061037017=00:80:961500=E451=-0.111020=265600274=1277=L1003=3990288=45289=70279=0269=922=8207=BVMF48=380249383=103645270=9.381273=00:80:96272=201406101500=E279=0269=222=8207=BVMF48=380249383=103646270=9.34273=00:80:96271=100272=2014061037016=2014061037017=00:80:961500=E451=-0.111020=265700274=1277=L1003=4000288=45289=40279=0269=922=8207=BVMF48=380249383=103647270=9.381273=00:80:96272=201406101500=E279=4269=122=8207=BVMF48=380249383=103648273=00:80:96272=20140610290=3279=1269=122=8207=BVMF48=380249383=103649270=9.34273=00:80:96271=500272=2014061037016=2014061037017=00:30:8837=80531946834289=40290=1
10:30:08.083: 659576 - 71 - 1128=935=X34=65957652=20140610-13:30:08.09875=20140610268=1279=2269=122=8207=BVMF48=380968883=253678273=00:80:98272=2014061037=80531946819289=3290=4
10:30:08.088: 659577 - 82 - 1128=935=X34=65957752=20140610-13:30:08.10375=20140610268=1279=0269=022=8207=BVMF48=380963983=256292270=26.3273=00:81:02271=3000272=2014061037016=2014061037017=00:81:0237=80531946965288=45290=77
10:30:08.104: 659578 - 81 - 1128=935=X34=65957852=20140610-13:30:08.11875=20140610268=1279=0269=122=8207=BVMF48=380968883=253679270=29.49273=00:81:18271=300272=2014061037016=2014061037017=00:81:1837=80531946966289=8290=35
10:30:08.110: 659579 - 160 - 1128=935=X34=65957952=20140610-13:30:08.12575=20140610268=3279=0269=222=8207=BVMF48=380249383=103650270=9.33273=00:81:24271=100272=2014061037016=2014061037017=00:81:241500=E451=-0.121020=265800274=21003=4010288=127289=735279=0269=922=8207=BVMF48=380249383=103651270=9.381273=00:81:24272=201406101500=E279=1269=022=8207=BVMF48=380249383=103652270=9.33273=00:81:24271=1700272=2014061037016=2014061037017=75:48:4737=80531940535288=127290=1
10:30:08.126: 659580 - 160 - 1128=935=X34=65958052=20140610-13:30:08.14175=20140610268=3279=0269=222=8207=BVMF48=380249383=103653270=9.33273=00:81:40271=100272=2014061037016=2014061037017=00:81:401500=E451=-0.121020=265900274=3277=L1003=4020288=127289=735279=0269=922=8207=BVMF48=380249383=103654270=9.38273=00:81:40272=201406101500=E279=1269=022=8207=BVMF48=380249383=103655270=9.33273=00:81:40271=1600272=2014061037016=2014061037017=75:48:4737=80531940535288=127290=1
10:30:08.140: 659581 - 82 - 1128=935=X34=65958152=20140610-13:30:08.15575=20140610268=1279=0269=122=8207=BVMF48=380968883=253680270=29.47273=00:81:54271=3000272=2014061037016=2014061037017=00:81:5437=80531946974289=45290=28
10:30:08.141: 659582 - 81 - 1128=935=X34=65958252=20140610-13:30:08.15675=20140610268=1279=0269=122=8207=BVMF48=380249383=103656270=9.36273=00:81:56271=100272=2014061037016=2014061037017=00:81:5637=80531946975289=8290=14
10:30:08.143: 659583 - 83 - 1128=935=X34=65958352=20140610-13:30:08.15775=20140610268=1279=0269=122=8207=BVMF48=380249383=103657270=9.34273=00:81:57271=300272=2014061037016=2014061037017=00:81:5737=80531946976289=735290=2
10:30:08.211: 659584 - 72 - 1128=935=X34=65958452=20140610-13:30:08.22575=20140610268=1279=2269=122=8207=BVMF48=380968883=253681273=00:82:25272=2014061037=80531946161289=16290=33
10:30:08.277: 659585 - 81 - 1128=935=X34=65958552=20140610-13:30:08.29175=20140610268=1279=0269=022=8207=BVMF48=380968883=253682270=29.34273=00:82:91271=3000272=2014061037016=2014061037017=00:82:9137=80531946977288=45290=24
10:30:08.315: 659586 - 120 - 1128=935=X34=65958652=20140610-13:30:08.33075=20140610268=2279=2269=022=8207=BVMF48=380963983=256293273=00:83:30272=2014061037=80531946588288=72290=178279=0269=022=8207=BVMF48=380963983=256294270=25.91273=00:83:30271=300272=2014061037016=2014061037017=00:83:3037=80531946978288=72290=172
10:30:08.316: 659587 - 118 - 1128=935=X34=65958752=20140610-13:30:08.33175=20140610268=2279=2269=022=8207=BVMF48=380968883=253683273=00:83:31272=2014061037=80531946589288=72290=20279=0269=022=8207=BVMF48=380968883=253684270=29.36273=00:83:31271=300272=2014061037016=2014061037017=00:83:3137=80531946979288=72290=16
10:30:08.341: 659588 - 82 - 1128=935=X34=65958852=20140610-13:30:08.35675=20140610268=1279=0269=122=8207=BVMF48=380968883=253685270=29.48273=00:83:55271=3000272=2014061037016=2014061037017=00:83:5537=80531946980289=45290=33
10:30:08.399: 659589 - 82 - 1128=935=X34=65958952=20140610-13:30:08.41475=20140610268=1279=0269=122=8207=BVMF48=380977983=20289270=7.43273=00:84:13271=600272=2014061037016=2014061037017=00:84:1337=80531946981289=40290=14
10:30:08.400: 659590 - 81 - 1128=935=X34=65959052=20140610-13:30:08.41575=20140610268=1279=0269=022=8207=BVMF48=380977983=20290270=7.28273=00:84:14271=100272=2014061037016=2014061037017=00:84:1437=80531946982288=40290=21
10:30:08.414: 659591 - 82 - 1128=935=X34=65959152=20140610-13:30:08.42975=20140610268=1279=0269=122=8207=BVMF48=380977983=20291270=7.46273=00:84:28271=100272=2014061037016=2014061037017=00:84:2837=80531946983289=40290=25
10:30:08.477: 659592 - 81 - 1128=935=X34=65959252=20140610-13:30:08.49275=20140610268=1279=0269=022=8207=BVMF48=380968883=253686270=29.33273=00:84:92271=3000272=2014061037016=2014061037017=00:84:9237=80531946984288=45290=29
10:30:08.511: 659593 - 81 - 1128=935=X34=65959352=20140610-13:30:08.52675=20140610268=1279=0269=022=8207=BVMF48=380965483=79823270=8.12273=00:85:25271=7000272=2014061037016=2014061037017=00:85:2537=80531946985288=40290=65
10:30:08.514: 659594 - 81 - 1128=935=X34=65959452=20140610-13:30:08.52975=20140610268=1279=0269=022=8207=BVMF48=380965483=79824270=8.09273=00:85:28271=2000272=2014061037016=2014061037017=00:85:2837=80531946986288=40290=84
10:30:08.516: 659595 - 81 - 1128=935=X34=65959552=20140610-13:30:08.53075=20140610268=1279=0269=022=8207=BVMF48=380977983=20292270=7.31273=00:85:30271=600272=2014061037016=2014061037017=00:85:3037=80531946987288=40290=13
10:30:08.518: 659596 - 82 - 1128=935=X34=65959652=20140610-13:30:08.53375=20140610268=1279=0269=122=8207=BVMF48=380965483=79825270=8.28273=00:85:33271=2500272=2014061037016=2014061037017=00:85:3337=80531946988289=40290=53
10:30:08.529: 659597 - 83 - 1128=935=X34=65959752=20140610-13:30:08.54475=20140610268=1279=0269=122=8207=BVMF48=380965483=79826270=8.25273=00:85:43271=10900272=2014061037016=2014061037017=00:85:4337=80531946989289=40290=35
10:30:08.542: 659598 - 82 - 1128=935=X34=65959852=20140610-13:30:08.55775=20140610268=1279=0269=122=8207=BVMF48=380968883=253687270=29.49273=00:85:56271=3000272=2014061037016=2014061037017=00:85:5637=80531946990289=45290=37
10:30:08.679: 659599 - 81 - 1128=935=X34=65959952=20140610-13:30:08.69375=20140610268=1279=0269=022=8207=BVMF48=380968883=253688270=29.32273=00:86:93271=3000272=2014061037016=2014061037017=00:86:9237=80531946991288=45290=33
10:30:08.743: 659600 - 83 - 1128=935=X34=65960052=20140610-13:30:08.75875=20140610268=1279=0269=122=8207=BVMF48=380968883=253689270=29.5273=00:87:57271=3000272=2014061037016=2014061037017=00:87:5737=80531946992289=45290=42
10:30:08.879: 659601 - 81 - 1128=935=X34=65960152=20140610-13:30:08.89475=20140610268=1279=0269=022=8207=BVMF48=380968883=253690270=29.31273=00:88:94271=3000272=2014061037016=2014061037017=00:88:9337=80531946994288=45290=38
10:30:08.944: 659602 - 82 - 1128=935=X34=65960252=20140610-13:30:08.95875=20140610268=1279=0269=122=8207=BVMF48=380968883=253691270=29.51273=00:89:58271=3000272=2014061037016=2014061037017=00:89:5837=80531946995289=45290=44
10:30:09.080: 659603 - 82 - 1128=935=X34=65960352=20140610-13:30:09.09575=20140610268=1279=0269=022=8207=BVMF48=380968883=253692270=29.3273=00:90:94271=3000272=2014061037016=2014061037017=00:90:9437=80531946996288=45290=43
10:30:09.108: 659604 - 82 - 1128=935=X34=65960452=20140610-13:30:09.12275=20140610268=1279=0269=122=8207=BVMF48=380968883=253693270=29.49273=00:91:22271=3400272=2014061037016=2014061037017=00:91:2237=80531946997289=16290=38
10:30:09.145: 659605 - 82 - 1128=935=X34=65960552=20140610-13:30:09.15975=20140610268=1279=0269=122=8207=BVMF48=380968883=253694270=29.52273=00:91:59271=3000272=2014061037016=2014061037017=00:91:5937=80531946999289=45290=48
10:30:09.194: 659606 - 81 - 1128=935=X34=65960652=20140610-13:30:09.20875=20140610268=1279=0269=022=8207=BVMF48=380968883=253695270=29.39273=00:92:08271=400272=2014061037016=2014061037017=00:92:0737=80531947001288=70290=6
10:30:09.198: 659607 - 72 - 1128=935=X34=65960752=20140610-13:30:09.21375=20140610268=1279=2269=122=8207=BVMF48=380249383=103658273=00:92:12272=2014061037=80531942610289=70290=8
10:30:09.281: 659608 - 81 - 1128=935=X34=65960852=20140610-13:30:09.29675=20140610268=1279=0269=022=8207=BVMF48=380968883=253696270=29.29273=00:92:95271=3000272=2014061037016=2014061037017=00:92:9537=80531947003288=45290=49
10:30:09.345: 659609 - 82 - 1128=935=X34=65960952=20140610-13:30:09.36075=20140610268=1279=0269=122=8207=BVMF48=380968883=253697270=29.53273=00:93:60271=3000272=2014061037016=2014061037017=00:93:5937=80531947004289=45290=51
10:30:09.365: 659610 - 69 - 1128=935=X34=65961052=20140610-13:30:09.38075=20140610268=1279=2269=022=8207=BVMF48=380388983=12960273=00:93:79272=2014061037=80531938587288=8290=2
10:30:09.365: 659611 - 70 - 1128=935=X34=65961152=20140610-13:30:09.38075=20140610268=1279=2269=122=8207=BVMF48=380388983=12961273=00:93:79272=2014061037=80531938522289=8290=1
10:30:09.365: 659612 - 70 - 1128=935=X34=65961252=20140610-13:30:09.38075=20140610268=1279=2269=022=8207=BVMF48=380391383=106367273=00:93:80272=2014061037=80531946501288=8290=4
10:30:09.365: 659613 - 71 - 1128=935=X34=65961352=20140610-13:30:09.38075=20140610268=1279=2269=122=8207=BVMF48=380391383=106368273=00:93:80272=2014061037=80531945306289=8290=8
10:30:09.366: 659614 - 70 - 1128=935=X34=65961452=20140610-13:30:09.38175=20140610268=1279=2269=022=8207=BVMF48=380394783=65893273=00:93:80272=2014061037=80531935170288=8290=1
10:30:09.366: 659615 - 71 - 1128=935=X34=65961552=20140610-13:30:09.38175=20140610268=1279=2269=122=8207=BVMF48=380394783=65894273=00:93:80272=2014061037=80531946536289=8290=1
10:30:09.366: 659616 - 69 - 1128=935=X34=65961652=20140610-13:30:09.38175=20140610268=1279=2269=022=8207=BVMF48=380557983=2418273=00:93:81272=2014061037=80531940932288=8290=1
10:30:09.366: 659617 - 70 - 1128=935=X34=65961752=20140610-13:30:09.38175=20140610268=1279=2269=122=8207=BVMF48=380557983=2419273=00:93:81272=2014061037=80531939316289=8290=1
10:30:09.367: 659618 - 80 - 1128=935=X34=65961852=20140610-13:30:09.38175=20140610268=1279=0269=122=8207=BVMF48=380388983=12962270=11.39273=00:93:81271=100272=2014061037016=2014061037017=00:93:8137=80531947005289=8290=2
10:30:09.372: 659619 - 79 - 1128=935=X34=65961952=20140610-13:30:09.38775=20140610268=1279=0269=022=8207=BVMF48=380388983=12963270=11.35273=00:93:87271=100272=2014061037016=2014061037017=00:93:8637=80531947006288=8290=2
10:30:09.373: 659620 - 80 - 1128=935=X34=65962052=20140610-13:30:09.38775=20140610268=1279=0269=122=8207=BVMF48=380388983=12964270=11.39273=00:93:87271=100272=2014061037016=2014061037017=00:93:8737=80531947007289=8290=3
10:30:09.373: 659621 - 80 - 1128=935=X34=65962152=20140610-13:30:09.38875=20140610268=1279=0269=022=8207=BVMF48=380391383=106369270=13.83273=00:93:87271=300272=2014061037016=2014061037017=00:93:8737=80531947008288=8290=4
10:30:09.404: 659622 - 82 - 1128=935=X34=65962252=20140610-13:30:09.41975=20140610268=1279=0269=122=8207=BVMF48=380249383=103659270=9.34273=00:94:18271=400272=2014061037016=2014061037017=00:94:1837=80531947009289=70290=3
10:30:09.434: 659623 - 70 - 1128=935=X34=65962352=20140610-13:30:09.44975=20140610268=1279=2269=022=8207=BVMF48=380391383=106370273=00:94:48272=2014061037=80531946752288=8290=33
10:30:09.458: 659624 - 80 - 1128=935=X34=65962452=20140610-13:30:09.47375=20140610268=1279=0269=022=8207=BVMF48=380391383=106371270=13.78273=00:94:73271=200272=2014061037016=2014061037017=00:94:7337=80531947010288=8290=33
10:30:09.478: 659625 - 145 - 1128=935=X34=65962552=20140610-13:30:09.49375=20140610268=3279=0269=222=8207=BVMF48=380968883=253698270=29.39273=00:94:92271=100272=2014061037016=2014061037017=00:94:921500=E451=-0.241020=458800274=21003=6760288=40289=3279=0269=922=8207=BVMF48=380968883=253699270=29.476273=00:94:92272=201406101500=E279=2269=022=8207=BVMF48=380968883=253700273=00:94:92272=2014061037=80531946633288=40290=1
10:30:09.479: 659626 - 81 - 1128=935=X34=65962652=20140610-13:30:09.49475=20140610268=1279=0269=122=8207=BVMF48=380968883=253701270=29.41273=00:94:94271=300272=2014061037016=2014061037017=00:94:9337=80531947012289=8290=9
10:30:09.482: 659627 - 81 - 1128=935=X34=65962752=20140610-13:30:09.49775=20140610268=1279=0269=022=8207=BVMF48=380968883=253702270=29.28273=00:94:96271=3000272=2014061037016=2014061037017=00:94:9637=80531947013288=45290=53
10:30:09.546: 659628 - 82 - 1128=935=X34=65962852=20140610-13:30:09.56175=20140610268=1279=0269=122=8207=BVMF48=380968883=253703270=29.54273=00:95:61271=3000272=2014061037016=2014061037017=00:95:6037=80531947015289=45290=54
10:30:09.664: 659629 - 82 - 1128=935=X34=65962952=20140610-13:30:09.67875=20140610268=1279=0269=122=8207=BVMF48=380963983=256295270=26.42273=00:96:78271=400272=2014061037016=2014061037017=00:96:7837=80531947016289=27290=9
10:30:09.747: 659630 - 82 - 1128=935=X34=65963052=20140610-13:30:09.76275=20140610268=1279=0269=122=8207=BVMF48=380968883=253704270=29.55273=00:97:61271=3000272=2014061037016=2014061037017=00:97:6137=80531947017289=45290=58
10:30:09.948: 659631 - 82 - 1128=935=X34=65963152=20140610-13:30:09.96375=20140610268=1279=0269=122=8207=BVMF48=380968883=253705270=29.56273=00:99:62271=3000272=2014061037016=2014061037017=00:99:6237=80531947019289=45290=61
10:30:10.084: 659632 - 70 - 1128=935=X34=65963252=20140610-13:30:10.09975=20140610268=1279=2269=022=8207=BVMF48=380968883=253706273=01:00:98272=2014061037=80531946956288=8290=4
10:30:10.084: 659633 - 71 - 1128=935=X34=65963352=20140610-13:30:10.09975=20140610268=1279=2269=122=8207=BVMF48=380968883=253707273=01:00:98272=2014061037=80531946966289=8290=37
10:30:10.308: 659634 - 156 - 1128=935=X34=65963452=20140610-13:30:10.32375=20140610268=3279=0269=222=8207=BVMF48=380249383=103660270=9.34273=01:03:23271=100272=2014061037016=2014061037017=01:03:221500=E451=-0.111020=266000274=01003=4030288=8289=40279=0269=922=8207=BVMF48=380249383=103661270=9.38273=01:03:23272=201406101500=E279=1269=122=8207=BVMF48=380249383=103662270=9.34273=01:03:23271=400272=2014061037016=2014061037017=00:30:8837=80531946834289=40290=1
10:30:10.360: 659635 - 81 - 1128=935=X34=65963552=20140610-13:30:10.37575=20140610268=1279=0269=022=8207=BVMF48=380249383=103663270=9.31273=01:03:74271=4400272=2014061037016=2014061037017=01:03:7437=80531947021288=40290=18
10:30:10.362: 659636 - 82 - 1128=935=X34=65963652=20140610-13:30:10.37775=20140610268=1279=0269=122=8207=BVMF48=380249383=103664270=9.37273=01:03:77271=4400272=2014061037016=2014061037017=01:03:7637=80531947022289=40290=20
10:30:10.364: 659637 - 80 - 1128=935=X34=65963752=20140610-13:30:10.37975=20140610268=1279=0269=022=8207=BVMF48=380394783=65895270=17.02273=01:03:78271=200272=2014061037016=2014061037017=01:03:7837=80531947023288=8290=3
10:30:10.364: 659638 - 81 - 1128=935=X34=65963852=20140610-13:30:10.37975=20140610268=1279=0269=122=8207=BVMF48=380394783=65896270=17.05273=01:03:79271=200272=2014061037016=2014061037017=01:03:7937=80531947024289=8290=4
10:30:10.369: 659639 - 79 - 1128=935=X34=65963952=20140610-13:30:10.38475=20140610268=1279=0269=022=8207=BVMF48=380557983=2420270=2.93273=01:03:83271=100272=2014061037016=2014061037017=01:03:8337=80531947025288=8290=1
10:30:10.369: 659640 - 80 - 1128=935=X34=65964052=20140610-13:30:10.38475=20140610268=1279=0269=122=8207=BVMF48=380557983=2421270=3.02273=01:03:84271=100272=2014061037016=2014061037017=01:03:8437=80531947026289=8290=1
10:30:10.389: 659641 - 70 - 1128=935=X34=65964152=20140610-13:30:10.40475=20140610268=1279=2269=022=8207=BVMF48=380391383=106372273=01:04:03272=2014061037=80531947010288=8290=33
10:30:10.415: 659642 - 80 - 1128=935=X34=65964252=20140610-13:30:10.43075=20140610268=1279=0269=022=8207=BVMF48=380391383=106373270=13.78273=01:04:29271=400272=2014061037016=2014061037017=01:04:2937=80531947027288=8290=33
10:30:10.482: 659643 - 82 - 1128=935=X34=65964352=20140610-13:30:10.49675=20140610268=1279=0269=122=8207=BVMF48=380968883=253708270=29.4273=01:04:96271=300272=2014061037016=2014061037017=01:04:9637=80531947028289=8290=6
10:30:10.985: 659644 - 119 - 1128=935=X34=65964452=20140610-13:30:11.00075=20140610268=2279=2269=122=8207=BVMF48=380968883=253709273=01:09:99272=2014061037=80531947019289=45290=61279=0269=122=8207=BVMF48=380968883=253710270=29.46273=01:09:99271=3000272=2014061037016=2014061037017=01:09:9937=80531947030289=45290=27
10:30:10.986: 659645 - 72 - 1128=935=X34=65964552=20140610-13:30:11.00175=20140610268=1279=2269=122=8207=BVMF48=380968883=253711273=01:10:00272=2014061037=80531947030289=45290=27
10:30:11.187: 659646 - 82 - 1128=935=X34=65964652=20140610-13:30:11.20275=20140610268=1279=0269=122=8207=BVMF48=380968883=253712270=29.46273=01:12:01271=3000272=2014061037016=2014061037017=01:12:0137=80531947031289=45290=27
10:30:11.894: 659647 - 158 - 1128=935=X34=65964752=20140610-13:30:11.90975=20140610268=3279=0269=222=8207=BVMF48=380963983=256296270=26.41273=01:19:08271=1900272=2014061037016=2014061037017=01:19:071500=E451=-0.21020=1452900274=3277=L1003=19700288=45289=8279=0269=922=8207=BVMF48=380963983=256297270=26.468273=01:19:08272=201406101500=E279=1269=022=8207=BVMF48=380963983=256298270=26.41273=01:19:08271=2500272=2014061037016=2014061037017=00:61:5337=80531946880288=45290=1
10:30:11.894: 659648 - 158 - 1128=935=X34=65964852=20140610-13:30:11.90975=20140610268=3279=0269=222=8207=BVMF48=380963983=256299270=26.41273=01:19:08271=100272=2014061037016=2014061037017=01:19:081500=E451=-0.21020=1453000274=3277=L1003=19710288=45289=8279=0269=922=8207=BVMF48=380963983=256300270=26.468273=01:19:08272=201406101500=E279=1269=022=8207=BVMF48=380963983=256301270=26.41273=01:19:08271=2400272=2014061037016=2014061037017=00:61:5337=80531946880288=45290=1
10:30:11.895: 659649 - 71 - 1128=935=X34=65964952=20140610-13:30:11.91075=20140610268=1279=2269=022=8207=BVMF48=380963983=256302273=01:19:10272=2014061037=80531946880288=45290=1
10:30:11.897: 659650 - 206 - 1128=935=X34=65965052=20140610-13:30:11.91275=20140610268=5279=0269=222=8207=BVMF48=380963983=256303270=26.41273=01:19:11271=400272=2014061037016=2014061037017=01:19:111500=E451=-0.21020=1453400274=3277=L1003=19720288=40289=8279=0269=922=8207=BVMF48=380963983=256304270=26.468273=01:19:11272=201406101500=E279=0269=222=8207=BVMF48=380963983=256305270=26.41273=01:19:11271=400272=2014061037016=2014061037017=01:19:111500=E451=-0.21020=1453800274=3277=L1003=19730288=45289=8279=0269=922=8207=BVMF48=380963983=256306270=26.468273=01:19:11272=201406101500=E279=4269=022=8207=BVMF48=380963983=256307273=01:19:11272=20140610290=2
10:30:11.898: 659651 - 71 - 1128=935=X34=65965152=20140610-13:30:11.91375=20140610268=1279=2269=022=8207=BVMF48=380968883=253713273=01:19:12272=2014061037=80531946022288=45290=11
10:30:11.898: 659652 - 81 - 1128=935=X34=65965252=20140610-13:30:11.91375=20140610268=1279=0269=122=8207=BVMF48=380963983=256308270=26.42273=01:19:13271=200272=2014061037016=2014061037017=01:19:1337=80531947040289=8290=10
10:30:11.907: 659653 - 81 - 1128=935=X34=65965352=20140610-13:30:11.92275=20140610268=1279=0269=022=8207=BVMF48=380963983=256309270=26.41273=01:19:21271=400272=2014061037016=2014061037017=01:19:2137=80531947050288=45290=1
10:30:11.908: 659654 - 147 - 1128=935=X34=65965452=20140610-13:30:11.92375=20140610268=3279=0269=222=8207=BVMF48=380963983=256310270=26.41273=01:19:23271=400272=2014061037016=2014061037017=01:19:221500=E451=-0.21020=1454200274=3277=L1003=19740288=45289=8279=0269=922=8207=BVMF48=380963983=256311270=26.468273=01:19:23272=201406101500=E279=2269=022=8207=BVMF48=380963983=256312273=01:19:23272=2014061037=80531947050288=45290=1
10:30:11.922: 659655 - 82 - 1128=935=X34=65965552=20140610-13:30:11.93775=20140610268=1279=0269=022=8207=BVMF48=380963983=256313270=26.4273=01:19:37271=800272=2014061037016=2014061037017=01:19:3737=80531947085288=45290=4
10:30:11.927: 659656 - 72 - 1128=935=X34=65965652=20140610-13:30:11.94275=20140610268=1279=2269=022=8207=BVMF48=380968883=253714273=01:19:41272=2014061037=80531946074288=227290=12
10:30:11.940: 659657 - 70 - 1128=935=X34=65965752=20140610-13:30:11.95575=20140610268=1279=2269=022=8207=BVMF48=380963983=256314273=01:19:54272=2014061037=80531946580288=8290=35
10:30:11.940: 659658 - 81 - 1128=935=X34=65965852=20140610-13:30:11.95575=20140610268=1279=0269=122=8207=BVMF48=380963983=256315270=26.45273=01:19:55271=100272=2014061037016=2014061037017=01:19:5437=80531947099289=8290=33
10:30:11.940: 659659 - 71 - 1128=935=X34=65965952=20140610-13:30:11.95575=20140610268=1279=2269=122=8207=BVMF48=380963983=256316273=01:19:55272=2014061037=80531947099289=8290=33
10:30:11.941: 659660 - 82 - 1128=935=X34=65966052=20140610-13:30:11.95675=20140610268=1279=0269=022=8207=BVMF48=380968883=253715270=29.35273=01:19:56271=800272=2014061037016=2014061037017=01:19:5637=80531947100288=227290=19
10:30:12.099: 659661 - 81 - 1128=935=X34=65966152=20140610-13:30:12.11475=20140610268=1279=0269=022=8207=BVMF48=380968883=253716270=29.33273=01:21:13271=2000272=2014061037016=2014061037017=01:21:1337=80531947125288=45290=28
10:30:12.253: 659662 - 65 - 1128=935=X34=65966252=20140610-13:30:12.26875=20140610268=1279=0269=B22=8207=BVMF48=380391383=106374270=1577678273=01:22:58271=358272=201406101500=E15=BRL
10:30:12.253: 659663 - 65 - 1128=935=X34=65966352=20140610-13:30:12.26875=20140610268=1279=0269=B22=8207=BVMF48=380963983=256317270=38489140273=01:22:58271=1974272=201406101500=E15=BRL
10:30:12.254: 659664 - 65 - 1128=935=X34=65966452=20140610-13:30:12.26975=20140610268=1279=0269=B22=8207=BVMF48=380968883=253717270=13523621273=01:22:58271=676272=201406101500=E15=BRL
10:30:12.258: 659665 - 65 - 1128=935=X34=65966552=20140610-13:30:12.27275=20140610268=1279=0269=B22=8207=BVMF48=380965483=79827270=2434053273=01:22:58271=347272=201406101500=E15=BRL
10:30:12.259: 659666 - 65 - 1128=935=X34=65966652=20140610-13:30:12.27475=20140610268=1279=0269=B22=8207=BVMF48=380249383=103665270=2495205273=01:22:58271=403272=201406101500=E15=BRL
10:30:12.262: 659667 - 160 - 1128=935=X34=65966752=20140610-13:30:12.27775=20140610268=3279=0269=222=8207=BVMF48=380963983=256318270=26.42273=01:22:76271=100272=2014061037016=2014061037017=01:22:751500=E451=-0.191020=1454300274=01003=19750288=735289=40279=0269=922=8207=BVMF48=380963983=256319270=26.468273=01:22:76272=201406101500=E279=1269=122=8207=BVMF48=380963983=256320270=26.42273=01:22:76271=700272=2014061037016=2014061037017=93:99:9737=80531946092289=40290=1
10:30:12.290: 659668 - 62 - 1128=935=X34=65966852=20140610-13:30:12.30575=20140610268=1279=0269=B22=8207=BVMF48=380566083=11411270=177988273=01:22:58271=35272=201406101500=E15=BRL
10:30:12.306: 659669 - 62 - 1128=935=X34=65966952=20140610-13:30:12.32175=20140610268=1279=0269=B22=8207=BVMF48=380653683=6260270=428072273=01:22:58271=60272=201406101500=E15=BRL
10:30:12.306: 659670 - 64 - 1128=935=X34=65967052=20140610-13:30:12.32175=20140610268=1279=0269=B22=8207=BVMF48=380394783=65897270=335114273=01:22:58271=120272=201406101500=E15=BRL
10:30:12.410: 659671 - 70 - 1128=935=X34=65967152=20140610-13:30:12.42575=20140610268=1279=2269=022=8207=BVMF48=380963983=256321273=01:24:25272=2014061037=80531946115288=8290=16
10:30:12.436: 659672 - 71 - 1128=935=X34=65967252=20140610-13:30:12.45175=20140610268=1279=2269=022=8207=BVMF48=380968883=253718273=01:24:50272=2014061037=80531946957288=45290=9
10:30:12.436: 659673 - 70 - 1128=935=X34=65967352=20140610-13:30:12.45175=20140610268=1279=2269=022=8207=BVMF48=380968883=253719273=01:24:50272=2014061037=80531946873288=8290=6
10:30:12.436: 659674 - 71 - 1128=935=X34=65967452=20140610-13:30:12.45175=20140610268=1279=2269=022=8207=BVMF48=380968883=253720273=01:24:50272=2014061037=80531946958288=45290=10
10:30:12.436: 659675 - 72 - 1128=935=X34=65967552=20140610-13:30:12.45175=20140610268=1279=2269=122=8207=BVMF48=380968883=253721273=01:24:50272=2014061037=80531947031289=45290=27
10:30:12.637: 659676 - 81 - 1128=935=X34=65967652=20140610-13:30:12.65175=20140610268=1279=0269=022=8207=BVMF48=380968883=253722270=29.37273=01:26:51271=3000272=2014061037016=2014061037017=01:26:5137=80531947141288=45290=8
10:30:12.637: 659677 - 81 - 1128=935=X34=65967752=20140610-13:30:12.65275=20140610268=1279=0269=022=8207=BVMF48=380968883=253723270=29.36273=01:26:51271=3000272=2014061037016=2014061037017=01:26:5137=80531947142288=45290=12
10:30:12.637: 659678 - 82 - 1128=935=X34=65967852=20140610-13:30:12.65275=20140610268=1279=0269=122=8207=BVMF48=380968883=253724270=29.46273=01:26:51271=3000272=2014061037016=2014061037017=01:26:5137=80531947143289=45290=27
10:30:12.638: 659679 - 80 - 1128=935=X34=65967952=20140610-13:30:12.65375=20140610268=1279=0269=022=8207=BVMF48=380968883=253725270=29.38273=01:26:53271=300272=2014061037016=2014061037017=01:26:5237=80531947144288=8290=6
10:30:12.737: 659680 - 156 - 1128=935=X34=65968052=20140610-13:30:12.75275=20140610268=3279=0269=222=8207=BVMF48=380968883=253726270=29.4273=01:27:51271=200272=2014061037016=2014061037017=01:27:511500=E451=-0.231020=459000274=01003=6770288=8289=8279=0269=922=8207=BVMF48=380968883=253727270=29.476273=01:27:51272=201406101500=E279=1269=122=8207=BVMF48=380968883=253728270=29.4273=01:27:51271=2500272=2014061037016=2014061037017=42:17:5937=80531927360289=8290=1
10:30:12.865: 659681 - 83 - 1128=935=X34=65968152=20140610-13:30:12.88075=20140610268=1279=0269=022=8207=BVMF48=380968883=253729270=29.36273=01:28:80271=10000272=2014061037016=2014061037017=01:28:8037=80531947146288=227290=14
10:30:12.866: 659682 - 84 - 1128=935=X34=65968252=20140610-13:30:12.88175=20140610268=1279=0269=122=8207=BVMF48=380968883=253730270=29.46273=01:28:80271=10000272=2014061037016=2014061037017=01:28:8037=80531947147289=227290=28
10:30:12.871: 659683 - 156 - 1128=935=X34=65968352=20140610-13:30:12.88675=20140610268=3279=0269=222=8207=BVMF48=380968883=253731270=29.4273=01:28:86271=100272=2014061037016=2014061037017=01:28:851500=E451=-0.231020=459100274=1277=L1003=6780288=8289=8279=0269=922=8207=BVMF48=380968883=253732270=29.476273=01:28:86272=201406101500=E279=1269=122=8207=BVMF48=380968883=253733270=29.4273=01:28:86271=2400272=2014061037016=2014061037017=42:17:5937=80531927360289=8290=1
10:30:12.898: 659684 - 81 - 1128=935=X34=65968452=20140610-13:30:12.91275=20140610268=1279=0269=022=8207=BVMF48=380963983=256322270=26.32273=01:29:12271=5000272=2014061037016=2014061037017=01:29:1237=80531947149288=45290=60
10:30:12.898: 659685 - 119 - 1128=935=X34=65968552=20140610-13:30:12.91375=20140610268=2279=2269=122=8207=BVMF48=380963983=256323273=01:29:12272=2014061037=80531946108289=45290=64279=0269=122=8207=BVMF48=380963983=256324270=26.43273=01:29:12271=5000272=2014061037016=2014061037017=01:29:1237=80531947150289=45290=14
10:30:12.910: 659686 - 70 - 1128=935=X34=65968652=20140610-13:30:12.92575=20140610268=1279=2269=022=8207=BVMF48=380963983=256325273=01:29:25272=2014061037=80531946133288=8290=22
10:30:13.133: 659687 - 82 - 1128=935=X34=65968752=20140610-13:30:13.14875=20140610268=1279=0269=022=8207=BVMF48=380963983=256326270=26.38273=01:31:47271=100272=2014061037016=2014061037017=01:31:4737=80531947151288=102290=16
10:30:13.141: 659688 - 80 - 1128=935=X34=65968852=20140610-13:30:13.15675=20140610268=1279=0269=022=8207=BVMF48=380963983=256327270=26.36273=01:31:55271=100272=2014061037016=2014061037017=01:31:5537=80531947152288=8290=34
10:30:13.168: 659689 - 118 - 1128=935=X34=65968952=20140610-13:30:13.18475=20140610268=2279=2269=022=8207=BVMF48=380963983=256328273=01:31:83272=2014061037=80531946040288=59290=3279=0269=022=8207=BVMF48=380963983=256329270=26.39273=01:31:83271=800272=2014061037016=2014061037017=01:31:8337=80531947153288=59290=11
10:30:13.188: 659690 - 72 - 1128=935=X34=65969052=20140610-13:30:13.20375=20140610268=1279=2269=022=8207=BVMF48=380963983=256330273=01:32:02272=2014061037=80531947151288=102290=16
10:30:13.188: 659691 - 118 - 1128=935=X34=65969152=20140610-13:30:13.20375=20140610268=2279=2269=022=8207=BVMF48=380963983=256331273=01:32:02272=2014061037=80531947085288=45290=3279=0269=022=8207=BVMF48=380963983=256332270=26.39273=01:32:02271=800272=2014061037016=2014061037017=01:32:0237=80531947154288=45290=11
10:30:13.384: 659692 - 81 - 1128=935=X34=65969252=20140610-13:30:13.39975=20140610268=1279=0269=022=8207=BVMF48=380963983=256333270=26.35273=01:33:98271=10000272=2014061037016=2014061037017=01:33:9837=80531947156288=3290=41
10:30:13.384: 659693 - 82 - 1128=935=X34=65969352=20140610-13:30:13.39975=20140610268=1279=0269=122=8207=BVMF48=380963983=256334270=26.46273=01:33:99271=10000272=2014061037016=2014061037017=01:33:9837=80531947157289=3290=40
10:30:13.534: 659694 - 72 - 1128=935=X34=65969452=20140610-13:30:13.54975=20140610268=1279=2269=022=8207=BVMF48=380968883=253734273=01:35:48272=2014061037=80531947146288=227290=14
10:30:13.831: 659695 - 329 - 1128=935=X34=65969552=20140610-13:30:13.84675=20140610268=8279=0269=222=8207=BVMF48=380249383=103666270=9.34273=01:38:45271=400272=2014061037016=2014061037017=01:38:441500=E451=-0.111020=266400274=1277=L1003=4040288=45289=40279=0269=922=8207=BVMF48=380249383=103667270=9.38273=01:38:45272=201406101500=E279=0269=222=8207=BVMF48=380249383=103668270=9.34273=01:38:45271=300272=2014061037016=2014061037017=01:38:441500=E451=-0.111020=266700274=1277=L1003=4050288=45289=735279=0269=922=8207=BVMF48=380249383=103669270=9.38273=01:38:45272=201406101500=E279=0269=222=8207=BVMF48=380249383=103670270=9.34273=01:38:45271=400272=2014061037016=2014061037017=01:38:441500=E451=-0.111020=267100274=1277=L1003=4060288=45289=70279=0269=922=8207=BVMF48=380249383=103671270=9.38273=01:38:45272=201406101500=E279=4269=122=8207=BVMF48=380249383=103672273=01:38:45272=20140610290=3279=0269=022=8207=BVMF48=380249383=103673270=9.34273=01:38:45271=4900272=2014061037016=2014061037017=01:38:4437=80531947161288=45290=1
10:30:13.832: 659696 - 80 - 1128=935=X34=65969652=20140610-13:30:13.84775=20140610268=1279=0269=022=8207=BVMF48=380249383=103674270=9.32273=01:38:47271=100272=2014061037016=2014061037017=01:38:4737=80531947162288=8290=15
10:30:13.840: 659697 - 83 - 1128=935=X34=65969752=20140610-13:30:13.85575=20140610268=1279=0269=122=8207=BVMF48=380249383=103675270=9.35273=01:38:55271=100272=2014061037016=2014061037017=01:38:5537=80531947182289=735290=9
10:30:13.844: 659698 - 80 - 1128=935=X34=65969852=20140610-13:30:13.85975=20140610268=1279=0269=022=8207=BVMF48=380249383=103676270=9.31273=01:38:59271=700272=2014061037016=2014061037017=01:38:5837=80531947201288=8290=21
10:30:13.859: 659699 - 72 - 1128=935=X34=65969952=20140610-13:30:13.87475=20140610268=1279=2269=122=8207=BVMF48=380249383=103677273=01:38:73272=2014061037=80531946414289=40290=6
10:30:14.085: 659700 - 71 - 1128=935=X34=65970052=20140610-13:30:14.10075=20140610268=1279=2269=022=8207=BVMF48=380968883=253735273=01:40:99272=2014061037=80531947141288=45290=9
10:30:14.100: 659701 - 119 - 1128=935=X34=65970152=20140610-13:30:14.11675=20140610268=2279=2269=022=8207=BVMF48=380249383=103678273=01:41:15272=2014061037=80531947021288=40290=20279=0269=022=8207=BVMF48=380249383=103679270=9.3273=01:41:15271=4400272=2014061037016=2014061037017=01:41:1537=80531947223288=40290=28
10:30:14.103: 659702 - 119 - 1128=935=X34=65970252=20140610-13:30:14.11875=20140610268=2279=2269=122=8207=BVMF48=380391383=106375273=01:41:17272=2014061037=80531946856289=40290=18279=0269=122=8207=BVMF48=380391383=106376270=13.87273=01:41:17271=4700272=2014061037016=2014061037017=01:41:1737=80531947224289=40290=13
10:30:14.141: 659703 - 70 - 1128=935=X34=65970352=20140610-13:30:14.15675=20140610268=1279=2269=022=8207=BVMF48=380963983=256335273=01:41:55272=2014061037=80531947152288=8290=33
10:30:14.209: 659704 - 119 - 1128=935=X34=65970452=20140610-13:30:14.22475=20140610268=2279=2269=122=8207=BVMF48=380391383=106377273=01:42:23272=2014061037=80531947224289=40290=13279=0269=122=8207=BVMF48=380391383=106378270=13.88273=01:42:23271=4700272=2014061037016=2014061037017=01:42:2337=80531947225289=40290=18
10:30:14.253: 659705 - 118 - 1128=935=X34=65970552=20140610-13:30:14.26875=20140610268=2279=2269=022=8207=BVMF48=380249383=103680273=01:42:67272=2014061037=80531947223288=40290=28279=0269=022=8207=BVMF48=380249383=103681270=9.31273=01:42:67271=4400272=2014061037016=2014061037017=01:42:6737=80531947226288=40290=21
10:30:14.286: 659706 - 81 - 1128=935=X34=65970652=20140610-13:30:14.30175=20140610268=1279=0269=022=8207=BVMF48=380968883=253736270=29.37273=01:43:01271=3000272=2014061037016=2014061037017=01:43:0037=80531947227288=45290=9
10:30:14.374: 659707 - 71 - 1128=935=X34=65970752=20140610-13:30:14.39075=20140610268=1279=2269=022=8207=BVMF48=380968883=253737273=01:43:89272=2014061037=80531947227288=45290=9
