10:27:35.149: 657658 - 71 - 1128=935=X34=65765852=20140610-13:27:35.15775=20140610268=1279=2269=122=8207=BVMF48=380965483=79351273=73:51:56272=2014061037=80531939118289=8290=6
10:27:35.150: 657659 - 81 - 1128=935=X34=65765952=20140610-13:27:35.15875=20140610268=1279=0269=122=8207=BVMF48=380965483=79352270=8.25273=73:51:58271=100272=2014061037016=2014061037017=73:51:5737=80531939460289=8290=11
10:27:35.160: 657660 - 81 - 1128=935=X34=65766052=20140610-13:27:35.16875=20140610268=1279=0269=022=8207=BVMF48=380965483=79353270=8.23273=73:51:67271=100272=2014061037016=2014061037017=73:51:6737=80531939461288=40290=3
10:27:35.264: 657661 - 72 - 1128=935=X34=65766152=20140610-13:27:35.27275=20140610268=1279=2269=122=8207=BVMF48=380965483=79354273=73:52:71272=2014061037=80531932638289=40290=23
10:27:35.266: 657662 - 72 - 1128=935=X34=65766252=20140610-13:27:35.27475=20140610268=1279=2269=122=8207=BVMF48=380965483=79355273=73:52:73272=2014061037=80531932637289=40290=39
10:27:35.412: 657663 - 82 - 1128=935=X34=65766352=20140610-13:27:35.42075=20140610268=1279=0269=122=8207=BVMF48=380965483=79356270=8.31273=73:54:19271=3900272=2014061037016=2014061037017=73:54:1937=80531939463289=40290=50
10:27:35.413: 657664 - 82 - 1128=935=X34=65766452=20140610-13:27:35.42175=20140610268=1279=0269=122=8207=BVMF48=380965483=79357270=8.29273=73:54:21271=7200272=2014061037016=2014061037017=73:54:2137=80531939464289=40290=40
10:27:35.550: 657665 - 72 - 1128=935=X34=65766552=20140610-13:27:35.55875=20140610268=1279=2269=122=8207=BVMF48=380965483=79358273=73:55:57272=2014061037=80531932630289=40290=4
10:27:35.592: 657666 - 80 - 1128=935=X34=65766652=20140610-13:27:35.60075=20140610268=1279=0269=022=8207=BVMF48=380965483=79359270=8.23273=73:56:00271=1900272=2014061037016=2014061037017=73:56:0037=80531939466288=9290=4
10:27:35.597: 657667 - 80 - 1128=935=X34=65766752=20140610-13:27:35.60575=20140610268=1279=0269=022=8207=BVMF48=380965483=79360270=8.22273=73:56:04271=900272=2014061037016=2014061037017=73:56:0437=80531939467288=3290=10
10:27:35.920: 657668 - 84 - 1128=935=X34=65766852=20140610-13:27:35.92875=20140610268=1279=0269=122=8207=BVMF48=380249383=103369270=9.4273=73:59:28271=5000272=2014061037016=2014061037017=73:59:2737=80531939470289=735290=32
10:27:36.506: 657669 - 154 - 1128=935=X34=65766952=20140610-13:27:36.51475=20140610268=3279=0269=222=8207=BVMF48=380394783=65706270=17.02273=73:65:13271=100272=2014061037016=2014061037017=73:65:131500=E451=-0.141020=18800274=21003=1120288=3289=3279=0269=922=8207=BVMF48=380394783=65707270=17.1273=73:65:13272=201406101500=E279=1269=022=8207=BVMF48=380394783=65708270=17.02273=73:65:13271=600272=2014061037016=2014061037017=50:96:4837=80531929161288=3290=1
10:27:36.511: 657670 - 71 - 1128=935=X34=65767052=20140610-13:27:36.51975=20140610268=1279=2269=122=8207=BVMF48=380391383=106091273=73:65:18272=2014061037=80531935355289=3290=8
10:27:36.518: 657671 - 156 - 1128=935=X34=65767152=20140610-13:27:36.52675=20140610268=3279=0269=222=8207=BVMF48=380391383=106092270=13.83273=73:65:25271=200272=2014061037016=2014061037017=73:65:251500=E451=-0.061020=107500274=21003=3270288=39289=3279=0269=922=8207=BVMF48=380391383=106093270=13.878273=73:65:25272=201406101500=E279=1269=022=8207=BVMF48=380391383=106094270=13.83273=73:65:25271=3200272=2014061037016=2014061037017=25:97:0537=80531848615288=39290=1
10:27:36.524: 657672 - 81 - 1128=935=X34=65767252=20140610-13:27:36.53275=20140610268=1279=0269=122=8207=BVMF48=380391383=106095270=13.86273=73:65:31271=1100272=2014061037016=2014061037017=73:65:3137=80531939561289=3290=8
10:27:36.525: 657673 - 70 - 1128=935=X34=65767352=20140610-13:27:36.53375=20140610268=1279=2269=022=8207=BVMF48=380391383=106096273=73:65:32272=2014061037=80531919194288=8290=3
10:27:36.547: 657674 - 81 - 1128=935=X34=65767452=20140610-13:27:36.55575=20140610268=1279=0269=122=8207=BVMF48=380394783=65709270=17.06273=73:65:54271=100272=2014061037016=2014061037017=73:65:5437=80531939564289=8290=6
10:27:36.594: 657675 - 80 - 1128=935=X34=65767552=20140610-13:27:36.60275=20140610268=1279=0269=022=8207=BVMF48=380391383=106097270=13.83273=73:66:02271=300272=2014061037016=2014061037017=73:66:0237=80531939566288=8290=6
10:27:36.595: 657676 - 70 - 1128=935=X34=65767652=20140610-13:27:36.60375=20140610268=1279=2269=022=8207=BVMF48=380391383=106098273=73:66:03272=2014061037=80531939036288=8290=5
10:27:37.096: 657677 - 71 - 1128=935=X34=65767752=20140610-13:27:37.10475=20140610268=1279=2269=122=8207=BVMF48=380968883=253222273=73:71:04272=2014061037=80531939333289=8290=2
10:27:37.104: 657678 - 70 - 1128=935=X34=65767852=20140610-13:27:37.11275=20140610268=1279=2269=022=8207=BVMF48=380965483=79361273=73:71:12272=2014061037=80531939216288=8290=7
10:27:37.106: 657679 - 120 - 1128=935=X34=65767952=20140610-13:27:37.11475=20140610268=2279=2269=122=8207=BVMF48=380968883=253223273=73:71:13272=2014061037=80531939334289=45290=2279=0269=122=8207=BVMF48=380968883=253224270=29.4273=73:71:13271=5000272=2014061037016=2014061037017=73:71:1337=80531939574289=45290=6
10:27:37.139: 657680 - 80 - 1128=935=X34=65768052=20140610-13:27:37.14675=20140610268=1279=1269=122=8207=BVMF48=380963983=255305270=26.42273=73:71:46271=600272=2014061037016=2014061037017=72:73:2537=80531939602289=8290=2
10:27:37.148: 657681 - 160 - 1128=935=X34=65768152=20140610-13:27:37.15675=20140610268=3279=0269=222=8207=BVMF48=380963983=255306270=26.42273=73:71:56271=100272=2014061037016=2014061037017=73:71:551500=E451=-0.191020=1355100274=1277=L1003=18350288=735289=27279=0269=922=8207=BVMF48=380963983=255307270=26.472273=73:71:56272=201406101500=E279=1269=122=8207=BVMF48=380963983=255308270=26.42273=73:71:56271=300272=2014061037016=2014061037017=72:56:5637=80531939243289=27290=1
10:27:37.264: 657682 - 183 - 1128=935=X34=65768252=20140610-13:27:37.27275=20140610268=4279=0269=222=8207=BVMF48=380963983=255309270=26.42273=73:72:72271=300272=2014061037016=2014061037017=73:72:711500=E451=-0.191020=1355400274=1277=L1003=18360288=3289=27279=0269=922=8207=BVMF48=380963983=255310270=26.472273=73:72:72272=201406101500=E279=2269=022=8207=BVMF48=380963983=255311273=73:72:72272=2014061037=80531939324288=3290=4279=2269=122=8207=BVMF48=380963983=255312273=73:72:72272=2014061037=80531939243289=27290=1
10:27:37.298: 657683 - 80 - 1128=935=X34=65768352=20140610-13:27:37.30675=20140610268=1279=0269=022=8207=BVMF48=380963983=255313270=26.41273=73:73:05271=600272=2014061037016=2014061037017=73:73:0537=80531939628288=3290=4
10:27:37.353: 657684 - 71 - 1128=935=X34=65768452=20140610-13:27:37.36175=20140610268=1279=2269=122=8207=BVMF48=380391383=106099273=73:73:60272=2014061037=80531935709289=8290=5
10:27:38.104: 657685 - 80 - 1128=935=X34=65768552=20140610-13:27:38.11275=20140610268=1279=0269=022=8207=BVMF48=380965483=79362270=8.23273=73:81:12271=5300272=2014061037016=2014061037017=73:81:1237=80531939636288=8290=5
10:27:38.105: 657686 - 71 - 1128=935=X34=65768652=20140610-13:27:38.11375=20140610268=1279=2269=122=8207=BVMF48=380965483=79363273=73:81:13272=2014061037=80531932282289=8290=3
10:27:38.129: 657687 - 72 - 1128=935=X34=65768752=20140610-13:27:38.13775=20140610268=1279=2269=022=8207=BVMF48=380965483=79364273=73:81:36272=2014061037=80531939035288=114290=7
10:27:38.348: 657688 - 82 - 1128=935=X34=65768852=20140610-13:27:38.35675=20140610268=1279=0269=022=8207=BVMF48=380965483=79365270=8.23273=73:83:56271=1000272=2014061037016=2014061037017=73:83:5637=80531939638288=114290=6
10:27:38.650: 657689 - 82 - 1128=935=X34=65768952=20140610-13:27:38.65875=20140610268=1279=0269=122=8207=BVMF48=380963983=255314270=26.42273=73:86:58271=300272=2014061037016=2014061037017=73:86:5837=80531939639289=27290=4
10:27:39.210: 657690 - 82 - 1128=935=X34=65769052=20140610-13:27:39.21875=20140610268=1279=0269=122=8207=BVMF48=380249383=103370270=9.33273=73:92:17271=400272=2014061037016=2014061037017=73:92:1737=80531939642289=70290=1
10:27:39.220: 657691 - 121 - 1128=935=X34=65769152=20140610-13:27:39.22875=20140610268=2279=2269=122=8207=BVMF48=380249383=103371273=73:92:28272=2014061037=80531938455289=735290=6279=0269=122=8207=BVMF48=380249383=103372270=9.33273=73:92:28271=200272=2014061037016=2014061037017=73:92:2837=80531939651289=735290=2
10:27:39.253: 657692 - 71 - 1128=935=X34=65769252=20140610-13:27:39.26175=20140610268=1279=2269=122=8207=BVMF48=380249383=103373273=73:92:60272=2014061037=80531938456289=8290=7
10:27:39.293: 657693 - 270 - 1128=935=X34=65769352=20140610-13:27:39.30175=20140610268=6279=0269=222=8207=BVMF48=380249383=103374270=9.33273=73:93:01271=400272=2014061037016=2014061037017=73:93:001500=E451=-0.121020=257800274=01003=3580288=308289=70279=0269=922=8207=BVMF48=380249383=103375270=9.382273=73:93:01272=201406101500=E279=0269=222=8207=BVMF48=380249383=103376270=9.33273=73:93:01271=100272=2014061037016=2014061037017=73:93:001500=E451=-0.121020=257900274=1277=L1003=3590288=308289=735279=0269=922=8207=BVMF48=380249383=103377270=9.382273=73:93:01272=201406101500=E279=2269=122=8207=BVMF48=380249383=103378273=73:93:01272=2014061037=80531939642289=70290=1279=1269=122=8207=BVMF48=380249383=103379270=9.33273=73:93:01271=100272=2014061037016=2014061037017=73:92:2837=80531939651289=735290=1
10:27:39.347: 657694 - 70 - 1128=935=X34=65769452=20140610-13:27:39.35575=20140610268=1279=2269=022=8207=BVMF48=380249383=103380273=73:93:54272=2014061037=80531938693288=8290=11
10:27:39.505: 657695 - 81 - 1128=935=X34=65769552=20140610-13:27:39.51375=20140610268=1279=0269=122=8207=BVMF48=380968883=253225270=29.39273=73:95:13271=300272=2014061037016=2014061037017=73:95:1237=80531939656289=8290=2
10:27:39.526: 657696 - 119 - 1128=935=X34=65769652=20140610-13:27:39.53375=20140610268=2279=2269=122=8207=BVMF48=380968883=253226273=73:95:33272=2014061037=80531939574289=45290=7279=0269=122=8207=BVMF48=380968883=253227270=29.39273=73:95:33271=300272=2014061037016=2014061037017=73:95:3337=80531939657289=45290=3
10:27:39.596: 657697 - 81 - 1128=935=X34=65769752=20140610-13:27:39.60275=20140610268=1279=0269=122=8207=BVMF48=380963983=255315270=26.42273=73:96:02271=700272=2014061037016=2014061037017=73:96:0237=80531939658289=8290=5
10:27:39.603: 657698 - 81 - 1128=935=X34=65769852=20140610-13:27:39.61175=20140610268=1279=0269=022=8207=BVMF48=380963983=255316270=26.34273=73:96:11271=5000272=2014061037016=2014061037017=73:96:1037=80531939663288=45290=46
10:27:39.603: 657699 - 82 - 1128=935=X34=65769952=20140610-13:27:39.61175=20140610268=1279=0269=122=8207=BVMF48=380963983=255317270=26.51273=73:96:11271=5000272=2014061037016=2014061037017=73:96:1137=80531939665289=45290=58
10:27:39.644: 657700 - 72 - 1128=935=X34=65770052=20140610-13:27:39.65275=20140610268=1279=2269=022=8207=BVMF48=380968883=253228273=73:96:52272=2014061037=80531930828288=227290=10
10:27:39.644: 657701 - 82 - 1128=935=X34=65770152=20140610-13:27:39.65375=20140610268=1279=0269=022=8207=BVMF48=380968883=253229270=29.32273=73:96:52271=1000272=2014061037016=2014061037017=73:96:5237=80531939666288=227290=26
10:27:39.713: 657702 - 148 - 1128=935=X34=65770252=20140610-13:27:39.72175=20140610268=3279=0269=222=8207=BVMF48=380249383=103381270=9.33273=73:97:20271=100272=2014061037016=2014061037017=73:97:201500=E451=-0.121020=258000274=1277=L1003=3600288=45289=735279=0269=922=8207=BVMF48=380249383=103382270=9.382273=73:97:20272=201406101500=E279=2269=122=8207=BVMF48=380249383=103383273=73:97:20272=2014061037=80531939651289=735290=1
10:27:39.724: 657703 - 83 - 1128=935=X34=65770352=20140610-13:27:39.73375=20140610268=1279=0269=122=8207=BVMF48=380249383=103384270=9.34273=73:97:32271=200272=2014061037016=2014061037017=73:97:3237=80531939676289=735290=5
10:27:39.726: 657704 - 81 - 1128=935=X34=65770452=20140610-13:27:39.73475=20140610268=1279=0269=122=8207=BVMF48=380249383=103385270=9.34273=73:97:34271=100272=2014061037016=2014061037017=73:97:3337=80531939677289=8290=6
10:27:39.753: 657705 - 81 - 1128=935=X34=65770552=20140610-13:27:39.76175=20140610268=1279=0269=122=8207=BVMF48=380249383=103386270=9.34273=73:97:60271=100272=2014061037016=2014061037017=73:97:6037=80531939678289=8290=7
10:27:39.802: 657706 - 82 - 1128=935=X34=65770652=20140610-13:27:39.81075=20140610268=1279=0269=122=8207=BVMF48=380965483=79366270=8.27273=73:98:09271=1500272=2014061037016=2014061037017=73:98:0937=80531939679289=98290=21
10:27:40.008: 657707 - 159 - 1128=935=X34=65770752=20140610-13:27:40.01675=20140610268=3279=0269=222=8207=BVMF48=380965483=79367270=8.23273=74:00:15271=100272=2014061037016=2014061037017=74:00:151500=E451=-0.051020=194400274=21003=2760288=227289=238279=0269=922=8207=BVMF48=380965483=79368270=8.254273=74:00:15272=201406101500=E279=1269=022=8207=BVMF48=380965483=79369270=8.23273=74:00:15271=13000272=2014061037016=2014061037017=73:50:8637=80531939345288=227290=1
10:27:40.019: 657708 - 83 - 1128=935=X34=65770852=20140610-13:27:40.02775=20140610268=1279=0269=122=8207=BVMF48=380963983=255318270=26.42273=74:00:27271=200272=2014061037016=2014061037017=74:00:2637=80531939684289=238290=6
10:27:40.314: 657709 - 151 - 1128=935=X34=65770952=20140610-13:27:40.32275=20140610268=3279=0269=222=8207=BVMF48=380342683=421270=12.12273=74:03:21271=100272=2014061037016=2014061037017=74:03:211500=E451=-0.121020=900274=01003=60288=3289=227279=0269=922=8207=BVMF48=380342683=422270=12.14273=74:03:21272=201406101500=E279=1269=022=8207=BVMF48=380342683=423270=12.12273=74:03:21271=100272=2014061037016=2014061037017=12:84:0137=80531919626288=3290=1
10:27:40.579: 657710 - 81 - 1128=935=X34=65771052=20140610-13:27:40.58775=20140610268=1279=0269=022=8207=BVMF48=380963983=255319270=26.41273=74:05:86271=100272=2014061037016=2014061037017=74:05:8637=80531939695288=70290=5
10:27:40.587: 657711 - 118 - 1128=935=X34=65771152=20140610-13:27:40.59675=20140610268=2279=2269=022=8207=BVMF48=380249383=103387273=74:05:95272=2014061037=80531938493288=40290=17279=0269=022=8207=BVMF48=380249383=103388270=9.31273=74:05:95271=100272=2014061037016=2014061037017=74:05:9537=80531939696288=40290=11
10:27:40.592: 657712 - 118 - 1128=935=X34=65771252=20140610-13:27:40.60075=20140610268=2279=2269=022=8207=BVMF48=380963983=255320273=74:05:99272=2014061037=80531939224288=45290=10279=0269=022=8207=BVMF48=380963983=255321270=26.41273=74:05:99271=100272=2014061037016=2014061037017=74:05:9937=80531939697288=45290=6
10:27:40.768: 657713 - 72 - 1128=935=X34=65771352=20140610-13:27:40.77575=20140610268=1279=2269=022=8207=BVMF48=380968883=253230273=74:07:75272=2014061037=80531939666288=227290=26
10:27:40.768: 657714 - 82 - 1128=935=X34=65771452=20140610-13:27:40.77675=20140610268=1279=0269=022=8207=BVMF48=380968883=253231270=29.36273=74:07:75271=1000272=2014061037016=2014061037017=74:07:7537=80531939698288=227290=12
10:27:41.213: 657715 - 81 - 1128=935=X34=65771552=20140610-13:27:41.22175=20140610268=1279=0269=022=8207=BVMF48=380249383=103389270=9.32273=74:12:21271=100272=2014061037016=2014061037017=74:12:2037=80531939702288=40290=8
10:27:41.214: 657716 - 80 - 1128=935=X34=65771652=20140610-13:27:41.22375=20140610268=1279=0269=022=8207=BVMF48=380249383=103390270=9.31273=74:12:22271=100272=2014061037016=2014061037017=74:12:2237=80531939703288=8290=13
10:27:41.225: 657717 - 194 - 1128=935=X34=65771752=20140610-13:27:41.23375=20140610268=4279=0269=222=8207=BVMF48=380963983=255322270=26.42273=74:12:33271=300272=2014061037016=2014061037017=74:12:321500=E451=-0.191020=1355700274=1277=L1003=18370288=3289=8279=0269=922=8207=BVMF48=380963983=255323270=26.472273=74:12:33272=201406101500=E279=1269=122=8207=BVMF48=380963983=255324270=26.42273=74:12:33271=300272=2014061037016=2014061037017=72:73:2537=80531939602289=8290=1279=2269=022=8207=BVMF48=380963983=255325273=74:12:33272=2014061037=80531939628288=3290=4
10:27:41.236: 657718 - 80 - 1128=935=X34=65771852=20140610-13:27:41.24475=20140610268=1279=0269=022=8207=BVMF48=380963983=255326270=26.41273=74:12:43271=600272=2014061037016=2014061037017=74:12:4337=80531939707288=3290=6
10:27:41.240: 657719 - 156 - 1128=935=X34=65771952=20140610-13:27:41.24875=20140610268=3279=0269=222=8207=BVMF48=380968883=253232270=29.39273=74:12:48271=300272=2014061037016=2014061037017=74:12:481500=E451=-0.241020=429400274=01003=6170288=8289=45279=0269=922=8207=BVMF48=380968883=253233270=29.482273=74:12:48272=201406101500=E279=1269=122=8207=BVMF48=380968883=253234270=29.39273=74:12:48271=900272=2014061037016=2014061037017=70:17:4337=80531938566289=45290=1
10:27:41.246: 657720 - 71 - 1128=935=X34=65772052=20140610-13:27:41.25475=20140610268=1279=2269=122=8207=BVMF48=380963983=255327273=74:12:53272=2014061037=80531939336289=8290=3
10:27:41.248: 657721 - 71 - 1128=935=X34=65772152=20140610-13:27:41.25775=20140610268=1279=2269=122=8207=BVMF48=380963983=255328273=74:12:56272=2014061037=80531939602289=8290=1
10:27:41.250: 657722 - 71 - 1128=935=X34=65772252=20140610-13:27:41.25875=20140610268=1279=2269=122=8207=BVMF48=380963983=255329273=74:12:57272=2014061037=80531939658289=8290=3
10:27:41.270: 657723 - 81 - 1128=935=X34=65772352=20140610-13:27:41.27875=20140610268=1279=0269=122=8207=BVMF48=380963983=255330270=26.42273=74:12:77271=1600272=2014061037016=2014061037017=74:12:7737=80531939734289=8290=4
10:27:41.428: 657724 - 81 - 1128=935=X34=65772452=20140610-13:27:41.43675=20140610268=1279=0269=022=8207=BVMF48=380249383=103391270=9.32273=74:14:36271=2200272=2014061037016=2014061037017=74:14:3637=80531939754288=21290=9
10:27:41.485: 657725 - 65 - 1128=935=X34=65772552=20140610-13:27:41.49375=20140610268=1279=0269=B22=8207=BVMF48=380965483=79370270=1604659273=74:14:92271=276272=201406101500=E15=BRL
10:27:41.486: 657726 - 65 - 1128=935=X34=65772652=20140610-13:27:41.49475=20140610268=1279=0269=B22=8207=BVMF48=380391383=106100270=1491868273=74:14:92271=327272=201406101500=E15=BRL
10:27:41.504: 657727 - 64 - 1128=935=X34=65772752=20140610-13:27:41.51275=20140610268=1279=0269=B22=8207=BVMF48=380394783=65710270=321482273=74:15:08271=112272=201406101500=E15=BRL
10:27:41.516: 657728 - 65 - 1128=935=X34=65772852=20140610-13:27:41.52475=20140610268=1279=0269=B22=8207=BVMF48=380963983=255331270=35888380273=74:14:92271=1837272=201406101500=E15=BRL
10:27:41.532: 657729 - 65 - 1128=935=X34=65772952=20140610-13:27:41.54075=20140610268=1279=0269=B22=8207=BVMF48=380249383=103392270=2420450273=74:15:08271=359272=201406101500=E15=BRL
10:27:41.547: 657730 - 62 - 1128=935=X34=65773052=20140610-13:27:41.55675=20140610268=1279=0269=B22=8207=BVMF48=380342683=424270=10926273=74:14:92271=6272=201406101500=E15=BRL
10:27:41.548: 657731 - 62 - 1128=935=X34=65773152=20140610-13:27:41.55675=20140610268=1279=0269=B22=8207=BVMF48=380557983=2416270=13956273=74:14:92271=7272=201406101500=E15=BRL
10:27:41.548: 657732 - 65 - 1128=935=X34=65773252=20140610-13:27:41.55675=20140610268=1279=0269=B22=8207=BVMF48=380968883=253235270=12659593273=74:14:92271=617272=201406101500=E15=BRL
10:27:41.697: 657733 - 82 - 1128=935=X34=65773352=20140610-13:27:41.70575=20140610268=1279=0269=122=8207=BVMF48=380963983=255332270=26.52273=74:17:05271=5000272=2014061037016=2014061037017=74:17:0537=80531939759289=45290=63
10:27:41.721: 657734 - 158 - 1128=935=X34=65773452=20140610-13:27:41.72975=20140610268=3279=0269=222=8207=BVMF48=380968883=253236270=29.39273=74:17:28271=800272=2014061037016=2014061037017=74:17:281500=E451=-0.241020=430200274=1277=L1003=6180288=227289=45279=0269=922=8207=BVMF48=380968883=253237270=29.482273=74:17:28272=201406101500=E279=1269=122=8207=BVMF48=380968883=253238270=29.39273=74:17:28271=100272=2014061037016=2014061037017=70:17:4337=80531938566289=45290=1
10:27:41.722: 657735 - 71 - 1128=935=X34=65773552=20140610-13:27:41.73075=20140610268=1279=2269=122=8207=BVMF48=380968883=253239273=74:17:30272=2014061037=80531939656289=8290=2
10:27:41.737: 657736 - 73 - 1128=935=X34=65773652=20140610-13:27:41.74575=20140610268=1279=2269=122=8207=BVMF48=380963983=255333273=74:17:45272=2014061037=80531937189289=227290=11
10:27:41.741: 657737 - 80 - 1128=935=X34=65773752=20140610-13:27:41.74975=20140610268=1279=1269=122=8207=BVMF48=380963983=255334270=26.42273=74:17:49271=400272=2014061037016=2014061037017=74:12:7737=80531939761289=8290=4
10:27:41.747: 657738 - 83 - 1128=935=X34=65773852=20140610-13:27:41.75575=20140610268=1279=0269=122=8207=BVMF48=380963983=255335270=26.44273=74:17:54271=700272=2014061037016=2014061037017=74:17:5437=80531939766289=227290=14
10:27:41.756: 657739 - 73 - 1128=935=X34=65773952=20140610-13:27:41.76475=20140610268=1279=2269=122=8207=BVMF48=380963983=255336273=74:17:64272=2014061037=80531939766289=227290=14
10:27:41.762: 657740 - 83 - 1128=935=X34=65774052=20140610-13:27:41.77075=20140610268=1279=0269=122=8207=BVMF48=380963983=255337270=26.44273=74:17:70271=400272=2014061037016=2014061037017=74:17:7037=80531939770289=227290=14
10:27:41.780: 657741 - 120 - 1128=935=X34=65774152=20140610-13:27:41.78875=20140610268=2279=2269=122=8207=BVMF48=380968883=253240273=74:17:87272=2014061037=80531939657289=45290=2279=0269=122=8207=BVMF48=380968883=253241270=29.4273=74:17:87271=5000272=2014061037016=2014061037017=74:17:8737=80531939771289=45290=6
10:27:41.795: 657742 - 73 - 1128=935=X34=65774252=20140610-13:27:41.80375=20140610268=1279=2269=122=8207=BVMF48=380963983=255338273=74:18:02272=2014061037=80531939770289=227290=14
10:27:41.805: 657743 - 83 - 1128=935=X34=65774352=20140610-13:27:41.81275=20140610268=1279=0269=122=8207=BVMF48=380963983=255339270=26.44273=74:18:12271=100272=2014061037016=2014061037017=74:18:1137=80531939772289=227290=14
10:27:41.805: 657744 - 80 - 1128=935=X34=65774452=20140610-13:27:41.81275=20140610268=1279=1269=122=8207=BVMF48=380963983=255340270=26.42273=74:18:12271=100272=2014061037016=2014061037017=74:12:7737=80531939773289=8290=4
10:27:42.007: 657745 - 71 - 1128=935=X34=65774552=20140610-13:27:42.01675=20140610268=1279=2269=122=8207=BVMF48=380963983=255341273=74:20:15272=2014061037=80531938836289=8290=8
10:27:42.017: 657746 - 149 - 1128=935=X34=65774652=20140610-13:27:42.02575=20140610268=3279=0269=222=8207=BVMF48=380963983=255342270=26.42273=74:20:24271=200272=2014061037016=2014061037017=74:20:241500=E451=-0.191020=1355900274=1277=L1003=18380288=735289=40279=0269=922=8207=BVMF48=380963983=255343270=26.472273=74:20:24272=201406101500=E279=2269=122=8207=BVMF48=380963983=255344273=74:20:24272=2014061037=80531939328289=40290=1
10:27:42.051: 657747 - 81 - 1128=935=X34=65774752=20140610-13:27:42.05975=20140610268=1279=0269=122=8207=BVMF48=380963983=255345270=26.43273=74:20:59271=100272=2014061037016=2014061037017=74:20:5837=80531939789289=8290=7
10:27:42.134: 657748 - 71 - 1128=935=X34=65774852=20140610-13:27:42.14375=20140610268=1279=2269=122=8207=BVMF48=380965483=79371273=74:21:42272=2014061037=80531939354289=8290=4
10:27:42.175: 657749 - 82 - 1128=935=X34=65774952=20140610-13:27:42.18375=20140610268=1279=0269=122=8207=BVMF48=380963983=255346270=26.42273=74:21:83271=300272=2014061037016=2014061037017=74:21:8237=80531939792289=40290=4
10:27:42.547: 657750 - 327 - 1128=935=X34=65775052=20140610-13:27:42.55575=20140610268=8279=0269=222=8207=BVMF48=380968883=253242270=29.38273=74:25:54271=300272=2014061037016=2014061037017=74:25:541500=E451=-0.251020=430500274=21003=6190288=70289=21279=0269=922=8207=BVMF48=380968883=253243270=29.482273=74:25:54272=201406101500=E279=0269=222=8207=BVMF48=380968883=253244270=29.38273=74:25:54271=400272=2014061037016=2014061037017=74:25:541500=E451=-0.251020=430900274=3277=L1003=6200288=40289=21279=0269=922=8207=BVMF48=380968883=253245270=29.482273=74:25:54272=201406101500=E279=0269=222=8207=BVMF48=380968883=253246270=29.38273=74:25:54271=300272=2014061037016=2014061037017=74:25:541500=E451=-0.251020=431200274=3277=L1003=6210288=40289=21279=0269=922=8207=BVMF48=380968883=253247270=29.482273=74:25:54272=201406101500=E279=4269=022=8207=BVMF48=380968883=253248273=74:25:54272=20140610290=2279=1269=022=8207=BVMF48=380968883=253249270=29.38273=74:25:54271=100272=2014061037016=2014061037017=64:65:0937=80531937540288=40290=1
10:27:42.559: 657751 - 80 - 1128=935=X34=65775152=20140610-13:27:42.56875=20140610268=1279=1269=022=8207=BVMF48=380968883=253250270=29.38273=74:25:67271=500272=2014061037016=2014061037017=73:39:4237=80531939797288=45290=4
10:27:42.561: 657752 - 81 - 1128=935=X34=65775252=20140610-13:27:42.56975=20140610268=1279=0269=122=8207=BVMF48=380968883=253251270=29.39273=74:25:69271=300272=2014061037016=2014061037017=74:25:6937=80531939798289=8290=2
10:27:42.574: 657753 - 119 - 1128=935=X34=65775352=20140610-13:27:42.58275=20140610268=2279=2269=122=8207=BVMF48=380968883=253252273=74:25:81272=2014061037=80531939771289=45290=7279=0269=122=8207=BVMF48=380968883=253253270=29.39273=74:25:81271=300272=2014061037016=2014061037017=74:25:8137=80531939799289=45290=3
10:27:42.579: 657754 - 73 - 1128=935=X34=65775452=20140610-13:27:42.58875=20140610268=1279=2269=122=8207=BVMF48=380963983=255347273=74:25:87272=2014061037=80531939772289=227290=14
10:27:42.590: 657755 - 83 - 1128=935=X34=65775552=20140610-13:27:42.59875=20140610268=1279=0269=122=8207=BVMF48=380963983=255348270=26.44273=74:25:98271=400272=2014061037016=2014061037017=74:25:9737=80531939800289=227290=14
10:27:42.602: 657756 - 73 - 1128=935=X34=65775652=20140610-13:27:42.61175=20140610268=1279=2269=122=8207=BVMF48=380963983=255349273=74:26:10272=2014061037=80531939800289=227290=14
10:27:42.613: 657757 - 83 - 1128=935=X34=65775752=20140610-13:27:42.62175=20140610268=1279=0269=122=8207=BVMF48=380963983=255350270=26.44273=74:26:20271=700272=2014061037016=2014061037017=74:26:2037=80531939801289=227290=14
10:27:43.017: 657758 - 71 - 1128=935=X34=65775852=20140610-13:27:43.02575=20140610268=1279=2269=122=8207=BVMF48=380963983=255351273=74:30:25272=2014061037=80531939789289=8290=8
10:27:43.034: 657759 - 81 - 1128=935=X34=65775952=20140610-13:27:43.04275=20140610268=1279=0269=122=8207=BVMF48=380963983=255352270=26.43273=74:30:41271=500272=2014061037016=2014061037017=74:30:4137=80531939803289=8290=8
10:27:43.049: 657760 - 72 - 1128=935=X34=65776052=20140610-13:27:43.05875=20140610268=1279=2269=022=8207=BVMF48=380963983=255353273=74:30:57272=2014061037=80531930364288=386290=52
10:27:43.147: 657761 - 70 - 1128=935=X34=65776152=20140610-13:27:43.15575=20140610268=1279=2269=022=8207=BVMF48=380249383=103393273=74:31:55272=2014061037=80531939703288=8290=14
10:27:43.199: 657762 - 83 - 1128=935=X34=65776252=20140610-13:27:43.20775=20140610268=1279=0269=022=8207=BVMF48=380963983=255354270=26.36273=74:32:06271=10000272=2014061037016=2014061037017=74:32:0637=80531939804288=386290=34
10:27:43.219: 657763 - 71 - 1128=935=X34=65776352=20140610-13:27:43.22775=20140610268=1279=2269=122=8207=BVMF48=380963983=255355273=74:32:27272=2014061037=80531939803289=8290=8
10:27:43.250: 657764 - 81 - 1128=935=X34=65776452=20140610-13:27:43.25875=20140610268=1279=0269=122=8207=BVMF48=380963983=255356270=26.42273=74:32:58271=600272=2014061037016=2014061037017=74:32:5837=80531939805289=8290=5
10:27:43.262: 657765 - 81 - 1128=935=X34=65776552=20140610-13:27:43.27075=20140610268=1279=0269=122=8207=BVMF48=380963983=255357270=26.43273=74:32:70271=800272=2014061037016=2014061037017=74:32:7037=80531939814289=8290=9
10:27:43.701: 657766 - 80 - 1128=935=X34=65776652=20140610-13:27:43.71075=20140610268=1279=0269=022=8207=BVMF48=380391383=106101270=13.84273=74:37:09271=100272=2014061037016=2014061037017=74:37:0937=80531939833288=8290=1
10:27:43.703: 657767 - 143 - 1128=935=X34=65776752=20140610-13:27:43.71175=20140610268=3279=0269=222=8207=BVMF48=380391383=106102270=13.84273=74:37:11271=100272=2014061037016=2014061037017=74:37:101500=E451=-0.051020=107600274=01003=3280288=8289=8279=0269=922=8207=BVMF48=380391383=106103270=13.878273=74:37:11272=201406101500=E279=2269=022=8207=BVMF48=380391383=106104273=74:37:11272=2014061037=80531939833288=8290=1
10:27:43.734: 657768 - 72 - 1128=935=X34=65776852=20140610-13:27:43.74375=20140610268=1279=2269=022=8207=BVMF48=380394783=65711273=74:37:42272=2014061037=80531939319288=110290=10
10:27:43.738: 657769 - 82 - 1128=935=X34=65776952=20140610-13:27:43.74675=20140610268=1279=0269=022=8207=BVMF48=380394783=65712270=16.98273=74:37:46271=400272=2014061037016=2014061037017=74:37:4537=80531939855288=110290=10
10:27:43.754: 657770 - 81 - 1128=935=X34=65777052=20140610-13:27:43.76275=20140610268=1279=0269=022=8207=BVMF48=380968883=253254270=29.33273=74:37:61271=100272=2014061037016=2014061037017=74:37:6137=80531939859288=72290=22
10:27:43.815: 657771 - 83 - 1128=935=X34=65777152=20140610-13:27:43.82375=20140610268=1279=0269=122=8207=BVMF48=380391383=106105270=13.84273=74:38:23271=100272=2014061037016=2014061037017=74:38:2237=80531939860289=227290=1
10:27:43.930: 657772 - 73 - 1128=935=X34=65777252=20140610-13:27:43.93875=20140610268=1279=2269=122=8207=BVMF48=380391383=106106273=74:39:38272=2014061037=80531939860289=227290=1
10:27:43.953: 657773 - 81 - 1128=935=X34=65777352=20140610-13:27:43.96175=20140610268=1279=0269=122=8207=BVMF48=380391383=106107270=13.85273=74:39:60271=100272=2014061037016=2014061037017=74:39:6037=80531939863289=8290=5
10:27:44.224: 657774 - 82 - 1128=935=X34=65777452=20140610-13:27:44.23275=20140610268=1279=0269=122=8207=BVMF48=380249383=103394270=9.33273=74:42:31271=300272=2014061037016=2014061037017=74:42:3137=80531939864289=72290=1
10:27:44.225: 657775 - 80 - 1128=935=X34=65777552=20140610-13:27:44.23475=20140610268=1279=0269=022=8207=BVMF48=380249383=103395270=9.31273=74:42:33271=100272=2014061037016=2014061037017=74:42:3337=80531939865288=8290=14
10:27:44.253: 657776 - 71 - 1128=935=X34=65777652=20140610-13:27:44.26175=20140610268=1279=2269=122=8207=BVMF48=380249383=103396273=74:42:60272=2014061037=80531939677289=8290=7
10:27:44.727: 657777 - 146 - 1128=935=X34=65777752=20140610-13:27:44.73675=20140610268=3279=0269=222=8207=BVMF48=380249383=103397270=9.33273=74:47:35271=300272=2014061037016=2014061037017=74:47:341500=E451=-0.121020=258300274=1277=L1003=3610288=45289=72279=0269=922=8207=BVMF48=380249383=103398270=9.382273=74:47:35272=201406101500=E279=2269=122=8207=BVMF48=380249383=103399273=74:47:35272=2014061037=80531939864289=72290=1
10:27:44.747: 657778 - 70 - 1128=935=X34=65777852=20140610-13:27:44.75575=20140610268=1279=2269=022=8207=BVMF48=380249383=103400273=74:47:54272=2014061037=80531939865288=8290=14
10:27:44.747: 657779 - 71 - 1128=935=X34=65777952=20140610-13:27:44.75575=20140610268=1279=2269=122=8207=BVMF48=380249383=103401273=74:47:54272=2014061037=80531939344289=8290=11
10:27:45.335: 657780 - 158 - 1128=935=X34=65778052=20140610-13:27:45.34375=20140610268=3279=0269=222=8207=BVMF48=380965483=79372270=8.23273=74:53:42271=200272=2014061037016=2014061037017=74:53:421500=E451=-0.051020=194600274=3277=L1003=2770288=227289=72279=0269=922=8207=BVMF48=380965483=79373270=8.254273=74:53:42272=201406101500=E279=1269=022=8207=BVMF48=380965483=79374270=8.23273=74:53:42271=12800272=2014061037016=2014061037017=73:50:8637=80531939345288=227290=1
10:27:45.356: 657781 - 183 - 1128=935=X34=65778152=20140610-13:27:45.36475=20140610268=4279=0269=222=8207=BVMF48=380963983=255358270=26.42273=74:53:64271=300272=2014061037016=2014061037017=74:53:631500=E451=-0.191020=1356200274=1277=L1003=18390288=3289=27279=0269=922=8207=BVMF48=380963983=255359270=26.472273=74:53:64272=201406101500=E279=2269=022=8207=BVMF48=380963983=255360273=74:53:64272=2014061037=80531939707288=3290=6279=2269=122=8207=BVMF48=380963983=255361273=74:53:64272=2014061037=80531939639289=27290=1
10:27:45.366: 657782 - 80 - 1128=935=X34=65778252=20140610-13:27:45.37475=20140610268=1279=0269=022=8207=BVMF48=380963983=255362270=26.41273=74:53:73271=600272=2014061037016=2014061037017=74:53:7337=80531939889288=3290=6
10:27:46.650: 657783 - 82 - 1128=935=X34=65778352=20140610-13:27:46.65975=20140610268=1279=0269=122=8207=BVMF48=380963983=255363270=26.42273=74:66:58271=300272=2014061037016=2014061037017=74:66:5837=80531939896289=27290=5
10:27:47.372: 657784 - 83 - 1128=935=X34=65778452=20140610-13:27:47.38075=20140610268=1279=0269=122=8207=BVMF48=380963983=255364270=26.44273=74:73:79271=700272=2014061037016=2014061037017=74:73:7937=80531939909289=308290=16
10:27:48.078: 657785 - 82 - 1128=935=X34=65778552=20140610-13:27:48.08775=20140610268=1279=0269=122=8207=BVMF48=380965483=79375270=8.24273=74:80:86271=100272=2014061037016=2014061037017=74:80:8637=80531939913289=16290=4
10:27:49.767: 657786 - 71 - 1128=935=X34=65778652=20140610-13:27:49.77675=20140610268=1279=2269=122=8207=BVMF48=380963983=255365273=74:97:75272=2014061037=80531921865289=3290=31
10:27:50.343: 657787 - 71 - 1128=935=X34=65778752=20140610-13:27:50.35275=20140610268=1279=2269=122=8207=BVMF48=380963983=255366273=75:03:51272=2014061037=80531919141289=3290=22
10:27:51.148: 657788 - 70 - 1128=935=X34=65778852=20140610-13:27:51.15775=20140610268=1279=2269=022=8207=BVMF48=380968883=253255273=75:11:56272=2014061037=80531938360288=8290=20
10:27:51.149: 657789 - 80 - 1128=935=X34=65778952=20140610-13:27:51.15875=20140610268=1279=0269=022=8207=BVMF48=380968883=253256270=29.34273=75:11:58271=100272=2014061037016=2014061037017=75:11:5737=80531939923288=8290=18
10:27:51.423: 657790 - 71 - 1128=935=X34=65779052=20140610-13:27:51.43075=20140610268=1279=2269=122=8207=BVMF48=380968883=253257273=75:14:29272=2014061037=80531939798289=8290=2
10:27:51.423: 657791 - 74 - 1128=935=X34=65779152=20140610-13:27:51.43075=20140610268=1279=2269=122=8207=BVMF48=380963983=255367273=75:14:29272=2014061037=80531855877289=386290=193
10:27:51.433: 657792 - 120 - 1128=935=X34=65779252=20140610-13:27:51.44175=20140610268=2279=2269=122=8207=BVMF48=380968883=253258273=75:14:41272=2014061037=80531939799289=45290=2279=0269=122=8207=BVMF48=380968883=253259270=29.4273=75:14:41271=5000272=2014061037016=2014061037017=75:14:4137=80531939924289=45290=6
10:27:51.438: 657793 - 73 - 1128=935=X34=65779352=20140610-13:27:51.44675=20140610268=1279=2269=122=8207=BVMF48=380963983=255368273=75:14:46272=2014061037=80531939801289=227290=15
10:27:51.448: 657794 - 83 - 1128=935=X34=65779452=20140610-13:27:51.45675=20140610268=1279=0269=122=8207=BVMF48=380963983=255369270=26.44273=75:14:55271=400272=2014061037016=2014061037017=75:14:5537=80531939925289=227290=16
10:27:51.460: 657795 - 73 - 1128=935=X34=65779552=20140610-13:27:51.46975=20140610268=1279=2269=122=8207=BVMF48=380963983=255370273=75:14:68272=2014061037=80531939925289=227290=16
10:27:51.471: 657796 - 83 - 1128=935=X34=65779652=20140610-13:27:51.47975=20140610268=1279=0269=122=8207=BVMF48=380963983=255371270=26.44273=75:14:79271=100272=2014061037016=2014061037017=75:14:7937=80531939927289=227290=16
10:27:51.491: 657797 - 80 - 1128=935=X34=65779752=20140610-13:27:51.49975=20140610268=1279=1269=122=8207=BVMF48=380963983=255372270=26.42273=75:14:98271=100272=2014061037016=2014061037017=74:32:5837=80531939928289=8290=4
10:27:51.497: 657798 - 71 - 1128=935=X34=65779852=20140610-13:27:51.50575=20140610268=1279=2269=122=8207=BVMF48=380963983=255373273=75:15:04272=2014061037=80531939773289=8290=2
10:27:51.570: 657799 - 71 - 1128=935=X34=65779952=20140610-13:27:51.57875=20140610268=1279=2269=122=8207=BVMF48=380963983=255374273=75:15:78272=2014061037=80531939814289=8290=8
10:27:51.614: 657800 - 81 - 1128=935=X34=65780052=20140610-13:27:51.62275=20140610268=1279=0269=122=8207=BVMF48=380963983=255375270=26.43273=75:16:21271=500272=2014061037016=2014061037017=75:16:2137=80531939939289=8290=8
10:27:51.622: 657801 - 84 - 1128=935=X34=65780152=20140610-13:27:51.63075=20140610268=1279=0269=122=8207=BVMF48=380963983=255376270=26.95273=75:16:29271=300272=2014061037016=2014061037017=75:16:2937=80531939940289=386290=193
10:27:51.765: 657802 - 71 - 1128=935=X34=65780252=20140610-13:27:51.77475=20140610268=1279=2269=122=8207=BVMF48=380963983=255377273=75:17:73272=2014061037=80531939939289=8290=8
10:27:52.001: 657803 - 79 - 1128=935=X34=65780352=20140610-13:27:52.00975=20140610268=1279=1269=022=8207=BVMF48=380566083=11397270=2.37273=75:20:09271=5000272=2014061037016=2014061037017=64:79:1137=80531939943288=27290=50
10:27:52.037: 657804 - 81 - 1128=935=X34=65780452=20140610-13:27:52.04675=20140610268=1279=0269=122=8207=BVMF48=380963983=255378270=26.43273=75:20:45271=100272=2014061037016=2014061037017=75:20:4537=80531939944289=8290=8
10:27:52.046: 657805 - 83 - 1128=935=X34=65780552=20140610-13:27:52.05575=20140610268=1279=0269=022=8207=BVMF48=380391383=106108270=12.9273=75:20:54271=600272=2014061037016=2014061037017=75:20:5437=80531939945288=39290=164
10:27:53.323: 657806 - 537 - 1128=935=X34=65780652=20140610-13:27:53.33175=20140610268=14279=0269=222=8207=BVMF48=380965483=79376270=8.23273=75:33:30271=12800272=2014061037016=2014061037017=75:33:291500=E451=-0.051020=207400274=3277=L1003=2780288=227289=85279=0269=922=8207=BVMF48=380965483=79377270=8.253273=75:33:30272=201406101500=E279=0269=222=8207=BVMF48=380965483=79378270=8.23273=75:33:30271=500272=2014061037016=2014061037017=75:33:291500=E451=-0.051020=207900274=3277=L1003=2790288=8289=85279=0269=922=8207=BVMF48=380965483=79379270=8.253273=75:33:30272=201406101500=E279=0269=222=8207=BVMF48=380965483=79380270=8.23273=75:33:30271=100272=2014061037016=2014061037017=75:33:291500=E451=-0.051020=208000274=3277=L1003=2800288=40289=85279=0269=922=8207=BVMF48=380965483=79381270=8.253273=75:33:30272=201406101500=E279=0269=222=8207=BVMF48=380965483=79382270=8.23273=75:33:30271=1900272=2014061037016=2014061037017=75:33:291500=E451=-0.051020=209900274=3277=L1003=2810288=9289=85279=0269=922=8207=BVMF48=380965483=79383270=8.253273=75:33:30272=201406101500=E279=0269=222=8207=BVMF48=380965483=79384270=8.23273=75:33:30271=5300272=2014061037016=2014061037017=75:33:291500=E451=-0.051020=215200274=3277=L1003=2820288=8289=85279=0269=922=8207=BVMF48=380965483=79385270=8.252273=75:33:30272=201406101500=E279=0269=222=8207=BVMF48=380965483=79386270=8.23273=75:33:30271=1000272=2014061037016=2014061037017=75:33:291500=E451=-0.051020=216200274=3277=L1003=2830288=114289=85279=0269=922=8207=BVMF48=380965483=79387270=8.252273=75:33:30272=201406101500=E279=4269=022=8207=BVMF48=380965483=79388273=75:33:30272=20140610290=6279=0269=122=8207=BVMF48=380965483=79389270=8.23273=75:33:30271=28400272=2014061037016=2014061037017=75:33:2937=80531939947289=85290=1
10:27:53.324: 657807 - 70 - 1128=935=X34=65780752=20140610-13:27:53.33275=20140610268=1279=2269=022=8207=BVMF48=380965483=79390273=75:33:32272=2014061037=80531932294288=8290=28
10:27:53.324: 657808 - 81 - 1128=935=X34=65780852=20140610-13:27:53.33275=20140610268=1279=0269=122=8207=BVMF48=380965483=79391270=8.38273=75:33:32271=500272=2014061037016=2014061037017=75:33:3237=80531939948289=8290=77
10:27:53.324: 657809 - 81 - 1128=935=X34=65780952=20140610-13:27:53.33375=20140610268=1279=0269=122=8207=BVMF48=380965483=79392270=8.24273=75:33:32271=100272=2014061037016=2014061037017=75:33:3237=80531939949289=8290=6
10:27:53.324: 657810 - 156 - 1128=935=X34=65781052=20140610-13:27:53.33375=20140610268=3279=0269=222=8207=BVMF48=380965483=79393270=8.22273=75:33:33271=700272=2014061037016=2014061037017=75:33:321500=E451=-0.061020=216900274=21003=2840288=564289=8279=0269=922=8207=BVMF48=380965483=79394270=8.252273=75:33:33272=201406101500=E279=1269=022=8207=BVMF48=380965483=79395270=8.22273=75:33:33271=300272=2014061037016=2014061037017=71:80:9537=80531938877288=564290=1
10:27:53.324: 657811 - 81 - 1128=935=X34=65781152=20140610-13:27:53.33375=20140610268=1279=0269=122=8207=BVMF48=380965483=79396270=8.23273=75:33:33271=200272=2014061037016=2014061037017=75:33:3337=80531939951289=8290=2
10:27:53.325: 657812 - 339 - 1128=935=X34=65781252=20140610-13:27:53.33475=20140610268=9279=0269=222=8207=BVMF48=380965483=79397270=8.22273=75:33:33271=300272=2014061037016=2014061037017=75:33:331500=E451=-0.061020=217200274=3277=L1003=2850288=564289=8279=0269=922=8207=BVMF48=380965483=79398270=8.252273=75:33:33272=201406101500=E279=0269=222=8207=BVMF48=380965483=79399270=8.22273=75:33:33271=500272=2014061037016=2014061037017=75:33:331500=E451=-0.061020=217700274=3277=L1003=2860288=8289=8279=0269=922=8207=BVMF48=380965483=79400270=8.252273=75:33:33272=201406101500=E279=0269=222=8207=BVMF48=380965483=79401270=8.22273=75:33:33271=500272=2014061037016=2014061037017=75:33:331500=E451=-0.061020=218200274=3277=L1003=2870288=72289=8279=0269=922=8207=BVMF48=380965483=79402270=8.252273=75:33:33272=201406101500=E279=0269=222=8207=BVMF48=380965483=79403270=8.22273=75:33:33271=900272=2014061037016=2014061037017=75:33:331500=E451=-0.061020=219100274=3277=L1003=2880288=3289=8279=0269=922=8207=BVMF48=380965483=79404270=8.252273=75:33:33272=201406101500=E279=4269=022=8207=BVMF48=380965483=79405273=75:33:33272=20140610290=4
10:27:53.326: 657813 - 71 - 1128=935=X34=65781352=20140610-13:27:53.33475=20140610268=1279=2269=122=8207=BVMF48=380965483=79406273=75:33:34272=2014061037=80531939949289=8290=7
10:27:53.326: 657814 - 81 - 1128=935=X34=65781452=20140610-13:27:53.33575=20140610268=1279=0269=122=8207=BVMF48=380965483=79407270=8.23273=75:33:34271=500272=2014061037016=2014061037017=75:33:3437=80531939956289=8290=3
10:27:53.326: 657815 - 81 - 1128=935=X34=65781552=20140610-13:27:53.33575=20140610268=1279=0269=122=8207=BVMF48=380965483=79408270=8.24273=75:33:34271=500272=2014061037016=2014061037017=75:33:3437=80531939957289=8290=8
10:27:53.329: 657816 - 81 - 1128=935=X34=65781652=20140610-13:27:53.33875=20140610268=1279=0269=122=8207=BVMF48=380965483=79409270=8.23273=75:33:37271=100272=2014061037016=2014061037017=75:33:3737=80531939979289=8290=4
10:27:53.329: 657817 - 81 - 1128=935=X34=65781752=20140610-13:27:53.33875=20140610268=1279=0269=122=8207=BVMF48=380965483=79410270=8.22273=75:33:37271=700272=2014061037016=2014061037017=75:33:3737=80531939980289=8290=1
10:27:53.329: 657818 - 71 - 1128=935=X34=65781852=20140610-13:27:53.33875=20140610268=1279=2269=122=8207=BVMF48=380965483=79411273=75:33:38272=2014061037=80531939979289=8290=5
10:27:53.333: 657819 - 81 - 1128=935=X34=65781952=20140610-13:27:53.34175=20140610268=1279=0269=122=8207=BVMF48=380965483=79412270=8.22273=75:33:41271=500272=2014061037016=2014061037017=75:33:4037=80531940003289=8290=2
10:27:53.333: 657820 - 81 - 1128=935=X34=65782052=20140610-13:27:53.34275=20140610268=1279=0269=122=8207=BVMF48=380977983=20193270=7.39273=75:33:41271=700272=2014061037016=2014061037017=75:33:4137=80531940008289=3290=3
10:27:53.337: 657821 - 70 - 1128=935=X34=65782152=20140610-13:27:53.34675=20140610268=1279=2269=022=8207=BVMF48=380965483=79413273=75:33:45272=2014061037=80531939459288=3290=2
10:27:53.354: 657822 - 81 - 1128=935=X34=65782252=20140610-13:27:53.36375=20140610268=1279=0269=122=8207=BVMF48=380965483=79414270=8.23273=75:33:62271=900272=2014061037016=2014061037017=75:33:6237=80531940127289=3290=6
10:27:53.357: 657823 - 81 - 1128=935=X34=65782352=20140610-13:27:53.36675=20140610268=1279=0269=122=8207=BVMF48=380965483=79415270=8.22273=75:33:65271=900272=2014061037016=2014061037017=75:33:6537=80531940137289=3290=3
10:27:53.393: 657824 - 71 - 1128=935=X34=65782452=20140610-13:27:53.40275=20140610268=1279=2269=122=8207=BVMF48=380965483=79416273=75:34:01272=2014061037=80531939446289=8290=41
10:27:53.393: 657825 - 71 - 1128=935=X34=65782552=20140610-13:27:53.40275=20140610268=1279=2269=122=8207=BVMF48=380965483=79417273=75:34:01272=2014061037=80531939444289=8290=52
10:27:53.394: 657826 - 70 - 1128=935=X34=65782652=20140610-13:27:53.40275=20140610268=1279=2269=022=8207=BVMF48=380965483=79418273=75:34:01272=2014061037=80531939451288=8290=36
10:27:53.394: 657827 - 70 - 1128=935=X34=65782752=20140610-13:27:53.40275=20140610268=1279=2269=022=8207=BVMF48=380965483=79419273=75:34:02272=2014061037=80531939448288=8290=14
10:27:53.394: 657828 - 70 - 1128=935=X34=65782852=20140610-13:27:53.40375=20140610268=1279=2269=022=8207=BVMF48=380965483=79420273=75:34:03272=2014061037=80531938878288=8290=1
10:27:53.395: 657829 - 82 - 1128=935=X34=65782952=20140610-13:27:53.40375=20140610268=1279=0269=122=8207=BVMF48=380965483=79421270=8.28273=75:34:03271=9000272=2014061037016=2014061037017=75:34:0337=80531940146289=8290=41
10:27:53.395: 657830 - 81 - 1128=935=X34=65783052=20140610-13:27:53.40375=20140610268=1279=0269=122=8207=BVMF48=380965483=79422270=8.26273=75:34:03271=5400272=2014061037016=2014061037017=75:34:0337=80531940147289=8290=23
10:27:53.396: 657831 - 80 - 1128=935=X34=65783152=20140610-13:27:53.40475=20140610268=1279=0269=022=8207=BVMF48=380965483=79423270=8.18273=75:34:04271=500272=2014061037016=2014061037017=75:34:0437=80531940148288=8290=23
10:27:53.396: 657832 - 80 - 1128=935=X34=65783252=20140610-13:27:53.40575=20140610268=1279=0269=022=8207=BVMF48=380965483=79424270=8.17273=75:34:04271=6600272=2014061037016=2014061037017=75:34:0437=80531940149288=8290=35
10:27:53.396: 657833 - 80 - 1128=935=X34=65783352=20140610-13:27:53.40575=20140610268=1279=0269=022=8207=BVMF48=380965483=79425270=8.15273=75:34:04271=4700272=2014061037016=2014061037017=75:34:0437=80531940150288=8290=59
10:27:53.396: 657834 - 81 - 1128=935=X34=65783452=20140610-13:27:53.40575=20140610268=1279=0269=022=8207=BVMF48=380965483=79426270=8.2273=75:34:05271=600272=2014061037016=2014061037017=75:34:0437=80531940151288=3290=6
10:27:53.397: 657835 - 81 - 1128=935=X34=65783552=20140610-13:27:53.40675=20140610268=1279=0269=122=8207=BVMF48=380965483=79427270=8.22273=75:34:05271=300272=2014061037016=2014061037017=75:34:0537=80531940155289=8290=4
10:27:53.453: 657836 - 81 - 1128=935=X34=65783652=20140610-13:27:53.46175=20140610268=1279=0269=122=8207=BVMF48=380965483=79428270=8.22273=75:34:61271=100272=2014061037016=2014061037017=75:34:6037=80531940200289=8290=5
10:27:53.453: 657837 - 71 - 1128=935=X34=65783752=20140610-13:27:53.46175=20140610268=1279=2269=122=8207=BVMF48=380965483=79429273=75:34:61272=2014061037=80531940200289=8290=5
10:27:53.467: 657838 - 72 - 1128=935=X34=65783852=20140610-13:27:53.47675=20140610268=1279=2269=122=8207=BVMF48=380965483=79430273=75:34:75272=2014061037=80531939464289=40290=49
10:27:53.468: 657839 - 72 - 1128=935=X34=65783952=20140610-13:27:53.47775=20140610268=1279=2269=122=8207=BVMF48=380965483=79431273=75:34:76272=2014061037=80531939463289=40290=58
10:27:53.545: 657840 - 71 - 1128=935=X34=65784052=20140610-13:27:53.55375=20140610268=1279=2269=122=8207=BVMF48=380963983=255379273=75:35:53272=2014061037=80531881157289=3290=70
10:27:53.565: 657841 - 71 - 1128=935=X34=65784152=20140610-13:27:53.57475=20140610268=1279=2269=022=8207=BVMF48=380965483=79432273=75:35:73272=2014061037=80531939016288=40290=59
10:27:53.566: 657842 - 71 - 1128=935=X34=65784252=20140610-13:27:53.57575=20140610268=1279=2269=022=8207=BVMF48=380965483=79433273=75:35:75272=2014061037=80531939015288=40290=34
10:27:53.614: 657843 - 82 - 1128=935=X34=65784352=20140610-13:27:53.62275=20140610268=1279=0269=122=8207=BVMF48=380965483=79434270=8.27273=75:36:22271=4900272=2014061037016=2014061037017=75:36:2137=80531940206289=40290=32
10:27:53.615: 657844 - 82 - 1128=935=X34=65784452=20140610-13:27:53.62375=20140610268=1279=0269=122=8207=BVMF48=380965483=79435270=8.29273=75:36:23271=3300272=2014061037016=2014061037017=75:36:2337=80531940207289=40290=50
10:27:53.633: 657845 - 115 - 1128=935=X34=65784552=20140610-13:27:53.64275=20140610268=2279=2269=022=8207=BVMF48=399729383=2266273=75:36:41272=2014061037=80531935371288=3290=1279=0269=022=8207=BVMF48=399729383=2267270=8.15273=75:36:41271=96272=2014061037016=2014061037017=75:36:4137=80531940208288=3290=2
10:27:53.658: 657846 - 411 - 1128=935=X34=65784652=20140610-13:27:53.66775=20140610268=10279=0269=222=8207=BVMF48=380963983=255380270=26.42273=75:36:66271=200272=2014061037016=2014061037017=75:36:651500=E451=-0.191020=1356400274=1277=L1003=18400288=227289=238279=0269=922=8207=BVMF48=380963983=255381270=26.472273=75:36:66272=201406101500=E279=0269=222=8207=BVMF48=380963983=255382270=26.42273=75:36:66271=300272=2014061037016=2014061037017=75:36:651500=E451=-0.191020=1356700274=1277=L1003=18410288=227289=40279=0269=922=8207=BVMF48=380963983=255383270=26.472273=75:36:66272=201406101500=E279=0269=222=8207=BVMF48=380963983=255384270=26.42273=75:36:66271=100272=2014061037016=2014061037017=75:36:651500=E451=-0.191020=1356800274=1277=L1003=18420288=227289=8279=0269=922=8207=BVMF48=380963983=255385270=26.472273=75:36:66272=201406101500=E279=0269=222=8207=BVMF48=380963983=255386270=26.42273=75:36:66271=300272=2014061037016=2014061037017=75:36:651500=E451=-0.191020=1357100274=1277=L1003=18430288=227289=27279=0269=922=8207=BVMF48=380963983=255387270=26.472273=75:36:66272=201406101500=E279=4269=122=8207=BVMF48=380963983=255388273=75:36:66272=20140610290=4279=0269=022=8207=BVMF48=380963983=255389270=26.42273=75:36:66271=4300272=2014061037016=2014061037017=75:36:6537=80531940209288=227290=1
10:27:53.659: 657847 - 72 - 1128=935=X34=65784752=20140610-13:27:53.66875=20140610268=1279=2269=122=8207=BVMF48=380968883=253260273=75:36:68272=2014061037=80531938837289=45290=33
10:27:53.660: 657848 - 118 - 1128=935=X34=65784852=20140610-13:27:53.66975=20140610268=2279=2269=022=8207=BVMF48=380968883=253261273=75:36:69272=2014061037=80531938752288=45290=8279=0269=022=8207=BVMF48=380968883=253262270=29.37273=75:36:69271=2000272=2014061037016=2014061037017=75:36:6837=80531940214288=45290=7
10:27:53.661: 657849 - 80 - 1128=935=X34=65784952=20140610-13:27:53.67075=20140610268=1279=0269=022=8207=BVMF48=380968883=253263270=29.38273=75:36:69271=300272=2014061037016=2014061037017=75:36:6937=80531940218288=8290=5
10:27:53.663: 657850 - 71 - 1128=935=X34=65785052=20140610-13:27:53.67175=20140610268=1279=2269=122=8207=BVMF48=380963983=255390273=75:36:71272=2014061037=80531936300289=8290=2
10:27:53.673: 657851 - 80 - 1128=935=X34=65785152=20140610-13:27:53.68275=20140610268=1279=0269=022=8207=BVMF48=380963983=255391270=26.42273=75:36:81271=100272=2014061037016=2014061037017=75:36:8137=80531940229288=8290=2
10:27:53.684: 657852 - 193 - 1128=935=X34=65785252=20140610-13:27:53.69375=20140610268=4279=0269=222=8207=BVMF48=380968883=253264270=29.39273=75:36:92271=100272=2014061037016=2014061037017=75:36:921500=E451=-0.241020=431300274=01003=6220288=8289=45279=0269=922=8207=BVMF48=380968883=253265270=29.482273=75:36:92272=201406101500=E279=2269=122=8207=BVMF48=380968883=253266273=75:36:92272=2014061037=80531938566289=45290=1279=0269=122=8207=BVMF48=380968883=253267270=29.39273=75:36:92271=5000272=2014061037016=2014061037017=75:36:9237=80531940245289=45290=1
10:27:53.684: 657853 - 81 - 1128=935=X34=65785352=20140610-13:27:53.69375=20140610268=1279=0269=122=8207=BVMF48=380963983=255392270=26.45273=75:36:92271=800272=2014061037016=2014061037017=75:36:9237=80531940248289=3290=21
10:27:53.688: 657854 - 82 - 1128=935=X34=65785452=20140610-13:27:53.69775=20140610268=1279=0269=122=8207=BVMF48=380963983=255393270=26.43273=75:36:97271=200272=2014061037016=2014061037017=75:36:9637=80531940258289=40290=4
10:27:53.690: 657855 - 72 - 1128=935=X34=65785552=20140610-13:27:53.69875=20140610268=1279=2269=022=8207=BVMF48=380968883=253268273=75:36:98272=2014061037=80531938821288=227290=10
10:27:53.690: 657856 - 82 - 1128=935=X34=65785652=20140610-13:27:53.69975=20140610268=1279=0269=122=8207=BVMF48=380963983=255394270=26.43273=75:36:98271=900272=2014061037016=2014061037017=75:36:9837=80531940262289=40290=5
10:27:53.697: 657857 - 118 - 1128=935=X34=65785752=20140610-13:27:53.70675=20140610268=2279=2269=022=8207=BVMF48=380963983=255395273=75:37:05272=2014061037=80531938822288=59290=12279=0269=022=8207=BVMF48=380963983=255396270=26.41273=75:37:05271=800272=2014061037016=2014061037017=75:37:0537=80531940275288=59290=9
10:27:53.699: 657858 - 118 - 1128=935=X34=65785852=20140610-13:27:53.70775=20140610268=2279=2269=022=8207=BVMF48=380963983=255397273=75:37:07272=2014061037=80531939697288=45290=7279=0269=022=8207=BVMF48=380963983=255398270=26.42273=75:37:07271=100272=2014061037016=2014061037017=75:37:0737=80531940277288=45290=3
10:27:53.704: 657859 - 82 - 1128=935=X34=65785952=20140610-13:27:53.71275=20140610268=1279=0269=022=8207=BVMF48=380968883=253269270=29.37273=75:37:12271=800272=2014061037016=2014061037017=75:37:1237=80531940279288=227290=9
10:27:53.710: 657860 - 73 - 1128=935=X34=65786052=20140610-13:27:53.71875=20140610268=1279=2269=122=8207=BVMF48=380963983=255399273=75:37:18272=2014061037=80531939927289=227290=12
10:27:53.710: 657861 - 118 - 1128=935=X34=65786152=20140610-13:27:53.71875=20140610268=2279=2269=022=8207=BVMF48=380968883=253270273=75:37:18272=2014061037=80531939859288=72290=23279=0269=022=8207=BVMF48=380968883=253271270=29.33273=75:37:18271=600272=2014061037016=2014061037017=75:37:1837=80531940282288=72290=23
10:27:53.711: 657862 - 120 - 1128=935=X34=65786252=20140610-13:27:53.72075=20140610268=2279=2269=022=8207=BVMF48=380963983=255400273=75:37:19272=2014061037=80531938852288=72290=172279=0269=022=8207=BVMF48=380963983=255401270=25.89273=75:37:19271=700272=2014061037016=2014061037017=75:37:1937=80531940283288=72290=172
10:27:53.712: 657863 - 81 - 1128=935=X34=65786352=20140610-13:27:53.72075=20140610268=1279=0269=022=8207=BVMF48=380965483=79436270=8.15273=75:37:20271=5700272=2014061037016=2014061037017=75:37:2037=80531940284288=40290=59
10:27:53.714: 657864 - 81 - 1128=935=X34=65786452=20140610-13:27:53.72275=20140610268=1279=0269=022=8207=BVMF48=380965483=79437270=8.13273=75:37:22271=2600272=2014061037016=2014061037017=75:37:2237=80531940285288=40290=68
10:27:53.715: 657865 - 81 - 1128=935=X34=65786552=20140610-13:27:53.72475=20140610268=1279=0269=122=8207=BVMF48=380963983=255402270=26.43273=75:37:24271=100272=2014061037016=2014061037017=75:37:2437=80531940286289=3290=6
10:27:53.719: 657866 - 81 - 1128=935=X34=65786652=20140610-13:27:53.72875=20140610268=1279=0269=122=8207=BVMF48=380963983=255403270=26.43273=75:37:27271=100272=2014061037016=2014061037017=75:37:2737=80531940287289=3290=7
10:27:53.720: 657867 - 80 - 1128=935=X34=65786752=20140610-13:27:53.72875=20140610268=1279=0269=022=8207=BVMF48=380968883=253272270=29.38273=75:37:28271=900272=2014061037016=2014061037017=75:37:2837=80531940289288=3290=6
10:27:53.720: 657868 - 83 - 1128=935=X34=65786852=20140610-13:27:53.72875=20140610268=1279=0269=122=8207=BVMF48=380963983=255404270=26.44273=75:37:28271=1000272=2014061037016=2014061037017=75:37:2837=80531940290289=227290=14
10:27:53.724: 657869 - 116 - 1128=935=X34=65786952=20140610-13:27:53.73375=20140610268=2279=2269=022=8207=BVMF48=400223483=5857273=75:37:32272=2014061037=80531934110288=3290=3279=0269=022=8207=BVMF48=400223483=5858270=26.4273=75:37:32271=85272=2014061037016=2014061037017=75:37:3237=80531940293288=3290=2
10:27:53.726: 657870 - 117 - 1128=935=X34=65787052=20140610-13:27:53.73575=20140610268=2279=2269=122=8207=BVMF48=380963983=255405273=75:37:34272=2014061037=80531940286289=3290=6279=0269=122=8207=BVMF48=380963983=255406270=26.43273=75:37:34271=1000272=2014061037016=2014061037017=75:37:3437=80531940294289=3290=7
10:27:53.730: 657871 - 117 - 1128=935=X34=65787152=20140610-13:27:53.73875=20140610268=2279=2269=122=8207=BVMF48=380963983=255407273=75:37:38272=2014061037=80531940287289=3290=6279=0269=122=8207=BVMF48=380963983=255408270=26.43273=75:37:38271=1000272=2014061037016=2014061037017=75:37:3737=80531940295289=3290=7
10:27:53.747: 657872 - 160 - 1128=935=X34=65787252=20140610-13:27:53.75575=20140610268=3279=0269=222=8207=BVMF48=380963983=255409270=26.42273=75:37:55271=2500272=2014061037016=2014061037017=75:37:541500=E451=-0.191020=1359600274=1277=L1003=18440288=227289=8279=0269=922=8207=BVMF48=380963983=255410270=26.472273=75:37:55272=201406101500=E279=1269=022=8207=BVMF48=380963983=255411270=26.42273=75:37:55271=1800272=2014061037016=2014061037017=75:36:6537=80531940209288=227290=1
10:27:53.759: 657873 - 156 - 1128=935=X34=65787352=20140610-13:27:53.76875=20140610268=3279=0269=222=8207=BVMF48=380968883=253273270=29.39273=75:37:67271=2200272=2014061037016=2014061037017=75:37:671500=E451=-0.241020=433500274=1277=L1003=6230288=8289=45279=0269=922=8207=BVMF48=380968883=253274270=29.481273=75:37:67272=201406101500=E279=1269=122=8207=BVMF48=380968883=253275270=29.39273=75:37:67271=2800272=2014061037016=2014061037017=75:36:9237=80531940245289=45290=1
10:27:53.794: 657874 - 83 - 1128=935=X34=65787452=20140610-13:27:53.80375=20140610268=1279=0269=122=8207=BVMF48=380249383=103402270=9.34273=75:38:02271=400272=2014061037016=2014061037017=75:38:0237=80531940310289=735290=7
10:27:53.812: 657875 - 161 - 1128=935=X34=65787552=20140610-13:27:53.82075=20140610268=3279=0269=222=8207=BVMF48=380963983=255412270=26.42273=75:38:19271=400272=2014061037016=2014061037017=75:38:191500=E451=-0.191020=1360000274=1277=L1003=18450288=227289=40279=0269=922=8207=BVMF48=380963983=255413270=26.472273=75:38:19272=201406101500=E279=1269=022=8207=BVMF48=380963983=255414270=26.42273=75:38:19271=1400272=2014061037016=2014061037017=75:36:6537=80531940209288=227290=1
10:27:53.828: 657876 - 70 - 1128=935=X34=65787652=20140610-13:27:53.83775=20140610268=1279=2269=022=8207=BVMF48=380965483=79438273=75:38:36272=2014061037=80531939431288=8290=5
10:27:53.828: 657877 - 81 - 1128=935=X34=65787752=20140610-13:27:53.83775=20140610268=1279=0269=122=8207=BVMF48=380965483=79439270=8.24273=75:38:36271=1000272=2014061037016=2014061037017=75:38:3637=80531940320289=8290=14
10:27:53.852: 657878 - 81 - 1128=935=X34=65787852=20140610-13:27:53.86175=20140610268=1279=0269=122=8207=BVMF48=380249383=103403270=9.34273=75:38:60271=100272=2014061037016=2014061037017=75:38:6037=80531940323289=8290=8
10:27:53.858: 657879 - 71 - 1128=935=X34=65787952=20140610-13:27:53.86775=20140610268=1279=2269=122=8207=BVMF48=380963983=255415273=75:38:67272=2014061037=80531887769289=3290=58
10:27:53.860: 657880 - 82 - 1128=935=X34=65788052=20140610-13:27:53.86975=20140610268=1279=0269=122=8207=BVMF48=380968883=253276270=29.52273=75:38:68271=2000272=2014061037016=2014061037017=75:38:6837=80531940324289=45290=40
10:27:53.865: 657881 - 72 - 1128=935=X34=65788152=20140610-13:27:53.87375=20140610268=1279=2269=122=8207=BVMF48=380963983=255416273=75:38:73272=2014061037=80531938306289=45290=12
10:27:53.947: 657882 - 81 - 1128=935=X34=65788252=20140610-13:27:53.95575=20140610268=1279=0269=122=8207=BVMF48=380249383=103404270=9.35273=75:39:54271=100272=2014061037016=2014061037017=75:39:5437=80531940329289=8290=13
10:27:53.985: 657883 - 70 - 1128=935=X34=65788352=20140610-13:27:53.99475=20140610268=1279=2269=022=8207=BVMF48=380968883=253277273=75:39:93272=2014061037=80531940218288=8290=5
10:27:54.015: 657884 - 117 - 1128=935=X34=65788452=20140610-13:27:54.02475=20140610268=2279=2269=122=8207=BVMF48=380965483=79440273=75:40:23272=2014061037=80531939951289=8290=6279=0269=122=8207=BVMF48=380965483=79441270=8.22273=75:40:23271=200272=2014061037016=2014061037017=75:40:2337=80531940330289=8290=5
10:27:54.043: 657885 - 71 - 1128=935=X34=65788552=20140610-13:27:54.05275=20140610268=1279=2269=122=8207=BVMF48=380963983=255417273=75:40:51272=2014061037=80531939944289=8290=3
10:27:54.052: 657886 - 80 - 1128=935=X34=65788652=20140610-13:27:54.06175=20140610268=1279=1269=022=8207=BVMF48=380968883=253278270=29.33273=75:40:60271=500272=2014061037016=2014061037017=75:37:1837=80531940335288=72290=23
10:27:54.053: 657887 - 81 - 1128=935=X34=65788752=20140610-13:27:54.06275=20140610268=1279=1269=022=8207=BVMF48=380963983=255418270=25.89273=75:40:61271=600272=2014061037016=2014061037017=75:37:1937=80531940336288=72290=172
10:27:54.066: 657888 - 82 - 1128=935=X34=65788852=20140610-13:27:54.07575=20140610268=1279=0269=122=8207=BVMF48=380963983=255419270=26.53273=75:40:74271=5000272=2014061037016=2014061037017=75:40:7437=80531940338289=45290=62
10:27:54.076: 657889 - 72 - 1128=935=X34=65788952=20140610-13:27:54.08475=20140610268=1279=2269=122=8207=BVMF48=380965483=79442273=75:40:84272=2014061037=80531939913289=16290=12
10:27:54.078: 657890 - 121 - 1128=935=X34=65789052=20140610-13:27:54.08675=20140610268=2279=2269=022=8207=BVMF48=380963983=255420273=75:40:86272=2014061037=80531940336288=72290=172279=0269=022=8207=BVMF48=380963983=255421270=25.9273=75:40:86271=100272=2014061037016=2014061037017=75:40:8637=80531940340288=72290=171
10:27:54.078: 657891 - 118 - 1128=935=X34=65789152=20140610-13:27:54.08775=20140610268=2279=2269=022=8207=BVMF48=380968883=253279273=75:40:87272=2014061037=80531940335288=72290=23279=0269=022=8207=BVMF48=380968883=253280270=29.35273=75:40:87271=100272=2014061037016=2014061037017=75:40:8737=80531940341288=72290=15
10:27:54.079: 657892 - 81 - 1128=935=X34=65789252=20140610-13:27:54.08775=20140610268=1279=0269=122=8207=BVMF48=380963983=255422270=26.43273=75:40:87271=1000272=2014061037016=2014061037017=75:40:8737=80531940342289=8290=7
10:27:54.165: 657893 - 70 - 1128=935=X34=65789352=20140610-13:27:54.17475=20140610268=1279=2269=022=8207=BVMF48=380963983=255423273=75:41:73272=2014061037=80531933106288=8290=43
10:27:54.165: 657894 - 71 - 1128=935=X34=65789452=20140610-13:27:54.17475=20140610268=1279=2269=122=8207=BVMF48=380963983=255424273=75:41:73272=2014061037=80531937832289=8290=11
10:27:54.166: 657895 - 80 - 1128=935=X34=65789552=20140610-13:27:54.17475=20140610268=1279=0269=022=8207=BVMF48=380963983=255425270=26.39273=75:41:73271=300272=2014061037016=2014061037017=75:41:7337=80531940352288=8290=15
10:27:54.166: 657896 - 81 - 1128=935=X34=65789652=20140610-13:27:54.17475=20140610268=1279=0269=122=8207=BVMF48=380963983=255426270=26.48273=75:41:74271=300272=2014061037016=2014061037017=75:41:7337=80531940353289=8290=39
10:27:54.200: 657897 - 82 - 1128=935=X34=65789752=20140610-13:27:54.20875=20140610268=1279=0269=122=8207=BVMF48=380965483=79443270=8.22273=75:42:08271=100272=2014061037016=2014061037017=75:42:0837=80531940355289=16290=6
10:27:54.223: 657898 - 80 - 1128=935=X34=65789852=20140610-13:27:54.23275=20140610268=1279=0269=022=8207=BVMF48=380968883=253281270=29.38273=75:42:31271=300272=2014061037016=2014061037017=75:42:3137=80531940356288=8290=6
10:27:54.354: 657899 - 70 - 1128=935=X34=65789952=20140610-13:27:54.36375=20140610268=1279=2269=022=8207=BVMF48=380965483=79444273=75:43:62272=2014061037=80531939044288=8290=12
10:27:54.354: 657900 - 81 - 1128=935=X34=65790052=20140610-13:27:54.36375=20140610268=1279=0269=122=8207=BVMF48=380965483=79445270=8.25273=75:43:62271=1000272=2014061037016=2014061037017=75:43:6237=80531940364289=8290=20
10:27:54.462: 657901 - 80 - 1128=935=X34=65790152=20140610-13:27:54.47075=20140610268=1279=0269=122=8207=BVMF48=380342683=425270=12.28273=75:44:70271=100272=2014061037016=2014061037017=75:44:7037=80531940467289=3290=1
10:27:54.521: 657902 - 72 - 1128=935=X34=65790252=20140610-13:27:54.53075=20140610268=1279=2269=122=8207=BVMF48=380965483=79446273=75:45:29272=2014061037=80531881975289=77290=36
10:27:54.665: 657903 - 70 - 1128=935=X34=65790352=20140610-13:27:54.67475=20140610268=1279=2269=022=8207=BVMF48=380963983=255427273=75:46:73272=2014061037=80531928673288=8290=54
10:27:54.666: 657904 - 80 - 1128=935=X34=65790452=20140610-13:27:54.67475=20140610268=1279=0269=022=8207=BVMF48=380963983=255428270=26.38273=75:46:73271=300272=2014061037016=2014061037017=75:46:7337=80531940472288=8290=20
10:27:54.666: 657905 - 81 - 1128=935=X34=65790552=20140610-13:27:54.67475=20140610268=1279=0269=122=8207=BVMF48=380963983=255429270=26.47273=75:46:74271=300272=2014061037016=2014061037017=75:46:7337=80531940473289=8290=35
10:27:54.666: 657906 - 71 - 1128=935=X34=65790652=20140610-13:27:54.67475=20140610268=1279=2269=122=8207=BVMF48=380963983=255430273=75:46:74272=2014061037=80531937766289=8290=10
10:27:54.710: 657907 - 324 - 1128=935=X34=65790752=20140610-13:27:54.71975=20140610268=8279=0269=222=8207=BVMF48=380965483=79447270=8.2273=75:47:18271=500272=2014061037016=2014061037017=75:47:171500=E451=-0.081020=219600274=21003=2890288=8289=77279=0269=922=8207=BVMF48=380965483=79448270=8.251273=75:47:18272=201406101500=E279=0269=222=8207=BVMF48=380965483=79449270=8.2273=75:47:18271=1000272=2014061037016=2014061037017=75:47:171500=E451=-0.081020=220600274=3277=L1003=2900288=72289=77279=0269=922=8207=BVMF48=380965483=79450270=8.251273=75:47:18272=201406101500=E279=0269=222=8207=BVMF48=380965483=79451270=8.2273=75:47:18271=200272=2014061037016=2014061037017=75:47:171500=E451=-0.081020=220800274=3277=L1003=2910288=27289=77279=0269=922=8207=BVMF48=380965483=79452270=8.251273=75:47:18272=201406101500=E279=4269=022=8207=BVMF48=380965483=79453273=75:47:18272=20140610290=2279=1269=022=8207=BVMF48=380965483=79454270=8.2273=75:47:18271=800272=2014061037016=2014061037017=71:44:4137=80531938707288=27290=1
10:27:54.712: 657908 - 81 - 1128=935=X34=65790852=20140610-13:27:54.72075=20140610268=1279=0269=122=8207=BVMF48=380965483=79455270=8.22273=75:47:20271=100272=2014061037016=2014061037017=75:47:2037=80531940475289=8290=7
10:27:54.712: 657909 - 81 - 1128=935=X34=65790952=20140610-13:27:54.72075=20140610268=1279=0269=022=8207=BVMF48=380965483=79456270=8.2273=75:47:20271=100272=2014061037016=2014061037017=75:47:2037=80531940476288=8290=4
10:27:54.712: 657910 - 71 - 1128=935=X34=65791052=20140610-13:27:54.72175=20140610268=1279=2269=122=8207=BVMF48=380965483=79457273=75:47:20272=2014061037=80531940475289=8290=7
10:27:54.712: 657911 - 70 - 1128=935=X34=65791152=20140610-13:27:54.72175=20140610268=1279=2269=022=8207=BVMF48=380965483=79458273=75:47:20272=2014061037=80531940476288=8290=4
10:27:54.713: 657912 - 81 - 1128=935=X34=65791252=20140610-13:27:54.72275=20140610268=1279=0269=022=8207=BVMF48=380965483=79459270=8.2273=75:47:21271=100272=2014061037016=2014061037017=75:47:2137=80531940477288=8290=4
10:27:54.713: 657913 - 70 - 1128=935=X34=65791352=20140610-13:27:54.72275=20140610268=1279=2269=022=8207=BVMF48=380965483=79460273=75:47:21272=2014061037=80531940477288=8290=4
10:27:54.716: 657914 - 70 - 1128=935=X34=65791452=20140610-13:27:54.72575=20140610268=1279=2269=022=8207=BVMF48=380965483=79461273=75:47:25272=2014061037=80531939385288=3290=2
10:27:54.779: 657915 - 327 - 1128=935=X34=65791552=20140610-13:27:54.78875=20140610268=8279=0269=222=8207=BVMF48=380963983=255431270=26.42273=75:47:87271=1400272=2014061037016=2014061037017=75:47:871500=E451=-0.191020=1361400274=1277=L1003=18460288=227289=8279=0269=922=8207=BVMF48=380963983=255432270=26.472273=75:47:87272=201406101500=E279=0269=222=8207=BVMF48=380963983=255433270=26.42273=75:47:87271=100272=2014061037016=2014061037017=75:47:871500=E451=-0.191020=1361500274=1277=L1003=18470288=8289=8279=0269=922=8207=BVMF48=380963983=255434270=26.472273=75:47:87272=201406101500=E279=0269=222=8207=BVMF48=380963983=255435270=26.42273=75:47:87271=100272=2014061037016=2014061037017=75:47:871500=E451=-0.191020=1361600274=1277=L1003=18480288=45289=8279=0269=922=8207=BVMF48=380963983=255436270=26.472273=75:47:87272=201406101500=E279=4269=022=8207=BVMF48=380963983=255437273=75:47:87272=20140610290=3279=0269=122=8207=BVMF48=380963983=255438270=26.42273=75:47:87271=900272=2014061037016=2014061037017=75:47:8737=80531940485289=8290=1
10:27:54.780: 657916 - 70 - 1128=935=X34=65791652=20140610-13:27:54.78975=20140610268=1279=2269=022=8207=BVMF48=380963983=255439273=75:47:89272=2014061037=80531938601288=8290=34
10:27:54.780: 657917 - 71 - 1128=935=X34=65791752=20140610-13:27:54.78975=20140610268=1279=2269=022=8207=BVMF48=380968883=253282273=75:47:89272=2014061037=80531940214288=45290=9
10:27:54.786: 657918 - 81 - 1128=935=X34=65791852=20140610-13:27:54.79475=20140610268=1279=0269=122=8207=BVMF48=380963983=255440270=26.45273=75:47:94271=300272=2014061037016=2014061037017=75:47:9437=80531940487289=8290=24
10:27:54.792: 657919 - 156 - 1128=935=X34=65791952=20140610-13:27:54.80075=20140610268=3279=0269=222=8207=BVMF48=380968883=253283270=29.39273=75:48:00271=1300272=2014061037016=2014061037017=75:48:001500=E451=-0.241020=434800274=1277=L1003=6240288=8289=45279=0269=922=8207=BVMF48=380968883=253284270=29.481273=75:48:00272=201406101500=E279=1269=122=8207=BVMF48=380968883=253285270=29.39273=75:48:00271=1500272=2014061037016=2014061037017=75:36:9237=80531940245289=45290=1
10:27:54.793: 657920 - 81 - 1128=935=X34=65792052=20140610-13:27:54.80275=20140610268=1279=0269=022=8207=BVMF48=380963983=255441270=26.41273=75:48:01271=900272=2014061037016=2014061037017=75:48:0137=80531940499288=45290=7
10:27:54.797: 657921 - 71 - 1128=935=X34=65792152=20140610-13:27:54.80675=20140610268=1279=2269=122=8207=BVMF48=380963983=255442273=75:48:06272=2014061037=80531940248289=3290=23
10:27:54.797: 657922 - 71 - 1128=935=X34=65792252=20140610-13:27:54.80675=20140610268=1279=2269=122=8207=BVMF48=380963983=255443273=75:48:06272=2014061037=80531940485289=8290=1
10:27:54.798: 657923 - 116 - 1128=935=X34=65792352=20140610-13:27:54.80775=20140610268=2279=2269=022=8207=BVMF48=380968883=253286273=75:48:06272=2014061037=80531940289288=3290=5279=0269=022=8207=BVMF48=380968883=253287270=29.37273=75:48:06271=900272=2014061037016=2014061037017=75:48:0637=80531940500288=3290=9
10:27:54.798: 657924 - 72 - 1128=935=X34=65792452=20140610-13:27:54.80775=20140610268=1279=2269=022=8207=BVMF48=380968883=253288273=75:48:06272=2014061037=80531940279288=227290=8
10:27:54.799: 657925 - 81 - 1128=935=X34=65792552=20140610-13:27:54.80775=20140610268=1279=0269=122=8207=BVMF48=380963983=255444270=26.43273=75:48:07271=100272=2014061037016=2014061037017=75:48:0737=80531940501289=8290=8
10:27:54.800: 657926 - 156 - 1128=935=X34=65792652=20140610-13:27:54.80975=20140610268=3279=0269=222=8207=BVMF48=380968883=253289270=29.39273=75:48:09271=100272=2014061037016=2014061037017=75:48:081500=E451=-0.241020=434900274=1277=L1003=6250288=8289=45279=0269=922=8207=BVMF48=380968883=253290270=29.481273=75:48:09272=201406101500=E279=1269=122=8207=BVMF48=380968883=253291270=29.39273=75:48:09271=1400272=2014061037016=2014061037017=75:36:9237=80531940245289=45290=1
10:27:54.806: 657927 - 156 - 1128=935=X34=65792752=20140610-13:27:54.81575=20140610268=3279=0269=222=8207=BVMF48=380968883=253292270=29.39273=75:48:14271=100272=2014061037016=2014061037017=75:48:141500=E451=-0.241020=435000274=1277=L1003=6260288=8289=45279=0269=922=8207=BVMF48=380968883=253293270=29.481273=75:48:14272=201406101500=E279=1269=122=8207=BVMF48=380968883=253294270=29.39273=75:48:14271=1300272=2014061037016=2014061037017=75:36:9237=80531940245289=45290=1
10:27:54.809: 657928 - 82 - 1128=935=X34=65792852=20140610-13:27:54.81875=20140610268=1279=0269=022=8207=BVMF48=380968883=253295270=29.36273=75:48:18271=800272=2014061037016=2014061037017=75:48:1737=80531940508288=227290=11
10:27:54.818: 657929 - 81 - 1128=935=X34=65792952=20140610-13:27:54.82775=20140610268=1279=0269=122=8207=BVMF48=380963983=255445270=26.45273=75:48:26271=800272=2014061037016=2014061037017=75:48:2637=80531940512289=3290=24
10:27:54.823: 657930 - 80 - 1128=935=X34=65793052=20140610-13:27:54.83175=20140610268=1279=1269=122=8207=BVMF48=380963983=255446270=26.43273=75:48:31271=900272=2014061037016=2014061037017=75:37:3437=80531940519289=3290=5
10:27:54.826: 657931 - 80 - 1128=935=X34=65793152=20140610-13:27:54.83575=20140610268=1279=1269=122=8207=BVMF48=380963983=255447270=26.43273=75:48:34271=900272=2014061037016=2014061037017=75:37:3737=80531940523289=3290=6
10:27:54.839: 657932 - 82 - 1128=935=X34=65793252=20140610-13:27:54.84875=20140610268=1279=0269=022=8207=BVMF48=380249383=103405270=9.33273=75:48:47271=3000272=2014061037016=2014061037017=75:48:4737=80531940535288=127290=1
10:27:54.841: 657933 - 80 - 1128=935=X34=65793352=20140610-13:27:54.84975=20140610268=1279=0269=022=8207=BVMF48=380249383=103406270=9.33273=75:48:49271=300272=2014061037016=2014061037017=75:48:4937=80531940538288=8290=2
10:27:54.848: 657934 - 70 - 1128=935=X34=65793452=20140610-13:27:54.85775=20140610268=1279=2269=022=8207=BVMF48=380249383=103407273=75:48:57272=2014061037=80531938398288=3290=49
10:27:54.852: 657935 - 71 - 1128=935=X34=65793552=20140610-13:27:54.86175=20140610268=1279=2269=122=8207=BVMF48=380249383=103408273=75:48:61272=2014061037=80531940323289=8290=8
10:27:54.928: 657936 - 115 - 1128=935=X34=65793652=20140610-13:27:54.93775=20140610268=2279=2269=022=8207=BVMF48=400223483=5859273=75:49:36272=2014061037=80531940293288=3290=2279=0269=022=8207=BVMF48=400223483=5860270=26.38273=75:49:36271=85272=2014061037016=2014061037017=75:49:3637=80531940575288=3290=3
10:27:54.982: 657937 - 81 - 1128=935=X34=65793752=20140610-13:27:54.99175=20140610268=1279=0269=022=8207=BVMF48=380968883=253296270=29.36273=75:49:90271=2000272=2014061037016=2014061037017=75:49:9037=80531940576288=45290=12
10:27:54.987: 657938 - 119 - 1128=935=X34=65793852=20140610-13:27:54.99575=20140610268=2279=2269=122=8207=BVMF48=380963983=255448273=75:49:94272=2014061037=80531940338289=45290=65279=0269=122=8207=BVMF48=380963983=255449270=26.44273=75:49:94271=5000272=2014061037016=2014061037017=75:49:9437=80531940578289=45290=13
10:27:55.002: 657939 - 72 - 1128=935=X34=65793952=20140610-13:27:55.01075=20140610268=1279=2269=122=8207=BVMF48=380963983=255450273=75:50:10272=2014061037=80531940578289=45290=13
10:27:55.127: 657940 - 118 - 1128=935=X34=65794052=20140610-13:27:55.13675=20140610268=2279=2269=022=8207=BVMF48=380249383=103409273=75:51:36272=2014061037=80531939702288=40290=10279=0269=022=8207=BVMF48=380249383=103410270=9.33273=75:51:36271=100272=2014061037016=2014061037017=75:51:3637=80531940591288=40290=3
10:27:55.176: 657941 - 118 - 1128=935=X34=65794152=20140610-13:27:55.18575=20140610268=2279=2269=022=8207=BVMF48=380968883=253297273=75:51:84272=2014061037=80531940341288=72290=16279=0269=022=8207=BVMF48=380968883=253298270=29.32273=75:51:84271=1000272=2014061037016=2014061037017=75:51:8437=80531940592288=72290=27
10:27:55.177: 657942 - 120 - 1128=935=X34=65794252=20140610-13:27:55.18675=20140610268=2279=2269=022=8207=BVMF48=380963983=255451273=75:51:85272=2014061037=80531940340288=72290=168279=0269=022=8207=BVMF48=380963983=255452270=25.87273=75:51:85271=1000272=2014061037016=2014061037017=75:51:8537=80531940593288=72290=169
10:27:55.185: 657943 - 118 - 1128=935=X34=65794352=20140610-13:27:55.19375=20140610268=2279=2269=022=8207=BVMF48=380968883=253299273=75:51:93272=2014061037=80531940592288=72290=27279=0269=022=8207=BVMF48=380968883=253300270=29.33273=75:51:93271=100272=2014061037016=2014061037017=75:51:9337=80531940594288=72290=24
10:27:55.185: 657944 - 120 - 1128=935=X34=65794452=20140610-13:27:55.19475=20140610268=2279=2269=022=8207=BVMF48=380963983=255453273=75:51:94272=2014061037=80531940593288=72290=169279=0269=022=8207=BVMF48=380963983=255454270=25.89273=75:51:94271=100272=2014061037016=2014061037017=75:51:9337=80531940595288=72290=169
10:27:55.192: 657945 - 81 - 1128=935=X34=65794552=20140610-13:27:55.20175=20140610268=1279=0269=122=8207=BVMF48=380963983=255455270=26.42273=75:52:00271=1400272=2014061037016=2014061037017=75:52:0037=80531940596289=8290=1
10:27:55.196: 657946 - 71 - 1128=935=X34=65794652=20140610-13:27:55.20575=20140610268=1279=2269=022=8207=BVMF48=380963983=255456273=75:52:05272=2014061037=80531938747288=45290=1
10:27:55.196: 657947 - 72 - 1128=935=X34=65794752=20140610-13:27:55.20575=20140610268=1279=2269=122=8207=BVMF48=380963983=255457273=75:52:05272=2014061037=80531925283289=45290=21
10:27:55.201: 657948 - 71 - 1128=935=X34=65794852=20140610-13:27:55.21075=20140610268=1279=2269=122=8207=BVMF48=380963983=255458273=75:52:09272=2014061037=80531940512289=3290=24
10:27:55.223: 657949 - 119 - 1128=935=X34=65794952=20140610-13:27:55.23275=20140610268=2279=2269=122=8207=BVMF48=380963983=255459273=75:52:31272=2014061037=80531940262289=40290=5279=0269=122=8207=BVMF48=380963983=255460270=26.42273=75:52:31271=900272=2014061037016=2014061037017=75:52:3137=80531940621289=40290=2
10:27:55.225: 657950 - 119 - 1128=935=X34=65795052=20140610-13:27:55.23475=20140610268=2279=2269=122=8207=BVMF48=380968883=253301273=75:52:33272=2014061037=80531940324289=45290=40279=0269=122=8207=BVMF48=380968883=253302270=29.49273=75:52:33271=2000272=2014061037016=2014061037017=75:52:3337=80531940623289=45290=33
10:27:55.285: 657951 - 70 - 1128=935=X34=65795152=20140610-13:27:55.29475=20140610268=1279=2269=022=8207=BVMF48=380963983=255461273=75:52:94272=2014061037=80531940352288=8290=12
10:27:55.286: 657952 - 71 - 1128=935=X34=65795252=20140610-13:27:55.29575=20140610268=1279=2269=122=8207=BVMF48=380963983=255462273=75:52:94272=2014061037=80531940353289=8290=40
10:27:55.286: 657953 - 81 - 1128=935=X34=65795352=20140610-13:27:55.29575=20140610268=1279=0269=122=8207=BVMF48=380963983=255463270=26.44273=75:52:94271=300272=2014061037016=2014061037017=75:52:9437=80531940636289=8290=14
10:27:55.288: 657954 - 71 - 1128=935=X34=65795452=20140610-13:27:55.29675=20140610268=1279=2269=122=8207=BVMF48=380963983=255464273=75:52:96272=2014061037=80531888816289=3290=47
10:27:55.398: 657955 - 81 - 1128=935=X34=65795552=20140610-13:27:55.40775=20140610268=1279=0269=022=8207=BVMF48=380963983=255465270=26.41273=75:54:06271=5000272=2014061037016=2014061037017=75:54:0637=80531940640288=45290=7
10:27:55.398: 657956 - 82 - 1128=935=X34=65795652=20140610-13:27:55.40775=20140610268=1279=0269=122=8207=BVMF48=380963983=255466270=26.44273=75:54:06271=5000272=2014061037016=2014061037017=75:54:0637=80531940641289=45290=15
10:27:55.398: 657957 - 82 - 1128=935=X34=65795752=20140610-13:27:55.40775=20140610268=1279=0269=122=8207=BVMF48=380963983=255467270=26.45273=75:54:07271=5000272=2014061037016=2014061037017=75:54:0637=80531940642289=45290=26
10:27:55.399: 657958 - 80 - 1128=935=X34=65795852=20140610-13:27:55.40875=20140610268=1279=0269=022=8207=BVMF48=380963983=255468270=26.37273=75:54:07271=100272=2014061037016=2014061037017=75:54:0737=80531940643288=8290=25
10:27:55.414: 657959 - 72 - 1128=935=X34=65795952=20140610-13:27:55.42375=20140610268=1279=2269=122=8207=BVMF48=380963983=255469273=75:54:22272=2014061037=80531940621289=40290=2
10:27:55.786: 657960 - 70 - 1128=935=X34=65796052=20140610-13:27:55.79475=20140610268=1279=2269=022=8207=BVMF48=380963983=255470273=75:57:94272=2014061037=80531940472288=8290=17
10:27:55.786: 657961 - 81 - 1128=935=X34=65796152=20140610-13:27:55.79575=20140610268=1279=0269=122=8207=BVMF48=380963983=255471270=26.44273=75:57:94271=300272=2014061037016=2014061037017=75:57:9437=80531940726289=8290=15
10:27:56.147: 657962 - 70 - 1128=935=X34=65796252=20140610-13:27:56.15675=20140610268=1279=2269=122=8207=BVMF48=380653683=6221273=75:61:55272=2014061037=80531938488289=8290=11
10:27:56.148: 657963 - 80 - 1128=935=X34=65796352=20140610-13:27:56.15775=20140610268=1279=0269=122=8207=BVMF48=380653683=6222270=3.15273=75:61:57271=100272=2014061037016=2014061037017=75:61:5737=80531940733289=8290=11
10:27:56.363: 657964 - 82 - 1128=935=X34=65796452=20140610-13:27:56.37175=20140610268=1279=0269=122=8207=BVMF48=380394783=65713270=17.04273=75:63:71271=100272=2014061037016=2014061037017=75:63:7137=80531940737289=70290=2
10:27:56.625: 657965 - 83 - 1128=935=X34=65796552=20140610-13:27:56.63475=20140610268=1279=0269=022=8207=BVMF48=380965483=79462270=8.12273=75:66:33271=10000272=2014061037016=2014061037017=75:66:3337=80531940739288=110290=68
10:27:56.797: 657966 - 80 - 1128=935=X34=65796652=20140610-13:27:56.80675=20140610268=1279=0269=022=8207=BVMF48=380963983=255472270=26.21273=75:68:06271=300272=2014061037016=2014061037017=75:68:0537=80531940744288=3290=89
10:27:57.316: 657967 - 82 - 1128=935=X34=65796752=20140610-13:27:57.32475=20140610268=1279=0269=122=8207=BVMF48=380965483=79463270=8.23273=75:73:24271=7500272=2014061037016=2014061037017=75:73:2437=80531940757289=70290=10
10:27:57.637: 657968 - 82 - 1128=935=X34=65796852=20140610-13:27:57.64575=20140610268=1279=0269=122=8207=BVMF48=380963983=255473270=26.42273=75:76:44271=100272=2014061037016=2014061037017=75:76:4437=80531940762289=40290=2
10:27:57.652: 657969 - 82 - 1128=935=X34=65796952=20140610-13:27:57.66075=20140610268=1279=0269=122=8207=BVMF48=380963983=255474270=26.42273=75:76:60271=300272=2014061037016=2014061037017=75:76:6037=80531940764289=27290=3
10:27:58.146: 657970 - 83 - 1128=935=X34=65797052=20140610-13:27:58.15475=20140610268=1279=0269=122=8207=BVMF48=380963983=255475270=26.42273=75:81:54271=200272=2014061037016=2014061037017=75:81:5337=80531940771289=238290=4
10:27:58.234: 657971 - 80 - 1128=935=X34=65797152=20140610-13:27:58.24375=20140610268=1279=0269=022=8207=BVMF48=380249383=103411270=9.32273=75:82:42271=2900272=2014061037016=2014061037017=75:82:4237=80531940777288=3290=12
10:27:58.380: 657972 - 71 - 1128=935=X34=65797252=20140610-13:27:58.38975=20140610268=1279=2269=122=8207=BVMF48=380963983=255476273=75:83:88272=2014061037=80531893958289=3290=46
10:27:58.520: 657973 - 82 - 1128=935=X34=65797352=20140610-13:27:58.52975=20140610268=1279=0269=122=8207=BVMF48=380965483=79464270=8.22273=75:85:28271=600272=2014061037016=2014061037017=75:85:2837=80531940784289=77290=7
10:27:58.521: 657974 - 81 - 1128=935=X34=65797452=20140610-13:27:58.53075=20140610268=1279=0269=022=8207=BVMF48=380965483=79465270=8.2273=75:85:30271=100272=2014061037016=2014061037017=75:85:2937=80531940785288=8290=3
10:27:58.521: 657975 - 81 - 1128=935=X34=65797552=20140610-13:27:58.53075=20140610268=1279=0269=122=8207=BVMF48=380965483=79466270=8.22273=75:85:30271=100272=2014061037016=2014061037017=75:85:2937=80531940786289=8290=8
10:27:58.546: 657976 - 80 - 1128=935=X34=65797652=20140610-13:27:58.55575=20140610268=1279=0269=022=8207=BVMF48=380965483=79467270=8.19273=75:85:54271=100272=2014061037016=2014061037017=75:85:5437=80531940788288=8290=10
10:27:58.879: 657977 - 71 - 1128=935=X34=65797752=20140610-13:27:58.88875=20140610268=1279=2269=122=8207=BVMF48=380963983=255477273=75:88:88272=2014061037=80531896571289=3290=36
10:27:59.127: 657978 - 72 - 1128=935=X34=65797852=20140610-13:27:59.13575=20140610268=1279=2269=022=8207=BVMF48=380391383=106109273=75:91:34272=2014061037=80531846250288=308290=56
10:27:59.148: 657979 - 70 - 1128=935=X34=65797952=20140610-13:27:59.15675=20140610268=1279=2269=022=8207=BVMF48=380965483=79468273=75:91:55272=2014061037=80531940788288=8290=10
10:27:59.148: 657980 - 70 - 1128=935=X34=65798052=20140610-13:27:59.15675=20140610268=1279=2269=022=8207=BVMF48=380963983=255478273=75:91:55272=2014061037=80531940643288=8290=24
10:27:59.652: 657981 - 71 - 1128=935=X34=65798152=20140610-13:27:59.66175=20140610268=1279=2269=122=8207=BVMF48=380977983=20194273=75:96:60272=2014061037=80531924589289=8290=9
10:28:00.146: 657982 - 81 - 1128=935=X34=65798252=20140610-13:28:00.15575=20140610268=1279=0269=022=8207=BVMF48=380968883=253303270=29.38273=80:01:55271=300272=2014061037016=2014061037017=80:01:5537=80531940801288=70290=6
10:28:00.152: 657983 - 71 - 1128=935=X34=65798352=20140610-13:28:00.16175=20140610268=1279=2269=122=8207=BVMF48=380968883=253304273=80:01:60272=2014061037=80531938533289=3290=5
10:28:00.152: 657984 - 70 - 1128=935=X34=65798452=20140610-13:28:00.16175=20140610268=1279=2269=022=8207=BVMF48=380968883=253305273=80:01:61272=2014061037=80531940356288=8290=5
10:28:00.391: 657985 - 82 - 1128=935=X34=65798552=20140610-13:28:00.40075=20140610268=1279=0269=022=8207=BVMF48=380963983=255479270=26.1273=80:04:00271=600272=2014061037016=2014061037017=80:04:0037=80531940804288=90290=110
10:28:00.393: 657986 - 80 - 1128=935=X34=65798652=20140610-13:28:00.40275=20140610268=1279=0269=022=8207=BVMF48=380963983=255480270=26.37273=80:04:01271=100272=2014061037016=2014061037017=80:04:0137=80531940805288=8290=24
10:28:00.453: 657987 - 81 - 1128=935=X34=65798752=20140610-13:28:00.46275=20140610268=1279=0269=022=8207=BVMF48=380391383=106110270=13.84273=80:04:61271=300272=2014061037016=2014061037017=80:04:6137=80531940806288=40290=1
10:28:00.461: 657988 - 81 - 1128=935=X34=65798852=20140610-13:28:00.47075=20140610268=1279=0269=022=8207=BVMF48=380963983=255481270=26.41273=80:04:69271=500272=2014061037016=2014061037017=80:04:6937=80531940815288=40290=8
10:28:00.461: 657989 - 81 - 1128=935=X34=65798952=20140610-13:28:00.47075=20140610268=1279=0269=022=8207=BVMF48=380968883=253306270=29.38273=80:04:70271=400272=2014061037016=2014061037017=80:04:7037=80531940818288=40290=6
10:28:00.467: 657990 - 81 - 1128=935=X34=65799052=20140610-13:28:00.47675=20140610268=1279=0269=022=8207=BVMF48=380394783=65714270=17.03273=80:04:75271=100272=2014061037016=2014061037017=80:04:7537=80531940820288=40290=1
10:28:00.473: 657991 - 81 - 1128=935=X34=65799152=20140610-13:28:00.48275=20140610268=1279=0269=022=8207=BVMF48=380249383=103412270=9.33273=80:04:81271=200272=2014061037016=2014061037017=80:04:8137=80531940821288=40290=4
10:28:00.473: 657992 - 81 - 1128=935=X34=65799252=20140610-13:28:00.48275=20140610268=1279=0269=022=8207=BVMF48=380965483=79469270=8.21273=80:04:81271=100272=2014061037016=2014061037017=80:04:8137=80531940822288=40290=1
10:28:00.474: 657993 - 70 - 1128=935=X34=65799352=20140610-13:28:00.48375=20140610268=1279=2269=022=8207=BVMF48=380965483=79470273=80:04:83272=2014061037=80531940785288=8290=4
10:28:00.474: 657994 - 71 - 1128=935=X34=65799452=20140610-13:28:00.48375=20140610268=1279=2269=122=8207=BVMF48=380965483=79471273=80:04:83272=2014061037=80531940786289=8290=8
10:28:00.475: 657995 - 144 - 1128=935=X34=65799552=20140610-13:28:00.48475=20140610268=3279=0269=222=8207=BVMF48=380965483=79472270=8.21273=80:04:83271=100272=2014061037016=2014061037017=80:04:831500=E451=-0.071020=220900274=01003=2920288=40289=8279=0269=922=8207=BVMF48=380965483=79473270=8.251273=80:04:83272=201406101500=E279=2269=022=8207=BVMF48=380965483=79474273=80:04:83272=2014061037=80531940822288=40290=1
10:28:00.475: 657996 - 70 - 1128=935=X34=65799652=20140610-13:28:00.48475=20140610268=1279=2269=022=8207=BVMF48=380965483=79475273=80:04:83272=2014061037=80531940151288=3290=2
10:28:00.476: 657997 - 81 - 1128=935=X34=65799752=20140610-13:28:00.48575=20140610268=1279=0269=022=8207=BVMF48=380965483=79476270=8.2273=80:04:85271=100272=2014061037016=2014061037017=80:04:8537=80531940838288=8290=2
10:28:00.476: 657998 - 71 - 1128=935=X34=65799852=20140610-13:28:00.48575=20140610268=1279=2269=122=8207=BVMF48=380965483=79477273=80:04:85272=2014061037=80531939980289=8290=1
10:28:00.477: 657999 - 81 - 1128=935=X34=65799952=20140610-13:28:00.48675=20140610268=1279=0269=022=8207=BVMF48=380965483=79478270=8.2273=80:04:86271=600272=2014061037016=2014061037017=80:04:8537=80531940845288=3290=3
10:28:00.478: 658000 - 70 - 1128=935=X34=65800052=20140610-13:28:00.48675=20140610268=1279=2269=022=8207=BVMF48=380965483=79479273=80:04:86272=2014061037=80531940838288=8290=2
10:28:00.486: 658001 - 120 - 1128=935=X34=65800152=20140610-13:28:00.49575=20140610268=2279=2269=022=8207=BVMF48=380394783=65715273=80:04:94272=2014061037=80531939855288=110290=11279=0269=022=8207=BVMF48=380394783=65716270=16.99273=80:04:94271=200272=2014061037016=2014061037017=80:04:9437=80531940905288=110290=7
10:28:00.507: 658002 - 72 - 1128=935=X34=65800252=20140610-13:28:00.51675=20140610268=1279=2269=022=8207=BVMF48=380394783=65717273=80:05:16272=2014061037=80531940905288=110290=7
10:28:00.533: 658003 - 70 - 1128=935=X34=65800352=20140610-13:28:00.54275=20140610268=1279=2269=022=8207=BVMF48=380391383=106111273=80:05:42272=2014061037=80531939042288=8290=35
10:28:00.571: 658004 - 80 - 1128=935=X34=65800452=20140610-13:28:00.58075=20140610268=1279=0269=022=8207=BVMF48=380391383=106112270=13.78273=80:05:80271=100272=2014061037016=2014061037017=80:05:8037=80531940917288=8290=35
10:28:00.580: 658005 - 158 - 1128=935=X34=65800552=20140610-13:28:00.58975=20140610268=3279=0269=222=8207=BVMF48=380391383=106113270=13.84273=80:05:88271=100272=2014061037016=2014061037017=80:05:881500=E451=-0.051020=107700274=1277=L1003=3290288=40289=227279=0269=922=8207=BVMF48=380391383=106114270=13.878273=80:05:88272=201406101500=E279=1269=022=8207=BVMF48=380391383=106115270=13.84273=80:05:88271=200272=2014061037016=2014061037017=80:04:6137=80531940806288=40290=1
10:28:00.600: 658006 - 80 - 1128=935=X34=65800652=20140610-13:28:00.60975=20140610268=1279=1269=022=8207=BVMF48=380391383=106116270=13.84273=80:06:08271=100272=2014061037016=2014061037017=80:04:6137=80531940920288=40290=1
10:28:00.601: 658007 - 115 - 1128=935=X34=65800752=20140610-13:28:00.60975=20140610268=2279=2269=022=8207=BVMF48=390102283=4007273=80:06:09272=2014061037=80531939043288=3290=2279=0269=022=8207=BVMF48=390102283=4008270=17.02273=80:06:09271=96272=2014061037016=2014061037017=80:06:0937=80531940921288=3290=1
10:28:00.607: 658008 - 116 - 1128=935=X34=65800852=20140610-13:28:00.61675=20140610268=2279=2269=022=8207=BVMF48=399729383=2268273=80:06:15272=2014061037=80531940208288=3290=2279=0269=022=8207=BVMF48=399729383=2269270=8.2273=80:06:15271=96272=2014061037016=2014061037017=80:06:1537=80531940922288=3290=1
10:28:00.664: 658009 - 71 - 1128=935=X34=65800952=20140610-13:28:00.67375=20140610268=1279=2269=022=8207=BVMF48=380968883=253307273=80:06:72272=2014061037=80531940818288=40290=6
10:28:00.666: 658010 - 71 - 1128=935=X34=65801052=20140610-13:28:00.67575=20140610268=1279=2269=022=8207=BVMF48=380249383=103413273=80:06:75272=2014061037=80531940821288=40290=4
10:28:00.666: 658011 - 71 - 1128=935=X34=65801152=20140610-13:28:00.67575=20140610268=1279=2269=022=8207=BVMF48=380394783=65718273=80:06:75272=2014061037=80531940820288=40290=1
10:28:00.667: 658012 - 71 - 1128=935=X34=65801252=20140610-13:28:00.67675=20140610268=1279=2269=022=8207=BVMF48=380963983=255482273=80:06:76272=2014061037=80531940815288=40290=8
10:28:00.720: 658013 - 70 - 1128=935=X34=65801352=20140610-13:28:00.72975=20140610268=1279=2269=022=8207=BVMF48=380391383=106117273=80:07:28272=2014061037=80531940917288=8290=35
10:28:00.728: 658014 - 80 - 1128=935=X34=65801452=20140610-13:28:00.73775=20140610268=1279=0269=022=8207=BVMF48=380391383=106118270=13.78273=80:07:37271=1000272=2014061037016=2014061037017=80:07:3737=80531940923288=8290=35
10:28:00.752: 658015 - 80 - 1128=935=X34=65801552=20140610-13:28:00.76175=20140610268=1279=0269=022=8207=BVMF48=380394783=65719270=17.02273=80:07:60271=100272=2014061037016=2014061037017=80:07:6037=80531940924288=8290=4
10:28:00.800: 658016 - 115 - 1128=935=X34=65801652=20140610-13:28:00.80975=20140610268=2279=2269=022=8207=BVMF48=399729383=2270273=80:08:08272=2014061037=80531940922288=3290=1279=0269=022=8207=BVMF48=399729383=2271270=8.15273=80:08:08271=96272=2014061037016=2014061037017=80:08:0837=80531940925288=3290=2
10:28:00.880: 658017 - 115 - 1128=935=X34=65801752=20140610-13:28:00.88975=20140610268=2279=2269=022=8207=BVMF48=390102283=4009273=80:08:88272=2014061037=80531940921288=3290=1279=0269=022=8207=BVMF48=390102283=4010270=17.01273=80:08:88271=96272=2014061037016=2014061037017=80:08:8837=80531940927288=3290=2
10:28:00.990: 658018 - 70 - 1128=935=X34=65801852=20140610-13:28:00.99975=20140610268=1279=2269=022=8207=BVMF48=380394783=65720273=80:09:99272=2014061037=80531939041288=8290=3
10:28:01.012: 658019 - 80 - 1128=935=X34=65801952=20140610-13:28:01.02175=20140610268=1279=0269=022=8207=BVMF48=380394783=65721270=17.03273=80:10:20271=400272=2014061037016=2014061037017=80:10:2037=80531940931288=8290=1
10:28:01.014: 658020 - 79 - 1128=935=X34=65802052=20140610-13:28:01.02375=20140610268=1279=0269=022=8207=BVMF48=380557983=2417270=2.93273=80:10:22271=100272=2014061037016=2014061037017=80:10:2237=80531940932288=8290=1
10:28:01.030: 658021 - 70 - 1128=935=X34=65802152=20140610-13:28:01.03975=20140610268=1279=2269=022=8207=BVMF48=380391383=106119273=80:10:38272=2014061037=80531940923288=8290=35
10:28:01.043: 658022 - 80 - 1128=935=X34=65802252=20140610-13:28:01.05275=20140610268=1279=0269=022=8207=BVMF48=380391383=106120270=13.78273=80:10:51271=400272=2014061037016=2014061037017=80:10:5137=80531940933288=8290=35
10:28:01.215: 658023 - 115 - 1128=935=X34=65802352=20140610-13:28:01.22475=20140610268=2279=2269=022=8207=BVMF48=390102283=4011273=80:12:24272=2014061037=80531940927288=3290=2279=0269=022=8207=BVMF48=390102283=4012270=17.02273=80:12:24271=96272=2014061037016=2014061037017=80:12:2337=80531940935288=3290=1
10:28:01.268: 658024 - 195 - 1128=935=X34=65802452=20140610-13:28:01.27775=20140610268=4279=0269=222=8207=BVMF48=380963983=255483270=26.42273=80:12:76271=300272=2014061037016=2014061037017=80:12:761500=E451=-0.191020=1361900274=1277=L1003=18490288=3289=8279=0269=922=8207=BVMF48=380963983=255484270=26.472273=80:12:76272=201406101500=E279=1269=122=8207=BVMF48=380963983=255485270=26.42273=80:12:76271=1100272=2014061037016=2014061037017=75:52:0037=80531940596289=8290=1279=2269=022=8207=BVMF48=380963983=255486273=80:12:76272=2014061037=80531939889288=3290=4
10:28:01.278: 658025 - 156 - 1128=935=X34=65802552=20140610-13:28:01.28775=20140610268=3279=0269=222=8207=BVMF48=380968883=253308270=29.39273=80:12:86271=200272=2014061037016=2014061037017=80:12:861500=E451=-0.241020=435200274=1277=L1003=6270288=8289=45279=0269=922=8207=BVMF48=380968883=253309270=29.481273=80:12:86272=201406101500=E279=1269=122=8207=BVMF48=380968883=253310270=29.39273=80:12:86271=1100272=2014061037016=2014061037017=75:36:9237=80531940245289=45290=1
10:28:01.285: 658026 - 71 - 1128=935=X34=65802652=20140610-13:28:01.29475=20140610268=1279=2269=122=8207=BVMF48=380963983=255487273=80:12:93272=2014061037=80531940596289=8290=1
10:28:01.289: 658027 - 80 - 1128=935=X34=65802752=20140610-13:28:01.29875=20140610268=1279=0269=022=8207=BVMF48=380963983=255488270=26.41273=80:12:97271=600272=2014061037016=2014061037017=80:12:9737=80531940941288=3290=7
10:28:01.292: 658028 - 71 - 1128=935=X34=65802852=20140610-13:28:01.30175=20140610268=1279=2269=122=8207=BVMF48=380963983=255489273=80:13:00272=2014061037=80531940519289=3290=7
10:28:01.295: 658029 - 71 - 1128=935=X34=65802952=20140610-13:28:01.30475=20140610268=1279=2269=122=8207=BVMF48=380963983=255490273=80:13:04272=2014061037=80531940523289=3290=7
10:28:01.299: 658030 - 82 - 1128=935=X34=65803052=20140610-13:28:01.30875=20140610268=1279=0269=122=8207=BVMF48=380963983=255491270=26.42273=80:13:08271=900272=2014061037016=2014061037017=80:13:0837=80531940952289=40290=4
10:28:01.307: 658031 - 81 - 1128=935=X34=65803152=20140610-13:28:01.31675=20140610268=1279=0269=122=8207=BVMF48=380963983=255492270=26.42273=80:13:16271=1200272=2014061037016=2014061037017=80:13:1637=80531940955289=8290=5
10:28:01.319: 658032 - 72 - 1128=935=X34=65803252=20140610-13:28:01.32875=20140610268=1279=2269=122=8207=BVMF48=380963983=255493273=80:13:28272=2014061037=80531940952289=40290=4
10:28:01.379: 658033 - 71 - 1128=935=X34=65803352=20140610-13:28:01.38875=20140610268=1279=2269=022=8207=BVMF48=380968883=253311273=80:13:87272=2014061037=80531940594288=72290=24
10:28:01.382: 658034 - 72 - 1128=935=X34=65803452=20140610-13:28:01.39275=20140610268=1279=2269=022=8207=BVMF48=380963983=255494273=80:13:91272=2014061037=80531940595288=72290=170
10:28:01.388: 658035 - 81 - 1128=935=X34=65803552=20140610-13:28:01.39775=20140610268=1279=0269=022=8207=BVMF48=380968883=253312270=29.33273=80:13:96271=100272=2014061037016=2014061037017=80:13:9637=80531940982288=72290=24
10:28:01.541: 658036 - 82 - 1128=935=X34=65803652=20140610-13:28:01.55075=20140610268=1279=0269=022=8207=BVMF48=380963983=255495270=25.89273=80:15:49271=100272=2014061037016=2014061037017=80:15:4937=80531940987288=72290=170
10:28:01.734: 658037 - 195 - 1128=935=X34=65803752=20140610-13:28:01.74475=20140610268=4279=0269=222=8207=BVMF48=380968883=253313270=29.39273=80:17:43271=1100272=2014061037016=2014061037017=80:17:421500=E451=-0.241020=436300274=1277=L1003=6280288=227289=45279=0269=922=8207=BVMF48=380968883=253314270=29.481273=80:17:43272=201406101500=E279=2269=122=8207=BVMF48=380968883=253315273=80:17:43272=2014061037=80531940245289=45290=1279=0269=122=8207=BVMF48=380968883=253316270=29.39273=80:17:43271=5000272=2014061037016=2014061037017=80:17:4237=80531940989289=45290=1
10:28:01.736: 658038 - 156 - 1128=935=X34=65803852=20140610-13:28:01.74575=20140610268=3279=0269=222=8207=BVMF48=380968883=253317270=29.39273=80:17:45271=500272=2014061037016=2014061037017=80:17:441500=E451=-0.241020=436800274=1277=L1003=6290288=8289=45279=0269=922=8207=BVMF48=380968883=253318270=29.48273=80:17:45272=201406101500=E279=1269=122=8207=BVMF48=380968883=253319270=29.39273=80:17:45271=4500272=2014061037016=2014061037017=80:17:4237=80531940989289=45290=1
10:28:01.746: 658039 - 70 - 1128=935=X34=65803952=20140610-13:28:01.75575=20140610268=1279=2269=022=8207=BVMF48=380968883=253320273=80:17:54272=2014061037=80531939923288=8290=20
10:28:01.788: 658040 - 81 - 1128=935=X34=65804052=20140610-13:28:01.79775=20140610268=1279=0269=122=8207=BVMF48=380963983=255496270=26.42273=80:17:97271=1300272=2014061037016=2014061037017=80:17:9737=80531940991289=8290=5
10:28:01.815: 658041 - 82 - 1128=935=X34=65804152=20140610-13:28:01.82375=20140610268=1279=0269=122=8207=BVMF48=380963983=255497270=26.42273=80:18:23271=900272=2014061037016=2014061037017=80:18:2337=80531940995289=40290=6
10:28:03.366: 658042 - 117 - 1128=935=X34=65804252=20140610-13:28:03.37575=20140610268=2279=2269=122=8207=BVMF48=380963983=255498273=80:33:75272=2014061037=80531921551289=3290=13279=0269=122=8207=BVMF48=380963983=255499270=26.42273=80:33:75271=100272=2014061037016=2014061037017=80:33:7437=80531941011289=3290=7
10:28:03.484: 658043 - 307 - 1128=935=X34=65804352=20140610-13:28:03.49375=20140610268=7279=0269=222=8207=BVMF48=380963983=255500270=26.42273=80:34:92271=100272=2014061037016=2014061037017=80:34:921500=E451=-0.191020=1362000274=1277=L1003=18500288=3289=40279=0269=922=8207=BVMF48=380963983=255501270=26.472273=80:34:92272=201406101500=E279=0269=222=8207=BVMF48=380963983=255502270=26.42273=80:34:92271=200272=2014061037016=2014061037017=80:34:921500=E451=-0.191020=1362200274=1277=L1003=18510288=3289=27279=0269=922=8207=BVMF48=380963983=255503270=26.472273=80:34:92272=201406101500=E279=2269=122=8207=BVMF48=380963983=255504273=80:34:92272=2014061037=80531940762289=40290=1279=1269=122=8207=BVMF48=380963983=255505270=26.42273=80:34:92271=100272=2014061037016=2014061037017=75:76:6037=80531940764289=27290=1279=2269=022=8207=BVMF48=380963983=255506273=80:34:92272=2014061037=80531940941288=3290=7
10:28:03.494: 658044 - 80 - 1128=935=X34=65804452=20140610-13:28:03.50375=20140610268=1279=0269=022=8207=BVMF48=380963983=255507270=26.41273=80:35:03271=600272=2014061037016=2014061037017=80:35:0337=80531941051288=3290=7
10:28:03.635: 658045 - 82 - 1128=935=X34=65804552=20140610-13:28:03.64475=20140610268=1279=0269=122=8207=BVMF48=380963983=255508270=26.42273=80:36:44271=200272=2014061037016=2014061037017=80:36:4437=80531941063289=40290=7
10:28:03.897: 658046 - 185 - 1128=935=X34=65804652=20140610-13:28:03.90775=20140610268=4279=0269=222=8207=BVMF48=380963983=255509270=26.42273=80:39:06271=100272=2014061037016=2014061037017=80:39:051500=E451=-0.191020=1362300274=1277=L1003=18520288=70289=27279=0269=922=8207=BVMF48=380963983=255510270=26.472273=80:39:06272=201406101500=E279=2269=022=8207=BVMF48=380963983=255511273=80:39:06272=2014061037=80531939695288=70290=3279=2269=122=8207=BVMF48=380963983=255512273=80:39:06272=2014061037=80531940764289=27290=1
10:28:03.917: 658047 - 80 - 1128=935=X34=65804752=20140610-13:28:03.92675=20140610268=1279=1269=022=8207=BVMF48=380963983=255513270=26.41273=80:39:26271=800272=2014061037016=2014061037017=75:48:0137=80531941111288=45290=4
10:28:04.147: 658048 - 70 - 1128=935=X34=65804852=20140610-13:28:04.15675=20140610268=1279=2269=022=8207=BVMF48=380963983=255514273=80:41:55272=2014061037=80531940805288=8290=23
10:28:04.163: 658049 - 81 - 1128=935=X34=65804952=20140610-13:28:04.17275=20140610268=1279=0269=122=8207=BVMF48=380965483=79480270=8.22273=80:41:72271=1000272=2014061037016=2014061037017=80:41:7137=80531941119289=3290=7
10:28:04.170: 658050 - 116 - 1128=935=X34=65805052=20140610-13:28:04.17975=20140610268=2279=2269=022=8207=BVMF48=380965483=79481273=80:41:79272=2014061037=80531892163288=3290=32279=0269=022=8207=BVMF48=380965483=79482270=8.15273=80:41:79271=1800272=2014061037016=2014061037017=80:41:7937=80531941125288=3290=54
10:28:04.252: 658051 - 81 - 1128=935=X34=65805152=20140610-13:28:04.26175=20140610268=1279=0269=022=8207=BVMF48=380965483=79483270=8.2273=80:42:60271=100272=2014061037016=2014061037017=80:42:6037=80531941150288=8290=3
10:28:04.252: 658052 - 70 - 1128=935=X34=65805252=20140610-13:28:04.26175=20140610268=1279=2269=022=8207=BVMF48=380965483=79484273=80:42:61272=2014061037=80531941150288=8290=3
10:28:04.253: 658053 - 81 - 1128=935=X34=65805352=20140610-13:28:04.26275=20140610268=1279=0269=022=8207=BVMF48=380965483=79485270=8.2273=80:42:62271=100272=2014061037016=2014061037017=80:42:6237=80531941151288=8290=3
10:28:04.253: 658054 - 70 - 1128=935=X34=65805452=20140610-13:28:04.26275=20140610268=1279=2269=022=8207=BVMF48=380965483=79486273=80:42:62272=2014061037=80531941151288=8290=3
10:28:04.255: 658055 - 81 - 1128=935=X34=65805552=20140610-13:28:04.26475=20140610268=1279=0269=022=8207=BVMF48=380965483=79487270=8.2273=80:42:63271=100272=2014061037016=2014061037017=80:42:6337=80531941153288=8290=3
10:28:04.346: 658056 - 80 - 1128=935=X34=65805652=20140610-13:28:04.35575=20140610268=1279=0269=022=8207=BVMF48=380965483=79488270=8.19273=80:43:54271=100272=2014061037016=2014061037017=80:43:5437=80531941163288=8290=10
10:28:04.417: 658057 - 119 - 1128=935=X34=65805752=20140610-13:28:04.42675=20140610268=2279=2269=122=8207=BVMF48=380965483=79489273=80:44:25272=2014061037=80531879753289=77290=37279=0269=122=8207=BVMF48=380965483=79490270=8.22273=80:44:25271=100272=2014061037016=2014061037017=80:44:2537=80531941164289=77290=8
10:28:05.410: 658058 - 307 - 1128=935=X34=65805852=20140610-13:28:05.41975=20140610268=7279=0269=222=8207=BVMF48=380963983=255515270=26.42273=80:54:19271=200272=2014061037016=2014061037017=80:54:181500=E451=-0.191020=1362500274=1277=L1003=18530288=3289=238279=0269=922=8207=BVMF48=380963983=255516270=26.472273=80:54:19272=201406101500=E279=0269=222=8207=BVMF48=380963983=255517270=26.42273=80:54:19271=100272=2014061037016=2014061037017=80:54:181500=E451=-0.191020=1362600274=1277=L1003=18540288=3289=8279=0269=922=8207=BVMF48=380963983=255518270=26.472273=80:54:19272=201406101500=E279=2269=122=8207=BVMF48=380963983=255519273=80:54:19272=2014061037=80531940771289=238290=1279=1269=122=8207=BVMF48=380963983=255520270=26.42273=80:54:19271=1100272=2014061037016=2014061037017=80:13:1637=80531940955289=8290=1279=2269=022=8207=BVMF48=380963983=255521273=80:54:19272=2014061037=80531941051288=3290=6
10:28:05.422: 658059 - 80 - 1128=935=X34=65805952=20140610-13:28:05.43075=20140610268=1279=0269=022=8207=BVMF48=380963983=255522270=26.41273=80:54:30271=600272=2014061037016=2014061037017=80:54:3037=80531941170288=3290=6
10:28:05.424: 658060 - 156 - 1128=935=X34=65806052=20140610-13:28:05.43375=20140610268=3279=0269=222=8207=BVMF48=380968883=253321270=29.39273=80:54:32271=100272=2014061037016=2014061037017=80:54:321500=E451=-0.241020=436900274=1277=L1003=6300288=8289=45279=0269=922=8207=BVMF48=380968883=253322270=29.48273=80:54:32272=201406101500=E279=1269=122=8207=BVMF48=380968883=253323270=29.39273=80:54:32271=4400272=2014061037016=2014061037017=80:17:4237=80531940989289=45290=1
10:28:05.430: 658061 - 71 - 1128=935=X34=65806152=20140610-13:28:05.44075=20140610268=1279=2269=122=8207=BVMF48=380963983=255523273=80:54:39272=2014061037=80531940955289=8290=1
10:28:05.432: 658062 - 71 - 1128=935=X34=65806252=20140610-13:28:05.44175=20140610268=1279=2269=122=8207=BVMF48=380963983=255524273=80:54:40272=2014061037=80531940991289=8290=1
10:28:05.432: 658063 - 80 - 1128=935=X34=65806352=20140610-13:28:05.44175=20140610268=1279=0269=022=8207=BVMF48=380963983=255525270=26.37273=80:54:41271=100272=2014061037016=2014061037017=80:54:4037=80531941174288=8290=23
10:28:05.455: 658064 - 81 - 1128=935=X34=65806452=20140610-13:28:05.46575=20140610268=1279=0269=122=8207=BVMF48=380963983=255526270=26.42273=80:54:64271=2500272=2014061037016=2014061037017=80:54:6437=80531941185289=8290=4
10:28:05.652: 658065 - 82 - 1128=935=X34=65806552=20140610-13:28:05.66275=20140610268=1279=0269=122=8207=BVMF48=380963983=255527270=26.42273=80:56:61271=300272=2014061037016=2014061037017=80:56:6137=80531941190289=27290=5
10:28:05.663: 658066 - 72 - 1128=935=X34=65806652=20140610-13:28:05.67275=20140610268=1279=2269=122=8207=BVMF48=380963983=255528273=80:56:71272=2014061037=80531940641289=45290=15
10:28:05.789: 658067 - 82 - 1128=935=X34=65806752=20140610-13:28:05.79975=20140610268=1279=0269=022=8207=BVMF48=380249383=103414270=9.31273=80:57:98271=1000272=2014061037016=2014061037017=80:57:9837=80531941198288=232290=17
10:28:05.863: 658068 - 82 - 1128=935=X34=65806852=20140610-13:28:05.87275=20140610268=1279=0269=122=8207=BVMF48=380963983=255529270=26.44273=80:58:72271=5000272=2014061037016=2014061037017=80:58:7237=80531941200289=45290=16
10:28:05.875: 658069 - 119 - 1128=935=X34=65806952=20140610-13:28:05.88475=20140610268=2279=2269=122=8207=BVMF48=380394783=65722273=80:58:84272=2014061037=80531939219289=23290=6279=0269=122=8207=BVMF48=380394783=65723270=17.05273=80:58:84271=100272=2014061037016=2014061037017=80:58:8437=80531941205289=23290=5
10:28:06.147: 658070 - 70 - 1128=935=X34=65807052=20140610-13:28:06.15675=20140610268=1279=2269=022=8207=BVMF48=380963983=255530273=80:61:55272=2014061037=80531941174288=8290=23
10:28:06.257: 658071 - 120 - 1128=935=X34=65807152=20140610-13:28:06.26675=20140610268=2279=2269=022=8207=BVMF48=380963983=255531273=80:62:65272=2014061037=80531940987288=72290=168279=0269=022=8207=BVMF48=380963983=255532270=25.89273=80:62:65271=600272=2014061037016=2014061037017=80:62:6537=80531941207288=72290=168
10:28:06.257: 658072 - 118 - 1128=935=X34=65807252=20140610-13:28:06.26775=20140610268=2279=2269=022=8207=BVMF48=380968883=253324273=80:62:66272=2014061037=80531940982288=72290=23279=0269=022=8207=BVMF48=380968883=253325270=29.33273=80:62:66271=600272=2014061037016=2014061037017=80:62:6637=80531941208288=72290=23
10:28:06.346: 658073 - 80 - 1128=935=X34=65807352=20140610-13:28:06.35575=20140610268=1279=0269=022=8207=BVMF48=380968883=253326270=29.34273=80:63:54271=100272=2014061037016=2014061037017=80:63:5437=80531941209288=8290=20
10:28:06.495: 658074 - 83 - 1128=935=X34=65807452=20140610-13:28:06.50575=20140610268=1279=0269=022=8207=BVMF48=380965483=79491270=8.21273=80:65:04271=16000272=2014061037016=2014061037017=80:65:0437=80531941210288=227290=1
10:28:06.497: 658075 - 70 - 1128=935=X34=65807552=20140610-13:28:06.50675=20140610268=1279=2269=022=8207=BVMF48=380965483=79492273=80:65:05272=2014061037=80531941153288=8290=4
10:28:06.497: 658076 - 70 - 1128=935=X34=65807652=20140610-13:28:06.50775=20140610268=1279=2269=022=8207=BVMF48=380965483=79493273=80:65:06272=2014061037=80531940845288=3290=3
10:28:06.520: 658077 - 82 - 1128=935=X34=65807752=20140610-13:28:06.53075=20140610268=1279=0269=022=8207=BVMF48=380965483=79494270=8.21273=80:65:29271=1000272=2014061037016=2014061037017=80:65:2937=80531941317288=114290=2
10:28:06.581: 658078 - 116 - 1128=935=X34=65807852=20140610-13:28:06.59175=20140610268=2279=2269=022=8207=BVMF48=399729383=2272273=80:65:90272=2014061037=80531940925288=3290=2279=0269=022=8207=BVMF48=399729383=2273270=8.2273=80:65:90271=96272=2014061037016=2014061037017=80:65:9037=80531941322288=3290=1
10:28:06.738: 658079 - 72 - 1128=935=X34=65807952=20140610-13:28:06.74875=20140610268=1279=2269=122=8207=BVMF48=380965483=79495273=80:67:47272=2014061037=80531884043289=77290=40
10:28:06.740: 658080 - 72 - 1128=935=X34=65808052=20140610-13:28:06.75075=20140610268=1279=2269=122=8207=BVMF48=380965483=79496273=80:67:49272=2014061037=80531892670289=77290=40
10:28:06.806: 658081 - 72 - 1128=935=X34=65808152=20140610-13:28:06.81575=20140610268=1279=2269=122=8207=BVMF48=380965483=79497273=80:68:15272=2014061037=80531882029289=77290=39
10:28:06.807: 658082 - 72 - 1128=935=X34=65808252=20140610-13:28:06.81675=20140610268=1279=2269=122=8207=BVMF48=380965483=79498273=80:68:15272=2014061037=80531940784289=77290=6
10:28:06.807: 658083 - 72 - 1128=935=X34=65808352=20140610-13:28:06.81775=20140610268=1279=2269=122=8207=BVMF48=380965483=79499273=80:68:16272=2014061037=80531941164289=77290=7
10:28:07.016: 658084 - 157 - 1128=935=X34=65808452=20140610-13:28:07.02575=20140610268=3279=0269=222=8207=BVMF48=380965483=79500270=8.21273=80:70:24271=6200272=2014061037016=2014061037017=80:70:241500=E451=-0.071020=227100274=1277=L1003=2930288=227289=77279=0269=922=8207=BVMF48=380965483=79501270=8.25273=80:70:24272=201406101500=E279=1269=022=8207=BVMF48=380965483=79502270=8.21273=80:70:24271=9800272=2014061037016=2014061037017=80:65:0437=80531941210288=227290=1
10:28:07.207: 658085 - 157 - 1128=935=X34=65808552=20140610-13:28:07.21675=20140610268=3279=0269=222=8207=BVMF48=380965483=79503270=8.21273=80:72:16271=6300272=2014061037016=2014061037017=80:72:151500=E451=-0.071020=233400274=1277=L1003=2940288=227289=77279=0269=922=8207=BVMF48=380965483=79504270=8.249273=80:72:16272=201406101500=E279=1269=022=8207=BVMF48=380965483=79505270=8.21273=80:72:16271=3500272=2014061037016=2014061037017=80:65:0437=80531941210288=227290=1
10:28:07.208: 658086 - 70 - 1128=935=X34=65808652=20140610-13:28:07.21875=20140610268=1279=2269=022=8207=BVMF48=380965483=79506273=80:72:17272=2014061037=80531941163288=8290=10
10:28:07.208: 658087 - 81 - 1128=935=X34=65808752=20140610-13:28:07.21875=20140610268=1279=0269=122=8207=BVMF48=380965483=79507270=8.22273=80:72:17271=400272=2014061037016=2014061037017=80:72:1737=80531941374289=8290=7
10:28:07.231: 658088 - 82 - 1128=935=X34=65808852=20140610-13:28:07.24075=20140610268=1279=0269=022=8207=BVMF48=380249383=103415270=9.32273=80:72:39271=1000272=2014061037016=2014061037017=80:72:3937=80531941376288=114290=13
10:28:07.339: 658089 - 197 - 1128=935=X34=65808952=20140610-13:28:07.34875=20140610268=4279=0269=222=8207=BVMF48=380963983=255533270=26.42273=80:73:48271=300272=2014061037016=2014061037017=80:73:471500=E451=-0.191020=1362900274=1277=L1003=18550288=3289=40279=0269=922=8207=BVMF48=380963983=255534270=26.472273=80:73:48272=201406101500=E279=1269=122=8207=BVMF48=380963983=255535270=26.42273=80:73:48271=600272=2014061037016=2014061037017=80:18:2337=80531940995289=40290=1279=2269=022=8207=BVMF48=380963983=255536273=80:73:48272=2014061037=80531941170288=3290=6
10:28:07.349: 658090 - 80 - 1128=935=X34=65809052=20140610-13:28:07.35975=20140610268=1279=0269=022=8207=BVMF48=380963983=255537270=26.41273=80:73:59271=600272=2014061037016=2014061037017=80:73:5837=80531941383288=3290=6
10:28:07.810: 658091 - 81 - 1128=935=X34=65809152=20140610-13:28:07.81975=20140610268=1279=0269=022=8207=BVMF48=380249383=103416270=9.33273=80:78:18271=100272=2014061037016=2014061037017=80:78:1837=80531941398288=40290=4
10:28:08.146: 658092 - 71 - 1128=935=X34=65809252=20140610-13:28:08.15575=20140610268=1279=2269=122=8207=BVMF48=380249383=103417273=80:81:55272=2014061037=80531940329289=8290=12
10:28:08.146: 658093 - 70 - 1128=935=X34=65809352=20140610-13:28:08.15675=20140610268=1279=2269=022=8207=BVMF48=380968883=253327273=80:81:55272=2014061037=80531941209288=8290=20
10:28:08.622: 658094 - 118 - 1128=935=X34=65809452=20140610-13:28:08.63175=20140610268=2279=2269=022=8207=BVMF48=380249383=103418273=80:86:31272=2014061037=80531939696288=40290=18279=0269=022=8207=BVMF48=380249383=103419270=9.33273=80:86:31271=100272=2014061037016=2014061037017=80:86:3037=80531941400288=40290=5
10:28:09.024: 658095 - 118 - 1128=935=X34=65809552=20140610-13:28:09.03375=20140610268=2279=2269=022=8207=BVMF48=380968883=253328273=80:90:33272=2014061037=80531941208288=72290=23279=0269=022=8207=BVMF48=380968883=253329270=29.35273=80:90:33271=1000272=2014061037016=2014061037017=80:90:3237=80531941401288=72290=16
10:28:09.024: 658096 - 121 - 1128=935=X34=65809652=20140610-13:28:09.03475=20140610268=2279=2269=022=8207=BVMF48=380963983=255538273=80:90:33272=2014061037=80531941207288=72290=168279=0269=022=8207=BVMF48=380963983=255539270=25.9273=80:90:33271=1000272=2014061037016=2014061037017=80:90:3337=80531941402288=72290=167
10:28:09.570: 658097 - 118 - 1128=935=X34=65809752=20140610-13:28:09.57975=20140610268=2279=2269=022=8207=BVMF48=380391383=106121273=80:95:79272=2014061037=80531938570288=40290=17279=0269=022=8207=BVMF48=380391383=106122270=13.84273=80:95:79271=100272=2014061037016=2014061037017=80:95:7937=80531941410288=40290=2
10:28:09.655: 658098 - 80 - 1128=935=X34=65809852=20140610-13:28:09.66575=20140610268=1279=0269=022=8207=BVMF48=380391383=106123270=13.84273=80:96:64271=100272=2014061037016=2014061037017=80:96:6437=80531941411288=8290=3
10:28:09.965: 658099 - 69 - 1128=935=X34=65809952=20140610-13:28:09.97575=20140610268=1279=2269=022=8207=BVMF48=380653683=6223273=80:99:74272=2014061037=80531938636288=8290=4
10:28:09.967: 658100 - 79 - 1128=935=X34=65810052=20140610-13:28:09.97675=20140610268=1279=0269=022=8207=BVMF48=380653683=6224270=3.12273=80:99:75271=100272=2014061037016=2014061037017=80:99:7537=80531941414288=8290=4
10:28:10.146: 658101 - 71 - 1128=935=X34=65810152=20140610-13:28:10.15575=20140610268=1279=2269=122=8207=BVMF48=380394783=65724273=81:01:55272=2014061037=80531939564289=8290=7
10:28:10.438: 658102 - 70 - 1128=935=X34=65810252=20140610-13:28:10.44775=20140610268=1279=2269=022=8207=BVMF48=380963983=255540273=81:04:46272=2014061037=80531941383288=3290=6
10:28:10.776: 658103 - 158 - 1128=935=X34=65810352=20140610-13:28:10.78575=20140610268=3279=0269=222=8207=BVMF48=380963983=255541270=26.41273=81:07:85271=200272=2014061037016=2014061037017=81:07:841500=E451=-0.21020=1363100274=21003=18560288=3289=147279=0269=922=8207=BVMF48=380963983=255542270=26.472273=81:07:85272=201406101500=E279=1269=022=8207=BVMF48=380963983=255543270=26.41273=81:07:85271=800272=2014061037016=2014061037017=72:08:1237=80531939059288=3290=1
10:28:10.777: 658104 - 80 - 1128=935=X34=65810452=20140610-13:28:10.78775=20140610268=1279=0269=022=8207=BVMF48=380963983=255544270=26.37273=81:07:86271=100272=2014061037016=2014061037017=81:07:8637=80531941429288=8290=22
10:28:11.146: 658105 - 70 - 1128=935=X34=65810552=20140610-13:28:11.15675=20140610268=1279=2269=022=8207=BVMF48=380963983=255545273=81:11:55272=2014061037=80531941429288=8290=22
10:28:11.172: 658106 - 119 - 1128=935=X34=65810652=20140610-13:28:11.18175=20140610268=2279=2269=022=8207=BVMF48=380963983=255546273=81:11:81272=2014061037=80531940275288=59290=3279=0269=022=8207=BVMF48=380963983=255547270=26.4273=81:11:81271=800272=2014061037016=2014061037017=81:11:8137=80531941430288=59290=8
10:28:11.181: 658107 - 119 - 1128=935=X34=65810752=20140610-13:28:11.19175=20140610268=2279=2269=022=8207=BVMF48=380963983=255548273=81:11:90272=2014061037=80531941111288=45290=3279=0269=022=8207=BVMF48=380963983=255549270=26.4273=81:11:90271=800272=2014061037016=2014061037017=81:11:9037=80531941431288=45290=8
10:28:11.354: 658108 - 193 - 1128=935=X34=65810852=20140610-13:28:11.36375=20140610268=4279=0269=222=8207=BVMF48=380391383=106124270=13.85273=81:13:62271=100272=2014061037016=2014061037017=81:13:621500=E451=-0.041020=107800274=01003=3300288=8289=8279=0269=922=8207=BVMF48=380391383=106125270=13.878273=81:13:62272=201406101500=E279=1269=122=8207=BVMF48=380391383=106126270=13.85273=81:13:62271=700272=2014061037016=2014061037017=50:95:0937=80531929098289=8290=1279=2269=022=8207=BVMF48=380391383=106127273=81:13:62272=2014061037=80531941411288=8290=3
10:28:11.475: 658109 - 147 - 1128=935=X34=65810952=20140610-13:28:11.48475=20140610268=3279=0269=222=8207=BVMF48=380391383=106128270=13.84273=81:14:83271=100272=2014061037016=2014061037017=81:14:831500=E451=-0.051020=107900274=21003=3310288=40289=227279=0269=922=8207=BVMF48=380391383=106129270=13.878273=81:14:83272=201406101500=E279=2269=022=8207=BVMF48=380391383=106130273=81:14:83272=2014061037=80531940920288=40290=1
10:28:11.506: 658110 - 119 - 1128=935=X34=65811052=20140610-13:28:11.51675=20140610268=2279=2269=122=8207=BVMF48=380394783=65725273=81:15:15272=2014061037=80531935710289=40290=6279=0269=122=8207=BVMF48=380394783=65726270=17.05273=81:15:15271=100272=2014061037016=2014061037017=81:15:1537=80531941438289=40290=6
10:28:11.545: 658111 - 81 - 1128=935=X34=65811152=20140610-13:28:11.55575=20140610268=1279=0269=122=8207=BVMF48=380394783=65727270=17.06273=81:15:54271=100272=2014061037016=2014061037017=81:15:5437=80531941439289=8290=7
10:28:11.649: 658112 - 65 - 1128=935=X34=65811252=20140610-13:28:11.65875=20140610268=1279=0269=B22=8207=BVMF48=380249383=103420270=2423249273=81:16:49271=360272=201406101500=E15=BRL
10:28:11.655: 658113 - 65 - 1128=935=X34=65811352=20140610-13:28:11.66575=20140610268=1279=0269=B22=8207=BVMF48=380391383=106131270=1496021273=81:16:49271=330272=201406101500=E15=BRL
10:28:11.671: 658114 - 65 - 1128=935=X34=65811452=20140610-13:28:11.68075=20140610268=1279=0269=B22=8207=BVMF48=380968883=253330270=12880008273=81:16:49271=630272=201406101500=E15=BRL
10:28:11.702: 658115 - 65 - 1128=935=X34=65811552=20140610-13:28:11.71175=20140610268=1279=0269=B22=8207=BVMF48=380965483=79508270=1925297273=81:16:49271=294272=201406101500=E15=BRL
10:28:11.703: 658116 - 65 - 1128=935=X34=65811652=20140610-13:28:11.71275=20140610268=1279=0269=B22=8207=BVMF48=380963983=255550270=36083886273=81:16:49271=1856272=201406101500=E15=BRL
10:28:11.789: 658117 - 83 - 1128=935=X34=65811752=20140610-13:28:11.79975=20140610268=1279=0269=122=8207=BVMF48=380391383=106132270=13.85273=81:17:99271=100272=2014061037016=2014061037017=81:17:9837=80531941441289=238290=6
10:28:12.146: 658118 - 71 - 1128=935=X34=65811852=20140610-13:28:12.15575=20140610268=1279=2269=122=8207=BVMF48=380394783=65728273=81:21:55272=2014061037=80531941439289=8290=7
10:28:12.208: 658119 - 81 - 1128=935=X34=65811952=20140610-13:28:12.21875=20140610268=1279=0269=022=8207=BVMF48=380391383=106133270=13.84273=81:22:17271=100272=2014061037016=2014061037017=81:22:1737=80531941447288=40290=2
10:28:12.214: 658120 - 81 - 1128=935=X34=65812052=20140610-13:28:12.22475=20140610268=1279=0269=022=8207=BVMF48=380963983=255551270=26.41273=81:22:23271=500272=2014061037016=2014061037017=81:22:2337=80531941448288=40290=4
10:28:12.214: 658121 - 81 - 1128=935=X34=65812152=20140610-13:28:12.22475=20140610268=1279=0269=022=8207=BVMF48=380968883=253331270=29.38273=81:22:23271=400272=2014061037016=2014061037017=81:22:2337=80531941449288=40290=6
10:28:12.220: 658122 - 81 - 1128=935=X34=65812252=20140610-13:28:12.22975=20140610268=1279=0269=022=8207=BVMF48=380394783=65729270=17.03273=81:22:29271=100272=2014061037016=2014061037017=81:22:2937=80531941450288=40290=2
10:28:12.224: 658123 - 81 - 1128=935=X34=65812352=20140610-13:28:12.23475=20140610268=1279=0269=022=8207=BVMF48=380249383=103421270=9.33273=81:22:33271=200272=2014061037016=2014061037017=81:22:3337=80531941451288=40290=6
10:28:12.225: 658124 - 160 - 1128=935=X34=65812452=20140610-13:28:12.23575=20140610268=3279=0269=222=8207=BVMF48=380963983=255552270=26.42273=81:22:34271=100272=2014061037016=2014061037017=81:22:341500=E451=-0.191020=1363200274=01003=18570288=735289=40279=0269=922=8207=BVMF48=380963983=255553270=26.472273=81:22:34272=201406101500=E279=1269=122=8207=BVMF48=380963983=255554270=26.42273=81:22:34271=500272=2014061037016=2014061037017=80:18:2337=80531940995289=40290=1
10:28:12.229: 658125 - 118 - 1128=935=X34=65812552=20140610-13:28:12.23975=20140610268=2279=2269=022=8207=BVMF48=380963983=255555273=81:22:38272=2014061037=80531941431288=45290=9279=0269=022=8207=BVMF48=380963983=255556270=26.41273=81:22:38271=500272=2014061037016=2014061037017=81:22:3837=80531941454288=45290=5
10:28:12.294: 658126 - 71 - 1128=935=X34=65812652=20140610-13:28:12.30375=20140610268=1279=2269=022=8207=BVMF48=380391383=106134273=81:23:03272=2014061037=80531941447288=40290=2
10:28:12.297: 658127 - 71 - 1128=935=X34=65812752=20140610-13:28:12.30675=20140610268=1279=2269=022=8207=BVMF48=380968883=253332273=81:23:06272=2014061037=80531941449288=40290=6
10:28:12.298: 658128 - 71 - 1128=935=X34=65812852=20140610-13:28:12.30775=20140610268=1279=2269=022=8207=BVMF48=380394783=65730273=81:23:07272=2014061037=80531941450288=40290=2
10:28:12.298: 658129 - 71 - 1128=935=X34=65812952=20140610-13:28:12.30875=20140610268=1279=2269=022=8207=BVMF48=380963983=255557273=81:23:08272=2014061037=80531941448288=40290=4
10:28:12.299: 658130 - 71 - 1128=935=X34=65813052=20140610-13:28:12.30975=20140610268=1279=2269=022=8207=BVMF48=380249383=103422273=81:23:08272=2014061037=80531941451288=40290=6
10:28:12.307: 658131 - 70 - 1128=935=X34=65813152=20140610-13:28:12.31675=20140610268=1279=2269=022=8207=BVMF48=380391383=106135273=81:23:16272=2014061037=80531940933288=8290=34
10:28:12.308: 658132 - 119 - 1128=935=X34=65813252=20140610-13:28:12.31875=20140610268=2279=2269=022=8207=BVMF48=380963983=255558273=81:23:18272=2014061037=80531941454288=45290=4279=0269=022=8207=BVMF48=380963983=255559270=26.4273=81:23:18271=800272=2014061037016=2014061037017=81:23:1737=80531941455288=45290=8
10:28:12.326: 658133 - 80 - 1128=935=X34=65813352=20140610-13:28:12.33675=20140610268=1279=0269=022=8207=BVMF48=380391383=106136270=13.78273=81:23:35271=600272=2014061037016=2014061037017=81:23:3537=80531941456288=8290=34
10:28:12.594: 658134 - 70 - 1128=935=X34=65813452=20140610-13:28:12.60475=20140610268=1279=2269=022=8207=BVMF48=380394783=65731273=81:26:03272=2014061037=80531940924288=8290=4
10:28:12.596: 658135 - 81 - 1128=935=X34=65813552=20140610-13:28:12.60575=20140610268=1279=0269=122=8207=BVMF48=380394783=65732270=17.06273=81:26:05271=100272=2014061037016=2014061037017=81:26:0437=80531941458289=8290=7
10:28:13.652: 658136 - 80 - 1128=935=X34=65813652=20140610-13:28:13.66175=20140610268=1279=0269=022=8207=BVMF48=380566083=11398270=2.38273=81:36:61271=3000272=2014061037016=2014061037017=81:36:6037=80531941464288=27290=44
10:28:13.757: 658137 - 73 - 1128=935=X34=65813752=20140610-13:28:13.76775=20140512268=1279=2269=122=8207=BVMF48=380963983=255560273=81:37:66272=2014061037=80506300425289=39290=973
10:28:13.759: 658138 - 80 - 1128=935=X34=65813852=20140610-13:28:13.76875=20140610268=1279=0269=022=8207=BVMF48=380963983=255561270=26.37273=81:37:68271=100272=2014061037016=2014061037017=81:37:6837=80531941465288=8290=22
10:28:15.146: 658139 - 71 - 1128=935=X34=65813952=20140610-13:28:15.15675=20140610268=1279=2269=122=8207=BVMF48=380394783=65733273=81:51:55272=2014061037=80531941458289=8290=7
10:28:15.147: 658140 - 81 - 1128=935=X34=65814052=20140610-13:28:15.15775=20140610268=1279=0269=122=8207=BVMF48=380394783=65734270=17.06273=81:51:56271=100272=2014061037016=2014061037017=81:51:5637=80531941469289=8290=7
10:28:15.148: 658141 - 71 - 1128=935=X34=65814152=20140610-13:28:15.15875=20140610268=1279=2269=122=8207=BVMF48=380977983=20195273=81:51:58272=2014061037=80531938735289=8290=6
10:28:15.150: 658142 - 82 - 1128=935=X34=65814252=20140610-13:28:15.15975=20140610268=1279=0269=122=8207=BVMF48=380977983=20196270=7.4273=81:51:59271=100272=2014061037016=2014061037017=81:51:5937=80531941470289=8290=6
10:28:16.564: 658143 - 83 - 1128=935=X34=65814352=20140610-13:28:16.57375=20140610268=1279=0269=122=8207=BVMF48=380963983=255562270=26.42273=81:65:73271=200272=2014061037016=2014061037017=81:65:7337=80531941472289=238290=6
10:28:17.145: 658144 - 71 - 1128=935=X34=65814452=20140610-13:28:17.15575=20140610268=1279=2269=122=8207=BVMF48=380394783=65735273=81:71:55272=2014061037=80531941469289=8290=7
10:28:17.146: 658145 - 70 - 1128=935=X34=65814552=20140610-13:28:17.15675=20140610268=1279=2269=022=8207=BVMF48=380963983=255563273=81:71:55272=2014061037=80531941465288=8290=22
10:28:17.168: 658146 - 154 - 1128=935=X34=65814652=20140610-13:28:17.17775=20140610268=3279=0269=222=8207=BVMF48=380965483=79509270=8.22273=81:71:76271=100272=2014061037016=2014061037017=81:71:761500=E451=-0.061020=233500274=01003=2950288=735289=8279=0269=922=8207=BVMF48=380965483=79510270=8.249273=81:71:76272=201406101500=E279=1269=122=8207=BVMF48=380965483=79511270=8.22273=81:71:76271=400272=2014061037016=2014061037017=75:33:4037=80531940003289=8290=1
10:28:17.339: 658147 - 71 - 1128=935=X34=65814752=20140610-13:28:17.34975=20140610268=1279=2269=022=8207=BVMF48=380963983=255564273=81:73:48272=2014061037=80531939218288=21290=78
10:28:18.424: 658148 - 72 - 1128=935=X34=65814852=20140610-13:28:18.43475=20140610268=1279=2269=122=8207=BVMF48=380965483=79512273=81:84:33272=2014061037=80531940757289=70290=11
10:28:18.460: 658149 - 81 - 1128=935=X34=65814952=20140610-13:28:18.47075=20140610268=1279=0269=022=8207=BVMF48=380391383=106137270=13.84273=81:84:70271=100272=2014061037016=2014061037017=81:84:6937=80531941488288=40290=2
10:28:18.467: 658150 - 81 - 1128=935=X34=65815052=20140610-13:28:18.47775=20140610268=1279=0269=022=8207=BVMF48=380963983=255565270=26.41273=81:84:76271=500272=2014061037016=2014061037017=81:84:7637=80531941489288=40290=4
10:28:18.467: 658151 - 81 - 1128=935=X34=65815152=20140610-13:28:18.47775=20140610268=1279=0269=022=8207=BVMF48=380968883=253333270=29.38273=81:84:77271=400272=2014061037016=2014061037017=81:84:7737=80531941490288=40290=6
10:28:18.472: 658152 - 81 - 1128=935=X34=65815252=20140610-13:28:18.48275=20140610268=1279=0269=022=8207=BVMF48=380394783=65736270=17.03273=81:84:82271=100272=2014061037016=2014061037017=81:84:8237=80531941491288=40290=2
10:28:18.478: 658153 - 118 - 1128=935=X34=65815352=20140610-13:28:18.48875=20140610268=2279=2269=022=8207=BVMF48=380963983=255566273=81:84:87272=2014061037=80531941455288=45290=9279=0269=022=8207=BVMF48=380963983=255567270=26.41273=81:84:87271=500272=2014061037016=2014061037017=81:84:8737=80531941492288=45290=5
10:28:18.478: 658154 - 81 - 1128=935=X34=65815452=20140610-13:28:18.48875=20140610268=1279=0269=022=8207=BVMF48=380249383=103423270=9.33273=81:84:88271=200272=2014061037016=2014061037017=81:84:8837=80531941493288=40290=6
10:28:18.545: 658155 - 80 - 1128=935=X34=65815552=20140610-13:28:18.55575=20140610268=1279=0269=022=8207=BVMF48=380963983=255568270=26.37273=81:85:54271=100272=2014061037016=2014061037017=81:85:5437=80531941494288=8290=23
10:28:18.546: 658156 - 80 - 1128=935=X34=65815652=20140610-13:28:18.55575=20140610268=1279=0269=022=8207=BVMF48=380968883=253334270=29.34273=81:85:55271=100272=2014061037016=2014061037017=81:85:5437=80531941495288=8290=22
10:28:18.565: 658157 - 71 - 1128=935=X34=65815752=20140610-13:28:18.57575=20140610268=1279=2269=022=8207=BVMF48=380391383=106138273=81:85:75272=2014061037=80531941488288=40290=2
10:28:18.567: 658158 - 71 - 1128=935=X34=65815852=20140610-13:28:18.57775=20140610268=1279=2269=022=8207=BVMF48=380394783=65737273=81:85:77272=2014061037=80531941491288=40290=2
10:28:18.568: 658159 - 71 - 1128=935=X34=65815952=20140610-13:28:18.57775=20140610268=1279=2269=022=8207=BVMF48=380968883=253335273=81:85:77272=2014061037=80531941490288=40290=6
10:28:18.568: 658160 - 71 - 1128=935=X34=65816052=20140610-13:28:18.57875=20140610268=1279=2269=022=8207=BVMF48=380249383=103424273=81:85:77272=2014061037=80531941493288=40290=6
10:28:18.568: 658161 - 71 - 1128=935=X34=65816152=20140610-13:28:18.57875=20140610268=1279=2269=022=8207=BVMF48=380963983=255569273=81:85:77272=2014061037=80531941489288=40290=4
10:28:18.603: 658162 - 119 - 1128=935=X34=65816252=20140610-13:28:18.61375=20140610268=2279=2269=022=8207=BVMF48=380963983=255570273=81:86:12272=2014061037=80531941492288=45290=4279=0269=022=8207=BVMF48=380963983=255571270=26.4273=81:86:12271=800272=2014061037016=2014061037017=81:86:1237=80531941497288=45290=8
10:28:18.628: 658163 - 70 - 1128=935=X34=65816352=20140610-13:28:18.63875=20140610268=1279=2269=022=8207=BVMF48=380391383=106139273=81:86:37272=2014061037=80531941456288=8290=34
10:28:18.641: 658164 - 80 - 1128=935=X34=65816452=20140610-13:28:18.65175=20140610268=1279=0269=022=8207=BVMF48=380391383=106140270=13.78273=81:86:50271=400272=2014061037016=2014061037017=81:86:5037=80531941498288=8290=34
10:28:19.146: 658165 - 70 - 1128=935=X34=65816552=20140610-13:28:19.15675=20140610268=1279=2269=022=8207=BVMF48=380968883=253336273=81:91:55272=2014061037=80531941495288=8290=21
10:28:19.146: 658166 - 70 - 1128=935=X34=65816652=20140610-13:28:19.15675=20140610268=1279=2269=022=8207=BVMF48=380963983=255572273=81:91:55272=2014061037=80531941494288=8290=22
10:28:19.293: 658167 - 80 - 1128=935=X34=65816752=20140610-13:28:19.30375=20140610268=1279=0269=022=8207=BVMF48=400223483=5861270=26.4273=81:93:02271=5272=2014061037016=2014061037017=81:93:0237=80531941500288=27290=2
10:28:19.442: 658168 - 71 - 1128=935=X34=65816852=20140610-13:28:19.45275=20140610268=1279=2269=122=8207=BVMF48=380391383=106141273=81:94:51272=2014061037=80531939049289=8290=14
10:28:19.443: 658169 - 81 - 1128=935=X34=65816952=20140610-13:28:19.45375=20140610268=1279=0269=122=8207=BVMF48=380391383=106142270=13.87273=81:94:53271=100272=2014061037016=2014061037017=81:94:5337=80531941501289=8290=14
10:28:19.893: 658170 - 82 - 1128=935=X34=65817052=20140610-13:28:19.90375=20140610268=1279=0269=122=8207=BVMF48=380963983=255573270=26.59273=81:99:02271=300272=2014061037016=2014061037017=81:99:0237=80531941502289=39290=81
10:28:21.750: 658171 - 158 - 1128=935=X34=65817152=20140610-13:28:21.76075=20140610268=3279=0269=222=8207=BVMF48=380968883=253337270=29.39273=82:17:60271=400272=2014061037016=2014061037017=82:17:591500=E451=-0.241020=437300274=1277=L1003=6310288=227289=45279=0269=922=8207=BVMF48=380968883=253338270=29.48273=82:17:60272=201406101500=E279=1269=122=8207=BVMF48=380968883=253339270=29.39273=82:17:60271=4000272=2014061037016=2014061037017=80:17:4237=80531940989289=45290=1
10:28:21.752: 658172 - 80 - 1128=935=X34=65817252=20140610-13:28:21.76275=20140610268=1279=0269=022=8207=BVMF48=380968883=253340270=29.34273=82:17:61271=100272=2014061037016=2014061037017=82:17:6137=80531941508288=8290=21
10:28:22.750: 658173 - 160 - 1128=935=X34=65817352=20140610-13:28:22.76075=20140610268=3279=0269=222=8207=BVMF48=380963983=255574270=26.42273=82:27:60271=100272=2014061037016=2014061037017=82:27:591500=E451=-0.191020=1363300274=1277=L1003=18580288=735289=40279=0269=922=8207=BVMF48=380963983=255575270=26.472273=82:27:60272=201406101500=E279=1269=122=8207=BVMF48=380963983=255576270=26.42273=82:27:60271=400272=2014061037016=2014061037017=80:18:2337=80531940995289=40290=1
10:28:22.752: 658174 - 80 - 1128=935=X34=65817452=20140610-13:28:22.76275=20140610268=1279=0269=022=8207=BVMF48=380963983=255577270=26.37273=82:27:61271=100272=2014061037016=2014061037017=82:27:6137=80531941516288=8290=22
10:28:22.782: 658175 - 82 - 1128=935=X34=65817552=20140610-13:28:22.79275=20140610268=1279=0269=122=8207=BVMF48=380963983=255578270=26.42273=82:27:92271=600272=2014061037016=2014061037017=82:27:9237=80531941517289=40290=7
10:28:23.146: 658176 - 70 - 1128=935=X34=65817652=20140610-13:28:23.15675=20140610268=1279=2269=022=8207=BVMF48=380963983=255579273=82:31:55272=2014061037=80531941516288=8290=22
10:28:23.584: 658177 - 71 - 1128=935=X34=65817752=20140610-13:28:23.59575=20140610268=1279=2269=122=8207=BVMF48=380965483=79513273=82:35:94272=2014061037=80531941119289=3290=6
10:28:23.692: 658178 - 154 - 1128=935=X34=65817852=20140610-13:28:23.70275=20140610268=3279=0269=222=8207=BVMF48=380965483=79514270=8.22273=82:37:02271=100272=2014061037016=2014061037017=82:37:011500=E451=-0.061020=233600274=1277=L1003=2960288=735289=8279=0269=922=8207=BVMF48=380965483=79515270=8.249273=82:37:02272=201406101500=E279=1269=122=8207=BVMF48=380965483=79516270=8.22273=82:37:02271=300272=2014061037016=2014061037017=75:33:4037=80531940003289=8290=1
10:28:25.559: 658179 - 80 - 1128=935=X34=65817952=20140610-13:28:25.56975=20140610268=1279=0269=022=8207=BVMF48=380963983=255580270=26.41273=82:55:68271=100272=2014061037016=2014061037017=82:55:6837=80531941541288=8290=4
10:28:25.560: 658180 - 80 - 1128=935=X34=65818052=20140610-13:28:25.57075=20140610268=1279=0269=022=8207=BVMF48=380963983=255581270=26.37273=82:55:70271=100272=2014061037016=2014061037017=82:55:7037=80531941542288=8290=23
10:28:25.571: 658181 - 118 - 1128=935=X34=65818152=20140610-13:28:25.58175=20140610268=2279=2269=022=8207=BVMF48=380963983=255582273=82:55:80272=2014061037=80531941497288=45290=9279=0269=022=8207=BVMF48=380963983=255583270=26.41273=82:55:80271=100272=2014061037016=2014061037017=82:55:8037=80531941543288=45290=5
10:28:25.835: 658182 - 72 - 1128=935=X34=65818252=20140610-13:28:25.84675=20140610268=1279=2269=122=8207=BVMF48=380963983=255584273=82:58:45272=2014061037=80531941517289=40290=7
10:28:25.836: 658183 - 81 - 1128=935=X34=65818352=20140610-13:28:25.84675=20140610268=1279=1269=122=8207=BVMF48=380963983=255585270=26.42273=82:58:45271=100272=2014061037016=2014061037017=80:36:4437=80531941544289=40290=3
10:28:25.876: 658184 - 82 - 1128=935=X34=65818452=20140610-13:28:25.88675=20140610268=1279=0269=122=8207=BVMF48=380963983=255586270=26.42273=82:58:85271=600272=2014061037016=2014061037017=82:58:8537=80531941545289=40290=7
10:28:25.933: 658185 - 83 - 1128=935=X34=65818552=20140610-13:28:25.94375=20140610268=1279=0269=022=8207=BVMF48=380963983=255587270=26.4273=82:59:42271=1500272=2014061037016=2014061037017=82:59:4237=80531941546288=114290=10
10:28:26.551: 658186 - 81 - 1128=935=X34=65818652=20140610-13:28:26.56175=20140610268=1279=0269=122=8207=BVMF48=380963983=255588270=26.42273=82:65:61271=100272=2014061037016=2014061037017=82:65:6037=80531941549289=3290=8
10:28:27.216: 658187 - 81 - 1128=935=X34=65818752=20140610-13:28:27.22675=20140610268=1279=0269=022=8207=BVMF48=380963983=255589270=26.41273=82:72:26271=100272=2014061037016=2014061037017=82:72:2537=80531941559288=70290=6
10:28:27.226: 658188 - 197 - 1128=935=X34=65818852=20140610-13:28:27.23675=20140610268=4279=0269=222=8207=BVMF48=380963983=255590270=26.42273=82:72:35271=100272=2014061037016=2014061037017=82:72:351500=E451=-0.191020=1363400274=1277=L1003=18590288=8289=40279=0269=922=8207=BVMF48=380963983=255591270=26.472273=82:72:35272=201406101500=E279=1269=122=8207=BVMF48=380963983=255592270=26.42273=82:72:35271=300272=2014061037016=2014061037017=80:18:2337=80531940995289=40290=1279=2269=022=8207=BVMF48=380963983=255593273=82:72:35272=2014061037=80531941541288=8290=4
10:28:27.290: 658189 - 81 - 1128=935=X34=65818952=20140610-13:28:27.30075=20140610268=1279=0269=122=8207=BVMF48=380968883=253341270=29.39273=82:72:99271=100272=2014061037016=2014061037017=82:72:9937=80531941562289=3290=2
10:28:27.375: 658190 - 83 - 1128=935=X34=65819052=20140610-13:28:27.38575=20140610268=1279=0269=122=8207=BVMF48=380977983=20197270=7.4273=82:73:85271=100272=2014061037016=2014061037017=82:73:8437=80531941563289=72290=7
10:28:27.985: 658191 - 266 - 1128=935=X34=65819152=20140610-13:28:27.99675=20140610268=6279=0269=222=8207=BVMF48=380391383=106143270=13.84273=82:79:95271=100272=2014061037016=2014061037017=82:79:941500=E451=-0.051020=108000274=3277=L1003=3320288=40289=72279=0269=922=8207=BVMF48=380391383=106144270=13.878273=82:79:95272=201406101500=E279=0269=222=8207=BVMF48=380391383=106145270=13.83273=82:79:95271=100272=2014061037016=2014061037017=82:79:941500=E451=-0.061020=108100274=21003=3330288=39289=72279=0269=922=8207=BVMF48=380391383=106146270=13.878273=82:79:95272=201406101500=E279=2269=022=8207=BVMF48=380391383=106147273=82:79:95272=2014061037=80531941410288=40290=1279=1269=022=8207=BVMF48=380391383=106148270=13.83273=82:79:95271=3100272=2014061037016=2014061037017=25:97:0537=80531848615288=39290=1
10:28:28.005: 658192 - 116 - 1128=935=X34=65819252=20140610-13:28:28.01575=20140610268=2279=2269=022=8207=BVMF48=380394783=65738273=82:80:15272=2014061037=80531929161288=3290=2279=0269=022=8207=BVMF48=380394783=65739270=17.01273=82:80:15271=600272=2014061037016=2014061037017=82:80:1537=80531941577288=3290=5
10:28:28.007: 658193 - 81 - 1128=935=X34=65819352=20140610-13:28:28.01775=20140610268=1279=0269=122=8207=BVMF48=380394783=65740270=17.06273=82:80:16271=100272=2014061037016=2014061037017=82:80:1637=80531941578289=8290=7
10:28:28.145: 658194 - 70 - 1128=935=X34=65819452=20140610-13:28:28.15675=20140610268=1279=2269=022=8207=BVMF48=380968883=253342273=82:81:55272=2014061037=80531941508288=8290=21
10:28:28.314: 658195 - 70 - 1128=935=X34=65819552=20140610-13:28:28.32575=20140610268=1279=2269=022=8207=BVMF48=380394783=65741273=82:83:24272=2014061037=80531940931288=8290=1
10:28:28.319: 658196 - 82 - 1128=935=X34=65819652=20140610-13:28:28.33075=20140610268=1279=0269=022=8207=BVMF48=380394783=65742270=16.98273=82:83:29271=400272=2014061037016=2014061037017=82:83:2937=80531941595288=110290=9
10:28:28.340: 658197 - 70 - 1128=935=X34=65819752=20140610-13:28:28.35075=20140610268=1279=2269=022=8207=BVMF48=380391383=106149273=82:83:50272=2014061037=80531941498288=8290=33
10:28:28.346: 658198 - 80 - 1128=935=X34=65819852=20140610-13:28:28.35675=20140610268=1279=0269=022=8207=BVMF48=380394783=65743270=17.02273=82:83:55271=400272=2014061037016=2014061037017=82:83:5537=80531941596288=8290=2
10:28:28.351: 658199 - 80 - 1128=935=X34=65819952=20140610-13:28:28.36175=20140610268=1279=0269=022=8207=BVMF48=380394783=65744270=17.02273=82:83:60271=100272=2014061037016=2014061037017=82:83:6037=80531941597288=8290=3
10:28:28.352: 658200 - 80 - 1128=935=X34=65820052=20140610-13:28:28.36275=20140610268=1279=0269=022=8207=BVMF48=380391383=106150270=13.78273=82:83:62271=200272=2014061037016=2014061037017=82:83:6237=80531941598288=8290=33
10:28:28.388: 658201 - 70 - 1128=935=X34=65820152=20140610-13:28:28.39975=20140610268=1279=2269=022=8207=BVMF48=380391383=106151273=82:83:98272=2014061037=80531941598288=8290=33
10:28:28.398: 658202 - 80 - 1128=935=X34=65820252=20140610-13:28:28.40875=20140610268=1279=0269=022=8207=BVMF48=380391383=106152270=13.78273=82:84:08271=700272=2014061037016=2014061037017=82:84:0837=80531941599288=8290=33
10:28:28.399: 658203 - 71 - 1128=935=X34=65820352=20140610-13:28:28.40975=20140610268=1279=2269=122=8207=BVMF48=380963983=255594273=82:84:08272=2014061037=80531941549289=3290=8
10:28:28.400: 658204 - 71 - 1128=935=X34=65820452=20140610-13:28:28.41075=20140610268=1279=2269=122=8207=BVMF48=380968883=253343273=82:84:10272=2014061037=80531941562289=3290=2
10:28:28.401: 658205 - 80 - 1128=935=X34=65820552=20140610-13:28:28.41175=20140610268=1279=0269=022=8207=BVMF48=380968883=253344270=29.34273=82:84:11271=100272=2014061037016=2014061037017=82:84:1137=80531941600288=8290=21
10:28:28.411: 658206 - 70 - 1128=935=X34=65820652=20140610-13:28:28.42175=20140610268=1279=2269=022=8207=BVMF48=380391383=106153273=82:84:21272=2014061037=80531941599288=8290=33
10:28:28.422: 658207 - 80 - 1128=935=X34=65820752=20140610-13:28:28.43275=20140610268=1279=0269=022=8207=BVMF48=380391383=106154270=13.78273=82:84:31271=800272=2014061037016=2014061037017=82:84:3137=80531941601288=8290=33
10:28:28.448: 658208 - 115 - 1128=935=X34=65820852=20140610-13:28:28.45975=20140610268=2279=2269=022=8207=BVMF48=390102283=4013273=82:84:58272=2014061037=80531940935288=3290=1279=0269=022=8207=BVMF48=390102283=4014270=17.01273=82:84:58271=96272=2014061037016=2014061037017=82:84:5837=80531941602288=3290=2
10:28:28.993: 658209 - 854 - 1128=935=X34=65820952=20140610-13:28:29.00375=20140610268=22279=0269=222=8207=BVMF48=380963983=255595270=26.41273=82:90:02271=800272=2014061037016=2014061037017=82:90:011500=E451=-0.21020=1364200274=21003=18600288=3289=85279=0269=922=8207=BVMF48=380963983=255596270=26.472273=82:90:02272=201406101500=E279=0269=222=8207=BVMF48=380963983=255597270=26.41273=82:90:02271=3000272=2014061037016=2014061037017=82:90:011500=E451=-0.21020=1367200274=3277=L1003=18610288=45289=85279=0269=922=8207=BVMF48=380963983=255598270=26.472273=82:90:02272=201406101500=E279=0269=222=8207=BVMF48=380963983=255599270=26.41273=82:90:02271=5000272=2014061037016=2014061037017=82:90:011500=E451=-0.21020=1372200274=3277=L1003=18620288=45289=85279=0269=922=8207=BVMF48=380963983=255600270=26.472273=82:90:02272=201406101500=E279=0269=222=8207=BVMF48=380963983=255601270=26.41273=82:90:02271=100272=2014061037016=2014061037017=82:90:011500=E451=-0.21020=1372300274=3277=L1003=18630288=45289=85279=0269=922=8207=BVMF48=380963983=255602270=26.472273=82:90:02272=201406101500=E279=0269=222=8207=BVMF48=380963983=255603270=26.41273=82:90:02271=100272=2014061037016=2014061037017=82:90:011500=E451=-0.21020=1372400274=3277=L1003=18640288=70289=85279=0269=922=8207=BVMF48=380963983=255604270=26.472273=82:90:02272=201406101500=E279=0269=222=8207=BVMF48=380963983=255605270=26.4273=82:90:02271=3500272=2014061037016=2014061037017=82:90:011500=E451=-0.211020=1375900274=21003=18650288=45289=85279=0269=922=8207=BVMF48=380963983=255606270=26.471273=82:90:02272=201406101500=E279=0269=222=8207=BVMF48=380963983=255607270=26.4273=82:90:02271=3000272=2014061037016=2014061037017=82:90:011500=E451=-0.211020=1378900274=3277=L1003=18660288=45289=85279=0269=922=8207=BVMF48=380963983=255608270=26.471273=82:90:02272=201406101500=E279=0269=222=8207=BVMF48=380963983=255609270=26.4273=82:90:02271=600272=2014061037016=2014061037017=82:90:011500=E451=-0.211020=1379500274=3277=L1003=18670288=3289=85279=0269=922=8207=BVMF48=380963983=255610270=26.471273=82:90:02272=201406101500=E279=0269=222=8207=BVMF48=380963983=255611270=26.4273=82:90:02271=800272=2014061037016=2014061037017=82:90:011500=E451=-0.211020=1380300274=3277=L1003=18680288=59289=85279=0269=922=8207=BVMF48=380963983=255612270=26.471273=82:90:02272=201406101500=E279=0269=222=8207=BVMF48=380963983=255613270=26.4273=82:90:02271=1500272=2014061037016=2014061037017=82:90:011500=E451=-0.211020=1381800274=3277=L1003=18690288=114289=85279=0269=922=8207=BVMF48=380963983=255614270=26.471273=82:90:02272=201406101500=E279=4269=022=8207=BVMF48=380963983=255615273=82:90:02272=20140610290=10279=0269=122=8207=BVMF48=380963983=255616270=26.4273=82:90:02271=1600272=2014061037016=2014061037017=82:90:0137=80531941606289=85290=1
10:28:28.994: 658210 - 72 - 1128=935=X34=65821052=20140610-13:28:29.00475=20140610268=1279=2269=122=8207=BVMF48=380963983=255617273=82:90:04272=2014061037=80531939759289=45290=64
10:28:28.995: 658211 - 81 - 1128=935=X34=65821152=20140610-13:28:29.00575=20140610268=1279=0269=122=8207=BVMF48=380968883=253345270=29.39273=82:90:04271=300272=2014061037016=2014061037017=82:90:0437=80531941608289=8290=2
10:28:28.995: 658212 - 71 - 1128=935=X34=65821252=20140610-13:28:29.00575=20140610268=1279=2269=022=8207=BVMF48=380963983=255618273=82:90:05272=2014061037=80531933829288=45290=1
10:28:28.995: 658213 - 80 - 1128=935=X34=65821352=20140610-13:28:29.00575=20140610268=1279=0269=022=8207=BVMF48=380968883=253346270=29.28273=82:90:05271=300272=2014061037016=2014061037017=82:90:0537=80531941609288=8290=43
10:28:28.995: 658214 - 81 - 1128=935=X34=65821452=20140610-13:28:29.00575=20140610268=1279=0269=122=8207=BVMF48=380963983=255619270=26.46273=82:90:05271=100272=2014061037016=2014061037017=82:90:0537=80531941611289=8290=37
10:28:28.996: 658215 - 71 - 1128=935=X34=65821552=20140610-13:28:29.00675=20140610268=1279=2269=022=8207=BVMF48=380968883=253347273=82:90:06272=2014061037=80531940576288=45290=12
10:28:28.997: 658216 - 71 - 1128=935=X34=65821652=20140610-13:28:29.00775=20140610268=1279=2269=022=8207=BVMF48=380968883=253348273=82:90:06272=2014061037=80531937303288=45290=14
10:28:28.997: 658217 - 119 - 1128=935=X34=65821752=20140610-13:28:29.00775=20140610268=2279=2269=122=8207=BVMF48=380968883=253349273=82:90:07272=2014061037=80531940623289=45290=33279=0269=122=8207=BVMF48=380968883=253350270=29.48273=82:90:07271=2000272=2014061037016=2014061037017=82:90:0737=80531941618289=45290=31
10:28:28.999: 658218 - 70 - 1128=935=X34=65821852=20140610-13:28:29.00975=20140610268=1279=2269=022=8207=BVMF48=380968883=253351273=82:90:09272=2014061037=80531932984288=8290=7
10:28:29.000: 658219 - 420 - 1128=935=X34=65821952=20140610-13:28:29.01075=20140610268=11279=0269=222=8207=BVMF48=380968883=253352270=29.38273=82:90:09271=100272=2014061037016=2014061037017=82:90:081500=E451=-0.251020=437400274=21003=6320288=40289=8279=0269=922=8207=BVMF48=380968883=253353270=29.48273=82:90:09272=201406101500=E279=0269=222=8207=BVMF48=380968883=253354270=29.38273=82:90:09271=100272=2014061037016=2014061037017=82:90:081500=E451=-0.251020=437500274=3277=L1003=6330288=114289=8279=0269=922=8207=BVMF48=380968883=253355270=29.48273=82:90:09272=201406101500=E279=0269=222=8207=BVMF48=380968883=253356270=29.38273=82:90:09271=300272=2014061037016=2014061037017=82:90:081500=E451=-0.251020=437800274=3277=L1003=6340288=70289=8279=0269=922=8207=BVMF48=380968883=253357270=29.48273=82:90:09272=201406101500=E279=0269=222=8207=BVMF48=380968883=253358270=29.38273=82:90:09271=500272=2014061037016=2014061037017=82:90:081500=E451=-0.251020=438300274=3277=L1003=6350288=45289=8279=0269=922=8207=BVMF48=380968883=253359270=29.48273=82:90:09272=201406101500=E279=0269=222=8207=BVMF48=380968883=253360270=29.38273=82:90:09271=300272=2014061037016=2014061037017=82:90:081500=E451=-0.251020=438600274=3277=L1003=6360288=70289=8279=0269=922=8207=BVMF48=380968883=253361270=29.48273=82:90:09272=201406101500=E279=4269=022=8207=BVMF48=380968883=253362273=82:90:09272=20140610290=5
10:28:29.002: 658220 - 70 - 1128=935=X34=65822052=20140610-13:28:29.01275=20140610268=1279=2269=022=8207=BVMF48=380968883=253363273=82:90:11272=2014061037=80531941600288=8290=13
10:28:29.002: 658221 - 81 - 1128=935=X34=65822152=20140610-13:28:29.01275=20140610268=1279=0269=122=8207=BVMF48=380968883=253364270=29.39273=82:90:12271=200272=2014061037016=2014061037017=82:90:1237=80531941666289=8290=3
10:28:29.004: 658222 - 160 - 1128=935=X34=65822252=20140610-13:28:29.01475=20140610268=3279=0269=222=8207=BVMF48=380963983=255620270=26.4273=82:90:13271=600272=2014061037016=2014061037017=82:90:131500=E451=-0.211020=1382400274=3277=L1003=18700288=3289=85279=0269=922=8207=BVMF48=380963983=255621270=26.471273=82:90:13272=201406101500=E279=1269=122=8207=BVMF48=380963983=255622270=26.4273=82:90:13271=1000272=2014061037016=2014061037017=82:90:0137=80531941606289=85290=1
10:28:29.004: 658223 - 160 - 1128=935=X34=65822352=20140610-13:28:29.01575=20140610268=3279=0269=222=8207=BVMF48=380963983=255623270=26.4273=82:90:14271=600272=2014061037016=2014061037017=82:90:141500=E451=-0.211020=1383000274=3277=L1003=18710288=3289=85279=0269=922=8207=BVMF48=380963983=255624270=26.471273=82:90:14272=201406101500=E279=1269=122=8207=BVMF48=380963983=255625270=26.4273=82:90:14271=400272=2014061037016=2014061037017=82:90:0137=80531941606289=85290=1
10:28:29.005: 658224 - 80 - 1128=935=X34=65822452=20140610-13:28:29.01575=20140610268=1279=0269=022=8207=BVMF48=380963983=255626270=26.39273=82:90:15271=600272=2014061037016=2014061037017=82:90:1537=80531941690288=3290=2
10:28:29.006: 658225 - 70 - 1128=935=X34=65822552=20140610-13:28:29.01675=20140610268=1279=2269=022=8207=BVMF48=380963983=255627273=82:90:15272=2014061037=80531941542288=8290=14
10:28:29.006: 658226 - 311 - 1128=935=X34=65822652=20140610-13:28:29.01675=20140610268=7279=0269=222=8207=BVMF48=380963983=255628270=26.4273=82:90:16271=400272=2014061037016=2014061037017=82:90:151500=E451=-0.211020=1383400274=3277=L1003=18720288=3289=85279=0269=922=8207=BVMF48=380963983=255629270=26.471273=82:90:16272=201406101500=E279=2269=122=8207=BVMF48=380963983=255630273=82:90:16272=2014061037=80531941606289=85290=1279=0269=122=8207=BVMF48=380963983=255631270=26.4273=82:90:16271=5000272=2014061037016=2014061037017=82:90:1537=80531941697289=85290=1279=0269=222=8207=BVMF48=380963983=255632270=26.4273=82:90:16271=200272=2014061037016=2014061037017=82:90:151500=E451=-0.211020=1383600274=3277=L1003=18730288=3289=85279=0269=922=8207=BVMF48=380963983=255633270=26.471273=82:90:16272=201406101500=E279=1269=122=8207=BVMF48=380963983=255634270=26.4273=82:90:16271=4800272=2014061037016=2014061037017=82:90:1537=80531941697289=85290=1
10:28:29.007: 658227 - 80 - 1128=935=X34=65822752=20140610-13:28:29.01775=20140610268=1279=0269=022=8207=BVMF48=380963983=255635270=26.39273=82:90:17271=600272=2014061037016=2014061037017=82:90:1637=80531941704288=3290=3
10:28:29.008: 658228 - 80 - 1128=935=X34=65822852=20140610-13:28:29.01875=20140610268=1279=0269=022=8207=BVMF48=380968883=253365270=29.27273=82:90:18271=300272=2014061037016=2014061037017=82:90:1837=80531941717288=8290=36
10:28:29.010: 658229 - 119 - 1128=935=X34=65822952=20140610-13:28:29.02075=20140610268=2279=2269=122=8207=BVMF48=380968883=253366273=82:90:20272=2014061037=80531937275289=45290=38279=0269=122=8207=BVMF48=380968883=253367270=29.47273=82:90:20271=2000272=2014061037016=2014061037017=82:90:2037=80531941733289=45290=28
10:28:29.011: 658230 - 72 - 1128=935=X34=65823052=20140610-13:28:29.02175=20140610268=1279=2269=022=8207=BVMF48=380968883=253368273=82:90:21272=2014061037=80531940508288=227290=5
10:28:29.012: 658231 - 119 - 1128=935=X34=65823152=20140610-13:28:29.02275=20140610268=2279=2269=122=8207=BVMF48=380968883=253369273=82:90:22272=2014061037=80531939924289=45290=7279=0269=122=8207=BVMF48=380968883=253370270=29.39273=82:90:22271=300272=2014061037016=2014061037017=82:90:2137=80531941743289=45290=4
10:28:29.014: 658232 - 81 - 1128=935=X34=65823252=20140610-13:28:29.02475=20140610268=1279=0269=022=8207=BVMF48=380968883=253371270=29.37273=82:90:23271=100272=2014061037016=2014061037017=82:90:2337=80531941749288=40290=3
10:28:29.016: 658233 - 83 - 1128=935=X34=65823352=20140610-13:28:29.02675=20140610268=1279=0269=122=8207=BVMF48=380963983=255636270=26.4273=82:90:26271=1600272=2014061037016=2014061037017=82:90:2637=80531941764289=45290=2
10:28:29.020: 658234 - 119 - 1128=935=X34=65823452=20140610-13:28:29.03075=20140610268=2279=2269=122=8207=BVMF48=380963983=255637273=82:90:30272=2014061037=80531940258289=40290=12279=0269=122=8207=BVMF48=380963983=255638270=26.42273=82:90:30271=200272=2014061037016=2014061037017=82:90:3037=80531941786289=40290=10
10:28:29.021: 658235 - 81 - 1128=935=X34=65823552=20140610-13:28:29.03175=20140610268=1279=0269=022=8207=BVMF48=380968883=253372270=29.38273=82:90:30271=800272=2014061037016=2014061037017=82:90:3037=80531941789288=45290=1
10:28:29.024: 658236 - 145 - 1128=935=X34=65823652=20140610-13:28:29.03275=20140610268=3279=0269=222=8207=BVMF48=380968883=253373270=29.38273=82:90:32271=800272=2014061037016=2014061037017=82:90:321500=E451=-0.251020=439400274=3277=L1003=6370288=45289=8279=0269=922=8207=BVMF48=380968883=253374270=29.48273=82:90:32272=201406101500=E279=2269=022=8207=BVMF48=380968883=253375273=82:90:32272=2014061037=80531941789288=45290=1
10:28:29.024: 658237 - 80 - 1128=935=X34=65823752=20140610-13:28:29.03575=20140610268=1279=0269=022=8207=BVMF48=380968883=253376270=29.37273=82:90:34271=100272=2014061037016=2014061037017=82:90:3437=80531941818288=8290=4
10:28:29.025: 658238 - 81 - 1128=935=X34=65823852=20140610-13:28:29.03575=20140610268=1279=0269=022=8207=BVMF48=380963983=255639270=26.38273=82:90:35271=300272=2014061037016=2014061037017=82:90:3437=80531941825288=45290=8
10:28:29.025: 658239 - 82 - 1128=935=X34=65823952=20140610-13:28:29.03575=20140610268=1279=0269=022=8207=BVMF48=380968883=253377270=29.34273=82:90:35271=800272=2014061037016=2014061037017=82:90:3437=80531941826288=227290=14
10:28:29.025: 658240 - 71 - 1128=935=X34=65824052=20140610-13:28:29.03675=20140610268=1279=2269=022=8207=BVMF48=380968883=253378273=82:90:35272=2014061037=80531941749288=40290=3
10:28:29.027: 658241 - 118 - 1128=935=X34=65824152=20140610-13:28:29.03775=20140610268=2279=2269=022=8207=BVMF48=400223483=5862273=82:90:37272=2014061037=80531935974288=110290=1279=0269=022=8207=BVMF48=400223483=5863270=26.38273=82:90:37271=35272=2014061037016=2014061037017=82:90:3737=80531941839288=110290=4
10:28:29.028: 658242 - 80 - 1128=935=X34=65824252=20140610-13:28:29.03975=20140610268=1279=0269=022=8207=BVMF48=380963983=255640270=26.39273=82:90:38271=300272=2014061037016=2014061037017=82:90:3837=80531941847288=3290=4
10:28:29.029: 658243 - 81 - 1128=935=X34=65824352=20140610-13:28:29.03975=20140610268=1279=0269=022=8207=BVMF48=380968883=253379270=29.37273=82:90:39271=100272=2014061037016=2014061037017=82:90:3937=80531941850288=45290=4
10:28:29.032: 658244 - 80 - 1128=935=X34=65824452=20140610-13:28:29.04375=20140610268=1279=0269=022=8207=BVMF48=380963983=255641270=26.38273=82:90:42271=300272=2014061037016=2014061037017=82:90:4237=80531941863288=3290=10
10:28:29.036: 658245 - 81 - 1128=935=X34=65824552=20140610-13:28:29.04675=20140610268=1279=0269=122=8207=BVMF48=380968883=253380270=29.42273=82:90:46271=300272=2014061037016=2014061037017=82:90:4637=80531941880289=8290=12
10:28:29.037: 658246 - 160 - 1128=935=X34=65824652=20140610-13:28:29.04775=20140610268=3279=0269=222=8207=BVMF48=380963983=255642270=26.4273=82:90:47271=600272=2014061037016=2014061037017=82:90:461500=E451=-0.211020=1384200274=3277=L1003=18740288=3289=85279=0269=922=8207=BVMF48=380963983=255643270=26.471273=82:90:47272=201406101500=E279=1269=122=8207=BVMF48=380963983=255644270=26.4273=82:90:47271=4200272=2014061037016=2014061037017=82:90:1537=80531941697289=85290=1
10:28:29.058: 658247 - 160 - 1128=935=X34=65824752=20140610-13:28:29.06975=20140610268=3279=0269=222=8207=BVMF48=380963983=255645270=26.4273=82:90:68271=600272=2014061037016=2014061037017=82:90:681500=E451=-0.211020=1384800274=3277=L1003=18750288=3289=85279=0269=922=8207=BVMF48=380963983=255646270=26.471273=82:90:68272=201406101500=E279=1269=122=8207=BVMF48=380963983=255647270=26.4273=82:90:68271=3600272=2014061037016=2014061037017=82:90:1537=80531941697289=85290=1
10:28:29.070: 658248 - 80 - 1128=935=X34=65824852=20140610-13:28:29.08175=20140610268=1279=0269=022=8207=BVMF48=380963983=255648270=26.39273=82:90:80271=600272=2014061037016=2014061037017=82:90:8037=80531941923288=3290=5
10:28:29.077: 658249 - 160 - 1128=935=X34=65824952=20140610-13:28:29.08775=20140610268=3279=0269=222=8207=BVMF48=380963983=255649270=26.4273=82:90:86271=600272=2014061037016=2014061037017=82:90:861500=E451=-0.211020=1385400274=3277=L1003=18760288=3289=85279=0269=922=8207=BVMF48=380963983=255650270=26.471273=82:90:86272=201406101500=E279=1269=122=8207=BVMF48=380963983=255651270=26.4273=82:90:86271=3000272=2014061037016=2014061037017=82:90:1537=80531941697289=85290=1
10:28:29.089: 658250 - 161 - 1128=935=X34=65825052=20140610-13:28:29.10075=20140610268=3279=0269=222=8207=BVMF48=380963983=255652270=26.4273=82:90:99271=800272=2014061037016=2014061037017=82:90:991500=E451=-0.211020=1386200274=3277=L1003=18770288=88289=85279=0269=922=8207=BVMF48=380963983=255653270=26.471273=82:90:99272=201406101500=E279=1269=122=8207=BVMF48=380963983=255654270=26.4273=82:90:99271=2200272=2014061037016=2014061037017=82:90:1537=80531941697289=85290=1
10:28:29.109: 658251 - 80 - 1128=935=X34=65825152=20140610-13:28:29.12075=20140610268=1279=0269=022=8207=BVMF48=380963983=255655270=26.39273=82:91:19271=600272=2014061037016=2014061037017=82:91:1937=80531941947288=3290=6
10:28:29.130: 658252 - 199 - 1128=935=X34=65825252=20140610-13:28:29.14075=20140610268=4279=0269=222=8207=BVMF48=380963983=255656270=26.4273=82:91:39271=600272=2014061037016=2014061037017=82:91:391500=E451=-0.211020=1386800274=3277=L1003=18780288=3289=85279=0269=922=8207=BVMF48=380963983=255657270=26.471273=82:91:39272=201406101500=E279=1269=122=8207=BVMF48=380963983=255658270=26.4273=82:91:39271=1600272=2014061037016=2014061037017=82:90:1537=80531941697289=85290=1279=2269=022=8207=BVMF48=380963983=255659273=82:91:39272=2014061037=80531941947288=3290=6
10:28:29.138: 658253 - 115 - 1128=935=X34=65825352=20140610-13:28:29.14875=20140610268=2279=2269=022=8207=BVMF48=400223483=5864273=82:91:48272=2014061037=80531940575288=3290=3279=0269=022=8207=BVMF48=400223483=5865270=26.27273=82:91:48271=85272=2014061037016=2014061037017=82:91:4737=80531941973288=3290=5
10:28:29.146: 658254 - 70 - 1128=935=X34=65825452=20140610-13:28:29.15675=20140610268=1279=2269=122=8207=BVMF48=380388983=12959273=82:91:56272=2014061037=80531939300289=8290=3
10:28:29.165: 658255 - 71 - 1128=935=X34=65825552=20140610-13:28:29.17575=20140610268=1279=2269=122=8207=BVMF48=380963983=255660273=82:91:75272=2014061037=80531941185289=8290=6
10:28:29.177: 658256 - 80 - 1128=935=X34=65825652=20140610-13:28:29.18775=20140610268=1279=0269=022=8207=BVMF48=380968883=253381270=29.35273=82:91:86271=2500272=2014061037016=2014061037017=82:91:8637=80531941984288=8290=10
10:28:29.196: 658257 - 81 - 1128=935=X34=65825752=20140610-13:28:29.20675=20140610268=1279=0269=022=8207=BVMF48=380968883=253382270=29.34273=82:92:05271=2000272=2014061037016=2014061037017=82:92:0537=80531941988288=45290=16
10:28:29.236: 658258 - 71 - 1128=935=X34=65825852=20140610-13:28:29.24575=20140610268=1279=2269=122=8207=BVMF48=380963983=255661273=82:92:45272=2014061037=80531938835289=8290=11
10:28:29.242: 658259 - 71 - 1128=935=X34=65825952=20140610-13:28:29.25375=20140610268=1279=2269=122=8207=BVMF48=380963983=255662273=82:92:52272=2014061037=80531940342289=8290=11
10:28:29.246: 658260 - 193 - 1128=935=X34=65826052=20140610-13:28:29.25675=20140610268=4279=0269=222=8207=BVMF48=400223483=5866270=26.4273=82:92:56271=5272=2014061037016=2014061037017=82:92:551500=E451=-0.211020=655274=01003=370288=27289=63279=0269=922=8207=BVMF48=400223483=5867270=26.55273=82:92:56272=201406101500=E279=2269=022=8207=BVMF48=400223483=5868273=82:92:56272=2014061037=80531941500288=27290=1279=0269=122=8207=BVMF48=400223483=5869270=26.4273=82:92:56271=91272=2014061037016=2014061037017=82:92:5537=80531941996289=63290=1
10:28:29.254: 658261 - 70 - 1128=935=X34=65826152=20140610-13:28:29.26475=20140610268=1279=2269=022=8207=BVMF48=380968883=253383273=82:92:63272=2014061037=80531940500288=3290=2
10:28:29.269: 658262 - 70 - 1128=935=X34=65826252=20140610-13:28:29.27975=20140610268=1279=2269=022=8207=BVMF48=380963983=255663273=82:92:78272=2014061037=80531941704288=3290=3
10:28:29.312: 658263 - 70 - 1128=935=X34=65826352=20140610-13:28:29.32175=20140610268=1279=2269=022=8207=BVMF48=380963983=255664273=82:93:21272=2014061037=80531941690288=3290=2
10:28:29.326: 658264 - 70 - 1128=935=X34=65826452=20140610-13:28:29.33775=20140610268=1279=2269=022=8207=BVMF48=380394783=65745273=82:93:36272=2014061037=80531929140288=8290=9
10:28:29.357: 658265 - 80 - 1128=935=X34=65826552=20140610-13:28:29.36775=20140610268=1279=0269=022=8207=BVMF48=380963983=255665270=26.39273=82:93:66271=600272=2014061037016=2014061037017=82:93:6637=80531942053288=3290=4
10:28:29.374: 658266 - 70 - 1128=935=X34=65826652=20140610-13:28:29.38475=20140610268=1279=2269=022=8207=BVMF48=380968883=253384273=82:93:83272=2014061037=80531941984288=8290=9
10:28:29.384: 658267 - 81 - 1128=935=X34=65826752=20140610-13:28:29.39475=20140610268=1279=0269=122=8207=BVMF48=380963983=255666270=26.42273=82:93:94271=2500272=2014061037016=2014061037017=82:93:9337=80531942058289=8290=10
10:28:29.385: 658268 - 71 - 1128=935=X34=65826852=20140610-13:28:29.39575=20140610268=1279=2269=022=8207=BVMF48=380968883=253385273=82:93:95272=2014061037=80531930603288=16290=35
10:28:29.385: 658269 - 71 - 1128=935=X34=65826952=20140610-13:28:29.39575=20140610268=1279=2269=022=8207=BVMF48=380963983=255667273=82:93:95272=2014061037=80531935222288=16290=49
10:28:29.389: 658270 - 72 - 1128=935=X34=65827052=20140610-13:28:29.39975=20140610268=1279=2269=122=8207=BVMF48=380968883=253386273=82:93:99272=2014061037=80531927257289=16290=36
10:28:29.397: 658271 - 81 - 1128=935=X34=65827152=20140610-13:28:29.40775=20140610268=1279=0269=022=8207=BVMF48=380968883=253387270=29.32273=82:94:06271=2000272=2014061037016=2014061037017=82:94:0637=80531942060288=45290=21
10:28:29.457: 658272 - 71 - 1128=935=X34=65827252=20140610-13:28:29.46875=20140610268=1279=2269=122=8207=BVMF48=400223483=5870273=82:94:67272=2014061037=80531941996289=63290=1
10:28:29.499: 658273 - 70 - 1128=935=X34=65827352=20140610-13:28:29.51075=20140610268=1279=2269=022=8207=BVMF48=380963983=255668273=82:95:09272=2014061037=80531938844288=8290=8
10:28:29.500: 658274 - 71 - 1128=935=X34=65827452=20140610-13:28:29.51075=20140610268=1279=2269=122=8207=BVMF48=380963983=255669273=82:95:09272=2014061037=80531934375289=8290=40
10:28:29.500: 658275 - 80 - 1128=935=X34=65827552=20140610-13:28:29.51075=20140610268=1279=0269=022=8207=BVMF48=380963983=255670270=26.35273=82:95:09271=300272=2014061037016=2014061037017=82:95:0937=80531942086288=8290=33
10:28:29.500: 658276 - 81 - 1128=935=X34=65827652=20140610-13:28:29.51075=20140610268=1279=0269=122=8207=BVMF48=380963983=255671270=26.42273=82:95:09271=300272=2014061037016=2014061037017=82:95:0937=80531942087289=8290=11
10:28:29.504: 658277 - 80 - 1128=935=X34=65827752=20140610-13:28:29.51475=20140610268=1279=0269=022=8207=BVMF48=380963983=255672270=26.39273=82:95:14271=600272=2014061037016=2014061037017=82:95:1437=80531942088288=3290=5
10:28:29.508: 658278 - 118 - 1128=935=X34=65827852=20140610-13:28:29.51875=20140610268=2279=2269=022=8207=BVMF48=380963983=255673273=82:95:18272=2014061037=80531941825288=45290=9279=0269=022=8207=BVMF48=380963983=255674270=26.37273=82:95:18271=600272=2014061037016=2014061037017=82:95:1737=80531942091288=45290=17
10:28:29.509: 658279 - 199 - 1128=935=X34=65827952=20140610-13:28:29.51975=20140610268=4279=0269=222=8207=BVMF48=380963983=255675270=26.4273=82:95:18271=100272=2014061037016=2014061037017=82:95:181500=E451=-0.211020=1386900274=3277=L1003=18790288=3289=85279=0269=922=8207=BVMF48=380963983=255676270=26.471273=82:95:18272=201406101500=E279=1269=122=8207=BVMF48=380963983=255677270=26.4273=82:95:18271=1500272=2014061037016=2014061037017=82:90:1537=80531941697289=85290=1279=2269=022=8207=BVMF48=380963983=255678273=82:95:18272=2014061037=80531941923288=3290=3
10:28:29.516: 658280 - 80 - 1128=935=X34=65828052=20140610-13:28:29.52675=20140610268=1279=0269=022=8207=BVMF48=380963983=255679270=26.39273=82:95:26271=600272=2014061037016=2014061037017=82:95:2637=80531942097288=3290=5
10:28:29.524: 658281 - 82 - 1128=935=X34=65828152=20140610-13:28:29.53475=20140610268=1279=1269=122=8207=BVMF48=380963983=255680270=26.4273=82:95:34271=1500272=2014061037016=2014061037017=82:90:2637=80531942100289=45290=2
10:28:29.594: 658282 - 70 - 1128=935=X34=65828252=20140610-13:28:29.60475=20140610268=1279=2269=022=8207=BVMF48=380968883=253388273=82:96:03272=2014061037=80531941818288=8290=2
10:28:29.595: 658283 - 81 - 1128=935=X34=65828352=20140610-13:28:29.60575=20140610268=1279=0269=122=8207=BVMF48=380968883=253389270=29.43273=82:96:05271=100272=2014061037016=2014061037017=82:96:0537=80531942121289=8290=16
10:28:29.602: 658284 - 118 - 1128=935=X34=65828452=20140610-13:28:29.61275=20140610268=2279=2269=022=8207=BVMF48=380968883=253390273=82:96:11272=2014061037=80531941850288=45290=2279=0269=022=8207=BVMF48=380968883=253391270=29.36273=82:96:11271=200272=2014061037016=2014061037017=82:96:1137=80531942122288=45290=4
10:28:29.654: 658285 - 83 - 1128=935=X34=65828552=20140610-13:28:29.66475=20140610268=1279=0269=122=8207=BVMF48=380963983=255681270=26.4273=82:96:64271=100272=2014061037016=2014061037017=82:96:6337=80531942123289=27290=3
10:28:29.996: 658286 - 119 - 1128=935=X34=65828652=20140610-13:28:30.00675=20140610268=2279=2269=122=8207=BVMF48=380963983=255682273=83:00:06272=2014061037=80531939665289=45290=60279=0269=122=8207=BVMF48=380963983=255683270=26.42273=83:00:06271=5000272=2014061037016=2014061037017=83:00:0637=80531942130289=45290=13
10:28:29.996: 658287 - 119 - 1128=935=X34=65828752=20140610-13:28:30.00775=20140610268=2279=2269=122=8207=BVMF48=380963983=255684273=83:00:06272=2014061037=80531932783289=45290=57279=0269=122=8207=BVMF48=380963983=255685270=26.43273=83:00:06271=5000272=2014061037016=2014061037017=83:00:0637=80531942131289=45290=16
10:28:29.997: 658288 - 81 - 1128=935=X34=65828852=20140610-13:28:30.00775=20140610268=1279=0269=022=8207=BVMF48=380963983=255686270=26.31273=83:00:06271=3000272=2014061037016=2014061037017=83:00:0637=80531942132288=45290=57
10:28:29.997: 658289 - 119 - 1128=935=X34=65828952=20140610-13:28:30.00775=20140610268=2279=2269=122=8207=BVMF48=380963983=255687273=83:00:07272=2014061037=80531939207289=45290=69279=0269=122=8207=BVMF48=380963983=255688270=26.43273=83:00:07271=3000272=2014061037016=2014061037017=83:00:0737=80531942133289=45290=17
10:28:29.997: 658290 - 119 - 1128=935=X34=65829052=20140610-13:28:30.00775=20140610268=2279=2269=122=8207=BVMF48=380963983=255689273=83:00:07272=2014061037=80531936191289=45290=67279=0269=122=8207=BVMF48=380963983=255690270=26.44273=83:00:07271=3000272=2014061037016=2014061037017=83:00:0737=80531942135289=45290=24
10:28:29.997: 658291 - 119 - 1128=935=X34=65829152=20140610-13:28:30.00875=20140610268=2279=2269=122=8207=BVMF48=380963983=255691273=83:00:07272=2014061037=80531934662289=45290=66279=0269=122=8207=BVMF48=380963983=255692270=26.42273=83:00:07271=3000272=2014061037016=2014061037017=83:00:0737=80531942137289=45290=14
10:28:29.999: 658292 - 70 - 1128=935=X34=65829252=20140610-13:28:30.01075=20140610268=1279=2269=022=8207=BVMF48=380963983=255693273=83:00:09272=2014061037=80531938849288=8290=16
10:28:29.999: 658293 - 80 - 1128=935=X34=65829352=20140610-13:28:30.01075=20140610268=1279=0269=022=8207=BVMF48=380963983=255694270=26.34273=83:00:09271=300272=2014061037016=2014061037017=83:00:0937=80531942142288=8290=41
10:28:30.000: 658294 - 71 - 1128=935=X34=65829452=20140610-13:28:30.01075=20140610268=1279=2269=122=8207=BVMF48=380963983=255695273=83:00:09272=2014061037=80531940473289=8290=47
10:28:30.000: 658295 - 81 - 1128=935=X34=65829552=20140610-13:28:30.01075=20140610268=1279=0269=122=8207=BVMF48=380963983=255696270=26.43273=83:00:09271=300272=2014061037016=2014061037017=83:00:0937=80531942144289=8290=19
10:28:30.030: 658296 - 80 - 1128=935=X34=65829652=20140610-13:28:30.04075=20140610268=1279=1269=022=8207=BVMF48=380963983=255697270=26.37273=83:00:39271=300272=2014061037016=2014061037017=82:95:1737=80531942212288=45290=16
10:28:30.036: 658297 - 70 - 1128=935=X34=65829752=20140610-13:28:30.04675=20140610268=1279=2269=022=8207=BVMF48=380968883=253392273=83:00:45272=2014061037=80531934131288=8290=11
10:28:30.197: 658298 - 82 - 1128=935=X34=65829852=20140610-13:28:30.20775=20140610268=1279=0269=022=8207=BVMF48=380963983=255698270=26.3273=83:02:06271=3000272=2014061037016=2014061037017=83:02:0637=80531942217288=45290=64
10:28:30.274: 658299 - 158 - 1128=935=X34=65829952=20140610-13:28:30.28575=20140610268=3279=0269=222=8207=BVMF48=380963983=255699270=26.39273=83:02:84271=100272=2014061037016=2014061037017=83:02:841500=E451=-0.221020=1387000274=21003=18800288=45289=3279=0269=922=8207=BVMF48=380963983=255700270=26.471273=83:02:84272=201406101500=E279=1269=022=8207=BVMF48=380963983=255701270=26.39273=83:02:84271=4900272=2014061037016=2014061037017=61:20:8437=80531933834288=45290=1
10:28:30.397: 658300 - 81 - 1128=935=X34=65830052=20140610-13:28:30.40875=20140610268=1279=0269=022=8207=BVMF48=380963983=255702270=26.29273=83:04:07271=3000272=2014061037016=2014061037017=83:04:0737=80531942220288=45290=66
10:28:30.643: 658301 - 156 - 1128=935=X34=65830152=20140610-13:28:30.65475=20140610268=3279=0269=222=8207=BVMF48=380968883=253393270=29.37273=83:06:53271=100272=2014061037016=2014061037017=83:06:531500=E451=-0.261020=439500274=21003=6380288=27289=3279=0269=922=8207=BVMF48=380968883=253394270=29.48273=83:06:53272=201406101500=E279=1269=022=8207=BVMF48=380968883=253395270=29.37273=83:06:53271=4700272=2014061037016=2014061037017=55:33:0337=80531931833288=27290=1
10:28:31.148: 658302 - 83 - 1128=935=X34=65830252=20140610-13:28:31.15975=20140610268=1279=0269=122=8207=BVMF48=380963983=255703270=36.39273=83:11:58271=1600272=2014061037016=2014061037017=83:11:5837=80531942224289=39290=977
10:28:31.540: 658303 - 119 - 1128=935=X34=65830352=20140610-13:28:31.55075=20140610268=2279=2269=122=8207=BVMF48=380394783=65746273=83:15:50272=2014061037=80531941438289=40290=6279=0269=122=8207=BVMF48=380394783=65747270=17.07273=83:15:50271=100272=2014061037016=2014061037017=83:15:5037=80531942226289=40290=9
10:28:31.923: 658304 - 223 - 1128=935=X34=65830452=20140610-13:28:31.93375=20140610268=6279=0269=222=8207=BVMF48=386389183=28270=9.59273=83:19:32271=259272=2014061037016=2014061037017=83:98:641500=T451=0.14287=621020=3759274=01003=10288=58289=735279=0269=722=8207=BVMF48=386389183=29270=9.59273=83:19:32272=201406101500=T279=0269=922=8207=BVMF48=386389183=30270=9.505273=83:19:32272=201406101500=T279=0269=222=8207=BVMF48=386389183=31270=9.6273=83:19:32271=241272=2014061037016=2014061037017=83:98:641500=T451=0.15287=621020=4000274=01003=20288=58289=735279=0269=722=8207=BVMF48=386389183=32270=9.6273=83:19:32272=201406101500=T279=0269=922=8207=BVMF48=386389183=33270=9.51273=83:19:32272=201406101500=T
10:28:31.923: 658305 - 108 - 1128=935=X34=65830552=20140610-13:28:31.93375=20140610268=2279=0269=222=8207=BVMF48=380249383=103425270=9.44273=83:19:32271=500272=2014061037016=2014061037017=83:98:641500=E451=-0.011020=258800274=0277=31003=550288=735289=58279=0269=922=8207=BVMF48=380249383=103426270=9.382273=83:19:32272=201406101500=E
10:28:31.924: 658306 - 73 - 1128=935=X34=65830652=20140610-13:28:31.93575=20140610268=1279=2269=122=8207=BVMF48=380963983=255704273=83:19:34272=2014061037=80531941472289=238290=8
10:28:31.950: 658307 - 71 - 1128=935=X34=65830752=20140610-13:28:31.96175=20140610268=1279=2269=122=8207=BVMF48=380249383=103427273=83:19:60272=2014061037=80531939678289=8290=6
10:28:31.952: 658308 - 80 - 1128=935=X34=65830852=20140610-13:28:31.96275=20140610268=1279=0269=022=8207=BVMF48=380249383=103428270=9.31273=83:19:62271=100272=2014061037016=2014061037017=83:19:6137=80531942239288=8290=20
10:28:32.042: 658309 - 71 - 1128=935=X34=65830952=20140610-13:28:32.05175=20140610268=1279=2269=122=8207=BVMF48=380249383=103429273=83:20:51272=2014061037=80531927624289=8290=1
10:28:32.042: 658310 - 80 - 1128=935=X34=65831052=20140610-13:28:32.05275=20140610268=1279=0269=022=8207=BVMF48=380249383=103430270=9.33273=83:20:51271=800272=2014061037016=2014061037017=83:20:5137=80531942248288=8290=6
10:28:32.043: 658311 - 154 - 1128=935=X34=65831152=20140610-13:28:32.05375=20140610268=3279=0269=222=8207=BVMF48=380249383=103431270=9.34273=83:20:53271=300272=2014061037016=2014061037017=83:20:521500=E451=-0.111020=259100274=21003=3620288=8289=3279=0269=922=8207=BVMF48=380249383=103432270=9.382273=83:20:53272=201406101500=E279=1269=122=8207=BVMF48=380249383=103433270=9.34273=83:20:53271=500272=2014061037016=2014061037017=44:14:3937=80531927658289=3290=1
10:28:32.044: 658312 - 154 - 1128=935=X34=65831252=20140610-13:28:32.05575=20140610268=3279=0269=222=8207=BVMF48=380249383=103434270=9.34273=83:20:54271=400272=2014061037016=2014061037017=83:20:541500=E451=-0.111020=259500274=3277=L1003=3630288=8289=3279=0269=922=8207=BVMF48=380249383=103435270=9.382273=83:20:54272=201406101500=E279=1269=122=8207=BVMF48=380249383=103436270=9.34273=83:20:54271=100272=2014061037016=2014061037017=44:14:3937=80531927658289=3290=1
10:28:32.046: 658313 - 71 - 1128=935=X34=65831352=20140610-13:28:32.05675=20140610268=1279=2269=122=8207=BVMF48=380249383=103437273=83:20:56272=2014061037=80531931837289=8290=2
10:28:32.051: 658314 - 71 - 1128=935=X34=65831452=20140610-13:28:32.06275=20140610268=1279=2269=122=8207=BVMF48=380249383=103438273=83:20:61272=2014061037=80531927658289=3290=1
10:28:32.055: 658315 - 201 - 1128=935=X34=65831552=20140610-13:28:32.06675=20140610268=4279=0269=222=8207=BVMF48=380249383=103439270=9.33273=83:20:65271=100272=2014061037016=2014061037017=83:20:641500=E451=-0.121020=259600274=21003=3640288=127289=735279=0269=922=8207=BVMF48=380249383=103440270=9.382273=83:20:65272=201406101500=E279=1269=022=8207=BVMF48=380249383=103441270=9.33273=83:20:65271=2900272=2014061037016=2014061037017=75:48:4737=80531940535288=127290=1279=2269=122=8207=BVMF48=380249383=103442273=83:20:65272=2014061037=80531939676289=735290=2
10:28:32.057: 658316 - 72 - 1128=935=X34=65831652=20140610-13:28:32.06875=20140610268=1279=2269=122=8207=BVMF48=380249383=103443273=83:20:67272=2014061037=80531926266289=16290=17
10:28:32.063: 658317 - 160 - 1128=935=X34=65831752=20140610-13:28:32.07375=20140610268=3279=0269=222=8207=BVMF48=380249383=103444270=9.33273=83:20:73271=100272=2014061037016=2014061037017=83:20:721500=E451=-0.121020=259700274=3277=L1003=3650288=127289=735279=0269=922=8207=BVMF48=380249383=103445270=9.381273=83:20:73272=201406101500=E279=1269=022=8207=BVMF48=380249383=103446270=9.33273=83:20:73271=2800272=2014061037016=2014061037017=75:48:4737=80531940535288=127290=1
10:28:32.073: 658318 - 83 - 1128=935=X34=65831852=20140610-13:28:32.08375=20140610268=1279=0269=122=8207=BVMF48=380249383=103447270=9.34273=83:20:83271=300272=2014061037016=2014061037017=83:20:8237=80531942260289=735290=3
10:28:32.130: 658319 - 84 - 1128=935=X34=65831952=20140610-13:28:32.14075=20140610268=1279=0269=122=8207=BVMF48=380963983=255705270=26.4273=83:21:40271=200272=2014061037016=2014061037017=83:21:4037=80531942261289=238290=4
10:28:32.235: 658320 - 204 - 1128=935=X34=65832052=20140610-13:28:32.24575=20140610268=5279=0269=222=8207=BVMF48=380249383=103448270=9.34273=83:22:45271=400272=2014061037016=2014061037017=83:22:441500=E451=-0.111020=260100274=01003=3660288=9289=70279=0269=922=8207=BVMF48=380249383=103449270=9.381273=83:22:45272=201406101500=E279=0269=222=8207=BVMF48=380249383=103450270=9.34273=83:22:45271=400272=2014061037016=2014061037017=83:22:441500=E451=-0.111020=260500274=1277=L1003=3670288=9289=735279=0269=922=8207=BVMF48=380249383=103451270=9.381273=83:22:45272=201406101500=E279=4269=122=8207=BVMF48=380249383=103452273=83:22:45272=20140610290=2
10:28:32.356: 658321 - 83 - 1128=935=X34=65832152=20140610-13:28:32.36775=20140610268=1279=0269=022=8207=BVMF48=380963983=255706270=26.3273=83:23:66271=100272=2014061037016=2014061037017=83:23:6637=80531942275288=114290=65
10:28:32.726: 658322 - 120 - 1128=935=X34=65832252=20140610-13:28:32.73775=20140610268=2279=2269=122=8207=BVMF48=380963983=255707273=83:27:36272=2014061037=80531941544289=40290=7279=0269=122=8207=BVMF48=380963983=255708270=26.4273=83:27:36271=100272=2014061037016=2014061037017=83:27:3637=80531942279289=40290=5
10:28:32.737: 658323 - 70 - 1128=935=X34=65832352=20140610-13:28:32.74775=20140610268=1279=2269=022=8207=BVMF48=380963983=255709273=83:27:46272=2014061037=80531941847288=3290=2
10:28:32.882: 658324 - 83 - 1128=935=X34=65832452=20140610-13:28:32.89275=20140610268=1279=0269=122=8207=BVMF48=380249383=103453270=9.47273=83:28:92271=11600272=2014061037016=2014061037017=83:28:9137=80531942281289=16290=52
10:28:32.891: 658325 - 201 - 1128=935=X34=65832552=20140610-13:28:32.90275=20140610268=4279=0269=222=8207=BVMF48=380249383=103454270=9.33273=83:29:01271=200272=2014061037016=2014061037017=83:29:011500=E451=-0.121020=260700274=21003=3680288=127289=735279=0269=922=8207=BVMF48=380249383=103455270=9.381273=83:29:01272=201406101500=E279=1269=022=8207=BVMF48=380249383=103456270=9.33273=83:29:01271=2600272=2014061037016=2014061037017=75:48:4737=80531940535288=127290=1279=2269=122=8207=BVMF48=380249383=103457273=83:29:01272=2014061037=80531942260289=735290=1
10:28:32.893: 658326 - 81 - 1128=935=X34=65832652=20140610-13:28:32.90375=20140610268=1279=0269=122=8207=BVMF48=380249383=103458270=9.35273=83:29:03271=200272=2014061037016=2014061037017=83:29:0337=80531942283289=8290=5
10:28:32.894: 658327 - 81 - 1128=935=X34=65832752=20140610-13:28:32.90575=20140610268=1279=0269=122=8207=BVMF48=380249383=103459270=9.35273=83:29:04271=100272=2014061037016=2014061037017=83:29:0437=80531942284289=8290=6
10:28:32.897: 658328 - 119 - 1128=935=X34=65832852=20140610-13:28:32.90875=20140610268=2279=2269=122=8207=BVMF48=386391783=2482273=83:29:07272=2014061037=80531921346289=110290=1279=0269=122=8207=BVMF48=386391783=2483270=9.48273=83:29:07271=4272=2014061037016=2014061037017=83:29:0737=80531942289289=110290=1
10:28:32.898: 658329 - 83 - 1128=935=X34=65832952=20140610-13:28:32.90975=20140610268=1279=0269=122=8207=BVMF48=380249383=103460270=9.35273=83:29:08271=300272=2014061037016=2014061037017=83:29:0837=80531942293289=735290=7
10:28:32.950: 658330 - 81 - 1128=935=X34=65833052=20140610-13:28:32.96175=20140610268=1279=0269=122=8207=BVMF48=380249383=103461270=9.35273=83:29:60271=100272=2014061037016=2014061037017=83:29:6037=80531942330289=8290=8
10:28:32.952: 658331 - 81 - 1128=935=X34=65833152=20140610-13:28:32.96275=20140610268=1279=0269=122=8207=BVMF48=380249383=103462270=9.36273=83:29:62271=100272=2014061037016=2014061037017=83:29:6237=80531942331289=8290=13
10:28:32.991: 658332 - 71 - 1128=935=X34=65833252=20140610-13:28:33.00275=20140610268=1279=2269=122=8207=BVMF48=380249383=103463273=83:30:01272=2014061037=80531924799289=8290=38
10:28:32.991: 658333 - 71 - 1128=935=X34=65833352=20140610-13:28:33.00275=20140610268=1279=2269=122=8207=BVMF48=380249383=103464273=83:30:01272=2014061037=80531924798289=8290=46
10:28:32.991: 658334 - 70 - 1128=935=X34=65833452=20140610-13:28:33.00275=20140610268=1279=2269=022=8207=BVMF48=380249383=103465273=83:30:01272=2014061037=80531924801288=8290=48
10:28:32.992: 658335 - 70 - 1128=935=X34=65833552=20140610-13:28:33.00275=20140610268=1279=2269=022=8207=BVMF48=380249383=103466273=83:30:01272=2014061037=80531924800288=8290=43
10:28:32.993: 658336 - 82 - 1128=935=X34=65833652=20140610-13:28:33.00375=20140610268=1279=0269=122=8207=BVMF48=380249383=103467270=9.42273=83:30:03271=11800272=2014061037016=2014061037017=83:30:0337=80531942332289=8290=38
10:28:32.993: 658337 - 82 - 1128=935=X34=65833752=20140610-13:28:33.00475=20140610268=1279=0269=122=8207=BVMF48=380249383=103468270=9.4273=83:30:03271=5200272=2014061037016=2014061037017=83:30:0337=80531942333289=8290=30
10:28:32.994: 658338 - 81 - 1128=935=X34=65833852=20140610-13:28:33.00475=20140610268=1279=0269=022=8207=BVMF48=380249383=103469270=9.28273=83:30:04271=8900272=2014061037016=2014061037017=83:30:0437=80531942334288=8290=36
10:28:32.994: 658339 - 81 - 1128=935=X34=65833952=20140610-13:28:33.00575=20140610268=1279=0269=022=8207=BVMF48=380249383=103470270=9.26273=83:30:04271=11400272=2014061037016=2014061037017=83:30:0437=80531942335288=8290=45
10:28:33.065: 658340 - 72 - 1128=935=X34=65834052=20140610-13:28:33.07575=20140610268=1279=2269=122=8207=BVMF48=380249383=103471273=83:30:75272=2014061037=80531921293289=40290=38
10:28:33.065: 658341 - 72 - 1128=935=X34=65834152=20140610-13:28:33.07575=20140610268=1279=2269=122=8207=BVMF48=380249383=103472273=83:30:75272=2014061037=80531921282289=40290=45
10:28:33.079: 658342 - 72 - 1128=935=X34=65834252=20140610-13:28:33.09075=20140610268=1279=2269=122=8207=BVMF48=380963983=255710273=83:30:89272=2014061037=80531942100289=45290=2
10:28:33.083: 658343 - 71 - 1128=935=X34=65834352=20140610-13:28:33.09475=20140610268=1279=2269=022=8207=BVMF48=380963983=255711273=83:30:93272=2014061037=80531942212288=45290=15
10:28:33.089: 658344 - 676 - 1128=935=X34=65834452=20140610-13:28:33.10075=20140610268=17279=0269=222=8207=BVMF48=380963983=255712270=26.4273=83:30:99271=1500272=2014061037016=2014061037017=83:30:981500=E451=-0.211020=1388500274=01003=18810288=45289=85279=0269=922=8207=BVMF48=380963983=255713270=26.471273=83:30:99272=201406101500=E279=0269=222=8207=BVMF48=380963983=255714270=26.4273=83:30:99271=100272=2014061037016=2014061037017=83:30:981500=E451=-0.211020=1388600274=1277=L1003=18820288=45289=27279=0269=922=8207=BVMF48=380963983=255715270=26.471273=83:30:99272=201406101500=E279=0269=222=8207=BVMF48=380963983=255716270=26.4273=83:30:99271=200272=2014061037016=2014061037017=83:30:981500=E451=-0.211020=1388800274=1277=L1003=18830288=45289=238279=0269=922=8207=BVMF48=380963983=255717270=26.471273=83:30:99272=201406101500=E279=0269=222=8207=BVMF48=380963983=255718270=26.4273=83:30:99271=100272=2014061037016=2014061037017=83:30:981500=E451=-0.211020=1388900274=1277=L1003=18840288=45289=40279=0269=922=8207=BVMF48=380963983=255719270=26.471273=83:30:99272=201406101500=E279=4269=122=8207=BVMF48=380963983=255720273=83:30:99272=20140610290=4279=0269=122=8207=BVMF48=380963983=255721270=26.4273=83:30:99271=5000272=2014061037016=2014061037017=83:30:9837=80531942338289=85290=1279=0269=222=8207=BVMF48=380963983=255722270=26.4273=83:30:99271=5000272=2014061037016=2014061037017=83:30:981500=E451=-0.211020=1393900274=1277=L1003=18850288=45289=85279=0269=922=8207=BVMF48=380963983=255723270=26.47273=83:30:99272=201406101500=E279=2269=122=8207=BVMF48=380963983=255724273=83:30:99272=2014061037=80531942338289=85290=1279=0269=122=8207=BVMF48=380963983=255725270=26.4273=83:30:99271=5000272=2014061037016=2014061037017=83:30:9837=80531942339289=85290=1279=0269=222=8207=BVMF48=380963983=255726270=26.4273=83:30:99271=1100272=2014061037016=2014061037017=83:30:981500=E451=-0.211020=1395000274=1277=L1003=18860288=45289=85279=0269=922=8207=BVMF48=380963983=255727270=26.47273=83:30:99272=201406101500=E279=1269=122=8207=BVMF48=380963983=255728270=26.4273=83:30:99271=3900272=2014061037016=2014061037017=83:30:9837=80531942339289=85290=1
10:28:33.095: 658345 - 313 - 1128=935=X34=65834552=20140610-13:28:33.10675=20140610268=7279=0269=222=8207=BVMF48=380963983=255729270=26.4273=83:31:05271=3900272=2014061037016=2014061037017=83:31:051500=E451=-0.211020=1398900274=1277=L1003=18870288=45289=85279=0269=922=8207=BVMF48=380963983=255730270=26.47273=83:31:05272=201406101500=E279=2269=122=8207=BVMF48=380963983=255731273=83:31:05272=2014061037=80531942339289=85290=1279=0269=122=8207=BVMF48=380963983=255732270=26.4273=83:31:05271=5000272=2014061037016=2014061037017=83:31:0537=80531942343289=85290=1279=0269=222=8207=BVMF48=380963983=255733270=26.4273=83:31:05271=4100272=2014061037016=2014061037017=83:31:051500=E451=-0.211020=1403000274=1277=L1003=18880288=45289=85279=0269=922=8207=BVMF48=380963983=255734270=26.47273=83:31:05272=201406101500=E279=1269=122=8207=BVMF48=380963983=255735270=26.4273=83:31:05271=900272=2014061037016=2014061037017=83:31:0537=80531942343289=85290=1
10:28:33.096: 658346 - 72 - 1128=935=X34=65834652=20140610-13:28:33.10775=20140610268=1279=2269=122=8207=BVMF48=380963983=255736273=83:31:07272=2014061037=80531942137289=45290=10
