10:26:15.161: 656307 - 70 - 1128=935=X34=65630752=20140610-13:26:15.15675=20140610268=1279=2269=022=8207=BVMF48=380977983=20178273=61:51:55272=2014061037=80531933204288=8290=7
10:26:15.161: 656308 - 81 - 1128=935=X34=65630852=20140610-13:26:15.15775=20140610268=1279=0269=122=8207=BVMF48=380977983=20179270=7.41273=61:51:57271=100272=2014061037016=2014061037017=61:51:5737=80531934678289=8290=6
10:26:15.418: 656309 - 82 - 1128=935=X34=65630952=20140610-13:26:15.41875=20140610268=1279=0269=122=8207=BVMF48=380963983=254311270=26.41273=61:54:17271=100272=2014061037016=2014061037017=61:54:1737=80531934680289=77290=5
10:26:15.556: 656310 - 81 - 1128=935=X34=65631052=20140610-13:26:15.52175=20140610268=1279=0269=122=8207=BVMF48=380391383=105950270=13.84273=61:55:21271=300272=2014061037016=2014061037017=61:55:2137=80531934694289=3290=1
10:26:15.556: 656311 - 73 - 1128=935=X34=65631152=20140610-13:26:15.53575=20140610268=1279=2269=122=8207=BVMF48=380394783=65599273=61:55:34272=2014061037=80531932191289=227290=16
10:26:15.556: 656312 - 84 - 1128=935=X34=65631252=20140610-13:26:15.54575=20140610268=1279=0269=122=8207=BVMF48=380394783=65600270=17.1273=61:55:44271=200272=2014061037016=2014061037017=61:55:4437=80531934710289=227290=15
10:26:15.556: 656313 - 73 - 1128=935=X34=65631352=20140610-13:26:15.54875=20140610268=1279=2269=122=8207=BVMF48=380391383=105951273=61:55:47272=2014061037=80531933208289=110290=15
10:26:15.671: 656314 - 71 - 1128=935=X34=65631452=20140610-13:26:15.67575=20140610268=1279=2269=122=8207=BVMF48=380391383=105952273=61:56:74272=2014061037=80531933227289=9290=7
10:26:16.020: 656315 - 145 - 1128=935=X34=65631552=20140610-13:26:16.02475=20140610268=3279=0269=222=8207=BVMF48=380391383=105953270=13.84273=61:60:24271=300272=2014061037016=2014061037017=61:60:231500=E451=-0.051020=104600274=1277=L1003=3150288=735289=3279=0269=922=8207=BVMF48=380391383=105954270=13.879273=61:60:24272=201406101500=E279=2269=122=8207=BVMF48=380391383=105955273=61:60:24272=2014061037=80531934694289=3290=1
10:26:16.031: 656316 - 83 - 1128=935=X34=65631652=20140610-13:26:16.02975=20140610268=1279=0269=122=8207=BVMF48=380391383=105956270=13.87273=61:60:28271=500272=2014061037016=2014061037017=61:60:2837=80531934723289=110290=13
10:26:16.040: 656317 - 73 - 1128=935=X34=65631752=20140610-13:26:16.04575=20140610268=1279=2269=122=8207=BVMF48=380394783=65601273=61:60:44272=2014061037=80531934710289=227290=15
10:26:16.048: 656318 - 83 - 1128=935=X34=65631852=20140610-13:26:16.05275=20140610268=1279=0269=122=8207=BVMF48=380394783=65602270=17.11273=61:60:52271=800272=2014061037016=2014061037017=61:60:5237=80531934726289=227290=16
10:26:16.183: 656319 - 81 - 1128=935=X34=65631952=20140610-13:26:16.18875=20140610268=1279=0269=122=8207=BVMF48=380391383=105957270=13.85273=61:61:87271=1500272=2014061037016=2014061037017=61:61:8737=80531934729289=9290=6
10:26:16.623: 656320 - 71 - 1128=935=X34=65632052=20140610-13:26:16.60575=20140610268=1279=2269=122=8207=BVMF48=380968883=252700273=61:66:04272=2014061037=80531860735289=3290=86
10:26:16.928: 656321 - 81 - 1128=935=X34=65632152=20140610-13:26:16.92975=20140610268=1279=1269=022=8207=BVMF48=380963983=254312270=26.4273=61:69:29271=100272=2014061037016=2014061037017=61:42:9137=80531934737288=40290=5
10:26:16.938: 656322 - 81 - 1128=935=X34=65632252=20140610-13:26:16.94275=20140610268=1279=1269=022=8207=BVMF48=380968883=252701270=29.38273=61:69:42271=6200272=2014061037016=2014061037017=61:43:0037=80531934738288=114290=6
10:26:16.977: 656323 - 81 - 1128=935=X34=65632352=20140610-13:26:16.96775=20140610268=1279=0269=022=8207=BVMF48=380965483=79220270=8.2273=61:69:67271=6400272=2014061037016=2014061037017=61:69:6737=80531934739288=8290=2
10:26:16.977: 656324 - 71 - 1128=935=X34=65632452=20140610-13:26:16.96975=20140610268=1279=2269=122=8207=BVMF48=380965483=79221273=61:69:68272=2014061037=80531932769289=8290=3
10:26:17.057: 656325 - 81 - 1128=935=X34=65632552=20140610-13:26:17.06175=20140610268=1279=0269=022=8207=BVMF48=380965483=79222270=8.2273=61:70:60271=100272=2014061037016=2014061037017=61:70:6037=80531934754288=8290=3
10:26:17.057: 656326 - 70 - 1128=935=X34=65632652=20140610-13:26:17.06175=20140610268=1279=2269=022=8207=BVMF48=380965483=79223273=61:70:60272=2014061037=80531934754288=8290=3
10:26:17.058: 656327 - 81 - 1128=935=X34=65632752=20140610-13:26:17.06275=20140610268=1279=0269=022=8207=BVMF48=380965483=79224270=8.2273=61:70:62271=100272=2014061037016=2014061037017=61:70:6237=80531934755288=8290=3
10:26:17.058: 656328 - 70 - 1128=935=X34=65632852=20140610-13:26:17.06275=20140610268=1279=2269=022=8207=BVMF48=380965483=79225273=61:70:62272=2014061037=80531934755288=8290=3
10:26:17.059: 656329 - 81 - 1128=935=X34=65632952=20140610-13:26:17.06375=20140610268=1279=0269=022=8207=BVMF48=380965483=79226270=8.2273=61:70:63271=100272=2014061037016=2014061037017=61:70:6337=80531934756288=8290=3
10:26:17.059: 656330 - 70 - 1128=935=X34=65633052=20140610-13:26:17.06475=20140610268=1279=2269=022=8207=BVMF48=380965483=79227273=61:70:63272=2014061037=80531934756288=8290=3
10:26:17.076: 656331 - 71 - 1128=935=X34=65633152=20140610-13:26:17.08175=20140610268=1279=2269=022=8207=BVMF48=380963983=254313273=61:70:80272=2014061037=80531934737288=40290=5
10:26:17.080: 656332 - 71 - 1128=935=X34=65633252=20140610-13:26:17.08475=20140610268=1279=2269=022=8207=BVMF48=380963983=254314273=61:70:84272=2014061037=80531934655288=40290=2
10:26:17.085: 656333 - 81 - 1128=935=X34=65633352=20140610-13:26:17.08975=20140610268=1279=1269=022=8207=BVMF48=380968883=252702270=29.38273=61:70:89271=6100272=2014061037016=2014061037017=61:43:0037=80531934757288=114290=6
10:26:17.091: 656334 - 81 - 1128=935=X34=65633452=20140610-13:26:17.09475=20140610268=1279=1269=022=8207=BVMF48=380968883=252703270=29.38273=61:70:94271=5900272=2014061037016=2014061037017=61:43:0037=80531934758288=114290=6
10:26:17.096: 656335 - 118 - 1128=935=X34=65633552=20140610-13:26:17.10175=20140610268=2279=2269=022=8207=BVMF48=380963983=254315273=61:71:00272=2014061037=80531934658288=45290=2279=0269=022=8207=BVMF48=380963983=254316270=26.39273=61:71:00271=800272=2014061037016=2014061037017=61:71:0037=80531934759288=45290=6
10:26:17.104: 656336 - 81 - 1128=935=X34=65633652=20140610-13:26:17.10875=20140610268=1279=1269=022=8207=BVMF48=380968883=252704270=29.38273=61:71:08271=5800272=2014061037016=2014061037017=61:43:0037=80531934760288=114290=6
10:26:17.111: 656337 - 82 - 1128=935=X34=65633752=20140610-13:26:17.11575=20140610268=1279=0269=122=8207=BVMF48=394036883=1645270=2.53273=61:71:14271=67272=2014061037016=2014061037017=61:71:1437=80531934761289=129290=4
10:26:17.257: 656338 - 81 - 1128=935=X34=65633852=20140610-13:26:17.26175=20140610268=1279=1269=022=8207=BVMF48=380963983=254317270=26.21273=61:72:61271=1000272=2014061037016=2014061037017=90:41:1337=80531934763288=308290=86
10:26:18.844: 656339 - 71 - 1128=935=X34=65633952=20140610-13:26:18.84975=20140610268=1279=2269=122=8207=BVMF48=380965483=79228273=61:88:48272=2014061037=80531931616289=3290=8
10:26:18.846: 656340 - 80 - 1128=935=X34=65634052=20140610-13:26:18.85075=20140610268=1279=0269=022=8207=BVMF48=380965483=79229270=8.19273=61:88:50271=100272=2014061037016=2014061037017=61:88:4937=80531934775288=8290=8
10:26:19.388: 656341 - 71 - 1128=935=X34=65634152=20140610-13:26:19.39275=20140610268=1279=2269=122=8207=BVMF48=380391383=105958273=61:93:92272=2014061037=80531930337289=8290=20
10:26:19.389: 656342 - 81 - 1128=935=X34=65634252=20140610-13:26:19.39475=20140610268=1279=0269=122=8207=BVMF48=380391383=105959270=13.87273=61:93:93271=100272=2014061037016=2014061037017=61:93:9337=80531934784289=8290=15
10:26:19.497: 656343 - 81 - 1128=935=X34=65634352=20140610-13:26:19.50275=20140610268=1279=0269=022=8207=BVMF48=380963983=254318270=26.4273=61:95:01271=100272=2014061037016=2014061037017=61:95:0137=80531934785288=8290=3
10:26:19.502: 656344 - 119 - 1128=935=X34=65634452=20140610-13:26:19.50775=20140610268=2279=2269=022=8207=BVMF48=380963983=254319273=61:95:06272=2014061037=80531934759288=45290=7279=0269=022=8207=BVMF48=380963983=254320270=26.4273=61:95:06271=100272=2014061037016=2014061037017=61:95:0637=80531934786288=45290=4
10:26:19.505: 656345 - 120 - 1128=935=X34=65634552=20140610-13:26:19.50975=20140610268=2279=2269=022=8207=BVMF48=380968883=252705273=61:95:09272=2014061037=80531934760288=114290=6279=0269=022=8207=BVMF48=380968883=252706270=29.38273=61:95:09271=5900272=2014061037016=2014061037017=61:95:0937=80531934787288=114290=7
10:26:20.133: 656346 - 70 - 1128=935=X34=65634652=20140610-13:26:20.13875=20140610268=1279=2269=022=8207=BVMF48=380968883=252707273=62:01:37272=2014061037=80531934024288=8290=1
10:26:21.065: 656347 - 154 - 1128=935=X34=65634752=20140610-13:26:21.06975=20140610268=3279=0269=222=8207=BVMF48=380394783=65603270=17.02273=62:10:68271=100272=2014061037016=2014061037017=62:10:681500=E451=-0.141020=18000274=3277=L1003=1040288=3289=3279=0269=922=8207=BVMF48=380394783=65604270=17.103273=62:10:68272=201406101500=E279=1269=022=8207=BVMF48=380394783=65605270=17.02273=62:10:68271=700272=2014061037016=2014061037017=50:96:4837=80531929161288=3290=1
10:26:21.070: 656348 - 71 - 1128=935=X34=65634852=20140610-13:26:21.07475=20140610268=1279=2269=122=8207=BVMF48=380391383=105960273=62:10:74272=2014061037=80531933176289=3290=5
10:26:21.075: 656349 - 156 - 1128=935=X34=65634952=20140610-13:26:21.07975=20140610268=3279=0269=222=8207=BVMF48=380391383=105961270=13.83273=62:10:79271=100272=2014061037016=2014061037017=62:10:781500=E451=-0.061020=104700274=21003=3160288=39289=3279=0269=922=8207=BVMF48=380391383=105962270=13.879273=62:10:79272=201406101500=E279=1269=022=8207=BVMF48=380391383=105963270=13.83273=62:10:79271=3400272=2014061037016=2014061037017=25:97:0537=80531848615288=39290=1
10:26:21.081: 656350 - 81 - 1128=935=X34=65635052=20140610-13:26:21.08575=20140610268=1279=0269=122=8207=BVMF48=380391383=105964270=13.85273=62:10:84271=1300272=2014061037016=2014061037017=62:10:8437=80531934796289=3290=6
10:26:21.091: 656351 - 81 - 1128=935=X34=65635152=20140610-13:26:21.09575=20140610268=1279=0269=122=8207=BVMF48=380391383=105965270=13.84273=62:10:95271=100272=2014061037016=2014061037017=62:10:9437=80531934797289=8290=1
10:26:21.095: 656352 - 73 - 1128=935=X34=65635252=20140610-13:26:21.09975=20140610268=1279=2269=122=8207=BVMF48=380391383=105966273=62:10:98272=2014061037=80531934723289=110290=15
10:26:21.112: 656353 - 82 - 1128=935=X34=65635352=20140610-13:26:21.11775=20140610268=1279=0269=022=8207=BVMF48=380963983=254321270=26.05273=62:11:16271=500272=2014061037016=2014061037017=62:11:1637=80531934807288=735290=117
10:26:21.379: 656354 - 71 - 1128=935=X34=65635452=20140610-13:26:21.38375=20140610268=1279=2269=122=8207=BVMF48=380391383=105967273=62:13:83272=2014061037=80531934729289=9290=6
10:26:21.594: 656355 - 145 - 1128=935=X34=65635552=20140610-13:26:21.59975=20140610268=3279=0269=222=8207=BVMF48=380391383=105968270=13.84273=62:15:98271=100272=2014061037016=2014061037017=62:15:971500=E451=-0.051020=104800274=01003=3170288=735289=8279=0269=922=8207=BVMF48=380391383=105969270=13.879273=62:15:98272=201406101500=E279=2269=122=8207=BVMF48=380391383=105970273=62:15:98272=2014061037=80531934797289=8290=1
10:26:21.599: 656356 - 83 - 1128=935=X34=65635652=20140610-13:26:21.60375=20140610268=1279=0269=122=8207=BVMF48=380391383=105971270=13.87273=62:16:03271=500272=2014061037016=2014061037017=62:16:0337=80531934820289=110290=14
10:26:21.755: 656357 - 81 - 1128=935=X34=65635752=20140610-13:26:21.75975=20140610268=1279=0269=122=8207=BVMF48=380391383=105972270=13.85273=62:17:59271=1500272=2014061037016=2014061037017=62:17:5837=80531934824289=9290=6
10:26:21.756: 656358 - 158 - 1128=935=X34=65635852=20140610-13:26:21.76075=20140610268=3279=0269=222=8207=BVMF48=380968883=252708270=29.39273=62:17:59271=1100272=2014061037016=2014061037017=62:17:591500=E451=-0.241020=370500274=1277=L1003=5540288=227289=45279=0269=922=8207=BVMF48=380968883=252709270=29.497273=62:17:59272=201406101500=E279=1269=122=8207=BVMF48=380968883=252710270=29.39273=62:17:59271=3700272=2014061037016=2014061037017=61:21:2637=80531934048289=45290=1
10:26:21.768: 656359 - 72 - 1128=935=X34=65635952=20140610-13:26:21.77275=20140610268=1279=2269=122=8207=BVMF48=380963983=254322273=62:17:72272=2014061037=80531934142289=45290=2
10:26:21.769: 656360 - 81 - 1128=935=X34=65636052=20140610-13:26:21.77375=20140610268=1279=1269=122=8207=BVMF48=380963983=254323270=26.41273=62:17:72271=4300272=2014061037016=2014061037017=61:21:2537=80531934829289=45290=1
10:26:21.769: 656361 - 82 - 1128=935=X34=65636152=20140610-13:26:21.77375=20140610268=1279=1269=122=8207=BVMF48=380963983=254324270=26.41273=62:17:73271=4200272=2014061037016=2014061037017=61:40:5337=80531934830289=114290=3
10:26:21.783: 656362 - 81 - 1128=935=X34=65636252=20140610-13:26:21.78875=20140610268=1279=1269=122=8207=BVMF48=380963983=254325270=26.41273=62:17:87271=4200272=2014061037016=2014061037017=61:22:3437=80531934831289=45290=2
10:26:22.400: 656363 - 197 - 1128=935=X34=65636352=20140610-13:26:22.40575=20140610268=4279=0269=222=8207=BVMF48=380963983=254326270=26.41273=62:24:04271=100272=2014061037016=2014061037017=62:24:041500=E451=-0.21020=1278000274=01003=17190288=8289=45279=0269=922=8207=BVMF48=380963983=254327270=26.476273=62:24:04272=201406101500=E279=1269=122=8207=BVMF48=380963983=254328270=26.41273=62:24:04271=4200272=2014061037016=2014061037017=61:21:2537=80531934829289=45290=1279=2269=022=8207=BVMF48=380963983=254329273=62:24:04272=2014061037=80531934785288=8290=3
10:26:22.406: 656364 - 82 - 1128=935=X34=65636452=20140610-13:26:22.41075=20140610268=1279=0269=122=8207=BVMF48=380963983=254330270=26.41273=62:24:10271=100272=2014061037016=2014061037017=62:24:1037=80531934853289=45290=5
10:26:22.409: 656365 - 160 - 1128=935=X34=65636552=20140610-13:26:22.41375=20140610268=3279=0269=222=8207=BVMF48=380963983=254331270=26.41273=62:24:13271=100272=2014061037016=2014061037017=62:24:131500=E451=-0.21020=1278100274=1277=L1003=17200288=735289=45279=0269=922=8207=BVMF48=380963983=254332270=26.476273=62:24:13272=201406101500=E279=1269=122=8207=BVMF48=380963983=254333270=26.41273=62:24:13271=4100272=2014061037016=2014061037017=61:21:2537=80531934829289=45290=1
10:26:22.409: 656366 - 118 - 1128=935=X34=65636652=20140610-13:26:22.41475=20140610268=2279=2269=022=8207=BVMF48=380963983=254334273=62:24:13272=2014061037=80531934786288=45290=3279=0269=022=8207=BVMF48=380963983=254335270=26.39273=62:24:13271=800272=2014061037016=2014061037017=62:24:1337=80531934855288=45290=6
10:26:22.414: 656367 - 71 - 1128=935=X34=65636752=20140610-13:26:22.41875=20140610268=1279=2269=022=8207=BVMF48=380968883=252711273=62:24:18272=2014061037=80531934659288=45290=4
10:26:22.415: 656368 - 197 - 1128=935=X34=65636852=20140610-13:26:22.41975=20140610268=4279=0269=222=8207=BVMF48=380968883=252712270=29.39273=62:24:19271=100272=2014061037016=2014061037017=62:24:181500=E451=-0.241020=370600274=1277=L1003=5550288=45289=45279=0269=922=8207=BVMF48=380968883=252713270=29.497273=62:24:19272=201406101500=E279=1269=122=8207=BVMF48=380968883=252714270=29.39273=62:24:19271=3600272=2014061037016=2014061037017=61:21:2637=80531934048289=45290=1279=2269=022=8207=BVMF48=380968883=252715273=62:24:19272=2014061037=80531934202288=45290=3
10:26:22.415: 656369 - 72 - 1128=935=X34=65636952=20140610-13:26:22.42075=20140610268=1279=2269=122=8207=BVMF48=380963983=254336273=62:24:19272=2014061037=80531934853289=45290=5
10:26:22.415: 656370 - 72 - 1128=935=X34=65637052=20140610-13:26:22.42075=20140610268=1279=2269=122=8207=BVMF48=380963983=254337273=62:24:19272=2014061037=80531934829289=45290=1
10:26:22.420: 656371 - 81 - 1128=935=X34=65637152=20140610-13:26:22.42475=20140610268=1279=0269=022=8207=BVMF48=380968883=252716270=29.38273=62:24:24271=4000272=2014061037016=2014061037017=62:24:2437=80531934857288=45290=5
10:26:22.421: 656372 - 82 - 1128=935=X34=65637252=20140610-13:26:22.42575=20140610268=1279=0269=122=8207=BVMF48=380963983=254338270=26.41273=62:24:25271=4300272=2014061037016=2014061037017=62:24:2537=80531934860289=45290=4
10:26:22.424: 656373 - 81 - 1128=935=X34=65637352=20140610-13:26:22.42975=20140610268=1279=1269=022=8207=BVMF48=380968883=252717270=29.38273=62:24:28271=5800272=2014061037016=2014061037017=61:95:0937=80531934861288=114290=4
10:26:22.429: 656374 - 81 - 1128=935=X34=65637452=20140610-13:26:22.43475=20140610268=1279=1269=122=8207=BVMF48=380963983=254339270=26.41273=62:24:33271=4200272=2014061037016=2014061037017=62:24:2537=80531934863289=45290=4
10:26:22.430: 656375 - 82 - 1128=935=X34=65637552=20140610-13:26:22.43475=20140610268=1279=1269=122=8207=BVMF48=380963983=254340270=26.41273=62:24:34271=4100272=2014061037016=2014061037017=61:40:5337=80531934864289=114290=2
10:26:22.443: 656376 - 81 - 1128=935=X34=65637652=20140610-13:26:22.44775=20140610268=1279=1269=122=8207=BVMF48=380963983=254341270=26.41273=62:24:47271=4100272=2014061037016=2014061037017=61:22:3437=80531934867289=45290=1
10:26:22.771: 656377 - 82 - 1128=935=X34=65637752=20140610-13:26:22.77675=20140610268=1279=0269=022=8207=BVMF48=380965483=79230270=7.45273=62:27:75271=1000272=2014061037016=2014061037017=62:27:7537=80531934868288=39290=207
10:26:23.092: 656378 - 82 - 1128=935=X34=65637852=20140610-13:26:23.09675=20140610268=1279=0269=122=8207=BVMF48=380963983=254342270=26.41273=62:30:95271=200272=2014061037016=2014061037017=62:30:9537=80531934869289=40290=5
10:26:23.140: 656379 - 81 - 1128=935=X34=65637952=20140610-13:26:23.14575=20140610268=1279=0269=022=8207=BVMF48=380249383=103277270=9.32273=62:31:44271=500272=2014061037016=2014061037017=62:31:4437=80531934874288=40290=8
10:26:23.550: 656380 - 71 - 1128=935=X34=65638052=20140610-13:26:23.55575=20140610268=1279=2269=122=8207=BVMF48=380394783=65606273=62:35:54272=2014061037=80531930563289=8290=13
10:26:23.552: 656381 - 81 - 1128=935=X34=65638152=20140610-13:26:23.55675=20140610268=1279=0269=122=8207=BVMF48=380394783=65607270=17.06273=62:35:56271=100272=2014061037016=2014061037017=62:35:5637=80531934875289=8290=11
10:26:24.101: 656382 - 81 - 1128=935=X34=65638252=20140610-13:26:24.10675=20140610268=1279=0269=022=8207=BVMF48=380963983=254343270=26.01273=62:41:06271=1000272=2014061037016=2014061037017=62:41:0537=80531934879288=86290=124
10:26:24.565: 656383 - 82 - 1128=935=X34=65638352=20140610-13:26:24.57075=20140610268=1279=1269=122=8207=BVMF48=380963983=254344270=26.45273=62:45:69271=1000272=2014061037016=2014061037017=03:66:5237=80531934880289=564290=21
10:26:25.439: 656384 - 80 - 1128=935=X34=65638452=20140610-13:26:25.44475=20140610268=1279=0269=022=8207=BVMF48=380391383=105973270=13.84273=62:54:43271=100272=2014061037016=2014061037017=62:54:4337=80531934882288=8290=1
10:26:25.447: 656385 - 72 - 1128=935=X34=65638552=20140610-13:26:25.45175=20140610268=1279=2269=022=8207=BVMF48=380394783=65608273=62:54:51272=2014061037=80531934244288=110290=10
10:26:25.508: 656386 - 259 - 1128=935=X34=65638652=20140610-13:26:25.51375=20140610268=6279=0269=222=8207=BVMF48=380965483=79231270=8.2273=62:55:12271=100272=2014061037016=2014061037017=62:55:111500=E451=-0.081020=191100274=3277=L1003=2650288=8289=3279=0269=922=8207=BVMF48=380965483=79232270=8.255273=62:55:12272=201406101500=E279=0269=222=8207=BVMF48=380965483=79233270=8.2273=62:55:12271=100272=2014061037016=2014061037017=62:55:111500=E451=-0.081020=191200274=3277=L1003=2660288=8289=3279=0269=922=8207=BVMF48=380965483=79234270=8.255273=62:55:12272=201406101500=E279=2269=022=8207=BVMF48=380965483=79235273=62:55:12272=2014061037=80531933428288=8290=1279=1269=022=8207=BVMF48=380965483=79236270=8.2273=62:55:12271=6300272=2014061037016=2014061037017=61:69:6737=80531934739288=8290=1
10:26:25.509: 656387 - 81 - 1128=935=X34=65638752=20140610-13:26:25.51475=20140610268=1279=0269=022=8207=BVMF48=380965483=79237270=8.2273=62:55:13271=100272=2014061037016=2014061037017=62:55:1337=80531934890288=8290=2
10:26:25.509: 656388 - 70 - 1128=935=X34=65638852=20140610-13:26:25.51475=20140610268=1279=2269=022=8207=BVMF48=380965483=79238273=62:55:14272=2014061037=80531934890288=8290=2
10:26:25.511: 656389 - 81 - 1128=935=X34=65638952=20140610-13:26:25.51575=20140610268=1279=0269=022=8207=BVMF48=380965483=79239270=8.2273=62:55:15271=100272=2014061037016=2014061037017=62:55:1537=80531934891288=8290=2
10:26:25.511: 656390 - 70 - 1128=935=X34=65639052=20140610-13:26:25.51675=20140610268=1279=2269=022=8207=BVMF48=380965483=79240273=62:55:15272=2014061037=80531934891288=8290=2
10:26:25.511: 656391 - 71 - 1128=935=X34=65639152=20140610-13:26:25.51675=20140610268=1279=2269=122=8207=BVMF48=380968883=252718273=62:55:16272=2014061037=80531934669289=3290=2
10:26:25.512: 656392 - 81 - 1128=935=X34=65639252=20140610-13:26:25.51775=20140610268=1279=0269=022=8207=BVMF48=380965483=79241270=8.2273=62:55:16271=100272=2014061037016=2014061037017=62:55:1637=80531934892288=8290=2
10:26:25.512: 656393 - 70 - 1128=935=X34=65639352=20140610-13:26:25.51775=20140610268=1279=2269=022=8207=BVMF48=380965483=79242273=62:55:16272=2014061037=80531934892288=8290=2
10:26:25.528: 656394 - 81 - 1128=935=X34=65639452=20140610-13:26:25.53275=20140610268=1279=1269=122=8207=BVMF48=380963983=254345270=26.41273=62:55:32271=4000272=2014061037016=2014061037017=62:24:2537=80531934893289=45290=4
10:26:25.528: 656395 - 82 - 1128=935=X34=65639552=20140610-13:26:25.53375=20140610268=1279=1269=122=8207=BVMF48=380963983=254346270=26.41273=62:55:32271=3900272=2014061037016=2014061037017=61:40:5337=80531934894289=114290=2
10:26:25.553: 656396 - 145 - 1128=935=X34=65639652=20140610-13:26:25.55875=20140610268=3279=0269=222=8207=BVMF48=380391383=105974270=13.84273=62:55:57271=100272=2014061037016=2014061037017=62:55:571500=E451=-0.051020=104900274=1277=L1003=3180288=8289=227279=0269=922=8207=BVMF48=380391383=105975270=13.879273=62:55:57272=201406101500=E279=2269=022=8207=BVMF48=380391383=105976273=62:55:57272=2014061037=80531934882288=8290=1
10:26:25.556: 656397 - 82 - 1128=935=X34=65639752=20140610-13:26:25.56075=20140610268=1279=0269=122=8207=BVMF48=380965483=79243270=8.22273=62:55:60271=200272=2014061037016=2014061037017=62:55:6037=80531934896289=40290=4
10:26:25.557: 656398 - 80 - 1128=935=X34=65639852=20140610-13:26:25.56175=20140610268=1279=0269=022=8207=BVMF48=380391383=105977270=13.83273=62:55:61271=100272=2014061037016=2014061037017=62:55:6037=80531934897288=8290=6
10:26:25.568: 656399 - 121 - 1128=935=X34=65639952=20140610-13:26:25.57375=20140610268=2279=2269=022=8207=BVMF48=380963983=254347273=62:55:72272=2014061037=80531926281288=70290=204279=0269=022=8207=BVMF48=380963983=254348270=25.7273=62:55:72271=900272=2014061037016=2014061037017=62:55:7237=80531934903288=70290=195
10:26:25.574: 656400 - 82 - 1128=935=X34=65640052=20140610-13:26:25.57875=20140610268=1279=0269=022=8207=BVMF48=380394783=65609270=16.98273=62:55:78271=400272=2014061037016=2014061037017=62:55:7837=80531934904288=110290=10
10:26:25.600: 656401 - 117 - 1128=935=X34=65640152=20140610-13:26:25.60475=20140610268=2279=2269=122=8207=BVMF48=380391383=105978273=62:56:04272=2014061037=80531934824289=9290=6279=0269=122=8207=BVMF48=380391383=105979270=13.84273=62:56:04271=1500272=2014061037016=2014061037017=62:56:0337=80531934905289=9290=1
10:26:25.631: 656402 - 73 - 1128=935=X34=65640252=20140610-13:26:25.63675=20140610268=1279=2269=122=8207=BVMF48=380394783=65610273=62:56:35272=2014061037=80531934726289=227290=16
10:26:25.633: 656403 - 70 - 1128=935=X34=65640352=20140610-13:26:25.63875=20140610268=1279=2269=022=8207=BVMF48=380394783=65611273=62:56:38272=2014061037=80531931005288=8290=2
10:26:25.640: 656404 - 84 - 1128=935=X34=65640452=20140610-13:26:25.64475=20140610268=1279=0269=122=8207=BVMF48=380394783=65612270=17.1273=62:56:44271=800272=2014061037016=2014061037017=62:56:4437=80531934923289=227290=15
10:26:25.650: 656405 - 81 - 1128=935=X34=65640552=20140610-13:26:25.65575=20140610268=1279=0269=122=8207=BVMF48=380391383=105980270=13.84273=62:56:54271=100272=2014061037016=2014061037017=62:56:5437=80531934924289=8290=2
10:26:25.650: 656406 - 71 - 1128=935=X34=65640652=20140610-13:26:25.65575=20140610268=1279=2269=122=8207=BVMF48=380391383=105981273=62:56:54272=2014061037=80531934924289=8290=2
10:26:25.652: 656407 - 270 - 1128=935=X34=65640752=20140610-13:26:25.65675=20140610268=6279=0269=222=8207=BVMF48=380963983=254349270=26.41273=62:56:56271=4100272=2014061037016=2014061037017=62:56:551500=E451=-0.21020=1282200274=1277=L1003=17210288=3289=45279=0269=922=8207=BVMF48=380963983=254350270=26.476273=62:56:56272=201406101500=E279=0269=222=8207=BVMF48=380963983=254351270=26.41273=62:56:56271=400272=2014061037016=2014061037017=62:56:551500=E451=-0.21020=1282600274=1277=L1003=17220288=3289=114279=0269=922=8207=BVMF48=380963983=254352270=26.476273=62:56:56272=201406101500=E279=2269=122=8207=BVMF48=380963983=254353273=62:56:56272=2014061037=80531934867289=45290=1279=1269=122=8207=BVMF48=380963983=254354270=26.41273=62:56:56271=3500272=2014061037016=2014061037017=61:40:5337=80531934894289=114290=1
10:26:25.655: 656408 - 70 - 1128=935=X34=65640852=20140610-13:26:25.66075=20140610268=1279=2269=022=8207=BVMF48=380391383=105982273=62:56:59272=2014061037=80531931307288=8290=34
10:26:25.656: 656409 - 73 - 1128=935=X34=65640952=20140610-13:26:25.66175=20140610268=1279=2269=122=8207=BVMF48=380963983=254355273=62:56:61272=2014061037=80531934894289=114290=1
10:26:25.657: 656410 - 199 - 1128=935=X34=65641052=20140610-13:26:25.66275=20140610268=4279=0269=222=8207=BVMF48=380968883=252719270=29.39273=62:56:61271=400272=2014061037016=2014061037017=62:56:611500=E451=-0.241020=371000274=1277=L1003=5560288=114289=45279=0269=922=8207=BVMF48=380968883=252720270=29.497273=62:56:61272=201406101500=E279=1269=122=8207=BVMF48=380968883=252721270=29.39273=62:56:61271=3200272=2014061037016=2014061037017=61:21:2637=80531934048289=45290=1279=2269=022=8207=BVMF48=380968883=252722273=62:56:61272=2014061037=80531934861288=114290=4
10:26:25.658: 656411 - 72 - 1128=935=X34=65641152=20140610-13:26:25.66275=20140610268=1279=2269=122=8207=BVMF48=380963983=254356273=62:56:62272=2014061037=80531934644289=45290=8
10:26:25.659: 656412 - 283 - 1128=935=X34=65641252=20140610-13:26:25.66375=20140610268=7279=0269=222=8207=BVMF48=380963983=254357270=26.41273=62:56:63271=100272=2014061037016=2014061037017=62:56:621500=E451=-0.21020=1282700274=1277=L1003=17230288=45289=77279=0269=922=8207=BVMF48=380963983=254358270=26.476273=62:56:63272=201406101500=E279=0269=222=8207=BVMF48=380963983=254359270=26.41273=62:56:63271=4000272=2014061037016=2014061037017=62:56:621500=E451=-0.21020=1286700274=1277=L1003=17240288=45289=45279=0269=922=8207=BVMF48=380963983=254360270=26.476273=62:56:63272=201406101500=E279=0269=222=8207=BVMF48=380963983=254361270=26.41273=62:56:63271=200272=2014061037016=2014061037017=62:56:621500=E451=-0.21020=1286900274=1277=L1003=17250288=45289=40279=0269=922=8207=BVMF48=380963983=254362270=26.476273=62:56:63272=201406101500=E279=4269=122=8207=BVMF48=380963983=254363273=62:56:63272=20140610290=3
10:26:25.659: 656413 - 119 - 1128=935=X34=65641352=20140610-13:26:25.66475=20140610268=2279=2269=022=8207=BVMF48=380963983=254364273=62:56:63272=2014061037=80531934645288=45290=68279=0269=022=8207=BVMF48=380963983=254365270=26.4273=62:56:63271=3000272=2014061037016=2014061037017=62:56:6337=80531934937288=45290=3
10:26:25.660: 656414 - 72 - 1128=935=X34=65641452=20140610-13:26:25.66475=20140610268=1279=2269=122=8207=BVMF48=380968883=252723273=62:56:64272=2014061037=80531934260289=45290=32
10:26:25.661: 656415 - 118 - 1128=935=X34=65641552=20140610-13:26:25.66675=20140610268=2279=2269=022=8207=BVMF48=380968883=252724273=62:56:65272=2014061037=80531934266288=45290=20279=0269=022=8207=BVMF48=380968883=252725270=29.36273=62:56:65271=2000272=2014061037016=2014061037017=62:56:6537=80531934943288=45290=9
10:26:25.662: 656416 - 83 - 1128=935=X34=65641652=20140610-13:26:25.66775=20140610268=1279=0269=122=8207=BVMF48=380963983=254366270=26.41273=62:56:67271=3900272=2014061037016=2014061037017=62:56:6737=80531934960289=114290=1
10:26:25.663: 656417 - 82 - 1128=935=X34=65641752=20140610-13:26:25.66875=20140610268=1279=0269=022=8207=BVMF48=380968883=252726270=29.38273=62:56:68271=5700272=2014061037016=2014061037017=62:56:6837=80531934963288=114290=5
10:26:25.666: 656418 - 346 - 1128=935=X34=65641852=20140610-13:26:25.67075=20140610268=8279=0269=222=8207=BVMF48=380968883=252727270=29.39273=62:56:70271=3200272=2014061037016=2014061037017=62:56:691500=E451=-0.241020=374200274=1277=L1003=5570288=45289=45279=0269=922=8207=BVMF48=380968883=252728270=29.496273=62:56:70272=201406101500=E279=2269=122=8207=BVMF48=380968883=252729273=62:56:70272=2014061037=80531934048289=45290=1279=0269=122=8207=BVMF48=380968883=252730270=29.39273=62:56:70271=5000272=2014061037016=2014061037017=62:56:6937=80531934980289=45290=1279=0269=222=8207=BVMF48=380968883=252731270=29.39273=62:56:70271=400272=2014061037016=2014061037017=62:56:691500=E451=-0.241020=374600274=1277=L1003=5580288=45289=45279=0269=922=8207=BVMF48=380968883=252732270=29.496273=62:56:70272=201406101500=E279=1269=122=8207=BVMF48=380968883=252733270=29.39273=62:56:70271=4600272=2014061037016=2014061037017=62:56:6937=80531934980289=45290=1279=2269=022=8207=BVMF48=380968883=252734273=62:56:70272=2014061037=80531934857288=45290=4
10:26:25.668: 656419 - 80 - 1128=935=X34=65641952=20140610-13:26:25.67275=20140610268=1279=0269=022=8207=BVMF48=380391383=105983270=13.78273=62:56:72271=900272=2014061037016=2014061037017=62:56:7137=80531934998288=8290=34
10:26:25.673: 656420 - 81 - 1128=935=X34=65642052=20140610-13:26:25.67775=20140610268=1279=0269=022=8207=BVMF48=380968883=252735270=29.38273=62:56:77271=4000272=2014061037016=2014061037017=62:56:7637=80531935015288=45290=5
10:26:25.673: 656421 - 82 - 1128=935=X34=65642152=20140610-13:26:25.67775=20140610268=1279=0269=122=8207=BVMF48=380963983=254367270=26.41273=62:56:77271=4000272=2014061037016=2014061037017=62:56:7737=80531935018289=45290=2
10:26:25.679: 656422 - 81 - 1128=935=X34=65642252=20140610-13:26:25.68475=20140610268=1279=1269=122=8207=BVMF48=380963983=254368270=26.41273=62:56:83271=3500272=2014061037016=2014061037017=62:56:7737=80531935038289=45290=2
10:26:25.679: 656423 - 82 - 1128=935=X34=65642352=20140610-13:26:25.68475=20140610268=1279=1269=122=8207=BVMF48=380963983=254369270=26.41273=62:56:83271=3500272=2014061037016=2014061037017=62:56:6737=80531935040289=114290=1
10:26:25.681: 656424 - 121 - 1128=935=X34=65642452=20140610-13:26:25.68675=20140610268=2279=2269=022=8207=BVMF48=380968883=252736273=62:56:85272=2014061037=80531934963288=114290=4279=0269=022=8207=BVMF48=380968883=252737270=29.38273=62:56:85271=8400272=2014061037016=2014061037017=62:56:8537=80531935043288=114290=5
10:26:25.690: 656425 - 72 - 1128=935=X34=65642552=20140610-13:26:25.69575=20140610268=1279=2269=122=8207=BVMF48=380963983=254370273=62:56:94272=2014061037=80531934653289=45290=7
10:26:25.692: 656426 - 82 - 1128=935=X34=65642652=20140610-13:26:25.69775=20140610268=1279=0269=122=8207=BVMF48=380963983=254371270=26.42273=62:56:97271=900272=2014061037016=2014061037017=62:56:9637=80531935056289=40290=4
10:26:25.693: 656427 - 82 - 1128=935=X34=65642752=20140610-13:26:25.69875=20140610268=1279=0269=122=8207=BVMF48=380963983=254372270=26.41273=62:56:98271=1500272=2014061037016=2014061037017=62:56:9737=80531935059289=45290=3
10:26:25.694: 656428 - 121 - 1128=935=X34=65642852=20140610-13:26:25.69975=20140610268=2279=2269=122=8207=BVMF48=380963983=254373273=62:56:98272=2014061037=80531935040289=114290=1279=0269=122=8207=BVMF48=380963983=254374270=26.41273=62:56:98271=5100272=2014061037016=2014061037017=62:56:9837=80531935060289=114290=3
10:26:25.696: 656429 - 71 - 1128=935=X34=65642952=20140610-13:26:25.70075=20140610268=1279=2269=022=8207=BVMF48=380963983=254375273=62:57:00272=2014061037=80531934937288=45290=3
10:26:25.712: 656430 - 81 - 1128=935=X34=65643052=20140610-13:26:25.71775=20140610268=1279=1269=022=8207=BVMF48=380968883=252738270=29.38273=62:57:17271=5700272=2014061037016=2014061037017=62:56:8537=80531935081288=114290=5
10:26:25.813: 656431 - 82 - 1128=935=X34=65643152=20140610-13:26:25.81875=20140610268=1279=0269=122=8207=BVMF48=380963983=254376270=26.41273=62:58:17271=100272=2014061037016=2014061037017=62:58:1737=80531935106289=40290=4
10:26:25.850: 656432 - 82 - 1128=935=X34=65643252=20140610-13:26:25.85575=20140610268=1279=0269=122=8207=BVMF48=380963983=254377270=26.41273=62:58:54271=200272=2014061037016=2014061037017=62:58:5437=80531935118289=77290=5
10:26:25.858: 656433 - 82 - 1128=935=X34=65643352=20140610-13:26:25.86375=20140610268=1279=0269=122=8207=BVMF48=380963983=254378270=26.43273=62:58:62271=3000272=2014061037016=2014061037017=62:58:6237=80531935120289=45290=11
10:26:25.860: 656434 - 82 - 1128=935=X34=65643452=20140610-13:26:25.86575=20140610268=1279=0269=122=8207=BVMF48=380968883=252739270=29.49273=62:58:65271=2000272=2014061037016=2014061037017=62:58:6537=80531935121289=45290=32
10:26:25.869: 656435 - 73 - 1128=935=X34=65643552=20140610-13:26:25.87375=20140610268=1279=2269=122=8207=BVMF48=380391383=105984273=62:58:73272=2014061037=80531934820289=110290=15
10:26:25.892: 656436 - 82 - 1128=935=X34=65643652=20140610-13:26:25.89675=20140610268=1279=0269=122=8207=BVMF48=380963983=254379270=26.52273=62:58:96271=5000272=2014061037016=2014061037017=62:58:9637=80531935124289=45290=66
10:26:25.895: 656437 - 344 - 1128=935=X34=65643752=20140610-13:26:25.89975=20140610268=9279=0269=222=8207=BVMF48=380394783=65613270=17.03273=62:58:99271=100272=2014061037016=2014061037017=62:58:981500=E451=-0.131020=18100274=01003=1050288=8289=8279=0269=922=8207=BVMF48=380394783=65614270=17.103273=62:58:99272=201406101500=E279=0269=222=8207=BVMF48=380394783=65615270=17.03273=62:58:99271=100272=2014061037016=2014061037017=62:58:981500=E451=-0.131020=18200274=1277=L1003=1060288=8289=70279=0269=922=8207=BVMF48=380394783=65616270=17.102273=62:58:99272=201406101500=E279=0269=222=8207=BVMF48=380394783=65617270=17.03273=62:58:99271=100272=2014061037016=2014061037017=62:58:981500=E451=-0.131020=18300274=1277=L1003=1070288=8289=40279=0269=922=8207=BVMF48=380394783=65618270=17.102273=62:58:99272=201406101500=E279=0269=222=8207=BVMF48=380394783=65619270=17.03273=62:58:99271=100272=2014061037016=2014061037017=62:58:981500=E451=-0.131020=18400274=1277=L1003=1080288=8289=70279=0269=922=8207=BVMF48=380394783=65620270=17.102273=62:58:99272=201406101500=E279=4269=122=8207=BVMF48=380394783=65621273=62:58:99272=20140610290=4
10:26:25.896: 656438 - 82 - 1128=935=X34=65643852=20140610-13:26:25.90175=20140610268=1279=0269=022=8207=BVMF48=380963983=254380270=26.3273=62:59:01271=3000272=2014061037016=2014061037017=62:59:0037=80531935126288=45290=68
10:26:25.956: 656439 - 81 - 1128=935=X34=65643952=20140610-13:26:25.96175=20140610268=1279=0269=122=8207=BVMF48=380394783=65622270=17.04273=62:59:60271=100272=2014061037016=2014061037017=62:59:6037=80531935128289=8290=4
10:26:25.958: 656440 - 81 - 1128=935=X34=65644052=20140610-13:26:25.96375=20140610268=1279=0269=122=8207=BVMF48=380394783=65623270=17.04273=62:59:62271=200272=2014061037016=2014061037017=62:59:6237=80531935129289=8290=5
10:26:26.054: 656441 - 83 - 1128=935=X34=65644152=20140610-13:26:26.05975=20140610268=1279=0269=122=8207=BVMF48=380963983=254381270=26.41273=62:60:59271=200272=2014061037016=2014061037017=62:60:5937=80531935130289=238290=6
10:26:26.060: 656442 - 117 - 1128=935=X34=65644252=20140610-13:26:26.06475=20140610268=2279=2269=122=8207=BVMF48=380391383=105985273=62:60:64272=2014061037=80531934796289=3290=6279=0269=122=8207=BVMF48=380391383=105986270=13.86273=62:60:64271=1300272=2014061037016=2014061037017=62:60:6337=80531935131289=3290=8
10:26:26.094: 656443 - 117 - 1128=935=X34=65644352=20140610-13:26:26.09975=20140610268=2279=2269=122=8207=BVMF48=380391383=105987273=62:60:98272=2014061037=80531935131289=3290=8279=0269=122=8207=BVMF48=380391383=105988270=13.85273=62:60:98271=1300272=2014061037016=2014061037017=62:60:9837=80531935143289=3290=6
10:26:26.103: 656444 - 156 - 1128=935=X34=65644452=20140610-13:26:26.10875=20140610268=3279=0269=222=8207=BVMF48=380391383=105989270=13.84273=62:61:07271=1000272=2014061037016=2014061037017=62:61:071500=E451=-0.051020=105900274=1277=L1003=3190288=735289=9279=0269=922=8207=BVMF48=380391383=105990270=13.878273=62:61:07272=201406101500=E279=1269=122=8207=BVMF48=380391383=105991270=13.84273=62:61:07271=500272=2014061037016=2014061037017=62:56:0337=80531934905289=9290=1
10:26:26.111: 656445 - 71 - 1128=935=X34=65644552=20140610-13:26:26.11675=20140610268=1279=2269=022=8207=BVMF48=380391383=105992273=62:61:15272=2014061037=80531932078288=85290=5
10:26:26.112: 656446 - 144 - 1128=935=X34=65644652=20140610-13:26:26.11775=20140610268=3279=0269=222=8207=BVMF48=380391383=105993270=13.84273=62:61:17271=500272=2014061037016=2014061037017=62:61:161500=E451=-0.051020=106400274=1277=L1003=3200288=85289=9279=0269=922=8207=BVMF48=380391383=105994270=13.878273=62:61:17272=201406101500=E279=2269=122=8207=BVMF48=380391383=105995273=62:61:17272=2014061037=80531934905289=9290=1
10:26:26.122: 656447 - 73 - 1128=935=X34=65644752=20140610-13:26:26.12775=20140610268=1279=2269=122=8207=BVMF48=380394783=65624273=62:61:26272=2014061037=80531934923289=227290=13
10:26:26.134: 656448 - 84 - 1128=935=X34=65644852=20140610-13:26:26.13975=20140610268=1279=0269=122=8207=BVMF48=380394783=65625270=17.1273=62:61:39271=400272=2014061037016=2014061037017=62:61:3837=80531935164289=227290=13
10:26:26.148: 656449 - 73 - 1128=935=X34=65644952=20140610-13:26:26.15275=20140610268=1279=2269=122=8207=BVMF48=380394783=65626273=62:61:52272=2014061037=80531935164289=227290=13
10:26:26.156: 656450 - 71 - 1128=935=X34=65645052=20140610-13:26:26.16175=20140610268=1279=2269=122=8207=BVMF48=380391383=105996273=62:61:60272=2014061037=80531931596289=8290=3
10:26:26.159: 656451 - 83 - 1128=935=X34=65645152=20140610-13:26:26.16475=20140610268=1279=0269=122=8207=BVMF48=380394783=65627270=17.11273=62:61:63271=800272=2014061037016=2014061037017=62:61:6337=80531935166289=227290=14
10:26:26.296: 656452 - 80 - 1128=935=X34=65645252=20140610-13:26:26.30075=20140610268=1279=0269=022=8207=BVMF48=380394783=65628270=17.02273=62:63:00271=400272=2014061037016=2014061037017=62:63:0037=80531935169288=8290=3
10:26:26.297: 656453 - 80 - 1128=935=X34=65645352=20140610-13:26:26.30275=20140610268=1279=0269=022=8207=BVMF48=380394783=65629270=17.02273=62:63:01271=200272=2014061037016=2014061037017=62:63:0137=80531935170288=8290=4
10:26:26.310: 656454 - 70 - 1128=935=X34=65645452=20140610-13:26:26.31575=20140610268=1279=2269=022=8207=BVMF48=380391383=105997273=62:63:14272=2014061037=80531934998288=8290=33
10:26:26.320: 656455 - 80 - 1128=935=X34=65645552=20140610-13:26:26.32475=20140610268=1279=0269=022=8207=BVMF48=380391383=105998270=13.78273=62:63:24271=1000272=2014061037016=2014061037017=62:63:2437=80531935171288=8290=33
10:26:26.344: 656456 - 161 - 1128=935=X34=65645652=20140610-13:26:26.34975=20140610268=3279=0269=222=8207=BVMF48=380963983=254382270=26.4273=62:63:48271=3000272=2014061037016=2014061037017=62:63:481500=E451=-0.211020=1289900274=21003=17260288=45289=39279=0269=922=8207=BVMF48=380963983=254383270=26.475273=62:63:48272=201406101500=E279=1269=022=8207=BVMF48=380963983=254384270=26.4273=62:63:48271=1100272=2014061037016=2014061037017=61:22:1237=80531934175288=45290=1
10:26:26.345: 656457 - 71 - 1128=935=X34=65645752=20140610-13:26:26.35075=20140610268=1279=2269=022=8207=BVMF48=380968883=252740273=62:63:49272=2014061037=80531934943288=45290=10
10:26:26.347: 656458 - 71 - 1128=935=X34=65645852=20140610-13:26:26.35275=20140610268=1279=2269=022=8207=BVMF48=380963983=254385273=62:63:52272=2014061037=80531934175288=45290=1
10:26:26.350: 656459 - 81 - 1128=935=X34=65645952=20140610-13:26:26.35575=20140610268=1279=0269=122=8207=BVMF48=380963983=254386270=26.43273=62:63:55271=100272=2014061037016=2014061037017=62:63:5437=80531935183289=8290=13
10:26:26.352: 656460 - 80 - 1128=935=X34=65646052=20140610-13:26:26.35775=20140610268=1279=1269=022=8207=BVMF48=380968883=252741270=29.38273=62:63:56271=2900272=2014061037016=2014061037017=62:56:7637=80531935186288=45290=4
10:26:26.353: 656461 - 81 - 1128=935=X34=65646152=20140610-13:26:26.35875=20140610268=1279=1269=022=8207=BVMF48=380968883=252742270=29.38273=62:63:58271=3000272=2014061037016=2014061037017=62:56:8537=80531935188288=114290=5
10:26:26.364: 656462 - 80 - 1128=935=X34=65646252=20140610-13:26:26.36975=20140610268=1279=1269=022=8207=BVMF48=380968883=252743270=29.38273=62:63:68271=1900272=2014061037016=2014061037017=62:56:7637=80531935195288=45290=4
10:26:26.364: 656463 - 81 - 1128=935=X34=65646352=20140610-13:26:26.36975=20140610268=1279=1269=022=8207=BVMF48=380968883=252744270=29.38273=62:63:69271=2000272=2014061037016=2014061037017=62:56:8537=80531935196288=114290=5
10:26:26.404: 656464 - 83 - 1128=935=X34=65646452=20140610-13:26:26.40975=20140610268=1279=0269=122=8207=BVMF48=380391383=105999270=13.84273=62:64:08271=100272=2014061037016=2014061037017=62:64:0837=80531935199289=238290=1
10:26:26.479: 656465 - 71 - 1128=935=X34=65646552=20140610-13:26:26.48375=20140610268=1279=2269=022=8207=BVMF48=380963983=254387273=62:64:83272=2014061037=80531929844288=16290=65
10:26:26.547: 656466 - 81 - 1128=935=X34=65646652=20140610-13:26:26.55175=20140610268=1279=0269=022=8207=BVMF48=380968883=252745270=29.33273=62:65:51271=2000272=2014061037016=2014061037017=62:65:5137=80531935201288=45290=21
10:26:26.621: 656467 - 70 - 1128=935=X34=65646752=20140610-13:26:26.62675=20140610268=1279=2269=022=8207=BVMF48=380391383=106000273=62:66:25272=2014061037=80531863742288=8290=15
10:26:26.621: 656468 - 81 - 1128=935=X34=65646852=20140610-13:26:26.62675=20140610268=1279=0269=022=8207=BVMF48=380391383=106001270=13.8273=62:66:25271=700272=2014061037016=2014061037017=62:66:2537=80531935202288=8290=21
10:26:26.622: 656469 - 80 - 1128=935=X34=65646952=20140610-13:26:26.62675=20140610268=1279=0269=022=8207=BVMF48=380391383=106002270=13.75273=62:66:25271=700272=2014061037016=2014061037017=62:66:2537=80531935203288=8290=49
10:26:26.622: 656470 - 70 - 1128=935=X34=65647052=20140610-13:26:26.62675=20140610268=1279=2269=022=8207=BVMF48=380391383=106003273=62:66:26272=2014061037=80531935203288=8290=49
10:26:26.672: 656471 - 70 - 1128=935=X34=65647152=20140610-13:26:26.67775=20140610268=1279=2269=022=8207=BVMF48=380963983=254388273=62:66:76272=2014061037=80531930081288=8290=59
10:26:26.672: 656472 - 80 - 1128=935=X34=65647252=20140610-13:26:26.67775=20140610268=1279=0269=022=8207=BVMF48=380963983=254389270=26.37273=62:66:77271=300272=2014061037016=2014061037017=62:66:7637=80531935204288=8290=15
10:26:26.673: 656473 - 81 - 1128=935=X34=65647352=20140610-13:26:26.67775=20140610268=1279=0269=122=8207=BVMF48=380963983=254390270=26.46273=62:66:77271=300272=2014061037016=2014061037017=62:66:7737=80531935205289=8290=38
10:26:26.673: 656474 - 71 - 1128=935=X34=65647452=20140610-13:26:26.67875=20140610268=1279=2269=122=8207=BVMF48=380963983=254391273=62:66:77272=2014061037=80531930743289=8290=10
10:26:26.833: 656475 - 81 - 1128=935=X34=65647552=20140610-13:26:26.83775=20140610268=1279=0269=022=8207=BVMF48=380249383=103278270=9.03273=62:68:37271=1700272=2014061037016=2014061037017=62:68:3637=80531935206288=72290=57
10:26:26.907: 656476 - 149 - 1128=935=X34=65647652=20140610-13:26:26.91275=20140610268=3279=0269=222=8207=BVMF48=380391383=106004270=13.84273=62:69:12271=100272=2014061037016=2014061037017=62:69:111500=E451=-0.051020=106500274=1277=L1003=3210288=735289=238279=0269=922=8207=BVMF48=380391383=106005270=13.878273=62:69:12272=201406101500=E279=2269=122=8207=BVMF48=380391383=106006273=62:69:12272=2014061037=80531935199289=238290=1
10:26:26.914: 656477 - 71 - 1128=935=X34=65647752=20140610-13:26:26.91975=20140610268=1279=2269=122=8207=BVMF48=380391383=106007273=62:69:18272=2014061037=80531931041289=8290=11
10:26:26.940: 656478 - 72 - 1128=935=X34=65647852=20140610-13:26:26.94475=20140610268=1279=2269=022=8207=BVMF48=380963983=254392273=62:69:44272=2014061037=80531887906288=262290=28
10:26:26.956: 656479 - 81 - 1128=935=X34=65647952=20140610-13:26:26.96175=20140610268=1279=0269=122=8207=BVMF48=380391383=106008270=13.85273=62:69:60271=100272=2014061037016=2014061037017=62:69:6037=80531935213289=8290=5
10:26:26.993: 656480 - 81 - 1128=935=X34=65648052=20140610-13:26:26.99875=20140610268=1279=0269=122=8207=BVMF48=380963983=254393270=26.41273=62:69:98271=500272=2014061037016=2014061037017=62:69:9837=80531935214289=3290=7
10:26:27.032: 656481 - 82 - 1128=935=X34=65648152=20140610-13:26:27.03775=20140610268=1279=0269=022=8207=BVMF48=380963983=254394270=26.05273=62:70:36271=500272=2014061037016=2014061037017=62:70:3637=80531935218288=735290=114
10:26:27.311: 656482 - 119 - 1128=935=X34=65648252=20140610-13:26:27.31575=20140610268=2279=2269=122=8207=BVMF48=380394783=65630273=62:73:15272=2014061037=80531931830289=23290=3279=0269=122=8207=BVMF48=380394783=65631270=17.07273=62:73:15271=100272=2014061037016=2014061037017=62:73:1537=80531935221289=23290=10
10:26:27.330: 656483 - 81 - 1128=935=X34=65648352=20140610-13:26:27.33575=20140610268=1279=0269=022=8207=BVMF48=380963983=254395270=26.32273=62:73:35271=6700272=2014061037016=2014061037017=62:73:3537=80531935222288=16290=53
10:26:27.347: 656484 - 82 - 1128=935=X34=65648452=20140610-13:26:27.35275=20140610268=1279=0269=022=8207=BVMF48=380963983=254396270=26.4273=62:73:51271=5000272=2014061037016=2014061037017=62:73:5137=80531935223288=45290=2
10:26:27.347: 656485 - 119 - 1128=935=X34=65648552=20140610-13:26:27.35275=20140610268=2279=2269=122=8207=BVMF48=380963983=254397273=62:73:51272=2014061037=80531935124289=45290=69279=0269=122=8207=BVMF48=380963983=254398270=26.43273=62:73:51271=5000272=2014061037016=2014061037017=62:73:5137=80531935224289=45290=14
10:26:27.356: 656486 - 81 - 1128=935=X34=65648652=20140610-13:26:27.36175=20140610268=1279=0269=022=8207=BVMF48=380968883=252746270=29.38273=62:73:60271=2100272=2014061037016=2014061037017=62:73:6037=80531935230288=45290=6
10:26:27.356: 656487 - 120 - 1128=935=X34=65648752=20140610-13:26:27.36175=20140610268=2279=2269=022=8207=BVMF48=380968883=252747273=62:73:61272=2014061037=80531935196288=114290=5279=0269=022=8207=BVMF48=380968883=252748270=29.38273=62:73:61271=6500272=2014061037016=2014061037017=62:73:6037=80531935231288=114290=6
10:26:28.008: 656488 - 83 - 1128=935=X34=65648852=20140610-13:26:28.01375=20140610268=1279=0269=122=8207=BVMF48=380391383=106009270=13.85273=62:80:12271=100272=2014061037016=2014061037017=62:80:1237=80531935233289=238290=6
10:26:28.084: 656489 - 72 - 1128=935=X34=65648952=20140610-13:26:28.08975=20140610268=1279=2269=122=8207=BVMF48=380965483=79244273=62:80:89272=2014061037=80531932974289=16290=3
10:26:28.086: 656490 - 81 - 1128=935=X34=65649052=20140610-13:26:28.09075=20140610268=1279=0269=022=8207=BVMF48=380965483=79245270=8.2273=62:80:90271=100272=2014061037016=2014061037017=62:80:9037=80531935235288=8290=2
10:26:28.151: 656491 - 71 - 1128=935=X34=65649152=20140610-13:26:28.15675=20140610268=1279=2269=122=8207=BVMF48=380963983=254399273=62:81:55272=2014061037=80531935183289=8290=13
10:26:28.213: 656492 - 82 - 1128=935=X34=65649252=20140610-13:26:28.21875=20140610268=1279=0269=122=8207=BVMF48=380965483=79246270=8.22273=62:82:18271=200272=2014061037016=2014061037017=62:82:1837=80531935236289=16290=4
10:26:28.615: 656493 - 82 - 1128=935=X34=65649352=20140610-13:26:28.62075=20140610268=1279=0269=122=8207=BVMF48=380968883=252749270=29.4273=62:86:19271=300272=2014061037016=2014061037017=62:86:1937=80531935237289=8290=4
10:26:29.123: 656494 - 71 - 1128=935=X34=65649452=20140610-13:26:29.12875=20140610268=1279=2269=122=8207=BVMF48=380394783=65632273=62:91:27272=2014061037=80531924546289=3290=24
10:26:29.132: 656495 - 70 - 1128=935=X34=65649552=20140610-13:26:29.13775=20140610268=1279=2269=122=8207=BVMF48=380388983=12940273=62:91:36272=2014061037=80531924513289=3290=3
10:26:29.151: 656496 - 81 - 1128=935=X34=65649652=20140610-13:26:29.15675=20140610268=1279=0269=122=8207=BVMF48=380388983=12941270=11.4273=62:91:56271=100272=2014061037016=2014061037017=62:91:5537=80531935245289=8290=2
10:26:29.182: 656497 - 70 - 1128=935=X34=65649752=20140610-13:26:29.18775=20140610268=1279=2269=022=8207=BVMF48=380977983=20180273=62:91:86272=2014061037=80531923367288=3290=3
10:26:29.183: 656498 - 117 - 1128=935=X34=65649852=20140610-13:26:29.18875=20140610268=2279=2269=122=8207=BVMF48=380977983=20181273=62:91:87272=2014061037=80531932540289=8290=5279=0269=122=8207=BVMF48=380977983=20182270=7.39273=62:91:87271=200272=2014061037016=2014061037017=62:91:8737=80531935246289=8290=2
10:26:29.215: 656499 - 69 - 1128=935=X34=65649952=20140610-13:26:29.22075=20140610268=1279=2269=022=8207=BVMF48=380388983=12942273=62:92:19272=2014061037=80531919669288=3290=2
10:26:29.256: 656500 - 80 - 1128=935=X34=65650052=20140610-13:26:29.26175=20140610268=1279=0269=022=8207=BVMF48=380977983=20183270=7.37273=62:92:60271=100272=2014061037016=2014061037017=62:92:6037=80531935248288=8290=5
10:26:29.256: 656501 - 70 - 1128=935=X34=65650152=20140610-13:26:29.26175=20140610268=1279=2269=022=8207=BVMF48=380977983=20184273=62:92:60272=2014061037=80531935248288=8290=5
10:26:29.599: 656502 - 70 - 1128=935=X34=65650252=20140610-13:26:29.60475=20140610268=1279=2269=022=8207=BVMF48=380977983=20185273=62:96:03272=2014061037=80531932538288=8290=4
10:26:30.693: 656503 - 81 - 1128=935=X34=65650352=20140610-13:26:30.69875=20140610268=1279=0269=122=8207=BVMF48=380391383=106010270=13.85273=63:06:97271=100272=2014061037016=2014061037017=63:06:9737=80531935249289=3290=7
10:26:31.497: 656504 - 81 - 1128=935=X34=65650452=20140610-13:26:31.50275=20140610268=1279=0269=022=8207=BVMF48=380391383=106011270=13.84273=63:15:02271=200272=2014061037016=2014061037017=63:15:0137=80531935251288=40290=1
10:26:31.503: 656505 - 120 - 1128=935=X34=65650552=20140610-13:26:31.50775=20140610268=2279=2269=022=8207=BVMF48=380394783=65633273=63:15:06272=2014061037=80531934904288=110290=11279=0269=022=8207=BVMF48=380394783=65634270=16.99273=63:15:06271=100272=2014061037016=2014061037017=63:15:0637=80531935252288=110290=7
10:26:31.503: 656506 - 81 - 1128=935=X34=65650652=20140610-13:26:31.50875=20140610268=1279=0269=022=8207=BVMF48=380968883=252750270=29.38273=63:15:08271=400272=2014061037016=2014061037017=63:15:0837=80531935256288=40290=7
10:26:31.504: 656507 - 81 - 1128=935=X34=65650752=20140610-13:26:31.50975=20140610268=1279=0269=022=8207=BVMF48=380394783=65635270=17.03273=63:15:08271=100272=2014061037016=2014061037017=63:15:0837=80531935257288=40290=1
10:26:31.505: 656508 - 71 - 1128=935=X34=65650852=20140610-13:26:31.51075=20140610268=1279=2269=122=8207=BVMF48=380394783=65636273=63:15:09272=2014061037=80531935129289=8290=4
10:26:31.507: 656509 - 81 - 1128=935=X34=65650952=20140610-13:26:31.51275=20140610268=1279=0269=022=8207=BVMF48=380249383=103279270=9.33273=63:15:12271=200272=2014061037016=2014061037017=63:15:1237=80531935258288=40290=1
10:26:31.508: 656510 - 71 - 1128=935=X34=65651052=20140610-13:26:31.51475=20140610268=1279=2269=122=8207=BVMF48=380249383=103280273=63:15:13272=2014061037=80531934368289=8290=5
10:26:31.509: 656511 - 81 - 1128=935=X34=65651152=20140610-13:26:31.51475=20140610268=1279=0269=022=8207=BVMF48=380965483=79247270=8.21273=63:15:13271=100272=2014061037016=2014061037017=63:15:1337=80531935259288=40290=1
10:26:31.510: 656512 - 70 - 1128=935=X34=65651252=20140610-13:26:31.51575=20140610268=1279=2269=022=8207=BVMF48=380965483=79248273=63:15:14272=2014061037=80531935235288=8290=3
10:26:31.510: 656513 - 70 - 1128=935=X34=65651352=20140610-13:26:31.51575=20140610268=1279=2269=022=8207=BVMF48=380965483=79249273=63:15:14272=2014061037=80531932292288=8290=27
10:26:31.510: 656514 - 81 - 1128=935=X34=65651452=20140610-13:26:31.51575=20140610268=1279=0269=022=8207=BVMF48=380965483=79250270=8.2273=63:15:15271=500272=2014061037016=2014061037017=63:15:1437=80531935260288=8290=3
10:26:31.512: 656515 - 82 - 1128=935=X34=65651552=20140610-13:26:31.51775=20140610268=1279=0269=022=8207=BVMF48=380963983=254400270=26.4273=63:15:16271=600272=2014061037016=2014061037017=63:15:1637=80531935270288=40290=3
10:26:31.527: 656516 - 119 - 1128=935=X34=65651652=20140610-13:26:31.53275=20140610268=2279=2269=022=8207=BVMF48=380963983=254401273=63:15:31272=2014061037=80531934855288=45290=7279=0269=022=8207=BVMF48=380963983=254402270=26.4273=63:15:31271=600272=2014061037016=2014061037017=63:15:3137=80531935349288=45290=4
10:26:31.533: 656517 - 120 - 1128=935=X34=65651752=20140610-13:26:31.53875=20140610268=2279=2269=022=8207=BVMF48=380968883=252751273=63:15:37272=2014061037=80531935231288=114290=6279=0269=022=8207=BVMF48=380968883=252752270=29.38273=63:15:37271=7100272=2014061037016=2014061037017=63:15:3737=80531935350288=114290=7
10:26:31.539: 656518 - 72 - 1128=935=X34=65651852=20140610-13:26:31.54475=20140610268=1279=2269=022=8207=BVMF48=380394783=65637273=63:15:43272=2014061037=80531935252288=110290=8
10:26:31.551: 656519 - 120 - 1128=935=X34=65651952=20140610-13:26:31.55675=20140610268=2279=2269=022=8207=BVMF48=380968883=252753273=63:15:56272=2014061037=80531935350288=114290=7279=0269=022=8207=BVMF48=380968883=252754270=29.38273=63:15:56271=7600272=2014061037016=2014061037017=63:15:5637=80531935351288=114290=7
10:26:31.560: 656520 - 81 - 1128=935=X34=65652052=20140610-13:26:31.56575=20140610268=1279=0269=022=8207=BVMF48=380391383=106012270=13.84273=63:15:65271=300272=2014061037016=2014061037017=63:15:6537=80531935352288=40290=2
10:26:31.568: 656521 - 70 - 1128=935=X34=65652152=20140610-13:26:31.57375=20140610268=1279=2269=022=8207=BVMF48=380391383=106013273=63:15:73272=2014061037=80531935171288=8290=35
10:26:31.571: 656522 - 70 - 1128=935=X34=65652252=20140610-13:26:31.57675=20140610268=1279=2269=022=8207=BVMF48=380249383=103281273=63:15:75272=2014061037=80531927628288=3290=45
10:26:31.572: 656523 - 117 - 1128=935=X34=65652352=20140610-13:26:31.57775=20140610268=2279=2269=122=8207=BVMF48=380391383=106014273=63:15:77272=2014061037=80531935143289=3290=4279=0269=122=8207=BVMF48=380391383=106015270=13.86273=63:15:77271=1300272=2014061037016=2014061037017=63:15:7737=80531935355289=3290=9
10:26:31.576: 656524 - 82 - 1128=935=X34=65652452=20140610-13:26:31.58275=20140610268=1279=0269=022=8207=BVMF48=380963983=254403270=26.4273=63:15:81271=500272=2014061037016=2014061037017=63:15:8137=80531935356288=40290=5
10:26:31.579: 656525 - 81 - 1128=935=X34=65652552=20140610-13:26:31.58475=20140610268=1279=0269=022=8207=BVMF48=380968883=252755270=29.38273=63:15:83271=400272=2014061037016=2014061037017=63:15:8337=80531935357288=40290=8
10:26:31.584: 656526 - 81 - 1128=935=X34=65652652=20140610-13:26:31.58975=20140610268=1279=0269=022=8207=BVMF48=380394783=65638270=17.03273=63:15:88271=100272=2014061037016=2014061037017=63:15:8837=80531935361288=40290=2
10:26:31.586: 656527 - 120 - 1128=935=X34=65652752=20140610-13:26:31.59175=20140610268=2279=2269=022=8207=BVMF48=380968883=252756273=63:15:90272=2014061037=80531935351288=114290=7279=0269=022=8207=BVMF48=380968883=252757270=29.38273=63:15:90271=8100272=2014061037016=2014061037017=63:15:9037=80531935362288=114290=8
10:26:31.595: 656528 - 81 - 1128=935=X34=65652852=20140610-13:26:31.60075=20140610268=1279=0269=022=8207=BVMF48=380965483=79251270=8.21273=63:15:99271=100272=2014061037016=2014061037017=63:15:9937=80531935363288=40290=2
10:26:31.596: 656529 - 81 - 1128=935=X34=65652952=20140610-13:26:31.60175=20140610268=1279=0269=022=8207=BVMF48=380249383=103282270=9.33273=63:16:01271=200272=2014061037016=2014061037017=63:16:0037=80531935364288=40290=2
10:26:31.599: 656530 - 71 - 1128=935=X34=65653052=20140610-13:26:31.60475=20140610268=1279=2269=122=8207=BVMF48=380391383=106016273=63:16:03272=2014061037=80531935213289=8290=4
10:26:31.599: 656531 - 71 - 1128=935=X34=65653152=20140610-13:26:31.60475=20140610268=1279=2269=122=8207=BVMF48=380394783=65639273=63:16:03272=2014061037=80531935128289=8290=3
10:26:31.620: 656532 - 79 - 1128=935=X34=65653252=20140610-13:26:31.62475=20140610268=1279=0269=022=8207=BVMF48=389774183=6736270=13.81273=63:16:24271=11272=2014061037016=2014061037017=63:16:2437=80531935368288=82290=2
10:26:31.628: 656533 - 115 - 1128=935=X34=65653352=20140610-13:26:31.63375=20140610268=2279=2269=022=8207=BVMF48=390102283=3999273=63:16:33272=2014061037=80531931011288=3290=1279=0269=022=8207=BVMF48=390102283=4000270=17.02273=63:16:33271=96272=2014061037016=2014061037017=63:16:3237=80531935369288=3290=1
10:26:31.637: 656534 - 80 - 1128=935=X34=65653452=20140610-13:26:31.64275=20140610268=1279=0269=022=8207=BVMF48=380391383=106017270=13.78273=63:16:41271=100272=2014061037016=2014061037017=63:16:4137=80531935370288=8290=35
10:26:31.668: 656535 - 116 - 1128=935=X34=65653552=20140610-13:26:31.67375=20140610268=2279=2269=022=8207=BVMF48=399729383=2264273=63:16:72272=2014061037=80531932628288=3290=2279=0269=022=8207=BVMF48=399729383=2265270=8.2273=63:16:72271=96272=2014061037016=2014061037017=63:16:7237=80531935371288=3290=1
10:26:31.670: 656536 - 71 - 1128=935=X34=65653652=20140610-13:26:31.67575=20140610268=1279=2269=022=8207=BVMF48=380249383=103283273=63:16:74272=2014061037=80531930937288=40290=41
10:26:31.672: 656537 - 71 - 1128=935=X34=65653752=20140610-13:26:31.67775=20140610268=1279=2269=022=8207=BVMF48=380249383=103284273=63:16:76272=2014061037=80531930936288=40290=34
10:26:31.694: 656538 - 70 - 1128=935=X34=65653852=20140610-13:26:31.69975=20140610268=1279=2269=022=8207=BVMF48=380391383=106018273=63:16:98272=2014061037=80531935370288=8290=35
10:26:31.710: 656539 - 80 - 1128=935=X34=65653952=20140610-13:26:31.71575=20140610268=1279=0269=022=8207=BVMF48=380391383=106019270=13.78273=63:17:14271=200272=2014061037016=2014061037017=63:17:1437=80531935372288=8290=35
10:26:31.797: 656540 - 71 - 1128=935=X34=65654052=20140610-13:26:31.80375=20140610268=1279=2269=122=8207=BVMF48=380963983=254404273=63:18:02272=2014061037=80531934182289=3290=11
10:26:31.798: 656541 - 71 - 1128=935=X34=65654152=20140610-13:26:31.80375=20140610268=1279=2269=122=8207=BVMF48=380968883=252758273=63:18:03272=2014061037=80531933337289=3290=6
10:26:31.804: 656542 - 71 - 1128=935=X34=65654252=20140610-13:26:31.80975=20140610268=1279=2269=022=8207=BVMF48=380391383=106020273=63:18:09272=2014061037=80531935352288=40290=2
10:26:31.806: 656543 - 71 - 1128=935=X34=65654352=20140610-13:26:31.81175=20140610268=1279=2269=022=8207=BVMF48=380963983=254405273=63:18:11272=2014061037=80531935356288=40290=5
10:26:31.806: 656544 - 71 - 1128=935=X34=65654452=20140610-13:26:31.81175=20140610268=1279=2269=022=8207=BVMF48=380968883=252759273=63:18:11272=2014061037=80531935357288=40290=7
10:26:31.808: 656545 - 71 - 1128=935=X34=65654552=20140610-13:26:31.81375=20140610268=1279=2269=022=8207=BVMF48=380394783=65640273=63:18:13272=2014061037=80531935361288=40290=2
10:26:31.809: 656546 - 71 - 1128=935=X34=65654652=20140610-13:26:31.81475=20140610268=1279=2269=022=8207=BVMF48=380249383=103285273=63:18:13272=2014061037=80531935364288=40290=2
10:26:31.810: 656547 - 71 - 1128=935=X34=65654752=20140610-13:26:31.81675=20140610268=1279=2269=022=8207=BVMF48=380965483=79252273=63:18:15272=2014061037=80531935363288=40290=2
10:26:31.816: 656548 - 81 - 1128=935=X34=65654852=20140610-13:26:31.82275=20140610268=1279=1269=022=8207=BVMF48=380968883=252760270=29.38273=63:18:21271=7600272=2014061037016=2014061037017=63:15:9037=80531935373288=114290=7
10:26:31.821: 656549 - 81 - 1128=935=X34=65654952=20140610-13:26:31.82675=20140610268=1279=0269=022=8207=BVMF48=380249383=103286270=9.28273=63:18:25271=8000272=2014061037016=2014061037017=63:18:2537=80531935374288=40290=26
10:26:31.824: 656550 - 81 - 1128=935=X34=65655052=20140610-13:26:31.82975=20140610268=1279=0269=022=8207=BVMF48=380249383=103287270=9.26273=63:18:29271=4600272=2014061037016=2014061037017=63:18:2937=80531935375288=40290=34
10:26:31.862: 656551 - 70 - 1128=935=X34=65655152=20140610-13:26:31.86775=20140610268=1279=2269=022=8207=BVMF48=380391383=106021273=63:18:67272=2014061037=80531935372288=8290=34
10:26:31.874: 656552 - 80 - 1128=935=X34=65655252=20140610-13:26:31.87975=20140610268=1279=0269=022=8207=BVMF48=380391383=106022270=13.78273=63:18:78271=100272=2014061037016=2014061037017=63:18:7837=80531935376288=8290=34
10:26:31.928: 656553 - 82 - 1128=935=X34=65655352=20140610-13:26:31.93375=20140610268=1279=0269=022=8207=BVMF48=380963983=254406270=26.34273=63:19:32271=500272=2014061037016=2014061037017=63:19:3237=80531935377288=735290=43
10:26:31.936: 656554 - 118 - 1128=935=X34=65655452=20140610-13:26:31.94175=20140610268=2279=2269=022=8207=BVMF48=380249383=103288273=63:19:40272=2014061037=80531931659288=40290=4279=0269=022=8207=BVMF48=380249383=103289270=9.33273=63:19:40271=100272=2014061037016=2014061037017=63:19:4037=80531935378288=40290=2
10:26:31.939: 656555 - 115 - 1128=935=X34=65655552=20140610-13:26:31.94375=20140610268=2279=2269=022=8207=BVMF48=389774183=6737273=63:19:43272=2014061037=80531931007288=3290=3279=0269=022=8207=BVMF48=389774183=6738270=13.82273=63:19:43271=96272=2014061037016=2014061037017=63:19:4337=80531935379288=3290=2
10:26:31.971: 656556 - 118 - 1128=935=X34=65655652=20140610-13:26:31.97675=20140610268=2279=2269=022=8207=BVMF48=380249383=103290273=63:19:75272=2014061037=80531931658288=40290=4279=0269=022=8207=BVMF48=380249383=103291270=9.33273=63:19:75271=100272=2014061037016=2014061037017=63:19:7537=80531935380288=40290=3
10:26:32.069: 656557 - 78 - 1128=935=X34=65655752=20140610-13:26:32.07475=20140610268=1279=0269=022=8207=BVMF48=400223483=5852270=26.39273=63:20:74271=1272=2014061037016=2014061037017=63:20:7337=80531935381288=3290=1
10:26:32.150: 656558 - 71 - 1128=935=X34=65655852=20140610-13:26:32.15575=20140610268=1279=2269=122=8207=BVMF48=380249383=103292273=63:21:55272=2014061037=80531931883289=8290=10
10:26:32.511: 656559 - 70 - 1128=935=X34=65655952=20140610-13:26:32.51675=20140610268=1279=2269=022=8207=BVMF48=380965483=79253273=63:25:16272=2014061037=80531934739288=8290=2
10:26:32.516: 656560 - 81 - 1128=935=X34=65656052=20140610-13:26:32.52175=20140610268=1279=0269=122=8207=BVMF48=380965483=79254270=8.23273=63:25:20271=900272=2014061037016=2014061037017=63:25:2037=80531935384289=3290=7
10:26:32.802: 656561 - 80 - 1128=935=X34=65656152=20140610-13:26:32.80775=20140610268=1279=0269=122=8207=BVMF48=380566083=11389270=2.48273=63:28:06271=1000272=2014061037016=2014061037017=63:28:0637=80531935406289=9290=2
10:26:32.920: 656562 - 118 - 1128=935=X34=65656252=20140610-13:26:32.92575=20140610268=2279=2269=122=8207=BVMF48=380566083=11390273=63:29:24272=2014061037=80531926468289=85290=4279=0269=122=8207=BVMF48=380566083=11391270=2.48273=63:29:24271=600272=2014061037016=2014061037017=63:29:2437=80531935408289=85290=3
10:26:32.920: 656563 - 71 - 1128=935=X34=65656352=20140610-13:26:32.92575=20140610268=1279=2269=122=8207=BVMF48=380566083=11392273=63:29:25272=2014061037=80531926477289=85290=5
10:26:32.956: 656564 - 81 - 1128=935=X34=65656452=20140610-13:26:32.96175=20140610268=1279=0269=022=8207=BVMF48=380249383=103293270=9.27273=63:29:60271=3000272=2014061037016=2014061037017=63:29:6037=80531935409288=21290=29
10:26:33.077: 656565 - 81 - 1128=935=X34=65656552=20140610-13:26:33.08275=20140610268=1279=0269=122=8207=BVMF48=380566083=11393270=2.49273=63:30:81271=5000272=2014061037016=2014061037017=63:30:8137=80531935412289=85290=5
10:26:33.512: 656566 - 80 - 1128=935=X34=65656652=20140610-13:26:33.51775=20140610268=1279=0269=022=8207=BVMF48=380965483=79255270=8.21273=63:35:17271=6300272=2014061037016=2014061037017=63:35:1737=80531935415288=8290=2
10:26:33.514: 656567 - 71 - 1128=935=X34=65656752=20140610-13:26:33.51975=20140610268=1279=2269=122=8207=BVMF48=380965483=79256273=63:35:18272=2014061037=80531932359289=8290=2
10:26:33.530: 656568 - 79 - 1128=935=X34=65656852=20140610-13:26:33.53575=20140610268=1279=0269=022=8207=BVMF48=400223483=5853270=25273=63:35:34271=1272=2014061037016=2014061037017=63:35:3437=80531935465288=29290=84
10:26:33.798: 656569 - 81 - 1128=935=X34=65656952=20140610-13:26:33.80375=20140610268=1279=0269=122=8207=BVMF48=380965483=79257270=8.37273=63:38:03271=500272=2014061037016=2014061037017=63:38:0337=80531935468289=8290=81
10:26:34.025: 656570 - 154 - 1128=935=X34=65657052=20140610-13:26:34.03075=20140610268=3279=0269=222=8207=BVMF48=380968883=252761270=29.38273=63:40:29271=100272=2014061037016=2014061037017=63:40:291500=E451=-0.251020=374700274=21003=5590288=8289=3279=0269=922=8207=BVMF48=380968883=252762270=29.495273=63:40:29272=201406101500=E279=1269=022=8207=BVMF48=380968883=252763270=29.38273=63:40:29271=200272=2014061037016=2014061037017=61:21:2037=80531934030288=8290=1
10:26:34.195: 656571 - 194 - 1128=935=X34=65657152=20140610-13:26:34.20075=20140610268=4279=0269=222=8207=BVMF48=380968883=252764270=29.39273=63:41:99271=4600272=2014061037016=2014061037017=63:41:991500=E451=-0.241020=379300274=01003=5600288=45289=45279=0269=922=8207=BVMF48=380968883=252765270=29.494273=63:41:99272=201406101500=E279=2269=122=8207=BVMF48=380968883=252766273=63:41:99272=2014061037=80531934980289=45290=1279=0269=122=8207=BVMF48=380968883=252767270=29.39273=63:41:99271=5000272=2014061037016=2014061037017=63:41:9937=80531935471289=45290=1
10:26:34.196: 656572 - 82 - 1128=935=X34=65657252=20140610-13:26:34.20175=20140610268=1279=0269=122=8207=BVMF48=380968883=252768270=29.4273=63:42:01271=100272=2014061037016=2014061037017=63:42:0037=80531935472289=8290=5
10:26:34.199: 656573 - 71 - 1128=935=X34=65657352=20140610-13:26:34.20375=20140610268=1279=2269=122=8207=BVMF48=380968883=252769273=63:42:03272=2014061037=80531930564289=8290=9
10:26:34.202: 656574 - 119 - 1128=935=X34=65657452=20140610-13:26:34.20775=20140610268=2279=2269=122=8207=BVMF48=380963983=254407273=63:42:07272=2014061037=80531935059289=45290=2279=0269=122=8207=BVMF48=380963983=254408270=26.42273=63:42:07271=1500272=2014061037016=2014061037017=63:42:0737=80531935473289=45290=9
10:26:34.203: 656575 - 119 - 1128=935=X34=65657552=20140610-13:26:34.20875=20140610268=2279=2269=122=8207=BVMF48=380963983=254409273=63:42:07272=2014061037=80531935038289=45290=1279=0269=122=8207=BVMF48=380963983=254410270=26.42273=63:42:07271=3500272=2014061037016=2014061037017=63:42:0737=80531935474289=45290=9
10:26:34.203: 656576 - 73 - 1128=935=X34=65657652=20140610-13:26:34.20875=20140610268=1279=2269=122=8207=BVMF48=380963983=254411273=63:42:08272=2014061037=80531935060289=114290=1
10:26:34.204: 656577 - 71 - 1128=935=X34=65657752=20140610-13:26:34.20975=20140610268=1279=2269=122=8207=BVMF48=380968883=252770273=63:42:09272=2014061037=80531935237289=8290=4
10:26:34.205: 656578 - 72 - 1128=935=X34=65657852=20140610-13:26:34.21075=20140610268=1279=2269=122=8207=BVMF48=380963983=254412273=63:42:09272=2014061037=80531935120289=45290=10
10:26:34.206: 656579 - 356 - 1128=935=X34=65657952=20140610-13:26:34.21175=20140610268=9279=0269=222=8207=BVMF48=380963983=254413270=26.41273=63:42:10271=100272=2014061037016=2014061037017=63:42:091500=E451=-0.21020=1290000274=01003=17270288=45289=40279=0269=922=8207=BVMF48=380963983=254414270=26.475273=63:42:10272=201406101500=E279=0269=222=8207=BVMF48=380963983=254415270=26.41273=63:42:10271=200272=2014061037016=2014061037017=63:42:091500=E451=-0.21020=1290200274=1277=L1003=17280288=45289=77279=0269=922=8207=BVMF48=380963983=254416270=26.475273=63:42:10272=201406101500=E279=0269=222=8207=BVMF48=380963983=254417270=26.41273=63:42:10271=200272=2014061037016=2014061037017=63:42:091500=E451=-0.21020=1290400274=1277=L1003=17290288=45289=238279=0269=922=8207=BVMF48=380963983=254418270=26.475273=63:42:10272=201406101500=E279=0269=222=8207=BVMF48=380963983=254419270=26.41273=63:42:10271=500272=2014061037016=2014061037017=63:42:091500=E451=-0.21020=1290900274=1277=L1003=17300288=45289=3279=0269=922=8207=BVMF48=380963983=254420270=26.475273=63:42:10272=201406101500=E279=4269=122=8207=BVMF48=380963983=254421273=63:42:10272=20140610290=4
10:26:34.206: 656580 - 119 - 1128=935=X34=65658052=20140610-13:26:34.21175=20140610268=2279=2269=022=8207=BVMF48=380963983=254422273=63:42:10272=2014061037=80531935126288=45290=69279=0269=022=8207=BVMF48=380963983=254423270=26.4273=63:42:10271=3000272=2014061037016=2014061037017=63:42:1037=80531935478288=45290=5
10:26:34.206: 656581 - 118 - 1128=935=X34=65658152=20140610-13:26:34.21175=20140610268=2279=2269=022=8207=BVMF48=380968883=252771273=63:42:11272=2014061037=80531935201288=45290=23279=0269=022=8207=BVMF48=380968883=252772270=29.36273=63:42:11271=2000272=2014061037016=2014061037017=63:42:1037=80531935479288=45290=12
10:26:34.209: 656582 - 119 - 1128=935=X34=65658252=20140610-13:26:34.21475=20140610268=2279=2269=122=8207=BVMF48=380963983=254424273=63:42:14272=2014061037=80531935473289=45290=3279=0269=122=8207=BVMF48=380963983=254425270=26.41273=63:42:14271=1500272=2014061037016=2014061037017=63:42:1337=80531935482289=45290=1
10:26:34.210: 656583 - 119 - 1128=935=X34=65658352=20140610-13:26:34.21475=20140610268=2279=2269=122=8207=BVMF48=380963983=254426273=63:42:14272=2014061037=80531935474289=45290=4279=0269=122=8207=BVMF48=380963983=254427270=26.41273=63:42:14271=3500272=2014061037016=2014061037017=63:42:1437=80531935483289=45290=2
10:26:34.210: 656584 - 83 - 1128=935=X34=65658452=20140610-13:26:34.21575=20140610268=1279=0269=122=8207=BVMF48=380963983=254428270=26.41273=63:42:14271=5500272=2014061037016=2014061037017=63:42:1437=80531935485289=114290=3
10:26:34.216: 656585 - 71 - 1128=935=X34=65658552=20140610-13:26:34.22175=20140610268=1279=2269=022=8207=BVMF48=380963983=254429273=63:42:20272=2014061037=80531935478288=45290=5
10:26:34.228: 656586 - 71 - 1128=935=X34=65658652=20140610-13:26:34.23375=20140610268=1279=2269=022=8207=BVMF48=380963983=254430273=63:42:33272=2014061037=80531935223288=45290=2
10:26:34.228: 656587 - 72 - 1128=935=X34=65658752=20140610-13:26:34.23375=20140610268=1279=2269=122=8207=BVMF48=380963983=254431273=63:42:33272=2014061037=80531935224289=45290=7
10:26:34.228: 656588 - 72 - 1128=935=X34=65658852=20140610-13:26:34.23375=20140610268=1279=2269=122=8207=BVMF48=380963983=254432273=63:42:33272=2014061037=80531926337289=45290=9
10:26:34.234: 656589 - 119 - 1128=935=X34=65658952=20140610-13:26:34.23975=20140610268=2279=2269=122=8207=BVMF48=380963983=254433273=63:42:38272=2014061037=80531935056289=40290=5279=0269=122=8207=BVMF48=380963983=254434270=26.41273=63:42:38271=900272=2014061037016=2014061037017=63:42:3837=80531935558289=40290=4
10:26:34.234: 656590 - 121 - 1128=935=X34=65659052=20140610-13:26:34.23975=20140610268=2279=2269=022=8207=BVMF48=380968883=252773273=63:42:39272=2014061037=80531935373288=114290=7279=0269=022=8207=BVMF48=380968883=252774270=29.38273=63:42:39271=10300272=2014061037016=2014061037017=63:42:3837=80531935560288=114290=7
10:26:34.238: 656591 - 81 - 1128=935=X34=65659152=20140610-13:26:34.24375=20140610268=1279=1269=022=8207=BVMF48=380968883=252775270=29.38273=63:42:43271=7600272=2014061037016=2014061037017=63:42:3837=80531935570288=114290=7
10:26:34.251: 656592 - 80 - 1128=935=X34=65659252=20140610-13:26:34.25675=20140610268=1279=1269=022=8207=BVMF48=380968883=252776270=29.38273=63:42:55271=1100272=2014061037016=2014061037017=62:73:6037=80531935586288=45290=5
10:26:34.251: 656593 - 81 - 1128=935=X34=65659352=20140610-13:26:34.25675=20140610268=1279=1269=022=8207=BVMF48=380968883=252777270=29.38273=63:42:56271=3100272=2014061037016=2014061037017=63:42:3837=80531935587288=114290=7
10:26:34.254: 656594 - 72 - 1128=935=X34=65659452=20140610-13:26:34.26075=20140610268=1279=2269=122=8207=BVMF48=380963983=254435273=63:42:59272=2014061037=80531935558289=40290=4
10:26:34.357: 656595 - 82 - 1128=935=X34=65659552=20140610-13:26:34.36275=20140610268=1279=0269=122=8207=BVMF48=380963983=254436270=26.41273=63:43:62271=300272=2014061037016=2014061037017=63:43:6237=80531935600289=40290=4
10:26:34.391: 656596 - 71 - 1128=935=X34=65659652=20140610-13:26:34.39775=20140610268=1279=2269=022=8207=BVMF48=380968883=252778273=63:43:96272=2014061037=80531935479288=45290=12
10:26:34.392: 656597 - 119 - 1128=935=X34=65659752=20140610-13:26:34.39775=20140610268=2279=2269=122=8207=BVMF48=380968883=252779273=63:43:96272=2014061037=80531934361289=45290=36279=0269=122=8207=BVMF48=380968883=252780270=29.48273=63:43:96271=2000272=2014061037016=2014061037017=63:43:9637=80531935603289=45290=28
10:26:34.406: 656598 - 82 - 1128=935=X34=65659852=20140610-13:26:34.41175=20140610268=1279=0269=122=8207=BVMF48=380963983=254437270=26.43273=63:44:10271=3000272=2014061037016=2014061037017=63:44:1037=80531935604289=45290=7
10:26:34.411: 656599 - 82 - 1128=935=X34=65659952=20140610-13:26:34.41775=20140610268=1279=0269=022=8207=BVMF48=380963983=254438270=26.3273=63:44:16271=3000272=2014061037016=2014061037017=63:44:1637=80531935605288=45290=68
10:26:34.430: 656600 - 82 - 1128=935=X34=65660052=20140610-13:26:34.43575=20140610268=1279=0269=022=8207=BVMF48=380963983=254439270=26.4273=63:44:34271=5000272=2014061037016=2014061037017=63:44:3437=80531935606288=45290=4
10:26:34.430: 656601 - 82 - 1128=935=X34=65660152=20140610-13:26:34.43575=20140610268=1279=0269=122=8207=BVMF48=380963983=254440270=26.43273=63:44:34271=5000272=2014061037016=2014061037017=63:44:3437=80531935607289=45290=8
10:26:34.430: 656602 - 82 - 1128=935=X34=65660252=20140610-13:26:34.43575=20140610268=1279=0269=122=8207=BVMF48=380963983=254441270=26.44273=63:44:35271=5000272=2014061037016=2014061037017=63:44:3437=80531935608289=45290=15
10:26:34.437: 656603 - 118 - 1128=935=X34=65660352=20140610-13:26:34.44275=20140610268=2279=2269=022=8207=BVMF48=380968883=252781273=63:44:42272=2014061037=80531935586288=45290=5279=0269=022=8207=BVMF48=380968883=252782270=29.38273=63:44:42271=2100272=2014061037016=2014061037017=63:44:4237=80531935612288=45290=7
10:26:34.437: 656604 - 120 - 1128=935=X34=65660452=20140610-13:26:34.44375=20140610268=2279=2269=022=8207=BVMF48=380968883=252783273=63:44:42272=2014061037=80531935587288=114290=6279=0269=022=8207=BVMF48=380968883=252784270=29.38273=63:44:42271=7600272=2014061037016=2014061037017=63:44:4237=80531935613288=114290=7
10:26:34.592: 656605 - 81 - 1128=935=X34=65660552=20140610-13:26:34.59775=20140610268=1279=0269=022=8207=BVMF48=380968883=252785270=29.33273=63:45:97271=2000272=2014061037016=2014061037017=63:45:9737=80531935616288=45290=23
10:26:34.767: 656606 - 82 - 1128=935=X34=65660652=20140610-13:26:34.77275=20140610268=1279=0269=122=8207=BVMF48=380249383=103294270=9.34273=63:47:71271=400272=2014061037016=2014061037017=63:47:7137=80531935618289=70290=6
10:26:34.768: 656607 - 81 - 1128=935=X34=65660752=20140610-13:26:34.77375=20140610268=1279=0269=122=8207=BVMF48=380249383=103295270=9.35273=63:47:73271=100272=2014061037016=2014061037017=63:47:7237=80531935619289=8290=11
10:26:35.195: 656608 - 118 - 1128=935=X34=65660852=20140610-13:26:35.20175=20140610268=2279=2269=022=8207=BVMF48=380391383=106023273=63:52:00272=2014061037=80531932140288=40290=13279=0269=022=8207=BVMF48=380391383=106024270=13.84273=63:52:00271=100272=2014061037016=2014061037017=63:52:0037=80531935622288=40290=2
10:26:35.356: 656609 - 70 - 1128=935=X34=65660952=20140610-13:26:35.36175=20140610268=1279=2269=022=8207=BVMF48=380394783=65641273=63:53:60272=2014061037=80531935169288=8290=4
10:26:35.378: 656610 - 80 - 1128=935=X34=65661052=20140610-13:26:35.38375=20140610268=1279=0269=022=8207=BVMF48=380394783=65642270=17.03273=63:53:83271=400272=2014061037016=2014061037017=63:53:8237=80531935624288=8290=2
10:26:35.391: 656611 - 70 - 1128=935=X34=65661152=20140610-13:26:35.39675=20140610268=1279=2269=022=8207=BVMF48=380391383=106025273=63:53:96272=2014061037=80531935376288=8290=34
10:26:35.402: 656612 - 80 - 1128=935=X34=65661252=20140610-13:26:35.40775=20140610268=1279=0269=022=8207=BVMF48=380391383=106026270=13.78273=63:54:07271=600272=2014061037016=2014061037017=63:54:0637=80531935625288=8290=34
10:26:35.587: 656613 - 81 - 1128=935=X34=65661352=20140610-13:26:35.59375=20140610268=1279=0269=022=8207=BVMF48=380249383=103296270=9.33273=63:55:92271=100272=2014061037016=2014061037017=63:55:9237=80531935632288=40290=4
10:26:35.768: 656614 - 82 - 1128=935=X34=65661452=20140610-13:26:35.77375=20140610268=1279=0269=122=8207=BVMF48=380968883=252786270=29.4273=63:57:73271=300272=2014061037016=2014061037017=63:57:7337=80531935634289=8290=5
10:26:35.983: 656615 - 81 - 1128=935=X34=65661552=20140610-13:26:35.98875=20140610268=1279=0269=122=8207=BVMF48=380963983=254442270=26.41273=63:59:87271=1000272=2014061037016=2014061037017=63:59:8737=80531935637289=3290=5
10:26:35.986: 656616 - 80 - 1128=935=X34=65661652=20140610-13:26:35.99175=20140610268=1279=0269=022=8207=BVMF48=380968883=252787270=29.38273=63:59:91271=900272=2014061037016=2014061037017=63:59:9137=80531935638288=3290=8
10:26:36.286: 656617 - 161 - 1128=935=X34=65661752=20140610-13:26:36.29175=20140610268=3279=0269=222=8207=BVMF48=380963983=254443270=26.4273=63:62:91271=2000272=2014061037016=2014061037017=63:62:901500=E451=-0.211020=1292900274=21003=17310288=77289=21279=0269=922=8207=BVMF48=380963983=254444270=26.475273=63:62:91272=201406101500=E279=1269=022=8207=BVMF48=380963983=254445270=26.4273=63:62:91271=200272=2014061037016=2014061037017=61:40:2637=80531934666288=77290=1
10:26:36.294: 656618 - 81 - 1128=935=X34=65661852=20140610-13:26:36.29975=20140610268=1279=1269=022=8207=BVMF48=380968883=252788270=29.38273=63:62:99271=5800272=2014061037016=2014061037017=63:44:4237=80531935641288=114290=7
10:26:36.463: 656619 - 270 - 1128=935=X34=65661952=20140610-13:26:36.46875=20140610268=6279=0269=222=8207=BVMF48=380963983=254446270=26.41273=63:64:68271=1500272=2014061037016=2014061037017=63:64:671500=E451=-0.21020=1294400274=01003=17320288=39289=45279=0269=922=8207=BVMF48=380963983=254447270=26.475273=63:64:68272=201406101500=E279=0269=222=8207=BVMF48=380963983=254448270=26.41273=63:64:68271=500272=2014061037016=2014061037017=63:64:671500=E451=-0.21020=1294900274=1277=L1003=17330288=39289=45279=0269=922=8207=BVMF48=380963983=254449270=26.475273=63:64:68272=201406101500=E279=2269=122=8207=BVMF48=380963983=254450273=63:64:68272=2014061037=80531935482289=45290=1279=1269=122=8207=BVMF48=380963983=254451270=26.41273=63:64:68271=3000272=2014061037016=2014061037017=63:42:1437=80531935483289=45290=1
10:26:36.467: 656620 - 71 - 1128=935=X34=65662052=20140610-13:26:36.47375=20140610268=1279=2269=022=8207=BVMF48=380968883=252789273=63:64:72272=2014061037=80531935612288=45290=6
10:26:36.469: 656621 - 197 - 1128=935=X34=65662152=20140610-13:26:36.47475=20140610268=4279=0269=222=8207=BVMF48=380968883=252790270=29.39273=63:64:73271=1400272=2014061037016=2014061037017=63:64:731500=E451=-0.241020=380700274=1277=L1003=5610288=45289=45279=0269=922=8207=BVMF48=380968883=252791270=29.494273=63:64:73272=201406101500=E279=1269=122=8207=BVMF48=380968883=252792270=29.39273=63:64:73271=3600272=2014061037016=2014061037017=63:41:9937=80531935471289=45290=1279=2269=022=8207=BVMF48=380968883=252793273=63:64:73272=2014061037=80531935195288=45290=4
10:26:36.469: 656622 - 72 - 1128=935=X34=65662252=20140610-13:26:36.47475=20140610268=1279=2269=122=8207=BVMF48=380963983=254452273=63:64:74272=2014061037=80531935483289=45290=1
10:26:36.472: 656623 - 157 - 1128=935=X34=65662352=20140610-13:26:36.47875=20140610268=3279=0269=222=8207=BVMF48=380968883=252794270=29.39273=63:64:77271=400272=2014061037016=2014061037017=63:64:771500=E451=-0.241020=381100274=1277=L1003=5620288=45289=45279=0269=922=8207=BVMF48=380968883=252795270=29.494273=63:64:77272=201406101500=E279=1269=122=8207=BVMF48=380968883=252796270=29.39273=63:64:77271=3200272=2014061037016=2014061037017=63:41:9937=80531935471289=45290=1
10:26:36.478: 656624 - 81 - 1128=935=X34=65662452=20140610-13:26:36.48375=20140610268=1279=0269=022=8207=BVMF48=380968883=252797270=29.38273=63:64:82271=4000272=2014061037016=2014061037017=63:64:8237=80531935645288=45290=7
10:26:36.478: 656625 - 82 - 1128=935=X34=65662552=20140610-13:26:36.48375=20140610268=1279=0269=122=8207=BVMF48=380963983=254453270=26.41273=63:64:83271=5000272=2014061037016=2014061037017=63:64:8237=80531935646289=45290=4
10:26:36.485: 656626 - 81 - 1128=935=X34=65662652=20140610-13:26:36.49075=20140610268=1279=1269=122=8207=BVMF48=380963983=254454270=26.41273=63:64:89271=4000272=2014061037016=2014061037017=63:64:8237=80531935648289=45290=4
10:26:36.485: 656627 - 82 - 1128=935=X34=65662752=20140610-13:26:36.49075=20140610268=1279=1269=122=8207=BVMF48=380963983=254455270=26.41273=63:64:90271=3900272=2014061037016=2014061037017=63:42:1437=80531935649289=114290=1
10:26:36.490: 656628 - 81 - 1128=935=X34=65662852=20140610-13:26:36.49575=20140610268=1279=1269=122=8207=BVMF48=380963983=254456270=26.41273=63:64:94271=3500272=2014061037016=2014061037017=63:64:8237=80531935651289=45290=4
10:26:36.490: 656629 - 82 - 1128=935=X34=65662952=20140610-13:26:36.49575=20140610268=1279=1269=122=8207=BVMF48=380963983=254457270=26.41273=63:64:95271=3500272=2014061037016=2014061037017=63:42:1437=80531935652289=114290=1
10:26:36.556: 656630 - 71 - 1128=935=X34=65663052=20140610-13:26:36.56175=20140610268=1279=2269=122=8207=BVMF48=380968883=252798273=63:65:60272=2014061037=80531935472289=8290=4
10:26:37.046: 656631 - 119 - 1128=935=X34=65663152=20140610-13:26:37.05275=20140610268=2279=2269=122=8207=BVMF48=380394783=65643273=63:70:51272=2014061037=80531935221289=23290=8279=0269=122=8207=BVMF48=380394783=65644270=17.05273=63:70:51271=100272=2014061037016=2014061037017=63:70:5137=80531935678289=23290=6
10:26:37.158: 656632 - 119 - 1128=935=X34=65663252=20140610-13:26:37.16475=20140610268=2279=2269=122=8207=BVMF48=380394783=65645273=63:71:63272=2014061037=80531931802289=40290=2279=0269=122=8207=BVMF48=380394783=65646270=17.05273=63:71:63271=100272=2014061037016=2014061037017=63:71:6337=80531935679289=40290=6
10:26:37.234: 656633 - 162 - 1128=935=X34=65663352=20140610-13:26:37.23975=20140610268=3279=0269=222=8207=BVMF48=380963983=254458270=26.41273=63:72:38271=100272=2014061037016=2014061037017=63:72:381500=E451=-0.21020=1295000274=1277=L1003=17340288=735289=114279=0269=922=8207=BVMF48=380963983=254459270=26.475273=63:72:38272=201406101500=E279=1269=122=8207=BVMF48=380963983=254460270=26.41273=63:72:38271=3400272=2014061037016=2014061037017=63:42:1437=80531935652289=114290=1
10:26:37.238: 656634 - 73 - 1128=935=X34=65663452=20140610-13:26:37.24475=20140610268=1279=2269=122=8207=BVMF48=380963983=254461273=63:72:43272=2014061037=80531935652289=114290=1
10:26:37.239: 656635 - 199 - 1128=935=X34=65663552=20140610-13:26:37.24475=20140610268=4279=0269=222=8207=BVMF48=380968883=252799270=29.39273=63:72:44271=100272=2014061037016=2014061037017=63:72:431500=E451=-0.241020=381200274=1277=L1003=5630288=114289=45279=0269=922=8207=BVMF48=380968883=252800270=29.494273=63:72:44272=201406101500=E279=1269=122=8207=BVMF48=380968883=252801270=29.39273=63:72:44271=3100272=2014061037016=2014061037017=63:41:9937=80531935471289=45290=1279=2269=022=8207=BVMF48=380968883=252802273=63:72:44272=2014061037=80531935641288=114290=5
10:26:37.240: 656636 - 160 - 1128=935=X34=65663652=20140610-13:26:37.24575=20140610268=3279=0269=222=8207=BVMF48=380963983=254462270=26.41273=63:72:44271=200272=2014061037016=2014061037017=63:72:441500=E451=-0.21020=1295200274=1277=L1003=17350288=735289=40279=0269=922=8207=BVMF48=380963983=254463270=26.475273=63:72:44272=201406101500=E279=1269=122=8207=BVMF48=380963983=254464270=26.41273=63:72:44271=100272=2014061037016=2014061037017=63:43:6237=80531935600289=40290=1
10:26:37.245: 656637 - 83 - 1128=935=X34=65663752=20140610-13:26:37.25075=20140610268=1279=0269=122=8207=BVMF48=380963983=254465270=26.41273=63:72:50271=3500272=2014061037016=2014061037017=63:72:5037=80531935692289=114290=4
10:26:37.245: 656638 - 82 - 1128=935=X34=65663852=20140610-13:26:37.25175=20140610268=1279=0269=022=8207=BVMF48=380968883=252803270=29.38273=63:72:50271=5800272=2014061037016=2014061037017=63:72:5037=80531935693288=114290=7
10:26:37.254: 656639 - 81 - 1128=935=X34=65663952=20140610-13:26:37.25975=20140610268=1279=1269=122=8207=BVMF48=380963983=254466270=26.41273=63:72:58271=3400272=2014061037016=2014061037017=63:64:8237=80531935694289=45290=3
10:26:37.254: 656640 - 82 - 1128=935=X34=65664052=20140610-13:26:37.25975=20140610268=1279=1269=122=8207=BVMF48=380963983=254467270=26.41273=63:72:58271=3400272=2014061037016=2014061037017=63:72:5037=80531935695289=114290=4
10:26:37.270: 656641 - 208 - 1128=935=X34=65664152=20140610-13:26:37.27575=20140610268=5279=0269=222=8207=BVMF48=380391383=106027270=13.84273=63:72:75271=200272=2014061037016=2014061037017=63:72:741500=E451=-0.051020=106700274=1277=L1003=3220288=40289=227279=0269=922=8207=BVMF48=380391383=106028270=13.878273=63:72:75272=201406101500=E279=0269=222=8207=BVMF48=380391383=106029270=13.84273=63:72:75271=100272=2014061037016=2014061037017=63:72:741500=E451=-0.051020=106800274=1277=L1003=3230288=40289=227279=0269=922=8207=BVMF48=380391383=106030270=13.878273=63:72:75272=201406101500=E279=4269=022=8207=BVMF48=380391383=106031273=63:72:75272=20140610290=2
10:26:37.272: 656642 - 81 - 1128=935=X34=65664252=20140610-13:26:37.27775=20140610268=1279=0269=122=8207=BVMF48=380391383=106032270=13.84273=63:72:76271=100272=2014061037016=2014061037017=63:72:7637=80531935698289=8290=1
10:26:37.272: 656643 - 71 - 1128=935=X34=65664352=20140610-13:26:37.27775=20140610268=1279=2269=122=8207=BVMF48=380391383=106033273=63:72:77272=2014061037=80531935698289=8290=1
10:26:37.356: 656644 - 81 - 1128=935=X34=65664452=20140610-13:26:37.36175=20140610268=1279=0269=122=8207=BVMF48=380391383=106034270=13.85273=63:73:60271=100272=2014061037016=2014061037017=63:73:6037=80531935709289=8290=6
10:26:37.372: 656645 - 119 - 1128=935=X34=65664552=20140610-13:26:37.37775=20140610268=2279=2269=122=8207=BVMF48=380394783=65647273=63:73:77272=2014061037=80531935679289=40290=6279=0269=122=8207=BVMF48=380394783=65648270=17.06273=63:73:77271=100272=2014061037016=2014061037017=63:73:7637=80531935710289=40290=7
10:26:37.418: 656646 - 70 - 1128=935=X34=65664652=20140610-13:26:37.42375=20140610268=1279=2269=022=8207=BVMF48=380394783=65649273=63:74:22272=2014061037=80531935624288=8290=2
10:26:37.431: 656647 - 70 - 1128=935=X34=65664752=20140610-13:26:37.43675=20140610268=1279=2269=022=8207=BVMF48=380391383=106035273=63:74:35272=2014061037=80531935625288=8290=32
10:26:37.441: 656648 - 80 - 1128=935=X34=65664852=20140610-13:26:37.44675=20140610268=1279=0269=022=8207=BVMF48=380391383=106036270=13.78273=63:74:46271=100272=2014061037016=2014061037017=63:74:4537=80531935712288=8290=32
10:26:37.444: 656649 - 80 - 1128=935=X34=65664952=20140610-13:26:37.44975=20140610268=1279=0269=022=8207=BVMF48=380394783=65650270=17.02273=63:74:49271=400272=2014061037016=2014061037017=63:74:4937=80531935713288=8290=5
10:26:38.094: 656650 - 81 - 1128=935=X34=65665052=20140610-13:26:38.10075=20140610268=1279=0269=122=8207=BVMF48=380965483=79258270=8.22273=63:80:99271=100272=2014061037016=2014061037017=63:80:9937=80531935714289=3290=4
10:26:38.224: 656651 - 81 - 1128=935=X34=65665152=20140610-13:26:38.22975=20140610268=1279=0269=122=8207=BVMF48=380968883=252804270=29.39273=63:82:29271=100272=2014061037016=2014061037017=63:82:2937=80531935715289=9290=2
10:26:38.232: 656652 - 82 - 1128=935=X34=65665252=20140610-13:26:38.23775=20140610268=1279=0269=122=8207=BVMF48=380963983=254468270=26.41273=63:82:37271=100272=2014061037016=2014061037017=63:82:3737=80531935716289=45290=5
10:26:38.232: 656653 - 121 - 1128=935=X34=65665352=20140610-13:26:38.23875=20140610268=2279=2269=122=8207=BVMF48=380963983=254469273=63:82:37272=2014061037=80531935695289=114290=4279=0269=122=8207=BVMF48=380963983=254470270=26.41273=63:82:37271=3500272=2014061037016=2014061037017=63:82:3737=80531935717289=114290=5
10:26:38.235: 656654 - 119 - 1128=935=X34=65665452=20140610-13:26:38.24075=20140610268=2279=2269=122=8207=BVMF48=380968883=252805273=63:82:40272=2014061037=80531934240289=45290=4279=0269=122=8207=BVMF48=380968883=252806270=29.39273=63:82:40271=100272=2014061037016=2014061037017=63:82:4037=80531935718289=45290=3
10:26:38.245: 656655 - 119 - 1128=935=X34=65665552=20140610-13:26:38.25075=20140610268=2279=2269=122=8207=BVMF48=380963983=254471273=63:82:50272=2014061037=80531935716289=45290=4279=0269=122=8207=BVMF48=380963983=254472270=26.41273=63:82:50271=200272=2014061037016=2014061037017=63:82:5037=80531935719289=45290=5
10:26:38.245: 656656 - 121 - 1128=935=X34=65665652=20140610-13:26:38.25175=20140610268=2279=2269=122=8207=BVMF48=380963983=254473273=63:82:50272=2014061037=80531935717289=114290=4279=0269=122=8207=BVMF48=380963983=254474270=26.41273=63:82:50271=3600272=2014061037016=2014061037017=63:82:5037=80531935720289=114290=5
10:26:38.286: 656657 - 266 - 1128=935=X34=65665752=20140610-13:26:38.29175=20140610268=6279=0269=222=8207=BVMF48=380963983=254475270=26.41273=63:82:91271=100272=2014061037016=2014061037017=63:82:901500=E451=-0.21020=1295300274=1277=L1003=17360288=3289=40279=0269=922=8207=BVMF48=380963983=254476270=26.475273=63:82:91272=201406101500=E279=0269=222=8207=BVMF48=380963983=254477270=26.41273=63:82:91271=400272=2014061037016=2014061037017=63:82:901500=E451=-0.21020=1295700274=1277=L1003=17370288=3289=3279=0269=922=8207=BVMF48=380963983=254478270=26.475273=63:82:91272=201406101500=E279=2269=122=8207=BVMF48=380963983=254479273=63:82:91272=2014061037=80531935600289=40290=1279=1269=122=8207=BVMF48=380963983=254480270=26.41273=63:82:91271=600272=2014061037016=2014061037017=63:59:8737=80531935637289=3290=1
10:26:38.290: 656658 - 71 - 1128=935=X34=65665852=20140610-13:26:38.29575=20140610268=1279=2269=122=8207=BVMF48=380963983=254481273=63:82:95272=2014061037=80531935637289=3290=1
10:26:38.293: 656659 - 195 - 1128=935=X34=65665952=20140610-13:26:38.29975=20140610268=4279=0269=222=8207=BVMF48=380968883=252807270=29.39273=63:82:98271=400272=2014061037016=2014061037017=63:82:981500=E451=-0.241020=381600274=1277=L1003=5640288=3289=45279=0269=922=8207=BVMF48=380968883=252808270=29.494273=63:82:98272=201406101500=E279=1269=122=8207=BVMF48=380968883=252809270=29.39273=63:82:98271=2700272=2014061037016=2014061037017=63:41:9937=80531935471289=45290=1279=2269=022=8207=BVMF48=380968883=252810273=63:82:98272=2014061037=80531935638288=3290=5
10:26:38.298: 656660 - 81 - 1128=935=X34=65666052=20140610-13:26:38.30475=20140610268=1279=0269=122=8207=BVMF48=380963983=254482270=26.41273=63:83:03271=900272=2014061037016=2014061037017=63:83:0337=80531935724289=3290=4
10:26:38.302: 656661 - 80 - 1128=935=X34=65666152=20140610-13:26:38.30775=20140610268=1279=0269=022=8207=BVMF48=380968883=252811270=29.38273=63:83:07271=800272=2014061037016=2014061037017=63:83:0637=80531935725288=3290=7
10:26:38.305: 656662 - 72 - 1128=935=X34=65666252=20140610-13:26:38.31075=20140610268=1279=2269=122=8207=BVMF48=380963983=254483273=63:83:10272=2014061037=80531935719289=45290=2
10:26:38.306: 656663 - 81 - 1128=935=X34=65666352=20140610-13:26:38.31175=20140610268=1279=1269=122=8207=BVMF48=380963983=254484270=26.41273=63:83:11271=3200272=2014061037016=2014061037017=63:64:8237=80531935727289=45290=1
10:26:38.306: 656664 - 82 - 1128=935=X34=65666452=20140610-13:26:38.31175=20140610268=1279=1269=122=8207=BVMF48=380963983=254485270=26.41273=63:83:11271=3200272=2014061037016=2014061037017=63:82:5037=80531935728289=114290=2
10:26:38.447: 656665 - 82 - 1128=935=X34=65666552=20140610-13:26:38.45275=20140610268=1279=0269=122=8207=BVMF48=380963983=254486270=26.41273=63:84:51271=100272=2014061037016=2014061037017=63:84:5137=80531935729289=40290=4
10:26:38.654: 656666 - 81 - 1128=935=X34=65666652=20140610-13:26:38.65975=20140610268=1279=0269=022=8207=BVMF48=380963983=254487270=26.37273=63:86:58271=2000272=2014061037016=2014061037017=63:86:5837=80531935730288=33290=18
10:26:38.841: 656667 - 81 - 1128=935=X34=65666752=20140610-13:26:38.84775=20140610268=1279=0269=022=8207=BVMF48=380249383=103297270=9.33273=63:88:46271=100272=2014061037016=2014061037017=63:88:4637=80531935733288=40290=5
10:26:39.363: 656668 - 72 - 1128=935=X34=65666852=20140610-13:26:39.36975=20140610268=1279=2269=122=8207=BVMF48=380963983=254488273=63:93:68272=2014061037=80531935607289=45290=8
10:26:39.366: 656669 - 158 - 1128=935=X34=65666952=20140610-13:26:39.37175=20140610268=3279=0269=222=8207=BVMF48=380963983=254489270=26.41273=63:93:71271=600272=2014061037016=2014061037017=63:93:701500=E451=-0.21020=1296300274=1277=L1003=17380288=3289=45279=0269=922=8207=BVMF48=380963983=254490270=26.475273=63:93:71272=201406101500=E279=1269=122=8207=BVMF48=380963983=254491270=26.41273=63:93:71271=2600272=2014061037016=2014061037017=63:64:8237=80531935727289=45290=1
10:26:39.375: 656670 - 197 - 1128=935=X34=65667052=20140610-13:26:39.38075=20140610268=4279=0269=222=8207=BVMF48=380968883=252812270=29.39273=63:93:79271=600272=2014061037016=2014061037017=63:93:791500=E451=-0.241020=382200274=1277=L1003=5650288=45289=45279=0269=922=8207=BVMF48=380968883=252813270=29.493273=63:93:79272=201406101500=E279=1269=122=8207=BVMF48=380968883=252814270=29.39273=63:93:79271=2100272=2014061037016=2014061037017=63:41:9937=80531935471289=45290=1279=2269=022=8207=BVMF48=380968883=252815273=63:93:79272=2014061037=80531935645288=45290=5
10:26:39.375: 656671 - 72 - 1128=935=X34=65667152=20140610-13:26:39.38075=20140610268=1279=2269=122=8207=BVMF48=380963983=254492273=63:93:80272=2014061037=80531935727289=45290=1
10:26:39.380: 656672 - 160 - 1128=935=X34=65667252=20140610-13:26:39.38575=20140610268=3279=0269=222=8207=BVMF48=380963983=254493270=26.41273=63:93:84271=600272=2014061037016=2014061037017=63:93:841500=E451=-0.21020=1296900274=1277=L1003=17390288=3289=114279=0269=922=8207=BVMF48=380963983=254494270=26.475273=63:93:84272=201406101500=E279=1269=122=8207=BVMF48=380963983=254495270=26.41273=63:93:84271=2600272=2014061037016=2014061037017=63:82:5037=80531935728289=114290=1
10:26:39.380: 656673 - 81 - 1128=935=X34=65667352=20140610-13:26:39.38675=20140610268=1279=0269=022=8207=BVMF48=380968883=252816270=29.38273=63:93:85271=4000272=2014061037016=2014061037017=63:93:8537=80531935797288=45290=7
10:26:39.381: 656674 - 82 - 1128=935=X34=65667452=20140610-13:26:39.38675=20140610268=1279=0269=122=8207=BVMF48=380963983=254496270=26.41273=63:93:86271=3200272=2014061037016=2014061037017=63:93:8537=80531935798289=45290=4
10:26:39.382: 656675 - 72 - 1128=935=X34=65667552=20140610-13:26:39.38675=20140610268=1279=2269=122=8207=BVMF48=380963983=254497273=63:93:86272=2014061037=80531935604289=45290=7
10:26:39.382: 656676 - 119 - 1128=935=X34=65667652=20140610-13:26:39.38675=20140610268=2279=2269=022=8207=BVMF48=380963983=254498273=63:93:86272=2014061037=80531935605288=45290=70279=0269=022=8207=BVMF48=380963983=254499270=26.4273=63:93:86271=3000272=2014061037016=2014061037017=63:93:8637=80531935800288=45290=5
10:26:39.382: 656677 - 71 - 1128=935=X34=65667752=20140610-13:26:39.38775=20140610268=1279=2269=122=8207=BVMF48=380968883=252817273=63:93:86272=2014061037=80531935634289=8290=5
10:26:39.382: 656678 - 71 - 1128=935=X34=65667852=20140610-13:26:39.38775=20140610268=1279=2269=022=8207=BVMF48=380963983=254500273=63:93:87272=2014061037=80531935800288=45290=5
10:26:39.383: 656679 - 71 - 1128=935=X34=65667952=20140610-13:26:39.38875=20140610268=1279=2269=122=8207=BVMF48=380968883=252818273=63:93:88272=2014061037=80531927394289=3290=7
10:26:39.384: 656680 - 73 - 1128=935=X34=65668052=20140610-13:26:39.38975=20140610268=1279=2269=122=8207=BVMF48=380963983=254501273=63:93:89272=2014061037=80531935728289=114290=1
10:26:39.385: 656681 - 199 - 1128=935=X34=65668152=20140610-13:26:39.39075=20140610268=4279=0269=222=8207=BVMF48=380968883=252819270=29.39273=63:93:89271=500272=2014061037016=2014061037017=63:93:891500=E451=-0.241020=382700274=1277=L1003=5660288=114289=45279=0269=922=8207=BVMF48=380968883=252820270=29.493273=63:93:89272=201406101500=E279=1269=122=8207=BVMF48=380968883=252821270=29.39273=63:93:89271=1600272=2014061037016=2014061037017=63:41:9937=80531935471289=45290=1279=2269=022=8207=BVMF48=380968883=252822273=63:93:89272=2014061037=80531935693288=114290=5
10:26:39.386: 656682 - 81 - 1128=935=X34=65668252=20140610-13:26:39.39275=20140610268=1279=1269=122=8207=BVMF48=380963983=254502270=26.41273=63:93:91271=2500272=2014061037016=2014061037017=63:93:8537=80531935804289=45290=3
10:26:39.389: 656683 - 83 - 1128=935=X34=65668352=20140610-13:26:39.39575=20140610268=1279=0269=122=8207=BVMF48=380963983=254503270=26.41273=63:93:94271=2500272=2014061037016=2014061037017=63:93:9437=80531935821289=114290=4
10:26:39.390: 656684 - 82 - 1128=935=X34=65668452=20140610-13:26:39.39575=20140610268=1279=0269=022=8207=BVMF48=380968883=252823270=29.38273=63:93:95271=5800272=2014061037016=2014061037017=63:93:9537=80531935825288=114290=7
10:26:39.407: 656685 - 81 - 1128=935=X34=65668552=20140610-13:26:39.41275=20140610268=1279=1269=122=8207=BVMF48=380963983=254504270=26.41273=63:94:12271=2000272=2014061037016=2014061037017=63:93:8537=80531935871289=45290=3
10:26:39.407: 656686 - 82 - 1128=935=X34=65668652=20140610-13:26:39.41375=20140610268=1279=1269=122=8207=BVMF48=380963983=254505270=26.41273=63:94:12271=1900272=2014061037016=2014061037017=63:93:9437=80531935872289=114290=4
10:26:39.409: 656687 - 82 - 1128=935=X34=65668752=20140610-13:26:39.41475=20140610268=1279=0269=122=8207=BVMF48=380963983=254506270=26.41273=63:94:14271=900272=2014061037016=2014061037017=63:94:1337=80531935873289=40290=5
10:26:39.421: 656688 - 80 - 1128=935=X34=65668852=20140610-13:26:39.42675=20140610268=1279=1269=122=8207=BVMF48=380963983=254507270=26.42273=63:94:25271=2000272=2014061037016=2014061037017=61:22:0337=80531935880289=8290=6
10:26:39.429: 656689 - 72 - 1128=935=X34=65668952=20140610-13:26:39.43575=20140610268=1279=2269=122=8207=BVMF48=380963983=254508273=63:94:34272=2014061037=80531935873289=40290=5
10:26:39.451: 656690 - 157 - 1128=935=X34=65669052=20140610-13:26:39.45675=20140610268=3279=0269=222=8207=BVMF48=380963983=254509270=26.41273=63:94:56271=800272=2014061037016=2014061037017=63:94:551500=E451=-0.21020=1297700274=1277=L1003=17400288=88289=3279=0269=922=8207=BVMF48=380963983=254510270=26.475273=63:94:56272=201406101500=E279=1269=122=8207=BVMF48=380963983=254511270=26.41273=63:94:56271=100272=2014061037016=2014061037017=63:83:0337=80531935724289=3290=1
10:26:39.455: 656691 - 71 - 1128=935=X34=65669152=20140610-13:26:39.46175=20140610268=1279=2269=122=8207=BVMF48=380963983=254512273=63:94:60272=2014061037=80531935724289=3290=1
10:26:39.459: 656692 - 195 - 1128=935=X34=65669252=20140610-13:26:39.46475=20140610268=4279=0269=222=8207=BVMF48=380968883=252824270=29.39273=63:94:64271=700272=2014061037016=2014061037017=63:94:631500=E451=-0.241020=383400274=1277=L1003=5670288=3289=45279=0269=922=8207=BVMF48=380968883=252825270=29.493273=63:94:64272=201406101500=E279=1269=122=8207=BVMF48=380968883=252826270=29.39273=63:94:64271=900272=2014061037016=2014061037017=63:41:9937=80531935471289=45290=1279=2269=022=8207=BVMF48=380968883=252827273=63:94:64272=2014061037=80531935725288=3290=5
10:26:39.464: 656693 - 81 - 1128=935=X34=65669352=20140610-13:26:39.46975=20140610268=1279=0269=122=8207=BVMF48=380963983=254513270=26.41273=63:94:69271=100272=2014061037016=2014061037017=63:94:6837=80531935891289=3290=4
10:26:39.467: 656694 - 80 - 1128=935=X34=65669452=20140610-13:26:39.47275=20140610268=1279=0269=022=8207=BVMF48=380968883=252828270=29.38273=63:94:72271=100272=2014061037016=2014061037017=63:94:7237=80531935892288=3290=7
10:26:39.471: 656695 - 81 - 1128=935=X34=65669552=20140610-13:26:39.47775=20140610268=1279=1269=122=8207=BVMF48=380963983=254514270=26.41273=63:94:76271=1200272=2014061037016=2014061037017=63:93:8537=80531935893289=45290=2
10:26:39.472: 656696 - 82 - 1128=935=X34=65669652=20140610-13:26:39.47775=20140610268=1279=1269=122=8207=BVMF48=380963983=254515270=26.41273=63:94:77271=1100272=2014061037016=2014061037017=63:93:9437=80531935894289=114290=3
10:26:39.473: 656697 - 357 - 1128=935=X34=65669752=20140610-13:26:39.47975=20140610268=9279=0269=222=8207=BVMF48=380963983=254516270=26.41273=63:94:78271=100272=2014061037016=2014061037017=63:94:771500=E451=-0.21020=1297800274=1277=L1003=17410288=45289=40279=0269=922=8207=BVMF48=380963983=254517270=26.475273=63:94:78272=201406101500=E279=0269=222=8207=BVMF48=380963983=254518270=26.41273=63:94:78271=1200272=2014061037016=2014061037017=63:94:771500=E451=-0.21020=1299000274=1277=L1003=17420288=45289=45279=0269=922=8207=BVMF48=380963983=254519270=26.475273=63:94:78272=201406101500=E279=0269=222=8207=BVMF48=380963983=254520270=26.41273=63:94:78271=1100272=2014061037016=2014061037017=63:94:771500=E451=-0.21020=1300100274=1277=L1003=17430288=45289=114279=0269=922=8207=BVMF48=380963983=254521270=26.475273=63:94:78272=201406101500=E279=0269=222=8207=BVMF48=380963983=254522270=26.41273=63:94:78271=100272=2014061037016=2014061037017=63:94:771500=E451=-0.21020=1300200274=1277=L1003=17440288=45289=3279=0269=922=8207=BVMF48=380963983=254523270=26.475273=63:94:78272=201406101500=E279=4269=122=8207=BVMF48=380963983=254524273=63:94:78272=20140610290=4
10:26:39.474: 656698 - 72 - 1128=935=X34=65669852=20140610-13:26:39.48075=20140610268=1279=2269=122=8207=BVMF48=380968883=252829273=63:94:79272=2014061037=80531935603289=45290=27
10:26:39.475: 656699 - 82 - 1128=935=X34=65669952=20140610-13:26:39.48075=20140610268=1279=0269=122=8207=BVMF48=380968883=252830270=29.5273=63:94:80271=300272=2014061037016=2014061037017=63:94:7937=80531935906289=8290=34
10:26:39.478: 656700 - 195 - 1128=935=X34=65670052=20140610-13:26:39.48475=20140610268=4279=0269=222=8207=BVMF48=380968883=252831270=29.39273=63:94:83271=100272=2014061037016=2014061037017=63:94:831500=E451=-0.241020=383500274=1277=L1003=5680288=3289=45279=0269=922=8207=BVMF48=380968883=252832270=29.493273=63:94:83272=201406101500=E279=1269=122=8207=BVMF48=380968883=252833270=29.39273=63:94:83271=800272=2014061037016=2014061037017=63:41:9937=80531935471289=45290=1279=2269=022=8207=BVMF48=380968883=252834273=63:94:83272=2014061037=80531935892288=3290=7
10:26:39.479: 656701 - 365 - 1128=935=X34=65670152=20140610-13:26:39.48475=20140610268=9279=0269=222=8207=BVMF48=380968883=252835270=29.39273=63:94:84271=800272=2014061037016=2014061037017=63:94:831500=E451=-0.241020=384300274=1277=L1003=5690288=45289=45279=0269=922=8207=BVMF48=380968883=252836270=29.493273=63:94:84272=201406101500=E279=0269=222=8207=BVMF48=380968883=252837270=29.39273=63:94:84271=100272=2014061037016=2014061037017=63:94:831500=E451=-0.241020=384400274=1277=L1003=5700288=45289=9279=0269=922=8207=BVMF48=380968883=252838270=29.493273=63:94:84272=201406101500=E279=0269=222=8207=BVMF48=380968883=252839270=29.39273=63:94:84271=100272=2014061037016=2014061037017=63:94:831500=E451=-0.241020=384500274=1277=L1003=5710288=45289=45279=0269=922=8207=BVMF48=380968883=252840270=29.493273=63:94:84272=201406101500=E279=4269=122=8207=BVMF48=380968883=252841273=63:94:84272=20140610290=3279=0269=122=8207=BVMF48=380968883=252842270=29.39273=63:94:84271=5000272=2014061037016=2014061037017=63:94:8337=80531935918289=45290=1279=2269=022=8207=BVMF48=380968883=252843273=63:94:84272=2014061037=80531935797288=45290=5
10:26:39.479: 656702 - 80 - 1128=935=X34=65670252=20140610-13:26:39.48575=20140610268=1279=0269=022=8207=BVMF48=380963983=254525270=26.41273=63:94:84271=600272=2014061037016=2014061037017=63:94:8437=80531935919288=3290=1
10:26:39.479: 656703 - 199 - 1128=935=X34=65670352=20140610-13:26:39.48575=20140610268=4279=0269=222=8207=BVMF48=380968883=252844270=29.39273=63:94:84271=1000272=2014061037016=2014061037017=63:94:841500=E451=-0.241020=385500274=1277=L1003=5720288=114289=45279=0269=922=8207=BVMF48=380968883=252845270=29.493273=63:94:84272=201406101500=E279=1269=122=8207=BVMF48=380968883=252846270=29.39273=63:94:84271=4000272=2014061037016=2014061037017=63:94:8337=80531935918289=45290=1279=2269=022=8207=BVMF48=380968883=252847273=63:94:84272=2014061037=80531935825288=114290=5
10:26:39.484: 656704 - 70 - 1128=935=X34=65670452=20140610-13:26:39.49075=20140610268=1279=2269=022=8207=BVMF48=380963983=254526273=63:94:89272=2014061037=80531935204288=8290=18
10:26:39.485: 656705 - 71 - 1128=935=X34=65670552=20140610-13:26:39.49075=20140610268=1279=2269=122=8207=BVMF48=380963983=254527273=63:94:89272=2014061037=80531929319289=8290=7
10:26:39.485: 656706 - 81 - 1128=935=X34=65670652=20140610-13:26:39.49075=20140610268=1279=0269=122=8207=BVMF48=380963983=254528270=26.47273=63:94:89271=300272=2014061037016=2014061037017=63:94:8937=80531935940289=8290=32
10:26:39.485: 656707 - 82 - 1128=935=X34=65670752=20140610-13:26:39.49075=20140610268=1279=0269=122=8207=BVMF48=380968883=252848270=29.39273=63:94:90271=100272=2014061037016=2014061037017=63:94:9037=80531935946289=45290=2
10:26:39.487: 656708 - 81 - 1128=935=X34=65670852=20140610-13:26:39.49175=20140610268=1279=0269=022=8207=BVMF48=380968883=252849270=29.38273=63:94:91271=4000272=2014061037016=2014061037017=63:94:9037=80531935952288=45290=5
10:26:39.487: 656709 - 194 - 1128=935=X34=65670952=20140610-13:26:39.49275=20140610268=4279=0269=222=8207=BVMF48=380963983=254529270=26.41273=63:94:91271=600272=2014061037016=2014061037017=63:94:911500=E451=-0.21020=1300800274=1277=L1003=17450288=3289=45279=0269=922=8207=BVMF48=380963983=254530270=26.475273=63:94:91272=201406101500=E279=2269=022=8207=BVMF48=380963983=254531273=63:94:91272=2014061037=80531935919288=3290=1279=0269=122=8207=BVMF48=380963983=254532270=26.41273=63:94:91271=600272=2014061037016=2014061037017=63:94:9137=80531935956289=45290=1
10:26:39.487: 656710 - 83 - 1128=935=X34=65671052=20140610-13:26:39.49275=20140610268=1279=0269=122=8207=BVMF48=380963983=254533270=26.41273=63:94:92271=1100272=2014061037016=2014061037017=63:94:9237=80531935965289=114290=2
10:26:39.488: 656711 - 82 - 1128=935=X34=65671152=20140610-13:26:39.49375=20140610268=1279=0269=022=8207=BVMF48=380968883=252850270=29.38273=63:94:92271=5800272=2014061037016=2014061037017=63:94:9237=80531935970288=114290=6
10:26:39.488: 656712 - 119 - 1128=935=X34=65671252=20140610-13:26:39.49375=20140610268=2279=2269=022=8207=BVMF48=400223483=5854273=63:94:93272=2014061037=80531933858288=110290=2279=0269=022=8207=BVMF48=400223483=5855270=26.4273=63:94:93271=35272=2014061037016=2014061037017=63:94:9337=80531935974288=110290=1
10:26:39.490: 656713 - 120 - 1128=935=X34=65671352=20140610-13:26:39.49575=20140610268=2279=2269=122=8207=BVMF48=380968883=252851273=63:94:95272=2014061037=80531935946289=45290=2279=0269=122=8207=BVMF48=380968883=252852270=29.4273=63:94:95271=4000272=2014061037016=2014061037017=63:94:9537=80531935986289=45290=3
10:26:39.492: 656714 - 197 - 1128=935=X34=65671452=20140610-13:26:39.49775=20140610268=4279=0269=222=8207=BVMF48=380968883=252853270=29.39273=63:94:96271=600272=2014061037016=2014061037017=63:94:951500=E451=-0.241020=386100274=1277=L1003=5730288=45289=45279=0269=922=8207=BVMF48=380968883=252854270=29.492273=63:94:96272=201406101500=E279=1269=122=8207=BVMF48=380968883=252855270=29.39273=63:94:96271=3400272=2014061037016=2014061037017=63:94:8337=80531935918289=45290=1279=2269=022=8207=BVMF48=380968883=252856273=63:94:96272=2014061037=80531935952288=45290=5
10:26:39.492: 656715 - 72 - 1128=935=X34=65671552=20140610-13:26:39.49775=20140610268=1279=2269=122=8207=BVMF48=380963983=254534273=63:94:96272=2014061037=80531935956289=45290=1
10:26:39.492: 656716 - 201 - 1128=935=X34=65671652=20140610-13:26:39.49775=20140610268=4279=0269=222=8207=BVMF48=380963983=254535270=26.41273=63:94:96271=600272=2014061037016=2014061037017=63:94:961500=E451=-0.21020=1301400274=1277=L1003=17460288=40289=114279=0269=922=8207=BVMF48=380963983=254536270=26.475273=63:94:96272=201406101500=E279=1269=122=8207=BVMF48=380963983=254537270=26.41273=63:94:96271=500272=2014061037016=2014061037017=63:94:9237=80531935965289=114290=1279=2269=022=8207=BVMF48=380963983=254538273=63:94:96272=2014061037=80531935270288=40290=2
10:26:39.497: 656717 - 81 - 1128=935=X34=65671752=20140610-13:26:39.50275=20140610268=1279=0269=022=8207=BVMF48=380968883=252857270=29.38273=63:95:02271=4000272=2014061037016=2014061037017=63:95:0237=80531936023288=45290=6
10:26:39.498: 656718 - 73 - 1128=935=X34=65671852=20140610-13:26:39.50375=20140610268=1279=2269=122=8207=BVMF48=380963983=254539273=63:95:03272=2014061037=80531935965289=114290=1
10:26:39.499: 656719 - 199 - 1128=935=X34=65671952=20140610-13:26:39.50475=20140610268=4279=0269=222=8207=BVMF48=380968883=252858270=29.39273=63:95:03271=600272=2014061037016=2014061037017=63:95:031500=E451=-0.241020=386700274=1277=L1003=5740288=114289=45279=0269=922=8207=BVMF48=380968883=252859270=29.492273=63:95:03272=201406101500=E279=1269=122=8207=BVMF48=380968883=252860270=29.39273=63:95:03271=2800272=2014061037016=2014061037017=63:94:8337=80531935918289=45290=1279=2269=022=8207=BVMF48=380968883=252861273=63:95:03272=2014061037=80531935970288=114290=5
10:26:39.499: 656720 - 82 - 1128=935=X34=65672052=20140610-13:26:39.50475=20140610268=1279=0269=122=8207=BVMF48=380963983=254540270=26.41273=63:95:04271=1200272=2014061037016=2014061037017=63:95:0437=80531936025289=45290=1
10:26:39.500: 656721 - 81 - 1128=935=X34=65672152=20140610-13:26:39.50575=20140610268=1279=0269=022=8207=BVMF48=380963983=254541270=26.4273=63:95:05271=600272=2014061037016=2014061037017=63:95:0537=80531936028288=3290=4
10:26:39.503: 656722 - 82 - 1128=935=X34=65672252=20140610-13:26:39.50875=20140610268=1279=0269=122=8207=BVMF48=380963983=254542270=26.41273=63:95:08271=3800272=2014061037016=2014061037017=63:95:0837=80531936032289=45290=2
10:26:39.504: 656723 - 82 - 1128=935=X34=65672352=20140610-13:26:39.50975=20140610268=1279=0269=122=8207=BVMF48=380963983=254543270=26.41273=63:95:08271=900272=2014061037016=2014061037017=63:95:0837=80531936034289=40290=3
10:26:39.504: 656724 - 81 - 1128=935=X34=65672452=20140610-13:26:39.50975=20140610268=1279=0269=022=8207=BVMF48=380963983=254544270=26.4273=63:95:09271=600272=2014061037016=2014061037017=63:95:0837=80531936035288=3290=5
10:26:39.504: 656725 - 83 - 1128=935=X34=65672552=20140610-13:26:39.50975=20140610268=1279=0269=122=8207=BVMF48=380963983=254545270=26.41273=63:95:09271=5500272=2014061037016=2014061037017=63:95:0937=80531936036289=114290=4
10:26:39.504: 656726 - 82 - 1128=935=X34=65672652=20140610-13:26:39.51075=20140610268=1279=0269=022=8207=BVMF48=380968883=252862270=29.38273=63:95:09271=5800272=2014061037016=2014061037017=63:95:0937=80531936040288=114290=6
10:26:39.505: 656727 - 82 - 1128=935=X34=65672752=20140610-13:26:39.51175=20140610268=1279=0269=122=8207=BVMF48=380968883=252863270=29.4273=63:95:10271=300272=2014061037016=2014061037017=63:95:1037=80531936046289=8290=4
10:26:39.506: 656728 - 70 - 1128=935=X34=65672852=20140610-13:26:39.51175=20140610268=1279=2269=022=8207=BVMF48=380963983=254546273=63:95:10272=2014061037=80531928643288=8290=42
10:26:39.506: 656729 - 80 - 1128=935=X34=65672952=20140610-13:26:39.51175=20140610268=1279=0269=022=8207=BVMF48=380963983=254547270=26.38273=63:95:11271=300272=2014061037016=2014061037017=63:95:1037=80531936048288=8290=13
10:26:39.507: 656730 - 118 - 1128=935=X34=65673052=20140610-13:26:39.51275=20140610268=2279=2269=022=8207=BVMF48=380963983=254548273=63:95:12272=2014061037=80531935349288=45290=2279=0269=022=8207=BVMF48=380963983=254549270=26.39273=63:95:12271=800272=2014061037016=2014061037017=63:95:1237=80531936051288=45290=8
10:26:39.507: 656731 - 70 - 1128=935=X34=65673152=20140610-13:26:39.51375=20140610268=1279=2269=022=8207=BVMF48=380963983=254550273=63:95:12272=2014061037=80531936028288=3290=3
10:26:39.511: 656732 - 70 - 1128=935=X34=65673252=20140610-13:26:39.51675=20140610268=1279=2269=022=8207=BVMF48=380963983=254551273=63:95:16272=2014061037=80531936035288=3290=3
10:26:39.513: 656733 - 119 - 1128=935=X34=65673352=20140610-13:26:39.51975=20140610268=2279=2269=022=8207=BVMF48=380963983=254552273=63:95:18272=2014061037=80531934053288=59290=5279=0269=022=8207=BVMF48=380963983=254553270=26.4273=63:95:18271=800272=2014061037016=2014061037017=63:95:1837=80531936063288=59290=3
10:26:39.515: 656734 - 72 - 1128=935=X34=65673452=20140610-13:26:39.52075=20140610268=1279=2269=122=8207=BVMF48=380963983=254554273=63:95:20272=2014061037=80531935608289=45290=12
10:26:39.516: 656735 - 81 - 1128=935=X34=65673552=20140610-13:26:39.52275=20140610268=1279=1269=122=8207=BVMF48=380963983=254555270=26.41273=63:95:21271=3200272=2014061037016=2014061037017=63:95:0837=80531936069289=45290=2
10:26:39.517: 656736 - 82 - 1128=935=X34=65673652=20140610-13:26:39.52275=20140610268=1279=1269=122=8207=BVMF48=380963983=254556270=26.41273=63:95:22271=4400272=2014061037016=2014061037017=63:95:0937=80531936070289=114290=4
10:26:39.518: 656737 - 197 - 1128=935=X34=65673752=20140610-13:26:39.52375=20140610268=4279=0269=222=8207=BVMF48=380968883=252864270=29.39273=63:95:22271=500272=2014061037016=2014061037017=63:95:221500=E451=-0.241020=387200274=1277=L1003=5750288=45289=45279=0269=922=8207=BVMF48=380968883=252865270=29.492273=63:95:22272=201406101500=E279=1269=122=8207=BVMF48=380968883=252866270=29.39273=63:95:22271=2300272=2014061037016=2014061037017=63:94:8337=80531935918289=45290=1279=2269=022=8207=BVMF48=380968883=252867273=63:95:22272=2014061037=80531936023288=45290=5
10:26:39.518: 656738 - 199 - 1128=935=X34=65673852=20140610-13:26:39.52375=20140610268=4279=0269=222=8207=BVMF48=380968883=252868270=29.39273=63:95:23271=600272=2014061037016=2014061037017=63:95:221500=E451=-0.241020=387800274=1277=L1003=5760288=114289=45279=0269=922=8207=BVMF48=380968883=252869270=29.492273=63:95:23272=201406101500=E279=1269=122=8207=BVMF48=380968883=252870270=29.39273=63:95:23271=1700272=2014061037016=2014061037017=63:94:8337=80531935918289=45290=1279=2269=022=8207=BVMF48=380968883=252871273=63:95:23272=2014061037=80531936040288=114290=5
10:26:39.519: 656739 - 82 - 1128=935=X34=65673952=20140610-13:26:39.52575=20140610268=1279=0269=022=8207=BVMF48=380965483=79259270=8.21273=63:95:24271=1000272=2014061037016=2014061037017=63:95:2437=80531936077288=114290=3
10:26:39.520: 656740 - 72 - 1128=935=X34=65674052=20140610-13:26:39.52675=20140610268=1279=2269=022=8207=BVMF48=380968883=252872273=63:95:25272=2014061037=80531934273288=227290=16
10:26:39.521: 656741 - 119 - 1128=935=X34=65674152=20140610-13:26:39.52675=20140610268=2279=2269=122=8207=BVMF48=380963983=254557273=63:95:26272=2014061037=80531936069289=45290=2279=0269=122=8207=BVMF48=380963983=254558270=26.41273=63:95:26271=3300272=2014061037016=2014061037017=63:95:2637=80531936080289=45290=4
10:26:39.522: 656742 - 121 - 1128=935=X34=65674252=20140610-13:26:39.52775=20140610268=2279=2269=122=8207=BVMF48=380963983=254559273=63:95:27272=2014061037=80531936070289=114290=3279=0269=122=8207=BVMF48=380963983=254560270=26.41273=63:95:27271=4500272=2014061037016=2014061037017=63:95:2637=80531936082289=114290=4
10:26:39.523: 656743 - 81 - 1128=935=X34=65674352=20140610-13:26:39.52875=20140610268=1279=0269=022=8207=BVMF48=380968883=252873270=29.38273=63:95:28271=3500272=2014061037016=2014061037017=63:95:2737=80531936083288=45290=5
10:26:39.525: 656744 - 72 - 1128=935=X34=65674452=20140610-13:26:39.53175=20140610268=1279=2269=122=8207=BVMF48=380963983=254561273=63:95:30272=2014061037=80531936080289=45290=3
10:26:39.526: 656745 - 313 - 1128=935=X34=65674552=20140610-13:26:39.53275=20140610268=7279=0269=222=8207=BVMF48=380963983=254562270=26.4273=63:95:31271=200272=2014061037016=2014061037017=63:95:311500=E451=-0.211020=1301600274=21003=17470288=77289=45279=0269=922=8207=BVMF48=380963983=254563270=26.475273=63:95:31272=201406101500=E279=0269=222=8207=BVMF48=380963983=254564270=26.4273=63:95:31271=300272=2014061037016=2014061037017=63:95:311500=E451=-0.211020=1301900274=3277=L1003=17480288=45289=45279=0269=922=8207=BVMF48=380963983=254565270=26.475273=63:95:31272=201406101500=E279=2269=022=8207=BVMF48=380963983=254566273=63:95:31272=2014061037=80531934666288=77290=1279=1269=022=8207=BVMF48=380963983=254567270=26.4273=63:95:31271=4700272=2014061037016=2014061037017=63:44:3437=80531935606288=45290=1279=2269=122=8207=BVMF48=380963983=254568273=63:95:31272=2014061037=80531936025289=45290=1
10:26:39.526: 656746 - 203 - 1128=935=X34=65674652=20140610-13:26:39.53275=20140610268=4279=0269=222=8207=BVMF48=380963983=254569270=26.4273=63:95:31271=600272=2014061037016=2014061037017=63:95:311500=E451=-0.211020=1302500274=3277=L1003=17490288=45289=114279=0269=922=8207=BVMF48=380963983=254570270=26.475273=63:95:31272=201406101500=E279=1269=022=8207=BVMF48=380963983=254571270=26.4273=63:95:31271=4100272=2014061037016=2014061037017=63:44:3437=80531935606288=45290=1279=2269=122=8207=BVMF48=380963983=254572273=63:95:31272=2014061037=80531936082289=114290=2
10:26:39.527: 656747 - 71 - 1128=935=X34=65674752=20140610-13:26:39.53275=20140610268=1279=2269=022=8207=BVMF48=380968883=252874273=63:95:32272=2014061037=80531936083288=45290=5
10:26:39.531: 656748 - 82 - 1128=935=X34=65674852=20140610-13:26:39.53675=20140610268=1279=0269=022=8207=BVMF48=380968883=252875270=29.36273=63:95:36271=500272=2014061037016=2014061037017=63:95:3637=80531936105288=227290=9
10:26:39.532: 656749 - 119 - 1128=935=X34=65674952=20140610-13:26:39.53775=20140610268=2279=2269=022=8207=BVMF48=380963983=254573273=63:95:37272=2014061037=80531936051288=45290=5279=0269=022=8207=BVMF48=380963983=254574270=26.4273=63:95:37271=800272=2014061037016=2014061037017=63:95:3737=80531936108288=45290=3
10:26:39.533: 656750 - 83 - 1128=935=X34=65675052=20140610-13:26:39.53875=20140610268=1279=0269=122=8207=BVMF48=380963983=254575270=26.41273=63:95:38271=3800272=2014061037016=2014061037017=63:95:3837=80531936112289=114290=2
10:26:39.533: 656751 - 82 - 1128=935=X34=65675152=20140610-13:26:39.53975=20140610268=1279=0269=022=8207=BVMF48=380968883=252876270=29.38273=63:95:38271=5200272=2014061037016=2014061037017=63:95:3837=80531936113288=114290=5
10:26:39.534: 656752 - 82 - 1128=935=X34=65675252=20140610-13:26:39.54075=20140610268=1279=0269=122=8207=BVMF48=380963983=254576270=26.41273=63:95:39271=3700272=2014061037016=2014061037017=63:95:3937=80531936119289=45290=3
10:26:39.536: 656753 - 81 - 1128=935=X34=65675352=20140610-13:26:39.54175=20140610268=1279=0269=022=8207=BVMF48=380968883=252877270=29.38273=63:95:41271=4000272=2014061037016=2014061037017=63:95:4037=80531936129288=45290=6
10:26:39.537: 656754 - 82 - 1128=935=X34=65675452=20140610-13:26:39.54375=20140610268=1279=1269=122=8207=BVMF48=380963983=254577270=26.41273=63:95:42271=3200272=2014061037016=2014061037017=63:95:3837=80531936137289=114290=2
10:26:39.538: 656755 - 120 - 1128=935=X34=65675552=20140610-13:26:39.54375=20140610268=2279=2269=022=8207=BVMF48=380968883=252878273=63:95:43272=2014061037=80531936113288=114290=5279=0269=022=8207=BVMF48=380968883=252879270=29.38273=63:95:43271=5700272=2014061037016=2014061037017=63:95:4337=80531936141288=114290=6
10:26:39.542: 656756 - 81 - 1128=935=X34=65675652=20140610-13:26:39.54875=20140610268=1279=1269=122=8207=BVMF48=380963983=254578270=26.41273=63:95:43271=3100272=2014061037016=2014061037017=63:95:3937=80531936144289=45290=3
10:26:39.542: 656757 - 119 - 1128=935=X34=65675752=20140610-13:26:39.54875=20140610268=2279=2269=122=8207=BVMF48=380963983=254579273=63:95:47272=2014061037=80531936034289=40290=1279=0269=122=8207=BVMF48=380963983=254580270=26.42273=63:95:47271=900272=2014061037016=2014061037017=63:95:4737=80531936146289=40290=4
10:26:39.548: 656758 - 81 - 1128=935=X34=65675852=20140610-13:26:39.55375=20140610268=1279=1269=022=8207=BVMF48=380968883=252880270=29.38273=63:95:53271=5300272=2014061037016=2014061037017=63:95:4337=80531936149288=114290=6
10:26:39.549: 656759 - 72 - 1128=935=X34=65675952=20140610-13:26:39.55575=20140610268=1279=2269=022=8207=BVMF48=380968883=252881273=63:95:54272=2014061037=80531936105288=227290=11
10:26:39.554: 656760 - 81 - 1128=935=X34=65676052=20140610-13:26:39.55975=20140610268=1279=0269=122=8207=BVMF48=380963983=254581270=26.42273=63:95:59271=500272=2014061037016=2014061037017=63:95:5937=80531936151289=8290=5
10:26:39.554: 656761 - 81 - 1128=935=X34=65676152=20140610-13:26:39.56075=20140610268=1279=1269=122=8207=BVMF48=380963983=254582270=26.41273=63:95:59271=1800272=2014061037016=2014061037017=63:95:3937=80531936153289=45290=2
10:26:39.555: 656762 - 82 - 1128=935=X34=65676252=20140610-13:26:39.56075=20140610268=1279=1269=122=8207=BVMF48=380963983=254583270=26.41273=63:95:60271=1900272=2014061037016=2014061037017=63:95:3837=80531936154289=114290=1
10:26:39.558: 656763 - 82 - 1128=935=X34=65676352=20140610-13:26:39.56375=20140610268=1279=0269=022=8207=BVMF48=380968883=252882270=29.35273=63:95:63271=800272=2014061037016=2014061037017=63:95:6237=80531936160288=227290=14
10:26:39.563: 656764 - 81 - 1128=935=X34=65676452=20140610-13:26:39.56975=20140610268=1279=1269=022=8207=BVMF48=380968883=252883270=29.38273=63:95:68271=4400272=2014061037016=2014061037017=63:95:4337=80531936174288=114290=6
10:26:39.570: 656765 - 120 - 1128=935=X34=65676552=20140610-13:26:39.57575=20140610268=2279=2269=022=8207=BVMF48=380968883=252884273=63:95:75272=2014061037=80531936174288=114290=6279=0269=022=8207=BVMF48=380968883=252885270=29.38273=63:95:75271=5100272=2014061037016=2014061037017=63:95:7437=80531936185288=114290=6
10:26:39.573: 656766 - 119 - 1128=935=X34=65676652=20140610-13:26:39.57775=20140610268=2279=2269=122=8207=BVMF48=380963983=254584273=63:95:76272=2014061037=80531936146289=40290=4279=0269=122=8207=BVMF48=380963983=254585270=26.41273=63:95:76271=900272=2014061037016=2014061037017=63:95:7637=80531936186289=40290=3
10:26:39.576: 656767 - 81 - 1128=935=X34=65676752=20140610-13:26:39.58275=20140610268=1279=0269=122=8207=BVMF48=380394783=65651270=17.04273=63:95:81271=100272=2014061037016=2014061037017=63:95:8137=80531936188289=3290=2
10:26:39.582: 656768 - 82 - 1128=935=X34=65676852=20140610-13:26:39.58775=20140610268=1279=0269=122=8207=BVMF48=380963983=254586270=26.53273=63:95:87271=3000272=2014061037016=2014061037017=63:95:8637=80531936191289=45290=62
10:26:39.583: 656769 - 82 - 1128=935=X34=65676952=20140610-13:26:39.58875=20140610268=1279=0269=022=8207=BVMF48=380963983=254587270=26.3273=63:95:88271=3000272=2014061037016=2014061037017=63:95:8737=80531936192288=45290=67
10:26:39.616: 656770 - 81 - 1128=935=X34=65677052=20140610-13:26:39.62175=20140610268=1279=0269=022=8207=BVMF48=380963983=254588270=26.4273=63:96:20271=600272=2014061037016=2014061037017=63:96:2037=80531936203288=3290=4
10:26:39.622: 656771 - 81 - 1128=935=X34=65677152=20140610-13:26:39.62875=20140610268=1279=0269=022=8207=BVMF48=380963983=254589270=26.4273=63:96:27271=600272=2014061037016=2014061037017=63:96:2737=80531936208288=3290=5
10:26:39.624: 656772 - 120 - 1128=935=X34=65677252=20140610-13:26:39.62975=20140610268=2279=2269=022=8207=BVMF48=380968883=252886273=63:96:29272=2014061037=80531936185288=114290=6279=0269=022=8207=BVMF48=380968883=252887270=29.38273=63:96:29271=5600272=2014061037016=2014061037017=63:96:2837=80531936210288=114290=6
10:26:39.625: 656773 - 81 - 1128=935=X34=65677352=20140610-13:26:39.63075=20140610268=1279=0269=022=8207=BVMF48=380963983=254590270=26.4273=63:96:30271=600272=2014061037016=2014061037017=63:96:3037=80531936212288=3290=6
10:26:39.633: 656774 - 120 - 1128=935=X34=65677452=20140610-13:26:39.63875=20140610268=2279=2269=022=8207=BVMF48=380968883=252888273=63:96:37272=2014061037=80531936210288=114290=6279=0269=022=8207=BVMF48=380968883=252889270=29.38273=63:96:37271=6200272=2014061037016=2014061037017=63:96:3737=80531936217288=114290=6
10:26:39.638: 656775 - 120 - 1128=935=X34=65677552=20140610-13:26:39.64375=20140610268=2279=2269=022=8207=BVMF48=380968883=252890273=63:96:42272=2014061037=80531936217288=114290=6279=0269=022=8207=BVMF48=380968883=252891270=29.38273=63:96:42271=6700272=2014061037016=2014061037017=63:96:4237=80531936222288=114290=6
10:26:39.645: 656776 - 72 - 1128=935=X34=65677652=20140610-13:26:39.65075=20140610268=1279=2269=122=8207=BVMF48=380963983=254591273=63:96:50272=2014061037=80531936186289=40290=3
10:26:39.646: 656777 - 119 - 1128=935=X34=65677752=20140610-13:26:39.65275=20140610268=2279=2269=022=8207=BVMF48=380963983=254592273=63:96:51272=2014061037=80531936192288=45290=70279=0269=022=8207=BVMF48=380963983=254593270=26.4273=63:96:51271=3000272=2014061037016=2014061037017=63:96:5137=80531936229288=45290=7
10:26:39.660: 656778 - 121 - 1128=935=X34=65677852=20140610-13:26:39.66675=20140610268=2279=2269=022=8207=BVMF48=380968883=252892273=63:96:65272=2014061037=80531936222288=114290=6279=0269=022=8207=BVMF48=380968883=252893270=29.38273=63:96:65271=9400272=2014061037016=2014061037017=63:96:6537=80531936232288=114290=6
10:26:39.673: 656779 - 82 - 1128=935=X34=65677952=20140610-13:26:39.67975=20140610268=1279=0269=022=8207=BVMF48=380963983=254594270=26.4273=63:96:78271=800272=2014061037016=2014061037017=63:96:7837=80531936235288=88290=8
10:26:39.674: 656780 - 71 - 1128=935=X34=65678052=20140610-13:26:39.68075=20140610268=1279=2269=122=8207=BVMF48=380963983=254595273=63:96:79272=2014061037=80531936151289=8290=4
10:26:39.675: 656781 - 82 - 1128=935=X34=65678152=20140610-13:26:39.68175=20140610268=1279=0269=122=8207=BVMF48=380968883=252894270=29.48273=63:96:80271=2000272=2014061037016=2014061037017=63:96:8037=80531936236289=45290=27
10:26:39.682: 656782 - 118 - 1128=935=X34=65678252=20140610-13:26:39.68775=20140610268=2279=2269=022=8207=BVMF48=380963983=254596273=63:96:86272=2014061037=80531936235288=88290=8279=0269=022=8207=BVMF48=380963983=254597270=26.38273=63:96:86271=800272=2014061037016=2014061037017=63:96:8637=80531936238288=88290=15
10:26:39.682: 656783 - 121 - 1128=935=X34=65678352=20140610-13:26:39.68775=20140610268=2279=2269=022=8207=BVMF48=380968883=252895273=63:96:87272=2014061037=80531936232288=114290=6279=0269=022=8207=BVMF48=380968883=252896270=29.38273=63:96:87271=10100272=2014061037016=2014061037017=63:96:8637=80531936239288=114290=6
10:26:39.687: 656784 - 71 - 1128=935=X34=65678452=20140610-13:26:39.69375=20140610268=1279=2269=122=8207=BVMF48=380963983=254598273=63:96:92272=2014061037=80531935880289=8290=3
10:26:39.693: 656785 - 160 - 1128=935=X34=65678552=20140610-13:26:39.69975=20140610268=3279=0269=222=8207=BVMF48=380963983=254599270=26.41273=63:96:98271=600272=2014061037016=2014061037017=63:96:981500=E451=-0.21020=1303100274=01003=17500288=3289=114279=0269=922=8207=BVMF48=380963983=254600270=26.475273=63:96:98272=201406101500=E279=1269=122=8207=BVMF48=380963983=254601270=26.41273=63:96:98271=1300272=2014061037016=2014061037017=63:95:3837=80531936154289=114290=1
10:26:39.696: 656786 - 82 - 1128=935=X34=65678652=20140610-13:26:39.70275=20140610268=1279=1269=022=8207=BVMF48=380968883=252897270=29.38273=63:97:01271=9400272=2014061037016=2014061037017=63:96:8637=80531936256288=114290=6
10:26:39.698: 656787 - 73 - 1128=935=X34=65678752=20140610-13:26:39.70375=20140610268=1279=2269=122=8207=BVMF48=380963983=254602273=63:97:03272=2014061037=80531936154289=114290=1
10:26:39.699: 656788 - 72 - 1128=935=X34=65678852=20140610-13:26:39.70475=20140610268=1279=2269=122=8207=BVMF48=380968883=252898273=63:97:04272=2014061037=80531936236289=45290=27
10:26:39.700: 656789 - 199 - 1128=935=X34=65678952=20140610-13:26:39.70675=20140610268=4279=0269=222=8207=BVMF48=380968883=252899270=29.39273=63:97:05271=400272=2014061037016=2014061037017=63:97:051500=E451=-0.241020=388200274=1277=L1003=5770288=114289=45279=0269=922=8207=BVMF48=380968883=252900270=29.492273=63:97:05272=201406101500=E279=1269=122=8207=BVMF48=380968883=252901270=29.39273=63:97:05271=1300272=2014061037016=2014061037017=63:94:8337=80531935918289=45290=1279=2269=022=8207=BVMF48=380968883=252902273=63:97:05272=2014061037=80531936256288=114290=6
10:26:39.705: 656790 - 83 - 1128=935=X34=65679052=20140610-13:26:39.71175=20140610268=1279=0269=122=8207=BVMF48=380963983=254603270=26.41273=63:97:10271=1800272=2014061037016=2014061037017=63:97:1037=80531936262289=114290=2
10:26:39.706: 656791 - 83 - 1128=935=X34=65679152=20140610-13:26:39.71175=20140610268=1279=0269=022=8207=BVMF48=380968883=252903270=29.38273=63:97:10271=9500272=2014061037016=2014061037017=63:97:1037=80531936263288=114290=6
10:26:39.707: 656792 - 158 - 1128=935=X34=65679252=20140610-13:26:39.71375=20140610268=3279=0269=222=8207=BVMF48=380963983=254604270=26.41273=63:97:12271=500272=2014061037016=2014061037017=63:97:121500=E451=-0.21020=1303600274=1277=L1003=17510288=3289=45279=0269=922=8207=BVMF48=380963983=254605270=26.475273=63:97:12272=201406101500=E279=1269=122=8207=BVMF48=380963983=254606270=26.41273=63:97:12271=1300272=2014061037016=2014061037017=63:95:3937=80531936153289=45290=1
10:26:39.712: 656793 - 197 - 1128=935=X34=65679352=20140610-13:26:39.71775=20140610268=4279=0269=222=8207=BVMF48=380968883=252904270=29.39273=63:97:17271=400272=2014061037016=2014061037017=63:97:161500=E451=-0.241020=388600274=1277=L1003=5780288=45289=45279=0269=922=8207=BVMF48=380968883=252905270=29.492273=63:97:17272=201406101500=E279=1269=122=8207=BVMF48=380968883=252906270=29.39273=63:97:17271=900272=2014061037016=2014061037017=63:94:8337=80531935918289=45290=1279=2269=022=8207=BVMF48=380968883=252907273=63:97:17272=2014061037=80531936129288=45290=5
10:26:39.712: 656794 - 72 - 1128=935=X34=65679452=20140610-13:26:39.71775=20140610268=1279=2269=122=8207=BVMF48=380963983=254607273=63:97:17272=2014061037=80531936153289=45290=1
10:26:39.716: 656795 - 80 - 1128=935=X34=65679552=20140610-13:26:39.72275=20140610268=1279=0269=022=8207=BVMF48=380968883=252908270=29.37273=63:97:21271=2500272=2014061037016=2014061037017=63:97:2137=80531936270288=8290=8
10:26:39.717: 656796 - 81 - 1128=935=X34=65679652=20140610-13:26:39.72275=20140610268=1279=0269=022=8207=BVMF48=380968883=252909270=29.38273=63:97:22271=4000272=2014061037016=2014061037017=63:97:2137=80531936271288=45290=6
10:26:39.718: 656797 - 71 - 1128=935=X34=65679752=20140610-13:26:39.72375=20140610268=1279=2269=122=8207=BVMF48=380968883=252910273=63:97:23272=2014061037=80531936046289=8290=4
10:26:39.718: 656798 - 82 - 1128=935=X34=65679852=20140610-13:26:39.72375=20140610268=1279=0269=122=8207=BVMF48=380963983=254608270=26.41273=63:97:23271=1800272=2014061037016=2014061037017=63:97:2337=80531936276289=45290=2
10:26:39.718: 656799 - 82 - 1128=935=X34=65679952=20140610-13:26:39.72475=20140610268=1279=1269=122=8207=BVMF48=380963983=254609270=26.41273=63:97:24271=1300272=2014061037016=2014061037017=63:97:1037=80531936277289=114290=1
10:26:39.721: 656800 - 81 - 1128=935=X34=65680052=20140610-13:26:39.72775=20140610268=1279=1269=122=8207=BVMF48=380963983=254610270=26.41273=63:97:27271=1400272=2014061037016=2014061037017=63:97:2337=80531936279289=45290=2
10:26:39.726: 656801 - 160 - 1128=935=X34=65680152=20140610-13:26:39.73175=20140610268=3279=0269=222=8207=BVMF48=380963983=254611270=26.41273=63:97:31271=600272=2014061037016=2014061037017=63:97:301500=E451=-0.21020=1304200274=1277=L1003=17520288=3289=114279=0269=922=8207=BVMF48=380963983=254612270=26.475273=63:97:31272=201406101500=E279=1269=122=8207=BVMF48=380963983=254613270=26.41273=63:97:31271=700272=2014061037016=2014061037017=63:97:1037=80531936277289=114290=1
10:26:39.726: 656802 - 81 - 1128=935=X34=65680252=20140610-13:26:39.73275=20140610268=1279=1269=122=8207=BVMF48=380963983=254614270=26.41273=63:97:31271=1000272=2014061037016=2014061037017=63:97:2337=80531936282289=45290=2
10:26:39.727: 656803 - 82 - 1128=935=X34=65680352=20140610-13:26:39.73275=20140610268=1279=1269=122=8207=BVMF48=380963983=254615270=26.41273=63:97:32271=300272=2014061037016=2014061037017=63:97:1037=80531936283289=114290=1
10:26:39.730: 656804 - 199 - 1128=935=X34=65680452=20140610-13:26:39.73675=20140610268=4279=0269=222=8207=BVMF48=380968883=252911270=29.39273=63:97:35271=600272=2014061037016=2014061037017=63:97:351500=E451=-0.241020=389200274=1277=L1003=5790288=114289=45279=0269=922=8207=BVMF48=380968883=252912270=29.492273=63:97:35272=201406101500=E279=1269=122=8207=BVMF48=380968883=252913270=29.39273=63:97:35271=300272=2014061037016=2014061037017=63:94:8337=80531935918289=45290=1279=2269=022=8207=BVMF48=380968883=252914273=63:97:35272=2014061037=80531936263288=114290=5
10:26:39.731: 656805 - 73 - 1128=935=X34=65680552=20140610-13:26:39.73775=20140610268=1279=2269=122=8207=BVMF48=380963983=254616273=63:97:36272=2014061037=80531936283289=114290=1
10:26:39.736: 656806 - 83 - 1128=935=X34=65680652=20140610-13:26:39.74175=20140610268=1279=0269=022=8207=BVMF48=380968883=252915270=29.38273=63:97:40271=9500272=2014061037016=2014061037017=63:97:4037=80531936288288=114290=6
10:26:39.736: 656807 - 83 - 1128=935=X34=65680752=20140610-13:26:39.74275=20140610268=1279=0269=122=8207=BVMF48=380963983=254617270=26.41273=63:97:41271=1000272=2014061037016=2014061037017=63:97:4137=80531936289289=114290=2
10:26:39.737: 656808 - 147 - 1128=935=X34=65680852=20140610-13:26:39.74275=20140610268=3279=0269=222=8207=BVMF48=380963983=254618270=26.41273=63:97:42271=1000272=2014061037016=2014061037017=63:97:411500=E451=-0.21020=1305200274=1277=L1003=17530288=8289=45279=0269=922=8207=BVMF48=380963983=254619270=26.475273=63:97:42272=201406101500=E279=2269=122=8207=BVMF48=380963983=254620273=63:97:42272=2014061037=80531936282289=45290=1
10:26:39.738: 656809 - 160 - 1128=935=X34=65680952=20140610-13:26:39.74475=20140610268=3279=0269=222=8207=BVMF48=380963983=254621270=26.41273=63:97:43271=900272=2014061037016=2014061037017=63:97:431500=E451=-0.21020=1306100274=1277=L1003=17540288=8289=114279=0269=922=8207=BVMF48=380963983=254622270=26.475273=63:97:43272=201406101500=E279=1269=122=8207=BVMF48=380963983=254623270=26.41273=63:97:43271=100272=2014061037016=2014061037017=63:97:4137=80531936289289=114290=1
10:26:39.742: 656810 - 346 - 1128=935=X34=65681052=20140610-13:26:39.74775=20140610268=8279=0269=222=8207=BVMF48=380968883=252916270=29.39273=63:97:46271=300272=2014061037016=2014061037017=63:97:461500=E451=-0.241020=389500274=1277=L1003=5800288=45289=45279=0269=922=8207=BVMF48=380968883=252917270=29.491273=63:97:46272=201406101500=E279=2269=122=8207=BVMF48=380968883=252918273=63:97:46272=2014061037=80531935918289=45290=1279=0269=122=8207=BVMF48=380968883=252919270=29.39273=63:97:46271=5000272=2014061037016=2014061037017=63:97:4637=80531936297289=45290=1279=0269=222=8207=BVMF48=380968883=252920270=29.39273=63:97:46271=600272=2014061037016=2014061037017=63:97:461500=E451=-0.241020=390100274=1277=L1003=5810288=45289=45279=0269=922=8207=BVMF48=380968883=252921270=29.491273=63:97:46272=201406101500=E279=1269=122=8207=BVMF48=380968883=252922270=29.39273=63:97:46271=4400272=2014061037016=2014061037017=63:97:4637=80531936297289=45290=1279=2269=022=8207=BVMF48=380968883=252923273=63:97:46272=2014061037=80531936271288=45290=5
10:26:39.743: 656811 - 73 - 1128=935=X34=65681152=20140610-13:26:39.74975=20140610268=1279=2269=122=8207=BVMF48=380963983=254624273=63:97:48272=2014061037=80531936289289=114290=1
10:26:39.743: 656812 - 71 - 1128=935=X34=65681252=20140610-13:26:39.74975=20140610268=1279=2269=022=8207=BVMF48=380963983=254625273=63:97:48272=2014061037=80531936238288=88290=15
10:26:39.744: 656813 - 199 - 1128=935=X34=65681352=20140610-13:26:39.74975=20140610268=4279=0269=222=8207=BVMF48=380968883=252924270=29.39273=63:97:49271=800272=2014061037016=2014061037017=63:97:491500=E451=-0.241020=390900274=1277=L1003=5820288=114289=45279=0269=922=8207=BVMF48=380968883=252925270=29.491273=63:97:49272=201406101500=E279=1269=122=8207=BVMF48=380968883=252926270=29.39273=63:97:49271=3600272=2014061037016=2014061037017=63:97:4637=80531936297289=45290=1279=2269=022=8207=BVMF48=380968883=252927273=63:97:49272=2014061037=80531936288288=114290=5
10:26:39.744: 656814 - 80 - 1128=935=X34=65681452=20140610-13:26:39.74975=20140610268=1279=0269=022=8207=BVMF48=380963983=254626270=26.41273=63:97:49271=200272=2014061037016=2014061037017=63:97:4937=80531936299288=3290=1
10:26:39.744: 656815 - 81 - 1128=935=X34=65681552=20140610-13:26:39.75075=20140610268=1279=0269=122=8207=BVMF48=380963983=254627270=26.43273=63:97:49271=200272=2014061037016=2014061037017=63:97:4937=80531936300289=8290=2
10:26:39.745: 656816 - 71 - 1128=935=X34=65681652=20140610-13:26:39.75075=20140610268=1279=2269=122=8207=BVMF48=380968883=252928273=63:97:50272=2014061037=80531927395289=3290=7
10:26:39.745: 656817 - 72 - 1128=935=X34=65681752=20140610-13:26:39.75175=20140610268=1279=2269=122=8207=BVMF48=380963983=254628273=63:97:50272=2014061037=80531927940289=45290=5
10:26:39.748: 656818 - 116 - 1128=935=X34=65681852=20140610-13:26:39.75375=20140610268=2279=2269=022=8207=BVMF48=380963983=254629273=63:97:53272=2014061037=80531936299288=3290=1279=0269=022=8207=BVMF48=380963983=254630270=26.41273=63:97:53271=600272=2014061037016=2014061037017=63:97:5337=80531936305288=3290=1
10:26:39.749: 656819 - 81 - 1128=935=X34=65681952=20140610-13:26:39.75375=20140610268=1279=0269=022=8207=BVMF48=380968883=252929270=29.38273=63:97:53271=4000272=2014061037016=2014061037017=63:97:5337=80531936306288=45290=5
10:26:39.749: 656820 - 195 - 1128=935=X34=65682052=20140610-13:26:39.75475=20140610268=4279=0269=222=8207=BVMF48=380963983=254631270=26.41273=63:97:53271=600272=2014061037016=2014061037017=63:97:531500=E451=-0.21020=1306700274=1277=L1003=17550288=3289=45279=0269=922=8207=BVMF48=380963983=254632270=26.475273=63:97:53272=201406101500=E279=2269=022=8207=BVMF48=380963983=254633273=63:97:53272=2014061037=80531936305288=3290=1279=0269=122=8207=BVMF48=380963983=254634270=26.41273=63:97:53271=400272=2014061037016=2014061037017=63:97:5337=80531936307289=45290=1
10:26:39.750: 656821 - 83 - 1128=935=X34=65682152=20140610-13:26:39.75675=20140610268=1279=0269=122=8207=BVMF48=380963983=254635270=26.41273=63:97:55271=1000272=2014061037016=2014061037017=63:97:5537=80531936310289=114290=2
10:26:39.750: 656822 - 83 - 1128=935=X34=65682252=20140610-13:26:39.75675=20140610268=1279=0269=022=8207=BVMF48=380968883=252930270=29.38273=63:97:55271=9500272=2014061037016=2014061037017=63:97:5537=80531936312288=114290=6
10:26:39.751: 656823 - 81 - 1128=935=X34=65682352=20140610-13:26:39.75775=20140610268=1279=0269=022=8207=BVMF48=380963983=254636270=26.4273=63:97:56271=300272=2014061037016=2014061037017=63:97:5637=80531936314288=3290=8
10:26:39.752: 656824 - 72 - 1128=935=X34=65682452=20140610-13:26:39.75875=20140610268=1279=2269=122=8207=BVMF48=380963983=254637273=63:97:57272=2014061037=80531936307289=45290=1
10:26:39.754: 656825 - 197 - 1128=935=X34=65682552=20140610-13:26:39.75975=20140610268=4279=0269=222=8207=BVMF48=380968883=252931270=29.39273=63:97:58271=300272=2014061037016=2014061037017=63:97:581500=E451=-0.241020=391200274=1277=L1003=5830288=45289=45279=0269=922=8207=BVMF48=380968883=252932270=29.491273=63:97:58272=201406101500=E279=1269=122=8207=BVMF48=380968883=252933270=29.39273=63:97:58271=3300272=2014061037016=2014061037017=63:97:4637=80531936297289=45290=1279=2269=022=8207=BVMF48=380968883=252934273=63:97:58272=2014061037=80531936306288=45290=5
10:26:39.754: 656826 - 82 - 1128=935=X34=65682652=20140610-13:26:39.75975=20140610268=1279=1269=122=8207=BVMF48=380963983=254638270=26.41273=63:97:59271=300272=2014061037016=2014061037017=63:97:5537=80531936316289=114290=1
10:26:39.758: 656827 - 73 - 1128=935=X34=65682752=20140610-13:26:39.76375=20140610268=1279=2269=122=8207=BVMF48=380963983=254639273=63:97:62272=2014061037=80531931429289=227290=7
10:26:39.758: 656828 - 157 - 1128=935=X34=65682852=20140610-13:26:39.76375=20140610268=3279=0269=222=8207=BVMF48=380968883=252935270=29.39273=63:97:63271=200272=2014061037016=2014061037017=63:97:621500=E451=-0.241020=391400274=1277=L1003=5840288=45289=45279=0269=922=8207=BVMF48=380968883=252936270=29.491273=63:97:63272=201406101500=E279=1269=122=8207=BVMF48=380968883=252937270=29.39273=63:97:63271=3100272=2014061037016=2014061037017=63:97:4637=80531936297289=45290=1
10:26:39.760: 656829 - 73 - 1128=935=X34=65682952=20140610-13:26:39.76675=20140610268=1279=2269=122=8207=BVMF48=380963983=254640273=63:97:65272=2014061037=80531936316289=114290=1
10:26:39.763: 656830 - 81 - 1128=935=X34=65683052=20140610-13:26:39.76975=20140610268=1279=0269=022=8207=BVMF48=380968883=252938270=29.38273=63:97:68271=4000272=2014061037016=2014061037017=63:97:6837=80531936329288=45290=6
10:26:39.763: 656831 - 81 - 1128=935=X34=65683152=20140610-13:26:39.76975=20140610268=1279=0269=122=8207=BVMF48=380963983=254641270=26.43273=63:97:68271=1000272=2014061037016=2014061037017=63:97:6837=80531936331289=3290=3
10:26:39.764: 656832 - 82 - 1128=935=X34=65683252=20140610-13:26:39.76975=20140610268=1279=0269=122=8207=BVMF48=380963983=254642270=26.42273=63:97:68271=5000272=2014061037016=2014061037017=63:97:6837=80531936332289=45290=1
10:26:39.764: 656833 - 80 - 1128=935=X34=65683352=20140610-13:26:39.76975=20140610268=1279=0269=022=8207=BVMF48=380963983=254643270=26.37273=63:97:69271=300272=2014061037016=2014061037017=63:97:6937=80531936336288=8290=22
10:26:39.766: 656834 - 81 - 1128=935=X34=65683452=20140610-13:26:39.77275=20140610268=1279=0269=122=8207=BVMF48=380963983=254644270=26.43273=63:97:71271=1000272=2014061037016=2014061037017=63:97:7137=80531936344289=3290=5
10:26:39.770: 656835 - 83 - 1128=935=X34=65683552=20140610-13:26:39.77575=20140610268=1279=0269=122=8207=BVMF48=380963983=254645270=26.44273=63:97:75271=300272=2014061037016=2014061037017=63:97:7437=80531936346289=227290=9
10:26:39.770: 656836 - 119 - 1128=935=X34=65683652=20140610-13:26:39.77675=20140610268=2279=2269=122=8207=BVMF48=380963983=254646273=63:97:75272=2014061037=80531936332289=45290=1279=0269=122=8207=BVMF48=380963983=254647270=26.41273=63:97:75271=4000272=2014061037016=2014061037017=63:97:7537=80531936347289=45290=1
10:26:39.770: 656837 - 83 - 1128=935=X34=65683752=20140610-13:26:39.77675=20140610268=1279=0269=122=8207=BVMF48=380963983=254648270=26.41273=63:97:76271=4000272=2014061037016=2014061037017=63:97:7537=80531936348289=114290=2
10:26:39.772: 656838 - 81 - 1128=935=X34=65683852=20140610-13:26:39.77775=20140610268=1279=0269=122=8207=BVMF48=380963983=254649270=26.43273=63:97:77271=100272=2014061037016=2014061037017=63:97:7637=80531936349289=8290=7
10:26:39.773: 656839 - 197 - 1128=935=X34=65683952=20140610-13:26:39.77875=20140610268=4279=0269=222=8207=BVMF48=380968883=252939270=29.39273=63:97:77271=100272=2014061037016=2014061037017=63:97:771500=E451=-0.241020=391500274=1277=L1003=5850288=45289=45279=0269=922=8207=BVMF48=380968883=252940270=29.491273=63:97:77272=201406101500=E279=1269=122=8207=BVMF48=380968883=252941270=29.39273=63:97:77271=3000272=2014061037016=2014061037017=63:97:4637=80531936297289=45290=1279=2269=022=8207=BVMF48=380968883=252942273=63:97:77272=2014061037=80531936329288=45290=6
10:26:39.773: 656840 - 199 - 1128=935=X34=65684052=20140610-13:26:39.77875=20140610268=4279=0269=222=8207=BVMF48=380968883=252943270=29.39273=63:97:78271=200272=2014061037016=2014061037017=63:97:771500=E451=-0.241020=391700274=1277=L1003=5860288=114289=45279=0269=922=8207=BVMF48=380968883=252944270=29.491273=63:97:78272=201406101500=E279=1269=122=8207=BVMF48=380968883=252945270=29.39273=63:97:78271=2800272=2014061037016=2014061037017=63:97:4637=80531936297289=45290=1279=2269=022=8207=BVMF48=380968883=252946273=63:97:78272=2014061037=80531936312288=114290=5
10:26:39.774: 656841 - 82 - 1128=935=X34=65684152=20140610-13:26:39.78075=20140610268=1279=0269=122=8207=BVMF48=380968883=252947270=29.4273=63:97:79271=300272=2014061037016=2014061037017=63:97:7937=80531936352289=8290=4
10:26:39.776: 656842 - 70 - 1128=935=X34=65684252=20140610-13:26:39.78275=20140610268=1279=2269=022=8207=BVMF48=380963983=254650273=63:97:81272=2014061037=80531936314288=3290=8
10:26:39.776: 656843 - 72 - 1128=935=X34=65684352=20140610-13:26:39.78275=20140610268=1279=2269=022=8207=BVMF48=380968883=252948273=63:97:81272=2014061037=80531936160288=227290=13
10:26:39.777: 656844 - 81 - 1128=935=X34=65684452=20140610-13:26:39.78375=20140610268=1279=0269=122=8207=BVMF48=380963983=254651270=26.44273=63:97:82271=100272=2014061037016=2014061037017=63:97:8237=80531936354289=8290=12
10:26:39.778: 656845 - 157 - 1128=935=X34=65684552=20140610-13:26:39.78475=20140610268=3279=0269=222=8207=BVMF48=380968883=252949270=29.39273=63:97:83271=100272=2014061037016=2014061037017=63:97:831500=E451=-0.241020=391800274=1277=L1003=5870288=45289=45279=0269=922=8207=BVMF48=380968883=252950270=29.491273=63:97:83272=201406101500=E279=1269=122=8207=BVMF48=380968883=252951270=29.39273=63:97:83271=2700272=2014061037016=2014061037017=63:97:4637=80531936297289=45290=1
10:26:39.779: 656846 - 82 - 1128=935=X34=65684652=20140610-13:26:39.78575=20140610268=1279=1269=122=8207=BVMF48=380963983=254652270=26.41273=63:97:84271=100272=2014061037016=2014061037017=63:97:7537=80531936358289=114290=2
10:26:39.782: 656847 - 82 - 1128=935=X34=65684752=20140610-13:26:39.78775=20140610268=1279=0269=122=8207=BVMF48=380963983=254653270=26.42273=63:97:86271=900272=2014061037016=2014061037017=63:97:8637=80531936360289=40290=3
10:26:39.783: 656848 - 82 - 1128=935=X34=65684852=20140610-13:26:39.78975=20140610268=1279=0269=022=8207=BVMF48=380968883=252952270=29.36273=63:97:88271=100272=2014061037016=2014061037017=63:97:8837=80531936363288=227290=10
10:26:39.783: 656849 - 81 - 1128=935=X34=65684952=20140610-13:26:39.78975=20140610268=1279=1269=122=8207=BVMF48=380963983=254654270=26.41273=63:97:88271=100272=2014061037016=2014061037017=63:97:7537=80531936364289=45290=1
10:26:39.787: 656850 - 203 - 1128=935=X34=65685052=20140610-13:26:39.79275=20140610268=4279=0269=222=8207=BVMF48=380963983=254655270=26.4273=63:97:92271=100272=2014061037016=2014061037017=63:97:911500=E451=-0.211020=1306800274=21003=17560288=45289=114279=0269=922=8207=BVMF48=380963983=254656270=26.475273=63:97:92272=201406101500=E279=1269=022=8207=BVMF48=380963983=254657270=26.4273=63:97:92271=4000272=2014061037016=2014061037017=63:44:3437=80531935606288=45290=1279=2269=122=8207=BVMF48=380963983=254658273=63:97:92272=2014061037=80531936358289=114290=2
10:26:39.788: 656851 - 201 - 1128=935=X34=65685152=20140610-13:26:39.79375=20140610268=4279=0269=222=8207=BVMF48=380963983=254659270=26.4273=63:97:92271=100272=2014061037016=2014061037017=63:97:921500=E451=-0.211020=1306900274=3277=L1003=17570288=45289=45279=0269=922=8207=BVMF48=380963983=254660270=26.475273=63:97:92272=201406101500=E279=1269=022=8207=BVMF48=380963983=254661270=26.4273=63:97:92271=3900272=2014061037016=2014061037017=63:44:3437=80531935606288=45290=1279=2269=122=8207=BVMF48=380963983=254662273=63:97:92272=2014061037=80531936364289=45290=1
10:26:39.788: 656852 - 71 - 1128=935=X34=65685252=20140610-13:26:39.79375=20140610268=1279=2269=122=8207=BVMF48=380963983=254663273=63:97:93272=2014061037=80531936354289=8290=11
10:26:39.792: 656853 - 83 - 1128=935=X34=65685352=20140610-13:26:39.79875=20140610268=1279=0269=122=8207=BVMF48=380963983=254664270=26.41273=63:97:97271=3500272=2014061037016=2014061037017=63:97:9737=80531936379289=114290=1
10:26:39.793: 656854 - 83 - 1128=935=X34=65685452=20140610-13:26:39.79875=20140610268=1279=0269=022=8207=BVMF48=380968883=252953270=29.38273=63:97:97271=9600272=2014061037016=2014061037017=63:97:9737=80531936382288=114290=5
10:26:39.794: 656855 - 81 - 1128=935=X34=65685552=20140610-13:26:39.80075=20140610268=1279=0269=022=8207=BVMF48=380968883=252954270=29.38273=63:97:99271=4000272=2014061037016=2014061037017=63:97:9937=80531936388288=45290=6
10:26:39.795: 656856 - 82 - 1128=935=X34=65685652=20140610-13:26:39.80075=20140610268=1279=0269=122=8207=BVMF48=380963983=254665270=26.41273=63:98:00271=3400272=2014061037016=2014061037017=63:97:9937=80531936391289=45290=2
10:26:39.796: 656857 - 82 - 1128=935=X34=65685752=20140610-13:26:39.80175=20140610268=1279=1269=122=8207=BVMF48=380963983=254666270=26.41273=63:98:01271=3400272=2014061037016=2014061037017=63:97:9737=80531936394289=114290=1
10:26:39.798: 656858 - 81 - 1128=935=X34=65685852=20140610-13:26:39.80475=20140610268=1279=1269=122=8207=BVMF48=380963983=254667270=26.41273=63:98:03271=3300272=2014061037016=2014061037017=63:97:9937=80531936410289=45290=2
10:26:39.799: 656859 - 70 - 1128=935=X34=65685952=20140610-13:26:39.80475=20140610268=1279=2269=022=8207=BVMF48=380963983=254668273=63:98:04272=2014061037=80531936212288=3290=6
10:26:39.802: 656860 - 70 - 1128=935=X34=65686052=20140610-13:26:39.80775=20140610268=1279=2269=022=8207=BVMF48=380963983=254669273=63:98:07272=2014061037=80531936208288=3290=5
10:26:39.808: 656861 - 81 - 1128=935=X34=65686152=20140610-13:26:39.81475=20140610268=1279=1269=122=8207=BVMF48=380963983=254670270=26.41273=63:98:13271=3000272=2014061037016=2014061037017=63:97:9937=80531936430289=45290=2
10:26:39.808: 656862 - 82 - 1128=935=X34=65686252=20140610-13:26:39.81475=20140610268=1279=1269=122=8207=BVMF48=380963983=254671270=26.41273=63:98:13271=3100272=2014061037016=2014061037017=63:97:9737=80531936432289=114290=1
10:26:39.809: 656863 - 82 - 1128=935=X34=65686352=20140610-13:26:39.81575=20140610268=1279=1269=022=8207=BVMF48=380968883=252955270=29.38273=63:98:14271=9400272=2014061037016=2014061037017=63:97:9737=80531936434288=114290=5
10:26:39.820: 656864 - 82 - 1128=935=X34=65686452=20140610-13:26:39.82575=20140610268=1279=1269=022=8207=BVMF48=380968883=252956270=29.38273=63:98:25271=9200272=2014061037016=2014061037017=63:97:9737=80531936451288=114290=5
10:26:39.824: 656865 - 81 - 1128=935=X34=65686552=20140610-13:26:39.83075=20140610268=1279=1269=022=8207=BVMF48=380968883=252957270=29.38273=63:98:29271=8100272=2014061037016=2014061037017=63:97:9737=80531936459288=114290=5
10:26:39.829: 656866 - 82 - 1128=935=X34=65686652=20140610-13:26:39.83475=20140610268=1279=0269=022=8207=BVMF48=380963983=254672270=26.4273=63:98:34271=800272=2014061037016=2014061037017=63:98:3437=80531936463288=88290=6
10:26:39.830: 656867 - 81 - 1128=935=X34=65686752=20140610-13:26:39.83675=20140610268=1279=0269=022=8207=BVMF48=380963983=254673270=26.4273=63:98:35271=600272=2014061037016=2014061037017=63:98:3537=80531936465288=3290=7
10:26:39.834: 656868 - 81 - 1128=935=X34=65686852=20140610-13:26:39.83975=20140610268=1279=0269=022=8207=BVMF48=380963983=254674270=26.4273=63:98:39271=600272=2014061037016=2014061037017=63:98:3937=80531936468288=3290=8
10:26:39.839: 656869 - 70 - 1128=935=X34=65686952=20140610-13:26:39.84475=20140610268=1279=2269=022=8207=BVMF48=380963983=254675273=63:98:44272=2014061037=80531936465288=3290=7
10:26:39.839: 656870 - 121 - 1128=935=X34=65687052=20140610-13:26:39.84475=20140610268=2279=2269=022=8207=BVMF48=380968883=252958273=63:98:44272=2014061037=80531936459288=114290=5279=0269=022=8207=BVMF48=380968883=252959270=29.38273=63:98:44271=8800272=2014061037016=2014061037017=63:98:4437=80531936471288=114290=6
10:26:39.841: 656871 - 70 - 1128=935=X34=65687152=20140610-13:26:39.84675=20140610268=1279=2269=022=8207=BVMF48=380963983=254676273=63:98:46272=2014061037=80531936468288=3290=7
10:26:39.844: 656872 - 121 - 1128=935=X34=65687252=20140610-13:26:39.84975=20140610268=2279=2269=022=8207=BVMF48=380968883=252960273=63:98:49272=2014061037=80531936471288=114290=6279=0269=022=8207=BVMF48=380968883=252961270=29.38273=63:98:49271=9400272=2014061037016=2014061037017=63:98:4937=80531936473288=114290=6
10:26:39.848: 656873 - 121 - 1128=935=X34=65687352=20140610-13:26:39.85375=20140610268=2279=2269=022=8207=BVMF48=380968883=252962273=63:98:52272=2014061037=80531936473288=114290=6279=0269=022=8207=BVMF48=380968883=252963270=29.38273=63:98:52271=9900272=2014061037016=2014061037017=63:98:5237=80531936476288=114290=6
10:26:39.851: 656874 - 82 - 1128=935=X34=65687452=20140610-13:26:39.85775=20140610268=1279=1269=022=8207=BVMF48=380968883=252964270=29.38273=63:98:56271=9400272=2014061037016=2014061037017=63:98:5237=80531936477288=114290=6
10:26:39.857: 656875 - 82 - 1128=935=X34=65687552=20140610-13:26:39.86375=20140610268=1279=1269=022=8207=BVMF48=380968883=252965270=29.38273=63:98:62271=8800272=2014061037016=2014061037017=63:98:5237=80531936479288=114290=6
10:26:39.868: 656876 - 118 - 1128=935=X34=65687652=20140610-13:26:39.87375=20140610268=2279=2269=022=8207=BVMF48=380963983=254677273=63:98:72272=2014061037=80531936463288=88290=6279=0269=022=8207=BVMF48=380963983=254678270=26.38273=63:98:72271=800272=2014061037016=2014061037017=63:98:7237=80531936484288=88290=13
10:26:39.878: 656877 - 81 - 1128=935=X34=65687752=20140610-13:26:39.88375=20140610268=1279=1269=022=8207=BVMF48=380968883=252966270=29.38273=63:98:83271=8100272=2014061037016=2014061037017=63:98:5237=80531936488288=114290=6
10:26:39.899: 656878 - 71 - 1128=935=X34=65687852=20140610-13:26:39.90475=20140610268=1279=2269=022=8207=BVMF48=380963983=254679273=63:99:04272=2014061037=80531936484288=88290=13
10:26:39.900: 656879 - 82 - 1128=935=X34=65687952=20140610-13:26:39.90675=20140610268=1279=0269=122=8207=BVMF48=380968883=252967270=29.48273=63:99:05271=2000272=2014061037016=2014061037017=63:99:0537=80531936492289=45290=26
10:26:39.924: 656880 - 81 - 1128=935=X34=65688052=20140610-13:26:39.93075=20140610268=1279=0269=122=8207=BVMF48=380963983=254680270=26.43273=63:99:29271=100272=2014061037016=2014061037017=63:99:2937=80531936496289=8290=9
10:26:39.930: 656881 - 81 - 1128=935=X34=65688152=20140610-13:26:39.93675=20140610268=1279=0269=122=8207=BVMF48=380963983=254681270=26.43273=63:99:35271=1000272=2014061037016=2014061037017=63:99:3537=80531936497289=8290=10
10:26:39.946: 656882 - 82 - 1128=935=X34=65688252=20140610-13:26:39.95275=20140610268=1279=0269=122=8207=BVMF48=380963983=254682270=26.44273=63:99:51271=3000272=2014061037016=2014061037017=63:99:5137=80531936500289=45290=15
10:26:39.971: 656883 - 71 - 1128=935=X34=65688352=20140610-13:26:39.97775=20140610268=1279=2269=122=8207=BVMF48=380963983=254683273=63:99:76272=2014061037=80531936496289=8290=9
10:26:39.978: 656884 - 71 - 1128=935=X34=65688452=20140610-13:26:39.98375=20140610268=1279=2269=122=8207=BVMF48=380963983=254684273=63:99:83272=2014061037=80531936497289=8290=9
10:26:40.009: 656885 - 70 - 1128=935=X34=65688552=20140610-13:26:40.01475=20140610268=1279=2269=022=8207=BVMF48=380963983=254685273=64:00:14272=2014061037=80531936048288=8290=12
10:26:40.009: 656886 - 81 - 1128=935=X34=65688652=20140610-13:26:40.01575=20140610268=1279=0269=122=8207=BVMF48=380963983=254686270=26.43273=64:00:14271=300272=2014061037016=2014061037017=64:00:1437=80531936509289=8290=9
10:26:40.026: 656887 - 81 - 1128=935=X34=65688752=20140610-13:26:40.03175=20140610268=1279=0269=022=8207=BVMF48=380963983=254687270=26.4273=64:00:31271=600272=2014061037016=2014061037017=64:00:3137=80531936514288=3290=6
10:26:40.030: 656888 - 81 - 1128=935=X34=65688852=20140610-13:26:40.03675=20140610268=1279=0269=022=8207=BVMF48=380963983=254688270=26.4273=64:00:35271=600272=2014061037016=2014061037017=64:00:3537=80531936517288=3290=7
10:26:40.034: 656889 - 121 - 1128=935=X34=65688952=20140610-13:26:40.04075=20140610268=2279=2269=022=8207=BVMF48=380968883=252968273=64:00:39272=2014061037=80531936488288=114290=6279=0269=022=8207=BVMF48=380968883=252969270=29.38273=64:00:39271=8600272=2014061037016=2014061037017=64:00:3937=80531936520288=114290=6
10:26:40.040: 656890 - 121 - 1128=935=X34=65689052=20140610-13:26:40.04675=20140610268=2279=2269=022=8207=BVMF48=380968883=252970273=64:00:45272=2014061037=80531936520288=114290=6279=0269=022=8207=BVMF48=380968883=252971270=29.38273=64:00:45271=9200272=2014061037016=2014061037017=64:00:4537=80531936522288=114290=6
10:26:40.065: 656891 - 70 - 1128=935=X34=65689152=20140610-13:26:40.07075=20140610268=1279=2269=022=8207=BVMF48=380963983=254689273=64:00:70272=2014061037=80531936514288=3290=6
10:26:40.070: 656892 - 81 - 1128=935=X34=65689252=20140610-13:26:40.07575=20140610268=1279=0269=022=8207=BVMF48=380963983=254690270=26.4273=64:00:74271=600272=2014061037016=2014061037017=64:00:7437=80531936530288=3290=7
10:26:40.072: 656893 - 82 - 1128=935=X34=65689352=20140610-13:26:40.07775=20140610268=1279=1269=022=8207=BVMF48=380968883=252972270=29.38273=64:00:77271=8600272=2014061037016=2014061037017=64:00:4537=80531936532288=114290=6
10:26:40.076: 656894 - 70 - 1128=935=X34=65689452=20140610-13:26:40.08175=20140610268=1279=2269=022=8207=BVMF48=380963983=254691273=64:00:81272=2014061037=80531936517288=3290=6
10:26:40.078: 656895 - 121 - 1128=935=X34=65689552=20140610-13:26:40.08475=20140610268=2279=2269=022=8207=BVMF48=380968883=252973273=64:00:83272=2014061037=80531936532288=114290=6279=0269=022=8207=BVMF48=380968883=252974270=29.38273=64:00:83271=9200272=2014061037016=2014061037017=64:00:8337=80531936534288=114290=6
10:26:40.079: 656896 - 70 - 1128=935=X34=65689652=20140610-13:26:40.08575=20140610268=1279=2269=022=8207=BVMF48=380963983=254692273=64:00:84272=2014061037=80531936530288=3290=6
10:26:40.086: 656897 - 82 - 1128=935=X34=65689752=20140610-13:26:40.09275=20140610268=1279=1269=022=8207=BVMF48=380968883=252975270=29.38273=64:00:91271=8600272=2014061037016=2014061037017=64:00:8337=80531936540288=114290=6
10:26:40.091: 656898 - 81 - 1128=935=X34=65689852=20140610-13:26:40.09775=20140610268=1279=1269=022=8207=BVMF48=380968883=252976270=29.38273=64:00:96271=8100272=2014061037016=2014061037017=64:00:8337=80531936544288=114290=6
10:26:40.404: 656899 - 206 - 1128=935=X34=65689952=20140610-13:26:40.40975=20140610268=5279=0269=222=8207=BVMF48=380249383=103298270=9.33273=64:04:08271=200272=2014061037016=2014061037017=64:04:081500=E451=-0.121020=255400274=01003=3470288=40289=21279=0269=922=8207=BVMF48=380249383=103299270=9.382273=64:04:08272=201406101500=E279=0269=222=8207=BVMF48=380249383=103300270=9.33273=64:04:08271=100272=2014061037016=2014061037017=64:04:081500=E451=-0.121020=255500274=1277=L1003=3480288=40289=21279=0269=922=8207=BVMF48=380249383=103301270=9.382273=64:04:08272=201406101500=E279=4269=022=8207=BVMF48=380249383=103302273=64:04:08272=20140610290=2
10:26:40.405: 656900 - 274 - 1128=935=X34=65690052=20140610-13:26:40.41175=20140610268=7279=0269=222=8207=BVMF48=380249383=103303270=9.33273=64:04:10271=100272=2014061037016=2014061037017=64:04:101500=E451=-0.121020=255600274=1277=L1003=3490288=40289=8279=0269=922=8207=BVMF48=380249383=103304270=9.382273=64:04:10272=201406101500=E279=0269=222=8207=BVMF48=380249383=103305270=9.33273=64:04:10271=100272=2014061037016=2014061037017=64:04:101500=E451=-0.121020=255700274=1277=L1003=3500288=40289=8279=0269=922=8207=BVMF48=380249383=103306270=9.382273=64:04:10272=201406101500=E279=0269=222=8207=BVMF48=380249383=103307270=9.33273=64:04:10271=100272=2014061037016=2014061037017=64:04:101500=E451=-0.121020=255800274=1277=L1003=3510288=40289=8279=0269=922=8207=BVMF48=380249383=103308270=9.382273=64:04:10272=201406101500=E279=4269=022=8207=BVMF48=380249383=103309273=64:04:10272=20140610290=3
10:26:40.407: 656901 - 80 - 1128=935=X34=65690152=20140610-13:26:40.41275=20140610268=1279=0269=022=8207=BVMF48=380249383=103310270=9.32273=64:04:12271=100272=2014061037016=2014061037017=64:04:1137=80531936583288=8290=7
10:26:40.426: 656902 - 121 - 1128=935=X34=65690252=20140610-13:26:40.43175=20140610268=2279=2269=122=8207=BVMF48=380249383=103311273=64:04:31272=2014061037=80531934370289=735290=5279=0269=122=8207=BVMF48=380249383=103312270=9.33273=64:04:31271=100272=2014061037016=2014061037017=64:04:3037=80531936591289=735290=1
10:26:40.438: 656903 - 199 - 1128=935=X34=65690352=20140610-13:26:40.44475=20140610268=4279=0269=222=8207=BVMF48=380249383=103313270=9.32273=64:04:43271=200272=2014061037016=2014061037017=64:04:431500=E451=-0.131020=256000274=21003=3520288=21289=735279=0269=922=8207=BVMF48=380249383=103314270=9.382273=64:04:43272=201406101500=E279=1269=022=8207=BVMF48=380249383=103315270=9.32273=64:04:43271=600272=2014061037016=2014061037017=54:88:9437=80531931617288=21290=1279=2269=122=8207=BVMF48=380249383=103316273=64:04:43272=2014061037=80531936591289=735290=1
10:26:40.444: 656904 - 80 - 1128=935=X34=65690452=20140610-13:26:40.45075=20140610268=1279=0269=022=8207=BVMF48=380249383=103317270=9.22273=64:04:49271=1600272=2014061037016=2014061037017=64:04:4937=80531936604288=3290=44
10:26:40.445: 656905 - 83 - 1128=935=X34=65690552=20140610-13:26:40.45175=20140610268=1279=0269=122=8207=BVMF48=380249383=103318270=9.34273=64:04:50271=200272=2014061037016=2014061037017=64:04:5037=80531936605289=735290=6
10:26:40.456: 656906 - 81 - 1128=935=X34=65690652=20140610-13:26:40.46175=20140610268=1279=0269=122=8207=BVMF48=380249383=103319270=9.34273=64:04:60271=100272=2014061037016=2014061037017=64:04:6037=80531936606289=8290=7
10:26:40.456: 656907 - 80 - 1128=935=X34=65690752=20140610-13:26:40.46175=20140610268=1279=0269=022=8207=BVMF48=380249383=103320270=9.32273=64:04:60271=100272=2014061037016=2014061037017=64:04:6037=80531936607288=8290=8
10:26:40.456: 656908 - 71 - 1128=935=X34=65690852=20140610-13:26:40.46175=20140610268=1279=2269=122=8207=BVMF48=380249383=103321273=64:04:61272=2014061037=80531936606289=8290=7
10:26:40.456: 656909 - 70 - 1128=935=X34=65690952=20140610-13:26:40.46175=20140610268=1279=2269=022=8207=BVMF48=380249383=103322273=64:04:61272=2014061037=80531936607288=8290=8
10:26:40.457: 656910 - 81 - 1128=935=X34=65691052=20140610-13:26:40.46275=20140610268=1279=0269=122=8207=BVMF48=380249383=103323270=9.34273=64:04:62271=100272=2014061037016=2014061037017=64:04:6237=80531936609289=8290=7
10:26:40.457: 656911 - 71 - 1128=935=X34=65691152=20140610-13:26:40.46275=20140610268=1279=2269=122=8207=BVMF48=380249383=103324273=64:04:62272=2014061037=80531936609289=8290=7
10:26:40.776: 656912 - 81 - 1128=935=X34=65691252=20140610-13:26:40.78275=20140610268=1279=0269=122=8207=BVMF48=380963983=254693270=26.44273=64:07:81271=300272=2014061037016=2014061037017=64:07:8137=80531936734289=8290=15
10:26:40.791: 656913 - 82 - 1128=935=X34=65691352=20140610-13:26:40.79675=20140610268=1279=0269=122=8207=BVMF48=380963983=254694270=26.44273=64:07:96271=5000272=2014061037016=2014061037017=64:07:9637=80531936735289=45290=16
10:26:40.833: 656914 - 82 - 1128=935=X34=65691452=20140610-13:26:40.83975=20140610268=1279=0269=022=8207=BVMF48=380965483=79260270=8.2273=64:08:38271=1000272=2014061037016=2014061037017=64:08:3837=80531936736288=72290=5
10:26:40.960: 656915 - 80 - 1128=935=X34=65691552=20140610-13:26:40.96575=20140610268=1279=0269=022=8207=BVMF48=380391383=106037270=13.78273=64:09:65271=100272=2014061037016=2014061037017=64:09:6537=80531936737288=3290=33
10:26:40.992: 656916 - 82 - 1128=935=X34=65691652=20140610-13:26:40.99775=20140610268=1279=0269=122=8207=BVMF48=380963983=254695270=26.52273=64:09:97271=5000272=2014061037016=2014061037017=64:09:9637=80531936739289=45290=66
10:26:41.165: 656917 - 64 - 1128=935=X34=65691752=20140610-13:26:41.17175=20140610268=1279=0269=B22=8207=BVMF48=380394783=65652270=314670273=64:11:64271=108272=201406101500=E15=BRL
10:26:41.169: 656918 - 65 - 1128=935=X34=65691852=20140610-13:26:41.17475=20140610268=1279=0269=B22=8207=BVMF48=380963983=254696270=34599529273=64:11:64271=1757272=201406101500=E15=BRL
10:26:41.171: 656919 - 61 - 1128=935=X34=65691952=20140610-13:26:41.17675=20140610268=1279=0269=B22=8207=BVMF48=394036883=1646270=271.41273=64:11:64271=3272=201406101500=E15=BRL
10:26:41.173: 656920 - 65 - 1128=935=X34=65692052=20140610-13:26:41.17875=20140610268=1279=0269=B22=8207=BVMF48=380249383=103325270=2401792273=64:11:64271=351272=201406101500=E15=BRL
10:26:41.190: 656921 - 65 - 1128=935=X34=65692152=20140610-13:26:41.19675=20140610268=1279=0269=B22=8207=BVMF48=380391383=106038270=1482180273=64:11:64271=323272=201406101500=E15=BRL
10:26:41.206: 656922 - 65 - 1128=935=X34=65692252=20140610-13:26:41.21275=20140610268=1279=0269=B22=8207=BVMF48=380968883=252977270=11554530273=64:11:64271=587272=201406101500=E15=BRL
10:26:41.223: 656923 - 65 - 1128=935=X34=65692352=20140610-13:26:41.22975=20140610268=1279=0269=B22=8207=BVMF48=380965483=79261270=1578331273=64:11:64271=266272=201406101500=E15=BRL
10:26:41.580: 656924 - 162 - 1128=935=X34=65692452=20140610-13:26:41.58575=20140610268=3279=0269=222=8207=BVMF48=380963983=254697270=26.41273=64:15:84271=1000272=2014061037016=2014061037017=64:15:841500=E451=-0.21020=1307900274=01003=17580288=262289=114279=0269=922=8207=BVMF48=380963983=254698270=26.474273=64:15:84272=201406101500=E279=1269=122=8207=BVMF48=380963983=254699270=26.41273=64:15:84271=2100272=2014061037016=2014061037017=63:97:9737=80531936432289=114290=1
10:26:41.584: 656925 - 73 - 1128=935=X34=65692552=20140610-13:26:41.59075=20140610268=1279=2269=122=8207=BVMF48=380963983=254700273=64:15:89272=2014061037=80531936432289=114290=1
10:26:41.586: 656926 - 199 - 1128=935=X34=65692652=20140610-13:26:41.59175=20140610268=4279=0269=222=8207=BVMF48=380968883=252978270=29.39273=64:15:90271=800272=2014061037016=2014061037017=64:15:901500=E451=-0.241020=392600274=1277=L1003=5880288=114289=45279=0269=922=8207=BVMF48=380968883=252979270=29.491273=64:15:90272=201406101500=E279=1269=122=8207=BVMF48=380968883=252980270=29.39273=64:15:90271=1900272=2014061037016=2014061037017=63:97:4637=80531936297289=45290=1279=2269=022=8207=BVMF48=380968883=252981273=64:15:90272=2014061037=80531936544288=114290=6
10:26:41.587: 656927 - 148 - 1128=935=X34=65692752=20140610-13:26:41.59275=20140610268=3279=0269=222=8207=BVMF48=380963983=254701270=26.41273=64:15:92271=3000272=2014061037016=2014061037017=64:15:911500=E451=-0.21020=1310900274=1277=L1003=17590288=45289=45279=0269=922=8207=BVMF48=380963983=254702270=26.474273=64:15:92272=201406101500=E279=2269=122=8207=BVMF48=380963983=254703273=64:15:92272=2014061037=80531936430289=45290=1
10:26:41.588: 656928 - 72 - 1128=935=X34=65692852=20140610-13:26:41.59375=20140610268=1279=2269=122=8207=BVMF48=380968883=252982273=64:15:93272=2014061037=80531936492289=45290=26
10:26:41.590: 656929 - 81 - 1128=935=X34=65692952=20140610-13:26:41.59575=20140610268=1279=0269=022=8207=BVMF48=380963983=254704270=26.41273=64:15:95271=5000272=2014061037016=2014061037017=64:15:9537=80531936776288=77290=1
10:26:41.590: 656930 - 160 - 1128=935=X34=65693052=20140610-13:26:41.59675=20140610268=3279=0269=222=8207=BVMF48=380963983=254705270=26.41273=64:15:95271=3000272=2014061037016=2014061037017=64:15:951500=E451=-0.21020=1313900274=1277=L1003=17600288=77289=114279=0269=922=8207=BVMF48=380963983=254706270=26.474273=64:15:95272=201406101500=E279=1269=022=8207=BVMF48=380963983=254707270=26.41273=64:15:95271=2000272=2014061037016=2014061037017=64:15:9537=80531936776288=77290=1
10:26:41.590: 656931 - 83 - 1128=935=X34=65693152=20140610-13:26:41.59675=20140610268=1279=0269=022=8207=BVMF48=380968883=252983270=29.38273=64:15:95271=8200272=2014061037016=2014061037017=64:15:9537=80531936778288=114290=6
10:26:41.591: 656932 - 71 - 1128=935=X34=65693252=20140610-13:26:41.59675=20140610268=1279=2269=122=8207=BVMF48=380968883=252984273=64:15:96272=2014061037=80531936352289=8290=4
10:26:41.591: 656933 - 72 - 1128=935=X34=65693352=20140610-13:26:41.59775=20140610268=1279=2269=122=8207=BVMF48=380963983=254708273=64:15:96272=2014061037=80531936500289=45290=12
10:26:41.592: 656934 - 118 - 1128=935=X34=65693452=20140610-13:26:41.59775=20140610268=2279=2269=022=8207=BVMF48=380963983=254709273=64:15:97272=2014061037=80531920384288=45290=63279=0269=022=8207=BVMF48=380963983=254710270=26.41273=64:15:97271=3000272=2014061037016=2014061037017=64:15:9637=80531936781288=45290=2
10:26:41.592: 656935 - 118 - 1128=935=X34=65693552=20140610-13:26:41.59775=20140610268=2279=2269=022=8207=BVMF48=380968883=252985273=64:15:97272=2014061037=80531935616288=45290=23279=0269=022=8207=BVMF48=380968883=252986270=29.36273=64:15:97271=2000272=2014061037016=2014061037017=64:15:9737=80531936784288=45290=13
10:26:41.592: 656936 - 346 - 1128=935=X34=65693652=20140610-13:26:41.59875=20140610268=8279=0269=222=8207=BVMF48=380968883=252987270=29.39273=64:15:97271=1900272=2014061037016=2014061037017=64:15:971500=E451=-0.241020=394500274=1277=L1003=5890288=45289=45279=0269=922=8207=BVMF48=380968883=252988270=29.49273=64:15:97272=201406101500=E279=2269=122=8207=BVMF48=380968883=252989273=64:15:97272=2014061037=80531936297289=45290=1279=0269=122=8207=BVMF48=380968883=252990270=29.39273=64:15:97271=5000272=2014061037016=2014061037017=64:15:9737=80531936786289=45290=1279=0269=222=8207=BVMF48=380968883=252991270=29.39273=64:15:97271=700272=2014061037016=2014061037017=64:15:971500=E451=-0.241020=395200274=1277=L1003=5900288=45289=45279=0269=922=8207=BVMF48=380968883=252992270=29.49273=64:15:97272=201406101500=E279=1269=122=8207=BVMF48=380968883=252993270=29.39273=64:15:97271=4300272=2014061037016=2014061037017=64:15:9737=80531936786289=45290=1279=2269=022=8207=BVMF48=380968883=252994273=64:15:97272=2014061037=80531936388288=45290=5
10:26:41.593: 656937 - 81 - 1128=935=X34=65693752=20140610-13:26:41.59875=20140610268=1279=0269=022=8207=BVMF48=380963983=254711270=26.4273=64:15:98271=300272=2014061037016=2014061037017=64:15:9737=80531936789288=3290=8
10:26:41.593: 656938 - 71 - 1128=935=X34=65693852=20140610-13:26:41.59875=20140610268=1279=2269=022=8207=BVMF48=380963983=254712273=64:15:98272=2014061037=80531936781288=45290=2
10:26:41.594: 656939 - 80 - 1128=935=X34=65693952=20140610-13:26:41.60075=20140610268=1279=0269=022=8207=BVMF48=380963983=254713270=26.41273=64:15:99271=600272=2014061037016=2014061037017=64:15:9937=80531936791288=3290=2
10:26:41.596: 656940 - 199 - 1128=935=X34=65694052=20140610-13:26:41.60175=20140610268=4279=0269=222=8207=BVMF48=380968883=252995270=29.39273=64:16:00271=2700272=2014061037016=2014061037017=64:16:001500=E451=-0.241020=397900274=1277=L1003=5910288=114289=45279=0269=922=8207=BVMF48=380968883=252996270=29.489273=64:16:00272=201406101500=E279=1269=122=8207=BVMF48=380968883=252997270=29.39273=64:16:00271=1600272=2014061037016=2014061037017=64:15:9737=80531936786289=45290=1279=2269=022=8207=BVMF48=380968883=252998273=64:16:00272=2014061037=80531936778288=114290=5
10:26:41.598: 656941 - 81 - 1128=935=X34=65694152=20140610-13:26:41.60475=20140610268=1279=0269=022=8207=BVMF48=380968883=252999270=29.38273=64:16:03271=2700272=2014061037016=2014061037017=64:16:0337=80531936793288=45290=5
10:26:41.599: 656942 - 257 - 1128=935=X34=65694252=20140610-13:26:41.60575=20140610268=6279=0269=222=8207=BVMF48=380963983=254714270=26.41273=64:16:04271=2000272=2014061037016=2014061037017=64:16:041500=E451=-0.21020=1315900274=1277=L1003=17610288=77289=45279=0269=922=8207=BVMF48=380963983=254715270=26.474273=64:16:04272=201406101500=E279=0269=222=8207=BVMF48=380963983=254716270=26.41273=64:16:04271=600272=2014061037016=2014061037017=64:16:041500=E451=-0.21020=1316500274=1277=L1003=17620288=3289=45279=0269=922=8207=BVMF48=380963983=254717270=26.474273=64:16:04272=201406101500=E279=4269=022=8207=BVMF48=380963983=254718273=64:16:04272=20140610290=2279=0269=122=8207=BVMF48=380963983=254719270=26.41273=64:16:04271=300272=2014061037016=2014061037017=64:16:0437=80531936794289=45290=1
10:26:41.600: 656943 - 70 - 1128=935=X34=65694352=20140610-13:26:41.60575=20140610268=1279=2269=022=8207=BVMF48=380963983=254720273=64:16:05272=2014061037=80531936336288=8290=19
10:26:41.601: 656944 - 194 - 1128=935=X34=65694452=20140610-13:26:41.60675=20140610268=4279=0269=222=8207=BVMF48=380963983=254721270=26.41273=64:16:06271=300272=2014061037016=2014061037017=64:16:051500=E451=-0.21020=1316800274=1277=L1003=17630288=3289=45279=0269=922=8207=BVMF48=380963983=254722270=26.474273=64:16:06272=201406101500=E279=2269=122=8207=BVMF48=380963983=254723273=64:16:06272=2014061037=80531936794289=45290=1279=0269=022=8207=BVMF48=380963983=254724270=26.41273=64:16:06271=300272=2014061037016=2014061037017=64:16:0537=80531936800288=3290=1
10:26:41.601: 656945 - 197 - 1128=935=X34=65694552=20140610-13:26:41.60675=20140610268=4279=0269=222=8207=BVMF48=380963983=254725270=26.41273=64:16:06271=300272=2014061037016=2014061037017=64:16:061500=E451=-0.21020=1317100274=1277=L1003=17640288=3289=114279=0269=922=8207=BVMF48=380963983=254726270=26.474273=64:16:06272=201406101500=E279=2269=022=8207=BVMF48=380963983=254727273=64:16:06272=2014061037=80531936800288=3290=1279=0269=122=8207=BVMF48=380963983=254728270=26.41273=64:16:06271=2700272=2014061037016=2014061037017=64:16:0637=80531936801289=114290=1
10:26:41.601: 656946 - 83 - 1128=935=X34=65694652=20140610-13:26:41.60775=20140610268=1279=0269=022=8207=BVMF48=380968883=253000270=29.38273=64:16:06271=8200272=2014061037016=2014061037017=64:16:0637=80531936804288=114290=6
10:26:41.602: 656947 - 71 - 1128=935=X34=65694752=20140610-13:26:41.60875=20140610268=1279=2269=022=8207=BVMF48=380968883=253001273=64:16:07272=2014061037=80531936784288=45290=13
10:26:41.605: 656948 - 346 - 1128=935=X34=65694852=20140610-13:26:41.61075=20140610268=8279=0269=222=8207=BVMF48=380968883=253002270=29.39273=64:16:09271=1600272=2014061037016=2014061037017=64:16:091500=E451=-0.241020=399500274=1277=L1003=5920288=45289=45279=0269=922=8207=BVMF48=380968883=253003270=29.489273=64:16:09272=201406101500=E279=2269=122=8207=BVMF48=380968883=253004273=64:16:09272=2014061037=80531936786289=45290=1279=0269=122=8207=BVMF48=380968883=253005270=29.39273=64:16:09271=5000272=2014061037016=2014061037017=64:16:0937=80531936816289=45290=1279=0269=222=8207=BVMF48=380968883=253006270=29.39273=64:16:09271=200272=2014061037016=2014061037017=64:16:091500=E451=-0.241020=399700274=1277=L1003=5930288=45289=45279=0269=922=8207=BVMF48=380968883=253007270=29.489273=64:16:09272=201406101500=E279=1269=122=8207=BVMF48=380968883=253008270=29.39273=64:16:09271=4800272=2014061037016=2014061037017=64:16:0937=80531936816289=45290=1279=2269=022=8207=BVMF48=380968883=253009273=64:16:09272=2014061037=80531936793288=45290=5
10:26:41.607: 656949 - 82 - 1128=935=X34=65694952=20140610-13:26:41.61275=20140610268=1279=1269=122=8207=BVMF48=380963983=254729270=26.41273=64:16:12271=1800272=2014061037016=2014061037017=64:16:0637=80531936825289=114290=1
10:26:41.609: 656950 - 199 - 1128=935=X34=65695052=20140610-13:26:41.61475=20140610268=4279=0269=222=8207=BVMF48=380968883=253010270=29.39273=64:16:14271=200272=2014061037016=2014061037017=64:16:131500=E451=-0.241020=399900274=1277=L1003=5940288=114289=45279=0269=922=8207=BVMF48=380968883=253011270=29.489273=64:16:14272=201406101500=E279=1269=122=8207=BVMF48=380968883=253012270=29.39273=64:16:14271=4600272=2014061037016=2014061037017=64:16:0937=80531936816289=45290=1279=2269=022=8207=BVMF48=380968883=253013273=64:16:14272=2014061037=80531936804288=114290=5
10:26:41.609: 656951 - 157 - 1128=935=X34=65695152=20140610-13:26:41.61575=20140610268=3279=0269=222=8207=BVMF48=380968883=253014270=29.39273=64:16:14271=100272=2014061037016=2014061037017=64:16:141500=E451=-0.241020=400000274=1277=L1003=5950288=45289=45279=0269=922=8207=BVMF48=380968883=253015270=29.489273=64:16:14272=201406101500=E279=1269=122=8207=BVMF48=380968883=253016270=29.39273=64:16:14271=4500272=2014061037016=2014061037017=64:16:0937=80531936816289=45290=1
10:26:41.612: 656952 - 160 - 1128=935=X34=65695252=20140610-13:26:41.61775=20140610268=3279=0269=222=8207=BVMF48=380963983=254730270=26.41273=64:16:17271=200272=2014061037016=2014061037017=64:16:161500=E451=-0.21020=1317300274=1277=L1003=17650288=3289=114279=0269=922=8207=BVMF48=380963983=254731270=26.474273=64:16:17272=201406101500=E279=1269=122=8207=BVMF48=380963983=254732270=26.41273=64:16:17271=1600272=2014061037016=2014061037017=64:16:0637=80531936825289=114290=1
10:26:41.612: 656953 - 73 - 1128=935=X34=65695352=20140610-13:26:41.61775=20140610268=1279=2269=122=8207=BVMF48=380963983=254733273=64:16:17272=2014061037=80531936825289=114290=1
10:26:41.613: 656954 - 118 - 1128=935=X34=65695452=20140610-13:26:41.61975=20140610268=2279=2269=022=8207=BVMF48=380963983=254734273=64:16:18272=2014061037=80531924228288=45290=55279=0269=022=8207=BVMF48=380963983=254735270=26.41273=64:16:18271=5000272=2014061037016=2014061037017=64:16:1837=80531936838288=45290=1
10:26:41.614: 656955 - 308 - 1128=935=X34=65695552=20140610-13:26:41.62075=20140610268=7279=0269=222=8207=BVMF48=380968883=253017270=29.39273=64:16:19271=4500272=2014061037016=2014061037017=64:16:191500=E451=-0.241020=404500274=1277=L1003=5960288=114289=45279=0269=922=8207=BVMF48=380968883=253018270=29.488273=64:16:19272=201406101500=E279=2269=122=8207=BVMF48=380968883=253019273=64:16:19272=2014061037=80531936816289=45290=1279=0269=122=8207=BVMF48=380968883=253020270=29.39273=64:16:19271=5000272=2014061037016=2014061037017=64:16:1937=80531936842289=45290=1279=0269=222=8207=BVMF48=380968883=253021270=29.39273=64:16:19271=100272=2014061037016=2014061037017=64:16:191500=E451=-0.241020=404600274=1277=L1003=5970288=114289=45279=0269=922=8207=BVMF48=380968883=253022270=29.488273=64:16:19272=201406101500=E279=1269=122=8207=BVMF48=380968883=253023270=29.39273=64:16:19271=4900272=2014061037016=2014061037017=64:16:1937=80531936842289=45290=1
10:26:41.615: 656956 - 157 - 1128=935=X34=65695652=20140610-13:26:41.62075=20140610268=3279=0269=222=8207=BVMF48=380968883=253024270=29.39273=64:16:20271=800272=2014061037016=2014061037017=64:16:201500=E451=-0.241020=405400274=1277=L1003=5980288=45289=45279=0269=922=8207=BVMF48=380968883=253025270=29.488273=64:16:20272=201406101500=E279=1269=122=8207=BVMF48=380968883=253026270=29.39273=64:16:20271=4100272=2014061037016=2014061037017=64:16:1937=80531936842289=45290=1
10:26:41.616: 656957 - 82 - 1128=935=X34=65695752=20140610-13:26:41.62175=20140610268=1279=0269=122=8207=BVMF48=380968883=253027270=29.4273=64:16:21271=100272=2014061037016=2014061037017=64:16:2137=80531936853289=8290=4
10:26:41.616: 656958 - 71 - 1128=935=X34=65695852=20140610-13:26:41.62175=20140610268=1279=2269=122=8207=BVMF48=380968883=253028273=64:16:21272=2014061037=80531936853289=8290=4
10:26:41.620: 656959 - 160 - 1128=935=X34=65695952=20140610-13:26:41.62575=20140610268=3279=0269=222=8207=BVMF48=380963983=254736270=26.41273=64:16:24271=4700272=2014061037016=2014061037017=64:16:241500=E451=-0.21020=1322000274=1277=L1003=17660288=45289=114279=0269=922=8207=BVMF48=380963983=254737270=26.474273=64:16:24272=201406101500=E279=1269=022=8207=BVMF48=380963983=254738270=26.41273=64:16:24271=300272=2014061037016=2014061037017=64:16:1837=80531936838288=45290=1
10:26:41.621: 656960 - 80 - 1128=935=X34=65696052=20140610-13:26:41.62675=20140610268=1279=0269=022=8207=BVMF48=380963983=254739270=26.39273=64:16:26271=300272=2014061037016=2014061037017=64:16:2637=80531936867288=3290=10
10:26:41.621: 656961 - 71 - 1128=935=X34=65696152=20140610-13:26:41.62675=20140610268=1279=2269=022=8207=BVMF48=380963983=254740273=64:16:26272=2014061037=80531936838288=45290=1
10:26:41.621: 656962 - 72 - 1128=935=X34=65696252=20140610-13:26:41.62775=20140610268=1279=2269=122=8207=BVMF48=380963983=254741273=64:16:26272=2014061037=80531936739289=45290=63
10:26:41.625: 656963 - 83 - 1128=935=X34=65696352=20140610-13:26:41.63075=20140610268=1279=0269=122=8207=BVMF48=380963983=254742270=26.41273=64:16:29271=100272=2014061037016=2014061037017=64:16:2937=80531936879289=114290=1
10:26:41.629: 656964 - 203 - 1128=935=X34=65696452=20140610-13:26:41.63475=20140610268=4279=0269=222=8207=BVMF48=380963983=254743270=26.4273=64:16:33271=100272=2014061037016=2014061037017=64:16:331500=E451=-0.211020=1322100274=21003=17670288=45289=114279=0269=922=8207=BVMF48=380963983=254744270=26.474273=64:16:33272=201406101500=E279=1269=022=8207=BVMF48=380963983=254745270=26.4273=64:16:33271=3800272=2014061037016=2014061037017=63:44:3437=80531935606288=45290=1279=2269=122=8207=BVMF48=380963983=254746273=64:16:33272=2014061037=80531936879289=114290=1
10:26:41.633: 656965 - 83 - 1128=935=X34=65696552=20140610-13:26:41.63875=20140610268=1279=0269=122=8207=BVMF48=380963983=254747270=26.41273=64:16:38271=1800272=2014061037016=2014061037017=64:16:3837=80531936893289=114290=1
10:26:41.633: 656966 - 83 - 1128=935=X34=65696652=20140610-13:26:41.63975=20140610268=1279=0269=022=8207=BVMF48=380968883=253029270=29.38273=64:16:38271=8400272=2014061037016=2014061037017=64:16:3837=80531936894288=114290=5
10:26:41.638: 656967 - 81 - 1128=935=X34=65696752=20140610-13:26:41.64375=20140610268=1279=0269=022=8207=BVMF48=380963983=254748270=26.4273=64:16:43271=600272=2014061037016=2014061037017=64:16:4337=80531936910288=3290=7
10:26:41.639: 656968 - 81 - 1128=935=X34=65696852=20140610-13:26:41.64575=20140610268=1279=0269=022=8207=BVMF48=380963983=254749270=26.4273=64:16:44271=600272=2014061037016=2014061037017=64:16:4437=80531936914288=3290=8
10:26:41.640: 656969 - 121 - 1128=935=X34=65696952=20140610-13:26:41.64575=20140610268=2279=2269=122=8207=BVMF48=380963983=254750273=64:16:45272=2014061037=80531936893289=114290=1279=0269=122=8207=BVMF48=380963983=254751270=26.41273=64:16:45271=5400272=2014061037016=2014061037017=64:16:4537=80531936915289=114290=1
10:26:41.644: 656970 - 82 - 1128=935=X34=65697052=20140610-13:26:41.65075=20140610268=1279=1269=122=8207=BVMF48=380963983=254752270=26.41273=64:16:49271=5000272=2014061037016=2014061037017=64:16:4537=80531936939289=114290=1
10:26:41.648: 656971 - 72 - 1128=935=X34=65697152=20140610-13:26:41.65375=20140610268=1279=2269=022=8207=BVMF48=380968883=253030273=64:16:52272=2014061037=80531936363288=227290=11
